{"name":"broken_castle","world":{"pos1":{"x":-122,"y":0,"z":41},"pos2":{"x":-152,"y":20,"z":9},"door_bottom":{"x":-137,"y":1,"z":25}},"meta":{},"size":{"x":31,"y":21,"z":33},"door_pos":{"x":15,"y":1,"z":16},"blocks":[{"move":{"x":-15,"y":-1,"z":5},"block_id":2},{"move":{"x":-15,"y":-1,"z":7},"block_id":2},{"move":{"x":-15,"y":-1,"z":25},"block_id":2},{"move":{"x":-15,"y":-1,"z":27},"block_id":2},{"move":{"x":-15,"y":0,"z":7},"block_id":106,"extra_data":{},"rotate":{"x":1,"y":0,"z":0}},{"move":{"x":-15,"y":1,"z":7},"block_id":106,"extra_data":{},"rotate":{"x":1,"y":0,"z":0}},{"move":{"x":-15,"y":2,"z":7},"block_id":106,"extra_data":{},"rotate":{"x":1,"y":0,"z":0}},{"move":{"x":-15,"y":2,"z":27},"block_id":106,"extra_data":{},"rotate":{"x":1,"y":0,"z":0}},{"move":{"x":-15,"y":3,"z":5},"block_id":106,"extra_data":{},"rotate":{"x":1,"y":0,"z":0}},{"move":{"x":-15,"y":3,"z":25},"block_id":106,"extra_data":{},"rotate":{"x":1,"y":0,"z":0}},{"move":{"x":-15,"y":3,"z":27},"block_id":106,"extra_data":{},"rotate":{"x":1,"y":0,"z":0}},{"move":{"x":-15,"y":4,"z":5},"block_id":106,"extra_data":{},"rotate":{"x":1,"y":0,"z":0}},{"move":{"x":-15,"y":4,"z":25},"block_id":106,"extra_data":{},"rotate":{"x":1,"y":0,"z":0}},{"move":{"x":-15,"y":4,"z":27},"block_id":106,"extra_data":{},"rotate":{"x":1,"y":0,"z":0}},{"move":{"x":-15,"y":5,"z":5},"block_id":106,"extra_data":{},"rotate":{"x":1,"y":0,"z":0}},{"move":{"x":-15,"y":5,"z":25},"block_id":106,"extra_data":{},"rotate":{"x":1,"y":0,"z":0}},{"move":{"x":-15,"y":5,"z":27},"block_id":106,"extra_data":{},"rotate":{"x":1,"y":0,"z":0}},{"move":{"x":-15,"y":6,"z":27},"block_id":106,"extra_data":{},"rotate":{"x":1,"y":0,"z":0}},{"move":{"x":-14,"y":-1,"z":4},"block_id":2},{"move":{"x":-14,"y":-1,"z":5},"block_id":18},{"move":{"x":-14,"y":-1,"z":6},"block_id":2},{"move":{"x":-14,"y":-1,"z":7},"block_id":18},{"move":{"x":-14,"y":-1,"z":8},"block_id":2},{"move":{"x":-14,"y":-1,"z":24},"block_id":2},{"move":{"x":-14,"y":-1,"z":25},"block_id":18},{"move":{"x":-14,"y":-1,"z":26},"block_id":2},{"move":{"x":-14,"y":-1,"z":27},"block_id":18},{"move":{"x":-14,"y":-1,"z":28},"block_id":2},{"move":{"x":-14,"y":0,"z":5},"block_id":8},{"move":{"x":-14,"y":0,"z":6},"block_id":106,"extra_data":{},"rotate":{"x":0,"y":0,"z":0}},{"move":{"x":-14,"y":0,"z":7},"block_id":8},{"move":{"x":-14,"y":0,"z":8},"block_id":106,"extra_data":{},"rotate":{"x":0,"y":0,"z":0}},{"move":{"x":-14,"y":0,"z":25},"block_id":146},{"move":{"x":-14,"y":0,"z":27},"block_id":8},{"move":{"x":-14,"y":1,"z":5},"block_id":146},{"move":{"x":-14,"y":1,"z":6},"block_id":106,"extra_data":{},"rotate":{"x":0,"y":0,"z":0}},{"move":{"x":-14,"y":1,"z":7},"block_id":8},{"move":{"x":-14,"y":1,"z":8},"block_id":106,"extra_data":{},"rotate":{"x":0,"y":0,"z":0}},{"move":{"x":-14,"y":1,"z":25},"block_id":8},{"move":{"x":-14,"y":1,"z":27},"block_id":8},{"move":{"x":-14,"y":1,"z":28},"block_id":106,"extra_data":{},"rotate":{"x":0,"y":0,"z":0}},{"move":{"x":-14,"y":2,"z":5},"block_id":8},{"move":{"x":-14,"y":2,"z":7},"block_id":8},{"move":{"x":-14,"y":2,"z":8},"block_id":106,"extra_data":{},"rotate":{"x":0,"y":0,"z":0}},{"move":{"x":-14,"y":2,"z":25},"block_id":8},{"move":{"x":-14,"y":2,"z":27},"block_id":8},{"move":{"x":-14,"y":2,"z":28},"block_id":106,"extra_data":{},"rotate":{"x":0,"y":0,"z":0}},{"move":{"x":-14,"y":3,"z":4},"block_id":106,"extra_data":{},"rotate":{"x":2,"y":0,"z":0}},{"move":{"x":-14,"y":3,"z":5},"block_id":8},{"move":{"x":-14,"y":3,"z":6},"block_id":106,"extra_data":{},"rotate":{"x":2,"y":0,"z":0}},{"move":{"x":-14,"y":3,"z":7},"block_id":146},{"move":{"x":-14,"y":3,"z":8},"block_id":106,"extra_data":{},"rotate":{"x":0,"y":0,"z":0}},{"move":{"x":-14,"y":3,"z":24},"block_id":106,"extra_data":{},"rotate":{"x":2,"y":0,"z":0}},{"move":{"x":-14,"y":3,"z":25},"block_id":8},{"move":{"x":-14,"y":3,"z":27},"block_id":8},{"move":{"x":-14,"y":3,"z":28},"block_id":106,"extra_data":{},"rotate":{"x":0,"y":0,"z":0}},{"move":{"x":-14,"y":4,"z":5},"block_id":8},{"move":{"x":-14,"y":4,"z":6},"block_id":106,"extra_data":{},"rotate":{"x":2,"y":0,"z":0}},{"move":{"x":-14,"y":4,"z":7},"block_id":8},{"move":{"x":-14,"y":4,"z":8},"block_id":106,"extra_data":{},"rotate":{"x":0,"y":0,"z":0}},{"move":{"x":-14,"y":4,"z":24},"block_id":106,"extra_data":{},"rotate":{"x":2,"y":0,"z":0}},{"move":{"x":-14,"y":4,"z":25},"block_id":8},{"move":{"x":-14,"y":4,"z":27},"block_id":8},{"move":{"x":-14,"y":4,"z":28},"block_id":106,"extra_data":{},"rotate":{"x":0,"y":0,"z":0}},{"move":{"x":-14,"y":5,"z":5},"block_id":8},{"move":{"x":-14,"y":5,"z":6},"block_id":106,"extra_data":{},"rotate":{"x":0,"y":0,"z":0}},{"move":{"x":-14,"y":5,"z":7},"block_id":8},{"move":{"x":-14,"y":5,"z":24},"block_id":106,"extra_data":{},"rotate":{"x":2,"y":0,"z":0}},{"move":{"x":-14,"y":5,"z":25},"block_id":8},{"move":{"x":-14,"y":5,"z":27},"block_id":8},{"move":{"x":-14,"y":5,"z":28},"block_id":106,"extra_data":{},"rotate":{"x":0,"y":0,"z":0}},{"move":{"x":-14,"y":6,"z":5},"block_id":67,"extra_data":{"point":{"x":0,"y":0.1,"z":0}},"rotate":{"x":3,"y":0,"z":0}},{"move":{"x":-14,"y":6,"z":6},"block_id":106,"extra_data":{},"rotate":{"x":1,"y":0,"z":0}},{"move":{"x":-14,"y":6,"z":7},"block_id":67,"extra_data":{"point":{"x":0,"y":0.1,"z":0}},"rotate":{"x":3,"y":0,"z":0}},{"move":{"x":-14,"y":6,"z":25},"block_id":8},{"move":{"x":-14,"y":6,"z":27},"block_id":8},{"move":{"x":-14,"y":6,"z":28},"block_id":106,"extra_data":{},"rotate":{"x":0,"y":0,"z":0}},{"move":{"x":-14,"y":7,"z":6},"block_id":106,"extra_data":{},"rotate":{"x":1,"y":0,"z":0}},{"move":{"x":-14,"y":10,"z":5},"block_id":106,"extra_data":{},"rotate":{"x":1,"y":0,"z":0}},{"move":{"x":-14,"y":11,"z":5},"block_id":106,"extra_data":{},"rotate":{"x":1,"y":0,"z":0}},{"move":{"x":-14,"y":12,"z":5},"block_id":106,"extra_data":{},"rotate":{"x":1,"y":0,"z":0}},{"move":{"x":-13,"y":-1,"z":4},"block_id":2},{"move":{"x":-13,"y":-1,"z":5},"block_id":18},{"move":{"x":-13,"y":-1,"z":6},"block_id":18},{"move":{"x":-13,"y":-1,"z":7},"block_id":18},{"move":{"x":-13,"y":-1,"z":8},"block_id":2},{"move":{"x":-13,"y":-1,"z":24},"block_id":2},{"move":{"x":-13,"y":-1,"z":25},"block_id":18},{"move":{"x":-13,"y":-1,"z":26},"block_id":18},{"move":{"x":-13,"y":-1,"z":27},"block_id":18},{"move":{"x":-13,"y":-1,"z":28},"block_id":2},{"move":{"x":-13,"y":0,"z":4},"block_id":106,"extra_data":{},"rotate":{"x":2,"y":0,"z":0}},{"move":{"x":-13,"y":0,"z":5},"block_id":8},{"move":{"x":-13,"y":0,"z":6},"block_id":8},{"move":{"x":-13,"y":0,"z":7},"block_id":146},{"move":{"x":-13,"y":0,"z":8},"block_id":106,"extra_data":{},"rotate":{"x":0,"y":0,"z":0}},{"move":{"x":-13,"y":0,"z":24},"block_id":106,"extra_data":{},"rotate":{"x":2,"y":0,"z":0}},{"move":{"x":-13,"y":0,"z":25},"block_id":8},{"move":{"x":-13,"y":0,"z":26},"block_id":8},{"move":{"x":-13,"y":0,"z":27},"block_id":8},{"move":{"x":-13,"y":0,"z":28},"block_id":106,"extra_data":{},"rotate":{"x":0,"y":0,"z":0}},{"move":{"x":-13,"y":1,"z":4},"block_id":106,"extra_data":{},"rotate":{"x":2,"y":0,"z":0}},{"move":{"x":-13,"y":1,"z":5},"block_id":8},{"move":{"x":-13,"y":1,"z":6},"block_id":8},{"move":{"x":-13,"y":1,"z":7},"block_id":8},{"move":{"x":-13,"y":1,"z":8},"block_id":106,"extra_data":{},"rotate":{"x":0,"y":0,"z":0}},{"move":{"x":-13,"y":1,"z":24},"block_id":106,"extra_data":{},"rotate":{"x":2,"y":0,"z":0}},{"move":{"x":-13,"y":1,"z":25},"block_id":98},{"move":{"x":-13,"y":1,"z":26},"block_id":98},{"move":{"x":-13,"y":1,"z":27},"block_id":98},{"move":{"x":-13,"y":1,"z":28},"block_id":106,"extra_data":{},"rotate":{"x":0,"y":0,"z":0}},{"move":{"x":-13,"y":2,"z":4},"block_id":106,"extra_data":{},"rotate":{"x":2,"y":0,"z":0}},{"move":{"x":-13,"y":2,"z":5},"block_id":83},{"move":{"x":-13,"y":2,"z":6},"block_id":632},{"move":{"x":-13,"y":2,"z":7},"block_id":83},{"move":{"x":-13,"y":2,"z":8},"block_id":106,"extra_data":{},"rotate":{"x":0,"y":0,"z":0}},{"move":{"x":-13,"y":2,"z":25},"block_id":8},{"move":{"x":-13,"y":2,"z":26},"block_id":8},{"move":{"x":-13,"y":2,"z":27},"block_id":8},{"move":{"x":-13,"y":2,"z":28},"block_id":106,"extra_data":{},"rotate":{"x":0,"y":0,"z":0}},{"move":{"x":-13,"y":3,"z":4},"block_id":106,"extra_data":{},"rotate":{"x":2,"y":0,"z":0}},{"move":{"x":-13,"y":3,"z":5},"block_id":98},{"move":{"x":-13,"y":3,"z":6},"block_id":83},{"move":{"x":-13,"y":3,"z":7},"block_id":98},{"move":{"x":-13,"y":3,"z":8},"block_id":106,"extra_data":{},"rotate":{"x":0,"y":0,"z":0}},{"move":{"x":-13,"y":3,"z":25},"block_id":98},{"move":{"x":-13,"y":3,"z":26},"block_id":98},{"move":{"x":-13,"y":3,"z":27},"block_id":98},{"move":{"x":-13,"y":3,"z":28},"block_id":106,"extra_data":{},"rotate":{"x":0,"y":0,"z":0}},{"move":{"x":-13,"y":4,"z":4},"block_id":106,"extra_data":{},"rotate":{"x":2,"y":0,"z":0}},{"move":{"x":-13,"y":4,"z":5},"block_id":98},{"move":{"x":-13,"y":4,"z":6},"block_id":85},{"move":{"x":-13,"y":4,"z":7},"block_id":98},{"move":{"x":-13,"y":4,"z":8},"block_id":106,"extra_data":{},"rotate":{"x":0,"y":0,"z":0}},{"move":{"x":-13,"y":4,"z":25},"block_id":98},{"move":{"x":-13,"y":4,"z":26},"block_id":98},{"move":{"x":-13,"y":4,"z":27},"block_id":98},{"move":{"x":-13,"y":5,"z":4},"block_id":106,"extra_data":{},"rotate":{"x":2,"y":0,"z":0}},{"move":{"x":-13,"y":5,"z":5},"block_id":98},{"move":{"x":-13,"y":5,"z":6},"block_id":98},{"move":{"x":-13,"y":5,"z":7},"block_id":98},{"move":{"x":-13,"y":5,"z":25},"block_id":98},{"move":{"x":-13,"y":5,"z":26},"block_id":98},{"move":{"x":-13,"y":5,"z":27},"block_id":98},{"move":{"x":-13,"y":6,"z":5},"block_id":8},{"move":{"x":-13,"y":6,"z":6},"block_id":8},{"move":{"x":-13,"y":6,"z":7},"block_id":8},{"move":{"x":-13,"y":6,"z":8},"block_id":106,"extra_data":{},"rotate":{"x":0,"y":0,"z":0}},{"move":{"x":-13,"y":6,"z":25},"block_id":98},{"move":{"x":-13,"y":6,"z":26},"block_id":8},{"move":{"x":-13,"y":6,"z":27},"block_id":98},{"move":{"x":-13,"y":7,"z":5},"block_id":98},{"move":{"x":-13,"y":7,"z":6},"block_id":83},{"move":{"x":-13,"y":7,"z":7},"block_id":98},{"move":{"x":-13,"y":7,"z":8},"block_id":106,"extra_data":{},"rotate":{"x":0,"y":0,"z":0}},{"move":{"x":-13,"y":7,"z":25},"block_id":8},{"move":{"x":-13,"y":7,"z":26},"block_id":8},{"move":{"x":-13,"y":7,"z":27},"block_id":8},{"move":{"x":-13,"y":8,"z":4},"block_id":106,"extra_data":{},"rotate":{"x":2,"y":0,"z":0}},{"move":{"x":-13,"y":8,"z":5},"block_id":632},{"move":{"x":-13,"y":8,"z":6},"block_id":85},{"move":{"x":-13,"y":8,"z":7},"block_id":98},{"move":{"x":-13,"y":8,"z":25},"block_id":8},{"move":{"x":-13,"y":8,"z":27},"block_id":98},{"move":{"x":-13,"y":9,"z":5},"block_id":8},{"move":{"x":-13,"y":9,"z":6},"block_id":146},{"move":{"x":-13,"y":9,"z":7},"block_id":8},{"move":{"x":-13,"y":9,"z":25},"block_id":8},{"move":{"x":-13,"y":9,"z":27},"block_id":8},{"move":{"x":-13,"y":10,"z":5},"block_id":83},{"move":{"x":-13,"y":10,"z":6},"block_id":98},{"move":{"x":-13,"y":10,"z":7},"block_id":632},{"move":{"x":-13,"y":11,"z":4},"block_id":106,"extra_data":{},"rotate":{"x":2,"y":0,"z":0}},{"move":{"x":-13,"y":11,"z":5},"block_id":83},{"move":{"x":-13,"y":11,"z":6},"block_id":632},{"move":{"x":-13,"y":11,"z":7},"block_id":83},{"move":{"x":-13,"y":12,"z":4},"block_id":106,"extra_data":{},"rotate":{"x":2,"y":0,"z":0}},{"move":{"x":-13,"y":12,"z":5},"block_id":98},{"move":{"x":-13,"y":12,"z":6},"block_id":98},{"move":{"x":-13,"y":12,"z":7},"block_id":83},{"move":{"x":-13,"y":13,"z":4},"block_id":106,"extra_data":{},"rotate":{"x":2,"y":0,"z":0}},{"move":{"x":-13,"y":13,"z":5},"block_id":98},{"move":{"x":-13,"y":13,"z":6},"block_id":632},{"move":{"x":-13,"y":13,"z":7},"block_id":98},{"move":{"x":-13,"y":14,"z":4},"block_id":106,"extra_data":{},"rotate":{"x":2,"y":0,"z":0}},{"move":{"x":-13,"y":14,"z":5},"block_id":8},{"move":{"x":-13,"y":14,"z":6},"block_id":98},{"move":{"x":-13,"y":14,"z":7},"block_id":8},{"move":{"x":-13,"y":14,"z":8},"block_id":106,"extra_data":{},"rotate":{"x":0,"y":0,"z":0}},{"move":{"x":-13,"y":15,"z":4},"block_id":106,"extra_data":{},"rotate":{"x":2,"y":0,"z":0}},{"move":{"x":-13,"y":15,"z":5},"block_id":8},{"move":{"x":-13,"y":15,"z":7},"block_id":146},{"move":{"x":-13,"y":15,"z":8},"block_id":106,"extra_data":{},"rotate":{"x":0,"y":0,"z":0}},{"move":{"x":-13,"y":16,"z":5},"block_id":67,"extra_data":{"point":{"x":0,"y":0.1,"z":0}},"rotate":{"x":3,"y":0,"z":0}},{"move":{"x":-13,"y":16,"z":7},"block_id":67,"extra_data":{"point":{"x":0,"y":0.1,"z":0}},"rotate":{"x":3,"y":0,"z":0}},{"move":{"x":-12,"y":-1,"z":3},"block_id":2},{"move":{"x":-12,"y":-1,"z":4},"block_id":18},{"move":{"x":-12,"y":-1,"z":5},"block_id":18},{"move":{"x":-12,"y":-1,"z":6},"block_id":18},{"move":{"x":-12,"y":-1,"z":7},"block_id":18},{"move":{"x":-12,"y":-1,"z":8},"block_id":18},{"move":{"x":-12,"y":-1,"z":9},"block_id":2},{"move":{"x":-12,"y":-1,"z":23},"block_id":2},{"move":{"x":-12,"y":-1,"z":24},"block_id":18},{"move":{"x":-12,"y":-1,"z":25},"block_id":18},{"move":{"x":-12,"y":-1,"z":26},"block_id":18},{"move":{"x":-12,"y":-1,"z":27},"block_id":18},{"move":{"x":-12,"y":-1,"z":28},"block_id":18},{"move":{"x":-12,"y":-1,"z":29},"block_id":2},{"move":{"x":-12,"y":0,"z":4},"block_id":8},{"move":{"x":-12,"y":0,"z":5},"block_id":8},{"move":{"x":-12,"y":0,"z":6},"block_id":8},{"move":{"x":-12,"y":0,"z":7},"block_id":8},{"move":{"x":-12,"y":0,"z":8},"block_id":8},{"move":{"x":-12,"y":0,"z":9},"block_id":106,"extra_data":{},"rotate":{"x":0,"y":0,"z":0}},{"move":{"x":-12,"y":0,"z":24},"block_id":8},{"move":{"x":-12,"y":0,"z":25},"block_id":8},{"move":{"x":-12,"y":0,"z":26},"block_id":146},{"move":{"x":-12,"y":0,"z":27},"block_id":8},{"move":{"x":-12,"y":0,"z":28},"block_id":146},{"move":{"x":-12,"y":1,"z":3},"block_id":85},{"move":{"x":-12,"y":1,"z":4},"block_id":8},{"move":{"x":-12,"y":1,"z":7},"block_id":65,"rotate":{"x":1,"y":0,"z":0}},{"move":{"x":-12,"y":1,"z":8},"block_id":8},{"move":{"x":-12,"y":1,"z":24},"block_id":8},{"move":{"x":-12,"y":1,"z":25},"block_id":106,"extra_data":{},"rotate":{"x":0,"y":0,"z":0}},{"move":{"x":-12,"y":1,"z":27},"block_id":106,"extra_data":{},"rotate":{"x":2,"y":0,"z":0}},{"move":{"x":-12,"y":1,"z":28},"block_id":8},{"move":{"x":-12,"y":1,"z":29},"block_id":106,"extra_data":{},"rotate":{"x":1,"y":0,"z":0}},{"move":{"x":-12,"y":2,"z":3},"block_id":85},{"move":{"x":-12,"y":2,"z":4},"block_id":98},{"move":{"x":-12,"y":2,"z":7},"block_id":65,"rotate":{"x":1,"y":0,"z":0}},{"move":{"x":-12,"y":2,"z":8},"block_id":632},{"move":{"x":-12,"y":2,"z":23},"block_id":85},{"move":{"x":-12,"y":2,"z":24},"block_id":8},{"move":{"x":-12,"y":2,"z":25},"block_id":106,"extra_data":{},"rotate":{"x":0,"y":0,"z":0}},{"move":{"x":-12,"y":2,"z":28},"block_id":8},{"move":{"x":-12,"y":2,"z":29},"block_id":85},{"move":{"x":-12,"y":3,"z":3},"block_id":85},{"move":{"x":-12,"y":3,"z":4},"block_id":83},{"move":{"x":-12,"y":3,"z":5},"block_id":106,"extra_data":{},"rotate":{"x":0,"y":0,"z":0}},{"move":{"x":-12,"y":3,"z":7},"block_id":65,"rotate":{"x":1,"y":0,"z":0}},{"move":{"x":-12,"y":3,"z":8},"block_id":83},{"move":{"x":-12,"y":3,"z":23},"block_id":106,"extra_data":{},"rotate":{"x":2,"y":0,"z":0}},{"move":{"x":-12,"y":3,"z":24},"block_id":98},{"move":{"x":-12,"y":3,"z":25},"block_id":106,"extra_data":{},"rotate":{"x":0,"y":0,"z":0}},{"move":{"x":-12,"y":3,"z":27},"block_id":106,"extra_data":{},"rotate":{"x":2,"y":0,"z":0}},{"move":{"x":-12,"y":3,"z":28},"block_id":98},{"move":{"x":-12,"y":3,"z":29},"block_id":106,"extra_data":{},"rotate":{"x":1,"y":0,"z":0}},{"move":{"x":-12,"y":4,"z":3},"block_id":85},{"move":{"x":-12,"y":4,"z":4},"block_id":83},{"move":{"x":-12,"y":4,"z":7},"block_id":65,"rotate":{"x":1,"y":0,"z":0}},{"move":{"x":-12,"y":4,"z":8},"block_id":98},{"move":{"x":-12,"y":4,"z":23},"block_id":106,"extra_data":{},"rotate":{"x":2,"y":0,"z":0}},{"move":{"x":-12,"y":4,"z":24},"block_id":98},{"move":{"x":-12,"y":4,"z":25},"block_id":106,"extra_data":{},"rotate":{"x":0,"y":0,"z":0}},{"move":{"x":-12,"y":4,"z":27},"block_id":106,"extra_data":{},"rotate":{"x":2,"y":0,"z":0}},{"move":{"x":-12,"y":4,"z":28},"block_id":98},{"move":{"x":-12,"y":4,"z":29},"block_id":106,"extra_data":{},"rotate":{"x":1,"y":0,"z":0}},{"move":{"x":-12,"y":5,"z":3},"block_id":85},{"move":{"x":-12,"y":5,"z":4},"block_id":83},{"move":{"x":-12,"y":5,"z":6},"block_id":50,"rotate":{"x":1,"y":0,"z":0}},{"move":{"x":-12,"y":5,"z":7},"block_id":65,"rotate":{"x":1,"y":0,"z":0}},{"move":{"x":-12,"y":5,"z":8},"block_id":98},{"move":{"x":-12,"y":5,"z":23},"block_id":106,"extra_data":{},"rotate":{"x":2,"y":0,"z":0}},{"move":{"x":-12,"y":5,"z":24},"block_id":98},{"move":{"x":-12,"y":5,"z":25},"block_id":106,"extra_data":{},"rotate":{"x":0,"y":0,"z":0}},{"move":{"x":-12,"y":5,"z":27},"block_id":106,"extra_data":{},"rotate":{"x":2,"y":0,"z":0}},{"move":{"x":-12,"y":5,"z":28},"block_id":98},{"move":{"x":-12,"y":5,"z":29},"block_id":106,"extra_data":{},"rotate":{"x":1,"y":0,"z":0}},{"move":{"x":-12,"y":6,"z":3},"block_id":85},{"move":{"x":-12,"y":6,"z":4},"block_id":146},{"move":{"x":-12,"y":6,"z":5},"block_id":7},{"move":{"x":-12,"y":6,"z":6},"block_id":7},{"move":{"x":-12,"y":6,"z":7},"block_id":65,"rotate":{"x":1,"y":0,"z":0}},{"move":{"x":-12,"y":6,"z":8},"block_id":8},{"move":{"x":-12,"y":6,"z":23},"block_id":106,"extra_data":{},"rotate":{"x":2,"y":0,"z":0}},{"move":{"x":-12,"y":6,"z":24},"block_id":98},{"move":{"x":-12,"y":6,"z":27},"block_id":106,"extra_data":{},"rotate":{"x":2,"y":0,"z":0}},{"move":{"x":-12,"y":6,"z":28},"block_id":98},{"move":{"x":-12,"y":7,"z":3},"block_id":85},{"move":{"x":-12,"y":7,"z":4},"block_id":98},{"move":{"x":-12,"y":7,"z":5},"block_id":58,"rotate":{"x":2,"y":1,"z":0}},{"move":{"x":-12,"y":7,"z":6},"block_id":58,"rotate":{"x":2,"y":1,"z":0}},{"move":{"x":-12,"y":7,"z":7},"block_id":65,"rotate":{"x":1,"y":0,"z":0}},{"move":{"x":-12,"y":7,"z":8},"block_id":98},{"move":{"x":-12,"y":7,"z":9},"block_id":106,"extra_data":{},"rotate":{"x":0,"y":0,"z":0}},{"move":{"x":-12,"y":7,"z":23},"block_id":106,"extra_data":{},"rotate":{"x":1,"y":0,"z":0}},{"move":{"x":-12,"y":7,"z":24},"block_id":98},{"move":{"x":-12,"y":7,"z":27},"block_id":106,"extra_data":{},"rotate":{"x":2,"y":0,"z":0}},{"move":{"x":-12,"y":7,"z":28},"block_id":8},{"move":{"x":-12,"y":7,"z":29},"block_id":106,"extra_data":{},"rotate":{"x":1,"y":0,"z":0}},{"move":{"x":-12,"y":8,"z":3},"block_id":85},{"move":{"x":-12,"y":8,"z":4},"block_id":98},{"move":{"x":-12,"y":8,"z":7},"block_id":65,"rotate":{"x":1,"y":0,"z":0}},{"move":{"x":-12,"y":8,"z":8},"block_id":632},{"move":{"x":-12,"y":8,"z":9},"block_id":106,"extra_data":{},"rotate":{"x":0,"y":0,"z":0}},{"move":{"x":-12,"y":8,"z":24},"block_id":83},{"move":{"x":-12,"y":8,"z":28},"block_id":98},{"move":{"x":-12,"y":9,"z":3},"block_id":85},{"move":{"x":-12,"y":9,"z":4},"block_id":8},{"move":{"x":-12,"y":9,"z":7},"block_id":65,"rotate":{"x":1,"y":0,"z":0}},{"move":{"x":-12,"y":9,"z":8},"block_id":67,"extra_data":{"point":{"x":0,"y":0.9,"z":0}},"rotate":{"x":0,"y":0,"z":0}},{"move":{"x":-12,"y":9,"z":27},"block_id":106,"extra_data":{},"rotate":{"x":2,"y":0,"z":0}},{"move":{"x":-12,"y":9,"z":28},"block_id":8},{"move":{"x":-12,"y":10,"z":3},"block_id":85},{"move":{"x":-12,"y":10,"z":4},"block_id":83},{"move":{"x":-12,"y":10,"z":5},"block_id":7},{"move":{"x":-12,"y":10,"z":6},"block_id":53,"extra_data":{"point":{"x":0,"y":0.9,"z":0}},"rotate":{"x":0,"y":0,"z":0}},{"move":{"x":-12,"y":10,"z":7},"block_id":65,"rotate":{"x":1,"y":0,"z":0}},{"move":{"x":-12,"y":10,"z":8},"block_id":98},{"move":{"x":-12,"y":10,"z":28},"block_id":98},{"move":{"x":-12,"y":11,"z":3},"block_id":85},{"move":{"x":-12,"y":11,"z":4},"block_id":98},{"move":{"x":-12,"y":11,"z":7},"block_id":65,"rotate":{"x":1,"y":0,"z":0}},{"move":{"x":-12,"y":11,"z":8},"block_id":83},{"move":{"x":-12,"y":11,"z":9},"block_id":106,"extra_data":{},"rotate":{"x":0,"y":0,"z":0}},{"move":{"x":-12,"y":12,"z":3},"block_id":85},{"move":{"x":-12,"y":12,"z":4},"block_id":98},{"move":{"x":-12,"y":12,"z":8},"block_id":83},{"move":{"x":-12,"y":12,"z":9},"block_id":106,"extra_data":{},"rotate":{"x":0,"y":0,"z":0}},{"move":{"x":-12,"y":13,"z":3},"block_id":85},{"move":{"x":-12,"y":13,"z":4},"block_id":83},{"move":{"x":-12,"y":13,"z":5},"block_id":7},{"move":{"x":-12,"y":13,"z":6},"block_id":7},{"move":{"x":-12,"y":13,"z":7},"block_id":7},{"move":{"x":-12,"y":13,"z":8},"block_id":98},{"move":{"x":-12,"y":13,"z":9},"block_id":106,"extra_data":{},"rotate":{"x":0,"y":0,"z":0}},{"move":{"x":-12,"y":14,"z":3},"block_id":85},{"move":{"x":-12,"y":14,"z":4},"block_id":98},{"move":{"x":-12,"y":14,"z":5},"block_id":146},{"move":{"x":-12,"y":14,"z":7},"block_id":8},{"move":{"x":-12,"y":14,"z":8},"block_id":101,"extra_data":{"point":{"x":0,"y":0.1,"z":0}}},{"move":{"x":-12,"y":15,"z":3},"block_id":85},{"move":{"x":-12,"y":15,"z":4},"block_id":85},{"move":{"x":-12,"y":15,"z":5},"block_id":8},{"move":{"x":-12,"y":15,"z":7},"block_id":67,"extra_data":{"point":{"x":0,"y":0.1,"z":0}},"rotate":{"x":3,"y":0,"z":0}},{"move":{"x":-12,"y":16,"z":5},"block_id":67,"extra_data":{"point":{"x":0,"y":0.1,"z":0}},"rotate":{"x":1,"y":0,"z":0}},{"move":{"x":-12,"y":16,"z":7},"block_id":67,"extra_data":{"point":{"x":0,"y":0.1,"z":0}},"rotate":{"x":1,"y":0,"z":0}},{"move":{"x":-11,"y":-1,"z":1},"block_id":2},{"move":{"x":-11,"y":-1,"z":2},"block_id":2},{"move":{"x":-11,"y":-1,"z":3},"block_id":18},{"move":{"x":-11,"y":-1,"z":4},"block_id":18},{"move":{"x":-11,"y":-1,"z":5},"block_id":18},{"move":{"x":-11,"y":-1,"z":6},"block_id":18},{"move":{"x":-11,"y":-1,"z":7},"block_id":18},{"move":{"x":-11,"y":-1,"z":8},"block_id":18},{"move":{"x":-11,"y":-1,"z":9},"block_id":18},{"move":{"x":-11,"y":-1,"z":10},"block_id":2},{"move":{"x":-11,"y":-1,"z":11},"block_id":2},{"move":{"x":-11,"y":-1,"z":12},"block_id":2},{"move":{"x":-11,"y":-1,"z":13},"block_id":2},{"move":{"x":-11,"y":-1,"z":14},"block_id":2},{"move":{"x":-11,"y":-1,"z":15},"block_id":2},{"move":{"x":-11,"y":-1,"z":16},"block_id":2},{"move":{"x":-11,"y":-1,"z":17},"block_id":2},{"move":{"x":-11,"y":-1,"z":18},"block_id":2},{"move":{"x":-11,"y":-1,"z":19},"block_id":2},{"move":{"x":-11,"y":-1,"z":20},"block_id":2},{"move":{"x":-11,"y":-1,"z":21},"block_id":2},{"move":{"x":-11,"y":-1,"z":22},"block_id":2},{"move":{"x":-11,"y":-1,"z":23},"block_id":2},{"move":{"x":-11,"y":-1,"z":24},"block_id":18},{"move":{"x":-11,"y":-1,"z":25},"block_id":18},{"move":{"x":-11,"y":-1,"z":26},"block_id":18},{"move":{"x":-11,"y":-1,"z":27},"block_id":18},{"move":{"x":-11,"y":-1,"z":28},"block_id":18},{"move":{"x":-11,"y":-1,"z":29},"block_id":18},{"move":{"x":-11,"y":-1,"z":30},"block_id":2},{"move":{"x":-11,"y":-1,"z":31},"block_id":2},{"move":{"x":-11,"y":0,"z":3},"block_id":146},{"move":{"x":-11,"y":0,"z":4},"block_id":8},{"move":{"x":-11,"y":0,"z":5},"block_id":8},{"move":{"x":-11,"y":0,"z":6},"block_id":8},{"move":{"x":-11,"y":0,"z":7},"block_id":146},{"move":{"x":-11,"y":0,"z":8},"block_id":8},{"move":{"x":-11,"y":0,"z":9},"block_id":8},{"move":{"x":-11,"y":0,"z":11},"block_id":106,"extra_data":{},"rotate":{"x":1,"y":0,"z":0}},{"move":{"x":-11,"y":0,"z":14},"block_id":106,"extra_data":{},"rotate":{"x":1,"y":0,"z":0}},{"move":{"x":-11,"y":0,"z":15},"block_id":106,"extra_data":{},"rotate":{"x":1,"y":0,"z":0}},{"move":{"x":-11,"y":0,"z":19},"block_id":106,"extra_data":{},"rotate":{"x":1,"y":0,"z":0}},{"move":{"x":-11,"y":0,"z":20},"block_id":106,"extra_data":{},"rotate":{"x":1,"y":0,"z":0}},{"move":{"x":-11,"y":0,"z":21},"block_id":106,"extra_data":{},"rotate":{"x":1,"y":0,"z":0}},{"move":{"x":-11,"y":0,"z":22},"block_id":106,"extra_data":{},"rotate":{"x":2,"y":0,"z":0}},{"move":{"x":-11,"y":0,"z":23},"block_id":67,"extra_data":{"point":{"x":0,"y":0.1,"z":0}},"rotate":{"x":2,"y":0,"z":0}},{"move":{"x":-11,"y":0,"z":24},"block_id":8},{"move":{"x":-11,"y":0,"z":25},"block_id":146},{"move":{"x":-11,"y":0,"z":26},"block_id":8},{"move":{"x":-11,"y":0,"z":27},"block_id":8},{"move":{"x":-11,"y":0,"z":28},"block_id":8},{"move":{"x":-11,"y":0,"z":29},"block_id":8},{"move":{"x":-11,"y":0,"z":30},"block_id":106,"extra_data":{},"rotate":{"x":1,"y":0,"z":0}},{"move":{"x":-11,"y":1,"z":2},"block_id":106,"extra_data":{},"rotate":{"x":1,"y":0,"z":0}},{"move":{"x":-11,"y":1,"z":3},"block_id":8},{"move":{"x":-11,"y":1,"z":8},"block_id":106,"extra_data":{},"rotate":{"x":2,"y":0,"z":0}},{"move":{"x":-11,"y":1,"z":9},"block_id":146},{"move":{"x":-11,"y":1,"z":10},"block_id":106,"extra_data":{},"rotate":{"x":0,"y":0,"z":0}},{"move":{"x":-11,"y":1,"z":11},"block_id":106,"extra_data":{},"rotate":{"x":1,"y":0,"z":0}},{"move":{"x":-11,"y":1,"z":14},"block_id":106,"extra_data":{},"rotate":{"x":1,"y":0,"z":0}},{"move":{"x":-11,"y":1,"z":15},"block_id":106,"extra_data":{},"rotate":{"x":1,"y":0,"z":0}},{"move":{"x":-11,"y":1,"z":17},"block_id":106,"extra_data":{},"rotate":{"x":1,"y":0,"z":0}},{"move":{"x":-11,"y":1,"z":19},"block_id":106,"extra_data":{},"rotate":{"x":1,"y":0,"z":0}},{"move":{"x":-11,"y":1,"z":20},"block_id":106,"extra_data":{},"rotate":{"x":1,"y":0,"z":0}},{"move":{"x":-11,"y":1,"z":21},"block_id":106,"extra_data":{},"rotate":{"x":1,"y":0,"z":0}},{"move":{"x":-11,"y":1,"z":22},"block_id":106,"extra_data":{},"rotate":{"x":1,"y":0,"z":0}},{"move":{"x":-11,"y":1,"z":23},"block_id":98},{"move":{"x":-11,"y":1,"z":28},"block_id":106,"extra_data":{},"rotate":{"x":3,"y":0,"z":0}},{"move":{"x":-11,"y":1,"z":29},"block_id":98},{"move":{"x":-11,"y":2,"z":2},"block_id":106,"extra_data":{},"rotate":{"x":1,"y":0,"z":0}},{"move":{"x":-11,"y":2,"z":3},"block_id":98},{"move":{"x":-11,"y":2,"z":8},"block_id":106,"extra_data":{},"rotate":{"x":2,"y":0,"z":0}},{"move":{"x":-11,"y":2,"z":9},"block_id":98},{"move":{"x":-11,"y":2,"z":15},"block_id":106,"extra_data":{},"rotate":{"x":1,"y":0,"z":0}},{"move":{"x":-11,"y":2,"z":17},"block_id":106,"extra_data":{},"rotate":{"x":1,"y":0,"z":0}},{"move":{"x":-11,"y":2,"z":19},"block_id":106,"extra_data":{},"rotate":{"x":1,"y":0,"z":0}},{"move":{"x":-11,"y":2,"z":22},"block_id":106,"extra_data":{},"rotate":{"x":1,"y":0,"z":0}},{"move":{"x":-11,"y":2,"z":23},"block_id":8},{"move":{"x":-11,"y":2,"z":24},"block_id":106,"extra_data":{},"rotate":{"x":0,"y":0,"z":0}},{"move":{"x":-11,"y":2,"z":28},"block_id":106,"extra_data":{},"rotate":{"x":3,"y":0,"z":0}},{"move":{"x":-11,"y":2,"z":29},"block_id":8},{"move":{"x":-11,"y":3,"z":3},"block_id":98},{"move":{"x":-11,"y":3,"z":9},"block_id":98},{"move":{"x":-11,"y":3,"z":12},"block_id":106,"extra_data":{},"rotate":{"x":1,"y":0,"z":0}},{"move":{"x":-11,"y":3,"z":14},"block_id":106,"extra_data":{},"rotate":{"x":1,"y":0,"z":0}},{"move":{"x":-11,"y":3,"z":17},"block_id":106,"extra_data":{},"rotate":{"x":1,"y":0,"z":0}},{"move":{"x":-11,"y":3,"z":18},"block_id":106,"extra_data":{},"rotate":{"x":1,"y":0,"z":0}},{"move":{"x":-11,"y":3,"z":20},"block_id":106,"extra_data":{},"rotate":{"x":1,"y":0,"z":0}},{"move":{"x":-11,"y":3,"z":21},"block_id":106,"extra_data":{},"rotate":{"x":1,"y":0,"z":0}},{"move":{"x":-11,"y":3,"z":22},"block_id":106,"extra_data":{},"rotate":{"x":1,"y":0,"z":0}},{"move":{"x":-11,"y":3,"z":23},"block_id":98},{"move":{"x":-11,"y":3,"z":24},"block_id":106,"extra_data":{},"rotate":{"x":0,"y":0,"z":0}},{"move":{"x":-11,"y":3,"z":28},"block_id":106,"extra_data":{},"rotate":{"x":3,"y":0,"z":0}},{"move":{"x":-11,"y":3,"z":29},"block_id":98},{"move":{"x":-11,"y":4,"z":2},"block_id":106,"extra_data":{},"rotate":{"x":1,"y":0,"z":0}},{"move":{"x":-11,"y":4,"z":3},"block_id":98},{"move":{"x":-11,"y":4,"z":9},"block_id":98},{"move":{"x":-11,"y":4,"z":12},"block_id":106,"extra_data":{},"rotate":{"x":1,"y":0,"z":0}},{"move":{"x":-11,"y":4,"z":14},"block_id":106,"extra_data":{},"rotate":{"x":1,"y":0,"z":0}},{"move":{"x":-11,"y":4,"z":20},"block_id":106,"extra_data":{},"rotate":{"x":1,"y":0,"z":0}},{"move":{"x":-11,"y":4,"z":22},"block_id":106,"extra_data":{},"rotate":{"x":1,"y":0,"z":0}},{"move":{"x":-11,"y":4,"z":23},"block_id":98},{"move":{"x":-11,"y":4,"z":24},"block_id":106,"extra_data":{},"rotate":{"x":0,"y":0,"z":0}},{"move":{"x":-11,"y":4,"z":28},"block_id":106,"extra_data":{},"rotate":{"x":3,"y":0,"z":0}},{"move":{"x":-11,"y":4,"z":29},"block_id":98},{"move":{"x":-11,"y":4,"z":30},"block_id":106,"extra_data":{},"rotate":{"x":1,"y":0,"z":0}},{"move":{"x":-11,"y":5,"z":2},"block_id":106,"extra_data":{},"rotate":{"x":1,"y":0,"z":0}},{"move":{"x":-11,"y":5,"z":3},"block_id":632},{"move":{"x":-11,"y":5,"z":9},"block_id":98},{"move":{"x":-11,"y":5,"z":10},"block_id":106,"extra_data":{},"rotate":{"x":0,"y":0,"z":0}},{"move":{"x":-11,"y":5,"z":11},"block_id":106,"extra_data":{},"rotate":{"x":1,"y":0,"z":0}},{"move":{"x":-11,"y":5,"z":14},"block_id":106,"extra_data":{},"rotate":{"x":1,"y":0,"z":0}},{"move":{"x":-11,"y":5,"z":19},"block_id":106,"extra_data":{},"rotate":{"x":1,"y":0,"z":0}},{"move":{"x":-11,"y":5,"z":22},"block_id":106,"extra_data":{},"rotate":{"x":1,"y":0,"z":0}},{"move":{"x":-11,"y":5,"z":23},"block_id":98},{"move":{"x":-11,"y":5,"z":24},"block_id":106,"extra_data":{},"rotate":{"x":0,"y":0,"z":0}},{"move":{"x":-11,"y":5,"z":28},"block_id":106,"extra_data":{},"rotate":{"x":3,"y":0,"z":0}},{"move":{"x":-11,"y":5,"z":29},"block_id":98},{"move":{"x":-11,"y":5,"z":30},"block_id":106,"extra_data":{},"rotate":{"x":1,"y":0,"z":0}},{"move":{"x":-11,"y":6,"z":2},"block_id":106,"extra_data":{},"rotate":{"x":1,"y":0,"z":0}},{"move":{"x":-11,"y":6,"z":3},"block_id":8},{"move":{"x":-11,"y":6,"z":4},"block_id":7},{"move":{"x":-11,"y":6,"z":5},"block_id":53,"extra_data":{"point":{"x":0,"y":0.9,"z":0}},"rotate":{"x":3,"y":0,"z":0}},{"move":{"x":-11,"y":6,"z":6},"block_id":7},{"move":{"x":-11,"y":6,"z":7},"block_id":7},{"move":{"x":-11,"y":6,"z":9},"block_id":98},{"move":{"x":-11,"y":6,"z":10},"block_id":106,"extra_data":{},"rotate":{"x":0,"y":0,"z":0}},{"move":{"x":-11,"y":6,"z":19},"block_id":106,"extra_data":{},"rotate":{"x":1,"y":0,"z":0}},{"move":{"x":-11,"y":6,"z":22},"block_id":106,"extra_data":{},"rotate":{"x":1,"y":0,"z":0}},{"move":{"x":-11,"y":6,"z":23},"block_id":98},{"move":{"x":-11,"y":6,"z":28},"block_id":106,"extra_data":{},"rotate":{"x":3,"y":0,"z":0}},{"move":{"x":-11,"y":6,"z":29},"block_id":98},{"move":{"x":-11,"y":6,"z":30},"block_id":106,"extra_data":{},"rotate":{"x":1,"y":0,"z":0}},{"move":{"x":-11,"y":7,"z":3},"block_id":98},{"move":{"x":-11,"y":7,"z":9},"block_id":8},{"move":{"x":-11,"y":7,"z":18},"block_id":106,"extra_data":{},"rotate":{"x":1,"y":0,"z":0}},{"move":{"x":-11,"y":7,"z":19},"block_id":106,"extra_data":{},"rotate":{"x":1,"y":0,"z":0}},{"move":{"x":-11,"y":7,"z":20},"block_id":106,"extra_data":{},"rotate":{"x":1,"y":0,"z":0}},{"move":{"x":-11,"y":7,"z":23},"block_id":98},{"move":{"x":-11,"y":7,"z":24},"block_id":106,"extra_data":{},"rotate":{"x":3,"y":0,"z":0}},{"move":{"x":-11,"y":7,"z":28},"block_id":106,"extra_data":{},"rotate":{"x":2,"y":0,"z":0}},{"move":{"x":-11,"y":7,"z":29},"block_id":8},{"move":{"x":-11,"y":7,"z":30},"block_id":106,"extra_data":{},"rotate":{"x":1,"y":0,"z":0}},{"move":{"x":-11,"y":8,"z":3},"block_id":98},{"move":{"x":-11,"y":8,"z":4},"block_id":106,"extra_data":{},"rotate":{"x":3,"y":0,"z":0}},{"move":{"x":-11,"y":8,"z":9},"block_id":98},{"move":{"x":-11,"y":8,"z":18},"block_id":106,"extra_data":{},"rotate":{"x":1,"y":0,"z":0}},{"move":{"x":-11,"y":8,"z":23},"block_id":98},{"move":{"x":-11,"y":8,"z":24},"block_id":106,"extra_data":{},"rotate":{"x":3,"y":0,"z":0}},{"move":{"x":-11,"y":8,"z":29},"block_id":98},{"move":{"x":-11,"y":9,"z":3},"block_id":8},{"move":{"x":-11,"y":9,"z":29},"block_id":8},{"move":{"x":-11,"y":10,"z":3},"block_id":83},{"move":{"x":-11,"y":10,"z":4},"block_id":7},{"move":{"x":-11,"y":10,"z":5},"block_id":7},{"move":{"x":-11,"y":10,"z":6},"block_id":7},{"move":{"x":-11,"y":10,"z":7},"block_id":7},{"move":{"x":-11,"y":10,"z":29},"block_id":98},{"move":{"x":-11,"y":11,"z":3},"block_id":98},{"move":{"x":-11,"y":11,"z":4},"block_id":106,"extra_data":{},"rotate":{"x":0,"y":0,"z":0}},{"move":{"x":-11,"y":11,"z":8},"block_id":106,"extra_data":{},"rotate":{"x":3,"y":0,"z":0}},{"move":{"x":-11,"y":12,"z":3},"block_id":98},{"move":{"x":-11,"y":12,"z":4},"block_id":106,"extra_data":{},"rotate":{"x":0,"y":0,"z":0}},{"move":{"x":-11,"y":12,"z":8},"block_id":106,"extra_data":{},"rotate":{"x":3,"y":0,"z":0}},{"move":{"x":-11,"y":13,"z":3},"block_id":83},{"move":{"x":-11,"y":13,"z":4},"block_id":7},{"move":{"x":-11,"y":13,"z":5},"block_id":7},{"move":{"x":-11,"y":13,"z":6},"block_id":7},{"move":{"x":-11,"y":13,"z":7},"block_id":7},{"move":{"x":-11,"y":13,"z":8},"block_id":106,"extra_data":{},"rotate":{"x":3,"y":0,"z":0}},{"move":{"x":-11,"y":14,"z":3},"block_id":98},{"move":{"x":-11,"y":14,"z":4},"block_id":85},{"move":{"x":-11,"y":15,"z":3},"block_id":85},{"move":{"x":-11,"y":15,"z":4},"block_id":85},{"move":{"x":-10,"y":-1,"z":0},"block_id":2},{"move":{"x":-10,"y":-1,"z":1},"block_id":18},{"move":{"x":-10,"y":-1,"z":2},"block_id":18},{"move":{"x":-10,"y":-1,"z":3},"block_id":18},{"move":{"x":-10,"y":-1,"z":4},"block_id":18},{"move":{"x":-10,"y":-1,"z":5},"block_id":18},{"move":{"x":-10,"y":-1,"z":6},"block_id":18},{"move":{"x":-10,"y":-1,"z":7},"block_id":18},{"move":{"x":-10,"y":-1,"z":8},"block_id":18},{"move":{"x":-10,"y":-1,"z":9},"block_id":18},{"move":{"x":-10,"y":-1,"z":10},"block_id":18},{"move":{"x":-10,"y":-1,"z":11},"block_id":18},{"move":{"x":-10,"y":-1,"z":12},"block_id":18},{"move":{"x":-10,"y":-1,"z":13},"block_id":18},{"move":{"x":-10,"y":-1,"z":14},"block_id":18},{"move":{"x":-10,"y":-1,"z":15},"block_id":18},{"move":{"x":-10,"y":-1,"z":16},"block_id":18},{"move":{"x":-10,"y":-1,"z":17},"block_id":18},{"move":{"x":-10,"y":-1,"z":18},"block_id":18},{"move":{"x":-10,"y":-1,"z":19},"block_id":18},{"move":{"x":-10,"y":-1,"z":20},"block_id":18},{"move":{"x":-10,"y":-1,"z":21},"block_id":2},{"move":{"x":-10,"y":-1,"z":22},"block_id":18},{"move":{"x":-10,"y":-1,"z":23},"block_id":18},{"move":{"x":-10,"y":-1,"z":24},"block_id":18},{"move":{"x":-10,"y":-1,"z":25},"block_id":18},{"move":{"x":-10,"y":-1,"z":26},"block_id":18},{"move":{"x":-10,"y":-1,"z":27},"block_id":18},{"move":{"x":-10,"y":-1,"z":28},"block_id":18},{"move":{"x":-10,"y":-1,"z":29},"block_id":18},{"move":{"x":-10,"y":-1,"z":30},"block_id":18},{"move":{"x":-10,"y":-1,"z":31},"block_id":2},{"move":{"x":-10,"y":-1,"z":32},"block_id":2},{"move":{"x":-10,"y":0,"z":0},"block_id":106,"extra_data":{},"rotate":{"x":2,"y":0,"z":0}},{"move":{"x":-10,"y":0,"z":1},"block_id":8},{"move":{"x":-10,"y":0,"z":2},"block_id":8},{"move":{"x":-10,"y":0,"z":3},"block_id":8},{"move":{"x":-10,"y":0,"z":4},"block_id":8},{"move":{"x":-10,"y":0,"z":5},"block_id":8},{"move":{"x":-10,"y":0,"z":6},"block_id":8},{"move":{"x":-10,"y":0,"z":7},"block_id":8},{"move":{"x":-10,"y":0,"z":8},"block_id":8},{"move":{"x":-10,"y":0,"z":9},"block_id":8},{"move":{"x":-10,"y":0,"z":10},"block_id":146},{"move":{"x":-10,"y":0,"z":11},"block_id":8},{"move":{"x":-10,"y":0,"z":12},"block_id":8},{"move":{"x":-10,"y":0,"z":13},"block_id":8},{"move":{"x":-10,"y":0,"z":14},"block_id":8},{"move":{"x":-10,"y":0,"z":15},"block_id":8},{"move":{"x":-10,"y":0,"z":16},"block_id":98},{"move":{"x":-10,"y":0,"z":17},"block_id":8},{"move":{"x":-10,"y":0,"z":18},"block_id":8},{"move":{"x":-10,"y":0,"z":19},"block_id":8},{"move":{"x":-10,"y":0,"z":20},"block_id":8},{"move":{"x":-10,"y":0,"z":21},"block_id":67,"extra_data":{"point":{"x":0,"y":0.1,"z":0}},"rotate":{"x":1,"y":0,"z":0}},{"move":{"x":-10,"y":0,"z":22},"block_id":8},{"move":{"x":-10,"y":0,"z":23},"block_id":8},{"move":{"x":-10,"y":0,"z":24},"block_id":8},{"move":{"x":-10,"y":0,"z":25},"block_id":362},{"move":{"x":-10,"y":0,"z":26},"block_id":362},{"move":{"x":-10,"y":0,"z":27},"block_id":8},{"move":{"x":-10,"y":0,"z":28},"block_id":8},{"move":{"x":-10,"y":0,"z":29},"block_id":8},{"move":{"x":-10,"y":0,"z":30},"block_id":8},{"move":{"x":-10,"y":0,"z":31},"block_id":67,"extra_data":{"point":{"x":0,"y":0.1,"z":0}},"rotate":{"x":1,"y":0,"z":0}},{"move":{"x":-10,"y":0,"z":32},"block_id":106,"extra_data":{},"rotate":{"x":0,"y":0,"z":0}},{"move":{"x":-10,"y":1,"z":1},"block_id":8},{"move":{"x":-10,"y":1,"z":2},"block_id":67,"extra_data":{"point":{"x":0,"y":0.9,"z":0}},"rotate":{"x":0,"y":0,"z":0}},{"move":{"x":-10,"y":1,"z":3},"block_id":53,"extra_data":{"point":{"x":0,"y":0.1,"z":0}},"rotate":{"x":1,"y":0,"z":0}},{"move":{"x":-10,"y":1,"z":4},"block_id":53,"extra_data":{"point":{"x":0,"y":0.1,"z":0}},"rotate":{"x":1,"y":0,"z":0}},{"move":{"x":-10,"y":1,"z":5},"block_id":53,"extra_data":{"point":{"x":0,"y":0.1,"z":0}},"rotate":{"x":1,"y":0,"z":0}},{"move":{"x":-10,"y":1,"z":9},"block_id":106,"extra_data":{},"rotate":{"x":2,"y":0,"z":0}},{"move":{"x":-10,"y":1,"z":10},"block_id":8},{"move":{"x":-10,"y":1,"z":11},"block_id":8},{"move":{"x":-10,"y":1,"z":12},"block_id":8},{"move":{"x":-10,"y":1,"z":13},"block_id":8},{"move":{"x":-10,"y":1,"z":14},"block_id":8},{"move":{"x":-10,"y":1,"z":15},"block_id":98},{"move":{"x":-10,"y":1,"z":16},"block_id":615,"extra_data":{"point":{"x":0,"y":0.1,"z":0}},"rotate":{"x":1,"y":0,"z":0}},{"move":{"x":-10,"y":1,"z":17},"block_id":83},{"move":{"x":-10,"y":1,"z":18},"block_id":8},{"move":{"x":-10,"y":1,"z":19},"block_id":8},{"move":{"x":-10,"y":1,"z":20},"block_id":8},{"move":{"x":-10,"y":1,"z":21},"block_id":8},{"move":{"x":-10,"y":1,"z":22},"block_id":8},{"move":{"x":-10,"y":1,"z":23},"block_id":5},{"move":{"x":-10,"y":1,"z":25},"block_id":362},{"move":{"x":-10,"y":1,"z":26},"block_id":362},{"move":{"x":-10,"y":1,"z":29},"block_id":61,"extra_data":{"can_destroy":true,"slots":{},"lit":false,"state":{"fuel_time":0,"result_ticks":0,"result_percent":0},"active":false},"rotate":{"x":0,"y":0,"z":0}},{"move":{"x":-10,"y":1,"z":30},"block_id":8},{"move":{"x":-10,"y":1,"z":31},"block_id":8},{"move":{"x":-10,"y":1,"z":32},"block_id":106,"extra_data":{},"rotate":{"x":0,"y":0,"z":0}},{"move":{"x":-10,"y":2,"z":1},"block_id":8},{"move":{"x":-10,"y":2,"z":2},"block_id":98},{"move":{"x":-10,"y":2,"z":10},"block_id":8},{"move":{"x":-10,"y":2,"z":11},"block_id":98},{"move":{"x":-10,"y":2,"z":12},"block_id":98},{"move":{"x":-10,"y":2,"z":13},"block_id":98},{"move":{"x":-10,"y":2,"z":14},"block_id":98},{"move":{"x":-10,"y":2,"z":15},"block_id":98},{"move":{"x":-10,"y":2,"z":16},"block_id":146},{"move":{"x":-10,"y":2,"z":17},"block_id":615,"extra_data":{"point":{"x":0,"y":0.9,"z":0}},"rotate":{"x":2,"y":0,"z":0}},{"move":{"x":-10,"y":2,"z":18},"block_id":8},{"move":{"x":-10,"y":2,"z":19},"block_id":8},{"move":{"x":-10,"y":2,"z":20},"block_id":8},{"move":{"x":-10,"y":2,"z":21},"block_id":8},{"move":{"x":-10,"y":2,"z":22},"block_id":8},{"move":{"x":-10,"y":2,"z":23},"block_id":5},{"move":{"x":-10,"y":2,"z":29},"block_id":61,"extra_data":{"can_destroy":true,"slots":{},"lit":false,"state":{"fuel_time":0,"result_ticks":0,"result_percent":0},"active":false},"rotate":{"x":0,"y":0,"z":0}},{"move":{"x":-10,"y":2,"z":30},"block_id":8},{"move":{"x":-10,"y":2,"z":31},"block_id":8},{"move":{"x":-10,"y":2,"z":32},"block_id":106,"extra_data":{},"rotate":{"x":0,"y":0,"z":0}},{"move":{"x":-10,"y":3,"z":1},"block_id":8},{"move":{"x":-10,"y":3,"z":2},"block_id":98},{"move":{"x":-10,"y":3,"z":3},"block_id":30},{"move":{"x":-10,"y":3,"z":9},"block_id":106,"extra_data":{},"rotate":{"x":3,"y":0,"z":0}},{"move":{"x":-10,"y":3,"z":10},"block_id":8},{"move":{"x":-10,"y":3,"z":11},"block_id":98},{"move":{"x":-10,"y":3,"z":12},"block_id":98},{"move":{"x":-10,"y":3,"z":13},"block_id":98},{"move":{"x":-10,"y":3,"z":14},"block_id":98},{"move":{"x":-10,"y":3,"z":15},"block_id":146},{"move":{"x":-10,"y":3,"z":17},"block_id":8},{"move":{"x":-10,"y":3,"z":18},"block_id":98},{"move":{"x":-10,"y":3,"z":19},"block_id":98},{"move":{"x":-10,"y":3,"z":20},"block_id":98},{"move":{"x":-10,"y":3,"z":21},"block_id":98},{"move":{"x":-10,"y":3,"z":22},"block_id":98},{"move":{"x":-10,"y":3,"z":29},"block_id":10},{"move":{"x":-10,"y":3,"z":30},"block_id":98},{"move":{"x":-10,"y":3,"z":31},"block_id":8},{"move":{"x":-10,"y":3,"z":32},"block_id":106,"extra_data":{},"rotate":{"x":0,"y":0,"z":0}},{"move":{"x":-10,"y":4,"z":2},"block_id":98},{"move":{"x":-10,"y":4,"z":3},"block_id":106,"extra_data":{},"rotate":{"x":0,"y":0,"z":0}},{"move":{"x":-10,"y":4,"z":10},"block_id":98},{"move":{"x":-10,"y":4,"z":11},"block_id":98},{"move":{"x":-10,"y":4,"z":12},"block_id":98},{"move":{"x":-10,"y":4,"z":13},"block_id":98},{"move":{"x":-10,"y":4,"z":14},"block_id":98},{"move":{"x":-10,"y":4,"z":18},"block_id":98},{"move":{"x":-10,"y":4,"z":19},"block_id":98},{"move":{"x":-10,"y":4,"z":20},"block_id":98},{"move":{"x":-10,"y":4,"z":21},"block_id":98},{"move":{"x":-10,"y":4,"z":22},"block_id":98},{"move":{"x":-10,"y":4,"z":29},"block_id":106,"extra_data":{},"rotate":{"x":2,"y":0,"z":0}},{"move":{"x":-10,"y":4,"z":30},"block_id":98},{"move":{"x":-10,"y":4,"z":31},"block_id":8},{"move":{"x":-10,"y":4,"z":32},"block_id":106,"extra_data":{},"rotate":{"x":0,"y":0,"z":0}},{"move":{"x":-10,"y":5,"z":2},"block_id":98},{"move":{"x":-10,"y":5,"z":3},"block_id":106,"extra_data":{},"rotate":{"x":0,"y":0,"z":0}},{"move":{"x":-10,"y":5,"z":9},"block_id":106,"extra_data":{},"rotate":{"x":2,"y":0,"z":0}},{"move":{"x":-10,"y":5,"z":10},"block_id":98},{"move":{"x":-10,"y":5,"z":11},"block_id":98},{"move":{"x":-10,"y":5,"z":12},"block_id":98},{"move":{"x":-10,"y":5,"z":13},"block_id":98},{"move":{"x":-10,"y":5,"z":14},"block_id":98},{"move":{"x":-10,"y":5,"z":18},"block_id":98},{"move":{"x":-10,"y":5,"z":19},"block_id":98},{"move":{"x":-10,"y":5,"z":20},"block_id":98},{"move":{"x":-10,"y":5,"z":21},"block_id":98},{"move":{"x":-10,"y":5,"z":22},"block_id":98},{"move":{"x":-10,"y":5,"z":29},"block_id":106,"extra_data":{},"rotate":{"x":2,"y":0,"z":0}},{"move":{"x":-10,"y":5,"z":30},"block_id":98},{"move":{"x":-10,"y":5,"z":31},"block_id":8},{"move":{"x":-10,"y":6,"z":2},"block_id":98},{"move":{"x":-10,"y":6,"z":3},"block_id":7},{"move":{"x":-10,"y":6,"z":4},"block_id":7},{"move":{"x":-10,"y":6,"z":5},"block_id":7},{"move":{"x":-10,"y":6,"z":6},"block_id":7},{"move":{"x":-10,"y":6,"z":9},"block_id":106,"extra_data":{},"rotate":{"x":2,"y":0,"z":0}},{"move":{"x":-10,"y":6,"z":10},"block_id":98},{"move":{"x":-10,"y":6,"z":11},"block_id":98},{"move":{"x":-10,"y":6,"z":12},"block_id":98},{"move":{"x":-10,"y":6,"z":13},"block_id":98},{"move":{"x":-10,"y":6,"z":14},"block_id":98},{"move":{"x":-10,"y":6,"z":18},"block_id":98},{"move":{"x":-10,"y":6,"z":19},"block_id":98},{"move":{"x":-10,"y":6,"z":20},"block_id":98},{"move":{"x":-10,"y":6,"z":21},"block_id":98},{"move":{"x":-10,"y":6,"z":22},"block_id":98},{"move":{"x":-10,"y":6,"z":29},"block_id":106,"extra_data":{},"rotate":{"x":3,"y":0,"z":0}},{"move":{"x":-10,"y":6,"z":30},"block_id":98},{"move":{"x":-10,"y":6,"z":31},"block_id":8},{"move":{"x":-10,"y":7,"z":2},"block_id":8},{"move":{"x":-10,"y":7,"z":3},"block_id":5},{"move":{"x":-10,"y":7,"z":10},"block_id":8},{"move":{"x":-10,"y":7,"z":11},"block_id":8},{"move":{"x":-10,"y":7,"z":12},"block_id":8},{"move":{"x":-10,"y":7,"z":13},"block_id":8},{"move":{"x":-10,"y":7,"z":14},"block_id":8},{"move":{"x":-10,"y":7,"z":18},"block_id":8},{"move":{"x":-10,"y":7,"z":19},"block_id":8},{"move":{"x":-10,"y":7,"z":20},"block_id":8},{"move":{"x":-10,"y":7,"z":21},"block_id":8},{"move":{"x":-10,"y":7,"z":22},"block_id":8},{"move":{"x":-10,"y":7,"z":29},"block_id":106,"extra_data":{},"rotate":{"x":3,"y":0,"z":0}},{"move":{"x":-10,"y":7,"z":30},"block_id":8},{"move":{"x":-10,"y":8,"z":3},"block_id":50,"rotate":{"x":2,"y":1,"z":0}},{"move":{"x":-10,"y":8,"z":10},"block_id":8},{"move":{"x":-10,"y":8,"z":14},"block_id":8},{"move":{"x":-10,"y":8,"z":16},"block_id":67,"extra_data":{"point":{"x":0,"y":0.1,"z":0}},"rotate":{"x":3,"y":0,"z":0}},{"move":{"x":-10,"y":8,"z":17},"block_id":67,"extra_data":{"point":{"x":0,"y":0.1,"z":0}},"rotate":{"x":0,"y":0,"z":0}},{"move":{"x":-10,"y":8,"z":18},"block_id":146},{"move":{"x":-10,"y":8,"z":22},"block_id":98},{"move":{"x":-10,"y":8,"z":29},"block_id":106,"extra_data":{},"rotate":{"x":3,"y":0,"z":0}},{"move":{"x":-10,"y":9,"z":3},"block_id":106,"extra_data":{},"rotate":{"x":3,"y":0,"z":0}},{"move":{"x":-10,"y":10,"z":3},"block_id":7},{"move":{"x":-10,"y":10,"z":4},"block_id":7},{"move":{"x":-10,"y":10,"z":5},"block_id":7},{"move":{"x":-10,"y":10,"z":6},"block_id":7},{"move":{"x":-10,"y":11,"z":3},"block_id":106,"extra_data":{},"rotate":{"x":3,"y":0,"z":0}},{"move":{"x":-10,"y":13,"z":3},"block_id":7},{"move":{"x":-10,"y":13,"z":4},"block_id":7},{"move":{"x":-10,"y":13,"z":5},"block_id":7},{"move":{"x":-10,"y":13,"z":6},"block_id":7},{"move":{"x":-10,"y":14,"z":3},"block_id":8},{"move":{"x":-10,"y":15,"z":3},"block_id":8},{"move":{"x":-10,"y":16,"z":3},"block_id":67,"extra_data":{"point":{"x":0,"y":0.1,"z":0}},"rotate":{"x":2,"y":0,"z":0}},{"move":{"x":-9,"y":-1,"z":1},"block_id":2},{"move":{"x":-9,"y":-1,"z":2},"block_id":18},{"move":{"x":-9,"y":-1,"z":3},"block_id":18},{"move":{"x":-9,"y":-1,"z":4},"block_id":18},{"move":{"x":-9,"y":-1,"z":5},"block_id":18},{"move":{"x":-9,"y":-1,"z":6},"block_id":18},{"move":{"x":-9,"y":-1,"z":7},"block_id":18},{"move":{"x":-9,"y":-1,"z":8},"block_id":18},{"move":{"x":-9,"y":-1,"z":9},"block_id":18},{"move":{"x":-9,"y":-1,"z":10},"block_id":18},{"move":{"x":-9,"y":-1,"z":11},"block_id":18},{"move":{"x":-9,"y":-1,"z":12},"block_id":18},{"move":{"x":-9,"y":-1,"z":13},"block_id":18},{"move":{"x":-9,"y":-1,"z":14},"block_id":18},{"move":{"x":-9,"y":-1,"z":15},"block_id":18},{"move":{"x":-9,"y":-1,"z":16},"block_id":18},{"move":{"x":-9,"y":-1,"z":17},"block_id":18},{"move":{"x":-9,"y":-1,"z":18},"block_id":18},{"move":{"x":-9,"y":-1,"z":19},"block_id":18},{"move":{"x":-9,"y":-1,"z":20},"block_id":18},{"move":{"x":-9,"y":-1,"z":21},"block_id":18},{"move":{"x":-9,"y":-1,"z":22},"block_id":18},{"move":{"x":-9,"y":-1,"z":23},"block_id":18},{"move":{"x":-9,"y":-1,"z":24},"block_id":18},{"move":{"x":-9,"y":-1,"z":25},"block_id":18},{"move":{"x":-9,"y":-1,"z":26},"block_id":18},{"move":{"x":-9,"y":-1,"z":27},"block_id":18},{"move":{"x":-9,"y":-1,"z":28},"block_id":18},{"move":{"x":-9,"y":-1,"z":29},"block_id":18},{"move":{"x":-9,"y":-1,"z":30},"block_id":18},{"move":{"x":-9,"y":-1,"z":31},"block_id":2},{"move":{"x":-9,"y":0,"z":1},"block_id":106,"extra_data":{},"rotate":{"x":1,"y":0,"z":0}},{"move":{"x":-9,"y":0,"z":2},"block_id":146},{"move":{"x":-9,"y":0,"z":3},"block_id":9},{"move":{"x":-9,"y":0,"z":4},"block_id":9},{"move":{"x":-9,"y":0,"z":5},"block_id":9},{"move":{"x":-9,"y":0,"z":6},"block_id":8},{"move":{"x":-9,"y":0,"z":7},"block_id":8},{"move":{"x":-9,"y":0,"z":8},"block_id":8},{"move":{"x":-9,"y":0,"z":9},"block_id":8},{"move":{"x":-9,"y":0,"z":10},"block_id":8},{"move":{"x":-9,"y":0,"z":11},"block_id":8},{"move":{"x":-9,"y":0,"z":12},"block_id":8},{"move":{"x":-9,"y":0,"z":13},"block_id":8},{"move":{"x":-9,"y":0,"z":14},"block_id":8},{"move":{"x":-9,"y":0,"z":15},"block_id":8},{"move":{"x":-9,"y":0,"z":16},"block_id":8},{"move":{"x":-9,"y":0,"z":17},"block_id":8},{"move":{"x":-9,"y":0,"z":18},"block_id":146},{"move":{"x":-9,"y":0,"z":19},"block_id":8},{"move":{"x":-9,"y":0,"z":20},"block_id":8},{"move":{"x":-9,"y":0,"z":21},"block_id":8},{"move":{"x":-9,"y":0,"z":22},"block_id":8},{"move":{"x":-9,"y":0,"z":23},"block_id":8},{"move":{"x":-9,"y":0,"z":24},"block_id":8},{"move":{"x":-9,"y":0,"z":25},"block_id":362},{"move":{"x":-9,"y":0,"z":26},"block_id":362},{"move":{"x":-9,"y":0,"z":27},"block_id":146},{"move":{"x":-9,"y":0,"z":28},"block_id":8},{"move":{"x":-9,"y":0,"z":29},"block_id":8},{"move":{"x":-9,"y":0,"z":30},"block_id":8},{"move":{"x":-9,"y":1,"z":1},"block_id":106,"extra_data":{},"rotate":{"x":1,"y":0,"z":0}},{"move":{"x":-9,"y":1,"z":2},"block_id":67,"extra_data":{"point":{"x":0,"y":0.1,"z":0}},"rotate":{"x":3,"y":0,"z":0}},{"move":{"x":-9,"y":1,"z":3},"block_id":7},{"move":{"x":-9,"y":1,"z":4},"block_id":106,"extra_data":{},"rotate":{"x":0,"y":0,"z":0}},{"move":{"x":-9,"y":1,"z":5},"block_id":7},{"move":{"x":-9,"y":1,"z":10},"block_id":98},{"move":{"x":-9,"y":1,"z":11},"block_id":98},{"move":{"x":-9,"y":1,"z":12},"block_id":98},{"move":{"x":-9,"y":1,"z":13},"block_id":98},{"move":{"x":-9,"y":1,"z":14},"block_id":83},{"move":{"x":-9,"y":1,"z":15},"block_id":98},{"move":{"x":-9,"y":1,"z":16},"block_id":83},{"move":{"x":-9,"y":1,"z":17},"block_id":83},{"move":{"x":-9,"y":1,"z":18},"block_id":83},{"move":{"x":-9,"y":1,"z":19},"block_id":98},{"move":{"x":-9,"y":1,"z":20},"block_id":98},{"move":{"x":-9,"y":1,"z":21},"block_id":83},{"move":{"x":-9,"y":1,"z":22},"block_id":98},{"move":{"x":-9,"y":1,"z":25},"block_id":362},{"move":{"x":-9,"y":1,"z":26},"block_id":362},{"move":{"x":-9,"y":1,"z":29},"block_id":61,"extra_data":{"can_destroy":true,"slots":{},"lit":false,"state":{"fuel_time":0,"result_ticks":0,"result_percent":0},"active":false},"rotate":{"x":0,"y":0,"z":0}},{"move":{"x":-9,"y":1,"z":30},"block_id":8},{"move":{"x":-9,"y":1,"z":31},"block_id":106,"extra_data":{},"rotate":{"x":3,"y":0,"z":0}},{"move":{"x":-9,"y":2,"z":1},"block_id":106,"extra_data":{},"rotate":{"x":1,"y":0,"z":0}},{"move":{"x":-9,"y":2,"z":2},"block_id":98},{"move":{"x":-9,"y":2,"z":3},"block_id":53,"extra_data":{"point":{"x":0,"y":0.9,"z":0}},"rotate":{"x":3,"y":0,"z":0}},{"move":{"x":-9,"y":2,"z":4},"block_id":106,"extra_data":{},"rotate":{"x":0,"y":0,"z":0}},{"move":{"x":-9,"y":2,"z":10},"block_id":98},{"move":{"x":-9,"y":2,"z":11},"block_id":106,"extra_data":{},"rotate":{"x":3,"y":0,"z":0}},{"move":{"x":-9,"y":2,"z":13},"block_id":106,"extra_data":{},"rotate":{"x":3,"y":0,"z":0}},{"move":{"x":-9,"y":2,"z":15},"block_id":106,"extra_data":{},"rotate":{"x":3,"y":0,"z":0}},{"move":{"x":-9,"y":2,"z":16},"block_id":106,"extra_data":{},"rotate":{"x":3,"y":0,"z":0}},{"move":{"x":-9,"y":2,"z":18},"block_id":106,"extra_data":{},"rotate":{"x":3,"y":0,"z":0}},{"move":{"x":-9,"y":2,"z":20},"block_id":106,"extra_data":{},"rotate":{"x":3,"y":0,"z":0}},{"move":{"x":-9,"y":2,"z":22},"block_id":98},{"move":{"x":-9,"y":2,"z":29},"block_id":61,"extra_data":{"can_destroy":true,"slots":{},"lit":false,"state":{"fuel_time":0,"result_ticks":0,"result_percent":0},"active":false},"rotate":{"x":0,"y":0,"z":0}},{"move":{"x":-9,"y":2,"z":30},"block_id":8},{"move":{"x":-9,"y":2,"z":31},"block_id":106,"extra_data":{},"rotate":{"x":1,"y":0,"z":0}},{"move":{"x":-9,"y":3,"z":1},"block_id":106,"extra_data":{},"rotate":{"x":1,"y":0,"z":0}},{"move":{"x":-9,"y":3,"z":2},"block_id":83},{"move":{"x":-9,"y":3,"z":3},"block_id":5},{"move":{"x":-9,"y":3,"z":4},"block_id":106,"extra_data":{},"rotate":{"x":0,"y":0,"z":0}},{"move":{"x":-9,"y":3,"z":10},"block_id":98},{"move":{"x":-9,"y":3,"z":11},"block_id":106,"extra_data":{},"rotate":{"x":3,"y":0,"z":0}},{"move":{"x":-9,"y":3,"z":12},"block_id":106,"extra_data":{},"rotate":{"x":3,"y":0,"z":0}},{"move":{"x":-9,"y":3,"z":13},"block_id":106,"extra_data":{},"rotate":{"x":3,"y":0,"z":0}},{"move":{"x":-9,"y":3,"z":20},"block_id":106,"extra_data":{},"rotate":{"x":3,"y":0,"z":0}},{"move":{"x":-9,"y":3,"z":22},"block_id":98},{"move":{"x":-9,"y":3,"z":29},"block_id":106,"extra_data":{},"rotate":{"x":2,"y":0,"z":0}},{"move":{"x":-9,"y":3,"z":30},"block_id":98},{"move":{"x":-9,"y":4,"z":2},"block_id":98},{"move":{"x":-9,"y":4,"z":3},"block_id":7},{"move":{"x":-9,"y":4,"z":10},"block_id":98},{"move":{"x":-9,"y":4,"z":11},"block_id":106,"extra_data":{},"rotate":{"x":3,"y":0,"z":0}},{"move":{"x":-9,"y":4,"z":12},"block_id":106,"extra_data":{},"rotate":{"x":3,"y":0,"z":0}},{"move":{"x":-9,"y":4,"z":13},"block_id":106,"extra_data":{},"rotate":{"x":3,"y":0,"z":0}},{"move":{"x":-9,"y":4,"z":21},"block_id":106,"extra_data":{},"rotate":{"x":3,"y":0,"z":0}},{"move":{"x":-9,"y":4,"z":22},"block_id":98},{"move":{"x":-9,"y":4,"z":30},"block_id":83},{"move":{"x":-9,"y":5,"z":2},"block_id":8},{"move":{"x":-9,"y":5,"z":10},"block_id":98},{"move":{"x":-9,"y":5,"z":11},"block_id":106,"extra_data":{},"rotate":{"x":0,"y":0,"z":0}},{"move":{"x":-9,"y":5,"z":12},"block_id":106,"extra_data":{},"rotate":{"x":3,"y":0,"z":0}},{"move":{"x":-9,"y":5,"z":18},"block_id":106,"extra_data":{},"rotate":{"x":2,"y":0,"z":0}},{"move":{"x":-9,"y":5,"z":21},"block_id":106,"extra_data":{},"rotate":{"x":3,"y":0,"z":0}},{"move":{"x":-9,"y":5,"z":22},"block_id":98},{"move":{"x":-9,"y":5,"z":29},"block_id":106,"extra_data":{},"rotate":{"x":2,"y":0,"z":0}},{"move":{"x":-9,"y":5,"z":30},"block_id":8},{"move":{"x":-9,"y":6,"z":2},"block_id":98},{"move":{"x":-9,"y":6,"z":4},"block_id":7},{"move":{"x":-9,"y":6,"z":6},"block_id":106,"extra_data":{},"rotate":{"x":0,"y":0,"z":0}},{"move":{"x":-9,"y":6,"z":10},"block_id":98},{"move":{"x":-9,"y":6,"z":18},"block_id":106,"extra_data":{},"rotate":{"x":2,"y":0,"z":0}},{"move":{"x":-9,"y":6,"z":22},"block_id":98},{"move":{"x":-9,"y":6,"z":29},"block_id":106,"extra_data":{},"rotate":{"x":2,"y":0,"z":0}},{"move":{"x":-9,"y":6,"z":30},"block_id":98},{"move":{"x":-9,"y":7,"z":2},"block_id":8},{"move":{"x":-9,"y":7,"z":6},"block_id":106,"extra_data":{},"rotate":{"x":0,"y":0,"z":0}},{"move":{"x":-9,"y":7,"z":10},"block_id":98},{"move":{"x":-9,"y":7,"z":18},"block_id":106,"extra_data":{},"rotate":{"x":2,"y":0,"z":0}},{"move":{"x":-9,"y":7,"z":22},"block_id":98},{"move":{"x":-9,"y":7,"z":30},"block_id":8},{"move":{"x":-9,"y":8,"z":2},"block_id":98},{"move":{"x":-9,"y":8,"z":6},"block_id":106,"extra_data":{},"rotate":{"x":0,"y":0,"z":0}},{"move":{"x":-9,"y":8,"z":18},"block_id":106,"extra_data":{},"rotate":{"x":2,"y":0,"z":0}},{"move":{"x":-9,"y":8,"z":19},"block_id":67,"extra_data":{"point":{"x":0,"y":0.1,"z":0}},"rotate":{"x":2,"y":0,"z":0}},{"move":{"x":-9,"y":8,"z":20},"block_id":67,"extra_data":{"point":{"x":0,"y":0.1,"z":0}},"rotate":{"x":3,"y":0,"z":0}},{"move":{"x":-9,"y":8,"z":21},"block_id":67,"extra_data":{"point":{"x":0,"y":0.1,"z":0}},"rotate":{"x":0,"y":0,"z":0}},{"move":{"x":-9,"y":9,"z":6},"block_id":106,"extra_data":{},"rotate":{"x":0,"y":0,"z":0}},{"move":{"x":-9,"y":10,"z":4},"block_id":7},{"move":{"x":-9,"y":10,"z":5},"block_id":7},{"move":{"x":-9,"y":10,"z":6},"block_id":106,"extra_data":{},"rotate":{"x":0,"y":0,"z":0}},{"move":{"x":-9,"y":13,"z":4},"block_id":7},{"move":{"x":-9,"y":13,"z":5},"block_id":7},{"move":{"x":-8,"y":-1,"z":0},"block_id":2},{"move":{"x":-8,"y":-1,"z":1},"block_id":18},{"move":{"x":-8,"y":-1,"z":2},"block_id":18},{"move":{"x":-8,"y":-1,"z":3},"block_id":18},{"move":{"x":-8,"y":-1,"z":4},"block_id":18},{"move":{"x":-8,"y":-1,"z":5},"block_id":2},{"move":{"x":-8,"y":-1,"z":6},"block_id":18},{"move":{"x":-8,"y":-1,"z":7},"block_id":18},{"move":{"x":-8,"y":-1,"z":8},"block_id":18},{"move":{"x":-8,"y":-1,"z":9},"block_id":18},{"move":{"x":-8,"y":-1,"z":10},"block_id":18},{"move":{"x":-8,"y":-1,"z":11},"block_id":18},{"move":{"x":-8,"y":-1,"z":12},"block_id":18},{"move":{"x":-8,"y":-1,"z":13},"block_id":18},{"move":{"x":-8,"y":-1,"z":14},"block_id":18},{"move":{"x":-8,"y":-1,"z":15},"block_id":18},{"move":{"x":-8,"y":-1,"z":16},"block_id":18},{"move":{"x":-8,"y":-1,"z":17},"block_id":18},{"move":{"x":-8,"y":-1,"z":18},"block_id":18},{"move":{"x":-8,"y":-1,"z":19},"block_id":2},{"move":{"x":-8,"y":-1,"z":20},"block_id":18},{"move":{"x":-8,"y":-1,"z":21},"block_id":18},{"move":{"x":-8,"y":-1,"z":22},"block_id":18},{"move":{"x":-8,"y":-1,"z":23},"block_id":18},{"move":{"x":-8,"y":-1,"z":24},"block_id":18},{"move":{"x":-8,"y":-1,"z":25},"block_id":18},{"move":{"x":-8,"y":-1,"z":26},"block_id":18},{"move":{"x":-8,"y":-1,"z":27},"block_id":18},{"move":{"x":-8,"y":-1,"z":28},"block_id":18},{"move":{"x":-8,"y":-1,"z":29},"block_id":18},{"move":{"x":-8,"y":-1,"z":30},"block_id":18},{"move":{"x":-8,"y":-1,"z":31},"block_id":18},{"move":{"x":-8,"y":-1,"z":32},"block_id":2},{"move":{"x":-8,"y":0,"z":0},"block_id":106,"extra_data":{},"rotate":{"x":2,"y":0,"z":0}},{"move":{"x":-8,"y":0,"z":1},"block_id":8},{"move":{"x":-8,"y":0,"z":2},"block_id":8},{"move":{"x":-8,"y":0,"z":3},"block_id":8},{"move":{"x":-8,"y":0,"z":4},"block_id":8},{"move":{"x":-8,"y":0,"z":5},"block_id":67,"extra_data":{"point":{"x":0,"y":0.9,"z":0}},"rotate":{"x":0,"y":0,"z":0}},{"move":{"x":-8,"y":0,"z":6},"block_id":8},{"move":{"x":-8,"y":0,"z":7},"block_id":8},{"move":{"x":-8,"y":0,"z":8},"block_id":146},{"move":{"x":-8,"y":0,"z":9},"block_id":8},{"move":{"x":-8,"y":0,"z":10},"block_id":8},{"move":{"x":-8,"y":0,"z":11},"block_id":8},{"move":{"x":-8,"y":0,"z":12},"block_id":8},{"move":{"x":-8,"y":0,"z":13},"block_id":8},{"move":{"x":-8,"y":0,"z":14},"block_id":8},{"move":{"x":-8,"y":0,"z":15},"block_id":83},{"move":{"x":-8,"y":0,"z":16},"block_id":8},{"move":{"x":-8,"y":0,"z":17},"block_id":8},{"move":{"x":-8,"y":0,"z":18},"block_id":8},{"move":{"x":-8,"y":0,"z":19},"block_id":67,"extra_data":{"point":{"x":0,"y":0.9,"z":0}},"rotate":{"x":1,"y":0,"z":0}},{"move":{"x":-8,"y":0,"z":20},"block_id":83},{"move":{"x":-8,"y":0,"z":21},"block_id":146},{"move":{"x":-8,"y":0,"z":22},"block_id":8},{"move":{"x":-8,"y":0,"z":23},"block_id":146},{"move":{"x":-8,"y":0,"z":24},"block_id":8},{"move":{"x":-8,"y":0,"z":25},"block_id":362},{"move":{"x":-8,"y":0,"z":26},"block_id":362},{"move":{"x":-8,"y":0,"z":27},"block_id":8},{"move":{"x":-8,"y":0,"z":28},"block_id":8},{"move":{"x":-8,"y":0,"z":29},"block_id":8},{"move":{"x":-8,"y":0,"z":30},"block_id":8},{"move":{"x":-8,"y":0,"z":31},"block_id":146},{"move":{"x":-8,"y":1,"z":0},"block_id":106,"extra_data":{},"rotate":{"x":2,"y":0,"z":0}},{"move":{"x":-8,"y":1,"z":1},"block_id":8},{"move":{"x":-8,"y":1,"z":2},"block_id":146},{"move":{"x":-8,"y":1,"z":3},"block_id":53,"extra_data":{"point":{"x":0,"y":0.1,"z":0}},"rotate":{"x":3,"y":0,"z":0}},{"move":{"x":-8,"y":1,"z":4},"block_id":53,"extra_data":{"point":{"x":0,"y":0.1,"z":0}},"rotate":{"x":3,"y":0,"z":0}},{"move":{"x":-8,"y":1,"z":10},"block_id":83},{"move":{"x":-8,"y":1,"z":11},"block_id":106,"extra_data":{},"rotate":{"x":0,"y":0,"z":0}},{"move":{"x":-8,"y":1,"z":15},"block_id":106,"extra_data":{},"rotate":{"x":3,"y":0,"z":0}},{"move":{"x":-8,"y":1,"z":18},"block_id":106,"extra_data":{},"rotate":{"x":3,"y":0,"z":0}},{"move":{"x":-8,"y":1,"z":20},"block_id":106,"extra_data":{},"rotate":{"x":3,"y":0,"z":0}},{"move":{"x":-8,"y":1,"z":22},"block_id":98},{"move":{"x":-8,"y":1,"z":23},"block_id":30},{"move":{"x":-8,"y":1,"z":25},"block_id":362},{"move":{"x":-8,"y":1,"z":26},"block_id":362},{"move":{"x":-8,"y":1,"z":29},"block_id":61,"extra_data":{"can_destroy":true,"slots":{},"lit":false,"state":{"fuel_time":0,"result_ticks":0,"result_percent":0},"active":false},"rotate":{"x":0,"y":0,"z":0}},{"move":{"x":-8,"y":1,"z":30},"block_id":8},{"move":{"x":-8,"y":1,"z":31},"block_id":8},{"move":{"x":-8,"y":2,"z":0},"block_id":106,"extra_data":{},"rotate":{"x":2,"y":0,"z":0}},{"move":{"x":-8,"y":2,"z":1},"block_id":8},{"move":{"x":-8,"y":2,"z":2},"block_id":83},{"move":{"x":-8,"y":2,"z":3},"block_id":7},{"move":{"x":-8,"y":2,"z":4},"block_id":7},{"move":{"x":-8,"y":2,"z":10},"block_id":632},{"move":{"x":-8,"y":2,"z":23},"block_id":106,"extra_data":{},"rotate":{"x":1,"y":0,"z":0}},{"move":{"x":-8,"y":2,"z":29},"block_id":61,"extra_data":{"can_destroy":true,"slots":{},"lit":false,"state":{"fuel_time":0,"result_ticks":0,"result_percent":0},"active":false},"rotate":{"x":0,"y":0,"z":0}},{"move":{"x":-8,"y":2,"z":30},"block_id":98},{"move":{"x":-8,"y":2,"z":31},"block_id":8},{"move":{"x":-8,"y":2,"z":32},"block_id":106,"extra_data":{},"rotate":{"x":0,"y":0,"z":0}},{"move":{"x":-8,"y":3,"z":1},"block_id":8},{"move":{"x":-8,"y":3,"z":2},"block_id":98},{"move":{"x":-8,"y":3,"z":3},"block_id":5},{"move":{"x":-8,"y":3,"z":4},"block_id":106,"extra_data":{},"rotate":{"x":0,"y":0,"z":0}},{"move":{"x":-8,"y":3,"z":10},"block_id":98},{"move":{"x":-8,"y":3,"z":21},"block_id":106,"extra_data":{},"rotate":{"x":2,"y":0,"z":0}},{"move":{"x":-8,"y":3,"z":22},"block_id":98},{"move":{"x":-8,"y":3,"z":23},"block_id":106,"extra_data":{},"rotate":{"x":0,"y":0,"z":0}},{"move":{"x":-8,"y":3,"z":29},"block_id":10},{"move":{"x":-8,"y":3,"z":30},"block_id":98},{"move":{"x":-8,"y":3,"z":31},"block_id":8},{"move":{"x":-8,"y":3,"z":32},"block_id":106,"extra_data":{},"rotate":{"x":0,"y":0,"z":0}},{"move":{"x":-8,"y":4,"z":1},"block_id":8},{"move":{"x":-8,"y":4,"z":2},"block_id":98},{"move":{"x":-8,"y":4,"z":3},"block_id":8},{"move":{"x":-8,"y":4,"z":4},"block_id":106,"extra_data":{},"rotate":{"x":0,"y":0,"z":0}},{"move":{"x":-8,"y":4,"z":10},"block_id":98},{"move":{"x":-8,"y":4,"z":21},"block_id":106,"extra_data":{},"rotate":{"x":2,"y":0,"z":0}},{"move":{"x":-8,"y":4,"z":22},"block_id":98},{"move":{"x":-8,"y":4,"z":29},"block_id":106,"extra_data":{},"rotate":{"x":2,"y":0,"z":0}},{"move":{"x":-8,"y":4,"z":30},"block_id":98},{"move":{"x":-8,"y":4,"z":31},"block_id":8},{"move":{"x":-8,"y":4,"z":32},"block_id":106,"extra_data":{},"rotate":{"x":0,"y":0,"z":0}},{"move":{"x":-8,"y":5,"z":1},"block_id":8},{"move":{"x":-8,"y":5,"z":2},"block_id":98},{"move":{"x":-8,"y":5,"z":3},"block_id":8},{"move":{"x":-8,"y":5,"z":4},"block_id":106,"extra_data":{},"rotate":{"x":0,"y":0,"z":0}},{"move":{"x":-8,"y":5,"z":10},"block_id":98},{"move":{"x":-8,"y":5,"z":21},"block_id":106,"extra_data":{},"rotate":{"x":2,"y":0,"z":0}},{"move":{"x":-8,"y":5,"z":22},"block_id":98},{"move":{"x":-8,"y":5,"z":23},"block_id":106,"extra_data":{},"rotate":{"x":0,"y":0,"z":0}},{"move":{"x":-8,"y":5,"z":29},"block_id":106,"extra_data":{},"rotate":{"x":2,"y":0,"z":0}},{"move":{"x":-8,"y":5,"z":30},"block_id":98},{"move":{"x":-8,"y":5,"z":31},"block_id":8},{"move":{"x":-8,"y":5,"z":32},"block_id":106,"extra_data":{},"rotate":{"x":0,"y":0,"z":0}},{"move":{"x":-8,"y":6,"z":1},"block_id":8},{"move":{"x":-8,"y":6,"z":2},"block_id":98},{"move":{"x":-8,"y":6,"z":10},"block_id":632},{"move":{"x":-8,"y":6,"z":21},"block_id":106,"extra_data":{},"rotate":{"x":2,"y":0,"z":0}},{"move":{"x":-8,"y":6,"z":22},"block_id":98},{"move":{"x":-8,"y":6,"z":29},"block_id":106,"extra_data":{},"rotate":{"x":1,"y":0,"z":0}},{"move":{"x":-8,"y":6,"z":30},"block_id":98},{"move":{"x":-8,"y":6,"z":31},"block_id":8},{"move":{"x":-8,"y":7,"z":2},"block_id":8},{"move":{"x":-8,"y":7,"z":21},"block_id":106,"extra_data":{},"rotate":{"x":2,"y":0,"z":0}},{"move":{"x":-8,"y":7,"z":22},"block_id":98},{"move":{"x":-8,"y":7,"z":29},"block_id":106,"extra_data":{},"rotate":{"x":1,"y":0,"z":0}},{"move":{"x":-8,"y":7,"z":30},"block_id":8},{"move":{"x":-8,"y":8,"z":2},"block_id":98},{"move":{"x":-8,"y":8,"z":3},"block_id":106,"extra_data":{},"rotate":{"x":0,"y":0,"z":0}},{"move":{"x":-8,"y":8,"z":22},"block_id":98},{"move":{"x":-8,"y":9,"z":2},"block_id":98},{"move":{"x":-8,"y":10,"z":2},"block_id":98},{"move":{"x":-8,"y":10,"z":5},"block_id":106,"extra_data":{},"rotate":{"x":3,"y":0,"z":0}},{"move":{"x":-8,"y":11,"z":4},"block_id":106,"extra_data":{},"rotate":{"x":3,"y":0,"z":0}},{"move":{"x":-8,"y":12,"z":4},"block_id":106,"extra_data":{},"rotate":{"x":3,"y":0,"z":0}},{"move":{"x":-8,"y":13,"z":3},"block_id":106,"extra_data":{},"rotate":{"x":1,"y":0,"z":0}},{"move":{"x":-8,"y":13,"z":4},"block_id":106,"extra_data":{},"rotate":{"x":3,"y":0,"z":0}},{"move":{"x":-7,"y":-1,"z":1},"block_id":2},{"move":{"x":-7,"y":-1,"z":2},"block_id":2},{"move":{"x":-7,"y":-1,"z":3},"block_id":18},{"move":{"x":-7,"y":-1,"z":4},"block_id":18},{"move":{"x":-7,"y":-1,"z":5},"block_id":18},{"move":{"x":-7,"y":-1,"z":6},"block_id":18},{"move":{"x":-7,"y":-1,"z":7},"block_id":18},{"move":{"x":-7,"y":-1,"z":8},"block_id":18},{"move":{"x":-7,"y":-1,"z":9},"block_id":18},{"move":{"x":-7,"y":-1,"z":10},"block_id":18},{"move":{"x":-7,"y":-1,"z":11},"block_id":18},{"move":{"x":-7,"y":-1,"z":12},"block_id":18},{"move":{"x":-7,"y":-1,"z":13},"block_id":18},{"move":{"x":-7,"y":-1,"z":14},"block_id":18},{"move":{"x":-7,"y":-1,"z":15},"block_id":18},{"move":{"x":-7,"y":-1,"z":16},"block_id":18},{"move":{"x":-7,"y":-1,"z":17},"block_id":18},{"move":{"x":-7,"y":-1,"z":18},"block_id":2},{"move":{"x":-7,"y":-1,"z":19},"block_id":18},{"move":{"x":-7,"y":-1,"z":20},"block_id":18},{"move":{"x":-7,"y":-1,"z":21},"block_id":18},{"move":{"x":-7,"y":-1,"z":22},"block_id":18},{"move":{"x":-7,"y":-1,"z":23},"block_id":18},{"move":{"x":-7,"y":-1,"z":24},"block_id":18},{"move":{"x":-7,"y":-1,"z":25},"block_id":18},{"move":{"x":-7,"y":-1,"z":26},"block_id":18},{"move":{"x":-7,"y":-1,"z":27},"block_id":18},{"move":{"x":-7,"y":-1,"z":28},"block_id":18},{"move":{"x":-7,"y":-1,"z":29},"block_id":18},{"move":{"x":-7,"y":-1,"z":30},"block_id":2},{"move":{"x":-7,"y":-1,"z":31},"block_id":2},{"move":{"x":-7,"y":0,"z":3},"block_id":8},{"move":{"x":-7,"y":0,"z":4},"block_id":8},{"move":{"x":-7,"y":0,"z":5},"block_id":8},{"move":{"x":-7,"y":0,"z":6},"block_id":8},{"move":{"x":-7,"y":0,"z":7},"block_id":146},{"move":{"x":-7,"y":0,"z":8},"block_id":8},{"move":{"x":-7,"y":0,"z":9},"block_id":146},{"move":{"x":-7,"y":0,"z":10},"block_id":8},{"move":{"x":-7,"y":0,"z":11},"block_id":8},{"move":{"x":-7,"y":0,"z":12},"block_id":8},{"move":{"x":-7,"y":0,"z":13},"block_id":8},{"move":{"x":-7,"y":0,"z":14},"block_id":8},{"move":{"x":-7,"y":0,"z":15},"block_id":8},{"move":{"x":-7,"y":0,"z":16},"block_id":98},{"move":{"x":-7,"y":0,"z":17},"block_id":8},{"move":{"x":-7,"y":0,"z":18},"block_id":615,"extra_data":{"point":{"x":0,"y":0.1,"z":0}},"rotate":{"x":1,"y":0,"z":0}},{"move":{"x":-7,"y":0,"z":19},"block_id":8},{"move":{"x":-7,"y":0,"z":20},"block_id":146},{"move":{"x":-7,"y":0,"z":21},"block_id":146},{"move":{"x":-7,"y":0,"z":22},"block_id":8},{"move":{"x":-7,"y":0,"z":23},"block_id":8},{"move":{"x":-7,"y":0,"z":24},"block_id":8},{"move":{"x":-7,"y":0,"z":25},"block_id":8},{"move":{"x":-7,"y":0,"z":26},"block_id":8},{"move":{"x":-7,"y":0,"z":27},"block_id":8},{"move":{"x":-7,"y":0,"z":28},"block_id":8},{"move":{"x":-7,"y":0,"z":29},"block_id":8},{"move":{"x":-7,"y":0,"z":30},"block_id":106,"extra_data":{},"rotate":{"x":3,"y":0,"z":0}},{"move":{"x":-7,"y":1,"z":2},"block_id":106,"extra_data":{},"rotate":{"x":2,"y":0,"z":0}},{"move":{"x":-7,"y":1,"z":3},"block_id":146},{"move":{"x":-7,"y":1,"z":4},"block_id":106,"extra_data":{},"rotate":{"x":1,"y":0,"z":0}},{"move":{"x":-7,"y":1,"z":9},"block_id":106,"extra_data":{},"rotate":{"x":2,"y":0,"z":0}},{"move":{"x":-7,"y":1,"z":10},"block_id":98},{"move":{"x":-7,"y":1,"z":11},"block_id":106,"extra_data":{},"rotate":{"x":0,"y":0,"z":0}},{"move":{"x":-7,"y":1,"z":13},"block_id":146},{"move":{"x":-7,"y":1,"z":14},"block_id":8},{"move":{"x":-7,"y":1,"z":15},"block_id":67,"extra_data":{"point":{"x":0,"y":0.1,"z":0}},"rotate":{"x":2,"y":0,"z":0}},{"move":{"x":-7,"y":1,"z":16},"block_id":98},{"move":{"x":-7,"y":1,"z":17},"block_id":30},{"move":{"x":-7,"y":1,"z":22},"block_id":98},{"move":{"x":-7,"y":1,"z":23},"block_id":5},{"move":{"x":-7,"y":1,"z":28},"block_id":106,"extra_data":{},"rotate":{"x":1,"y":0,"z":0}},{"move":{"x":-7,"y":1,"z":29},"block_id":8},{"move":{"x":-7,"y":1,"z":30},"block_id":106,"extra_data":{},"rotate":{"x":3,"y":0,"z":0}},{"move":{"x":-7,"y":2,"z":3},"block_id":83},{"move":{"x":-7,"y":2,"z":9},"block_id":106,"extra_data":{},"rotate":{"x":2,"y":0,"z":0}},{"move":{"x":-7,"y":2,"z":10},"block_id":98},{"move":{"x":-7,"y":2,"z":11},"block_id":106,"extra_data":{},"rotate":{"x":0,"y":0,"z":0}},{"move":{"x":-7,"y":2,"z":21},"block_id":85},{"move":{"x":-7,"y":2,"z":22},"block_id":98},{"move":{"x":-7,"y":2,"z":23},"block_id":5},{"move":{"x":-7,"y":2,"z":29},"block_id":98},{"move":{"x":-7,"y":2,"z":30},"block_id":106,"extra_data":{},"rotate":{"x":3,"y":0,"z":0}},{"move":{"x":-7,"y":3,"z":2},"block_id":106,"extra_data":{},"rotate":{"x":3,"y":0,"z":0}},{"move":{"x":-7,"y":3,"z":3},"block_id":98},{"move":{"x":-7,"y":3,"z":9},"block_id":106,"extra_data":{},"rotate":{"x":2,"y":0,"z":0}},{"move":{"x":-7,"y":3,"z":10},"block_id":98},{"move":{"x":-7,"y":3,"z":22},"block_id":98},{"move":{"x":-7,"y":3,"z":23},"block_id":106,"extra_data":{},"rotate":{"x":1,"y":0,"z":0}},{"move":{"x":-7,"y":3,"z":29},"block_id":98},{"move":{"x":-7,"y":3,"z":30},"block_id":106,"extra_data":{},"rotate":{"x":0,"y":0,"z":0}},{"move":{"x":-7,"y":4,"z":2},"block_id":106,"extra_data":{},"rotate":{"x":3,"y":0,"z":0}},{"move":{"x":-7,"y":4,"z":3},"block_id":615,"extra_data":{"point":{"x":0,"y":0.9,"z":0}},"rotate":{"x":0,"y":0,"z":0}},{"move":{"x":-7,"y":4,"z":9},"block_id":106,"extra_data":{},"rotate":{"x":2,"y":0,"z":0}},{"move":{"x":-7,"y":4,"z":10},"block_id":98},{"move":{"x":-7,"y":4,"z":11},"block_id":106,"extra_data":{},"rotate":{"x":0,"y":0,"z":0}},{"move":{"x":-7,"y":4,"z":22},"block_id":98},{"move":{"x":-7,"y":4,"z":29},"block_id":98},{"move":{"x":-7,"y":4,"z":30},"block_id":106,"extra_data":{},"rotate":{"x":0,"y":0,"z":0}},{"move":{"x":-7,"y":5,"z":1},"block_id":106,"extra_data":{},"rotate":{"x":3,"y":0,"z":0}},{"move":{"x":-7,"y":5,"z":3},"block_id":98},{"move":{"x":-7,"y":5,"z":10},"block_id":98},{"move":{"x":-7,"y":5,"z":22},"block_id":98},{"move":{"x":-7,"y":5,"z":23},"block_id":106,"extra_data":{},"rotate":{"x":1,"y":0,"z":0}},{"move":{"x":-7,"y":5,"z":29},"block_id":98},{"move":{"x":-7,"y":5,"z":31},"block_id":106,"extra_data":{},"rotate":{"x":3,"y":0,"z":0}},{"move":{"x":-7,"y":6,"z":3},"block_id":98},{"move":{"x":-7,"y":6,"z":4},"block_id":106,"extra_data":{},"rotate":{"x":1,"y":0,"z":0}},{"move":{"x":-7,"y":6,"z":10},"block_id":83},{"move":{"x":-7,"y":6,"z":22},"block_id":98},{"move":{"x":-7,"y":6,"z":23},"block_id":106,"extra_data":{},"rotate":{"x":1,"y":0,"z":0}},{"move":{"x":-7,"y":6,"z":29},"block_id":98},{"move":{"x":-7,"y":6,"z":31},"block_id":106,"extra_data":{},"rotate":{"x":3,"y":0,"z":0}},{"move":{"x":-7,"y":7,"z":2},"block_id":106,"extra_data":{},"rotate":{"x":2,"y":0,"z":0}},{"move":{"x":-7,"y":7,"z":3},"block_id":8},{"move":{"x":-7,"y":7,"z":22},"block_id":98},{"move":{"x":-7,"y":7,"z":23},"block_id":106,"extra_data":{},"rotate":{"x":1,"y":0,"z":0}},{"move":{"x":-7,"y":7,"z":29},"block_id":8},{"move":{"x":-7,"y":7,"z":30},"block_id":106,"extra_data":{},"rotate":{"x":0,"y":0,"z":0}},{"move":{"x":-7,"y":8,"z":2},"block_id":106,"extra_data":{},"rotate":{"x":2,"y":0,"z":0}},{"move":{"x":-7,"y":8,"z":3},"block_id":98},{"move":{"x":-7,"y":8,"z":22},"block_id":98},{"move":{"x":-7,"y":8,"z":29},"block_id":98},{"move":{"x":-7,"y":9,"z":2},"block_id":106,"extra_data":{},"rotate":{"x":2,"y":0,"z":0}},{"move":{"x":-7,"y":9,"z":3},"block_id":98},{"move":{"x":-7,"y":9,"z":29},"block_id":8},{"move":{"x":-7,"y":10,"z":2},"block_id":106,"extra_data":{},"rotate":{"x":2,"y":0,"z":0}},{"move":{"x":-7,"y":10,"z":3},"block_id":8},{"move":{"x":-7,"y":10,"z":29},"block_id":98},{"move":{"x":-7,"y":11,"z":2},"block_id":106,"extra_data":{},"rotate":{"x":2,"y":0,"z":0}},{"move":{"x":-7,"y":11,"z":3},"block_id":98},{"move":{"x":-7,"y":11,"z":4},"block_id":106,"extra_data":{},"rotate":{"x":0,"y":0,"z":0}},{"move":{"x":-7,"y":12,"z":2},"block_id":106,"extra_data":{},"rotate":{"x":2,"y":0,"z":0}},{"move":{"x":-7,"y":12,"z":3},"block_id":98},{"move":{"x":-7,"y":13,"z":3},"block_id":98},{"move":{"x":-7,"y":14,"z":3},"block_id":98},{"move":{"x":-6,"y":-1,"z":3},"block_id":2},{"move":{"x":-6,"y":-1,"z":4},"block_id":18},{"move":{"x":-6,"y":-1,"z":5},"block_id":18},{"move":{"x":-6,"y":-1,"z":6},"block_id":18},{"move":{"x":-6,"y":-1,"z":7},"block_id":18},{"move":{"x":-6,"y":-1,"z":8},"block_id":18},{"move":{"x":-6,"y":-1,"z":9},"block_id":18},{"move":{"x":-6,"y":-1,"z":10},"block_id":18},{"move":{"x":-6,"y":-1,"z":11},"block_id":18},{"move":{"x":-6,"y":-1,"z":12},"block_id":18},{"move":{"x":-6,"y":-1,"z":13},"block_id":2},{"move":{"x":-6,"y":-1,"z":14},"block_id":2},{"move":{"x":-6,"y":-1,"z":15},"block_id":2},{"move":{"x":-6,"y":-1,"z":16},"block_id":18},{"move":{"x":-6,"y":-1,"z":17},"block_id":18},{"move":{"x":-6,"y":-1,"z":18},"block_id":18},{"move":{"x":-6,"y":-1,"z":19},"block_id":18},{"move":{"x":-6,"y":-1,"z":20},"block_id":2},{"move":{"x":-6,"y":-1,"z":21},"block_id":18},{"move":{"x":-6,"y":-1,"z":22},"block_id":18},{"move":{"x":-6,"y":-1,"z":23},"block_id":18},{"move":{"x":-6,"y":-1,"z":24},"block_id":18},{"move":{"x":-6,"y":-1,"z":25},"block_id":18},{"move":{"x":-6,"y":-1,"z":26},"block_id":18},{"move":{"x":-6,"y":-1,"z":27},"block_id":18},{"move":{"x":-6,"y":-1,"z":28},"block_id":18},{"move":{"x":-6,"y":-1,"z":29},"block_id":2},{"move":{"x":-6,"y":0,"z":4},"block_id":8},{"move":{"x":-6,"y":0,"z":5},"block_id":146},{"move":{"x":-6,"y":0,"z":6},"block_id":8},{"move":{"x":-6,"y":0,"z":7},"block_id":8},{"move":{"x":-6,"y":0,"z":8},"block_id":146},{"move":{"x":-6,"y":0,"z":9},"block_id":8},{"move":{"x":-6,"y":0,"z":10},"block_id":8},{"move":{"x":-6,"y":0,"z":11},"block_id":8},{"move":{"x":-6,"y":0,"z":12},"block_id":8},{"move":{"x":-6,"y":0,"z":16},"block_id":8},{"move":{"x":-6,"y":0,"z":17},"block_id":98},{"move":{"x":-6,"y":0,"z":18},"block_id":8},{"move":{"x":-6,"y":0,"z":19},"block_id":8},{"move":{"x":-6,"y":0,"z":20},"block_id":67,"extra_data":{"point":{"x":0,"y":0.1,"z":0}},"rotate":{"x":2,"y":0,"z":0}},{"move":{"x":-6,"y":0,"z":21},"block_id":8},{"move":{"x":-6,"y":0,"z":22},"block_id":8},{"move":{"x":-6,"y":0,"z":23},"block_id":8},{"move":{"x":-6,"y":0,"z":24},"block_id":8},{"move":{"x":-6,"y":0,"z":25},"block_id":8},{"move":{"x":-6,"y":0,"z":26},"block_id":8},{"move":{"x":-6,"y":0,"z":27},"block_id":8},{"move":{"x":-6,"y":0,"z":28},"block_id":8},{"move":{"x":-6,"y":1,"z":4},"block_id":8},{"move":{"x":-6,"y":1,"z":5},"block_id":61,"extra_data":{"can_destroy":true,"slots":{},"lit":false,"state":{"fuel_time":0,"result_ticks":0,"result_percent":0},"active":false},"rotate":{"x":3,"y":0,"z":0}},{"move":{"x":-6,"y":1,"z":6},"block_id":61,"extra_data":{"can_destroy":true,"slots":{},"lit":false,"state":{"fuel_time":0,"result_ticks":0,"result_percent":0},"active":false},"rotate":{"x":3,"y":0,"z":0}},{"move":{"x":-6,"y":1,"z":7},"block_id":61,"extra_data":{"can_destroy":true,"slots":{},"lit":false,"state":{"fuel_time":0,"result_ticks":0,"result_percent":0},"active":false},"rotate":{"x":3,"y":0,"z":0}},{"move":{"x":-6,"y":1,"z":9},"block_id":8},{"move":{"x":-6,"y":1,"z":10},"block_id":8},{"move":{"x":-6,"y":1,"z":11},"block_id":8},{"move":{"x":-6,"y":1,"z":17},"block_id":98},{"move":{"x":-6,"y":1,"z":18},"block_id":106,"extra_data":{},"rotate":{"x":1,"y":0,"z":0}},{"move":{"x":-6,"y":1,"z":22},"block_id":106,"extra_data":{},"rotate":{"x":2,"y":0,"z":0}},{"move":{"x":-6,"y":1,"z":23},"block_id":83},{"move":{"x":-6,"y":1,"z":25},"block_id":106,"extra_data":{},"rotate":{"x":1,"y":0,"z":0}},{"move":{"x":-6,"y":1,"z":27},"block_id":106,"extra_data":{},"rotate":{"x":2,"y":0,"z":0}},{"move":{"x":-6,"y":1,"z":28},"block_id":8},{"move":{"x":-6,"y":2,"z":4},"block_id":98},{"move":{"x":-6,"y":2,"z":5},"block_id":61,"extra_data":{"can_destroy":true,"slots":{},"lit":false,"state":{"fuel_time":0,"result_ticks":0,"result_percent":0},"active":false},"rotate":{"x":3,"y":0,"z":0}},{"move":{"x":-6,"y":2,"z":6},"block_id":61,"extra_data":{"can_destroy":true,"slots":{},"lit":false,"state":{"fuel_time":0,"result_ticks":0,"result_percent":0},"active":false},"rotate":{"x":3,"y":0,"z":0}},{"move":{"x":-6,"y":2,"z":7},"block_id":61,"extra_data":{"can_destroy":true,"slots":{},"lit":false,"state":{"fuel_time":0,"result_ticks":0,"result_percent":0},"active":false},"rotate":{"x":3,"y":0,"z":0}},{"move":{"x":-6,"y":2,"z":9},"block_id":98},{"move":{"x":-6,"y":2,"z":10},"block_id":106,"extra_data":{},"rotate":{"x":3,"y":0,"z":0}},{"move":{"x":-6,"y":2,"z":23},"block_id":98},{"move":{"x":-6,"y":2,"z":26},"block_id":106,"extra_data":{},"rotate":{"x":1,"y":0,"z":0}},{"move":{"x":-6,"y":2,"z":28},"block_id":98},{"move":{"x":-6,"y":2,"z":29},"block_id":85},{"move":{"x":-6,"y":3,"z":3},"block_id":106,"extra_data":{},"rotate":{"x":3,"y":0,"z":0}},{"move":{"x":-6,"y":3,"z":4},"block_id":98},{"move":{"x":-6,"y":3,"z":5},"block_id":106,"extra_data":{},"rotate":{"x":1,"y":0,"z":0}},{"move":{"x":-6,"y":3,"z":9},"block_id":98},{"move":{"x":-6,"y":3,"z":10},"block_id":106,"extra_data":{},"rotate":{"x":3,"y":0,"z":0}},{"move":{"x":-6,"y":3,"z":23},"block_id":98},{"move":{"x":-6,"y":3,"z":26},"block_id":106,"extra_data":{},"rotate":{"x":1,"y":0,"z":0}},{"move":{"x":-6,"y":3,"z":28},"block_id":98},{"move":{"x":-6,"y":4,"z":3},"block_id":106,"extra_data":{},"rotate":{"x":3,"y":0,"z":0}},{"move":{"x":-6,"y":4,"z":4},"block_id":98},{"move":{"x":-6,"y":4,"z":5},"block_id":106,"extra_data":{},"rotate":{"x":1,"y":0,"z":0}},{"move":{"x":-6,"y":4,"z":9},"block_id":98},{"move":{"x":-6,"y":4,"z":23},"block_id":98},{"move":{"x":-6,"y":4,"z":26},"block_id":106,"extra_data":{},"rotate":{"x":1,"y":0,"z":0}},{"move":{"x":-6,"y":4,"z":27},"block_id":106,"extra_data":{},"rotate":{"x":1,"y":0,"z":0}},{"move":{"x":-6,"y":4,"z":28},"block_id":98},{"move":{"x":-6,"y":5,"z":3},"block_id":106,"extra_data":{},"rotate":{"x":3,"y":0,"z":0}},{"move":{"x":-6,"y":5,"z":4},"block_id":98},{"move":{"x":-6,"y":5,"z":9},"block_id":632},{"move":{"x":-6,"y":5,"z":22},"block_id":106,"extra_data":{},"rotate":{"x":3,"y":0,"z":0}},{"move":{"x":-6,"y":5,"z":23},"block_id":98},{"move":{"x":-6,"y":5,"z":24},"block_id":106,"extra_data":{},"rotate":{"x":0,"y":0,"z":0}},{"move":{"x":-6,"y":5,"z":26},"block_id":106,"extra_data":{},"rotate":{"x":1,"y":0,"z":0}},{"move":{"x":-6,"y":5,"z":27},"block_id":106,"extra_data":{},"rotate":{"x":1,"y":0,"z":0}},{"move":{"x":-6,"y":5,"z":28},"block_id":98},{"move":{"x":-6,"y":5,"z":29},"block_id":106,"extra_data":{},"rotate":{"x":3,"y":0,"z":0}},{"move":{"x":-6,"y":6,"z":3},"block_id":106,"extra_data":{},"rotate":{"x":3,"y":0,"z":0}},{"move":{"x":-6,"y":6,"z":4},"block_id":98},{"move":{"x":-6,"y":6,"z":22},"block_id":106,"extra_data":{},"rotate":{"x":3,"y":0,"z":0}},{"move":{"x":-6,"y":6,"z":23},"block_id":98},{"move":{"x":-6,"y":6,"z":24},"block_id":106,"extra_data":{},"rotate":{"x":1,"y":0,"z":0}},{"move":{"x":-6,"y":6,"z":25},"block_id":106,"extra_data":{},"rotate":{"x":1,"y":0,"z":0}},{"move":{"x":-6,"y":6,"z":26},"block_id":106,"extra_data":{},"rotate":{"x":1,"y":0,"z":0}},{"move":{"x":-6,"y":6,"z":28},"block_id":98},{"move":{"x":-6,"y":6,"z":29},"block_id":106,"extra_data":{},"rotate":{"x":3,"y":0,"z":0}},{"move":{"x":-6,"y":7,"z":4},"block_id":8},{"move":{"x":-6,"y":7,"z":23},"block_id":98},{"move":{"x":-6,"y":7,"z":25},"block_id":106,"extra_data":{},"rotate":{"x":1,"y":0,"z":0}},{"move":{"x":-6,"y":7,"z":26},"block_id":106,"extra_data":{},"rotate":{"x":1,"y":0,"z":0}},{"move":{"x":-6,"y":7,"z":28},"block_id":8},{"move":{"x":-6,"y":7,"z":29},"block_id":106,"extra_data":{},"rotate":{"x":3,"y":0,"z":0}},{"move":{"x":-6,"y":8,"z":3},"block_id":106,"extra_data":{},"rotate":{"x":3,"y":0,"z":0}},{"move":{"x":-6,"y":8,"z":4},"block_id":98},{"move":{"x":-6,"y":8,"z":22},"block_id":106,"extra_data":{},"rotate":{"x":3,"y":0,"z":0}},{"move":{"x":-6,"y":8,"z":23},"block_id":98},{"move":{"x":-6,"y":8,"z":28},"block_id":98},{"move":{"x":-6,"y":8,"z":29},"block_id":106,"extra_data":{},"rotate":{"x":3,"y":0,"z":0}},{"move":{"x":-6,"y":9,"z":3},"block_id":106,"extra_data":{},"rotate":{"x":3,"y":0,"z":0}},{"move":{"x":-6,"y":9,"z":4},"block_id":98},{"move":{"x":-6,"y":9,"z":23},"block_id":98},{"move":{"x":-6,"y":9,"z":25},"block_id":106,"extra_data":{},"rotate":{"x":1,"y":0,"z":0}},{"move":{"x":-6,"y":9,"z":28},"block_id":8},{"move":{"x":-6,"y":10,"z":28},"block_id":98},{"move":{"x":-6,"y":11,"z":28},"block_id":98},{"move":{"x":-5,"y":-1,"z":4},"block_id":2},{"move":{"x":-5,"y":-1,"z":5},"block_id":18},{"move":{"x":-5,"y":-1,"z":6},"block_id":18},{"move":{"x":-5,"y":-1,"z":7},"block_id":18},{"move":{"x":-5,"y":-1,"z":8},"block_id":2},{"move":{"x":-5,"y":-1,"z":9},"block_id":2},{"move":{"x":-5,"y":-1,"z":10},"block_id":2},{"move":{"x":-5,"y":-1,"z":11},"block_id":2},{"move":{"x":-5,"y":-1,"z":12},"block_id":2},{"move":{"x":-5,"y":-1,"z":13},"block_id":2},{"move":{"x":-5,"y":-1,"z":14},"block_id":2},{"move":{"x":-5,"y":-1,"z":15},"block_id":2},{"move":{"x":-5,"y":-1,"z":16},"block_id":2},{"move":{"x":-5,"y":-1,"z":17},"block_id":2},{"move":{"x":-5,"y":-1,"z":18},"block_id":18},{"move":{"x":-5,"y":-1,"z":19},"block_id":18},{"move":{"x":-5,"y":-1,"z":20},"block_id":18},{"move":{"x":-5,"y":-1,"z":21},"block_id":18},{"move":{"x":-5,"y":-1,"z":22},"block_id":18},{"move":{"x":-5,"y":-1,"z":23},"block_id":18},{"move":{"x":-5,"y":-1,"z":24},"block_id":18},{"move":{"x":-5,"y":-1,"z":25},"block_id":18},{"move":{"x":-5,"y":-1,"z":26},"block_id":18},{"move":{"x":-5,"y":-1,"z":27},"block_id":18},{"move":{"x":-5,"y":-1,"z":28},"block_id":2},{"move":{"x":-5,"y":0,"z":4},"block_id":106,"extra_data":{},"rotate":{"x":2,"y":0,"z":0}},{"move":{"x":-5,"y":0,"z":5},"block_id":146},{"move":{"x":-5,"y":0,"z":6},"block_id":18},{"move":{"x":-5,"y":0,"z":7},"block_id":8},{"move":{"x":-5,"y":0,"z":18},"block_id":98},{"move":{"x":-5,"y":0,"z":19},"block_id":98},{"move":{"x":-5,"y":0,"z":20},"block_id":8},{"move":{"x":-5,"y":0,"z":21},"block_id":8},{"move":{"x":-5,"y":0,"z":22},"block_id":8},{"move":{"x":-5,"y":0,"z":23},"block_id":8},{"move":{"x":-5,"y":0,"z":24},"block_id":8},{"move":{"x":-5,"y":0,"z":25},"block_id":8},{"move":{"x":-5,"y":0,"z":26},"block_id":8},{"move":{"x":-5,"y":0,"z":27},"block_id":8},{"move":{"x":-5,"y":0,"z":28},"block_id":106,"extra_data":{},"rotate":{"x":3,"y":0,"z":0}},{"move":{"x":-5,"y":1,"z":4},"block_id":106,"extra_data":{},"rotate":{"x":2,"y":0,"z":0}},{"move":{"x":-5,"y":1,"z":5},"block_id":8},{"move":{"x":-5,"y":1,"z":6},"block_id":8},{"move":{"x":-5,"y":1,"z":18},"block_id":98},{"move":{"x":-5,"y":1,"z":23},"block_id":8},{"move":{"x":-5,"y":1,"z":24},"block_id":106,"extra_data":{},"rotate":{"x":2,"y":0,"z":0}},{"move":{"x":-5,"y":1,"z":25},"block_id":8},{"move":{"x":-5,"y":1,"z":26},"block_id":8},{"move":{"x":-5,"y":1,"z":27},"block_id":8},{"move":{"x":-5,"y":1,"z":28},"block_id":106,"extra_data":{},"rotate":{"x":3,"y":0,"z":0}},{"move":{"x":-5,"y":2,"z":4},"block_id":106,"extra_data":{},"rotate":{"x":2,"y":0,"z":0}},{"move":{"x":-5,"y":2,"z":5},"block_id":8},{"move":{"x":-5,"y":2,"z":6},"block_id":8},{"move":{"x":-5,"y":2,"z":23},"block_id":8},{"move":{"x":-5,"y":2,"z":25},"block_id":98},{"move":{"x":-5,"y":2,"z":26},"block_id":98},{"move":{"x":-5,"y":2,"z":27},"block_id":98},{"move":{"x":-5,"y":2,"z":28},"block_id":106,"extra_data":{},"rotate":{"x":3,"y":0,"z":0}},{"move":{"x":-5,"y":3,"z":4},"block_id":106,"extra_data":{},"rotate":{"x":2,"y":0,"z":0}},{"move":{"x":-5,"y":3,"z":5},"block_id":98},{"move":{"x":-5,"y":3,"z":23},"block_id":8},{"move":{"x":-5,"y":3,"z":25},"block_id":98},{"move":{"x":-5,"y":3,"z":26},"block_id":98},{"move":{"x":-5,"y":3,"z":27},"block_id":98},{"move":{"x":-5,"y":3,"z":28},"block_id":106,"extra_data":{},"rotate":{"x":0,"y":0,"z":0}},{"move":{"x":-5,"y":4,"z":5},"block_id":98},{"move":{"x":-5,"y":4,"z":23},"block_id":8},{"move":{"x":-5,"y":4,"z":24},"block_id":98},{"move":{"x":-5,"y":4,"z":25},"block_id":98},{"move":{"x":-5,"y":4,"z":26},"block_id":98},{"move":{"x":-5,"y":4,"z":27},"block_id":98},{"move":{"x":-5,"y":4,"z":28},"block_id":106,"extra_data":{},"rotate":{"x":0,"y":0,"z":0}},{"move":{"x":-5,"y":5,"z":23},"block_id":30},{"move":{"x":-5,"y":5,"z":24},"block_id":98},{"move":{"x":-5,"y":5,"z":25},"block_id":98},{"move":{"x":-5,"y":5,"z":26},"block_id":8},{"move":{"x":-5,"y":5,"z":27},"block_id":98},{"move":{"x":-5,"y":6,"z":23},"block_id":106,"extra_data":{},"rotate":{"x":2,"y":0,"z":0}},{"move":{"x":-5,"y":6,"z":24},"block_id":98},{"move":{"x":-5,"y":6,"z":25},"block_id":98},{"move":{"x":-5,"y":6,"z":26},"block_id":98},{"move":{"x":-5,"y":6,"z":27},"block_id":98},{"move":{"x":-5,"y":6,"z":28},"block_id":106,"extra_data":{},"rotate":{"x":0,"y":0,"z":0}},{"move":{"x":-5,"y":7,"z":23},"block_id":106,"extra_data":{},"rotate":{"x":2,"y":0,"z":0}},{"move":{"x":-5,"y":7,"z":24},"block_id":98},{"move":{"x":-5,"y":7,"z":25},"block_id":8},{"move":{"x":-5,"y":7,"z":26},"block_id":8},{"move":{"x":-5,"y":7,"z":27},"block_id":8},{"move":{"x":-5,"y":7,"z":28},"block_id":106,"extra_data":{},"rotate":{"x":0,"y":0,"z":0}},{"move":{"x":-5,"y":8,"z":24},"block_id":98},{"move":{"x":-5,"y":8,"z":25},"block_id":98},{"move":{"x":-5,"y":8,"z":26},"block_id":98},{"move":{"x":-5,"y":8,"z":27},"block_id":98},{"move":{"x":-5,"y":8,"z":28},"block_id":106,"extra_data":{},"rotate":{"x":0,"y":0,"z":0}},{"move":{"x":-5,"y":9,"z":24},"block_id":98},{"move":{"x":-5,"y":9,"z":25},"block_id":8},{"move":{"x":-5,"y":9,"z":26},"block_id":98},{"move":{"x":-5,"y":9,"z":27},"block_id":8},{"move":{"x":-5,"y":10,"z":24},"block_id":98},{"move":{"x":-5,"y":10,"z":25},"block_id":98},{"move":{"x":-5,"y":10,"z":27},"block_id":98},{"move":{"x":-4,"y":-1,"z":4},"block_id":2},{"move":{"x":-4,"y":-1,"z":5},"block_id":18},{"move":{"x":-4,"y":-1,"z":6},"block_id":18},{"move":{"x":-4,"y":-1,"z":7},"block_id":18},{"move":{"x":-4,"y":-1,"z":8},"block_id":18},{"move":{"x":-4,"y":-1,"z":9},"block_id":2},{"move":{"x":-4,"y":-1,"z":10},"block_id":2},{"move":{"x":-4,"y":-1,"z":11},"block_id":2},{"move":{"x":-4,"y":-1,"z":12},"block_id":2},{"move":{"x":-4,"y":-1,"z":13},"block_id":2},{"move":{"x":-4,"y":-1,"z":14},"block_id":2},{"move":{"x":-4,"y":-1,"z":15},"block_id":2},{"move":{"x":-4,"y":-1,"z":16},"block_id":2},{"move":{"x":-4,"y":-1,"z":17},"block_id":2},{"move":{"x":-4,"y":-1,"z":18},"block_id":18},{"move":{"x":-4,"y":-1,"z":19},"block_id":18},{"move":{"x":-4,"y":-1,"z":20},"block_id":18},{"move":{"x":-4,"y":-1,"z":21},"block_id":18},{"move":{"x":-4,"y":-1,"z":22},"block_id":18},{"move":{"x":-4,"y":-1,"z":23},"block_id":18},{"move":{"x":-4,"y":-1,"z":24},"block_id":18},{"move":{"x":-4,"y":-1,"z":25},"block_id":18},{"move":{"x":-4,"y":-1,"z":26},"block_id":18},{"move":{"x":-4,"y":-1,"z":27},"block_id":18},{"move":{"x":-4,"y":-1,"z":28},"block_id":2},{"move":{"x":-4,"y":0,"z":5},"block_id":18},{"move":{"x":-4,"y":0,"z":6},"block_id":2},{"move":{"x":-4,"y":0,"z":7},"block_id":2},{"move":{"x":-4,"y":0,"z":8},"block_id":2},{"move":{"x":-4,"y":0,"z":18},"block_id":8},{"move":{"x":-4,"y":0,"z":19},"block_id":8},{"move":{"x":-4,"y":0,"z":20},"block_id":8},{"move":{"x":-4,"y":0,"z":21},"block_id":8},{"move":{"x":-4,"y":0,"z":22},"block_id":8},{"move":{"x":-4,"y":0,"z":23},"block_id":8},{"move":{"x":-4,"y":0,"z":24},"block_id":146},{"move":{"x":-4,"y":0,"z":25},"block_id":8},{"move":{"x":-4,"y":0,"z":26},"block_id":2},{"move":{"x":-4,"y":0,"z":27},"block_id":146},{"move":{"x":-4,"y":0,"z":28},"block_id":106,"extra_data":{},"rotate":{"x":0,"y":0,"z":0}},{"move":{"x":-4,"y":0,"z":29},"block_id":106,"extra_data":{},"rotate":{"x":1,"y":0,"z":0}},{"move":{"x":-4,"y":1,"z":5},"block_id":8},{"move":{"x":-4,"y":1,"z":18},"block_id":8},{"move":{"x":-4,"y":1,"z":19},"block_id":8},{"move":{"x":-4,"y":1,"z":22},"block_id":106,"extra_data":{},"rotate":{"x":2,"y":0,"z":0}},{"move":{"x":-4,"y":1,"z":23},"block_id":8},{"move":{"x":-4,"y":1,"z":24},"block_id":98},{"move":{"x":-4,"y":1,"z":25},"block_id":8},{"move":{"x":-4,"y":1,"z":26},"block_id":30},{"move":{"x":-4,"y":1,"z":27},"block_id":8},{"move":{"x":-4,"y":1,"z":28},"block_id":106,"extra_data":{},"rotate":{"x":0,"y":0,"z":0}},{"move":{"x":-4,"y":2,"z":5},"block_id":8},{"move":{"x":-4,"y":2,"z":22},"block_id":106,"extra_data":{},"rotate":{"x":2,"y":0,"z":0}},{"move":{"x":-4,"y":2,"z":23},"block_id":8},{"move":{"x":-4,"y":2,"z":24},"block_id":98},{"move":{"x":-4,"y":2,"z":25},"block_id":8},{"move":{"x":-4,"y":2,"z":26},"block_id":106,"extra_data":{},"rotate":{"x":2,"y":0,"z":0}},{"move":{"x":-4,"y":2,"z":27},"block_id":8},{"move":{"x":-4,"y":2,"z":28},"block_id":106,"extra_data":{},"rotate":{"x":0,"y":0,"z":0}},{"move":{"x":-4,"y":3,"z":22},"block_id":106,"extra_data":{},"rotate":{"x":2,"y":0,"z":0}},{"move":{"x":-4,"y":3,"z":23},"block_id":8},{"move":{"x":-4,"y":3,"z":24},"block_id":98},{"move":{"x":-4,"y":3,"z":25},"block_id":8},{"move":{"x":-4,"y":3,"z":26},"block_id":106,"extra_data":{},"rotate":{"x":0,"y":0,"z":0}},{"move":{"x":-4,"y":3,"z":27},"block_id":8},{"move":{"x":-4,"y":3,"z":28},"block_id":106,"extra_data":{},"rotate":{"x":0,"y":0,"z":0}},{"move":{"x":-4,"y":4,"z":23},"block_id":8},{"move":{"x":-4,"y":4,"z":25},"block_id":8},{"move":{"x":-4,"y":4,"z":26},"block_id":106,"extra_data":{},"rotate":{"x":0,"y":0,"z":0}},{"move":{"x":-4,"y":4,"z":27},"block_id":8},{"move":{"x":-4,"y":4,"z":28},"block_id":106,"extra_data":{},"rotate":{"x":0,"y":0,"z":0}},{"move":{"x":-4,"y":5,"z":25},"block_id":8},{"move":{"x":-4,"y":5,"z":26},"block_id":106,"extra_data":{},"rotate":{"x":0,"y":0,"z":0}},{"move":{"x":-4,"y":5,"z":27},"block_id":8},{"move":{"x":-4,"y":5,"z":28},"block_id":106,"extra_data":{},"rotate":{"x":0,"y":0,"z":0}},{"move":{"x":-4,"y":6,"z":25},"block_id":8},{"move":{"x":-4,"y":6,"z":26},"block_id":106,"extra_data":{},"rotate":{"x":0,"y":0,"z":0}},{"move":{"x":-4,"y":6,"z":27},"block_id":8},{"move":{"x":-4,"y":7,"z":25},"block_id":106,"extra_data":{},"rotate":{"x":3,"y":0,"z":0}},{"move":{"x":-4,"y":9,"z":27},"block_id":106,"extra_data":{},"rotate":{"x":3,"y":0,"z":0}},{"move":{"x":-3,"y":-1,"z":5},"block_id":18},{"move":{"x":-3,"y":-1,"z":7},"block_id":18},{"move":{"x":-3,"y":-1,"z":8},"block_id":18},{"move":{"x":-3,"y":-1,"z":9},"block_id":18},{"move":{"x":-3,"y":-1,"z":10},"block_id":2},{"move":{"x":-3,"y":-1,"z":11},"block_id":2},{"move":{"x":-3,"y":-1,"z":12},"block_id":2},{"move":{"x":-3,"y":-1,"z":13},"block_id":2},{"move":{"x":-3,"y":-1,"z":14},"block_id":2},{"move":{"x":-3,"y":-1,"z":15},"block_id":2},{"move":{"x":-3,"y":-1,"z":16},"block_id":2},{"move":{"x":-3,"y":-1,"z":17},"block_id":2},{"move":{"x":-3,"y":-1,"z":18},"block_id":2},{"move":{"x":-3,"y":-1,"z":19},"block_id":18},{"move":{"x":-3,"y":-1,"z":20},"block_id":18},{"move":{"x":-3,"y":-1,"z":21},"block_id":18},{"move":{"x":-3,"y":-1,"z":22},"block_id":18},{"move":{"x":-3,"y":-1,"z":23},"block_id":18},{"move":{"x":-3,"y":-1,"z":24},"block_id":18},{"move":{"x":-3,"y":-1,"z":25},"block_id":18},{"move":{"x":-3,"y":-1,"z":26},"block_id":18},{"move":{"x":-3,"y":-1,"z":27},"block_id":18},{"move":{"x":-3,"y":0,"z":4},"block_id":2},{"move":{"x":-3,"y":0,"z":5},"block_id":2},{"move":{"x":-3,"y":0,"z":6},"block_id":2},{"move":{"x":-3,"y":0,"z":7},"block_id":2},{"move":{"x":-3,"y":0,"z":8},"block_id":2},{"move":{"x":-3,"y":0,"z":9},"block_id":2},{"move":{"x":-3,"y":0,"z":19},"block_id":8},{"move":{"x":-3,"y":0,"z":20},"block_id":8},{"move":{"x":-3,"y":0,"z":21},"block_id":8},{"move":{"x":-3,"y":0,"z":22},"block_id":8},{"move":{"x":-3,"y":0,"z":23},"block_id":8},{"move":{"x":-3,"y":0,"z":24},"block_id":8},{"move":{"x":-3,"y":0,"z":25},"block_id":8},{"move":{"x":-3,"y":0,"z":26},"block_id":2},{"move":{"x":-3,"y":0,"z":27},"block_id":2},{"move":{"x":-3,"y":0,"z":28},"block_id":2},{"move":{"x":-3,"y":0,"z":29},"block_id":2},{"move":{"x":-3,"y":1,"z":19},"block_id":67,"extra_data":{"point":{"x":0,"y":0.9,"z":0}},"rotate":{"x":1,"y":0,"z":0}},{"move":{"x":-3,"y":1,"z":20},"block_id":146},{"move":{"x":-3,"y":1,"z":23},"block_id":146},{"move":{"x":-3,"y":1,"z":24},"block_id":83},{"move":{"x":-3,"y":1,"z":25},"block_id":146},{"move":{"x":-3,"y":1,"z":26},"block_id":106,"extra_data":{},"rotate":{"x":0,"y":0,"z":0}},{"move":{"x":-3,"y":2,"z":23},"block_id":8},{"move":{"x":-3,"y":2,"z":24},"block_id":83},{"move":{"x":-3,"y":2,"z":25},"block_id":8},{"move":{"x":-3,"y":2,"z":26},"block_id":106,"extra_data":{},"rotate":{"x":0,"y":0,"z":0}},{"move":{"x":-3,"y":2,"z":27},"block_id":106,"extra_data":{},"rotate":{"x":3,"y":0,"z":0}},{"move":{"x":-3,"y":3,"z":23},"block_id":8},{"move":{"x":-3,"y":3,"z":24},"block_id":98},{"move":{"x":-3,"y":3,"z":25},"block_id":8},{"move":{"x":-3,"y":3,"z":26},"block_id":106,"extra_data":{},"rotate":{"x":0,"y":0,"z":0}},{"move":{"x":-3,"y":3,"z":27},"block_id":106,"extra_data":{},"rotate":{"x":3,"y":0,"z":0}},{"move":{"x":-3,"y":4,"z":23},"block_id":8},{"move":{"x":-3,"y":4,"z":25},"block_id":8},{"move":{"x":-3,"y":4,"z":27},"block_id":106,"extra_data":{},"rotate":{"x":3,"y":0,"z":0}},{"move":{"x":-3,"y":5,"z":25},"block_id":106,"extra_data":{},"rotate":{"x":3,"y":0,"z":0}},{"move":{"x":-2,"y":-1,"z":2},"block_id":2},{"move":{"x":-2,"y":-1,"z":3},"block_id":18},{"move":{"x":-2,"y":-1,"z":4},"block_id":18},{"move":{"x":-2,"y":-1,"z":5},"block_id":18},{"move":{"x":-2,"y":-1,"z":6},"block_id":18},{"move":{"x":-2,"y":-1,"z":7},"block_id":18},{"move":{"x":-2,"y":-1,"z":8},"block_id":18},{"move":{"x":-2,"y":-1,"z":9},"block_id":18},{"move":{"x":-2,"y":-1,"z":10},"block_id":2},{"move":{"x":-2,"y":-1,"z":11},"block_id":2},{"move":{"x":-2,"y":-1,"z":12},"block_id":2},{"move":{"x":-2,"y":-1,"z":13},"block_id":2},{"move":{"x":-2,"y":-1,"z":14},"block_id":2},{"move":{"x":-2,"y":-1,"z":15},"block_id":2},{"move":{"x":-2,"y":-1,"z":16},"block_id":2},{"move":{"x":-2,"y":-1,"z":17},"block_id":2},{"move":{"x":-2,"y":-1,"z":18},"block_id":2},{"move":{"x":-2,"y":-1,"z":19},"block_id":2},{"move":{"x":-2,"y":-1,"z":20},"block_id":18},{"move":{"x":-2,"y":-1,"z":21},"block_id":18},{"move":{"x":-2,"y":-1,"z":22},"block_id":18},{"move":{"x":-2,"y":-1,"z":23},"block_id":18},{"move":{"x":-2,"y":-1,"z":24},"block_id":18},{"move":{"x":-2,"y":-1,"z":25},"block_id":18},{"move":{"x":-2,"y":-1,"z":26},"block_id":18},{"move":{"x":-2,"y":-1,"z":27},"block_id":18},{"move":{"x":-2,"y":-1,"z":28},"block_id":18},{"move":{"x":-2,"y":-1,"z":29},"block_id":18},{"move":{"x":-2,"y":-1,"z":30},"block_id":18},{"move":{"x":-2,"y":0,"z":3},"block_id":2},{"move":{"x":-2,"y":0,"z":4},"block_id":2},{"move":{"x":-2,"y":0,"z":5},"block_id":2},{"move":{"x":-2,"y":0,"z":6},"block_id":2},{"move":{"x":-2,"y":0,"z":7},"block_id":2},{"move":{"x":-2,"y":0,"z":8},"block_id":2},{"move":{"x":-2,"y":0,"z":9},"block_id":2},{"move":{"x":-2,"y":0,"z":20},"block_id":8},{"move":{"x":-2,"y":0,"z":21},"block_id":8},{"move":{"x":-2,"y":0,"z":22},"block_id":8},{"move":{"x":-2,"y":0,"z":23},"block_id":8},{"move":{"x":-2,"y":0,"z":24},"block_id":8},{"move":{"x":-2,"y":0,"z":25},"block_id":8},{"move":{"x":-2,"y":0,"z":26},"block_id":18},{"move":{"x":-2,"y":0,"z":27},"block_id":18},{"move":{"x":-2,"y":0,"z":28},"block_id":2},{"move":{"x":-2,"y":0,"z":29},"block_id":2},{"move":{"x":-2,"y":0,"z":30},"block_id":2},{"move":{"x":-2,"y":1,"z":20},"block_id":8},{"move":{"x":-2,"y":1,"z":21},"block_id":8},{"move":{"x":-2,"y":1,"z":23},"block_id":8},{"move":{"x":-2,"y":1,"z":24},"block_id":106,"extra_data":{},"rotate":{"x":2,"y":0,"z":0}},{"move":{"x":-2,"y":1,"z":25},"block_id":8},{"move":{"x":-2,"y":1,"z":26},"block_id":7},{"move":{"x":-2,"y":1,"z":27},"block_id":7},{"move":{"x":-2,"y":2,"z":21},"block_id":106,"extra_data":{},"rotate":{"x":1,"y":0,"z":0}},{"move":{"x":-2,"y":2,"z":23},"block_id":8},{"move":{"x":-2,"y":2,"z":24},"block_id":106,"extra_data":{},"rotate":{"x":2,"y":0,"z":0}},{"move":{"x":-2,"y":2,"z":25},"block_id":8},{"move":{"x":-2,"y":2,"z":26},"block_id":7},{"move":{"x":-2,"y":2,"z":27},"block_id":7},{"move":{"x":-2,"y":3,"z":22},"block_id":106,"extra_data":{},"rotate":{"x":1,"y":0,"z":0}},{"move":{"x":-2,"y":3,"z":23},"block_id":8},{"move":{"x":-2,"y":3,"z":24},"block_id":98},{"move":{"x":-2,"y":3,"z":25},"block_id":8},{"move":{"x":-2,"y":4,"z":23},"block_id":8},{"move":{"x":-2,"y":4,"z":24},"block_id":98},{"move":{"x":-2,"y":4,"z":25},"block_id":8},{"move":{"x":-2,"y":5,"z":24},"block_id":98},{"move":{"x":-2,"y":5,"z":25},"block_id":106,"extra_data":{},"rotate":{"x":0,"y":0,"z":0}},{"move":{"x":-2,"y":6,"z":24},"block_id":98},{"move":{"x":-1,"y":-1,"z":1},"block_id":2},{"move":{"x":-1,"y":-1,"z":2},"block_id":2},{"move":{"x":-1,"y":-1,"z":3},"block_id":2},{"move":{"x":-1,"y":-1,"z":4},"block_id":18},{"move":{"x":-1,"y":-1,"z":5},"block_id":18},{"move":{"x":-1,"y":-1,"z":6},"block_id":18},{"move":{"x":-1,"y":-1,"z":7},"block_id":18},{"move":{"x":-1,"y":-1,"z":8},"block_id":2},{"move":{"x":-1,"y":-1,"z":9},"block_id":2},{"move":{"x":-1,"y":-1,"z":10},"block_id":2},{"move":{"x":-1,"y":-1,"z":11},"block_id":2},{"move":{"x":-1,"y":-1,"z":12},"block_id":2},{"move":{"x":-1,"y":-1,"z":13},"block_id":2},{"move":{"x":-1,"y":-1,"z":14},"block_id":2},{"move":{"x":-1,"y":-1,"z":15},"block_id":2},{"move":{"x":-1,"y":-1,"z":16},"block_id":2},{"move":{"x":-1,"y":-1,"z":17},"block_id":2},{"move":{"x":-1,"y":-1,"z":18},"block_id":2},{"move":{"x":-1,"y":-1,"z":19},"block_id":2},{"move":{"x":-1,"y":-1,"z":20},"block_id":18},{"move":{"x":-1,"y":-1,"z":21},"block_id":18},{"move":{"x":-1,"y":-1,"z":22},"block_id":18},{"move":{"x":-1,"y":-1,"z":23},"block_id":18},{"move":{"x":-1,"y":-1,"z":24},"block_id":18},{"move":{"x":-1,"y":-1,"z":25},"block_id":18},{"move":{"x":-1,"y":-1,"z":26},"block_id":18},{"move":{"x":-1,"y":-1,"z":27},"block_id":18},{"move":{"x":-1,"y":-1,"z":28},"block_id":18},{"move":{"x":-1,"y":-1,"z":29},"block_id":18},{"move":{"x":-1,"y":-1,"z":30},"block_id":18},{"move":{"x":-1,"y":-1,"z":31},"block_id":2},{"move":{"x":-1,"y":0,"z":4},"block_id":2},{"move":{"x":-1,"y":0,"z":5},"block_id":2},{"move":{"x":-1,"y":0,"z":6},"block_id":2},{"move":{"x":-1,"y":0,"z":7},"block_id":2},{"move":{"x":-1,"y":0,"z":20},"block_id":8},{"move":{"x":-1,"y":0,"z":21},"block_id":8},{"move":{"x":-1,"y":0,"z":22},"block_id":8},{"move":{"x":-1,"y":0,"z":23},"block_id":8},{"move":{"x":-1,"y":0,"z":24},"block_id":146},{"move":{"x":-1,"y":0,"z":25},"block_id":146},{"move":{"x":-1,"y":0,"z":26},"block_id":8},{"move":{"x":-1,"y":0,"z":27},"block_id":8},{"move":{"x":-1,"y":0,"z":28},"block_id":18},{"move":{"x":-1,"y":0,"z":29},"block_id":18},{"move":{"x":-1,"y":0,"z":30},"block_id":7},{"move":{"x":-1,"y":0,"z":31},"block_id":106,"extra_data":{},"rotate":{"x":0,"y":0,"z":0}},{"move":{"x":-1,"y":1,"z":20},"block_id":8},{"move":{"x":-1,"y":1,"z":21},"block_id":8},{"move":{"x":-1,"y":1,"z":22},"block_id":8},{"move":{"x":-1,"y":1,"z":23},"block_id":98},{"move":{"x":-1,"y":1,"z":24},"block_id":8},{"move":{"x":-1,"y":1,"z":25},"block_id":5},{"move":{"x":-1,"y":1,"z":26},"block_id":8},{"move":{"x":-1,"y":1,"z":27},"block_id":67,"extra_data":{"point":{"x":0,"y":0.1,"z":0}},"rotate":{"x":2,"y":0,"z":0}},{"move":{"x":-1,"y":1,"z":28},"block_id":7},{"move":{"x":-1,"y":1,"z":29},"block_id":7},{"move":{"x":-1,"y":1,"z":30},"block_id":7},{"move":{"x":-1,"y":2,"z":21},"block_id":98},{"move":{"x":-1,"y":2,"z":22},"block_id":98},{"move":{"x":-1,"y":2,"z":23},"block_id":98},{"move":{"x":-1,"y":2,"z":24},"block_id":106,"extra_data":{},"rotate":{"x":0,"y":0,"z":0}},{"move":{"x":-1,"y":2,"z":25},"block_id":5},{"move":{"x":-1,"y":2,"z":26},"block_id":8},{"move":{"x":-1,"y":3,"z":21},"block_id":98},{"move":{"x":-1,"y":3,"z":22},"block_id":98},{"move":{"x":-1,"y":3,"z":23},"block_id":98},{"move":{"x":-1,"y":4,"z":23},"block_id":615,"extra_data":{"point":{"x":0,"y":0.1,"z":0}},"rotate":{"x":1,"y":0,"z":0}},{"move":{"x":0,"y":-1,"z":1},"block_id":2},{"move":{"x":0,"y":-1,"z":2},"block_id":2},{"move":{"x":0,"y":-1,"z":3},"block_id":2},{"move":{"x":0,"y":-1,"z":4},"block_id":2},{"move":{"x":0,"y":-1,"z":5},"block_id":2},{"move":{"x":0,"y":-1,"z":6},"block_id":2},{"move":{"x":0,"y":-1,"z":7},"block_id":18},{"move":{"x":0,"y":-1,"z":8},"block_id":2},{"move":{"x":0,"y":-1,"z":9},"block_id":2},{"move":{"x":0,"y":-1,"z":10},"block_id":2},{"move":{"x":0,"y":-1,"z":11},"block_id":2},{"move":{"x":0,"y":-1,"z":12},"block_id":2},{"move":{"x":0,"y":-1,"z":13},"block_id":2},{"move":{"x":0,"y":-1,"z":14},"block_id":2},{"move":{"x":0,"y":-1,"z":15},"block_id":2},{"move":{"x":0,"y":-1,"z":16},"block_id":2},{"move":{"x":0,"y":-1,"z":17},"block_id":2},{"move":{"x":0,"y":-1,"z":18},"block_id":2},{"move":{"x":0,"y":-1,"z":19},"block_id":2},{"move":{"x":0,"y":-1,"z":20},"block_id":2},{"move":{"x":0,"y":-1,"z":21},"block_id":18},{"move":{"x":0,"y":-1,"z":22},"block_id":18},{"move":{"x":0,"y":-1,"z":23},"block_id":18},{"move":{"x":0,"y":-1,"z":24},"block_id":18},{"move":{"x":0,"y":-1,"z":25},"block_id":18},{"move":{"x":0,"y":-1,"z":26},"block_id":18},{"move":{"x":0,"y":-1,"z":27},"block_id":18},{"move":{"x":0,"y":-1,"z":28},"block_id":18},{"move":{"x":0,"y":-1,"z":29},"block_id":18},{"move":{"x":0,"y":-1,"z":30},"block_id":18},{"move":{"x":0,"y":-1,"z":31},"block_id":2},{"move":{"x":0,"y":0,"z":7},"block_id":2},{"move":{"x":0,"y":0,"z":21},"block_id":8},{"move":{"x":0,"y":0,"z":22},"block_id":8},{"move":{"x":0,"y":0,"z":23},"block_id":8},{"move":{"x":0,"y":0,"z":24},"block_id":8},{"move":{"x":0,"y":0,"z":25},"block_id":8},{"move":{"x":0,"y":0,"z":26},"block_id":146},{"move":{"x":0,"y":0,"z":27},"block_id":8},{"move":{"x":0,"y":0,"z":28},"block_id":18},{"move":{"x":0,"y":0,"z":29},"block_id":7},