{"name":"house_dwarf","world":{"pos1":{"x":-46,"y":-133,"z":78},"pos2":{"x":-117,"y":5,"z":7},"door_bottom":{"x":-81,"y":1,"z":43}},"meta":{"draw_natural_basement":false,"air_column_from_basement":false},"size":{"x":72,"y":139,"z":72},"door_pos":{"x":35,"y":134,"z":35},"blocks":[{"move":{"x":-35,"y":-40,"z":25},"block_id":777,"rotate":{"x":13,"y":0,"z":0}},{"move":{"x":-35,"y":-40,"z":26},"block_id":777,"rotate":{"x":13,"y":0,"z":0}},{"move":{"x":-35,"y":-40,"z":27},"block_id":777,"rotate":{"x":13,"y":0,"z":0}},{"move":{"x":-35,"y":-40,"z":28},"block_id":777,"rotate":{"x":13,"y":0,"z":0}},{"move":{"x":-35,"y":-40,"z":29},"block_id":777,"rotate":{"x":13,"y":0,"z":0}},{"move":{"x":-35,"y":-40,"z":30},"block_id":777,"rotate":{"x":13,"y":0,"z":0}},{"move":{"x":-35,"y":-40,"z":31},"block_id":777,"rotate":{"x":13,"y":0,"z":0}},{"move":{"x":-35,"y":-40,"z":32},"block_id":777,"rotate":{"x":13,"y":0,"z":0}},{"move":{"x":-35,"y":-40,"z":33},"block_id":777,"rotate":{"x":13,"y":0,"z":0}},{"move":{"x":-35,"y":-40,"z":34},"block_id":777,"rotate":{"x":13,"y":0,"z":0}},{"move":{"x":-35,"y":-40,"z":35},"block_id":777,"rotate":{"x":13,"y":0,"z":0}},{"move":{"x":-35,"y":-40,"z":36},"block_id":777,"rotate":{"x":13,"y":0,"z":0}},{"move":{"x":-35,"y":-40,"z":37},"block_id":777,"rotate":{"x":13,"y":0,"z":0}},{"move":{"x":-35,"y":-40,"z":38},"block_id":777,"rotate":{"x":13,"y":0,"z":0}},{"move":{"x":-35,"y":-40,"z":39},"block_id":777,"rotate":{"x":13,"y":0,"z":0}},{"move":{"x":-35,"y":-40,"z":40},"block_id":777,"rotate":{"x":13,"y":0,"z":0}},{"move":{"x":-35,"y":-40,"z":41},"block_id":777,"rotate":{"x":13,"y":0,"z":0}},{"move":{"x":-35,"y":-40,"z":42},"block_id":777,"rotate":{"x":13,"y":0,"z":0}},{"move":{"x":-35,"y":-40,"z":43},"block_id":777,"rotate":{"x":13,"y":0,"z":0}},{"move":{"x":-35,"y":-40,"z":44},"block_id":777,"rotate":{"x":13,"y":0,"z":0}},{"move":{"x":-35,"y":-40,"z":45},"block_id":777,"rotate":{"x":13,"y":0,"z":0}},{"move":{"x":-35,"y":-40,"z":46},"block_id":777,"rotate":{"x":13,"y":0,"z":0}},{"move":{"x":-35,"y":-39,"z":23},"block_id":98},{"move":{"x":-35,"y":-39,"z":24},"block_id":98},{"move":{"x":-35,"y":-39,"z":25},"block_id":98},{"move":{"x":-35,"y":-39,"z":26},"block_id":98},{"move":{"x":-35,"y":-39,"z":27},"block_id":98},{"move":{"x":-35,"y":-39,"z":28},"block_id":98},{"move":{"x":-35,"y":-39,"z":29},"block_id":98},{"move":{"x":-35,"y":-39,"z":30},"block_id":98},{"move":{"x":-35,"y":-39,"z":31},"block_id":98},{"move":{"x":-35,"y":-39,"z":32},"block_id":98},{"move":{"x":-35,"y":-39,"z":33},"block_id":98},{"move":{"x":-35,"y":-39,"z":34},"block_id":98},{"move":{"x":-35,"y":-39,"z":35},"block_id":98},{"move":{"x":-35,"y":-39,"z":36},"block_id":98},{"move":{"x":-35,"y":-39,"z":37},"block_id":98},{"move":{"x":-35,"y":-39,"z":38},"block_id":98},{"move":{"x":-35,"y":-39,"z":39},"block_id":98},{"move":{"x":-35,"y":-39,"z":40},"block_id":98},{"move":{"x":-35,"y":-39,"z":41},"block_id":98},{"move":{"x":-35,"y":-39,"z":42},"block_id":98},{"move":{"x":-35,"y":-39,"z":43},"block_id":98},{"move":{"x":-35,"y":-39,"z":44},"block_id":98},{"move":{"x":-35,"y":-39,"z":47},"block_id":98},{"move":{"x":-35,"y":-39,"z":48},"block_id":98},{"move":{"x":-35,"y":-38,"z":23},"block_id":98},{"move":{"x":-35,"y":-38,"z":24},"block_id":98},{"move":{"x":-35,"y":-38,"z":25},"block_id":98},{"move":{"x":-35,"y":-38,"z":26},"block_id":98},{"move":{"x":-35,"y":-38,"z":27},"block_id":98},{"move":{"x":-35,"y":-38,"z":28},"block_id":98},{"move":{"x":-35,"y":-38,"z":29},"block_id":98},{"move":{"x":-35,"y":-38,"z":30},"block_id":98},{"move":{"x":-35,"y":-38,"z":31},"block_id":98},{"move":{"x":-35,"y":-38,"z":32},"block_id":98},{"move":{"x":-35,"y":-38,"z":33},"block_id":98},{"move":{"x":-35,"y":-38,"z":34},"block_id":98},{"move":{"x":-35,"y":-38,"z":35},"block_id":98},{"move":{"x":-35,"y":-38,"z":36},"block_id":98},{"move":{"x":-35,"y":-38,"z":37},"block_id":98},{"move":{"x":-35,"y":-38,"z":38},"block_id":98},{"move":{"x":-35,"y":-38,"z":39},"block_id":98},{"move":{"x":-35,"y":-38,"z":40},"block_id":98},{"move":{"x":-35,"y":-38,"z":41},"block_id":98},{"move":{"x":-35,"y":-38,"z":42},"block_id":98},{"move":{"x":-35,"y":-38,"z":43},"block_id":98},{"move":{"x":-35,"y":-38,"z":44},"block_id":98},{"move":{"x":-35,"y":-38,"z":45},"block_id":98},{"move":{"x":-35,"y":-38,"z":46},"block_id":98},{"move":{"x":-35,"y":-38,"z":47},"block_id":98},{"move":{"x":-35,"y":-38,"z":48},"block_id":98},{"move":{"x":-35,"y":-37,"z":24},"block_id":98},{"move":{"x":-35,"y":-37,"z":25},"block_id":98},{"move":{"x":-35,"y":-37,"z":26},"block_id":98},{"move":{"x":-35,"y":-37,"z":27},"block_id":98},{"move":{"x":-35,"y":-37,"z":28},"block_id":98},{"move":{"x":-35,"y":-37,"z":29},"block_id":98},{"move":{"x":-35,"y":-37,"z":30},"block_id":98},{"move":{"x":-35,"y":-37,"z":31},"block_id":98},{"move":{"x":-35,"y":-37,"z":32},"block_id":98},{"move":{"x":-35,"y":-37,"z":33},"block_id":98},{"move":{"x":-35,"y":-37,"z":34},"block_id":98},{"move":{"x":-35,"y":-37,"z":35},"block_id":98},{"move":{"x":-35,"y":-37,"z":36},"block_id":98},{"move":{"x":-35,"y":-37,"z":37},"block_id":98},{"move":{"x":-35,"y":-37,"z":38},"block_id":98},{"move":{"x":-35,"y":-37,"z":39},"block_id":98},{"move":{"x":-35,"y":-37,"z":40},"block_id":98},{"move":{"x":-35,"y":-37,"z":41},"block_id":98},{"move":{"x":-35,"y":-37,"z":42},"block_id":98},{"move":{"x":-35,"y":-37,"z":43},"block_id":98},{"move":{"x":-35,"y":-37,"z":44},"block_id":98},{"move":{"x":-35,"y":-37,"z":45},"block_id":98},{"move":{"x":-35,"y":-37,"z":46},"block_id":98},{"move":{"x":-35,"y":-37,"z":47},"block_id":98},{"move":{"x":-35,"y":-36,"z":24},"block_id":98},{"move":{"x":-35,"y":-36,"z":25},"block_id":98},{"move":{"x":-35,"y":-36,"z":26},"block_id":98},{"move":{"x":-35,"y":-36,"z":27},"block_id":98},{"move":{"x":-35,"y":-36,"z":28},"block_id":98},{"move":{"x":-35,"y":-36,"z":29},"block_id":98},{"move":{"x":-35,"y":-36,"z":30},"block_id":98},{"move":{"x":-35,"y":-36,"z":31},"block_id":98},{"move":{"x":-35,"y":-36,"z":32},"block_id":98},{"move":{"x":-35,"y":-36,"z":33},"block_id":98},{"move":{"x":-35,"y":-36,"z":34},"block_id":98},{"move":{"x":-35,"y":-36,"z":35},"block_id":98},{"move":{"x":-35,"y":-36,"z":36},"block_id":98},{"move":{"x":-35,"y":-36,"z":37},"block_id":98},{"move":{"x":-35,"y":-36,"z":38},"block_id":98},{"move":{"x":-35,"y":-36,"z":39},"block_id":98},{"move":{"x":-35,"y":-36,"z":40},"block_id":98},{"move":{"x":-35,"y":-36,"z":41},"block_id":98},{"move":{"x":-35,"y":-36,"z":42},"block_id":98},{"move":{"x":-35,"y":-36,"z":43},"block_id":98},{"move":{"x":-35,"y":-36,"z":44},"block_id":98},{"move":{"x":-35,"y":-36,"z":45},"block_id":98},{"move":{"x":-35,"y":-36,"z":46},"block_id":98},{"move":{"x":-35,"y":-36,"z":47},"block_id":98},{"move":{"x":-35,"y":-35,"z":24},"block_id":98},{"move":{"x":-35,"y":-35,"z":25},"block_id":98},{"move":{"x":-35,"y":-35,"z":26},"block_id":98},{"move":{"x":-35,"y":-35,"z":27},"block_id":98},{"move":{"x":-35,"y":-35,"z":28},"block_id":98},{"move":{"x":-35,"y":-35,"z":29},"block_id":98},{"move":{"x":-35,"y":-35,"z":30},"block_id":98},{"move":{"x":-35,"y":-35,"z":31},"block_id":98},{"move":{"x":-35,"y":-35,"z":32},"block_id":98},{"move":{"x":-35,"y":-35,"z":33},"block_id":545},{"move":{"x":-35,"y":-35,"z":34},"block_id":545},{"move":{"x":-35,"y":-35,"z":35},"block_id":545},{"move":{"x":-35,"y":-35,"z":36},"block_id":545},{"move":{"x":-35,"y":-35,"z":37},"block_id":545},{"move":{"x":-35,"y":-35,"z":38},"block_id":545},{"move":{"x":-35,"y":-35,"z":39},"block_id":98},{"move":{"x":-35,"y":-35,"z":40},"block_id":98},{"move":{"x":-35,"y":-35,"z":41},"block_id":98},{"move":{"x":-35,"y":-35,"z":42},"block_id":98},{"move":{"x":-35,"y":-35,"z":43},"block_id":98},{"move":{"x":-35,"y":-35,"z":44},"block_id":98},{"move":{"x":-35,"y":-35,"z":45},"block_id":98},{"move":{"x":-35,"y":-35,"z":46},"block_id":98},{"move":{"x":-35,"y":-35,"z":47},"block_id":98},{"move":{"x":-35,"y":-34,"z":24},"block_id":98},{"move":{"x":-35,"y":-34,"z":25},"block_id":98},{"move":{"x":-35,"y":-34,"z":26},"block_id":98},{"move":{"x":-35,"y":-34,"z":27},"block_id":98},{"move":{"x":-35,"y":-34,"z":28},"block_id":98},{"move":{"x":-35,"y":-34,"z":29},"block_id":98},{"move":{"x":-35,"y":-34,"z":30},"block_id":98},{"move":{"x":-35,"y":-34,"z":31},"block_id":98},{"move":{"x":-35,"y":-34,"z":32},"block_id":545},{"move":{"x":-35,"y":-34,"z":33},"block_id":98},{"move":{"x":-35,"y":-34,"z":34},"block_id":98},{"move":{"x":-35,"y":-34,"z":35},"block_id":98},{"move":{"x":-35,"y":-34,"z":36},"block_id":98},{"move":{"x":-35,"y":-34,"z":37},"block_id":98},{"move":{"x":-35,"y":-34,"z":38},"block_id":98},{"move":{"x":-35,"y":-34,"z":39},"block_id":545},{"move":{"x":-35,"y":-34,"z":40},"block_id":98},{"move":{"x":-35,"y":-34,"z":41},"block_id":98},{"move":{"x":-35,"y":-34,"z":42},"block_id":98},{"move":{"x":-35,"y":-34,"z":43},"block_id":98},{"move":{"x":-35,"y":-34,"z":44},"block_id":98},{"move":{"x":-35,"y":-34,"z":45},"block_id":98},{"move":{"x":-35,"y":-34,"z":46},"block_id":98},{"move":{"x":-35,"y":-34,"z":47},"block_id":98},{"move":{"x":-35,"y":-33,"z":24},"block_id":98},{"move":{"x":-35,"y":-33,"z":25},"block_id":98},{"move":{"x":-35,"y":-33,"z":26},"block_id":98},{"move":{"x":-35,"y":-33,"z":27},"block_id":98},{"move":{"x":-35,"y":-33,"z":28},"block_id":98},{"move":{"x":-35,"y":-33,"z":29},"block_id":98},{"move":{"x":-35,"y":-33,"z":30},"block_id":98},{"move":{"x":-35,"y":-33,"z":31},"block_id":545},{"move":{"x":-35,"y":-33,"z":32},"block_id":98},{"move":{"x":-35,"y":-33,"z":33},"block_id":98},{"move":{"x":-35,"y":-33,"z":34},"block_id":98},{"move":{"x":-35,"y":-33,"z":35},"block_id":98},{"move":{"x":-35,"y":-33,"z":36},"block_id":98},{"move":{"x":-35,"y":-33,"z":37},"block_id":98},{"move":{"x":-35,"y":-33,"z":38},"block_id":98},{"move":{"x":-35,"y":-33,"z":39},"block_id":98},{"move":{"x":-35,"y":-33,"z":40},"block_id":545},{"move":{"x":-35,"y":-33,"z":41},"block_id":98},{"move":{"x":-35,"y":-33,"z":42},"block_id":98},{"move":{"x":-35,"y":-33,"z":43},"block_id":98},{"move":{"x":-35,"y":-33,"z":44},"block_id":98},{"move":{"x":-35,"y":-33,"z":45},"block_id":98},{"move":{"x":-35,"y":-33,"z":46},"block_id":98},{"move":{"x":-35,"y":-33,"z":47},"block_id":98},{"move":{"x":-35,"y":-32,"z":24},"block_id":98},{"move":{"x":-35,"y":-32,"z":25},"block_id":98},{"move":{"x":-35,"y":-32,"z":26},"block_id":545},{"move":{"x":-35,"y":-32,"z":27},"block_id":545},{"move":{"x":-35,"y":-32,"z":28},"block_id":545},{"move":{"x":-35,"y":-32,"z":29},"block_id":545},{"move":{"x":-35,"y":-32,"z":30},"block_id":98},{"move":{"x":-35,"y":-32,"z":31},"block_id":545},{"move":{"x":-35,"y":-32,"z":32},"block_id":98},{"move":{"x":-35,"y":-32,"z":33},"block_id":98},{"move":{"x":-35,"y":-32,"z":34},"block_id":98},{"move":{"x":-35,"y":-32,"z":35},"block_id":545},{"move":{"x":-35,"y":-32,"z":36},"block_id":545},{"move":{"x":-35,"y":-32,"z":37},"block_id":98},{"move":{"x":-35,"y":-32,"z":38},"block_id":98},{"move":{"x":-35,"y":-32,"z":39},"block_id":98},{"move":{"x":-35,"y":-32,"z":40},"block_id":545},{"move":{"x":-35,"y":-32,"z":41},"block_id":98},{"move":{"x":-35,"y":-32,"z":42},"block_id":545},{"move":{"x":-35,"y":-32,"z":43},"block_id":545},{"move":{"x":-35,"y":-32,"z":44},"block_id":545},{"move":{"x":-35,"y":-32,"z":45},"block_id":545},{"move":{"x":-35,"y":-32,"z":46},"block_id":98},{"move":{"x":-35,"y":-32,"z":47},"block_id":98},{"move":{"x":-35,"y":-31,"z":24},"block_id":98},{"move":{"x":-35,"y":-31,"z":25},"block_id":98},{"move":{"x":-35,"y":-31,"z":26},"block_id":545},{"move":{"x":-35,"y":-31,"z":27},"block_id":98},{"move":{"x":-35,"y":-31,"z":28},"block_id":98},{"move":{"x":-35,"y":-31,"z":29},"block_id":545},{"move":{"x":-35,"y":-31,"z":30},"block_id":98},{"move":{"x":-35,"y":-31,"z":31},"block_id":545},{"move":{"x":-35,"y":-31,"z":32},"block_id":98},{"move":{"x":-35,"y":-31,"z":33},"block_id":98},{"move":{"x":-35,"y":-31,"z":34},"block_id":545},{"move":{"x":-35,"y":-31,"z":35},"block_id":98},{"move":{"x":-35,"y":-31,"z":36},"block_id":98},{"move":{"x":-35,"y":-31,"z":37},"block_id":545},{"move":{"x":-35,"y":-31,"z":38},"block_id":98},{"move":{"x":-35,"y":-31,"z":39},"block_id":98},{"move":{"x":-35,"y":-31,"z":40},"block_id":545},{"move":{"x":-35,"y":-31,"z":41},"block_id":98},{"move":{"x":-35,"y":-31,"z":42},"block_id":545},{"move":{"x":-35,"y":-31,"z":43},"block_id":98},{"move":{"x":-35,"y":-31,"z":44},"block_id":98},{"move":{"x":-35,"y":-31,"z":45},"block_id":545},{"move":{"x":-35,"y":-31,"z":46},"block_id":98},{"move":{"x":-35,"y":-31,"z":47},"block_id":98},{"move":{"x":-35,"y":-30,"z":24},"block_id":98},{"move":{"x":-35,"y":-30,"z":25},"block_id":98},{"move":{"x":-35,"y":-30,"z":26},"block_id":545},{"move":{"x":-35,"y":-30,"z":27},"block_id":98},{"move":{"x":-35,"y":-30,"z":28},"block_id":98},{"move":{"x":-35,"y":-30,"z":29},"block_id":545},{"move":{"x":-35,"y":-30,"z":30},"block_id":98},{"move":{"x":-35,"y":-30,"z":31},"block_id":545},{"move":{"x":-35,"y":-30,"z":32},"block_id":98},{"move":{"x":-35,"y":-30,"z":33},"block_id":98},{"move":{"x":-35,"y":-30,"z":34},"block_id":545},{"move":{"x":-35,"y":-30,"z":35},"block_id":98},{"move":{"x":-35,"y":-30,"z":36},"block_id":98},{"move":{"x":-35,"y":-30,"z":37},"block_id":545},{"move":{"x":-35,"y":-30,"z":38},"block_id":98},{"move":{"x":-35,"y":-30,"z":39},"block_id":98},{"move":{"x":-35,"y":-30,"z":40},"block_id":545},{"move":{"x":-35,"y":-30,"z":41},"block_id":98},{"move":{"x":-35,"y":-30,"z":42},"block_id":545},{"move":{"x":-35,"y":-30,"z":43},"block_id":98},{"move":{"x":-35,"y":-30,"z":44},"block_id":98},{"move":{"x":-35,"y":-30,"z":45},"block_id":545},{"move":{"x":-35,"y":-30,"z":46},"block_id":98},{"move":{"x":-35,"y":-30,"z":47},"block_id":98},{"move":{"x":-35,"y":-29,"z":24},"block_id":98},{"move":{"x":-35,"y":-29,"z":25},"block_id":98},{"move":{"x":-35,"y":-29,"z":26},"block_id":545},{"move":{"x":-35,"y":-29,"z":27},"block_id":545},{"move":{"x":-35,"y":-29,"z":28},"block_id":545},{"move":{"x":-35,"y":-29,"z":29},"block_id":545},{"move":{"x":-35,"y":-29,"z":30},"block_id":98},{"move":{"x":-35,"y":-29,"z":31},"block_id":545},{"move":{"x":-35,"y":-29,"z":32},"block_id":98},{"move":{"x":-35,"y":-29,"z":33},"block_id":98},{"move":{"x":-35,"y":-29,"z":34},"block_id":98},{"move":{"x":-35,"y":-29,"z":35},"block_id":545},{"move":{"x":-35,"y":-29,"z":36},"block_id":545},{"move":{"x":-35,"y":-29,"z":37},"block_id":98},{"move":{"x":-35,"y":-29,"z":38},"block_id":98},{"move":{"x":-35,"y":-29,"z":39},"block_id":98},{"move":{"x":-35,"y":-29,"z":40},"block_id":545},{"move":{"x":-35,"y":-29,"z":41},"block_id":98},{"move":{"x":-35,"y":-29,"z":42},"block_id":545},{"move":{"x":-35,"y":-29,"z":43},"block_id":545},{"move":{"x":-35,"y":-29,"z":44},"block_id":545},{"move":{"x":-35,"y":-29,"z":45},"block_id":545},{"move":{"x":-35,"y":-29,"z":46},"block_id":98},{"move":{"x":-35,"y":-29,"z":47},"block_id":98},{"move":{"x":-35,"y":-28,"z":24},"block_id":98},{"move":{"x":-35,"y":-28,"z":25},"block_id":98},{"move":{"x":-35,"y":-28,"z":26},"block_id":98},{"move":{"x":-35,"y":-28,"z":27},"block_id":98},{"move":{"x":-35,"y":-28,"z":28},"block_id":98},{"move":{"x":-35,"y":-28,"z":29},"block_id":98},{"move":{"x":-35,"y":-28,"z":30},"block_id":98},{"move":{"x":-35,"y":-28,"z":31},"block_id":545},{"move":{"x":-35,"y":-28,"z":32},"block_id":98},{"move":{"x":-35,"y":-28,"z":33},"block_id":98},{"move":{"x":-35,"y":-28,"z":34},"block_id":98},{"move":{"x":-35,"y":-28,"z":35},"block_id":98},{"move":{"x":-35,"y":-28,"z":36},"block_id":98},{"move":{"x":-35,"y":-28,"z":37},"block_id":98},{"move":{"x":-35,"y":-28,"z":38},"block_id":98},{"move":{"x":-35,"y":-28,"z":39},"block_id":98},{"move":{"x":-35,"y":-28,"z":40},"block_id":545},{"move":{"x":-35,"y":-28,"z":41},"block_id":98},{"move":{"x":-35,"y":-28,"z":42},"block_id":98},{"move":{"x":-35,"y":-28,"z":43},"block_id":98},{"move":{"x":-35,"y":-28,"z":44},"block_id":98},{"move":{"x":-35,"y":-28,"z":45},"block_id":98},{"move":{"x":-35,"y":-28,"z":46},"block_id":98},{"move":{"x":-35,"y":-28,"z":47},"block_id":98},{"move":{"x":-35,"y":-27,"z":24},"block_id":98},{"move":{"x":-35,"y":-27,"z":25},"block_id":98},{"move":{"x":-35,"y":-27,"z":26},"block_id":98},{"move":{"x":-35,"y":-27,"z":27},"block_id":98},{"move":{"x":-35,"y":-27,"z":28},"block_id":98},{"move":{"x":-35,"y":-27,"z":29},"block_id":98},{"move":{"x":-35,"y":-27,"z":30},"block_id":98},{"move":{"x":-35,"y":-27,"z":31},"block_id":98},{"move":{"x":-35,"y":-27,"z":32},"block_id":545},{"move":{"x":-35,"y":-27,"z":33},"block_id":98},{"move":{"x":-35,"y":-27,"z":34},"block_id":98},{"move":{"x":-35,"y":-27,"z":35},"block_id":98},{"move":{"x":-35,"y":-27,"z":36},"block_id":98},{"move":{"x":-35,"y":-27,"z":37},"block_id":98},{"move":{"x":-35,"y":-27,"z":38},"block_id":98},{"move":{"x":-35,"y":-27,"z":39},"block_id":545},{"move":{"x":-35,"y":-27,"z":40},"block_id":98},{"move":{"x":-35,"y":-27,"z":41},"block_id":98},{"move":{"x":-35,"y":-27,"z":42},"block_id":98},{"move":{"x":-35,"y":-27,"z":43},"block_id":98},{"move":{"x":-35,"y":-27,"z":44},"block_id":98},{"move":{"x":-35,"y":-27,"z":45},"block_id":98},{"move":{"x":-35,"y":-27,"z":46},"block_id":98},{"move":{"x":-35,"y":-27,"z":47},"block_id":98},{"move":{"x":-35,"y":-26,"z":24},"block_id":98},{"move":{"x":-35,"y":-26,"z":25},"block_id":98},{"move":{"x":-35,"y":-26,"z":26},"block_id":98},{"move":{"x":-35,"y":-26,"z":27},"block_id":98},{"move":{"x":-35,"y":-26,"z":28},"block_id":98},{"move":{"x":-35,"y":-26,"z":29},"block_id":98},{"move":{"x":-35,"y":-26,"z":30},"block_id":98},{"move":{"x":-35,"y":-26,"z":31},"block_id":98},{"move":{"x":-35,"y":-26,"z":32},"block_id":98},{"move":{"x":-35,"y":-26,"z":33},"block_id":545},{"move":{"x":-35,"y":-26,"z":34},"block_id":545},{"move":{"x":-35,"y":-26,"z":35},"block_id":545},{"move":{"x":-35,"y":-26,"z":36},"block_id":545},{"move":{"x":-35,"y":-26,"z":37},"block_id":545},{"move":{"x":-35,"y":-26,"z":38},"block_id":545},{"move":{"x":-35,"y":-26,"z":39},"block_id":98},{"move":{"x":-35,"y":-26,"z":40},"block_id":98},{"move":{"x":-35,"y":-26,"z":41},"block_id":98},{"move":{"x":-35,"y":-26,"z":42},"block_id":98},{"move":{"x":-35,"y":-26,"z":43},"block_id":98},{"move":{"x":-35,"y":-26,"z":44},"block_id":98},{"move":{"x":-35,"y":-26,"z":45},"block_id":98},{"move":{"x":-35,"y":-26,"z":46},"block_id":98},{"move":{"x":-35,"y":-26,"z":47},"block_id":98},{"move":{"x":-35,"y":-25,"z":24},"block_id":98},{"move":{"x":-35,"y":-25,"z":25},"block_id":98},{"move":{"x":-35,"y":-25,"z":26},"block_id":98},{"move":{"x":-35,"y":-25,"z":27},"block_id":98},{"move":{"x":-35,"y":-25,"z":28},"block_id":98},{"move":{"x":-35,"y":-25,"z":29},"block_id":98},{"move":{"x":-35,"y":-25,"z":30},"block_id":98},{"move":{"x":-35,"y":-25,"z":31},"block_id":98},{"move":{"x":-35,"y":-25,"z":32},"block_id":98},{"move":{"x":-35,"y":-25,"z":33},"block_id":98},{"move":{"x":-35,"y":-25,"z":34},"block_id":98},{"move":{"x":-35,"y":-25,"z":35},"block_id":98},{"move":{"x":-35,"y":-25,"z":36},"block_id":98},{"move":{"x":-35,"y":-25,"z":37},"block_id":98},{"move":{"x":-35,"y":-25,"z":38},"block_id":98},{"move":{"x":-35,"y":-25,"z":39},"block_id":98},{"move":{"x":-35,"y":-25,"z":40},"block_id":98},{"move":{"x":-35,"y":-25,"z":41},"block_id":98},{"move":{"x":-35,"y":-25,"z":42},"block_id":98},{"move":{"x":-35,"y":-25,"z":43},"block_id":98},{"move":{"x":-35,"y":-25,"z":44},"block_id":98},{"move":{"x":-35,"y":-25,"z":45},"block_id":98},{"move":{"x":-35,"y":-25,"z":46},"block_id":98},{"move":{"x":-35,"y":-25,"z":47},"block_id":98},{"move":{"x":-35,"y":-24,"z":24},"block_id":98},{"move":{"x":-35,"y":-24,"z":25},"block_id":98},{"move":{"x":-35,"y":-24,"z":26},"block_id":98},{"move":{"x":-35,"y":-24,"z":27},"block_id":98},{"move":{"x":-35,"y":-24,"z":28},"block_id":98},{"move":{"x":-35,"y":-24,"z":29},"block_id":98},{"move":{"x":-35,"y":-24,"z":30},"block_id":98},{"move":{"x":-35,"y":-24,"z":31},"block_id":98},{"move":{"x":-35,"y":-24,"z":32},"block_id":98},{"move":{"x":-35,"y":-24,"z":33},"block_id":98},{"move":{"x":-35,"y":-24,"z":34},"block_id":98},{"move":{"x":-35,"y":-24,"z":35},"block_id":98},{"move":{"x":-35,"y":-24,"z":36},"block_id":98},{"move":{"x":-35,"y":-24,"z":37},"block_id":98},{"move":{"x":-35,"y":-24,"z":38},"block_id":98},{"move":{"x":-35,"y":-24,"z":39},"block_id":98},{"move":{"x":-35,"y":-24,"z":40},"block_id":98},{"move":{"x":-35,"y":-24,"z":41},"block_id":98},{"move":{"x":-35,"y":-24,"z":42},"block_id":98},{"move":{"x":-35,"y":-24,"z":43},"block_id":98},{"move":{"x":-35,"y":-24,"z":44},"block_id":98},{"move":{"x":-35,"y":-24,"z":45},"block_id":98},{"move":{"x":-35,"y":-24,"z":46},"block_id":98},{"move":{"x":-35,"y":-24,"z":47},"block_id":98},{"move":{"x":-35,"y":-23,"z":24},"block_id":98},{"move":{"x":-35,"y":-23,"z":25},"block_id":98},{"move":{"x":-35,"y":-23,"z":26},"block_id":98},{"move":{"x":-35,"y":-23,"z":27},"block_id":98},{"move":{"x":-35,"y":-23,"z":28},"block_id":98},{"move":{"x":-35,"y":-23,"z":29},"block_id":98},{"move":{"x":-35,"y":-23,"z":30},"block_id":98},{"move":{"x":-35,"y":-23,"z":31},"block_id":98},{"move":{"x":-35,"y":-23,"z":32},"block_id":98},{"move":{"x":-35,"y":-23,"z":33},"block_id":98},{"move":{"x":-35,"y":-23,"z":34},"block_id":98},{"move":{"x":-35,"y":-23,"z":35},"block_id":98},{"move":{"x":-35,"y":-23,"z":36},"block_id":98},{"move":{"x":-35,"y":-23,"z":37},"block_id":98},{"move":{"x":-35,"y":-23,"z":38},"block_id":98},{"move":{"x":-35,"y":-23,"z":39},"block_id":98},{"move":{"x":-35,"y":-23,"z":40},"block_id":98},{"move":{"x":-35,"y":-23,"z":41},"block_id":98},{"move":{"x":-35,"y":-23,"z":42},"block_id":98},{"move":{"x":-35,"y":-23,"z":43},"block_id":98},{"move":{"x":-35,"y":-23,"z":44},"block_id":98},{"move":{"x":-35,"y":-23,"z":45},"block_id":98},{"move":{"x":-35,"y":-23,"z":46},"block_id":98},{"move":{"x":-35,"y":-23,"z":47},"block_id":98},{"move":{"x":-35,"y":-22,"z":24},"block_id":98},{"move":{"x":-35,"y":-22,"z":25},"block_id":98},{"move":{"x":-35,"y":-22,"z":26},"block_id":98},{"move":{"x":-35,"y":-22,"z":27},"block_id":98},{"move":{"x":-35,"y":-22,"z":28},"block_id":98},{"move":{"x":-35,"y":-22,"z":29},"block_id":98},{"move":{"x":-35,"y":-22,"z":30},"block_id":98},{"move":{"x":-35,"y":-22,"z":31},"block_id":98},{"move":{"x":-35,"y":-22,"z":32},"block_id":98},{"move":{"x":-35,"y":-22,"z":33},"block_id":98},{"move":{"x":-35,"y":-22,"z":34},"block_id":98},{"move":{"x":-35,"y":-22,"z":35},"block_id":98},{"move":{"x":-35,"y":-22,"z":36},"block_id":98},{"move":{"x":-35,"y":-22,"z":37},"block_id":98},{"move":{"x":-35,"y":-22,"z":38},"block_id":98},{"move":{"x":-35,"y":-22,"z":39},"block_id":98},{"move":{"x":-35,"y":-22,"z":40},"block_id":98},{"move":{"x":-35,"y":-22,"z":41},"block_id":98},{"move":{"x":-35,"y":-22,"z":42},"block_id":98},{"move":{"x":-35,"y":-22,"z":43},"block_id":98},{"move":{"x":-35,"y":-22,"z":44},"block_id":98},{"move":{"x":-35,"y":-22,"z":45},"block_id":98},{"move":{"x":-35,"y":-22,"z":46},"block_id":98},{"move":{"x":-35,"y":-22,"z":47},"block_id":98},{"move":{"x":-35,"y":-21,"z":24},"block_id":98},{"move":{"x":-35,"y":-21,"z":25},"block_id":98},{"move":{"x":-35,"y":-21,"z":26},"block_id":98},{"move":{"x":-35,"y":-21,"z":27},"block_id":98},{"move":{"x":-35,"y":-21,"z":28},"block_id":98},{"move":{"x":-35,"y":-21,"z":29},"block_id":98},{"move":{"x":-35,"y":-21,"z":30},"block_id":98},{"move":{"x":-35,"y":-21,"z":31},"block_id":98},{"move":{"x":-35,"y":-21,"z":32},"block_id":98},{"move":{"x":-35,"y":-21,"z":33},"block_id":98},{"move":{"x":-35,"y":-21,"z":34},"block_id":98},{"move":{"x":-35,"y":-21,"z":35},"block_id":98},{"move":{"x":-35,"y":-21,"z":36},"block_id":98},{"move":{"x":-35,"y":-21,"z":37},"block_id":98},{"move":{"x":-35,"y":-21,"z":38},"block_id":98},{"move":{"x":-35,"y":-21,"z":39},"block_id":98},{"move":{"x":-35,"y":-21,"z":40},"block_id":98},{"move":{"x":-35,"y":-21,"z":41},"block_id":98},{"move":{"x":-35,"y":-21,"z":42},"block_id":98},{"move":{"x":-35,"y":-21,"z":43},"block_id":98},{"move":{"x":-35,"y":-21,"z":44},"block_id":98},{"move":{"x":-35,"y":-21,"z":45},"block_id":98},{"move":{"x":-35,"y":-21,"z":46},"block_id":98},{"move":{"x":-35,"y":-21,"z":47},"block_id":98},{"move":{"x":-35,"y":-20,"z":24},"block_id":98},{"move":{"x":-35,"y":-20,"z":25},"block_id":98},{"move":{"x":-35,"y":-20,"z":26},"block_id":98},{"move":{"x":-35,"y":-20,"z":27},"block_id":98},{"move":{"x":-35,"y":-20,"z":28},"block_id":98},{"move":{"x":-35,"y":-20,"z":29},"block_id":98},{"move":{"x":-35,"y":-20,"z":30},"block_id":98},{"move":{"x":-35,"y":-20,"z":31},"block_id":98},{"move":{"x":-35,"y":-20,"z":32},"block_id":98},{"move":{"x":-35,"y":-20,"z":33},"block_id":98},{"move":{"x":-35,"y":-20,"z":34},"block_id":98},{"move":{"x":-35,"y":-20,"z":35},"block_id":98},{"move":{"x":-35,"y":-20,"z":36},"block_id":98},{"move":{"x":-35,"y":-20,"z":37},"block_id":98},{"move":{"x":-35,"y":-20,"z":38},"block_id":98},{"move":{"x":-35,"y":-20,"z":39},"block_id":98},{"move":{"x":-35,"y":-20,"z":40},"block_id":98},{"move":{"x":-35,"y":-20,"z":41},"block_id":98},{"move":{"x":-35,"y":-20,"z":42},"block_id":98},{"move":{"x":-35,"y":-20,"z":43},"block_id":98},{"move":{"x":-35,"y":-20,"z":44},"block_id":98},{"move":{"x":-35,"y":-20,"z":45},"block_id":98},{"move":{"x":-35,"y":-20,"z":46},"block_id":98},{"move":{"x":-35,"y":-20,"z":47},"block_id":98},{"move":{"x":-35,"y":-19,"z":24},"block_id":98},{"move":{"x":-35,"y":-19,"z":25},"block_id":98},{"move":{"x":-35,"y":-19,"z":26},"block_id":98},{"move":{"x":-35,"y":-19,"z":27},"block_id":98},{"move":{"x":-35,"y":-19,"z":28},"block_id":98},{"move":{"x":-35,"y":-19,"z":29},"block_id":98},{"move":{"x":-35,"y":-19,"z":30},"block_id":98},{"move":{"x":-35,"y":-19,"z":31},"block_id":98},{"move":{"x":-35,"y":-19,"z":32},"block_id":98},{"move":{"x":-35,"y":-19,"z":33},"block_id":98},{"move":{"x":-35,"y":-19,"z":34},"block_id":98},{"move":{"x":-35,"y":-19,"z":35},"block_id":98},{"move":{"x":-35,"y":-19,"z":36},"block_id":98},{"move":{"x":-35,"y":-19,"z":37},"block_id":98},{"move":{"x":-35,"y":-19,"z":38},"block_id":98},{"move":{"x":-35,"y":-19,"z":39},"block_id":98},{"move":{"x":-35,"y":-19,"z":40},"block_id":98},{"move":{"x":-35,"y":-19,"z":41},"block_id":98},{"move":{"x":-35,"y":-19,"z":42},"block_id":98},{"move":{"x":-35,"y":-19,"z":43},"block_id":98},{"move":{"x":-35,"y":-19,"z":44},"block_id":98},{"move":{"x":-35,"y":-19,"z":45},"block_id":98},{"move":{"x":-35,"y":-19,"z":46},"block_id":98},{"move":{"x":-35,"y":-19,"z":47},"block_id":98},{"move":{"x":-35,"y":-18,"z":5},"block_id":98},{"move":{"x":-35,"y":-18,"z":6},"block_id":98},{"move":{"x":-35,"y":-18,"z":7},"block_id":98},{"move":{"x":-35,"y":-18,"z":8},"block_id":98},{"move":{"x":-35,"y":-18,"z":9},"block_id":98},{"move":{"x":-35,"y":-18,"z":10},"block_id":98},{"move":{"x":-35,"y":-18,"z":11},"block_id":98},{"move":{"x":-35,"y":-18,"z":12},"block_id":98},{"move":{"x":-35,"y":-18,"z":13},"block_id":98},{"move":{"x":-35,"y":-18,"z":14},"block_id":98},{"move":{"x":-35,"y":-18,"z":15},"block_id":98},{"move":{"x":-35,"y":-18,"z":16},"block_id":98},{"move":{"x":-35,"y":-18,"z":17},"block_id":98},{"move":{"x":-35,"y":-18,"z":18},"block_id":98},{"move":{"x":-35,"y":-18,"z":19},"block_id":98},{"move":{"x":-35,"y":-18,"z":20},"block_id":98},{"move":{"x":-35,"y":-18,"z":21},"block_id":98},{"move":{"x":-35,"y":-18,"z":22},"block_id":98},{"move":{"x":-35,"y":-18,"z":23},"block_id":98},{"move":{"x":-35,"y":-18,"z":24},"block_id":98},{"move":{"x":-35,"y":-18,"z":25},"block_id":98},{"move":{"x":-35,"y":-18,"z":26},"block_id":98},{"move":{"x":-35,"y":-18,"z":27},"block_id":98},{"move":{"x":-35,"y":-18,"z":28},"block_id":98},{"move":{"x":-35,"y":-18,"z":29},"block_id":98},{"move":{"x":-35,"y":-18,"z":30},"block_id":98},{"move":{"x":-35,"y":-18,"z":31},"block_id":98},{"move":{"x":-35,"y":-18,"z":32},"block_id":98},{"move":{"x":-35,"y":-18,"z":33},"block_id":98},{"move":{"x":-35,"y":-18,"z":34},"block_id":98},{"move":{"x":-35,"y":-18,"z":35},"block_id":98},{"move":{"x":-35,"y":-18,"z":36},"block_id":98},{"move":{"x":-35,"y":-18,"z":37},"block_id":98},{"move":{"x":-35,"y":-18,"z":38},"block_id":98},{"move":{"x":-35,"y":-18,"z":39},"block_id":98},{"move":{"x":-35,"y":-18,"z":40},"block_id":98},{"move":{"x":-35,"y":-18,"z":41},"block_id":98},{"move":{"x":-35,"y":-18,"z":42},"block_id":98},{"move":{"x":-35,"y":-18,"z":43},"block_id":98},{"move":{"x":-35,"y":-18,"z":44},"block_id":98},{"move":{"x":-35,"y":-18,"z":45},"block_id":98},{"move":{"x":-35,"y":-18,"z":46},"block_id":98},{"move":{"x":-35,"y":-18,"z":47},"block_id":98},{"move":{"x":-35,"y":-18,"z":48},"block_id":98},{"move":{"x":-35,"y":-18,"z":49},"block_id":98},{"move":{"x":-35,"y":-18,"z":50},"block_id":98},{"move":{"x":-35,"y":-18,"z":51},"block_id":98},{"move":{"x":-35,"y":-18,"z":52},"block_id":98},{"move":{"x":-35,"y":-18,"z":53},"block_id":98},{"move":{"x":-35,"y":-18,"z":54},"block_id":98},{"move":{"x":-35,"y":-18,"z":55},"block_id":98},{"move":{"x":-35,"y":-18,"z":56},"block_id":98},{"move":{"x":-35,"y":-18,"z":57},"block_id":98},{"move":{"x":-35,"y":-18,"z":58},"block_id":98},{"move":{"x":-35,"y":-18,"z":59},"block_id":98},{"move":{"x":-35,"y":-18,"z":60},"block_id":98},{"move":{"x":-35,"y":-18,"z":61},"block_id":98},{"move":{"x":-35,"y":-18,"z":62},"block_id":98},{"move":{"x":-35,"y":-18,"z":63},"block_id":98},{"move":{"x":-35,"y":-18,"z":64},"block_id":98},{"move":{"x":-35,"y":-18,"z":65},"block_id":98},{"move":{"x":-35,"y":-18,"z":66},"block_id":98},{"move":{"x":-34,"y":-41,"z":25},"block_id":98},{"move":{"x":-34,"y":-41,"z":26},"block_id":98},{"move":{"x":-34,"y":-41,"z":27},"block_id":98},{"move":{"x":-34,"y":-41,"z":28},"block_id":98},{"move":{"x":-34,"y":-41,"z":29},"block_id":98},{"move":{"x":-34,"y":-41,"z":30},"block_id":98},{"move":{"x":-34,"y":-41,"z":31},"block_id":98},{"move":{"x":-34,"y":-41,"z":32},"block_id":98},{"move":{"x":-34,"y":-41,"z":33},"block_id":98},{"move":{"x":-34,"y":-41,"z":34},"block_id":98},{"move":{"x":-34,"y":-41,"z":35},"block_id":98},{"move":{"x":-34,"y":-41,"z":36},"block_id":98},{"move":{"x":-34,"y":-41,"z":37},"block_id":98},{"move":{"x":-34,"y":-41,"z":38},"block_id":98},{"move":{"x":-34,"y":-41,"z":39},"block_id":98},{"move":{"x":-34,"y":-41,"z":40},"block_id":98},{"move":{"x":-34,"y":-41,"z":41},"block_id":98},{"move":{"x":-34,"y":-41,"z":42},"block_id":98},{"move":{"x":-34,"y":-41,"z":43},"block_id":98},{"move":{"x":-34,"y":-41,"z":44},"block_id":98},{"move":{"x":-34,"y":-41,"z":45},"block_id":98},{"move":{"x":-34,"y":-41,"z":46},"block_id":98},{"move":{"x":-34,"y":-40,"z":24},"block_id":777,"rotate":{"x":18,"y":0,"z":0}},{"move":{"x":-34,"y":-40,"z":25},"block_id":98},{"move":{"x":-34,"y":-40,"z":26},"block_id":98},{"move":{"x":-34,"y":-40,"z":27},"block_id":98},{"move":{"x":-34,"y":-40,"z":28},"block_id":98},{"move":{"x":-34,"y":-40,"z":29},"block_id":98},{"move":{"x":-34,"y":-40,"z":30},"block_id":98},{"move":{"x":-34,"y":-40,"z":31},"block_id":98},{"move":{"x":-34,"y":-40,"z":32},"block_id":98},{"move":{"x":-34,"y":-40,"z":33},"block_id":98},{"move":{"x":-34,"y":-40,"z":34},"block_id":98},{"move":{"x":-34,"y":-40,"z":35},"block_id":98},{"move":{"x":-34,"y":-40,"z":36},"block_id":98},{"move":{"x":-34,"y":-40,"z":37},"block_id":98},{"move":{"x":-34,"y":-40,"z":38},"block_id":98},{"move":{"x":-34,"y":-40,"z":39},"block_id":98},{"move":{"x":-34,"y":-40,"z":40},"block_id":98},{"move":{"x":-34,"y":-40,"z":41},"block_id":98},{"move":{"x":-34,"y":-40,"z":42},"block_id":98},{"move":{"x":-34,"y":-40,"z":43},"block_id":98},{"move":{"x":-34,"y":-40,"z":44},"block_id":98},{"move":{"x":-34,"y":-40,"z":45},"block_id":98},{"move":{"x":-34,"y":-40,"z":46},"block_id":98},{"move":{"x":-34,"y":-40,"z":47},"block_id":777,"rotate":{"x":7,"y":0,"z":0}},{"move":{"x":-34,"y":-39,"z":23},"block_id":98},{"move":{"x":-34,"y":-39,"z":24},"block_id":98},{"move":{"x":-34,"y":-39,"z":25},"block_id":98},{"move":{"x":-34,"y":-39,"z":26},"block_id":98},{"move":{"x":-34,"y":-39,"z":27},"block_id":98},{"move":{"x":-34,"y":-39,"z":28},"block_id":98},{"move":{"x":-34,"y":-39,"z":29},"block_id":98},{"move":{"x":-34,"y":-39,"z":30},"block_id":98},{"move":{"x":-34,"y":-39,"z":31},"block_id":98},{"move":{"x":-34,"y":-39,"z":32},"block_id":98},{"move":{"x":-34,"y":-39,"z":33},"block_id":98},{"move":{"x":-34,"y":-39,"z":34},"block_id":98},{"move":{"x":-34,"y":-39,"z":35},"block_id":98},{"move":{"x":-34,"y":-39,"z":36},"block_id":98},{"move":{"x":-34,"y":-39,"z":37},"block_id":98},{"move":{"x":-34,"y":-39,"z":38},"block_id":98},{"move":{"x":-34,"y":-39,"z":39},"block_id":98},{"move":{"x":-34,"y":-39,"z":40},"block_id":98},{"move":{"x":-34,"y":-39,"z":41},"block_id":98},{"move":{"x":-34,"y":-39,"z":42},"block_id":98},{"move":{"x":-34,"y":-39,"z":43},"block_id":98},{"move":{"x":-34,"y":-39,"z":44},"block_id":98},{"move":{"x":-34,"y":-39,"z":45},"block_id":98},{"move":{"x":-34,"y":-39,"z":46},"block_id":98},{"move":{"x":-34,"y":-39,"z":47},"block_id":98},{"move":{"x":-34,"y":-39,"z":48},"block_id":98},{"move":{"x":-34,"y":-38,"z":23},"block_id":98},{"move":{"x":-34,"y":-38,"z":24},"block_id":98},{"move":{"x":-34,"y":-38,"z":25},"block_id":98},{"move":{"x":-34,"y":-38,"z":26},"block_id":98},{"move":{"x":-34,"y":-38,"z":27},"block_id":98},{"move":{"x":-34,"y":-38,"z":28},"block_id":98},{"move":{"x":-34,"y":-38,"z":29},"block_id":98},{"move":{"x":-34,"y":-38,"z":30},"block_id":98},{"move":{"x":-34,"y":-38,"z":31},"block_id":98},{"move":{"x":-34,"y":-38,"z":32},"block_id":98},{"move":{"x":-34,"y":-38,"z":33},"block_id":98},{"move":{"x":-34,"y":-38,"z":34},"block_id":98},{"move":{"x":-34,"y":-38,"z":35},"block_id":98},{"move":{"x":-34,"y":-38,"z":36},"block_id":98},{"move":{"x":-34,"y":-38,"z":37},"block_id":98},{"move":{"x":-34,"y":-38,"z":38},"block_id":98},{"move":{"x":-34,"y":-38,"z":39},"block_id":98},{"move":{"x":-34,"y":-38,"z":40},"block_id":98},{"move":{"x":-34,"y":-38,"z":41},"block_id":98},{"move":{"x":-34,"y":-38,"z":42},"block_id":98},{"move":{"x":-34,"y":-38,"z":43},"block_id":98},{"move":{"x":-34,"y":-38,"z":44},"block_id":98},{"move":{"x":-34,"y":-38,"z":45},"block_id":98},{"move":{"x":-34,"y":-38,"z":46},"block_id":98},{"move":{"x":-34,"y":-38,"z":47},"block_id":98},{"move":{"x":-34,"y":-38,"z":48},"block_id":98},{"move":{"x":-34,"y":-37,"z":24},"block_id":98},{"move":{"x":-34,"y":-37,"z":47},"block_id":98},{"move":{"x":-34,"y":-36,"z":24},"block_id":98},{"move":{"x":-34,"y":-36,"z":47},"block_id":98},{"move":{"x":-34,"y":-35,"z":24},"block_id":98},{"move":{"x":-34,"y":-35,"z":47},"block_id":98},{"move":{"x":-34,"y":-34,"z":24},"block_id":98},{"move":{"x":-34,"y":-34,"z":47},"block_id":98},{"move":{"x":-34,"y":-33,"z":24},"block_id":98},{"move":{"x":-34,"y":-33,"z":47},"block_id":98},{"move":{"x":-34,"y":-32,"z":24},"block_id":98},{"move":{"x":-34,"y":-32,"z":47},"block_id":98},{"move":{"x":-34,"y":-31,"z":24},"block_id":98},{"move":{"x":-34,"y":-31,"z":47},"block_id":98},{"move":{"x":-34,"y":-30,"z":24},"block_id":98},{"move":{"x":-34,"y":-30,"z":47},"block_id":98},{"move":{"x":-34,"y":-29,"z":24},"block_id":98},{"move":{"x":-34,"y":-29,"z":47},"block_id":98},{"move":{"x":-34,"y":-28,"z":24},"block_id":98},{"move":{"x":-34,"y":-28,"z":47},"block_id":98},{"move":{"x":-34,"y":-27,"z":24},"block_id":98},{"move":{"x":-34,"y":-27,"z":47},"block_id":98},{"move":{"x":-34,"y":-26,"z":24},"block_id":98},{"move":{"x":-34,"y":-26,"z":47},"block_id":98},{"move":{"x":-34,"y":-25,"z":24},"block_id":98},{"move":{"x":-34,"y":-25,"z":47},"block_id":98},{"move":{"x":-34,"y":-24,"z":24},"block_id":98},{"move":{"x":-34,"y":-24,"z":47},"block_id":98},{"move":{"x":-34,"y":-23,"z":24},"block_id":98},{"move":{"x":-34,"y":-23,"z":47},"block_id":98},{"move":{"x":-34,"y":-22,"z":24},"block_id":98},{"move":{"x":-34,"y":-22,"z":47},"block_id":98},{"move":{"x":-34,"y":-21,"z":24},"block_id":98},{"move":{"x":-34,"y":-21,"z":47},"block_id":98},{"move":{"x":-34,"y":-20,"z":24},"block_id":98},{"move":{"x":-34,"y":-20,"z":47},"block_id":98},{"move":{"x":-34,"y":-19,"z":24},"block_id":98},{"move":{"x":-34,"y":-19,"z":47},"block_id":98},{"move":{"x":-34,"y":-18,"z":4},"block_id":98},{"move":{"x":-34,"y":-18,"z":5},"block_id":98},{"move":{"x":-34,"y":-18,"z":6},"block_id":98},{"move":{"x":-34,"y":-18,"z":7},"block_id":98},{"move":{"x":-34,"y":-18,"z":8},"block_id":98},{"move":{"x":-34,"y":-18,"z":9},"block_id":98},{"move":{"x":-34,"y":-18,"z":10},"block_id":98},{"move":{"x":-34,"y":-18,"z":11},"block_id":98},{"move":{"x":-34,"y":-18,"z":12},"block_id":98},{"move":{"x":-34,"y":-18,"z":13},"block_id":98},{"move":{"x":-34,"y":-18,"z":14},"block_id":98},{"move":{"x":-34,"y":-18,"z":15},"block_id":98},{"move":{"x":-34,"y":-18,"z":16},"block_id":98},{"move":{"x":-34,"y":-18,"z":17},"block_id":98},{"move":{"x":-34,"y":-18,"z":18},"block_id":98},{"move":{"x":-34,"y":-18,"z":19},"block_id":98},{"move":{"x":-34,"y":-18,"z":20},"block_id":98},{"move":{"x":-34,"y":-18,"z":21},"block_id":98},{"move":{"x":-34,"y":-18,"z":22},"block_id":98},{"move":{"x":-34,"y":-18,"z":23},"block_id":98},{"move":{"x":-34,"y":-18,"z":24},"block_id":98},{"move":{"x":-34,"y":-18,"z":25},"block_id":98},{"move":{"x":-34,"y":-18,"z":26},"block_id":98},{"move":{"x":-34,"y":-18,"z":27},"block_id":98},{"move":{"x":-34,"y":-18,"z":28},"block_id":98},{"move":{"x":-34,"y":-18,"z":29},"block_id":98},{"move":{"x":-34,"y":-18,"z":30},"block_id":98},{"move":{"x":-34,"y":-18,"z":31},"block_id":98},{"move":{"x":-34,"y":-18,"z":32},"block_id":98},{"move":{"x":-34,"y":-18,"z":33},"block_id":98},{"move":{"x":-34,"y":-18,"z":34},"block_id":98},{"move":{"x":-34,"y":-18,"z":35},"block_id":98},{"move":{"x":-34,"y":-18,"z":36},"block_id":98},{"move":{"x":-34,"y":-18,"z":37},"block_id":98},{"move":{"x":-34,"y":-18,"z":38},"block_id":98},{"move":{"x":-34,"y":-18,"z":39},"block_id":98},{"move":{"x":-34,"y":-18,"z":40},"block_id":98},{"move":{"x":-34,"y":-18,"z":41},"block_id":98},{"move":{"x":-34,"y":-18,"z":42},"block_id":98},{"move":{"x":-34,"y":-18,"z":43},"block_id":98},{"move":{"x":-34,"y":-18,"z":44},"block_id":98},{"move":{"x":-34,"y":-18,"z":45},"block_id":98},{"move":{"x":-34,"y":-18,"z":46},"block_id":98},{"move":{"x":-34,"y":-18,"z":47},"block_id":98},{"move":{"x":-34,"y":-18,"z":48},"block_id":98},{"move":{"x":-34,"y":-18,"z":49},"block_id":98},{"move":{"x":-34,"y":-18,"z":50},"block_id":98},{"move":{"x":-34,"y":-18,"z":51},"block_id":98},{"move":{"x":-34,"y":-18,"z":52},"block_id":98},{"move":{"x":-34,"y":-18,"z":53},"block_id":98},{"move":{"x":-34,"y":-18,"z":54},"block_id":98},{"move":{"x":-34,"y":-18,"z":55},"block_id":98},{"move":{"x":-34,"y":-18,"z":56},"block_id":98},{"move":{"x":-34,"y":-18,"z":57},"block_id":98},{"move":{"x":-34,"y":-18,"z":58},"block_id":98},{"move":{"x":-34,"y":-18,"z":59},"block_id":98},{"move":{"x":-34,"y":-18,"z":60},"block_id":98},{"move":{"x":-34,"y":-18,"z":61},"block_id":98},{"move":{"x":-34,"y":-18,"z":62},"block_id":98},{"move":{"x":-34,"y":-18,"z":63},"block_id":98},{"move":{"x":-34,"y":-18,"z":64},"block_id":98},{"move":{"x":-34,"y":-18,"z":65},"block_id":98},{"move":{"x":-34,"y":-18,"z":66},"block_id":98},{"move":{"x":-34,"y":-18,"z":67},"block_id":98},{"move":{"x":-33,"y":-55,"z":26},"block_id":98},{"move":{"x":-33,"y":-55,"z":27},"block_id":98},{"move":{"x":-33,"y":-55,"z":28},"block_id":98},{"move":{"x":-33,"y":-55,"z":29},"block_id":98},{"move":{"x":-33,"y":-55,"z":30},"block_id":98},{"move":{"x":-33,"y":-55,"z":31},"block_id":98},{"move":{"x":-33,"y":-55,"z":32},"block_id":98},{"move":{"x":-33,"y":-55,"z":33},"block_id":98},{"move":{"x":-33,"y":-55,"z":34},"block_id":98},{"move":{"x":-33,"y":-55,"z":35},"block_id":98},{"move":{"x":-33,"y":-55,"z":36},"block_id":98},{"move":{"x":-33,"y":-55,"z":37},"block_id":98},{"move":{"x":-33,"y":-55,"z":38},"block_id":98},{"move":{"x":-33,"y":-55,"z":39},"block_id":98},{"move":{"x":-33,"y":-55,"z":40},"block_id":98},{"move":{"x":-33,"y":-55,"z":41},"block_id":98},{"move":{"x":-33,"y":-55,"z":42},"block_id":98},{"move":{"x":-33,"y":-55,"z":43},"block_id":98},{"move":{"x":-33,"y":-55,"z":44},"block_id":98},{"move":{"x":-33,"y":-55,"z":45},"block_id":98},{"move":{"x":-33,"y":-54,"z":26},"block_id":98},{"move":{"x":-33,"y":-54,"z":27},"block_id":98},{"move":{"x":-33,"y":-54,"z":28},"block_id":101,"extra_data":{"point":{"x":0,"y":0.1,"z":0}}},{"move":{"x":-33,"y":-54,"z":29},"block_id":101,"extra_data":{"point":{"x":0,"y":0.1,"z":0}}},{"move":{"x":-33,"y":-54,"z":30},"block_id":101,"extra_data":{"point":{"x":0,"y":0.1,"z":0}}},{"move":{"x":-33,"y":-54,"z":31},"block_id":98},{"move":{"x":-33,"y":-54,"z":32},"block_id":101,"extra_data":{"point":{"x":0,"y":0.1,"z":0}}},{"move":{"x":-33,"y":-54,"z":33},"block_id":101,"extra_data":{"point":{"x":0,"y":0.1,"z":0}}},{"move":{"x":-33,"y":-54,"z":34},"block_id":101,"extra_data":{"point":{"x":0,"y":0.1,"z":0}}},{"move":{"x":-33,"y":-54,"z":35},"block_id":98},{"move":{"x":-33,"y":-54,"z":36},"block_id":98},{"move":{"x":-33,"y":-54,"z":37},"block_id":101,"extra_data":{"point":{"x":0,"y":0.1,"z":0}}},{"move":{"x":-33,"y":-54,"z":38},"block_id":101,"extra_data":{"point":{"x":0,"y":0.1,"z":0}}},{"move":{"x":-33,"y":-54,"z":39},"block_id":101,"extra_data":{"point":{"x":0,"y":0.1,"z":0}}},{"move":{"x":-33,"y":-54,"z":40},"block_id":98},{"move":{"x":-33,"y":-54,"z":41},"block_id":101,"extra_data":{"point":{"x":0,"y":0.1,"z":0}}},{"move":{"x":-33,"y":-54,"z":42},"block_id":101,"extra_data":{"point":{"x":0,"y":0.1,"z":0}}},{"move":{"x":-33,"y":-54,"z":43},"block_id":101,"extra_data":{"point":{"x":0,"y":0.1,"z":0}}},{"move":{"x":-33,"y":-54,"z":44},"block_id":98},{"move":{"x":-33,"y":-54,"z":45},"block_id":98},{"move":{"x":-33,"y":-53,"z":26},"block_id":98},{"move":{"x":-33,"y":-53,"z":27},"block_id":98},{"move":{"x":-33,"y":-53,"z":31},"block_id":98},{"move":{"x":-33,"y":-53,"z":35},"block_id":98},{"move":{"x":-33,"y":-53,"z":36},"block_id":98},{"move":{"x":-33,"y":-53,"z":40},"block_id":98},{"move":{"x":-33,"y":-53,"z":44},"block_id":98},{"move":{"x":-33,"y":-53,"z":45},"block_id":98},{"move":{"x":-33,"y":-52,"z":26},"block_id":98},{"move":{"x":-33,"y":-52,"z":27},"block_id":98},{"move":{"x":-33,"y":-52,"z":31},"block_id":98},{"move":{"x":-33,"y":-52,"z":35},"block_id":98},{"move":{"x":-33,"y":-52,"z":36},"block_id":98},{"move":{"x":-33,"y":-52,"z":40},"block_id":98},{"move":{"x":-33,"y":-52,"z":44},"block_id":98},{"move":{"x":-33,"y":-52,"z":45},"block_id":98},{"move":{"x":-33,"y":-51,"z":26},"block_id":98},{"move":{"x":-33,"y":-51,"z":27},"block_id":98},{"move":{"x":-33,"y":-51,"z":31},"block_id":98},{"move":{"x":-33,"y":-51,"z":35},"block_id":98},{"move":{"x":-33,"y":-51,"z":36},"block_id":98},{"move":{"x":-33,"y":-51,"z":40},"block_id":98},{"move":{"x":-33,"y":-51,"z":44},"block_id":98},{"move":{"x":-33,"y":-51,"z":45},"block_id":98},{"move":{"x":-33,"y":-50,"z":26},"block_id":98},{"move":{"x":-33,"y":-50,"z":27},"block_id":98},{"move":{"x":-33,"y":-50,"z":31},"block_id":98},{"move":{"x":-33,"y":-50,"z":35},"block_id":98},{"move":{"x":-33,"y":-50,"z":36},"block_id":98},{"move":{"x":-33,"y":-50,"z":40},"block_id":98},{"move":{"x":-33,"y":-50,"z":44},"block_id":98},{"move":{"x":-33,"y":-50,"z":45},"block_id":98},{"move":{"x":-33,"y":-49,"z":26},"block_id":98},{"move":{"x":-33,"y":-49,"z":27},"block_id":98},{"move":{"x":-33,"y":-49,"z":28},"block_id":615,"extra_data":{"point":{"x":0,"y":0.9,"z":0}},"rotate":{"x":2,"y":0,"z":0}},{"move":{"x":-33,"y":-49,"z":30},"block_id":615,"extra_data":{"point":{"x":0,"y":0.9,"z":0}},"rotate":{"x":0,"y":0,"z":0}},{"move":{"x":-33,"y":-49,"z":31},"block_id":98},{"move":{"x":-33,"y":-49,"z":32},"block_id":615,"extra_data":{"point":{"x":0,"y":0.9,"z":0}},"rotate":{"x":2,"y":0,"z":0}},{"move":{"x":-33,"y":-49,"z":34},"block_id":615,"extra_data":{"point":{"x":0,"y":0.9,"z":0}},"rotate":{"x":0,"y":0,"z":0}},{"move":{"x":-33,"y":-49,"z":35},"block_id":98},{"move":{"x":-33,"y":-49,"z":36},"block_id":98},{"move":{"x":-33,"y":-49,"z":37},"block_id":615,"extra_data":{"point":{"x":0,"y":0.9,"z":0}},"rotate":{"x":2,"y":0,"z":0}},{"move":{"x":-33,"y":-49,"z":39},"block_id":615,"extra_data":{"point":{"x":0,"y":0.9,"z":0}},"rotate":{"x":0,"y":0,"z":0}},{"move":{"x":-33,"y":-49,"z":40},"block_id":98},{"move":{"x":-33,"y":-49,"z":41},"block_id":615,"extra_data":{"point":{"x":0,"y":0.9,"z":0}},"rotate":{"x":2,"y":0,"z":0}},{"move":{"x":-33,"y":-49,"z":43},"block_id":615,"extra_data":{"point":{"x":0,"y":0.9,"z":0}},"rotate":{"x":0,"y":0,"z":0}},{"move":{"x":-33,"y":-49,"z":44},"block_id":98},{"move":{"x":-33,"y":-49,"z":45},"block_id":98},{"move":{"x":-33,"y":-48,"z":26},"block_id":98},{"move":{"x":-33,"y":-48,"z":27},"block_id":98},{"move":{"x":-33,"y":-48,"z":28},"block_id":98},{"move":{"x":-33,"y":-48,"z":30},"block_id":98},{"move":{"x":-33,"y":-48,"z":31},"block_id":98},{"move":{"x":-33,"y":-48,"z":32},"block_id":98},{"move":{"x":-33,"y":-48,"z":34},"block_id":98},{"move":{"x":-33,"y":-48,"z":35},"block_id":98},{"move":{"x":-33,"y":-48,"z":36},"block_id":98},{"move":{"x":-33,"y":-48,"z":37},"block_id":98},{"move":{"x":-33,"y":-48,"z":39},"block_id":98},{"move":{"x":-33,"y":-48,"z":40},"block_id":98},{"move":{"x":-33,"y":-48,"z":41},"block_id":98},{"move":{"x":-33,"y":-48,"z":43},"block_id":98},{"move":{"x":-33,"y":-48,"z":44},"block_id":98},{"move":{"x":-33,"y":-48,"z":45},"block_id":98},{"move":{"x":-33,"y":-47,"z":26},"block_id":98},{"move":{"x":-33,"y":-47,"z":27},"block_id":98},{"move":{"x":-33,"y":-47,"z":28},"block_id":98},{"move":{"x":-33,"y":-47,"z":29},"block_id":98},{"move":{"x":-33,"y":-47,"z":30},"block_id":98},{"move":{"x":-33,"y":-47,"z":31},"block_id":98},{"move":{"x":-33,"y":-47,"z":32},"block_id":98},{"move":{"x":-33,"y":-47,"z":33},"block_id":98},{"move":{"x":-33,"y":-47,"z":34},"block_id":98},{"move":{"x":-33,"y":-47,"z":35},"block_id":98},{"move":{"x":-33,"y":-47,"z":36},"block_id":98},{"move":{"x":-33,"y":-47,"z":37},"block_id":98},{"move":{"x":-33,"y":-47,"z":38},"block_id":98},{"move":{"x":-33,"y":-47,"z":39},"block_id":98},{"move":{"x":-33,"y":-47,"z":40},"block_id":98},{"move":{"x":-33,"y":-47,"z":41},"block_id":98},{"move":{"x":-33,"y":-47,"z":42},"block_id":98},{"move":{"x":-33,"y":-47,"z":43},"block_id":98},{"move":{"x":-33,"y":-47,"z":44},"block_id":98},{"move":{"x":-33,"y":-47,"z":45},"block_id":98},{"move":{"x":-33,"y":-46,"z":26},"block_id":98},{"move":{"x":-33,"y":-46,"z":27},"block_id":98},{"move":{"x":-33,"y":-46,"z":28},"block_id":98},{"move":{"x":-33,"y":-46,"z":29},"block_id":98},{"move":{"x":-33,"y":-46,"z":30},"block_id":98},{"move":{"x":-33,"y":-46,"z":31},"block_id":98},{"move":{"x":-33,"y":-46,"z":32},"block_id":98},{"move":{"x":-33,"y":-46,"z":33},"block_id":98},{"move":{"x":-33,"y":-46,"z":34},"block_id":98},{"move":{"x":-33,"y":-46,"z":35},"block_id":98},{"move":{"x":-33,"y":-46,"z":36},"block_id":98},{"move":{"x":-33,"y":-46,"z":37},"block_id":98},{"move":{"x":-33,"y":-46,"z":38},"block_id":98},{"move":{"x":-33,"y":-46,"z":39},"block_id":98},{"move":{"x":-33,"y":-46,"z":40},"block_id":98},{"move":{"x":-33,"y":-46,"z":41},"block_id":98},{"move":{"x":-33,"y":-46,"z":42},"block_id":98},{"move":{"x":-33,"y":-46,"z":43},"block_id":98},{"move":{"x":-33,"y":-46,"z":44},"block_id":98},{"move":{"x":-33,"y":-46,"z":45},"block_id":98},{"move":{"x":-33,"y":-45,"z":26},"block_id":98},{"move":{"x":-33,"y":-45,"z":27},"block_id":98},{"move":{"x":-33,"y":-45,"z":28},"block_id":98},{"move":{"x":-33,"y":-45,"z":29},"block_id":98},{"move":{"x":-33,"y":-45,"z":30},"block_id":98},{"move":{"x":-33,"y":-45,"z":31},"block_id":98},{"move":{"x":-33,"y":-45,"z":32},"block_id":98},{"move":{"x":-33,"y":-45,"z":33},"block_id":98},{"move":{"x":-33,"y":-45,"z":34},"block_id":98},{"move":{"x":-33,"y":-45,"z":35},"block_id":98},{"move":{"x":-33,"y":-45,"z":36},"block_id":98},{"move":{"x":-33,"y":-45,"z":37},"block_id":98},{"move":{"x":-33,"y":-45,"z":38},"block_id":98},{"move":{"x":-33,"y":-45,"z":39},"block_id":98},{"move":{"x":-33,"y":-45,"z":40},"block_id":98},{"move":{"x":-33,"y":-45,"z":41},"block_id":98},{"move":{"x":-33,"y":-45,"z":42},"block_id":98},{"move":{"x":-33,"y":-45,"z":43},"block_id":98},{"move":{"x":-33,"y":-45,"z":44},"block_id":98},{"move":{"x":-33,"y":-45,"z":45},"block_id":98},{"move":{"x":-33,"y":-44,"z":26},"block_id":98},{"move":{"x":-33,"y":-44,"z":27},"block_id":98},{"move":{"x":-33,"y":-44,"z":28},"block_id":98},{"move":{"x":-33,"y":-44,"z":29},"block_id":98},{"move":{"x":-33,"y":-44,"z":30},"block_id":98},{"move":{"x":-33,"y":-44,"z":31},"block_id":98},{"move":{"x":-33,"y":-44,"z":32},"block_id":98},{"move":{"x":-33,"y":-44,"z":33},"block_id":98},{"move":{"x":-33,"y":-44,"z":34},"block_id":98},{"move":{"x":-33,"y":-44,"z":35},"block_id":98},{"move":{"x":-33,"y":-44,"z":36},"block_id":98},{"move":{"x":-33,"y":-44,"z":37},"block_id":98},{"move":{"x":-33,"y":-44,"z":38},"block_id":98},{"move":{"x":-33,"y":-44,"z":39},"block_id":98},{"move":{"x":-33,"y":-44,"z":40},"block_id":98},{"move":{"x":-33,"y":-44,"z":41},"block_id":98},{"move":{"x":-33,"y":-44,"z":42},"block_id":98},{"move":{"x":-33,"y":-44,"z":43},"block_id":98},{"move":{"x":-33,"y":-44,"z":44},"block_id":98},{"move":{"x":-33,"y":-44,"z":45},"block_id":98},{"move":{"x":-33,"y":-43,"z":26},"block_id":98},{"move":{"x":-33,"y":-43,"z":27},"block_id":98},{"move":{"x":-33,"y":-43,"z":28},"block_id":98},{"move":{"x":-33,"y":-43,"z":29},"block_id":98},{"move":{"x":-33,"y":-43,"z":30},"block_id":98},{"move":{"x":-33,"y":-43,"z":31},"block_id":98},{"move":{"x":-33,"y":-43,"z":32},"block_id":98},{"move":{"x":-33,"y":-43,"z":33},"block_id":98},{"move":{"x":-33,"y":-43,"z":34},"block_id":98},{"move":{"x":-33,"y":-43,"z":35},"block_id":98},{"move":{"x":-33,"y":-43,"z":36},"block_id":98},{"move":{"x":-33,"y":-43,"z":37},"block_id":98},{"move":{"x":-33,"y":-43,"z":38},"block_id":98},{"move":{"x":-33,"y":-43,"z":39},"block_id":98},{"move":{"x":-33,"y":-43,"z":40},"block_id":98},{"move":{"x":-33,"y":-43,"z":41},"block_id":98},{"move":{"x":-33,"y":-43,"z":42},"block_id":98},{"move":{"x":-33,"y":-43,"z":43},"block_id":98},{"move":{"x":-33,"y":-43,"z":44},"block_id":98},{"move":{"x":-33,"y":-43,"z":45},"block_id":98},{"move":{"x":-33,"y":-42,"z":26},"block_id":98},{"move":{"x":-33,"y":-42,"z":27},"block_id":98},{"move":{"x":-33,"y":-42,"z":28},"block_id":98},{"move":{"x":-33,"y":-42,"z":29},"block_id":98},{"move":{"x":-33,"y":-42,"z":30},"block_id":98},{"move":{"x":-33,"y":-42,"z":31},"block_id":98},{"move":{"x":-33,"y":-42,"z":32},"block_id":98},{"move":{"x":-33,"y":-42,"z":33},"block_id":98},{"move":{"x":-33,"y":-42,"z":34},"block_id":98},{"move":{"x":-33,"y":-42,"z":35},"block_id":98},{"move":{"x":-33,"y":-42,"z":36},"block_id":98},{"move":{"x":-33,"y":-42,"z":37},"block_id":98},{"move":{"x":-33,"y":-42,"z":38},"block_id":98},{"move":{"x":-33,"y":-42,"z":39},"block_id":98},{"move":{"x":-33,"y":-42,"z":40},"block_id":98},{"move":{"x":-33,"y":-42,"z":41},"block_id":98},{"move":{"x":-33,"y":-42,"z":42},"block_id":98},{"move":{"x":-33,"y":-42,"z":43},"block_id":98},{"move":{"x":-33,"y":-42,"z":44},"block_id":98},{"move":{"x":-33,"y":-42,"z":45},"block_id":98},{"move":{"x":-33,"y":-41,"z":25},"block_id":98},{"move":{"x":-33,"y":-41,"z":26},"block_id":98},{"move":{"x":-33,"y":-41,"z":27},"block_id":98},{"move":{"x":-33,"y":-41,"z":28},"block_id":98},{"move":{"x":-33,"y":-41,"z":29},"block_id":98},{"move":{"x":-33,"y":-41,"z":30},"block_id":98},{"move":{"x":-33,"y":-41,"z":31},"block_id":98},{"move":{"x":-33,"y":-41,"z":32},"block_id":98},{"move":{"x":-33,"y":-41,"z":33},"block_id":98},{"move":{"x":-33,"y":-41,"z":34},"block_id":98},{"move":{"x":-33,"y":-41,"z":35},"block_id":98},{"move":{"x":-33,"y":-41,"z":36},"block_id":98},{"move":{"x":-33,"y":-41,"z":37},"block_id":98},{"move":{"x":-33,"y":-41,"z":38},"block_id":98},{"move":{"x":-33,"y":-41,"z":39},"block_id":98},{"move":{"x":-33,"y":-41,"z":40},"block_id":98},{"move":{"x":-33,"y":-41,"z":41},"block_id":98},{"move":{"x":-33,"y":-41,"z":42},"block_id":98},{"move":{"x":-33,"y":-41,"z":43},"block_id":98},{"move":{"x":-33,"y":-41,"z":44},"block_id":98},{"move":{"x":-33,"y":-41,"z":45},"block_id":98},{"move":{"x":-33,"y":-41,"z":46},"block_id":98},{"move":{"x":-33,"y":-40,"z":24},"block_id":777,"rotate":{"x":18,"y":0,"z":0}},{"move":{"x":-33,"y":-40,"z":25},"block_id":98},{"move":{"x":-33,"y":-40,"z":26},"block_id":98},{"move":{"x":-33,"y":-40,"z":27},"block_id":98},{"move":{"x":-33,"y":-40,"z":28},"block_id":98},{"move":{"x":-33,"y":-40,"z":29},"block_id":98},{"move":{"x":-33,"y":-40,"z":30},"block_id":98},{"move":{"x":-33,"y":-40,"z":31},"block_id":98},{"move":{"x":-33,"y":-40,"z":32},"block_id":98},{"move":{"x":-33,"y":-40,"z":33},"block_id":98},{"move":{"x":-33,"y":-40,"z":34},"block_id":98},{"move":{"x":-33,"y":-40,"z":35},"block_id":98},{"move":{"x":-33,"y":-40,"z":36},"block_id":98},{"move":{"x":-33,"y":-40,"z":37},"block_id":98},{"move":{"x":-33,"y":-40,"z":38},"block_id":98},{"move":{"x":-33,"y":-40,"z":39},"block_id":98},{"move":{"x":-33,"y":-40,"z":40},"block_id":98},{"move":{"x":-33,"y":-40,"z":41},"block_id":98},{"move":{"x":-33,"y":-40,"z":42},"block_id":98},{"move":{"x":-33,"y":-40,"z":43},"block_id":98},{"move":{"x":-33,"y":-40,"z":44},"block_id":98},{"move":{"x":-33,"y":-40,"z":45},"block_id":98},{"move":{"x":-33,"y":-40,"z":46},"block_id":98},{"move":{"x":-33,"y":-40,"z":47},"block_id":777,"rotate":{"x":7,"y":0,"z":0}},{"move":{"x":-33,"y":-39,"z":23},"block_id":98},{"move":{"x":-33,"y":-39,"z":24},"block_id":98},{"move":{"x":-33,"y":-39,"z":25},"block_id":98},{"move":{"x":-33,"y":-39,"z":26},"block_id":98},{"move":{"x":-33,"y":-39,"z":27},"block_id":98},{"move":{"x":-33,"y":-39,"z":28},"block_id":98},{"move":{"x":-33,"y":-39,"z":29},"block_id":98},{"move":{"x":-33,"y":-39,"z":30},"block_id":98},{"move":{"x":-33,"y":-39,"z":31},"block_id":98},{"move":{"x":-33,"y":-39,"z":32},"block_id":98},{"move":{"x":-33,"y":-39,"z":33},"block_id":98},{"move":{"x":-33,"y":-39,"z":34},"block_id":98},{"move":{"x":-33,"y":-39,"z":35},"block_id":98},{"move":{"x":-33,"y":-39,"z":36},"block_id":98},{"move":{"x":-33,"y":-39,"z":37},"block_id":98},{"move":{"x":-33,"y":-39,"z":38},"block_id":98},{"move":{"x":-33,"y":-39,"z":39},"block_id":98},{"move":{"x":-33,"y":-39,"z":40},"block_id":98},{"move":{"x":-33,"y":-39,"z":41},"block_id":98},{"move":{"x":-33,"y":-39,"z":42},"block_id":98},{"move":{"x":-33,"y":-39,"z":43},"block_id":98},{"move":{"x":-33,"y":-39,"z":44},"block_id":98},{"move":{"x":-33,"y":-39,"z":45},"block_id":98},{"move":{"x":-33,"y":-39,"z":46},"block_id":98},{"move":{"x":-33,"y":-39,"z":47},"block_id":98},{"move":{"x":-33,"y":-39,"z":48},"block_id":98},{"move":{"x":-33,"y":-38,"z":23},"block_id":98},{"move":{"x":-33,"y":-38,"z":24},"block_id":98},{"move":{"x":-33,"y":-38,"z":25},"block_id":98},{"move":{"x":-33,"y":-38,"z":26},"block_id":98},{"move":{"x":-33,"y":-38,"z":27},"block_id":98},{"move":{"x":-33,"y":-38,"z":28},"block_id":98},{"move":{"x":-33,"y":-38,"z":29},"block_id":98},{"move":{"x":-33,"y":-38,"z":30},"block_id":98},{"move":{"x":-33,"y":-38,"z":31},"block_id":98},{"move":{"x":-33,"y":-38,"z":32},"block_id":98},{"move":{"x":-33,"y":-38,"z":33},"block_id":98},{"move":{"x":-33,"y":-38,"z":34},"block_id":98},{"move":{"x":-33,"y":-38,"z":35},"block_id":98},{"move":{"x":-33,"y":-38,"z":36},"block_id":98},{"move":{"x":-33,"y":-38,"z":37},"block_id":98},{"move":{"x":-33,"y":-38,"z":38},"block_id":98},{"move":{"x":-33,"y":-38,"z":39},"block_id":98},{"move":{"x":-33,"y":-38,"z":40},"block_id":98},{"move":{"x":-33,"y":-38,"z":41},"block_id":98},{"move":{"x":-33,"y":-38,"z":42},"block_id":98},{"move":{"x":-33,"y":-38,"z":43},"block_id":98},{"move":{"x":-33,"y":-38,"z":44},"block_id":98},{"move":{"x":-33,"y":-38,"z":45},"block_id":98},{"move":{"x":-33,"y":-38,"z":46},"block_id":98},{"move":{"x":-33,"y":-38,"z":47},"block_id":98},{"move":{"x":-33,"y":-38,"z":48},"block_id":98},{"move":{"x":-33,"y":-37,"z":24},"block_id":98},{"move":{"x":-33,"y":-37,"z":47},"block_id":98},{"move":{"x":-33,"y":-36,"z":24},"block_id":98},{"move":{"x":-33,"y":-36,"z":47},"block_id":98},{"move":{"x":-33,"y":-35,"z":24},"block_id":98},{"move":{"x":-33,"y":-35,"z":47},"block_id":98},{"move":{"x":-33,"y":-34,"z":24},"block_id":98},{"move":{"x":-33,"y":-34,"z":47},"block_id":98},{"move":{"x":-33,"y":-33,"z":24},"block_id":98},{"move":{"x":-33,"y":-33,"z":47},"block_id":98},{"move":{"x":-33,"y":-32,"z":24},"block_id":98},{"move":{"x":-33,"y":-32,"z":47},"block_id":98},{"move":{"x":-33,"y":-31,"z":24},"block_id":98},{"move":{"x":-33,"y":-31,"z":47},"block_id":98},{"move":{"x":-33,"y":-30,"z":24},"block_id":98},{"move":{"x":-33,"y":-30,"z":47},"block_id":98},{"move":{"x":-33,"y":-29,"z":24},"block_id":98},{"move":{"x":-33,"y":-29,"z":47},"block_id":98},{"move":{"x":-33,"y":-28,"z":24},"block_id":98},{"move":{"x":-33,"y":-28,"z":47},"block_id":98},{"move":{"x":-33,"y":-27,"z":24},"block_id":98},{"move":{"x":-33,"y":-27,"z":47},"block_id":98},{"move":{"x":-33,"y":-26,"z":24},"block_id":98},{"move":{"x":-33,"y":-26,"z":47},"block_id":98},{"move":{"x":-33,"y":-25,"z":24},"block_id":98},{"move":{"x":-33,"y":-25,"z":47},"block_id":98},{"move":{"x":-33,"y":-24,"z":24},"block_id":98},{"move":{"x":-33,"y":-24,"z":47},"block_id":98},{"move":{"x":-33,"y":-23,"z":24},"block_id":98},{"move":{"x":-33,"y":-23,"z":47},"block_id":98},{"move":{"x":-33,"y":-22,"z":24},"block_id":98},{"move":{"x":-33,"y":-22,"z":47},"block_id":98},{"move":{"x":-33,"y":-21,"z":24},"block_id":98},{"move":{"x":-33,"y":-21,"z":47},"block_id":98},{"move":{"x":-33,"y":-20,"z":24},"block_id":98},{"move":{"x":-33,"y":-20,"z":47},"block_id":98},{"move":{"x":-33,"y":-19,"z":24},"block_id":98},{"move":{"x":-33,"y":-19,"z":47},"block_id":98},{"move":{"x":-33,"y":-18,"z":3},"block_id":98},{"move":{"x":-33,"y":-18,"z":4},"block_id":98},{"move":{"x":-33,"y":-18,"z":5},"block_id":98},{"move":{"x":-33,"y":-18,"z":6},"block_id":98},{"move":{"x":-33,"y":-18,"z":7},"block_id":98},{"move":{"x":-33,"y":-18,"z":8},"block_id":98},{"move":{"x":-33,"y":-18,"z":9},"block_id":98},{"move":{"x":-33,"y":-18,"z":10},"block_id":98},{"move":{"x":-33,"y":-18,"z":11},"block_id":98},{"move":{"x":-33,"y":-18,"z":12},"block_id":98},{"move":{"x":-33,"y":-18,"z":13},"block_id":98},{"move":{"x":-33,"y":-18,"z":14},"block_id":98},{"move":{"x":-33,"y":-18,"z":15},"block_id":98},{"move":{"x":-33,"y":-18,"z":16},"block_id":98},{"move":{"x":-33,"y":-18,"z":17},"block_id":98},{"move":{"x":-33,"y":-18,"z":18},"block_id":98},{"move":{"x":-33,"y":-18,"z":19},"block_id":98},{"move":{"x":-33,"y":-18,"z":20},"block_id":98},{"move":{"x":-33,"y":-18,"z":21},"block_id":98},{"move":{"x":-33,"y":-18,"z":22},"block_id":98},{"move":{"x":-33,"y":-18,"z":23},"block_id":98},{"move":{"x":-33,"y":-18,"z":24},"block_id":98},{"move":{"x":-33,"y":-18,"z":25},"block_id":98},{"move":{"x":-33,"y":-18,"z":26},"block_id":98},{"move":{"x":-33,"y":-18,"z":27},"block_id":98},{"move":{"x":-33,"y":-18,"z":28},"block_id":98},{"move":{"x":-33,"y":-18,"z":29},"block_id":98},{"move":{"x":-33,"y":-18,"z":30},"block_id":98},{"move":{"x":-33,"y":-18,"z":31},"block_id":98},{"move":{"x":-33,"y":-18,"z":32},"block_id":98},{"move":{"x":-33,"y":-18,"z":33},"block_id":98},{"move":{"x":-33,"y":-18,"z":34},"block_id":98},{"move":{"x":-33,"y":-18,"z":35},"block_id":98},{"move":{"x":-33,"y":-18,"z":36},"block_id":98},{"move":{"x":-33,"y":-18,"z":37},"block_id":98},{"move":{"x":-33,"y":-18,"z":38},"block_id":98},{"move":{"x":-33,"y":-18,"z":39},"block_id":98},{"move":{"x":-33,"y":-18,"z":40},"block_id":98},{"move":{"x":-33,"y":-18,"z":41},"block_id":98},{"move":{"x":-33,"y":-18,"z":42},"block_id":98},{"move":{"x":-33,"y":-18,"z":43},"block_id":98},{"move":{"x":-33,"y":-18,"z":44},"block_id":98},{"move":{"x":-33,"y":-18,"z":45},"block_id":98},{"move":{"x":-33,"y":-18,"z":46},"block_id":98},{"move":{"x":-33,"y":-18,"z":47},"block_id":98},{"move":{"x":-33,"y":-18,"z":48},"block_id":98},{"move":{"x":-33,"y":-18,"z":49},"block_id":98},{"move":{"x":-33,"y":-18,"z":50},"block_id":98},{"move":{"x":-33,"y":-18,"z":51},"block_id":98},{"move":{"x":-33,"y":-18,"z":52},"block_id":98},{"move":{"x":-33,"y":-18,"z":53},"block_id":98},{"move":{"x":-33,"y":-18,"z":54},"block_id":98},{"move":{"x":-33,"y":-18,"z":55},"block_id":98},{"move":{"x":-33,"y":-18,"z":56},"block_id":98},{"move":{"x":-33,"y":-18,"z":57},"block_id":98},{"move":{"x":-33,"y":-18,"z":58},"block_id":98},{"move":{"x":-33,"y":-18,"z":59},"block_id":98},{"move":{"x":-33,"y":-18,"z":60},"block_id":98},{"move":{"x":-33,"y":-18,"z":61},"block_id":98},{"move":{"x":-33,"y":-18,"z":62},"block_id":98},{"move":{"x":-33,"y":-18,"z":63},"block_id":98},{"move":{"x":-33,"y":-18,"z":64},"block_id":98},{"move":{"x":-33,"y":-18,"z":65},"block_id":98},{"move":{"x":-33,"y":-18,"z":66},"block_id":98},{"move":{"x":-33,"y":-18,"z":67},"block_id":98},{"move":{"x":-33,"y":-18,"z":68},"block_id":98},{"move":{"x":-32,"y":-56,"z":27},"block_id":98},{"move":{"x":-32,"y":-56,"z":28},"block_id":98},{"move":{"x":-32,"y":-56,"z":29},"block_id":98},{"move":{"x":-32,"y":-56,"z":30},"block_id":98},{"move":{"x":-32,"y":-56,"z":31},"block_id":98},{"move":{"x":-32,"y":-56,"z":32},"block_id":98},{"move":{"x":-32,"y":-56,"z":33},"block_id":98},{"move":{"x":-32,"y":-56,"z":34},"block_id":98},{"move":{"x":-32,"y":-56,"z":35},"block_id":98},{"move":{"x":-32,"y":-56,"z":36},"block_id":98},{"move":{"x":-32,"y":-56,"z":37},"block_id":98},{"move":{"x":-32,"y":-56,"z":38},"block_id":98},{"move":{"x":-32,"y":-56,"z":39},"block_id":98},{"move":{"x":-32,"y":-56,"z":40},"block_id":98},{"move":{"x":-32,"y":-56,"z":41},"block_id":98},{"move":{"x":-32,"y":-56,"z":42},"block_id":98},{"move":{"x":-32,"y":-56,"z":43},"block_id":98},{"move":{"x":-32,"y":-56,"z":44},"block_id":98},{"move":{"x":-32,"y":-55,"z":26},"block_id":98},{"move":{"x":-32,"y":-55,"z":45},"block_id":98},{"move":{"x":-32,"y":-54,"z":26},"block_id":98},{"move":{"x":-32,"y":-54,"z":28},"block_id":98},{"move":{"x":-32,"y":-54,"z":29},"block_id":101,"extra_data":{"point":{"x":0,"y":0.1,"z":0}}},{"move":{"x":-32,"y":-54,"z":30},"block_id":98},{"move":{"x":-32,"y":-54,"z":32},"block_id":98},{"move":{"x":-32,"y":-54,"z":33},"block_id":101,"extra_data":{"point":{"x":0,"y":0.1,"z":0}}},{"move":{"x":-32,"y":-54,"z":34},"block_id":98},{"move":{"x":-32,"y":-54,"z":37},"block_id":98},{"move":{"x":-32,"y":-54,"z":38},"block_id":101,"extra_data":{"point":{"x":0,"y":0.1,"z":0}}},{"move":{"x":-32,"y":-54,"z":39},"block_id":98},{"move":{"x":-32,"y":-54,"z":41},"block_id":98},{"move":{"x":-32,"y":-54,"z":42},"block_id":101,"extra_data":{"point":{"x":0,"y":0.1,"z":0}}},{"move":{"x":-32,"y":-54,"z":43},"block_id":98},{"move":{"x":-32,"y":-54,"z":45},"block_id":98},{"move":{"x":-32,"y":-53,"z":26},"block_id":98},{"move":{"x":-32,"y":-53,"z":28},"block_id":98},{"move":{"x":-32,"y":-53,"z":29},"block_id":199,"rotate":{"x":3,"y":0,"z":0}},{"move":{"x":-32,"y":-53,"z":30},"block_id":98},{"move":{"x":-32,"y":-53,"z":32},"block_id":98},{"move":{"x":-32,"y":-53,"z":33},"block_id":199,"rotate":{"x":3,"y":0,"z":0}},{"move":{"x":-32,"y":-53,"z":34},"block_id":98},{"move":{"x":-32,"y":-53,"z":37},"block_id":98},{"move":{"x":-32,"y":-53,"z":38},"block_id":199,"rotate":{"x":3,"y":1,"z":0}},{"move":{"x":-32,"y":-53,"z":39},"block_id":98},{"move":{"x":-32,"y":-53,"z":41},"block_id":98},{"move":{"x":-32,"y":-53,"z":42},"block_id":199,"rotate":{"x":3,"y":1,"z":0}},{"move":{"x":-32,"y":-53,"z":43},"block_id":98},{"move":{"x":-32,"y":-53,"z":45},"block_id":98},{"move":{"x":-32,"y":-52,"z":26},"block_id":98},{"move":{"x":-32,"y":-52,"z":28},"block_id":98},{"move":{"x":-32,"y":-52,"z":29},"block_id":199,"rotate":{"x":3,"y":1,"z":0}},{"move":{"x":-32,"y":-52,"z":30},"block_id":98},{"move":{"x":-32,"y":-52,"z":32},"block_id":98},{"move":{"x":-32,"y":-52,"z":33},"block_id":199,"rotate":{"x":3,"y":1,"z":0}},{"move":{"x":-32,"y":-52,"z":34},"block_id":98},{"move":{"x":-32,"y":-52,"z":37},"block_id":98},{"move":{"x":-32,"y":-52,"z":38},"block_id":199,"rotate":{"x":3,"y":1,"z":0}},{"move":{"x":-32,"y":-52,"z":39},"block_id":98},{"move":{"x":-32,"y":-52,"z":41},"block_id":98},{"move":{"x":-32,"y":-52,"z":42},"block_id":199,"rotate":{"x":3,"y":1,"z":0}},{"move":{"x":-32,"y":-52,"z":43},"block_id":98},{"move":{"x":-32,"y":-52,"z":45},"block_id":98},{"move":{"x":-32,"y":-51,"z":26},"block_id":98},{"move":{"x":-32,"y":-51,"z":28},"block_id":98},{"move":{"x":-32,"y":-51,"z":29},"block_id":199,"rotate":{"x":3,"y":1,"z":0}},{"move":{"x":-32,"y":-51,"z":30},"block_id":98},{"move":{"x":-32,"y":-51,"z":32},"block_id":98},{"move":{"x":-32,"y":-51,"z":33},"block_id":199,"rotate":{"x":3,"y":1,"z":0}},{"move":{"x":-32,"y":-51,"z":34},"block_id":98},{"move":{"x":-32,"y":-51,"z":37},"block_id":98},{"move":{"x":-32,"y":-51,"z":38},"block_id":199,"rotate":{"x":3,"y":1,"z":0}},{"move":{"x":-32,"y":-51,"z":39},"block_id":98},{"move":{"x":-32,"y":-51,"z":41},"block_id":98},{"move":{"x":-32,"y":-51,"z":42},"block_id":199,"rotate":{"x":3,"y":1,"z":0}},{"move":{"x":-32,"y":-51,"z":43},"block_id":98},{"move":{"x":-32,"y":-51,"z":45},"block_id":98},{"move":{"x":-32,"y":-50,"z":26},"block_id":98},{"move":{"x":-32,"y":-50,"z":28},"block_id":98},{"move":{"x":-32,"y":-50,"z":29},"block_id":615,"extra_data":{"point":{"x":0,"y":0.9,"z":0}},"rotate":{"x":3,"y":0,"z":0}},{"move":{"x":-32,"y":-50,"z":30},"block_id":98},{"move":{"x":-32,"y":-50,"z":32},"block_id":98},{"move":{"x":-32,"y":-50,"z":33},"block_id":615,"extra_data":{"point":{"x":0,"y":0.9,"z":0}},"rotate":{"x":3,"y":0,"z":0}},{"move":{"x":-32,"y":-50,"z":34},"block_id":98},{"move":{"x":-32,"y":-50,"z":37},"block_id":98},{"move":{"x":-32,"y":-50,"z":38},"block_id":615,"extra_data":{"point":{"x":0,"y":0.9,"z":0}},"rotate":{"x":3,"y":0,"z":0}},{"move":{"x":-32,"y":-50,"z":39},"block_id":98},{"move":{"x":-32,"y":-50,"z":41},"block_id":98},{"move":{"x":-32,"y":-50,"z":42},"block_id":615,"extra_data":{"point":{"x":0,"y":0.9,"z":0}},"rotate":{"x":3,"y":0,"z":0}},{"move":{"x":-32,"y":-50,"z":43},"block_id":98},{"move":{"x":-32,"y":-50,"z":45},"block_id":98},{"move":{"x":-32,"y":-49,"z":26},"block_id":98},{"move":{"x":-32,"y":-49,"z":28},"block_id":98},{"move":{"x":-32,"y":-49,"z":29},"block_id":98},{"move":{"x":-32,"y":-49,"z":30},"block_id":98},{"move":{"x":-32,"y":-49,"z":32},"block_id":98},{"move":{"x":-32,"y":-49,"z":33},"block_id":98},{"move":{"x":-32,"y":-49,"z":34},"block_id":98},{"move":{"x":-32,"y":-49,"z":37},"block_id":98},{"move":{"x":-32,"y":-49,"z":38},"block_id":98},{"move":{"x":-32,"y":-49,"z":39},"block_id":98},{"move":{"x":-32,"y":-49,"z":41},"block_id":98},{"move":{"x":-32,"y":-49,"z":42},"block_id":98},{"move":{"x":-32,"y":-49,"z":43},"block_id":98},{"move":{"x":-32,"y":-49,"z":45},"block_id":98},{"move":{"x":-32,"y":-48,"z":26},"block_id":98},{"move":{"x":-32,"y":-48,"z":27},"block_id":98},{"move":{"x":-32,"y":-48,"z":28},"block_id":98},{"move":{"x":-32,"y":-48,"z":29},"block_id":98},{"move":{"x":-32,"y":-48,"z":30},"block_id":98},{"move":{"x":-32,"y":-48,"z":31},"block_id":98},{"move":{"x":-32,"y":-48,"z":32},"block_id":98},{"move":{"x":-32,"y":-48,"z":33},"block_id":98},{"move":{"x":-32,"y":-48,"z":34},"block_id":98},{"move":{"x":-32,"y":-48,"z":35},"block_id":98},{"move":{"x":-32,"y":-48,"z":36},"block_id":98},{"move":{"x":-32,"y":-48,"z":37},"block_id":98},{"move":{"x":-32,"y":-48,"z":38},"block_id":98},{"move":{"x":-32,"y":-48,"z":39},"block_id":98},{"move":{"x":-32,"y":-48,"z":40},"block_id":98},{"move":{"x":-32,"y":-48,"z":41},"block_id":98},{"move":{"x":-32,"y":-48,"z":42},"block_id":98},{"move":{"x":-32,"y":-48,"z":43},"block_id":98},{"move":{"x":-32,"y":-48,"z":44},"block_id":98},{"move":{"x":-32,"y":-48,"z":45},"block_id":98},{"move":{"x":-32,"y":-47,"z":26},"block_id":98},{"move":{"x":-32,"y":-47,"z":45},"block_id":98},{"move":{"x":-32,"y":-46,"z":26},"block_id":98},{"move":{"x":-32,"y":-46,"z":45},"block_id":98},{"move":{"x":-32,"y":-45,"z":26},"block_id":98},{"move":{"x":-32,"y":-45,"z":45},"block_id":98},{"move":{"x":-32,"y":-44,"z":26},"block_id":98},{"move":{"x":-32,"y":-44,"z":45},"block_id":98},{"move":{"x":-32,"y":-43,"z":26},"block_id":98},{"move":{"x":-32,"y":-43,"z":45},"block_id":98},{"move":{"x":-32,"y":-42,"z":26},"block_id":98},{"move":{"x":-32,"y":-42,"z":45},"block_id":98},{"move":{"x":-32,"y":-41,"z":25},"block_id":98},{"move":{"x":-32,"y":-41,"z":26},"block_id":98},{"move":{"x":-32,"y":-41,"z":45},"block_id":98},{"move":{"x":-32,"y":-41,"z":46},"block_id":98},{"move":{"x":-32,"y":-40,"z":24},"block_id":777,"rotate":{"x":18,"y":0,"z":0}},{"move":{"x":-32,"y":-40,"z":25},"block_id":98},{"move":{"x":-32,"y":-40,"z":26},"block_id":98},{"move":{"x":-32,"y":-40,"z":45},"block_id":98},{"move":{"x":-32,"y":-40,"z":46},"block_id":98},{"move":{"x":-32,"y":-40,"z":47},"block_id":777,"rotate":{"x":7,"y":0,"z":0}},{"move":{"x":-32,"y":-39,"z":13},"block_id":98},{"move":{"x":-32,"y":-39,"z":14},"block_id":98},{"move":{"x":-32,"y":-39,"z":15},"block_id":98},{"move":{"x":-32,"y":-39,"z":16},"block_id":98},{"move":{"x":-32,"y":-39,"z":17},"block_id":98},{"move":{"x":-32,"y":-39,"z":18},"block_id":98},{"move":{"x":-32,"y":-39,"z":19},"block_id":98},{"move":{"x":-32,"y":-39,"z":20},"block_id":98},{"move":{"x":-32,"y":-39,"z":21},"block_id":98},{"move":{"x":-32,"y":-39,"z":22},"block_id":98},{"move":{"x":-32,"y":-39,"z":23},"block_id":98},{"move":{"x":-32,"y":-39,"z":24},"block_id":98},{"move":{"x":-32,"y":-39,"z":25},"block_id":98},{"move":{"x":-32,"y":-39,"z":26},"block_id":98},{"move":{"x":-32,"y":-39,"z":45},"block_id":98},{"move":{"x":-32,"y":-39,"z":46},"block_id":98},{"move":{"x":-32,"y":-39,"z":47},"block_id":98},{"move":{"x":-32,"y":-39,"z":48},"block_id":98},{"move":{"x":-32,"y":-39,"z":49},"block_id":98},{"move":{"x":-32,"y":-39,"z":50},"block_id":98},{"move":{"x":-32,"y":-39,"z":51},"block_id":98},{"move":{"x":-32,"y":-39,"z":52},"block_id":98},{"move":{"x":-32,"y":-39,"z":53},"block_id":98},{"move":{"x":-32,"y":-39,"z":54},"block_id":98},{"move":{"x":-32,"y":-39,"z":55},"block_id":98},{"move":{"x":-32,"y":-39,"z":56},"block_id":98},{"move":{"x":-32,"y":-39,"z":57},"block_id":98},{"move":{"x":-32,"y":-39,"z":58},"block_id":98},{"move":{"x":-32,"y":-38,"z":13},"block_id":98},{"move":{"x":-32,"y":-38,"z":14},"block_id":98},{"move":{"x":-32,"y":-38,"z":15},"block_id":98},{"move":{"x":-32,"y":-38,"z":16},"block_id":98},{"move":{"x":-32,"y":-38,"z":17},"block_id":98},{"move":{"x":-32,"y":-38,"z":18},"block_id":98},{"move":{"x":-32,"y":-38,"z":19},"block_id":98},{"move":{"x":-32,"y":-38,"z":20},"block_id":98},{"move":{"x":-32,"y":-38,"z":21},"block_id":98},{"move":{"x":-32,"y":-38,"z":22},"block_id":98},{"move":{"x":-32,"y":-38,"z":23},"block_id":98},{"move":{"x":-32,"y":-38,"z":24},"block_id":98},{"move":{"x":-32,"y":-38,"z":25},"block_id":98},{"move":{"x":-32,"y":-38,"z":26},"block_id":98},{"move":{"x":-32,"y":-38,"z":45},"block_id":98},{"move":{"x":-32,"y":-38,"z":46},"block_id":98},{"move":{"x":-32,"y":-38,"z":47},"block_id":98},{"move":{"x":-32,"y":-38,"z":48},"block_id":98},{"move":{"x":-32,"y":-38,"z":49},"block_id":98},{"move":{"x":-32,"y":-38,"z":50},"block_id":98},{"move":{"x":-32,"y":-38,"z":51},"block_id":98},{"move":{"x":-32,"y":-38,"z":52},"block_id":98},{"move":{"x":-32,"y":-38,"z":53},"block_id":98},{"move":{"x":-32,"y":-38,"z":54},"block_id":98},{"move":{"x":-32,"y":-38,"z":55},"block_id":98},{"move":{"x":-32,"y":-38,"z":56},"block_id":98},{"move":{"x":-32,"y":-38,"z":57},"block_id":98},{"move":{"x":-32,"y":-38,"z":58},"block_id":98},{"move":{"x":-32,"y":-37,"z":24},"block_id":98},{"move":{"x":-32,"y":-37,"z":47},"block_id":98},{"move":{"x":-32,"y":-36,"z":24},"block_id":98},{"move":{"x":-32,"y":-36,"z":47},"block_id":98},{"move":{"x":-32,"y":-35,"z":24},"block_id":98},{"move":{"x":-32,"y":-35,"z":47},"block_id":98},{"move":{"x":-32,"y":-34,"z":24},"block_id":98},{"move":{"x":-32,"y":-34,"z":47},"block_id":98},{"move":{"x":-32,"y":-33,"z":24},"block_id":98},{"move":{"x":-32,"y":-33,"z":47},"block_id":98},{"move":{"x":-32,"y":-32,"z":24},"block_id":98},{"move":{"x":-32,"y":-32,"z":47},"block_id":98},{"move":{"x":-32,"y":-31,"z":24},"block_id":98},{"move":{"x":-32,"y":-31,"z":47},"block_id":98},{"move":{"x":-32,"y":-30,"z":24},"block_id":98},{"move":{"x":-32,"y":-30,"z":47},"block_id":98},{"move":{"x":-32,"y":-29,"z":24},"block_id":98},{"move":{"x":-32,"y":-29,"z":47},"block_id":98},{"move":{"x":-32,"y":-28,"z":24},"block_id":98},{"move":{"x":-32,"y":-28,"z":47},"block_id":98},{"move":{"x":-32,"y":-27,"z":24},"block_id":98},{"move":{"x":-32,"y":-27,"z":47},"block_id":98},{"move":{"x":-32,"y":-26,"z":24},"block_id":98},{"move":{"x":-32,"y":-26,"z":47},"block_id":98},{"move":{"x":-32,"y":-25,"z":24},"block_id":98},{"move":{"x":-32,"y":-25,"z":47},"block_id":98},{"move":{"x":-32,"y":-24,"z":24},"block_id":98},{"move":{"x":-32,"y":-24,"z":47},"block_id":98},{"move":{"x":-32,"y":-23,"z":24},"block_id":98},{"move":{"x":-32,"y":-23,"z":47},"block_id":98},{"move":{"x":-32,"y":-22,"z":24},"block_id":98},{"move":{"x":-32,"y":-22,"z":47},"block_id":98},{"move":{"x":-32,"y":-21,"z":24},"block_id":98},{"move":{"x":-32,"y":-21,"z":47},"block_id":98},{"move":{"x":-32,"y":-20,"z":24},"block_id":98},{"move":{"x":-32,"y":-20,"z":47},"block_id":98},{"move":{"x":-32,"y":-19,"z":24},"block_id":98},{"move":{"x":-32,"y":-19,"z":47},"block_id":98},{"move":{"x":-32,"y":-18,"z":2},"block_id":98},{"move":{"x":-32,"y":-18,"z":3},"block_id":98},{"move":{"x":-32,"y":-18,"z":4},"block_id":98},{"move":{"x":-32,"y":-18,"z":5},"block_id":98},{"move":{"x":-32,"y":-18,"z":6},"block_id":98},{"move":{"x":-32,"y":-18,"z":7},"block_id":98},{"move":{"x":-32,"y":-18,"z":8},"block_id":98},{"move":{"x":-32,"y":-18,"z":9},"block_id":98},{"move":{"x":-32,"y":-18,"z":10},"block_id":98},{"move":{"x":-32,"y":-18,"z":11},"block_id":98},{"move":{"x":-32,"y":-18,"z":12},"block_id":98},{"move":{"x":-32,"y":-18,"z":13},"block_id":98},{"move":{"x":-32,"y":-18,"z":14},"block_id":98},{"move":{"x":-32,"y":-18,"z":15},"block_id":98},{"move":{"x":-32,"y":-18,"z":16},"block_id":98},{"move":{"x":-32,"y":-18,"z":17},"block_id":98},{"move":{"x":-32,"y":-18,"z":18},"block_id":98},{"move":{"x":-32,"y":-18,"z":19},"block_id":98},{"move":{"x":-32,"y":-18,"z":20},"block_id":98},{"move":{"x":-32,"y":-18,"z":21},"block_id":98},{"move":{"x":-32,"y":-18,"z":22},"block_id":98},{"move":{"x":-32,"y":-18,"z":23},"block_id":98},{"move":{"x":-32,"y":-18,"z":24},"block_id":98},{"move":{"x":-32,"y":-18,"z":25},"block_id":98},{"move":{"x":-32,"y":-18,"z":26},"block_id":98},{"move":{"x":-32,"y":-18,"z":27},"block_id":98},{"move":{"x":-32,"y":-18,"z":28},"block_id":98},{"move":{"x":-32,"y":-18,"z":29},"block_id":98},{"move":{"x":-32,"y":-18,"z":30},"block_id":98},{"move":{"x":-32,"y":-18,"z":31},"block_id":98},{"move":{"x":-32,"y":-18,"z":32},"block_id":98},{"move":{"x":-32,"y":-18,"z":33},"block_id":98},{"move":{"x":-32,"y":-18,"z":34},"block_id":98},{"move":{"x":-32,"y":-18,"z":35},"block_id":98},{"move":{"x":-32,"y":-18,"z":36},"block_id":98},{"move":{"x":-32,"y":-18,"z":37},"block_id":98},{"move":{"x":-32,"y":-18,"z":38},"block_id":98},{"move":{"x":-32,"y":-18,"z":39},"block_id":98},{"move":{"x":-32,"y":-18,"z":40},"block_id":98},{"move":{"x":-32,"y":-18,"z":41},"block_id":98},{"move":{"x":-32,"y":-18,"z":42},"block_id":98},{"move":{"x":-32,"y":-18,"z":43},"block_id":98},{"move":{"x":-32,"y":-18,"z":44},"block_id":98},{"move":{"x":-32,"y":-18,"z":45},"block_id":98},{"move":{"x":-32,"y":-18,"z":46},"block_id":98},{"move":{"x":-32,"y":-18,"z":47},"block_id":98},{"move":{"x":-32,"y":-18,"z":48},"block_id":98},{"move":{"x":-32,"y":-18,"z":49},"block_id":98},{"move":{"x":-32,"y":-18,"z":50},"block_id":98},{"move":{"x":-32,"y":-18,"z":51},"block_id":98},{"move":{"x":-32,"y":-18,"z":52},"block_id":98},{"move":{"x":-32,"y":-18,"z":53},"block_id":98},{"move":{"x":-32,"y":-18,"z":54},"block_id":98},{"move":{"x":-32,"y":-18,"z":55},"block_id":98},{"move":{"x":-32,"y":-18,"z":56},"block_id":98},{"move":{"x":-32,"y":-18,"z":57},"block_id":98},{"move":{"x":-32,"y":-18,"z":58},"block_id":98},{"move":{"x":-32,"y":-18,"z":59},"block_id":98},{"move":{"x":-32,"y":-18,"z":60},"block_id":98},{"move":{"x":-32,"y":-18,"z":61},"block_id":98},{"move":{"x":-32,"y":-18,"z":62},"block_id":98},{"move":{"x":-32,"y":-18,"z":63},"block_id":98},{"move":{"x":-32,"y":-18,"z":64},"block_id":98},{"move":{"x":-32,"y":-18,"z":65},"block_id":98},{"move":{"x":-32,"y":-18,"z":66},"block_id":98},{"move":{"x":-32,"y":-18,"z":67},"block_id":98},{"move":{"x":-32,"y":-18,"z":68},"block_id":98},{"move":{"x":-32,"y":-18,"z":69},"block_id":98},{"move":{"x":-31,"y":-67,"z":28},"block_id":98},{"move":{"x":-31,"y":-67,"z":29},"block_id":98},{"move":{"x":-31,"y":-67,"z":30},"block_id":98},{"move":{"x":-31,"y":-67,"z":31},"block_id":98},{"move":{"x":-31,"y":-67,"z":32},"block_id":98},{"move":{"x":-31,"y":-67,"z":33},"block_id":98},{"move":{"x":-31,"y":-67,"z":34},"block_id":98},{"move":{"x":-31,"y":-67,"z":35},"block_id":98},{"move":{"x":-31,"y":-67,"z":36},"block_id":98},{"move":{"x":-31,"y":-67,"z":37},"block_id":98},{"move":{"x":-31,"y":-67,"z":38},"block_id":98},{"move":{"x":-31,"y":-67,"z":39},"block_id":98},{"move":{"x":-31,"y":-67,"z":40},"block_id":98},{"move":{"x":-31,"y":-67,"z":41},"block_id":98},{"move":{"x":-31,"y":-67,"z":42},"block_id":98},{"move":{"x":-31,"y":-67,"z":43},"block_id":98},{"move":{"x":-31,"y":-66,"z":28},"block_id":98},{"move":{"x":-31,"y":-66,"z":29},"block_id":98},{"move":{"x":-31,"y":-66,"z":30},"block_id":98},{"move":{"x":-31,"y":-66,"z":31},"block_id":98},{"move":{"x":-31,"y":-66,"z":32},"block_id":98},{"move":{"x":-31,"y":-66,"z":33},"block_id":98},{"move":{"x":-31,"y":-66,"z":34},"block_id":98},{"move":{"x":-31,"y":-66,"z":35},"block_id":98},{"move":{"x":-31,"y":-66,"z":36},"block_id":98},{"move":{"x":-31,"y":-66,"z":37},"block_id":98},{"move":{"x":-31,"y":-66,"z":38},"block_id":98},{"move":{"x":-31,"y":-66,"z":39},"block_id":98},{"move":{"x":-31,"y":-66,"z":40},"block_id":98},{"move":{"x":-31,"y":-66,"z":41},"block_id":98},{"move":{"x":-31,"y":-66,"z":42},"block_id":98},{"move":{"x":-31,"y":-66,"z":43},"block_id":98},{"move":{"x":-31,"y":-65,"z":28},"block_id":98},{"move":{"x":-31,"y":-65,"z":29},"block_id":98},{"move":{"x":-31,"y":-65,"z":30},"block_id":98},{"move":{"x":-31,"y":-65,"z":31},"block_id":98},{"move":{"x":-31,"y":-65,"z":32},"block_id":98},{"move":{"x":-31,"y":-65,"z":33},"block_id":98},{"move":{"x":-31,"y":-65,"z":34},"block_id":98},{"move":{"x":-31,"y":-65,"z":35},"block_id":98},{"move":{"x":-31,"y":-65,"z":36},"block_id":98},{"move":{"x":-31,"y":-65,"z":37},"block_id":98},{"move":{"x":-31,"y":-65,"z":38},"block_id":98},{"move":{"x":-31,"y":-65,"z":39},"block_id":98},{"move":{"x":-31,"y":-65,"z":40},"block_id":98},{"move":{"x":-31,"y":-65,"z":41},"block_id":98},{"move":{"x":-31,"y":-65,"z":42},"block_id":98},{"move":{"x":-31,"y":-65,"z":43},"block_id":98},{"move":{"x":-31,"y":-57,"z":28},"block_id":98},{"move":{"x":-31,"y":-57,"z":29},"block_id":98},{"move":{"x":-31,"y":-57,"z":30},"block_id":98},{"move":{"x":-31,"y":-57,"z":31},"block_id":98},{"move":{"x":-31,"y":-57,"z":32},"block_id":98},{"move":{"x":-31,"y":-57,"z":33},"block_id":98},{"move":{"x":-31,"y":-57,"z":34},"block_id":98},{"move":{"x":-31,"y":-57,"z":35},"block_id":98},{"move":{"x":-31,"y":-57,"z":36},"block_id":98},{"move":{"x":-31,"y":-57,"z":37},"block_id":98},{"move":{"x":-31,"y":-57,"z":38},"block_id":98},{"move":{"x":-31,"y":-57,"z":39},"block_id":98},{"move":{"x":-31,"y":-57,"z":40},"block_id":98},{"move":{"x":-31,"y":-57,"z":41},"block_id":98},{"move":{"x":-31,"y":-57,"z":42},"block_id":98},{"move":{"x":-31,"y":-57,"z":43},"block_id":98},{"move":{"x":-31,"y":-56,"z":27},"block_id":98},{"move":{"x":-31,"y":-56,"z":28},"block_id":98},{"move":{"x":-31,"y":-56,"z":29},"block_id":98},{"move":{"x":-31,"y":-56,"z":30},"block_id":98},{"move":{"x":-31,"y":-56,"z":31},"block_id":98},{"move":{"x":-31,"y":-56,"z":32},"block_id":98},{"move":{"x":-31,"y":-56,"z":33},"block_id":98},{"move":{"x":-31,"y":-56,"z":34},"block_id":98},{"move":{"x":-31,"y":-56,"z":35},"block_id":98},{"move":{"x":-31,"y":-56,"z":36},"block_id":98},{"move":{"x":-31,"y":-56,"z":37},"block_id":98},{"move":{"x":-31,"y":-56,"z":38},"block_id":98},{"move":{"x":-31,"y":-56,"z":39},"block_id":98},{"move":{"x":-31,"y":-56,"z":40},"block_id":98},{"move":{"x":-31,"y":-56,"z":41},"block_id":98},{"move":{"x":-31,"y":-56,"z":42},"block_id":98},{"move":{"x":-31,"y":-56,"z":43},"block_id":98},{"move":{"x":-31,"y":-56,"z":44},"block_id":98},{"move":{"x":-31,"y":-55,"z":26},"block_id":98},{"move":{"x":-31,"y":-55,"z":45},"block_id":98},{"move":{"x":-31,"y":-54,"z":26},"block_id":98},{"move":{"x":-31,"y":-54,"z":45},"block_id":98},{"move":{"x":-31,"y":-53,"z":14},"block_id":615,"extra_data":{"point":{"x":0,"y":0.9,"z":0}},"rotate":{"x":0,"y":0,"z":0}},{"move":{"x":-31,"y":-53,"z":15},"block_id":615,"extra_data":{"point":{"x":0,"y":0.9,"z":0}},"rotate":{"x":3,"y":0,"z":0}},{"move":{"x":-31,"y":-53,"z":16},"block_id":615,"extra_data":{"point":{"x":0,"y":0.9,"z":0}},"rotate":{"x":3,"y":0,"z":0}},{"move":{"x":-31,"y":-53,"z":17},"block_id":615,"extra_data":{"point":{"x":0,"y":0.9,"z":0}},"rotate":{"x":3,"y":0,"z":0}},{"move":{"x":-31,"y":-53,"z":18},"block_id":615,"extra_data":{"point":{"x":0,"y":0.9,"z":0}},"rotate":{"x":3,"y":0,"z":0}},{"move":{"x":-31,"y":-53,"z":19},"block_id":615,"extra_data":{"point":{"x":0,"y":0.9,"z":0}},"rotate":{"x":3,"y":0,"z":0}},{"move":{"x":-31,"y":-53,"z":20},"block_id":615,"extra_data":{"point":{"x":0,"y":0.9,"z":0}},"rotate":{"x":3,"y":0,"z":0}},{"move":{"x":-31,"y":-53,"z":21},"block_id":615,"extra_data":{"point":{"x":0,"y":0.9,"z":0}},"rotate":{"x":3,"y":0,"z":0}},{"move":{"x":-31,"y":-53,"z":22},"block_id":615,"extra_data":{"point":{"x":0,"y":0.9,"z":0}},"rotate":{"x":3,"y":0,"z":0}},{"move":{"x":-31,"y":-53,"z":23},"block_id":615,"extra_data":{"point":{"x":0,"y":0.9,"z":0}},"rotate":{"x":3,"y":0,"z":0}},{"move":{"x":-31,"y":-53,"z":24},"block_id":615,"extra_data":{"point":{"x":0,"y":0.9,"z":0}},"rotate":{"x":3,"y":0,"z":0}},{"move":{"x":-31,"y":-53,"z":25},"block_id":615,"extra_data":{"point":{"x":0,"y":0.9,"z":0}},"rotate":{"x":3,"y":0,"z":0}},{"move":{"x":-31,"y":-53,"z":26},"block_id":98},{"move":{"x":-31,"y":-53,"z":45},"block_id":98},{"move":{"x":-31,"y":-53,"z":46},"block_id":615,"extra_data":{"point":{"x":0,"y":0.9,"z":0}},"rotate":{"x":3,"y":0,"z":0}},{"move":{"x":-31,"y":-53,"z":47},"block_id":615,"extra_data":{"point":{"x":0,"y":0.9,"z":0}},"rotate":{"x":3,"y":0,"z":0}},{"move":{"x":-31,"y":-53,"z":48},"block_id":615,"extra_data":{"point":{"x":0,"y":0.9,"z":0}},"rotate":{"x":3,"y":0,"z":0}},{"move":{"x":-31,"y":-53,"z":49},"block_id":615,"extra_data":{"point":{"x":0,"y":0.9,"z":0}},"rotate":{"x":3,"y":0,"z":0}},{"move":{"x":-31,"y":-53,"z":50},"block_id":615,"extra_data":{"point":{"x":0,"y":0.9,"z":0}},"rotate":{"x":3,"y":0,"z":0}},{"move":{"x":-31,"y":-53,"z":51},"block_id":615,"extra_data":{"point":{"x":0,"y":0.9,"z":0}},"rotate":{"x":3,"y":0,"z":0}},{"move":{"x":-31,"y":-53,"z":52},"block_id":615,"extra_data":{"point":{"x":0,"y":0.9,"z":0}},"rotate":{"x":3,"y":0,"z":0}},{"move":{"x":-31,"y":-53,"z":53},"block_id":615,"extra_data":{"point":{"x":0,"y":0.9,"z":0}},"rotate":{"x":3,"y":0,"z":0}},{"move":{"x":-31,"y":-53,"z":54},"block_id":615,"extra_data":{"point":{"x":0,"y":0.9,"z":0}},"rotate":{"x":3,"y":0,"z":0}},{"move":{"x":-31,"y":-53,"z":55},"block_id":615,"extra_data":{"point":{"x":0,"y":0.9,"z":0}},"rotate":{"x":3,"y":0,"z":0}},{"move":{"x":-31,"y":-53,"z":56},"block_id":615,"extra_data":{"point":{"x":0,"y":0.9,"z":0}},"rotate":{"x":3,"y":0,"z":0}},{"move":{"x":-31,"y":-53,"z":57},"block_id":615,"extra_data":{"point":{"x":0,"y":0.9,"z":0}},"rotate":{"x":3,"y":0,"z":0}},{"move":{"x":-31,"y":-52,"z":14},"block_id":98},{"move":{"x":-31,"y":-52,"z":15},"block_id":98},{"move":{"x":-31,"y":-52,"z":16},"block_id":98},{"move":{"x":-31,"y":-52,"z":17},"block_id":98},{"move":{"x":-31,"y":-52,"z":18},"block_id":98},{"move":{"x":-31,"y":-52,"z":19},"block_id":98},{"move":{"x":-31,"y":-52,"z":20},"block_id":98},{"move":{"x":-31,"y":-52,"z":21},"block_id":98},{"move":{"x":-31,"y":-52,"z":22},"block_id":98},{"move":{"x":-31,"y":-52,"z":23},"block_id":98},{"move":{"x":-31,"y":-52,"z":24},"block_id":98},{"move":{"x":-31,"y":-52,"z":25},"block_id":98},{"move":{"x":-31,"y":-52,"z":26},"block_id":98},{"move":{"x":-31,"y":-52,"z":45},"block_id":98},{"move":{"x":-31,"y":-52,"z":46},"block_id":98},{"move":{"x":-31,"y":-52,"z":47},"block_id":98},{"move":{"x":-31,"y":-52,"z":48},"block_id":98},{"move":{"x":-31,"y":-52,"z":49},"block_id":98},{"move":{"x":-31,"y":-52,"z":50},"block_id":98},{"move":{"x":-31,"y":-52,"z":51},"block_id":98},{"move":{"x":-31,"y":-52,"z":52},"block_id":98},{"move":{"x":-31,"y":-52,"z":53},"block_id":98},{"move":{"x":-31,"y":-52,"z":54},"block_id":98},{"move":{"x":-31,"y":-52,"z":55},"block_id":98},{"move":{"x":-31,"y":-52,"z":56},"block_id":98},{"move":{"x":-31,"y":-52,"z":57},"block_id":98},{"move":{"x":-31,"y":-51,"z":14},"block_id":98},{"move":{"x":-31,"y":-51,"z":15},"block_id":98},{"move":{"x":-31,"y":-51,"z":16},"block_id":98},{"move":{"x":-31,"y":-51,"z":17},"block_id":98},{"move":{"x":-31,"y":-51,"z":18},"block_id":98},{"move":{"x":-31,"y":-51,"z":19},"block_id":98},{"move":{"x":-31,"y":-51,"z":20},"block_id":98},{"move":{"x":-31,"y":-51,"z":21},"block_id":98},{"move":{"x":-31,"y":-51,"z":22},"block_id":98},{"move":{"x":-31,"y":-51,"z":23},"block_id":98},{"move":{"x":-31,"y":-51,"z":24},"block_id":98},{"move":{"x":-31,"y":-51,"z":25},"block_id":98},{"move":{"x":-31,"y":-51,"z":26},"block_id":98},{"move":{"x":-31,"y":-51,"z":45},"block_id":98},{"move":{"x":-31,"y":-51,"z":46},"block_id":98},{"move":{"x":-31,"y":-51,"z":47},"block_id":98},{"move":{"x":-31,"y":-51,"z":48},"block_id":98},{"move":{"x":-31,"y":-51,"z":49},"block_id":98},{"move":{"x":-31,"y":-51,"z":50},"block_id":98},{"move":{"x":-31,"y":-51,"z":51},"block_id":98},{"move":{"x":-31,"y":-51,"z":52},"block_id":98},{"move":{"x":-31,"y":-51,"z":53},"block_id":98},{"move":{"x":-31,"y":-51,"z":54},"block_id":98},{"move":{"x":-31,"y":-51,"z":55},"block_id":98},{"move":{"x":-31,"y":-51,"z":56},"block_id":98},{"move":{"x":-31,"y":-51,"z":57},"block_id":98},{"move":{"x":-31,"y":-50,"z":14},"block_id":98},{"move":{"x":-31,"y":-50,"z":15},"block_id":98},{"move":{"x":-31,"y":-50,"z":16},"block_id":98},{"move":{"x":-31,"y":-50,"z":23},"block_id":98},{"move":{"x":-31,"y":-50,"z":24},"block_id":98},{"move":{"x":-31,"y":-50,"z":25},"block_id":98},{"move":{"x":-31,"y":-50,"z":26},"block_id":98},{"move":{"x":-31,"y":-50,"z":45},"block_id":98},{"move":{"x":-31,"y":-50,"z":46},"block_id":98},{"move":{"x":-31,"y":-50,"z":47},"block_id":98},{"move":{"x":-31,"y":-50,"z":48},"block_id":98},{"move":{"x":-31,"y":-50,"z":55},"block_id":98},{"move":{"x":-31,"y":-50,"z":56},"block_id":98},{"move":{"x":-31,"y":-50,"z":57},"block_id":98},{"move":{"x":-31,"y":-49,"z":14},"block_id":98},{"move":{"x":-31,"y":-49,"z":15},"block_id":98},{"move":{"x":-31,"y":-49,"z":16},"block_id":98},{"move":{"x":-31,"y":-49,"z":23},"block_id":98},{"move":{"x":-31,"y":-49,"z":24},"block_id":98},{"move":{"x":-31,"y":-49,"z":25},"block_id":98},{"move":{"x":-31,"y":-49,"z":26},"block_id":98},{"move":{"x":-31,"y":-49,"z":45},"block_id":98},{"move":{"x":-31,"y":-49,"z":46},"block_id":98},{"move":{"x":-31,"y":-49,"z":47},"block_id":98},{"move":{"x":-31,"y":-49,"z":48},"block_id":98},{"move":{"x":-31,"y":-49,"z":55},"block_id":98},{"move":{"x":-31,"y":-49,"z":56},"block_id":98},{"move":{"x":-31,"y":-49,"z":57},"block_id":98},{"move":{"x":-31,"y":-48,"z":14},"block_id":98},{"move":{"x":-31,"y":-48,"z":15},"block_id":98},{"move":{"x":-31,"y":-48,"z":16},"block_id":98},{"move":{"x":-31,"y":-48,"z":23},"block_id":98},{"move":{"x":-31,"y":-48,"z":24},"block_id":98},{"move":{"x":-31,"y":-48,"z":25},"block_id":98},{"move":{"x":-31,"y":-48,"z":26},"block_id":98},{"move":{"x":-31,"y":-48,"z":45},"block_id":98},{"move":{"x":-31,"y":-48,"z":46},"block_id":98},{"move":{"x":-31,"y":-48,"z":47},"block_id":98},{"move":{"x":-31,"y":-48,"z":48},"block_id":98},{"move":{"x":-31,"y":-48,"z":55},"block_id":98},{"move":{"x":-31,"y":-48,"z":56},"block_id":98},{"move":{"x":-31,"y":-48,"z":57},"block_id":98},{"move":{"x":-31,"y":-47,"z":14},"block_id":98},{"move":{"x":-31,"y":-47,"z":15},"block_id":98},{"move":{"x":-31,"y":-47,"z":16},"block_id":98},{"move":{"x":-31,"y":-47,"z":23},"block_id":98},{"move":{"x":-31,"y":-47,"z":24},"block_id":98},{"move":{"x":-31,"y":-47,"z":25},"block_id":98},{"move":{"x":-31,"y":-47,"z":26},"block_id":98},{"move":{"x":-31,"y":-47,"z":45},"block_id":98},{"move":{"x":-31,"y":-47,"z":46},"block_id":98},{"move":{"x":-31,"y":-47,"z":47},"block_id":98},{"move":{"x":-31,"y":-47,"z":48},"block_id":98},{"move":{"x":-31,"y":-47,"z":55},"block_id":98},{"move":{"x":-31,"y":-47,"z":56},"block_id":98},{"move":{"x":-31,"y":-47,"z":57},"block_id":98},{"move":{"x":-31,"y":-46,"z":14},"block_id":98},{"move":{"x":-31,"y":-46,"z":15},"block_id":98},{"move":{"x":-31,"y":-46,"z":16},"block_id":98},{"move":{"x":-31,"y":-46,"z":23},"block_id":98},{"move":{"x":-31,"y":-46,"z":24},"block_id":98},{"move":{"x":-31,"y":-46,"z":25},"block_id":98},{"move":{"x":-31,"y":-46,"z":26},"block_id":98},{"move":{"x":-31,"y":-46,"z":45},"block_id":98},{"move":{"x":-31,"y":-46,"z":46},"block_id":98},{"move":{"x":-31,"y":-46,"z":47},"block_id":98},{"move":{"x":-31,"y":-46,"z":48},"block_id":98},{"move":{"x":-31,"y":-46,"z":55},"block_id":98},{"move":{"x":-31,"y":-46,"z":56},"block_id":98},{"move":{"x":-31,"y":-46,"z":57},"block_id":98},{"move":{"x":-31,"y":-45,"z":14},"block_id":98},{"move":{"x":-31,"y":-45,"z":15},"block_id":98},{"move":{"x":-31,"y":-45,"z":16},"block_id":98},{"move":{"x":-31,"y":-45,"z":17},"block_id":615,"extra_data":{"point":{"x":0,"y":0.9,"z":0}},"rotate":{"x":2,"y":0,"z":0}},{"move":{"x":-31,"y":-45,"z":22},"block_id":615,"extra_data":{"point":{"x":0,"y":0.9,"z":0}},"rotate":{"x":0,"y":0,"z":0}},{"move":{"x":-31,"y":-45,"z":23},"block_id":98},{"move":{"x":-31,"y":-45,"z":24},"block_id":98},{"move":{"x":-31,"y":-45,"z":25},"block_id":98},{"move":{"x":-31,"y":-45,"z":26},"block_id":98},{"move":{"x":-31,"y":-45,"z":45},"block_id":98},{"move":{"x":-31,"y":-45,"z":46},"block_id":98},{"move":{"x":-31,"y":-45,"z":47},"block_id":98},{"move":{"x":-31,"y":-45,"z":48},"block_id":98},{"move":{"x":-31,"y":-45,"z":49},"block_id":615,"extra_data":{"point":{"x":0,"y":0.9,"z":0}},"rotate":{"x":2,"y":0,"z":0}},{"move":{"x":-31,"y":-45,"z":54},"block_id":615,"extra_data":{"point":{"x":0,"y":0.9,"z":0}},"rotate":{"x":0,"y":0,"z":0}},{"move":{"x":-31,"y":-45,"z":55},"block_id":98},{"move":{"x":-31,"y":-45,"z":56},"block_id":98},{"move":{"x":-31,"y":-45,"z":57},"block_id":98},{"move":{"x":-31,"y":-44,"z":14},"block_id":98},{"move":{"x":-31,"y":-44,"z":15},"block_id":98},{"move":{"x":-31,"y":-44,"z":16},"block_id":98},{"move":{"x":-31,"y":-44,"z":17},"block_id":98},{"move":{"x":-31,"y":-44,"z":18},"block_id":98},{"move":{"x":-31,"y":-44,"z":19},"block_id":98},{"move":{"x":-31,"y":-44,"z":20},"block_id":98},{"move":{"x":-31,"y":-44,"z":21},"block_id":98},{"move":{"x":-31,"y":-44,"z":22},"block_id":98},{"move":{"x":-31,"y":-44,"z":23},"block_id":98},{"move":{"x":-31,"y":-44,"z":24},"block_id":98},{"move":{"x":-31,"y":-44,"z":25},"block_id":98},{"move":{"x":-31,"y":-44,"z":26},"block_id":98},{"move":{"x":-31,"y":-44,"z":45},"block_id":98},{"move":{"x":-31,"y":-44,"z":46},"block_id":98},{"move":{"x":-31,"y":-44,"z":47},"block_id":98},{"move":{"x":-31,"y":-44,"z":48},"block_id":98},{"move":{"x":-31,"y":-44,"z":49},"block_id":98},{"move":{"x":-31,"y":-44,"z":50},"block_id":98},{"move":{"x":-31,"y":-44,"z":51},"block_id":98},{"move":{"x":-31,"y":-44,"z":52},"block_id":98},{"move":{"x":-31,"y":-44,"z":53},"block_id":98},{"move":{"x":-31,"y":-44,"z":54},"block_id":98},{"move":{"x":-31,"y":-44,"z":55},"block_id":98},{"move":{"x":-31,"y":-44,"z":56},"block_id":98},{"move":{"x":-31,"y":-44,"z":57},"block_id":98},{"move":{"x":-31,"y":-43,"z":14},"block_id":98},{"move":{"x":-31,"y":-43,"z":15},"block_id":98},{"move":{"x":-31,"y":-43,"z":16},"block_id":98},{"move":{"x":-31,"y":-43,"z":17},"block_id":98},{"move":{"x":-31,"y":-43,"z":18},"block_id":98},{"move":{"x":-31,"y":-43,"z":19},"block_id":98},{"move":{"x":-31,"y":-43,"z":20},"block_id":98},{"move":{"x":-31,"y":-43,"z":21},"block_id":98},{"move":{"x":-31,"y":-43,"z":22},"block_id":98},{"move":{"x":-31,"y":-43,"z":23},"block_id":98},{"move":{"x":-31,"y":-43,"z":24},"block_id":98},{"move":{"x":-31,"y":-43,"z":25},"block_id":98},{"move":{"x":-31,"y":-43,"z":26},"block_id":98},{"move":{"x":-31,"y":-43,"z":45},"block_id":98},{"move":{"x":-31,"y":-43,"z":46},"block_id":98},{"move":{"x":-31,"y":-43,"z":47},"block_id":98},{"move":{"x":-31,"y":-43,"z":48},"block_id":98},{"move":{"x":-31,"y":-43,"z":49},"block_id":98},{"move":{"x":-31,"y":-43,"z":50},"block_id":98},{"move":{"x":-31,"y":-43,"z":51},"block_id":98},{"move":{"x":-31,"y":-43,"z":52},"block_id":98},{"move":{"x":-31,"y":-43,"z":53},"block_id":98},{"move":{"x":-31,"y":-43,"z":54},"block_id":98},{"move":{"x":-31,"y":-43,"z":55},"block_id":98},{"move":{"x":-31,"y":-43,"z":56},"block_id":98},{"move":{"x":-31,"y":-43,"z":57},"block_id":98},{"move":{"x":-31,"y":-42,"z":14},"block_id":98},{"move":{"x":-31,"y":-42,"z":15},"block_id":98},{"move":{"x":-31,"y":-42,"z":16},"block_id":98},{"move":{"x":-31,"y":-42,"z":17},"block_id":98},{"move":{"x":-31,"y":-42,"z":18},"block_id":98},{"move":{"x":-31,"y":-42,"z":19},"block_id":98},{"move":{"x":-31,"y":-42,"z":20},"block_id":98},{"move":{"x":-31,"y":-42,"z":21},"block_id":98},{"move":{"x":-31,"y":-42,"z":22},"block_id":98},{"move":{"x":-31,"y":-42,"z":23},"block_id":98},{"move":{"x":-31,"y":-42,"z":24},"block_id":98},{"move":{"x":-31,"y":-42,"z":25},"block_id":98},{"move":{"x":-31,"y":-42,"z":26},"block_id":98},{"move":{"x":-31,"y":-42,"z":45},"block_id":98},{"move":{"x":-31,"y":-42,"z":46},"block_id":98},{"move":{"x":-31,"y":-42,"z":47},"block_id":98},{"move":{"x":-31,"y":-42,"z":48},"block_id":98},{"move":{"x":-31,"y":-42,"z":49},"block_id":98},{"move":{"x":-31,"y":-42,"z":50},"block_id":98},{"move":{"x":-31,"y":-42,"z":51},"block_id":98},{"move":{"x":-31,"y":-42,"z":52},"block_id":98},{"move":{"x":-31,"y":-42,"z":53},"block_id":98},{"move":{"x":-31,"y":-42,"z":54},"block_id":98},{"move":{"x":-31,"y":-42,"z":55},"block_id":98},{"move":{"x":-31,"y":-42,"z":56},"block_id":98},{"move":{"x":-31,"y":-42,"z":57},"block_id":98},{"move":{"x":-31,"y":-41,"z":14},"block_id":98},{"move":{"x":-31,"y":-41,"z":15},"block_id":98},{"move":{"x":-31,"y":-41,"z":16},"block_id":98},{"move":{"x":-31,"y":-41,"z":17},"block_id":98},{"move":{"x":-31,"y":-41,"z":18},"block_id":98},{"move":{"x":-31,"y":-41,"z":19},"block_id":98},{"move":{"x":-31,"y":-41,"z":20},"block_id":98},{"move":{"x":-31,"y":-41,"z":21},"block_id":98},{"move":{"x":-31,"y":-41,"z":22},"block_id":98},{"move":{"x":-31,"y":-41,"z":23},"block_id":98},{"move":{"x":-31,"y":-41,"z":24},"block_id":98},{"move":{"x":-31,"y":-41,"z":25},"block_id":98},{"move":{"x":-31,"y":-41,"z":26},"block_id":98},{"move":{"x":-31,"y":-41,"z":45},"block_id":98},{"move":{"x":-31,"y":-41,"z":46},"block_id":98},{"move":{"x":-31,"y":-41,"z":47},"block_id":98},{"move":{"x":-31,"y":-41,"z":48},"block_id":98},{"move":{"x":-31,"y":-41,"z":49},"block_id":98},{"move":{"x":-31,"y":-41,"z":50},"block_id":98},{"move":{"x":-31,"y":-41,"z":51},"block_id":98},{"move":{"x":-31,"y":-41,"z":52},"block_id":98},{"move":{"x":-31,"y":-41,"z":53},"block_id":98},{"move":{"x":-31,"y":-41,"z":54},"block_id":98},{"move":{"x":-31,"y":-41,"z":55},"block_id":98},{"move":{"x":-31,"y":-41,"z":56},"block_id":98},{"move":{"x":-31,"y":-41,"z":57},"block_id":98},{"move":{"x":-31,"y":-40,"z":14},"block_id":98},{"move":{"x":-31,"y":-40,"z":15},"block_id":98},{"move":{"x":-31,"y":-40,"z":16},"block_id":98},{"move":{"x":-31,"y":-40,"z":17},"block_id":98},{"move":{"x":-31,"y":-40,"z":18},"block_id":98},{"move":{"x":-31,"y":-40,"z":19},"block_id":98},{"move":{"x":-31,"y":-40,"z":20},"block_id":98},{"move":{"x":-31,"y":-40,"z":21},"block_id":98},{"move":{"x":-31,"y":-40,"z":22},"block_id":98},{"move":{"x":-31,"y":-40,"z":23},"block_id":98},{"move":{"x":-31,"y":-40,"z":24},"block_id":98},{"move":{"x":-31,"y":-40,"z":25},"block_id":98},{"move":{"x":-31,"y":-40,"z":26},"block_id":98},{"move":{"x":-31,"y":-40,"z":45},"block_id":98},{"move":{"x":-31,"y":-40,"z":46},"block_id":98},{"move":{"x":-31,"y":-40,"z":47},"block_id":98},{"move":{"x":-31,"y":-40,"z":48},"block_id":98},{"move":{"x":-31,"y":-40,"z":49},"block_id":98},{"move":{"x":-31,"y":-40,"z":50},"block_id":98},{"move":{"x":-31,"y":-40,"z":51},"block_id":98},{"move":{"x":-31,"y":-40,"z":52},"block_id":98},{"move":{"x":-31,"y":-40,"z":53},"block_id":98},{"move":{"x":-31,"y":-40,"z":54},"block_id":98},{"move":{"x":-31,"y":-40,"z":55},"block_id":98},{"move":{"x":-31,"y":-40,"z":56},"block_id":98},{"move":{"x":-31,"y":-40,"z":57},"block_id":98},{"move":{"x":-31,"y":-39,"z":13},"block_id":98},{"move":{"x":-31,"y":-39,"z":14},"block_id":98},{"move":{"x":-31,"y":-39,"z":15},"block_id":98},{"move":{"x":-31,"y":-39,"z":16},"block_id":98},{"move":{"x":-31,"y":-39,"z":17},"block_id":98},{"move":{"x":-31,"y":-39,"z":18},"block_id":98},{"move":{"x":-31,"y":-39,"z":19},"block_id":98},{"move":{"x":-31,"y":-39,"z":20},"block_id":98},{"move":{"x":-31,"y":-39,"z":21},"block_id":98},{"move":{"x":-31,"y":-39,"z":22},"block_id":98},{"move":{"x":-31,"y":-39,"z":23},"block_id":98},{"move":{"x":-31,"y":-39,"z":24},"block_id":98},{"move":{"x":-31,"y":-39,"z":25},"block_id":98},{"move":{"x":-31,"y":-39,"z":26},"block_id":98},{"move":{"x":-31,"y":-39,"z":45},"block_id":98},{"move":{"x":-31,"y":-39,"z":46},"block_id":98},{"move":{"x":-31,"y":-39,"z":47},"block_id":98},{"move":{"x":-31,"y":-39,"z":48},"block_id":98},{"move":{"x":-31,"y":-39,"z":49},"block_id":98},{"move":{"x":-31,"y":-39,"z":50},"block_id":98},{"move":{"x":-31,"y":-39,"z":51},"block_id":98},{"move":{"x":-31,"y":-39,"z":52},"block_id":98},{"move":{"x":-31,"y":-39,"z":53},"block_id":98},{"move":{"x":-31,"y":-39,"z":54},"block_id":98},{"move":{"x":-31,"y":-39,"z":55},"block_id":98},{"move":{"x":-31,"y":-39,"z":56},"block_id":98},{"move":{"x":-31,"y":-39,"z":57},"block_id":98},{"move":{"x":-31,"y":-39,"z":58},"block_id":98},{"move":{"x":-31,"y":-38,"z":13},"block_id":98},{"move":{"x":-31,"y":-38,"z":14},"block_id":98},{"move":{"x":-31,"y":-38,"z":15},"block_id":98},{"move":{"x":-31,"y":-38,"z":16},"block_id":98},{"move":{"x":-31,"y":-38,"z":17},"block_id":98},{"move":{"x":-31,"y":-38,"z":18},"block_id":98},{"move":{"x":-31,"y":-38,"z":19},"block_id":98},{"move":{"x":-31,"y":-38,"z":20},"block_id":98},{"move":{"x":-31,"y":-38,"z":21},"block_id":98},{"move":{"x":-31,"y":-38,"z":22},"block_id":98},{"move":{"x":-31,"y":-38,"z":23},"block_id":98},{"move":{"x":-31,"y":-38,"z":24},"block_id":98},{"move":{"x":-31,"y":-38,"z":25},"block_id":98},{"move":{"x":-31,"y":-38,"z":26},"block_id":98},{"move":{"x":-31,"y":-38,"z":45},"block_id":98},{"move":{"x":-31,"y":-38,"z":46},"block_id":98},{"move":{"x":-31,"y":-38,"z":47},"block_id":98},{"move":{"x":-31,"y":-38,"z":48},"block_id":98},{"move":{"x":-31,"y":-38,"z":49},"block_id":98},{"move":{"x":-31,"y":-38,"z":50},"block_id":98},{"move":{"x":-31,"y":-38,"z":51},"block_id":98},{"move":{"x":-31,"y":-38,"z":52},"block_id":98},{"move":{"x":-31,"y":-38,"z":53},"block_id":98},{"move":{"x":-31,"y":-38,"z":54},"block_id":98},{"move":{"x":-31,"y":-38,"z":55},"block_id":98},{"move":{"x":-31,"y":-38,"z":56},"block_id":98},{"move":{"x":-31,"y":-38,"z":57},"block_id":98},{"move":{"x":-31,"y":-38,"z":58},"block_id":98},{"move":{"x":-31,"y":-37,"z":14},"block_id":98},{"move":{"x":-31,"y":-37,"z":15},"block_id":98},{"move":{"x":-31,"y":-37,"z":16},"block_id":98},{"move":{"x":-31,"y":-37,"z":17},"block_id":98},{"move":{"x":-31,"y":-37,"z":18},"block_id":98},{"move":{"x":-31,"y":-37,"z":19},"block_id":98},{"move":{"x":-31,"y":-37,"z":20},"block_id":98},{"move":{"x":-31,"y":-37,"z":21},"block_id":98},{"move":{"x":-31,"y":-37,"z":22},"block_id":98},{"move":{"x":-31,"y":-37,"z":23},"block_id":98},{"move":{"x":-31,"y":-37,"z":24},"block_id":98},