{"name":"oak_house_small","world":{"pos1":{"x":-235,"y":0,"z":0},"pos2":{"x":-245,"y":13,"z":-9},"entrance":{"x":-240,"y":1,"z":0}},"meta":{},"size":{"x":11,"y":14,"z":10},"door_pos":{"x":5,"y":1,"z":0},"blocks":[{"move":{"x":-5,"y":-1,"z":1},"block_id":2},{"move":{"x":-5,"y":-1,"z":2},"block_id":2},{"move":{"x":-5,"y":-1,"z":3},"block_id":2},{"move":{"x":-5,"y":-1,"z":4},"block_id":2},{"move":{"x":-5,"y":-1,"z":5},"block_id":2},{"move":{"x":-5,"y":-1,"z":6},"block_id":2},{"move":{"x":-5,"y":-1,"z":7},"block_id":2},{"move":{"x":-5,"y":-1,"z":8},"block_id":2},{"move":{"x":-5,"y":-1,"z":9},"block_id":2},{"move":{"x":-5,"y":0,"z":2},"block_id":98},{"move":{"x":-5,"y":0,"z":3},"block_id":98},{"move":{"x":-5,"y":0,"z":4},"block_id":98},{"move":{"x":-5,"y":0,"z":5},"block_id":98},{"move":{"x":-5,"y":0,"z":6},"block_id":98},{"move":{"x":-5,"y":1,"z":2},"block_id":85},{"move":{"x":-5,"y":1,"z":3},"block_id":85},{"move":{"x":-5,"y":1,"z":4},"block_id":85},{"move":{"x":-5,"y":1,"z":5},"block_id":85},{"move":{"x":-5,"y":1,"z":6},"block_id":85},{"move":{"x":-4,"y":-1,"z":0},"block_id":2},{"move":{"x":-4,"y":-1,"z":1},"block_id":2},{"move":{"x":-4,"y":-1,"z":2},"block_id":2},{"move":{"x":-4,"y":-1,"z":3},"block_id":2},{"move":{"x":-4,"y":-1,"z":4},"block_id":2},{"move":{"x":-4,"y":-1,"z":5},"block_id":2},{"move":{"x":-4,"y":-1,"z":6},"block_id":2},{"move":{"x":-4,"y":-1,"z":7},"block_id":2},{"move":{"x":-4,"y":-1,"z":8},"block_id":2},{"move":{"x":-4,"y":-1,"z":9},"block_id":2},{"move":{"x":-4,"y":0,"z":0},"block_id":3,"rotate":{"x":0,"y":1,"z":0}},{"move":{"x":-4,"y":0,"z":1},"block_id":98},{"move":{"x":-4,"y":0,"z":2},"block_id":98},{"move":{"x":-4,"y":0,"z":3},"block_id":63},{"move":{"x":-4,"y":0,"z":4},"block_id":63},{"move":{"x":-4,"y":0,"z":5},"block_id":63},{"move":{"x":-4,"y":0,"z":6},"block_id":98},{"move":{"x":-4,"y":0,"z":7},"block_id":98},{"move":{"x":-4,"y":0,"z":8},"block_id":3,"rotate":{"x":0,"y":1,"z":0}},{"move":{"x":-4,"y":1,"z":0},"block_id":126,"extra_data":{"point":{"x":0.3769237520102138,"y":0,"z":0.7379376960248705}}},{"move":{"x":-4,"y":1,"z":2},"block_id":85},{"move":{"x":-4,"y":1,"z":6},"block_id":85},{"move":{"x":-4,"y":1,"z":7},"block_id":85},{"move":{"x":-4,"y":1,"z":8},"block_id":3,"rotate":{"x":0,"y":1,"z":0}},{"move":{"x":-4,"y":2,"z":8},"block_id":126,"extra_data":{"point":{"x":0.26496309490187286,"y":0,"z":0.7838101334438443}}},{"move":{"x":-4,"y":4,"z":1},"block_id":126,"extra_data":{"point":{"x":1.0020000000000095,"y":0.19018746400341602,"z":0.3183364839998112}}},{"move":{"x":-4,"y":4,"z":2},"block_id":3,"rotate":{"x":13,"y":0,"z":0}},{"move":{"x":-4,"y":4,"z":3},"block_id":126,"extra_data":{"point":{"x":1.0020000000000095,"y":0.1892791080676286,"z":0.577984042388918}}},{"move":{"x":-4,"y":4,"z":4},"block_id":126,"extra_data":{"point":{"x":1.0020000000000095,"y":0.17277194161287124,"z":0.770365274671474}}},{"move":{"x":-4,"y":4,"z":5},"block_id":126,"extra_data":{"point":{"x":1.0020000000000095,"y":0.2695570662634532,"z":0.34689392177643175}}},{"move":{"x":-4,"y":4,"z":6},"block_id":3,"rotate":{"x":13,"y":0,"z":0}},{"move":{"x":-4,"y":4,"z":7},"block_id":126,"extra_data":{"point":{"x":1.0020000000000095,"y":0.08678839883227063,"z":0.5416030102433167}}},{"move":{"x":-4,"y":7,"z":1},"block_id":53,"extra_data":{"point":{"x":1.0010000000000048,"y":0.37234563224025763,"z":0.08870071430483706}},"rotate":{"x":0,"y":0,"z":0}},{"move":{"x":-4,"y":7,"z":2},"block_id":53,"extra_data":{"point":{"x":0.18963934606145472,"y":0.6764003399485912,"z":-0.0009999999999998899}},"rotate":{"x":2,"y":0,"z":0}},{"move":{"x":-4,"y":7,"z":6},"block_id":53,"extra_data":{"point":{"x":0.45989444850945915,"y":0.698915766138354,"z":1.0009999999999994}},"rotate":{"x":0,"y":0,"z":0}},{"move":{"x":-4,"y":7,"z":7},"block_id":53,"extra_data":{"point":{"x":1.0010000000000048,"y":0.09952051985047738,"z":0.6224010170980323}},"rotate":{"x":2,"y":0,"z":0}},{"move":{"x":-4,"y":8,"z":2},"block_id":53,"extra_data":{"point":{"x":1.0010000000000048,"y":0.4439695292487613,"z":0.3184285729563481}},"rotate":{"x":0,"y":0,"z":0}},{"move":{"x":-4,"y":8,"z":3},"block_id":53,"extra_data":{"point":{"x":0.5751525004688745,"y":0.517469652964401,"z":-0.0009999999999998899}},"rotate":{"x":2,"y":0,"z":0}},{"move":{"x":-4,"y":8,"z":5},"block_id":53,"extra_data":{"point":{"x":0.5190275069124937,"y":0.731214827695803,"z":1.0009999999999994}},"rotate":{"x":0,"y":0,"z":0}},{"move":{"x":-4,"y":8,"z":6},"block_id":53,"extra_data":{"point":{"x":1.0010000000000048,"y":0.37659219831025226,"z":0.5787764295292908}},"rotate":{"x":2,"y":0,"z":0}},{"move":{"x":-4,"y":9,"z":3},"block_id":7},{"move":{"x":-4,"y":9,"z":4},"block_id":652,"rotate":{"x":3,"y":-1,"z":0}},{"move":{"x":-4,"y":9,"z":5},"block_id":7},{"move":{"x":-4,"y":10,"z":3},"block_id":53,"extra_data":{"point":{"x":0.8004295275650577,"y":0,"z":0.7282043085478951}},"rotate":{"x":0,"y":1,"z":0}},{"move":{"x":-4,"y":10,"z":4},"block_id":7},{"move":{"x":-4,"y":10,"z":5},"block_id":53,"extra_data":{"point":{"x":0.5462055133734509,"y":0,"z":0.5935109381519528}},"rotate":{"x":2,"y":1,"z":0}},{"move":{"x":-4,"y":11,"z":4},"block_id":7},{"move":{"x":-3,"y":-1,"z":0},"block_id":2},{"move":{"x":-3,"y":-1,"z":1},"block_id":2},{"move":{"x":-3,"y":-1,"z":2},"block_id":2},{"move":{"x":-3,"y":-1,"z":3},"block_id":2},{"move":{"x":-3,"y":-1,"z":4},"block_id":2},{"move":{"x":-3,"y":-1,"z":5},"block_id":2},{"move":{"x":-3,"y":-1,"z":6},"block_id":2},{"move":{"x":-3,"y":-1,"z":7},"block_id":2},{"move":{"x":-3,"y":-1,"z":8},"block_id":2},{"move":{"x":-3,"y":-1,"z":9},"block_id":2},{"move":{"x":-3,"y":0,"z":0},"block_id":98},{"move":{"x":-3,"y":0,"z":1},"block_id":98},{"move":{"x":-3,"y":0,"z":2},"block_id":98},{"move":{"x":-3,"y":0,"z":3},"block_id":63},{"move":{"x":-3,"y":0,"z":4},"block_id":63},{"move":{"x":-3,"y":0,"z":5},"block_id":63},{"move":{"x":-3,"y":0,"z":6},"block_id":63},{"move":{"x":-3,"y":0,"z":7},"block_id":63},{"move":{"x":-3,"y":0,"z":8},"block_id":98},{"move":{"x":-3,"y":1,"z":2},"block_id":85},{"move":{"x":-3,"y":1,"z":8},"block_id":85},{"move":{"x":-3,"y":3,"z":1},"block_id":652,"rotate":{"x":0,"y":-1,"z":0}},{"move":{"x":-3,"y":3,"z":2},"block_id":53,"extra_data":{"point":{"x":1.0020000000000095,"y":0.7677613862258621,"z":0.7395841594494541}},"rotate":{"x":3,"y":0,"z":0}},{"move":{"x":-3,"y":3,"z":6},"block_id":53,"extra_data":{"point":{"x":1.0020000000000095,"y":0.7426102924159821,"z":0.5703688449563247}},"rotate":{"x":3,"y":0,"z":0}},{"move":{"x":-3,"y":3,"z":7},"block_id":652,"rotate":{"x":3,"y":-1,"z":0}},{"move":{"x":-3,"y":4,"z":0},"block_id":126,"extra_data":{"point":{"x":0.758175206685479,"y":0.23326397281409506,"z":1.002}}},{"move":{"x":-3,"y":4,"z":1},"block_id":7},{"move":{"x":-3,"y":4,"z":2},"block_id":3,"rotate":{"x":13,"y":0,"z":0}},{"move":{"x":-3,"y":4,"z":3},"block_id":3,"rotate":{"x":7,"y":0,"z":0}},{"move":{"x":-3,"y":4,"z":4},"block_id":3,"rotate":{"x":7,"y":0,"z":0}},{"move":{"x":-3,"y":4,"z":5},"block_id":3,"rotate":{"x":7,"y":0,"z":0}},{"move":{"x":-3,"y":4,"z":6},"block_id":3,"rotate":{"x":13,"y":0,"z":0}},{"move":{"x":-3,"y":4,"z":7},"block_id":7},{"move":{"x":-3,"y":4,"z":8},"block_id":126,"extra_data":{"point":{"x":0.4507669229880378,"y":0.14481103377101956,"z":-0.0019999999999997797}}},{"move":{"x":-3,"y":5,"z":2},"block_id":3,"rotate":{"x":0,"y":1,"z":0}},{"move":{"x":-3,"y":5,"z":3},"block_id":7},{"move":{"x":-3,"y":5,"z":4},"block_id":7},{"move":{"x":-3,"y":5,"z":5},"block_id":7},{"move":{"x":-3,"y":5,"z":6},"block_id":3,"rotate":{"x":0,"y":1,"z":0}},{"move":{"x":-3,"y":6,"z":2},"block_id":3,"rotate":{"x":0,"y":1,"z":0}},{"move":{"x":-3,"y":6,"z":3},"block_id":7},{"move":{"x":-3,"y":6,"z":4},"block_id":102,"rotate":{"x":1,"y":-1,"z":0}},{"move":{"x":-3,"y":6,"z":5},"block_id":7},{"move":{"x":-3,"y":6,"z":6},"block_id":3,"rotate":{"x":0,"y":1,"z":0}},{"move":{"x":-3,"y":7,"z":1},"block_id":53,"extra_data":{"point":{"x":0.4756146974081332,"y":0.13220880820627023,"z":1.002}},"rotate":{"x":0,"y":0,"z":0}},{"move":{"x":-3,"y":7,"z":2},"block_id":3,"rotate":{"x":0,"y":1,"z":0}},{"move":{"x":-3,"y":7,"z":3},"block_id":7},{"move":{"x":-3,"y":7,"z":4},"block_id":102,"rotate":{"x":1,"y":-1,"z":0}},{"move":{"x":-3,"y":7,"z":5},"block_id":7},{"move":{"x":-3,"y":7,"z":6},"block_id":3,"rotate":{"x":0,"y":1,"z":0}},{"move":{"x":-3,"y":7,"z":7},"block_id":53,"extra_data":{"point":{"x":0.544384327568082,"y":0.26978421608232317,"z":-0.0019999999999997797}},"rotate":{"x":2,"y":0,"z":0}},{"move":{"x":-3,"y":8,"z":2},"block_id":53,"extra_data":{"point":{"x":-0.0010000000000047748,"y":0.18319287829595332,"z":0.44509174861710177}},"rotate":{"x":0,"y":0,"z":0}},{"move":{"x":-3,"y":8,"z":3},"block_id":3,"rotate":{"x":0,"y":1,"z":0}},{"move":{"x":-3,"y":8,"z":4},"block_id":7},{"move":{"x":-3,"y":8,"z":5},"block_id":3,"rotate":{"x":0,"y":1,"z":0}},{"move":{"x":-3,"y":8,"z":6},"block_id":53,"extra_data":{"point":{"x":-0.0010000000000047748,"y":0.15366366773958795,"z":0.6796748499204197}},"rotate":{"x":2,"y":0,"z":0}},{"move":{"x":-3,"y":9,"z":3},"block_id":7},{"move":{"x":-3,"y":9,"z":4},"block_id":3,"rotate":{"x":0,"y":1,"z":0}},{"move":{"x":-3,"y":9,"z":5},"block_id":7},{"move":{"x":-3,"y":10,"z":3},"block_id":53,"extra_data":{"point":{"x":-0.0010000000000047748,"y":0.476848239115375,"z":0.09644203379154437}},"rotate":{"x":0,"y":0,"z":0}},{"move":{"x":-3,"y":10,"z":4},"block_id":3,"rotate":{"x":0,"y":1,"z":0}},{"move":{"x":-3,"y":10,"z":5},"block_id":53,"extra_data":{"point":{"x":-0.0010000000000047748,"y":0.48108388121252155,"z":0.5861099524695437}},"rotate":{"x":2,"y":0,"z":0}},{"move":{"x":-3,"y":11,"z":4},"block_id":126,"extra_data":{"point":{"x":0.2284963814847174,"y":0,"z":0.3969739016451199}}},{"move":{"x":-2,"y":-1,"z":0},"block_id":2},{"move":{"x":-2,"y":-1,"z":1},"block_id":2},{"move":{"x":-2,"y":-1,"z":2},"block_id":2},{"move":{"x":-2,"y":-1,"z":3},"block_id":2},{"move":{"x":-2,"y":-1,"z":4},"block_id":2},{"move":{"x":-2,"y":-1,"z":5},"block_id":2},{"move":{"x":-2,"y":-1,"z":6},"block_id":2},{"move":{"x":-2,"y":-1,"z":7},"block_id":2},{"move":{"x":-2,"y":-1,"z":8},"block_id":2},{"move":{"x":-2,"y":-1,"z":9},"block_id":2},{"move":{"x":-2,"y":0,"z":0},"block_id":98},{"move":{"x":-2,"y":0,"z":1},"block_id":98},{"move":{"x":-2,"y":0,"z":2},"block_id":98},{"move":{"x":-2,"y":0,"z":3},"block_id":126,"extra_data":{"point":{"x":1.0020000000000095,"y":0.5441222698603787,"z":0.21036777179046195}}},{"move":{"x":-2,"y":0,"z":4},"block_id":126,"extra_data":{"point":{"x":1.0020000000000095,"y":0.7375144586099196,"z":0.38363567347842364}}},{"move":{"x":-2,"y":0,"z":5},"block_id":79},{"move":{"x":-2,"y":0,"z":6},"block_id":98},{"move":{"x":-2,"y":0,"z":7},"block_id":63},{"move":{"x":-2,"y":0,"z":8},"block_id":98},{"move":{"x":-2,"y":0,"z":9},"block_id":98},{"move":{"x":-2,"y":1,"z":0},"block_id":85},{"move":{"x":-2,"y":1,"z":1},"block_id":85},{"move":{"x":-2,"y":1,"z":2},"block_id":3,"rotate":{"x":0,"y":1,"z":0}},{"move":{"x":-2,"y":1,"z":3},"block_id":7},{"move":{"x":-2,"y":1,"z":4},"block_id":7},{"move":{"x":-2,"y":1,"z":5},"block_id":7},{"move":{"x":-2,"y":1,"z":6},"block_id":3,"rotate":{"x":0,"y":1,"z":0}},{"move":{"x":-2,"y":1,"z":8},"block_id":85},{"move":{"x":-2,"y":1,"z":9},"block_id":85},{"move":{"x":-2,"y":2,"z":2},"block_id":3,"rotate":{"x":0,"y":1,"z":0}},{"move":{"x":-2,"y":2,"z":3},"block_id":7},{"move":{"x":-2,"y":2,"z":4},"block_id":7},{"move":{"x":-2,"y":2,"z":5},"block_id":7},{"move":{"x":-2,"y":2,"z":6},"block_id":3,"rotate":{"x":0,"y":1,"z":0}},{"move":{"x":-2,"y":3,"z":1},"block_id":53,"extra_data":{"point":{"x":0.5803264913138833,"y":0.5255111147943197,"z":1.002}},"rotate":{"x":0,"y":0,"z":0}},{"move":{"x":-2,"y":3,"z":2},"block_id":3,"rotate":{"x":0,"y":1,"z":0}},{"move":{"x":-2,"y":3,"z":3},"block_id":7},{"move":{"x":-2,"y":3,"z":4},"block_id":7},{"move":{"x":-2,"y":3,"z":5},"block_id":7},{"move":{"x":-2,"y":3,"z":6},"block_id":3,"rotate":{"x":0,"y":1,"z":0}},{"move":{"x":-2,"y":3,"z":7},"block_id":53,"extra_data":{"point":{"x":0.7218025887497959,"y":0.6538475343806951,"z":-0.0019999999999997797}},"rotate":{"x":2,"y":0,"z":0}},{"move":{"x":-2,"y":4,"z":0},"block_id":3,"rotate":{"x":7,"y":0,"z":0}},{"move":{"x":-2,"y":4,"z":1},"block_id":3,"rotate":{"x":7,"y":0,"z":0}},{"move":{"x":-2,"y":4,"z":2},"block_id":7},{"move":{"x":-2,"y":4,"z":3},"block_id":126,"extra_data":{"point":{"x":1.0020000000000095,"y":0.8611613851692619,"z":0.38790548889922416}}},{"move":{"x":-2,"y":4,"z":4},"block_id":126,"extra_data":{"point":{"x":-0.0020000000000095497,"y":0.8319559845239688,"z":0.6278141647451094}}},{"move":{"x":-2,"y":4,"z":5},"block_id":126,"extra_data":{"point":{"x":0.8109382867312149,"y":0.7521140734867222,"z":1.0019999999999998}}},{"move":{"x":-2,"y":4,"z":6},"block_id":7},{"move":{"x":-2,"y":4,"z":7},"block_id":3,"rotate":{"x":7,"y":0,"z":0}},{"move":{"x":-2,"y":4,"z":8},"block_id":3,"rotate":{"x":7,"y":0,"z":0}},{"move":{"x":-2,"y":5,"z":1},"block_id":3,"rotate":{"x":0,"y":1,"z":0}},{"move":{"x":-2,"y":5,"z":2},"block_id":54,"extra_data":{"can_destroy":true,"slots":{}},"rotate":{"x":2,"y":1,"z":0}},{"move":{"x":-2,"y":5,"z":4},"block_id":1201,"extra_data":{"is_head":true},"rotate":{"x":2,"y":1,"z":0}},{"move":{"x":-2,"y":5,"z":5},"block_id":1201,"extra_data":{"is_head":false},"rotate":{"x":2,"y":1,"z":0}},{"move":{"x":-2,"y":5,"z":7},"block_id":3,"rotate":{"x":0,"y":1,"z":0}},{"move":{"x":-2,"y":6,"z":1},"block_id":3,"rotate":{"x":0,"y":1,"z":0}},{"move":{"x":-2,"y":6,"z":7},"block_id":3,"rotate":{"x":0,"y":1,"z":0}},{"move":{"x":-2,"y":7,"z":1},"block_id":3,"rotate":{"x":0,"y":1,"z":0}},{"move":{"x":-2,"y":7,"z":7},"block_id":3,"rotate":{"x":0,"y":1,"z":0}},{"move":{"x":-2,"y":7,"z":8},"block_id":126,"extra_data":{"point":{"x":0.3579604039177866,"y":0.17490962529574006,"z":-0.0019999999999997797}}},{"move":{"x":-2,"y":8,"z":0},"block_id":126,"extra_data":{"point":{"x":0.22206539828309246,"y":0.2833668167924248,"z":1.002}}},{"move":{"x":-2,"y":8,"z":1},"block_id":126,"extra_data":{"point":{"x":0.3620454161163025,"y":0,"z":0.6444808919396376}}},{"move":{"x":-2,"y":8,"z":2},"block_id":53,"extra_data":{"point":{"x":-0.0010000000000047748,"y":0.29785907331198125,"z":0.19149621444716192}},"rotate":{"x":0,"y":0,"z":0}},{"move":{"x":-2,"y":8,"z":6},"block_id":53,"extra_data":{"point":{"x":-0.0010000000000047748,"y":0.3003416518522446,"z":0.5715537313559373}},"rotate":{"x":2,"y":0,"z":0}},{"move":{"x":-2,"y":8,"z":7},"block_id":126,"extra_data":{"point":{"x":0.35094779614604477,"y":0,"z":0.5907609394842446}}},{"move":{"x":-2,"y":9,"z":3},"block_id":7},{"move":{"x":-2,"y":9,"z":5},"block_id":7},{"move":{"x":-2,"y":10,"z":3},"block_id":53,"extra_data":{"point":{"x":-0.0010000000000047748,"y":0.4575354224149759,"z":0.4803066423859814}},"rotate":{"x":0,"y":0,"z":0}},{"move":{"x":-2,"y":10,"z":4},"block_id":126,"extra_data":{"point":{"x":0.2826518792539616,"y":0.7196148207602882,"z":-0.0009999999999998899}}},{"move":{"x":-2,"y":10,"z":5},"block_id":53,"extra_data":{"point":{"x":-0.0010000000000047748,"y":0.28639001289154997,"z":0.491269510723658}},"rotate":{"x":2,"y":0,"z":0}},{"move":{"x":-1,"y":-1,"z":0},"block_id":2},{"move":{"x":-1,"y":-1,"z":1},"block_id":2},{"move":{"x":-1,"y":-1,"z":2},"block_id":2},{"move":{"x":-1,"y":-1,"z":3},"block_id":2},{"move":{"x":-1,"y":-1,"z":4},"block_id":2},{"move":{"x":-1,"y":-1,"z":5},"block_id":2},{"move":{"x":-1,"y":-1,"z":6},"block_id":2},{"move":{"x":-1,"y":-1,"z":7},"block_id":2},{"move":{"x":-1,"y":-1,"z":8},"block_id":2},{"move":{"x":-1,"y":-1,"z":9},"block_id":2},{"move":{"x":-1,"y":0,"z":0},"block_id":53,"extra_data":{"point":{"x":0.39759668734055253,"y":0,"z":0.26657980943300236}},"rotate":{"x":0,"y":1,"z":0}},{"move":{"x":-1,"y":0,"z":1},"block_id":126,"extra_data":{"point":{"x":0.7432063960696951,"y":0.6214486232770877,"z":1.002}}},{"move":{"x":-1,"y":0,"z":2},"block_id":126,"extra_data":{"point":{"x":0.6594632578915594,"y":0.6776448432689939,"z":1.002}}},{"move":{"x":-1,"y":0,"z":3},"block_id":126,"extra_data":{"point":{"x":0.5788532324180551,"y":0.6630121747920505,"z":1.0019999999999998}}},{"move":{"x":-1,"y":0,"z":4},"block_id":126,"extra_data":{"point":{"x":0.5444104170152855,"y":0.6535226082919823,"z":1.0019999999999998}}},{"move":{"x":-1,"y":0,"z":5},"block_id":126,"extra_data":{"point":{"x":0.7384001426013356,"y":0.7193231599571002,"z":1.0019999999999998}}},{"move":{"x":-1,"y":0,"z":6},"block_id":126,"extra_data":{"point":{"x":-0.0020000000000095497,"y":0.6895160183272908,"z":0.7913840840430098}}},{"move":{"x":-1,"y":0,"z":7},"block_id":63},{"move":{"x":-1,"y":0,"z":8},"block_id":63},{"move":{"x":-1,"y":0,"z":9},"block_id":98},{"move":{"x":-1,"y":1,"z":2},"block_id":7},{"move":{"x":-1,"y":1,"z":6},"block_id":7},{"move":{"x":-1,"y":1,"z":9},"block_id":85},{"move":{"x":-1,"y":2,"z":1},"block_id":126,"extra_data":{"point":{"x":0.31506047420464256,"y":0.7572682820238299,"z":1.002}}},{"move":{"x":-1,"y":2,"z":2},"block_id":7},{"move":{"x":-1,"y":2,"z":6},"block_id":7},{"move":{"x":-1,"y":3,"z":2},"block_id":7},{"move":{"x":-1,"y":3,"z":4},"block_id":784,"rotate":{"x":1,"y":0,"z":0}},{"move":{"x":-1,"y":3,"z":6},"block_id":7},{"move":{"x":-1,"y":4,"z":0},"block_id":126,"extra_data":{"point":{"x":0.756901937638446,"y":0.2704964739477047,"z":1.002}}},{"move":{"x":-1,"y":4,"z":1},"block_id":3,"rotate":{"x":13,"y":0,"z":0}},{"move":{"x":-1,"y":4,"z":2},"block_id":126,"extra_data":{"point":{"x":1.0020000000000095,"y":0.7396468527955253,"z":0.3213269116858599}}},{"move":{"x":-1,"y":4,"z":3},"block_id":126,"extra_data":{"point":{"x":1.0020000000000095,"y":0.8723565251196943,"z":0.3908077991816281}}},{"move":{"x":-1,"y":4,"z":4},"block_id":126,"extra_data":{"point":{"x":0.6514148547723266,"y":0.6807248603957934,"z":1.0019999999999998}}},{"move":{"x":-1,"y":4,"z":5},"block_id":126,"extra_data":{"point":{"x":0.35441736367212684,"y":0.8042711198267254,"z":1.0019999999999998}}},{"move":{"x":-1,"y":4,"z":6},"block_id":126,"extra_data":{"point":{"x":0.5498323099309346,"y":0.6862180411558523,"z":1.0019999999999998}}},{"move":{"x":-1,"y":4,"z":7},"block_id":3,"rotate":{"x":13,"y":0,"z":0}},{"move":{"x":-1,"y":4,"z":8},"block_id":126,"extra_data":{"point":{"x":0.6015401785655854,"y":0.0728747668094556,"z":-0.0019999999999997797}}},{"move":{"x":-1,"y":5,"z":1},"block_id":7},{"move":{"x":-1,"y":5,"z":7},"block_id":7},{"move":{"x":-1,"y":6,"z":1},"block_id":102,"rotate":{"x":2,"y":0,"z":0}},{"move":{"x":-1,"y":6,"z":7},"block_id":102,"rotate":{"x":0,"y":1,"z":0}},{"move":{"x":-1,"y":7,"z":1},"block_id":102,"rotate":{"x":0,"y":0,"z":0}},{"move":{"x":-1,"y":7,"z":7},"block_id":7},{"move":{"x":-1,"y":7,"z":8},"block_id":126,"extra_data":{"point":{"x":0.623324643808786,"y":0.22168848588385615,"z":-0.0019999999999997797}}},{"move":{"x":-1,"y":8,"z":0},"block_id":126,"extra_data":{"point":{"x":0.7621474470743408,"y":0.22144548583528234,"z":1.002}}},{"move":{"x":-1,"y":8,"z":1},"block_id":126,"extra_data":{"point":{"x":-0.0020000000000095497,"y":0.1997557938125123,"z":0.4623187270379179}}},{"move":{"x":-1,"y":8,"z":2},"block_id":53,"extra_data":{"point":{"x":-0.0010000000000047748,"y":0.3493540066394303,"z":0.47984268910575745}},"rotate":{"x":0,"y":0,"z":0}},{"move":{"x":-1,"y":8,"z":6},"block_id":53,"extra_data":{"point":{"x":-0.0010000000000047748,"y":0.4051001847508715,"z":0.10027941010391395}},"rotate":{"x":2,"y":0,"z":0}},{"move":{"x":-1,"y":9,"z":3},"block_id":7},{"move":{"x":-1,"y":9,"z":5},"block_id":7},{"move":{"x":-1,"y":10,"z":3},"block_id":53,"extra_data":{"point":{"x":-0.0010000000000047748,"y":0.19428663676209368,"z":0.12705913542875313}},"rotate":{"x":0,"y":0,"z":0}},{"move":{"x":-1,"y":10,"z":4},"block_id":126,"extra_data":{"point":{"x":1.0020000000000095,"y":0.7977218586152048,"z":0.6574178891563278}}},{"move":{"x":-1,"y":10,"z":5},"block_id":53,"extra_data":{"point":{"x":-0.0010000000000047748,"y":0.1948853787664575,"z":0.4125498066870943}},"rotate":{"x":2,"y":0,"z":0}},{"move":{"x":0,"y":-1,"z":0},"block_id":2},{"move":{"x":0,"y":-1,"z":1},"block_id":2},{"move":{"x":0,"y":-1,"z":2},"block_id":2},{"move":{"x":0,"y":-1,"z":3},"block_id":2},{"move":{"x":0,"y":-1,"z":4},"block_id":2},{"move":{"x":0,"y":-1,"z":5},"block_id":2},{"move":{"x":0,"y":-1,"z":6},"block_id":2},{"move":{"x":0,"y":-1,"z":7},"block_id":2},{"move":{"x":0,"y":-1,"z":8},"block_id":2},{"move":{"x":0,"y":-1,"z":9},"block_id":2},{"move":{"x":0,"y":0,"z":0},"block_id":53,"extra_data":{"point":{"x":0.36829385125281533,"y":0,"z":0.37445919952084866}},"rotate":{"x":0,"y":1,"z":0}},{"move":{"x":0,"y":0,"z":1},"block_id":126,"extra_data":{"point":{"x":0.555814683278868,"y":0.6570677733778694,"z":1.002}}},{"move":{"x":0,"y":0,"z":2},"block_id":126,"extra_data":{"point":{"x":0.3162202743481828,"y":0.8551948811051797,"z":1.002}}},{"move":{"x":0,"y":0,"z":3},"block_id":126,"extra_data":{"point":{"x":0.4825356848506317,"y":0.7744917487032543,"z":1.0019999999999998}}},{"move":{"x":0,"y":0,"z":4},"block_id":126,"extra_data":{"point":{"x":0.6262311321758034,"y":0.6261450072872297,"z":1.0019999999999998}}},{"move":{"x":0,"y":0,"z":5},"block_id":126,"extra_data":{"point":{"x":-0.0020000000000095497,"y":0.606784852987369,"z":0.49360914637634057}}},{"move":{"x":0,"y":0,"z":6},"block_id":126,"extra_data":{"point":{"x":-0.0020000000000095497,"y":0.6464914900712917,"z":0.31418206709262897}}},{"move":{"x":0,"y":0,"z":7},"block_id":63},{"move":{"x":0,"y":0,"z":8},"block_id":63},{"move":{"x":0,"y":0,"z":9},"block_id":98},{"move":{"x":0,"y":1,"z":2},"block_id":584,"extra_data":{"point":{"x":0.1271007452886863,"y":0,"z":0.5104083064663782},"opened":false,"left":false,"is_head":false},"rotate":{"x":0,"y":1,"z":0}},{"move":{"x":0,"y":1,"z":6},"block_id":584,"extra_data":{"point":{"x":0.325922071700802,"y":0,"z":0.027928989190260545},"opened":false,"left":false,"is_head":false},"rotate":{"x":0,"y":1,"z":0}},{"move":{"x":0,"y":1,"z":9},"block_id":85},{"move":{"x":0,"y":2,"z":2},"block_id":584,"extra_data":{"point":{"x":0.1271007452886863,"y":0,"z":0.5104083064663782},"opened":false,"left":false,"is_head":true},"rotate":{"x":0,"y":1,"z":0}},{"move":{"x":0,"y":2,"z":6},"block_id":584,"extra_data":{"point":{"x":0.325922071700802,"y":0,"z":0.027928989190260545},"opened":false,"left":false,"is_head":true},"rotate":{"x":0,"y":1,"z":0}},{"move":{"x":0,"y":3,"z":1},"block_id":126,"extra_data":{"point":{"x":0.29044651320242565,"y":0.08801601098722145,"z":1.002}}},{"move":{"x":0,"y":3,"z":2},"block_id":7},{"move":{"x":0,"y":3,"z":6},"block_id":7},{"move":{"x":0,"y":4,"z":0},"block_id":126,"extra_data":{"point":{"x":0.43811166460616846,"y":0.07221219125574319,"z":1.002}}},{"move":{"x":0,"y":4,"z":1},"block_id":3,"rotate":{"x":13,"y":0,"z":0}},{"move":{"x":0,"y":4,"z":2},"block_id":126,"extra_data":{"point":{"x":1.0020000000000095,"y":0.7325701003729357,"z":0.41099328420858194}}},{"move":{"x":0,"y":4,"z":3},"block_id":126,"extra_data":{"point":{"x":1.0020000000000095,"y":0.7836267164330097,"z":0.4718172632229609}}},{"move":{"x":0,"y":4,"z":4},"block_id":126,"extra_data":{"point":{"x":1.0020000000000095,"y":0.871016309746218,"z":0.5801407034818009}}},{"move":{"x":0,"y":4,"z":5},"block_id":126,"extra_data":{"point":{"x":1.0020000000000095,"y":0.9171263907343095,"z":0.598711430334296}}},{"move":{"x":0,"y":4,"z":6},"block_id":126,"extra_data":{"point":{"x":0.5126538600756305,"y":0.7035477924324427,"z":1.0019999999999998}}},{"move":{"x":0,"y":4,"z":7},"block_id":3,"rotate":{"x":13,"y":0,"z":0}},{"move":{"x":0,"y":4,"z":8},"block_id":126,"extra_data":{"point":{"x":0.6425647147616189,"y":0.06766464036171449,"z":-0.0019999999999997797}}},{"move":{"x":0,"y":5,"z":1},"block_id":7},{"move":{"x":0,"y":5,"z":2},"block_id":650,"extra_data":{"item":{"id":46},"rot":0}},{"move":{"x":0,"y":5,"z":6},"block_id":320,"extra_data":{"frame":"oak_log"},"rotate":{"x":0,"y":1,"z":0}},{"move":{"x":0,"y":5,"z":7},"block_id":7},{"move":{"x":0,"y":6,"z":1},"block_id":102,"rotate":{"x":2,"y":0,"z":0}},{"move":{"x":0,"y":6,"z":7},"block_id":102,"rotate":{"x":0,"y":-1,"z":0}},{"move":{"x":0,"y":7,"z":0},"block_id":652,"rotate":{"x":0,"y":-1,"z":0}},{"move":{"x":0,"y":7,"z":1},"block_id":102,"rotate":{"x":0,"y":1,"z":0}},{"move":{"x":0,"y":7,"z":7},"block_id":7},{"move":{"x":0,"y":7,"z":8},"block_id":126,"extra_data":{"point":{"x":0.37240637391232667,"y":0.6857919582530645,"z":-0.0019999999999997797}}},{"move":{"x":0,"y":8,"z":0},"block_id":126,"extra_data":{"point":{"x":0.558836725332867,"y":0.10972866728570452,"z":1.002}}},{"move":{"x":0,"y":8,"z":1},"block_id":7},{"move":{"x":0,"y":8,"z":2},"block_id":7},{"move":{"x":0,"y":8,"z":6},"block_id":53,"extra_data":{"point":{"x":-0.0010000000000047748,"y":0.22336483941085028,"z":0.5968621852191758}},"rotate":{"x":2,"y":0,"z":0}},{"move":{"x":0,"y":8,"z":7},"block_id":126,"extra_data":{"point":{"x":0.46466677563810777,"y":0,"z":0.4281433219284869}}},{"move":{"x":0,"y":9,"z":3},"block_id":7},{"move":{"x":0,"y":9,"z":5},"block_id":7},{"move":{"x":0,"y":10,"z":3},"block_id":53,"extra_data":{"point":{"x":-0.0010000000000047748,"y":0.3609662628936601,"z":0.6143054472835847}},"rotate":{"x":0,"y":0,"z":0}},{"move":{"x":0,"y":10,"z":4},"block_id":126,"extra_data":{"point":{"x":1.0020000000000095,"y":0.7128045190892962,"z":0.9225704037091291}}},{"move":{"x":0,"y":10,"z":5},"block_id":53,"extra_data":{"point":{"x":-0.0010000000000047748,"y":0.29916834043310914,"z":0.2299159928977499}},"rotate":{"x":2,"y":0,"z":0}},{"move":{"x":1,"y":-1,"z":0},"block_id":2},{"move":{"x":1,"y":-1,"z":1},"block_id":2},{"move":{"x":1,"y":-1,"z":2},"block_id":2},{"move":{"x":1,"y":-1,"z":3},"block_id":2},{"move":{"x":1,"y":-1,"z":4},"block_id":2},{"move":{"x":1,"y":-1,"z":5},"block_id":2},{"move":{"x":1,"y":-1,"z":6},"block_id":2},{"move":{"x":1,"y":-1,"z":7},"block_id":2},{"move":{"x":1,"y":-1,"z":8},"block_id":2},{"move":{"x":1,"y":-1,"z":9},"block_id":2},{"move":{"x":1,"y":0,"z":0},"block_id":53,"extra_data":{"point":{"x":0.4416149014547557,"y":0,"z":0.3993001060260705}},"rotate":{"x":0,"y":1,"z":0}},{"move":{"x":1,"y":0,"z":1},"block_id":126,"extra_data":{"point":{"x":0.5294310915520839,"y":0.6556896991901151,"z":1.002}}},{"move":{"x":1,"y":0,"z":2},"block_id":126,"extra_data":{"point":{"x":0.5323141003979117,"y":0.7248629781068843,"z":1.002}}},{"move":{"x":1,"y":0,"z":3},"block_id":126,"extra_data":{"point":{"x":0.5442670807124728,"y":0.7936163478853293,"z":1.0019999999999998}}},{"move":{"x":1,"y":0,"z":4},"block_id":126,"extra_data":{"point":{"x":0.5092322324464362,"y":0.6549560783662784,"z":1.0019999999999998}}},{"move":{"x":1,"y":0,"z":5},"block_id":126,"extra_data":{"point":{"x":-0.0020000000000095497,"y":0.6328142501457015,"z":0.5322206556066025}}},{"move":{"x":1,"y":0,"z":6},"block_id":79},{"move":{"x":1,"y":0,"z":7},"block_id":63},{"move":{"x":1,"y":0,"z":8},"block_id":63},{"move":{"x":1,"y":0,"z":9},"block_id":98},{"move":{"x":1,"y":1,"z":2},"block_id":7},{"move":{"x":1,"y":1,"z":3},"block_id":1533},{"move":{"x":1,"y":1,"z":6},"block_id":7},{"move":{"x":1,"y":1,"z":9},"block_id":85},{"move":{"x":1,"y":2,"z":1},"block_id":126,"extra_data":{"point":{"x":0.5987710054090769,"y":0.8542505718296307,"z":1.002}}},{"move":{"x":1,"y":2,"z":2},"block_id":7},{"move":{"x":1,"y":2,"z":6},"block_id":7},{"move":{"x":1,"y":3,"z":2},"block_id":7},{"move":{"x":1,"y":3,"z":6},"block_id":7},{"move":{"x":1,"y":4,"z":0},"block_id":126,"extra_data":{"point":{"x":0.191087865921304,"y":0.05762541563143131,"z":1.002}}},{"move":{"x":1,"y":4,"z":1},"block_id":3,"rotate":{"x":13,"y":0,"z":0}},{"move":{"x":1,"y":4,"z":2},"block_id":126,"extra_data":{"point":{"x":1.0020000000000095,"y":0.786321455357955,"z":0.39825424233644036}}},{"move":{"x":1,"y":4,"z":3},"block_id":126,"extra_data":{"point":{"x":-0.0020000000000095497,"y":0.8424242016680497,"z":0.7916450228710974}}},{"move":{"x":1,"y":4,"z":4},"block_id":126,"extra_data":{"point":{"x":0.33371641977046806,"y":0.7790987789722479,"z":-0.0019999999999997797}}},{"move":{"x":1,"y":4,"z":5},"block_id":126,"extra_data":{"point":{"x":1.0020000000000095,"y":0.6533235617472464,"z":0.7353477172139522}}},{"move":{"x":1,"y":4,"z":6},"block_id":126,"extra_data":{"point":{"x":0.38887147755662,"y":0.7797324013780056,"z":1.0019999999999998}}},{"move":{"x":1,"y":4,"z":7},"block_id":3,"rotate":{"x":13,"y":0,"z":0}},{"move":{"x":1,"y":4,"z":8},"block_id":126,"extra_data":{"point":{"x":0.5058936496008357,"y":0.11033782725570607,"z":-0.0019999999999997797}}},{"move":{"x":1,"y":5,"z":1},"block_id":7},{"move":{"x":1,"y":5,"z":7},"block_id":7},{"move":{"x":1,"y":6,"z":1},"block_id":102,"rotate":{"x":3,"y":0,"z":0}},{"move":{"x":1,"y":6,"z":7},"block_id":102,"rotate":{"x":0,"y":1,"z":0}},{"move":{"x":1,"y":7,"z":1},"block_id":102,"rotate":{"x":0,"y":1,"z":0}},{"move":{"x":1,"y":7,"z":7},"block_id":7},{"move":{"x":1,"y":7,"z":8},"block_id":126,"extra_data":{"point":{"x":0.1202860852916956,"y":0.08382054057635457,"z":-0.0019999999999997797}}},{"move":{"x":1,"y":8,"z":0},"block_id":126,"extra_data":{"point":{"x":0.6780558435430635,"y":0.3843750986279133,"z":1.002}}},{"move":{"x":1,"y":8,"z":1},"block_id":126,"extra_data":{"point":{"x":-0.0020000000000095497,"y":0.08999345067878828,"z":0.13609350787283636}}},{"move":{"x":1,"y":8,"z":2},"block_id":53,"extra_data":{"point":{"x":-0.0010000000000047748,"y":0.2453932089874229,"z":0.275846640044207}},"rotate":{"x":0,"y":0,"z":0}},{"move":{"x":1,"y":8,"z":6},"block_id":53,"extra_data":{"point":{"x":-0.0010000000000047748,"y":0.3799656513435714,"z":0.1462972204947839}},"rotate":{"x":2,"y":0,"z":0}},{"move":{"x":1,"y":9,"z":3},"block_id":7},{"move":{"x":1,"y":9,"z":5},"block_id":7},{"move":{"x":1,"y":10,"z":3},"block_id":53,"extra_data":{"point":{"x":-0.0010000000000047748,"y":0.1485009480662871,"z":0.42173290242631634}},"rotate":{"x":0,"y":0,"z":0}},{"move":{"x":1,"y":10,"z":4},"block_id":126,"extra_data":{"point":{"x":1.0020000000000095,"y":0.8386792975211002,"z":0.5829811605714159}}},{"move":{"x":1,"y":10,"z":5},"block_id":53,"extra_data":{"point":{"x":-0.0010000000000047748,"y":0.23581830204199683,"z":0.31270276771792993}},"rotate":{"x":2,"y":0,"z":0}},{"move":{"x":2,"y":-1,"z":0},"block_id":2},{"move":{"x":2,"y":-1,"z":1},"block_id":2},{"move":{"x":2,"y":-1,"z":2},"block_id":2},{"move":{"x":2,"y":-1,"z":3},"block_id":2},{"move":{"x":2,"y":-1,"z":4},"block_id":2},{"move":{"x":2,"y":-1,"z":5},"block_id":2},{"move":{"x":2,"y":-1,"z":6},"block_id":2},{"move":{"x":2,"y":-1,"z":7},"block_id":2},{"move":{"x":2,"y":-1,"z":8},"block_id":2},{"move":{"x":2,"y":-1,"z":9},"block_id":2},{"move":{"x":2,"y":0,"z":0},"block_id":98},{"move":{"x":2,"y":0,"z":1},"block_id":98},{"move":{"x":2,"y":0,"z":2},"block_id":98},{"move":{"x":2,"y":0,"z":3},"block_id":126,"extra_data":{"point":{"x":-0.0020000000000095497,"y":0.6078576887800269,"z":0.20898283524602324}}},{"move":{"x":2,"y":0,"z":4},"block_id":126,"extra_data":{"point":{"x":-0.0020000000000095497,"y":0.5958051255952928,"z":0.6210430045767672}}},{"move":{"x":2,"y":0,"z":5},"block_id":79},{"move":{"x":2,"y":0,"z":6},"block_id":98},{"move":{"x":2,"y":0,"z":7},"block_id":63},{"move":{"x":2,"y":0,"z":8},"block_id":98},{"move":{"x":2,"y":0,"z":9},"block_id":98},{"move":{"x":2,"y":1,"z":0},"block_id":85},{"move":{"x":2,"y":1,"z":1},"block_id":85},{"move":{"x":2,"y":1,"z":2},"block_id":3,"rotate":{"x":0,"y":1,"z":0}},{"move":{"x":2,"y":1,"z":3},"block_id":7},{"move":{"x":2,"y":1,"z":4},"block_id":65,"rotate":{"x":3,"y":0,"z":0}},{"move":{"x":2,"y":1,"z":5},"block_id":7},{"move":{"x":2,"y":1,"z":6},"block_id":3,"rotate":{"x":0,"y":1,"z":0}},{"move":{"x":2,"y":1,"z":8},"block_id":85},{"move":{"x":2,"y":1,"z":9},"block_id":85},{"move":{"x":2,"y":2,"z":2},"block_id":3,"rotate":{"x":0,"y":1,"z":0}},{"move":{"x":2,"y":2,"z":3},"block_id":7},{"move":{"x":2,"y":2,"z":4},"block_id":65,"rotate":{"x":3,"y":0,"z":0}},{"move":{"x":2,"y":2,"z":5},"block_id":7},{"move":{"x":2,"y":2,"z":6},"block_id":3,"rotate":{"x":0,"y":1,"z":0}},{"move":{"x":2,"y":3,"z":1},"block_id":53,"extra_data":{"point":{"x":0.39756574535024924,"y":1,"z":0.41049801245432427}},"rotate":{"x":0,"y":-1,"z":0}},{"move":{"x":2,"y":3,"z":2},"block_id":3,"rotate":{"x":0,"y":1,"z":0}},{"move":{"x":2,"y":3,"z":3},"block_id":7},{"move":{"x":2,"y":3,"z":4},"block_id":65,"rotate":{"x":3,"y":0,"z":0}},{"move":{"x":2,"y":3,"z":5},"block_id":7},{"move":{"x":2,"y":3,"z":6},"block_id":3,"rotate":{"x":0,"y":1,"z":0}},{"move":{"x":2,"y":3,"z":7},"block_id":53,"extra_data":{"point":{"x":0.48668337309575804,"y":0.7598336634229019,"z":-0.0019999999999997797}},"rotate":{"x":2,"y":0,"z":0}},{"move":{"x":2,"y":4,"z":0},"block_id":3,"rotate":{"x":7,"y":0,"z":0}},{"move":{"x":2,"y":4,"z":1},"block_id":3,"rotate":{"x":7,"y":0,"z":0}},{"move":{"x":2,"y":4,"z":2},"block_id":7},{"move":{"x":2,"y":4,"z":3},"block_id":126,"extra_data":{"point":{"x":0.5114731959321546,"y":0.6659738459051523,"z":-0.0019999999999997797}}},{"move":{"x":2,"y":4,"z":4},"block_id":65,"rotate":{"x":3,"y":0,"z":0}},{"move":{"x":2,"y":4,"z":5},"block_id":126,"extra_data":{"point":{"x":0.4984126504160997,"y":0.8606953184753561,"z":1.0019999999999998}}},{"move":{"x":2,"y":4,"z":6},"block_id":7},{"move":{"x":2,"y":4,"z":7},"block_id":3,"rotate":{"x":7,"y":0,"z":0}},{"move":{"x":2,"y":4,"z":8},"block_id":3,"rotate":{"x":7,"y":0,"z":0}},{"move":{"x":2,"y":5,"z":1},"block_id":3,"rotate":{"x":0,"y":1,"z":0}},{"move":{"x":2,"y":5,"z":6},"block_id":98},{"move":{"x":2,"y":5,"z":7},"block_id":3,"rotate":{"x":0,"y":1,"z":0}},{"move":{"x":2,"y":6,"z":1},"block_id":3,"rotate":{"x":0,"y":1,"z":0}},{"move":{"x":2,"y":6,"z":6},"block_id":98},{"move":{"x":2,"y":6,"z":7},"block_id":3,"rotate":{"x":0,"y":1,"z":0}},{"move":{"x":2,"y":7,"z":1},"block_id":3,"rotate":{"x":0,"y":1,"z":0}},{"move":{"x":2,"y":7,"z":6},"block_id":98},{"move":{"x":2,"y":7,"z":7},"block_id":3,"rotate":{"x":0,"y":1,"z":0}},{"move":{"x":2,"y":7,"z":8},"block_id":126,"extra_data":{"point":{"x":0.28155844424466636,"y":0.09976425079323903,"z":-0.0019999999999997797}}},{"move":{"x":2,"y":8,"z":0},"block_id":126,"extra_data":{"point":{"x":0.5447736549724027,"y":0.1181779493929298,"z":1.002}}},{"move":{"x":2,"y":8,"z":1},"block_id":126,"extra_data":{"point":{"x":-0.0020000000000095497,"y":0.14190439232985064,"z":0.39593832017916564}}},{"move":{"x":2,"y":8,"z":2},"block_id":53,"extra_data":{"point":{"x":-0.0010000000000047748,"y":0.14590581418997317,"z":0.3936164361985679}},"rotate":{"x":0,"y":0,"z":0}},{"move":{"x":2,"y":8,"z":6},"block_id":98},{"move":{"x":2,"y":8,"z":7},"block_id":126,"extra_data":{"point":{"x":0.39322476031262,"y":0,"z":0.5148476379545723}}},{"move":{"x":2,"y":9,"z":3},"block_id":7},{"move":{"x":2,"y":9,"z":5},"block_id":7},{"move":{"x":2,"y":9,"z":6},"block_id":98},{"move":{"x":2,"y":10,"z":3},"block_id":53,"extra_data":{"point":{"x":-0.0010000000000047748,"y":0.05534273517622168,"z":0.1550603703520972}},"rotate":{"x":0,"y":0,"z":0}},{"move":{"x":2,"y":10,"z":4},"block_id":126,"extra_data":{"point":{"x":1.0020000000000095,"y":0.6935107959503455,"z":0.9785918391326978}}},{"move":{"x":2,"y":10,"z":5},"block_id":53,"extra_data":{"point":{"x":-0.0010000000000047748,"y":0.3269144699060771,"z":0.13125537746469274}},"rotate":{"x":2,"y":0,"z":0}},{"move":{"x":2,"y":10,"z":6},"block_id":98},{"move":{"x":2,"y":11,"z":6},"block_id":1462},{"move":{"x":3,"y":-1,"z":0},"block_id":2},{"move":{"x":3,"y":-1,"z":1},"block_id":2},{"move":{"x":3,"y":-1,"z":2},"block_id":2},{"move":{"x":3,"y":-1,"z":3},"block_id":2},{"move":{"x":3,"y":-1,"z":4},"block_id":2},{"move":{"x":3,"y":-1,"z":5},"block_id":2},{"move":{"x":3,"y":-1,"z":6},"block_id":2},{"move":{"x":3,"y":-1,"z":7},"block_id":2},{"move":{"x":3,"y":-1,"z":8},"block_id":2},{"move":{"x":3,"y":-1,"z":9},"block_id":2},{"move":{"x":3,"y":0,"z":0},"block_id":98},{"move":{"x":3,"y":0,"z":1},"block_id":98},{"move":{"x":3,"y":0,"z":2},"block_id":98},{"move":{"x":3,"y":0,"z":3},"block_id":63},{"move":{"x":3,"y":0,"z":4},"block_id":3,"rotate":{"x":0,"y":1,"z":0}},{"move":{"x":3,"y":0,"z":5},"block_id":63},{"move":{"x":3,"y":0,"z":6},"block_id":63},{"move":{"x":3,"y":0,"z":7},"block_id":63},{"move":{"x":3,"y":0,"z":8},"block_id":98},{"move":{"x":3,"y":1,"z":2},"block_id":85},{"move":{"x":3,"y":1,"z":4},"block_id":3,"rotate":{"x":0,"y":1,"z":0}},{"move":{"x":3,"y":1,"z":8},"block_id":85},{"move":{"x":3,"y":2,"z":4},"block_id":3,"rotate":{"x":0,"y":1,"z":0}},{"move":{"x":3,"y":3,"z":1},"block_id":652,"rotate":{"x":0,"y":-1,"z":0}},{"move":{"x":3,"y":3,"z":2},"block_id":53,"extra_data":{"point":{"x":-0.0020000000000095497,"y":0.7264149132769404,"z":0.4952382720358117}},"rotate":{"x":1,"y":0,"z":0}},{"move":{"x":3,"y":3,"z":4},"block_id":3,"rotate":{"x":0,"y":1,"z":0}},{"move":{"x":3,"y":3,"z":6},"block_id":53,"extra_data":{"point":{"x":-0.0020000000000095497,"y":0.6667890406145105,"z":0.6142437244146599}},"rotate":{"x":1,"y":0,"z":0}},{"move":{"x":3,"y":3,"z":7},"block_id":652,"rotate":{"x":2,"y":-1,"z":0}},{"move":{"x":3,"y":4,"z":0},"block_id":126,"extra_data":{"point":{"x":0.37301549800375255,"y":0.24510197607378537,"z":1.002}}},{"move":{"x":3,"y":4,"z":1},"block_id":7},{"move":{"x":3,"y":4,"z":2},"block_id":3,"rotate":{"x":13,"y":0,"z":0}},{"move":{"x":3,"y":4,"z":3},"block_id":3,"rotate":{"x":7,"y":0,"z":0}},{"move":{"x":3,"y":4,"z":4},"block_id":3,"rotate":{"x":7,"y":0,"z":0}},{"move":{"x":3,"y":4,"z":5},"block_id":3,"rotate":{"x":7,"y":0,"z":0}},{"move":{"x":3,"y":4,"z":6},"block_id":3,"rotate":{"x":13,"y":0,"z":0}},{"move":{"x":3,"y":4,"z":7},"block_id":7},{"move":{"x":3,"y":4,"z":8},"block_id":126,"extra_data":{"point":{"x":0.35607067602384745,"y":0.10149890847856557,"z":-0.0019999999999997797}}},{"move":{"x":3,"y":5,"z":2},"block_id":3,"rotate":{"x":0,"y":1,"z":0}},{"move":{"x":3,"y":5,"z":3},"block_id":7},{"move":{"x":3,"y":5,"z":4},"block_id":7},{"move":{"x":3,"y":5,"z":5},"block_id":7},{"move":{"x":3,"y":5,"z":6},"block_id":3,"rotate":{"x":0,"y":1,"z":0}},{"move":{"x":3,"y":6,"z":2},"block_id":3,"rotate":{"x":0,"y":1,"z":0}},{"move":{"x":3,"y":6,"z":3},"block_id":7},{"move":{"x":3,"y":6,"z":4},"block_id":102,"rotate":{"x":1,"y":1,"z":0}},{"move":{"x":3,"y":6,"z":5},"block_id":7},{"move":{"x":3,"y":6,"z":6},"block_id":3,"rotate":{"x":0,"y":1,"z":0}},{"move":{"x":3,"y":7,"z":1},"block_id":53,"extra_data":{"point":{"x":0.7039627948755083,"y":0.2977352491052816,"z":1.002}},"rotate":{"x":0,"y":0,"z":0}},{"move":{"x":3,"y":7,"z":2},"block_id":3,"rotate":{"x":0,"y":1,"z":0}},{"move":{"x":3,"y":7,"z":3},"block_id":7},{"move":{"x":3,"y":7,"z":4},"block_id":102,"rotate":{"x":1,"y":-1,"z":0}},{"move":{"x":3,"y":7,"z":5},"block_id":7},{"move":{"x":3,"y":7,"z":6},"block_id":3,"rotate":{"x":0,"y":1,"z":0}},{"move":{"x":3,"y":7,"z":7},"block_id":53,"extra_data":{"point":{"x":0.5154319372699945,"y":0.18068735760987664,"z":-0.0019999999999997797}},"rotate":{"x":2,"y":0,"z":0}},{"move":{"x":3,"y":8,"z":2},"block_id":53,"extra_data":{"point":{"x":0.5979627118365158,"y":0,"z":0.21421275451120603}},"rotate":{"x":0,"y":1,"z":0}},{"move":{"x":3,"y":8,"z":3},"block_id":3,"rotate":{"x":0,"y":1,"z":0}},{"move":{"x":3,"y":8,"z":4},"block_id":7},{"move":{"x":3,"y":8,"z":5},"block_id":3,"rotate":{"x":0,"y":1,"z":0}},{"move":{"x":3,"y":8,"z":6},"block_id":98},{"move":{"x":3,"y":9,"z":3},"block_id":7},{"move":{"x":3,"y":9,"z":4},"block_id":3,"rotate":{"x":0,"y":1,"z":0}},{"move":{"x":3,"y":9,"z":5},"block_id":7},{"move":{"x":3,"y":9,"z":6},"block_id":98},{"move":{"x":3,"y":10,"z":3},"block_id":53,"extra_data":{"point":{"x":-0.0010000000000047748,"y":0.07955845325891708,"z":0.3094723029517499}},"rotate":{"x":0,"y":0,"z":0}},{"move":{"x":3,"y":10,"z":4},"block_id":3,"rotate":{"x":0,"y":1,"z":0}},{"move":{"x":3,"y":10,"z":5},"block_id":53,"extra_data":{"point":{"x":-0.0010000000000047748,"y":0.22652894681513835,"z":0.22962673646547316}},"rotate":{"x":2,"y":0,"z":0}},{"move":{"x":3,"y":10,"z":6},"block_id":98},{"move":{"x":3,"y":11,"z":4},"block_id":126,"extra_data":{"point":{"x":0.4491105571162848,"y":0,"z":0.32827692376047857}}},{"move":{"x":3,"y":11,"z":6},"block_id":1462},{"move":{"x":4,"y":-1,"z":0},"block_id":2},{"move":{"x":4,"y":-1,"z":1},"block_id":2},{"move":{"x":4,"y":-1,"z":2},"block_id":2},{"move":{"x":4,"y":-1,"z":3},"block_id":2},{"move":{"x":4,"y":-1,"z":4},"block_id":2},{"move":{"x":4,"y":-1,"z":5},"block_id":2},{"move":{"x":4,"y":-1,"z":6},"block_id":2},{"move":{"x":4,"y":-1,"z":7},"block_id":2},{"move":{"x":4,"y":-1,"z":8},"block_id":2},{"move":{"x":4,"y":-1,"z":9},"block_id":2},{"move":{"x":4,"y":0,"z":0},"block_id":3,"rotate":{"x":0,"y":1,"z":0}},{"move":{"x":4,"y":0,"z":1},"block_id":98},{"move":{"x":4,"y":0,"z":2},"block_id":98},{"move":{"x":4,"y":0,"z":3},"block_id":63},{"move":{"x":4,"y":0,"z":4},"block_id":63},{"move":{"x":4,"y":0,"z":5},"block_id":63},{"move":{"x":4,"y":0,"z":6},"block_id":98},{"move":{"x":4,"y":0,"z":7},"block_id":98},{"move":{"x":4,"y":0,"z":8},"block_id":3,"rotate":{"x":0,"y":1,"z":0}},{"move":{"x":4,"y":1,"z":0},"block_id":126,"extra_data":{"point":{"x":0.5846734490157814,"y":0,"z":0.7945334472530491}}},{"move":{"x":4,"y":1,"z":2},"block_id":85},{"move":{"x":4,"y":1,"z":6},"block_id":85},{"move":{"x":4,"y":1,"z":7},"block_id":85},{"move":{"x":4,"y":1,"z":8},"block_id":3,"rotate":{"x":0,"y":1,"z":0}},{"move":{"x":4,"y":2,"z":8},"block_id":126,"extra_data":{"point":{"x":0.5257238301613825,"y":0,"z":0.9380650149646437}}},{"move":{"x":4,"y":4,"z":1},"block_id":126,"extra_data":{"point":{"x":-0.0020000000000095497,"y":0.13161670134470782,"z":0.3557718924084312}}},{"move":{"x":4,"y":4,"z":2},"block_id":3,"rotate":{"x":13,"y":0,"z":0}},{"move":{"x":4,"y":4,"z":3},"block_id":126,"extra_data":{"point":{"x":-0.0020000000000095497,"y":0.1696989470100112,"z":0.4378391349705031}}},{"move":{"x":4,"y":4,"z":4},"block_id":126,"extra_data":{"point":{"x":-0.0020000000000095497,"y":0.2912977377931849,"z":0.30631206401214905}}},{"move":{"x":4,"y":4,"z":5},"block_id":126,"extra_data":{"point":{"x":-0.0020000000000095497,"y":0.3205307814011711,"z":0.36970386918622555}}},{"move":{"x":4,"y":4,"z":6},"block_id":3,"rotate":{"x":13,"y":0,"z":0}},{"move":{"x":4,"y":4,"z":7},"block_id":126,"extra_data":{"point":{"x":-0.0020000000000095497,"y":0.09354089278504052,"z":0.594823444265276}}},{"move":{"x":4,"y":7,"z":1},"block_id":53,"extra_data":{"point":{"x":-0.0010000000000047748,"y":0.42891898560415065,"z":0.6468840685148948}},"rotate":{"x":0,"y":0,"z":0}},{"move":{"x":4,"y":7,"z":2},"block_id":53,"extra_data":{"point":{"x":0.36987208657103565,"y":0.6782039978196028,"z":-0.0009999999999998899}},"rotate":{"x":2,"y":0,"z":0}},{"move":{"x":4,"y":7,"z":6},"block_id":53,"extra_data":{"point":{"x":0.5111272260571411,"y":0.8492093427718537,"z":1.0009999999999994}},"rotate":{"x":0,"y":0,"z":0}},{"move":{"x":4,"y":7,"z":7},"block_id":53,"extra_data":{"point":{"x":-0.0010000000000047748,"y":0.3226010488064297,"z":0.7770957799588301}},"rotate":{"x":2,"y":0,"z":0}},{"move":{"x":4,"y":8,"z":2},"block_id":53,"extra_data":{"point":{"x":-0.0010000000000047748,"y":0.23109099272386757,"z":0.5253716468642793}},"rotate":{"x":0,"y":0,"z":0}},{"move":{"x":4,"y":8,"z":3},"block_id":53,"extra_data":{"point":{"x":0.7214369365171365,"y":0.8104277302915541,"z":-0.0009999999999998899}},"rotate":{"x":2,"y":0,"z":0}},{"move":{"x":4,"y":8,"z":5},"block_id":53,"extra_data":{"point":{"x":0.3865303981531554,"y":0.7332288646090017,"z":1.0009999999999994}},"rotate":{"x":0,"y":0,"z":0}},{"move":{"x":4,"y":8,"z":6},"block_id":53,"extra_data":{"point":{"x":-0.0010000000000047748,"y":0.3097091155636793,"z":0.14524064118453772}},"rotate":{"x":2,"y":0,"z":0}},{"move":{"x":4,"y":9,"z":3},"block_id":7},{"move":{"x":4,"y":9,"z":4},"block_id":652,"rotate":{"x":1,"y":-1,"z":0}},{"move":{"x":4,"y":9,"z":5},"block_id":7},{"move":{"x":4,"y":10,"z":3},"block_id":53,"extra_data":{"point":{"x":0.43380994173278964,"y":0.18623498182360443,"z":1.0019999999999998}},"rotate":{"x":0,"y":0,"z":0}},{"move":{"x":4,"y":10,"z":4},"block_id":7},{"move":{"x":4,"y":10,"z":5},"block_id":53,"extra_data":{"point":{"x":0.40943938870324814,"y":0.016064170447039672,"z":-0.0019999999999997797}},"rotate":{"x":2,"y":0,"z":0}},{"move":{"x":4,"y":11,"z":4},"block_id":7},{"move":{"x":5,"y":-1,"z":0},"block_id":2},{"move":{"x":5,"y":-1,"z":1},"block_id":2},{"move":{"x":5,"y":-1,"z":2},"block_id":2},{"move":{"x":5,"y":-1,"z":3},"block_id":2},{"move":{"x":5,"y":-1,"z":4},"block_id":2},{"move":{"x":5,"y":-1,"z":5},"block_id":2},{"move":{"x":5,"y":-1,"z":6},"block_id":2},{"move":{"x":5,"y":-1,"z":7},"block_id":2},{"move":{"x":5,"y":-1,"z":8},"block_id":2},{"move":{"x":5,"y":-1,"z":9},"block_id":2},{"move":{"x":5,"y":0,"z":2},"block_id":98},{"move":{"x":5,"y":0,"z":3},"block_id":98},{"move":{"x":5,"y":0,"z":4},"block_id":98},{"move":{"x":5,"y":0,"z":5},"block_id":98},{"move":{"x":5,"y":0,"z":6},"block_id":98},{"move":{"x":5,"y":1,"z":2},"block_id":85},{"move":{"x":5,"y":1,"z":3},"block_id":85},{"move":{"x":5,"y":1,"z":4},"block_id":85},{"move":{"x":5,"y":1,"z":5},"block_id":85},{"move":{"x":5,"y":1,"z":6},"block_id":85}],"rot":[],"fluids":[]}