{"name":"ornated_stone_tower_ruins","world":{"pos1":{"x":-188,"y":0,"z":18},"pos2":{"x":-199,"y":25,"z":7},"door_bottom":{"x":-193,"y":1,"z":13}},"size":{"x":12,"y":26,"z":12},"door_pos":{"x":5,"y":1,"z":5},"blocks":[{"move":{"x":-5,"y":-1,"z":0},"block_id":632},{"move":{"x":-5,"y":-1,"z":1},"block_id":632},{"move":{"x":-5,"y":-1,"z":2},"block_id":632},{"move":{"x":-5,"y":-1,"z":3},"block_id":632},{"move":{"x":-5,"y":-1,"z":4},"block_id":632},{"move":{"x":-5,"y":-1,"z":5},"block_id":632},{"move":{"x":-5,"y":-1,"z":6},"block_id":632},{"move":{"x":-5,"y":-1,"z":7},"block_id":632},{"move":{"x":-5,"y":-1,"z":8},"block_id":632},{"move":{"x":-5,"y":-1,"z":9},"block_id":632},{"move":{"x":-5,"y":-1,"z":10},"block_id":632},{"move":{"x":-5,"y":-1,"z":11},"block_id":632},{"move":{"x":-5,"y":0,"z":4},"block_id":632},{"move":{"x":-5,"y":0,"z":7},"block_id":632},{"move":{"x":-5,"y":0,"z":8},"block_id":106,"rotate":{"x":3,"y":0,"z":0}},{"move":{"x":-5,"y":0,"z":9},"block_id":106,"rotate":{"x":3,"y":0,"z":0}},{"move":{"x":-5,"y":1,"z":4},"block_id":632},{"move":{"x":-5,"y":1,"z":7},"block_id":98},{"move":{"x":-5,"y":1,"z":8},"block_id":106,"rotate":{"x":3,"y":0,"z":0}},{"move":{"x":-5,"y":1,"z":9},"block_id":106,"rotate":{"x":3,"y":0,"z":0}},{"move":{"x":-5,"y":2,"z":4},"block_id":632},{"move":{"x":-5,"y":2,"z":5},"block_id":90},{"move":{"x":-5,"y":2,"z":6},"block_id":90},{"move":{"x":-5,"y":2,"z":7},"block_id":632},{"move":{"x":-5,"y":2,"z":8},"block_id":106,"rotate":{"x":3,"y":0,"z":0}},{"move":{"x":-5,"y":2,"z":9},"block_id":106,"rotate":{"x":3,"y":0,"z":0}},{"move":{"x":-5,"y":3,"z":4},"block_id":98},{"move":{"x":-5,"y":3,"z":5},"block_id":90},{"move":{"x":-5,"y":3,"z":6},"block_id":90},{"move":{"x":-5,"y":3,"z":7},"block_id":632},{"move":{"x":-5,"y":3,"z":8},"block_id":106,"rotate":{"x":3,"y":0,"z":0}},{"move":{"x":-5,"y":4,"z":4},"block_id":632},{"move":{"x":-5,"y":4,"z":5},"block_id":90},{"move":{"x":-5,"y":4,"z":6},"block_id":90},{"move":{"x":-5,"y":4,"z":7},"block_id":98},{"move":{"x":-5,"y":5,"z":4},"block_id":615,"extra_data":{"point":{"x":0,"y":0.1,"z":0}},"rotate":{"x":0,"y":0,"z":0}},{"move":{"x":-5,"y":5,"z":5},"block_id":615,"extra_data":{"point":{"x":0,"y":0.1,"z":0}},"rotate":{"x":3,"y":0,"z":0}},{"move":{"x":-5,"y":5,"z":6},"block_id":615,"extra_data":{"point":{"x":0,"y":0.1,"z":0}},"rotate":{"x":3,"y":0,"z":0}},{"move":{"x":-5,"y":5,"z":7},"block_id":615,"extra_data":{"point":{"x":0,"y":0.1,"z":0}},"rotate":{"x":2,"y":0,"z":0}},{"move":{"x":-4,"y":-1,"z":0},"block_id":632},{"move":{"x":-4,"y":-1,"z":1},"block_id":98},{"move":{"x":-4,"y":-1,"z":2},"block_id":98},{"move":{"x":-4,"y":-1,"z":3},"block_id":98},{"move":{"x":-4,"y":-1,"z":4},"block_id":98},{"move":{"x":-4,"y":-1,"z":5},"block_id":103},{"move":{"x":-4,"y":-1,"z":6},"block_id":103},{"move":{"x":-4,"y":-1,"z":7},"block_id":98},{"move":{"x":-4,"y":-1,"z":8},"block_id":98},{"move":{"x":-4,"y":-1,"z":9},"block_id":98},{"move":{"x":-4,"y":-1,"z":10},"block_id":98},{"move":{"x":-4,"y":-1,"z":11},"block_id":632},{"move":{"x":-4,"y":0,"z":1},"block_id":632},{"move":{"x":-4,"y":0,"z":2},"block_id":103},{"move":{"x":-4,"y":0,"z":3},"block_id":632},{"move":{"x":-4,"y":0,"z":4},"block_id":632},{"move":{"x":-4,"y":0,"z":7},"block_id":632},{"move":{"x":-4,"y":0,"z":8},"block_id":632},{"move":{"x":-4,"y":0,"z":9},"block_id":103},{"move":{"x":-4,"y":0,"z":10},"block_id":632},{"move":{"x":-4,"y":1,"z":1},"block_id":103},{"move":{"x":-4,"y":1,"z":2},"block_id":103},{"move":{"x":-4,"y":1,"z":3},"block_id":103},{"move":{"x":-4,"y":1,"z":4},"block_id":98},{"move":{"x":-4,"y":1,"z":7},"block_id":632},{"move":{"x":-4,"y":1,"z":8},"block_id":103},{"move":{"x":-4,"y":1,"z":9},"block_id":103},{"move":{"x":-4,"y":2,"z":1},"block_id":632},{"move":{"x":-4,"y":2,"z":2},"block_id":103},{"move":{"x":-4,"y":2,"z":3},"block_id":632},{"move":{"x":-4,"y":2,"z":4},"block_id":632},{"move":{"x":-4,"y":2,"z":5},"block_id":615,"extra_data":{"point":{"x":0,"y":0.9,"z":0}},"rotate":{"x":1,"y":0,"z":0}},{"move":{"x":-4,"y":2,"z":6},"block_id":615,"extra_data":{"point":{"x":0,"y":0.9,"z":0}},"rotate":{"x":1,"y":0,"z":0}},{"move":{"x":-4,"y":2,"z":7},"block_id":98},{"move":{"x":-4,"y":2,"z":8},"block_id":632},{"move":{"x":-4,"y":2,"z":9},"block_id":103},{"move":{"x":-4,"y":2,"z":10},"block_id":632},{"move":{"x":-4,"y":3,"z":1},"block_id":103},{"move":{"x":-4,"y":3,"z":2},"block_id":103},{"move":{"x":-4,"y":3,"z":3},"block_id":103},{"move":{"x":-4,"y":3,"z":4},"block_id":98},{"move":{"x":-4,"y":3,"z":5},"block_id":615,"extra_data":{"point":{"x":0,"y":0.1,"z":0}},"rotate":{"x":2,"y":0,"z":0}},{"move":{"x":-4,"y":3,"z":6},"block_id":615,"extra_data":{"point":{"x":0,"y":0.1,"z":0}},"rotate":{"x":0,"y":0,"z":0}},{"move":{"x":-4,"y":3,"z":7},"block_id":83},{"move":{"x":-4,"y":3,"z":8},"block_id":103},{"move":{"x":-4,"y":3,"z":9},"block_id":103},{"move":{"x":-4,"y":3,"z":10},"block_id":103},{"move":{"x":-4,"y":4,"z":1},"block_id":632},{"move":{"x":-4,"y":4,"z":2},"block_id":103},{"move":{"x":-4,"y":4,"z":3},"block_id":632},{"move":{"x":-4,"y":4,"z":4},"block_id":98},{"move":{"x":-4,"y":4,"z":5},"block_id":615,"extra_data":{"point":{"x":0,"y":0.9,"z":0}},"rotate":{"x":2,"y":0,"z":0}},{"move":{"x":-4,"y":4,"z":6},"block_id":615,"extra_data":{"point":{"x":0,"y":0.9,"z":0}},"rotate":{"x":0,"y":0,"z":0}},{"move":{"x":-4,"y":4,"z":7},"block_id":83},{"move":{"x":-4,"y":4,"z":8},"block_id":98},{"move":{"x":-4,"y":4,"z":9},"block_id":103},{"move":{"x":-4,"y":4,"z":10},"block_id":83},{"move":{"x":-4,"y":5,"z":1},"block_id":615,"extra_data":{"point":{"x":0,"y":0.1,"z":0}},"rotate":{"x":0,"y":0,"z":0}},{"move":{"x":-4,"y":5,"z":2},"block_id":615,"extra_data":{"point":{"x":0,"y":0.1,"z":0}},"rotate":{"x":3,"y":0,"z":0}},{"move":{"x":-4,"y":5,"z":3},"block_id":615,"extra_data":{"point":{"x":0,"y":0.1,"z":0}},"rotate":{"x":3,"y":0,"z":0}},{"move":{"x":-4,"y":5,"z":4},"block_id":101,"extra_data":{"point":{"x":0,"y":0.9,"z":0}}},{"move":{"x":-4,"y":5,"z":5},"block_id":98},{"move":{"x":-4,"y":5,"z":6},"block_id":98},{"move":{"x":-4,"y":5,"z":7},"block_id":101,"extra_data":{"point":{"x":0,"y":0.9,"z":0}}},{"move":{"x":-4,"y":5,"z":8},"block_id":615,"extra_data":{"point":{"x":0,"y":0.1,"z":0}},"rotate":{"x":3,"y":0,"z":0}},{"move":{"x":-4,"y":5,"z":9},"block_id":615,"extra_data":{"point":{"x":0,"y":0.1,"z":0}},"rotate":{"x":3,"y":0,"z":0}},{"move":{"x":-4,"y":5,"z":10},"block_id":615,"extra_data":{"point":{"x":0,"y":0.1,"z":0}},"rotate":{"x":3,"y":0,"z":0}},{"move":{"x":-4,"y":6,"z":4},"block_id":101,"extra_data":{"point":{"x":0,"y":0.1,"z":0}}},{"move":{"x":-4,"y":6,"z":5},"block_id":615,"extra_data":{"point":{"x":0,"y":0.1,"z":0}},"rotate":{"x":0,"y":0,"z":0}},{"move":{"x":-4,"y":6,"z":6},"block_id":615,"extra_data":{"point":{"x":0,"y":0.1,"z":0}},"rotate":{"x":2,"y":0,"z":0}},{"move":{"x":-4,"y":6,"z":7},"block_id":101,"extra_data":{"point":{"x":0,"y":0.1,"z":0}}},{"move":{"x":-4,"y":7,"z":4},"block_id":632},{"move":{"x":-4,"y":7,"z":5},"block_id":615,"extra_data":{"point":{"x":0,"y":0.9,"z":0}},"rotate":{"x":0,"y":0,"z":0}},{"move":{"x":-4,"y":7,"z":6},"block_id":615,"extra_data":{"point":{"x":0,"y":0.9,"z":0}},"rotate":{"x":2,"y":0,"z":0}},{"move":{"x":-4,"y":7,"z":7},"block_id":632},{"move":{"x":-4,"y":8,"z":5},"block_id":101,"extra_data":{"point":{"x":0,"y":0.1,"z":0}}},{"move":{"x":-4,"y":8,"z":6},"block_id":101,"extra_data":{"point":{"x":0,"y":0.1,"z":0}}},{"move":{"x":-3,"y":-1,"z":0},"block_id":632},{"move":{"x":-3,"y":-1,"z":1},"block_id":98},{"move":{"x":-3,"y":-1,"z":2},"block_id":103},{"move":{"x":-3,"y":-1,"z":3},"block_id":103},{"move":{"x":-3,"y":-1,"z":4},"block_id":90},{"move":{"x":-3,"y":-1,"z":5},"block_id":98},{"move":{"x":-3,"y":-1,"z":6},"block_id":98},{"move":{"x":-3,"y":-1,"z":7},"block_id":90},{"move":{"x":-3,"y":-1,"z":8},"block_id":2},{"move":{"x":-3,"y":-1,"z":9},"block_id":2},{"move":{"x":-3,"y":-1,"z":10},"block_id":98},{"move":{"x":-3,"y":-1,"z":11},"block_id":632},{"move":{"x":-3,"y":0,"z":0},"block_id":8},{"move":{"x":-3,"y":0,"z":1},"block_id":103},{"move":{"x":-3,"y":0,"z":2},"block_id":8},{"move":{"x":-3,"y":0,"z":3},"block_id":8},{"move":{"x":-3,"y":0,"z":10},"block_id":103},{"move":{"x":-3,"y":0,"z":11},"block_id":83},{"move":{"x":-3,"y":1,"z":1},"block_id":103},{"move":{"x":-3,"y":1,"z":3},"block_id":8},{"move":{"x":-3,"y":1,"z":8},"block_id":106,"rotate":{"x":1,"y":0,"z":0}},{"move":{"x":-3,"y":2,"z":1},"block_id":103},{"move":{"x":-3,"y":2,"z":2},"block_id":106,"rotate":{"x":2,"y":0,"z":0}},{"move":{"x":-3,"y":2,"z":3},"block_id":106,"rotate":{"x":1,"y":0,"z":0}},{"move":{"x":-3,"y":2,"z":4},"block_id":106,"rotate":{"x":1,"y":0,"z":0}},{"move":{"x":-3,"y":2,"z":7},"block_id":106,"rotate":{"x":1,"y":0,"z":0}},{"move":{"x":-3,"y":2,"z":8},"block_id":106,"rotate":{"x":1,"y":0,"z":0}},{"move":{"x":-3,"y":2,"z":9},"block_id":30},{"move":{"x":-3,"y":3,"z":1},"block_id":103},{"move":{"x":-3,"y":3,"z":2},"block_id":106,"rotate":{"x":2,"y":0,"z":0}},{"move":{"x":-3,"y":3,"z":3},"block_id":106,"rotate":{"x":1,"y":0,"z":0}},{"move":{"x":-3,"y":3,"z":4},"block_id":106,"rotate":{"x":1,"y":0,"z":0}},{"move":{"x":-3,"y":3,"z":8},"block_id":106,"rotate":{"x":1,"y":0,"z":0}},{"move":{"x":-3,"y":3,"z":9},"block_id":30},{"move":{"x":-3,"y":3,"z":10},"block_id":103},{"move":{"x":-3,"y":4,"z":1},"block_id":103},{"move":{"x":-3,"y":4,"z":2},"block_id":632},{"move":{"x":-3,"y":4,"z":3},"block_id":632},{"move":{"x":-3,"y":4,"z":8},"block_id":30},{"move":{"x":-3,"y":4,"z":9},"block_id":30},{"move":{"x":-3,"y":4,"z":10},"block_id":103},{"move":{"x":-3,"y":5,"z":1},"block_id":615,"extra_data":{"point":{"x":0,"y":0.1,"z":0}},"rotate":{"x":0,"y":0,"z":0}},{"move":{"x":-3,"y":5,"z":2},"block_id":632},{"move":{"x":-3,"y":5,"z":3},"block_id":632},{"move":{"x":-3,"y":5,"z":4},"block_id":83},{"move":{"x":-3,"y":5,"z":5},"block_id":83},{"move":{"x":-3,"y":5,"z":6},"block_id":83},{"move":{"x":-3,"y":5,"z":7},"block_id":98},{"move":{"x":-3,"y":5,"z":8},"block_id":98},{"move":{"x":-3,"y":5,"z":9},"block_id":98},{"move":{"x":-3,"y":5,"z":10},"block_id":615,"extra_data":{"point":{"x":0,"y":0.1,"z":0}},"rotate":{"x":2,"y":0,"z":0}},{"move":{"x":-3,"y":6,"z":4},"block_id":98},{"move":{"x":-3,"y":6,"z":5},"block_id":90},{"move":{"x":-3,"y":6,"z":6},"block_id":90},{"move":{"x":-3,"y":6,"z":7},"block_id":98},{"move":{"x":-3,"y":6,"z":8},"block_id":632},{"move":{"x":-3,"y":6,"z":9},"block_id":632},{"move":{"x":-3,"y":7,"z":4},"block_id":90},{"move":{"x":-3,"y":7,"z":5},"block_id":90},{"move":{"x":-3,"y":7,"z":6},"block_id":90},{"move":{"x":-3,"y":7,"z":7},"block_id":90},{"move":{"x":-3,"y":7,"z":8},"block_id":632},{"move":{"x":-3,"y":7,"z":9},"block_id":90},{"move":{"x":-3,"y":8,"z":4},"block_id":615,"extra_data":{"point":{"x":0,"y":0.1,"z":0}},"rotate":{"x":3,"y":0,"z":0}},{"move":{"x":-3,"y":8,"z":5},"block_id":615,"extra_data":{"point":{"x":0,"y":0.1,"z":0}},"rotate":{"x":3,"y":0,"z":0}},{"move":{"x":-3,"y":8,"z":6},"block_id":615,"extra_data":{"point":{"x":0,"y":0.1,"z":0}},"rotate":{"x":3,"y":0,"z":0}},{"move":{"x":-3,"y":8,"z":7},"block_id":615,"extra_data":{"point":{"x":0,"y":0.1,"z":0}},"rotate":{"x":3,"y":0,"z":0}},{"move":{"x":-3,"y":8,"z":8},"block_id":615,"extra_data":{"point":{"x":0,"y":0.1,"z":0}},"rotate":{"x":3,"y":0,"z":0}},{"move":{"x":-3,"y":8,"z":9},"block_id":103},{"move":{"x":-3,"y":9,"z":4},"block_id":83},{"move":{"x":-3,"y":9,"z":5},"block_id":615,"extra_data":{"point":{"x":0,"y":0.1,"z":0}},"rotate":{"x":2,"y":0,"z":0}},{"move":{"x":-3,"y":9,"z":6},"block_id":615,"extra_data":{"point":{"x":0,"y":0.1,"z":0}},"rotate":{"x":0,"y":0,"z":0}},{"move":{"x":-3,"y":9,"z":7},"block_id":632},{"move":{"x":-3,"y":9,"z":8},"block_id":83},{"move":{"x":-3,"y":9,"z":9},"block_id":632},{"move":{"x":-3,"y":10,"z":5},"block_id":615,"extra_data":{"point":{"x":0,"y":0.9,"z":0}},"rotate":{"x":2,"y":0,"z":0}},{"move":{"x":-3,"y":10,"z":6},"block_id":615,"extra_data":{"point":{"x":0,"y":0.9,"z":0}},"rotate":{"x":0,"y":0,"z":0}},{"move":{"x":-3,"y":10,"z":7},"block_id":98},{"move":{"x":-3,"y":10,"z":8},"block_id":615,"extra_data":{"point":{"x":0,"y":0.9,"z":0}},"rotate":{"x":3,"y":0,"z":0}},{"move":{"x":-3,"y":10,"z":9},"block_id":615,"extra_data":{"point":{"x":0,"y":0.9,"z":0}},"rotate":{"x":3,"y":0,"z":0}},{"move":{"x":-3,"y":11,"z":5},"block_id":615,"extra_data":{"point":{"x":0,"y":0.9,"z":0}},"rotate":{"x":3,"y":0,"z":0}},{"move":{"x":-3,"y":11,"z":6},"block_id":615,"extra_data":{"point":{"x":0,"y":0.9,"z":0}},"rotate":{"x":3,"y":0,"z":0}},{"move":{"x":-3,"y":11,"z":7},"block_id":83},{"move":{"x":-3,"y":11,"z":8},"block_id":632},{"move":{"x":-3,"y":11,"z":9},"block_id":615,"extra_data":{"point":{"x":0,"y":0.1,"z":0}},"rotate":{"x":2,"y":0,"z":0}},{"move":{"x":-3,"y":12,"z":5},"block_id":90},{"move":{"x":-3,"y":12,"z":6},"block_id":90},{"move":{"x":-3,"y":12,"z":7},"block_id":632},{"move":{"x":-3,"y":12,"z":8},"block_id":615,"extra_data":{"point":{"x":0,"y":0.9,"z":0}},"rotate":{"x":3,"y":0,"z":0}},{"move":{"x":-3,"y":12,"z":9},"block_id":615,"extra_data":{"point":{"x":0,"y":0.9,"z":0}},"rotate":{"x":3,"y":0,"z":0}},{"move":{"x":-3,"y":13,"z":6},"block_id":90},{"move":{"x":-3,"y":13,"z":7},"block_id":615,"extra_data":{"point":{"x":0,"y":0.9,"z":0}},"rotate":{"x":3,"y":0,"z":0}},{"move":{"x":-3,"y":13,"z":8},"block_id":632},{"move":{"x":-3,"y":13,"z":9},"block_id":103},{"move":{"x":-3,"y":14,"z":6},"block_id":90},{"move":{"x":-3,"y":14,"z":7},"block_id":615,"extra_data":{"point":{"x":0,"y":0.1,"z":0}},"rotate":{"x":3,"y":0,"z":0}},{"move":{"x":-3,"y":14,"z":8},"block_id":615,"extra_data":{"point":{"x":0,"y":0.1,"z":0}},"rotate":{"x":3,"y":0,"z":0}},{"move":{"x":-3,"y":14,"z":9},"block_id":615,"extra_data":{"point":{"x":0,"y":0.1,"z":0}},"rotate":{"x":3,"y":0,"z":0}},{"move":{"x":-2,"y":-1,"z":0},"block_id":632},{"move":{"x":-2,"y":-1,"z":1},"block_id":98},{"move":{"x":-2,"y":-1,"z":2},"block_id":103},{"move":{"x":-2,"y":-1,"z":3},"block_id":103},{"move":{"x":-2,"y":-1,"z":4},"block_id":90},{"move":{"x":-2,"y":-1,"z":5},"block_id":98},{"move":{"x":-2,"y":-1,"z":6},"block_id":2},{"move":{"x":-2,"y":-1,"z":7},"block_id":2},{"move":{"x":-2,"y":-1,"z":8},"block_id":2},{"move":{"x":-2,"y":-1,"z":9},"block_id":103},{"move":{"x":-2,"y":-1,"z":10},"block_id":98},{"move":{"x":-2,"y":-1,"z":11},"block_id":632},{"move":{"x":-2,"y":0,"z":0},"block_id":8},{"move":{"x":-2,"y":0,"z":1},"block_id":106,"rotate":{"x":0,"y":0,"z":0}},{"move":{"x":-2,"y":0,"z":2},"block_id":8},{"move":{"x":-2,"y":0,"z":10},"block_id":632},{"move":{"x":-2,"y":1,"z":1},"block_id":103},{"move":{"x":-2,"y":1,"z":2},"block_id":106,"rotate":{"x":2,"y":0,"z":0}},{"move":{"x":-2,"y":1,"z":10},"block_id":103},{"move":{"x":-2,"y":2,"z":1},"block_id":98},{"move":{"x":-2,"y":2,"z":2},"block_id":106,"rotate":{"x":2,"y":0,"z":0}},{"move":{"x":-2,"y":2,"z":10},"block_id":83},{"move":{"x":-2,"y":3,"z":1},"block_id":103},{"move":{"x":-2,"y":3,"z":2},"block_id":106,"rotate":{"x":2,"y":0,"z":0}},{"move":{"x":-2,"y":3,"z":9},"block_id":30},{"move":{"x":-2,"y":3,"z":10},"block_id":103},{"move":{"x":-2,"y":4,"z":1},"block_id":98},{"move":{"x":-2,"y":4,"z":2},"block_id":106,"rotate":{"x":2,"y":0,"z":0}},{"move":{"x":-2,"y":4,"z":9},"block_id":30},{"move":{"x":-2,"y":4,"z":10},"block_id":98},{"move":{"x":-2,"y":5,"z":1},"block_id":615,"extra_data":{"point":{"x":0,"y":0.1,"z":0}},"rotate":{"x":0,"y":0,"z":0}},{"move":{"x":-2,"y":5,"z":2},"block_id":98},{"move":{"x":-2,"y":5,"z":3},"block_id":83},{"move":{"x":-2,"y":5,"z":4},"block_id":83},{"move":{"x":-2,"y":5,"z":5},"block_id":83},{"move":{"x":-2,"y":5,"z":6},"block_id":83},{"move":{"x":-2,"y":5,"z":7},"block_id":98},{"move":{"x":-2,"y":5,"z":8},"block_id":98},{"move":{"x":-2,"y":5,"z":9},"block_id":98},{"move":{"x":-2,"y":5,"z":10},"block_id":615,"extra_data":{"point":{"x":0,"y":0.1,"z":0}},"rotate":{"x":2,"y":0,"z":0}},{"move":{"x":-2,"y":6,"z":2},"block_id":83},{"move":{"x":-2,"y":6,"z":4},"block_id":632},{"move":{"x":-2,"y":6,"z":5},"block_id":83},{"move":{"x":-2,"y":6,"z":6},"block_id":98},{"move":{"x":-2,"y":6,"z":7},"block_id":98},{"move":{"x":-2,"y":6,"z":8},"block_id":98},{"move":{"x":-2,"y":6,"z":9},"block_id":98},{"move":{"x":-2,"y":7,"z":2},"block_id":632},{"move":{"x":-2,"y":7,"z":6},"block_id":83},{"move":{"x":-2,"y":7,"z":7},"block_id":98},{"move":{"x":-2,"y":7,"z":8},"block_id":98},{"move":{"x":-2,"y":7,"z":9},"block_id":90},{"move":{"x":-2,"y":8,"z":9},"block_id":615,"extra_data":{"point":{"x":0,"y":0.1,"z":0}},"rotate":{"x":2,"y":0,"z":0}},{"move":{"x":-2,"y":9,"z":8},"block_id":106,"rotate":{"x":1,"y":0,"z":0}},{"move":{"x":-2,"y":9,"z":9},"block_id":83},{"move":{"x":-2,"y":10,"z":7},"block_id":106,"rotate":{"x":1,"y":0,"z":0}},{"move":{"x":-2,"y":10,"z":9},"block_id":615,"extra_data":{"point":{"x":0,"y":0.9,"z":0}},"rotate":{"x":2,"y":0,"z":0}},{"move":{"x":-2,"y":11,"z":7},"block_id":106,"rotate":{"x":1,"y":0,"z":0}},{"move":{"x":-2,"y":11,"z":8},"block_id":106,"rotate":{"x":1,"y":0,"z":0}},{"move":{"x":-2,"y":11,"z":9},"block_id":615,"extra_data":{"point":{"x":0,"y":0.1,"z":0}},"rotate":{"x":2,"y":0,"z":0}},{"move":{"x":-2,"y":12,"z":6},"block_id":615,"extra_data":{"point":{"x":0,"y":0.9,"z":0}},"rotate":{"x":1,"y":0,"z":0}},{"move":{"x":-2,"y":12,"z":7},"block_id":106,"rotate":{"x":1,"y":0,"z":0}},{"move":{"x":-2,"y":12,"z":8},"block_id":30},{"move":{"x":-2,"y":12,"z":9},"block_id":615,"extra_data":{"point":{"x":0,"y":0.9,"z":0}},"rotate":{"x":2,"y":0,"z":0}},{"move":{"x":-2,"y":13,"z":6},"block_id":98},{"move":{"x":-2,"y":13,"z":7},"block_id":30},{"move":{"x":-2,"y":13,"z":8},"block_id":30},{"move":{"x":-2,"y":13,"z":9},"block_id":615,"extra_data":{"point":{"x":0,"y":0.9,"z":0}},"rotate":{"x":2,"y":0,"z":0}},{"move":{"x":-2,"y":14,"z":6},"block_id":98},{"move":{"x":-2,"y":14,"z":7},"block_id":98},{"move":{"x":-2,"y":14,"z":8},"block_id":98},{"move":{"x":-2,"y":14,"z":9},"block_id":615,"extra_data":{"point":{"x":0,"y":0.1,"z":0}},"rotate":{"x":2,"y":0,"z":0}},{"move":{"x":-1,"y":-1,"z":0},"block_id":632},{"move":{"x":-1,"y":-1,"z":1},"block_id":98},{"move":{"x":-1,"y":-1,"z":2},"block_id":90},{"move":{"x":-1,"y":-1,"z":3},"block_id":90},{"move":{"x":-1,"y":-1,"z":4},"block_id":90},{"move":{"x":-1,"y":-1,"z":5},"block_id":2},{"move":{"x":-1,"y":-1,"z":6},"block_id":2},{"move":{"x":-1,"y":-1,"z":7},"block_id":2},{"move":{"x":-1,"y":-1,"z":8},"block_id":90},{"move":{"x":-1,"y":-1,"z":9},"block_id":90},{"move":{"x":-1,"y":-1,"z":10},"block_id":98},{"move":{"x":-1,"y":-1,"z":11},"block_id":632},{"move":{"x":-1,"y":0,"z":10},"block_id":632},{"move":{"x":-1,"y":0,"z":11},"block_id":632},{"move":{"x":-1,"y":1,"z":1},"block_id":106,"rotate":{"x":1,"y":0,"z":0}},{"move":{"x":-1,"y":1,"z":10},"block_id":98},{"move":{"x":-1,"y":1,"z":11},"block_id":83},{"move":{"x":-1,"y":2,"z":1},"block_id":106,"rotate":{"x":1,"y":0,"z":0}},{"move":{"x":-1,"y":2,"z":10},"block_id":632},{"move":{"x":-1,"y":2,"z":11},"block_id":83},{"move":{"x":-1,"y":3,"z":1},"block_id":106,"rotate":{"x":1,"y":0,"z":0}},{"move":{"x":-1,"y":3,"z":10},"block_id":632},{"move":{"x":-1,"y":3,"z":11},"block_id":83},{"move":{"x":-1,"y":4,"z":0},"block_id":98},{"move":{"x":-1,"y":4,"z":1},"block_id":98},{"move":{"x":-1,"y":4,"z":2},"block_id":106,"rotate":{"x":2,"y":0,"z":0}},{"move":{"x":-1,"y":4,"z":10},"block_id":98},{"move":{"x":-1,"y":4,"z":11},"block_id":83},{"move":{"x":-1,"y":5,"z":0},"block_id":615,"extra_data":{"point":{"x":0,"y":0.1,"z":0}},"rotate":{"x":3,"y":0,"z":0}},{"move":{"x":-1,"y":5,"z":1},"block_id":101,"extra_data":{"point":{"x":0,"y":0.9,"z":0}}},{"move":{"x":-1,"y":5,"z":2},"block_id":98},{"move":{"x":-1,"y":5,"z":3},"block_id":83},{"move":{"x":-1,"y":5,"z":8},"block_id":83},{"move":{"x":-1,"y":5,"z":9},"block_id":98},{"move":{"x":-1,"y":5,"z":10},"block_id":101,"extra_data":{"point":{"x":0,"y":0.9,"z":0}}},{"move":{"x":-1,"y":5,"z":11},"block_id":615,"extra_data":{"point":{"x":0,"y":0.1,"z":0}},"rotate":{"x":3,"y":0,"z":0}},{"move":{"x":-1,"y":6,"z":2},"block_id":83},{"move":{"x":-1,"y":6,"z":3},"block_id":98},{"move":{"x":-1,"y":6,"z":7},"block_id":30},{"move":{"x":-1,"y":6,"z":8},"block_id":83},{"move":{"x":-1,"y":6,"z":9},"block_id":98},{"move":{"x":-1,"y":6,"z":10},"block_id":101,"extra_data":{"point":{"x":0,"y":0.1,"z":0}}},{"move":{"x":-1,"y":7,"z":2},"block_id":90},{"move":{"x":-1,"y":7,"z":7},"block_id":83},{"move":{"x":-1,"y":7,"z":8},"block_id":98},{"move":{"x":-1,"y":7,"z":9},"block_id":90},{"move":{"x":-1,"y":8,"z":2},"block_id":615,"extra_data":{"point":{"x":0,"y":0.1,"z":0}},"rotate":{"x":0,"y":0,"z":0}},{"move":{"x":-1,"y":8,"z":8},"block_id":106,"rotate":{"x":0,"y":0,"z":0}},{"move":{"x":-1,"y":8,"z":9},"block_id":83},{"move":{"x":-1,"y":9,"z":8},"block_id":106,"rotate":{"x":0,"y":0,"z":0}},{"move":{"x":-1,"y":9,"z":9},"block_id":98},{"move":{"x":-1,"y":10,"z":8},"block_id":106,"rotate":{"x":0,"y":0,"z":0}},{"move":{"x":-1,"y":10,"z":9},"block_id":632},{"move":{"x":-1,"y":11,"z":8},"block_id":106,"rotate":{"x":0,"y":0,"z":0}},{"move":{"x":-1,"y":11,"z":9},"block_id":632},{"move":{"x":-1,"y":12,"z":8},"block_id":106,"rotate":{"x":0,"y":0,"z":0}},{"move":{"x":-1,"y":12,"z":9},"block_id":632},{"move":{"x":-1,"y":13,"z":8},"block_id":30},{"move":{"x":-1,"y":13,"z":9},"block_id":615,"extra_data":{"point":{"x":0,"y":0.9,"z":0}},"rotate":{"x":2,"y":0,"z":0}},{"move":{"x":-1,"y":14,"z":8},"block_id":83},{"move":{"x":-1,"y":14,"z":9},"block_id":615,"extra_data":{"point":{"x":0,"y":0.1,"z":0}},"rotate":{"x":2,"y":0,"z":0}},{"move":{"x":-1,"y":15,"z":8},"block_id":615,"extra_data":{"point":{"x":0,"y":0.9,"z":0}},"rotate":{"x":2,"y":0,"z":0}},{"move":{"x":-1,"y":16,"z":8},"block_id":103},{"move":{"x":0,"y":-1,"z":0},"block_id":632},{"move":{"x":0,"y":-1,"z":1},"block_id":103},{"move":{"x":0,"y":-1,"z":2},"block_id":98},{"move":{"x":0,"y":-1,"z":3},"block_id":98},{"move":{"x":0,"y":-1,"z":4},"block_id":90},{"move":{"x":0,"y":-1,"z":5},"block_id":83},{"move":{"x":0,"y":-1,"z":6},"block_id":83},{"move":{"x":0,"y":-1,"z":7},"block_id":2},{"move":{"x":0,"y":-1,"z":8},"block_id":2},{"move":{"x":0,"y":-1,"z":9},"block_id":98},{"move":{"x":0,"y":-1,"z":10},"block_id":103},{"move":{"x":0,"y":-1,"z":11},"block_id":632},{"move":{"x":0,"y":0,"z":5},"block_id":83},{"move":{"x":0,"y":0,"z":6},"block_id":83},{"move":{"x":0,"y":1,"z":5},"block_id":98},{"move":{"x":0,"y":1,"z":6},"block_id":83},{"move":{"x":0,"y":2,"z":5},"block_id":98},{"move":{"x":0,"y":2,"z":6},"block_id":83},{"move":{"x":0,"y":2,"z":10},"block_id":615,"extra_data":{"point":{"x":0,"y":0.9,"z":0}},"rotate":{"x":0,"y":0,"z":0}},{"move":{"x":0,"y":2,"z":11},"block_id":90},{"move":{"x":0,"y":3,"z":0},"block_id":90},{"move":{"x":0,"y":3,"z":1},"block_id":615,"extra_data":{"point":{"x":0,"y":0.1,"z":0}},"rotate":{"x":1,"y":0,"z":0}},{"move":{"x":0,"y":3,"z":5},"block_id":83},{"move":{"x":0,"y":3,"z":6},"block_id":98},{"move":{"x":0,"y":3,"z":10},"block_id":615,"extra_data":{"point":{"x":0,"y":0.1,"z":0}},"rotate":{"x":1,"y":0,"z":0}},{"move":{"x":0,"y":3,"z":11},"block_id":90},{"move":{"x":0,"y":4,"z":0},"block_id":90},{"move":{"x":0,"y":4,"z":1},"block_id":615,"extra_data":{"point":{"x":0,"y":0.9,"z":0}},"rotate":{"x":1,"y":0,"z":0}},{"move":{"x":0,"y":4,"z":5},"block_id":83},{"move":{"x":0,"y":4,"z":10},"block_id":615,"extra_data":{"point":{"x":0,"y":0.9,"z":0}},"rotate":{"x":1,"y":0,"z":0}},{"move":{"x":0,"y":4,"z":11},"block_id":90},{"move":{"x":0,"y":5,"z":0},"block_id":615,"extra_data":{"point":{"x":0,"y":0.1,"z":0}},"rotate":{"x":0,"y":0,"z":0}},{"move":{"x":0,"y":5,"z":1},"block_id":98},{"move":{"x":0,"y":5,"z":2},"block_id":98},{"move":{"x":0,"y":5,"z":3},"block_id":632},{"move":{"x":0,"y":5,"z":8},"block_id":632},{"move":{"x":0,"y":5,"z":9},"block_id":98},{"move":{"x":0,"y":5,"z":10},"block_id":98},{"move":{"x":0,"y":5,"z":11},"block_id":615,"extra_data":{"point":{"x":0,"y":0.1,"z":0}},"rotate":{"x":2,"y":0,"z":0}},{"move":{"x":0,"y":6,"z":2},"block_id":90},{"move":{"x":0,"y":6,"z":3},"block_id":98},{"move":{"x":0,"y":6,"z":8},"block_id":632},{"move":{"x":0,"y":6,"z":9},"block_id":90},{"move":{"x":0,"y":6,"z":10},"block_id":615,"extra_data":{"point":{"x":0,"y":0.1,"z":0}},"rotate":{"x":3,"y":0,"z":0}},{"move":{"x":0,"y":7,"z":2},"block_id":90},{"move":{"x":0,"y":7,"z":3},"block_id":83},{"move":{"x":0,"y":7,"z":8},"block_id":632},{"move":{"x":0,"y":7,"z":9},"block_id":90},{"move":{"x":0,"y":7,"z":10},"block_id":615,"extra_data":{"point":{"x":0,"y":0.9,"z":0}},"rotate":{"x":3,"y":0,"z":0}},{"move":{"x":0,"y":8,"z":2},"block_id":615,"extra_data":{"point":{"x":0,"y":0.1,"z":0}},"rotate":{"x":0,"y":0,"z":0}},{"move":{"x":0,"y":8,"z":3},"block_id":101,"extra_data":{"point":{"x":0,"y":0.1,"z":0}}},{"move":{"x":0,"y":8,"z":8},"block_id":101,"extra_data":{"point":{"x":0,"y":0.1,"z":0}}},{"move":{"x":0,"y":8,"z":9},"block_id":615,"extra_data":{"point":{"x":0,"y":0.1,"z":0}},"rotate":{"x":2,"y":0,"z":0}},{"move":{"x":0,"y":8,"z":10},"block_id":101,"extra_data":{"point":{"x":0,"y":0.1,"z":0}}},{"move":{"x":0,"y":9,"z":2},"block_id":615,"extra_data":{"point":{"x":0,"y":0.1,"z":0}},"rotate":{"x":1,"y":0,"z":0}},{"move":{"x":0,"y":9,"z":9},"block_id":615,"extra_data":{"point":{"x":0,"y":0.1,"z":0}},"rotate":{"x":1,"y":0,"z":0}},{"move":{"x":0,"y":10,"z":2},"block_id":615,"extra_data":{"point":{"x":0,"y":0.9,"z":0}},"rotate":{"x":1,"y":0,"z":0}},{"move":{"x":0,"y":10,"z":9},"block_id":615,"extra_data":{"point":{"x":0,"y":0.9,"z":0}},"rotate":{"x":1,"y":0,"z":0}},{"move":{"x":0,"y":11,"z":9},"block_id":615,"extra_data":{"point":{"x":0,"y":0.9,"z":0}},"rotate":{"x":2,"y":0,"z":0}},{"move":{"x":0,"y":12,"z":9},"block_id":90},{"move":{"x":0,"y":13,"z":8},"block_id":632},{"move":{"x":0,"y":13,"z":9},"block_id":90},{"move":{"x":0,"y":14,"z":8},"block_id":632},{"move":{"x":0,"y":14,"z":9},"block_id":90},{"move":{"x":0,"y":15,"z":8},"block_id":90},{"move":{"x":0,"y":16,"z":8},"block_id":90},{"move":{"x":0,"y":17,"z":8},"block_id":90},{"move":{"x":0,"y":18,"z":8},"block_id":90},{"move":{"x":1,"y":-1,"z":0},"block_id":632},{"move":{"x":1,"y":-1,"z":1},"block_id":103},{"move":{"x":1,"y":-1,"z":2},"block_id":98},{"move":{"x":1,"y":-1,"z":3},"block_id":2},{"move":{"x":1,"y":-1,"z":4},"block_id":2},{"move":{"x":1,"y":-1,"z":5},"block_id":83},{"move":{"x":1,"y":-1,"z":6},"block_id":90},{"move":{"x":1,"y":-1,"z":7},"block_id":2},{"move":{"x":1,"y":-1,"z":8},"block_id":2},{"move":{"x":1,"y":-1,"z":9},"block_id":2},{"move":{"x":1,"y":-1,"z":10},"block_id":2},{"move":{"x":1,"y":-1,"z":11},"block_id":632},{"move":{"x":1,"y":0,"z":5},"block_id":83},{"move":{"x":1,"y":1,"z":5},"block_id":98},{"move":{"x":1,"y":2,"z":0},"block_id":90},{"move":{"x":1,"y":2,"z":1},"block_id":615,"extra_data":{"point":{"x":0,"y":0.9,"z":0}},"rotate":{"x":2,"y":0,"z":0}},{"move":{"x":1,"y":2,"z":5},"block_id":83},{"move":{"x":1,"y":2,"z":10},"block_id":615,"extra_data":{"point":{"x":0,"y":0.9,"z":0}},"rotate":{"x":0,"y":0,"z":0}},{"move":{"x":1,"y":2,"z":11},"block_id":90},{"move":{"x":1,"y":3,"z":0},"block_id":90},{"move":{"x":1,"y":3,"z":1},"block_id":615,"extra_data":{"point":{"x":0,"y":0.1,"z":0}},"rotate":{"x":3,"y":0,"z":0}},{"move":{"x":1,"y":3,"z":5},"block_id":83},{"move":{"x":1,"y":3,"z":10},"block_id":615,"extra_data":{"point":{"x":0,"y":0.1,"z":0}},"rotate":{"x":3,"y":0,"z":0}},{"move":{"x":1,"y":3,"z":11},"block_id":90},{"move":{"x":1,"y":4,"z":0},"block_id":90},{"move":{"x":1,"y":4,"z":1},"block_id":615,"extra_data":{"point":{"x":0,"y":0.9,"z":0}},"rotate":{"x":3,"y":0,"z":0}},{"move":{"x":1,"y":4,"z":5},"block_id":98},{"move":{"x":1,"y":4,"z":10},"block_id":615,"extra_data":{"point":{"x":0,"y":0.9,"z":0}},"rotate":{"x":3,"y":0,"z":0}},{"move":{"x":1,"y":4,"z":11},"block_id":90},{"move":{"x":1,"y":5,"z":0},"block_id":615,"extra_data":{"point":{"x":0,"y":0.1,"z":0}},"rotate":{"x":0,"y":0,"z":0}},{"move":{"x":1,"y":5,"z":1},"block_id":98},{"move":{"x":1,"y":5,"z":2},"block_id":98},{"move":{"x":1,"y":5,"z":3},"block_id":83},{"move":{"x":1,"y":5,"z":5},"block_id":83},{"move":{"x":1,"y":5,"z":8},"block_id":98},{"move":{"x":1,"y":5,"z":9},"block_id":98},{"move":{"x":1,"y":5,"z":10},"block_id":98},{"move":{"x":1,"y":5,"z":11},"block_id":615,"extra_data":{"point":{"x":0,"y":0.1,"z":0}},"rotate":{"x":2,"y":0,"z":0}},{"move":{"x":1,"y":6,"z":2},"block_id":90},{"move":{"x":1,"y":6,"z":3},"block_id":83},{"move":{"x":1,"y":6,"z":5},"block_id":83},{"move":{"x":1,"y":6,"z":8},"block_id":632},{"move":{"x":1,"y":6,"z":9},"block_id":90},{"move":{"x":1,"y":6,"z":10},"block_id":615,"extra_data":{"point":{"x":0,"y":0.1,"z":0}},"rotate":{"x":1,"y":0,"z":0}},{"move":{"x":1,"y":7,"z":2},"block_id":90},{"move":{"x":1,"y":7,"z":3},"block_id":83},{"move":{"x":1,"y":7,"z":8},"block_id":98},{"move":{"x":1,"y":7,"z":9},"block_id":90},{"move":{"x":1,"y":7,"z":10},"block_id":615,"extra_data":{"point":{"x":0,"y":0.9,"z":0}},"rotate":{"x":1,"y":0,"z":0}},{"move":{"x":1,"y":8,"z":2},"block_id":615,"extra_data":{"point":{"x":0,"y":0.1,"z":0}},"rotate":{"x":0,"y":0,"z":0}},{"move":{"x":1,"y":8,"z":3},"block_id":101,"extra_data":{"point":{"x":0,"y":0.1,"z":0}}},{"move":{"x":1,"y":8,"z":8},"block_id":632},{"move":{"x":1,"y":8,"z":9},"block_id":615,"extra_data":{"point":{"x":0,"y":0.1,"z":0}},"rotate":{"x":2,"y":0,"z":0}},{"move":{"x":1,"y":8,"z":10},"block_id":101,"extra_data":{"point":{"x":0,"y":0.1,"z":0}}},{"move":{"x":1,"y":9,"z":2},"block_id":615,"extra_data":{"point":{"x":0,"y":0.1,"z":0}},"rotate":{"x":3,"y":0,"z":0}},{"move":{"x":1,"y":9,"z":9},"block_id":615,"extra_data":{"point":{"x":0,"y":0.1,"z":0}},"rotate":{"x":3,"y":0,"z":0}},{"move":{"x":1,"y":10,"z":2},"block_id":615,"extra_data":{"point":{"x":0,"y":0.9,"z":0}},"rotate":{"x":3,"y":0,"z":0}},{"move":{"x":1,"y":10,"z":9},"block_id":615,"extra_data":{"point":{"x":0,"y":0.9,"z":0}},"rotate":{"x":3,"y":0,"z":0}},{"move":{"x":1,"y":11,"z":2},"block_id":615,"extra_data":{"point":{"x":0,"y":0.9,"z":0}},"rotate":{"x":0,"y":0,"z":0}},{"move":{"x":1,"y":11,"z":9},"block_id":615,"extra_data":{"point":{"x":0,"y":0.9,"z":0}},"rotate":{"x":2,"y":0,"z":0}},{"move":{"x":1,"y":14,"z":8},"block_id":98},{"move":{"x":1,"y":14,"z":9},"block_id":90},{"move":{"x":1,"y":15,"z":8},"block_id":90},{"move":{"x":1,"y":16,"z":8},"block_id":90},{"move":{"x":1,"y":17,"z":8},"block_id":90},{"move":{"x":1,"y":18,"z":8},"block_id":90},{"move":{"x":1,"y":19,"z":8},"block_id":83},{"move":{"x":1,"y":20,"z":8},"block_id":615,"extra_data":{"point":{"x":0,"y":0.1,"z":0}},"rotate":{"x":3,"y":0,"z":0}},{"move":{"x":2,"y":-1,"z":0},"block_id":632},{"move":{"x":2,"y":-1,"z":1},"block_id":98},{"move":{"x":2,"y":-1,"z":2},"block_id":2},{"move":{"x":2,"y":-1,"z":3},"block_id":2},{"move":{"x":2,"y":-1,"z":4},"block_id":2},{"move":{"x":2,"y":-1,"z":5},"block_id":2},{"move":{"x":2,"y":-1,"z":6},"block_id":90},{"move":{"x":2,"y":-1,"z":7},"block_id":90},{"move":{"x":2,"y":-1,"z":8},"block_id":90},{"move":{"x":2,"y":-1,"z":9},"block_id":90},{"move":{"x":2,"y":-1,"z":10},"block_id":2},{"move":{"x":2,"y":-1,"z":11},"block_id":2},{"move":{"x":2,"y":0,"z":0},"block_id":632},{"move":{"x":2,"y":0,"z":1},"block_id":632},{"move":{"x":2,"y":0,"z":5},"block_id":106,"extra_data":{"west":true,"rotate":false}},{"move":{"x":2,"y":0,"z":7},"block_id":8},{"move":{"x":2,"y":1,"z":0},"block_id":98},{"move":{"x":2,"y":1,"z":1},"block_id":98},{"move":{"x":2,"y":1,"z":5},"block_id":106,"extra_data":{"west":true,"rotate":false}},{"move":{"x":2,"y":1,"z":10},"block_id":98},{"move":{"x":2,"y":1,"z":11},"block_id":83},{"move":{"x":2,"y":2,"z":0},"block_id":98},{"move":{"x":2,"y":2,"z":1},"block_id":83},{"move":{"x":2,"y":2,"z":5},"block_id":106,"extra_data":{"west":true,"rotate":false}},{"move":{"x":2,"y":2,"z":10},"block_id":98},{"move":{"x":2,"y":2,"z":11},"block_id":83},{"move":{"x":2,"y":3,"z":0},"block_id":98},{"move":{"x":2,"y":3,"z":5},"block_id":106,"extra_data":{"west":true,"rotate":false}},{"move":{"x":2,"y":3,"z":10},"block_id":632},{"move":{"x":2,"y":3,"z":11},"block_id":83},{"move":{"x":2,"y":4,"z":0},"block_id":98},{"move":{"x":2,"y":4,"z":1},"block_id":98},{"move":{"x":2,"y":4,"z":5},"block_id":106,"extra_data":{"west":true,"rotate":false}},{"move":{"x":2,"y":4,"z":10},"block_id":98},{"move":{"x":2,"y":4,"z":11},"block_id":632},{"move":{"x":2,"y":5,"z":0},"block_id":615,"extra_data":{"point":{"x":0,"y":0.1,"z":0}},"rotate":{"x":1,"y":0,"z":0}},{"move":{"x":2,"y":5,"z":1},"block_id":101,"extra_data":{"point":{"x":0,"y":0.9,"z":0}}},{"move":{"x":2,"y":5,"z":2},"block_id":83},{"move":{"x":2,"y":5,"z":3},"block_id":98},{"move":{"x":2,"y":5,"z":5},"block_id":106,"extra_data":{"west":true,"rotate":false}},{"move":{"x":2,"y":5,"z":8},"block_id":83},{"move":{"x":2,"y":5,"z":9},"block_id":98},{"move":{"x":2,"y":5,"z":10},"block_id":101,"extra_data":{"point":{"x":0,"y":0.9,"z":0}}},{"move":{"x":2,"y":5,"z":11},"block_id":615,"extra_data":{"point":{"x":0,"y":0.1,"z":0}},"rotate":{"x":1,"y":0,"z":0}},{"move":{"x":2,"y":6,"z":2},"block_id":83},{"move":{"x":2,"y":6,"z":3},"block_id":83},{"move":{"x":2,"y":6,"z":5},"block_id":106,"extra_data":{"west":true,"rotate":false}},{"move":{"x":2,"y":6,"z":8},"block_id":83},{"move":{"x":2,"y":6,"z":9},"block_id":98},{"move":{"x":2,"y":6,"z":10},"block_id":101,"extra_data":{"point":{"x":0,"y":0.1,"z":0}}},{"move":{"x":2,"y":7,"z":2},"block_id":90},{"move":{"x":2,"y":7,"z":3},"block_id":98},{"move":{"x":2,"y":7,"z":4},"block_id":83},{"move":{"x":2,"y":7,"z":9},"block_id":90},{"move":{"x":2,"y":7,"z":10},"block_id":83},{"move":{"x":2,"y":8,"z":2},"block_id":615,"extra_data":{"point":{"x":0,"y":0.1,"z":0}},"rotate":{"x":0,"y":0,"z":0}},{"move":{"x":2,"y":8,"z":9},"block_id":615,"extra_data":{"point":{"x":0,"y":0.1,"z":0}},"rotate":{"x":2,"y":0,"z":0}},{"move":{"x":2,"y":9,"z":2},"block_id":83},{"move":{"x":2,"y":9,"z":9},"block_id":98},{"move":{"x":2,"y":10,"z":2},"block_id":83},{"move":{"x":2,"y":10,"z":9},"block_id":83},{"move":{"x":2,"y":11,"z":2},"block_id":98},{"move":{"x":2,"y":11,"z":9},"block_id":83},{"move":{"x":2,"y":12,"z":2},"block_id":98},{"move":{"x":2,"y":12,"z":9},"block_id":98},{"move":{"x":2,"y":13,"z":2},"block_id":615,"extra_data":{"point":{"x":0,"y":0.9,"z":0}},"rotate":{"x":0,"y":0,"z":0}},{"move":{"x":2,"y":13,"z":8},"block_id":30},{"move":{"x":2,"y":13,"z":9},"block_id":615,"extra_data":{"point":{"x":0,"y":0.9,"z":0}},"rotate":{"x":2,"y":0,"z":0}},{"move":{"x":2,"y":14,"z":2},"block_id":615,"extra_data":{"point":{"x":0,"y":0.1,"z":0}},"rotate":{"x":0,"y":0,"z":0}},{"move":{"x":2,"y":14,"z":3},"block_id":98},{"move":{"x":2,"y":14,"z":5},"block_id":106,"rotate":{"x":3,"y":0,"z":0}},{"move":{"x":2,"y":14,"z":6},"block_id":106,"rotate":{"x":3,"y":0,"z":0}},{"move":{"x":2,"y":14,"z":8},"block_id":83},{"move":{"x":2,"y":14,"z":9},"block_id":615,"extra_data":{"point":{"x":0,"y":0.1,"z":0}},"rotate":{"x":2,"y":0,"z":0}},{"move":{"x":2,"y":15,"z":3},"block_id":615,"extra_data":{"point":{"x":0,"y":0.9,"z":0}},"rotate":{"x":0,"y":0,"z":0}},{"move":{"x":2,"y":15,"z":5},"block_id":106,"rotate":{"x":3,"y":0,"z":0}},{"move":{"x":2,"y":15,"z":6},"block_id":106,"rotate":{"x":3,"y":0,"z":0}},{"move":{"x":2,"y":15,"z":8},"block_id":615,"extra_data":{"point":{"x":0,"y":0.9,"z":0}},"rotate":{"x":2,"y":0,"z":0}},{"move":{"x":2,"y":16,"z":2},"block_id":106,"rotate":{"x":0,"y":0,"z":0}},{"move":{"x":2,"y":16,"z":3},"block_id":103},{"move":{"x":2,"y":16,"z":5},"block_id":106,"rotate":{"x":3,"y":0,"z":0}},{"move":{"x":2,"y":16,"z":6},"block_id":106,"rotate":{"x":3,"y":0,"z":0}},{"move":{"x":2,"y":16,"z":7},"block_id":106,"rotate":{"x":3,"y":0,"z":0}},{"move":{"x":2,"y":16,"z":8},"block_id":103},{"move":{"x":2,"y":17,"z":5},"block_id":106,"rotate":{"x":3,"y":0,"z":0}},{"move":{"x":2,"y":17,"z":6},"block_id":106,"rotate":{"x":3,"y":0,"z":0}},{"move":{"x":2,"y":17,"z":8},"block_id":615,"extra_data":{"point":{"x":0,"y":0.1,"z":0}},"rotate":{"x":2,"y":0,"z":0}},{"move":{"x":2,"y":18,"z":5},"block_id":106,"rotate":{"x":3,"y":0,"z":0}},{"move":{"x":2,"y":18,"z":6},"block_id":106,"rotate":{"x":3,"y":0,"z":0}},{"move":{"x":2,"y":18,"z":8},"block_id":90},{"move":{"x":2,"y":19,"z":5},"block_id":106,"rotate":{"x":3,"y":0,"z":0}},{"move":{"x":2,"y":19,"z":6},"block_id":106,"rotate":{"x":3,"y":0,"z":0}},{"move":{"x":2,"y":19,"z":8},"block_id":90},{"move":{"x":2,"y":20,"z":8},"block_id":90},{"move":{"x":2,"y":21,"z":8},"block_id":90},{"move":{"x":2,"y":22,"z":8},"block_id":90},{"move":{"x":3,"y":-1,"z":0},"block_id":632},{"move":{"x":3,"y":-1,"z":1},"block_id":98},{"move":{"x":3,"y":-1,"z":2},"block_id":2},{"move":{"x":3,"y":-1,"z":3},"block_id":2},{"move":{"x":3,"y":-1,"z":4},"block_id":2},{"move":{"x":3,"y":-1,"z":5},"block_id":98},{"move":{"x":3,"y":-1,"z":6},"block_id":98},{"move":{"x":3,"y":-1,"z":7},"block_id":90},{"move":{"x":3,"y":-1,"z":8},"block_id":103},{"move":{"x":3,"y":-1,"z":9},"block_id":103},{"move":{"x":3,"y":-1,"z":10},"block_id":98},{"move":{"x":3,"y":-1,"z":11},"block_id":2},{"move":{"x":3,"y":0,"z":1},"block_id":632},{"move":{"x":3,"y":0,"z":7},"block_id":8},{"move":{"x":3,"y":0,"z":8},"block_id":8},{"move":{"x":3,"y":0,"z":10},"block_id":632},{"move":{"x":3,"y":1,"z":1},"block_id":103},{"move":{"x":3,"y":1,"z":8},"block_id":8},{"move":{"x":3,"y":1,"z":10},"block_id":103},{"move":{"x":3,"y":2,"z":10},"block_id":632},{"move":{"x":3,"y":3,"z":10},"block_id":103},{"move":{"x":3,"y":4,"z":10},"block_id":632},{"move":{"x":3,"y":5,"z":1},"block_id":615,"extra_data":{"point":{"x":0,"y":0.1,"z":0}},"rotate":{"x":0,"y":0,"z":0}},{"move":{"x":3,"y":5,"z":2},"block_id":98},{"move":{"x":3,"y":5,"z":3},"block_id":98},{"move":{"x":3,"y":5,"z":4},"block_id":98},{"move":{"x":3,"y":5,"z":5},"block_id":83},{"move":{"x":3,"y":5,"z":6},"block_id":98},{"move":{"x":3,"y":5,"z":7},"block_id":98},{"move":{"x":3,"y":5,"z":8},"block_id":98},{"move":{"x":3,"y":5,"z":9},"block_id":98},{"move":{"x":3,"y":5,"z":10},"block_id":615,"extra_data":{"point":{"x":0,"y":0.1,"z":0}},"rotate":{"x":2,"y":0,"z":0}},{"move":{"x":3,"y":6,"z":2},"block_id":83},{"move":{"x":3,"y":6,"z":3},"block_id":98},{"move":{"x":3,"y":6,"z":4},"block_id":632},{"move":{"x":3,"y":6,"z":5},"block_id":83},{"move":{"x":3,"y":6,"z":6},"block_id":98},{"move":{"x":3,"y":6,"z":7},"block_id":98},{"move":{"x":3,"y":6,"z":8},"block_id":83},{"move":{"x":3,"y":6,"z":9},"block_id":83},{"move":{"x":3,"y":7,"z":2},"block_id":83},{"move":{"x":3,"y":7,"z":3},"block_id":98},{"move":{"x":3,"y":7,"z":7},"block_id":632},{"move":{"x":3,"y":7,"z":9},"block_id":83},{"move":{"x":3,"y":8,"z":2},"block_id":98},{"move":{"x":3,"y":8,"z":9},"block_id":83},{"move":{"x":3,"y":9,"z":2},"block_id":632},{"move":{"x":3,"y":9,"z":3},"block_id":106,"rotate":{"x":3,"y":0,"z":0}},{"move":{"x":3,"y":9,"z":4},"block_id":106,"rotate":{"x":3,"y":0,"z":0}},{"move":{"x":3,"y":9,"z":9},"block_id":83},{"move":{"x":3,"y":10,"z":2},"block_id":615,"extra_data":{"point":{"x":0,"y":0.9,"z":0}},"rotate":{"x":0,"y":0,"z":0}},{"move":{"x":3,"y":10,"z":4},"block_id":106,"rotate":{"x":3,"y":0,"z":0}},{"move":{"x":3,"y":10,"z":9},"block_id":615,"extra_data":{"point":{"x":0,"y":0.9,"z":0}},"rotate":{"x":2,"y":0,"z":0}},{"move":{"x":3,"y":11,"z":2},"block_id":615,"extra_data":{"point":{"x":0,"y":0.1,"z":0}},"rotate":{"x":0,"y":0,"z":0}},{"move":{"x":3,"y":11,"z":4},"block_id":106,"rotate":{"x":3,"y":0,"z":0}},{"move":{"x":3,"y":11,"z":9},"block_id":615,"extra_data":{"point":{"x":0,"y":0.1,"z":0}},"rotate":{"x":2,"y":0,"z":0}},{"move":{"x":3,"y":12,"z":2},"block_id":615,"extra_data":{"point":{"x":0,"y":0.9,"z":0}},"rotate":{"x":0,"y":0,"z":0}},{"move":{"x":3,"y":12,"z":3},"block_id":30},{"move":{"x":3,"y":12,"z":4},"block_id":106,"rotate":{"x":3,"y":0,"z":0}},{"move":{"x":3,"y":12,"z":8},"block_id":30},{"move":{"x":3,"y":12,"z":9},"block_id":615,"extra_data":{"point":{"x":0,"y":0.9,"z":0}},"rotate":{"x":2,"y":0,"z":0}},{"move":{"x":3,"y":13,"z":2},"block_id":98},{"move":{"x":3,"y":13,"z":3},"block_id":30},{"move":{"x":3,"y":13,"z":4},"block_id":30},{"move":{"x":3,"y":13,"z":7},"block_id":30},{"move":{"x":3,"y":13,"z":8},"block_id":30},{"move":{"x":3,"y":13,"z":9},"block_id":83},{"move":{"x":3,"y":14,"z":2},"block_id":615,"extra_data":{"point":{"x":0,"y":0.1,"z":0}},"rotate":{"x":0,"y":0,"z":0}},{"move":{"x":3,"y":14,"z":3},"block_id":98},{"move":{"x":3,"y":14,"z":4},"block_id":98},{"move":{"x":3,"y":14,"z":5},"block_id":83},{"move":{"x":3,"y":14,"z":6},"block_id":83},{"move":{"x":3,"y":14,"z":7},"block_id":83},{"move":{"x":3,"y":14,"z":8},"block_id":98},{"move":{"x":3,"y":14,"z":9},"block_id":615,"extra_data":{"point":{"x":0,"y":0.1,"z":0}},"rotate":{"x":2,"y":0,"z":0}},{"move":{"x":3,"y":15,"z":3},"block_id":615,"extra_data":{"point":{"x":0,"y":0.9,"z":0}},"rotate":{"x":0,"y":0,"z":0}},{"move":{"x":3,"y":15,"z":4},"block_id":615,"extra_data":{"point":{"x":0,"y":0.9,"z":0}},"rotate":{"x":1,"y":0,"z":0}},{"move":{"x":3,"y":15,"z":5},"block_id":90},{"move":{"x":3,"y":15,"z":6},"block_id":90},{"move":{"x":3,"y":15,"z":7},"block_id":83},{"move":{"x":3,"y":15,"z":8},"block_id":615,"extra_data":{"point":{"x":0,"y":0.9,"z":0}},"rotate":{"x":2,"y":0,"z":0}},{"move":{"x":3,"y":16,"z":2},"block_id":106,"rotate":{"x":0,"y":0,"z":0}},{"move":{"x":3,"y":16,"z":3},"block_id":103},{"move":{"x":3,"y":16,"z":4},"block_id":103},{"move":{"x":3,"y":16,"z":5},"block_id":90},{"move":{"x":3,"y":16,"z":6},"block_id":90},{"move":{"x":3,"y":16,"z":7},"block_id":103},{"move":{"x":3,"y":16,"z":8},"block_id":103},{"move":{"x":3,"y":17,"z":4},"block_id":615,"extra_data":{"point":{"x":0,"y":0.1,"z":0}},"rotate":{"x":1,"y":0,"z":0}},{"move":{"x":3,"y":17,"z":5},"block_id":90},{"move":{"x":3,"y":17,"z":6},"block_id":90},{"move":{"x":3,"y":17,"z":7},"block_id":615,"extra_data":{"point":{"x":0,"y":0.1,"z":0}},"rotate":{"x":1,"y":0,"z":0}},{"move":{"x":3,"y":17,"z":8},"block_id":615,"extra_data":{"point":{"x":0,"y":0.1,"z":0}},"rotate":{"x":2,"y":0,"z":0}},{"move":{"x":3,"y":18,"z":4},"block_id":90},{"move":{"x":3,"y":18,"z":5},"block_id":90},{"move":{"x":3,"y":18,"z":6},"block_id":90},{"move":{"x":3,"y":18,"z":7},"block_id":90},{"move":{"x":3,"y":18,"z":8},"block_id":90},{"move":{"x":3,"y":19,"z":4},"block_id":90},{"move":{"x":3,"y":19,"z":5},"block_id":83},{"move":{"x":3,"y":19,"z":6},"block_id":632},{"move":{"x":3,"y":19,"z":7},"block_id":90},{"move":{"x":3,"y":19,"z":8},"block_id":632},{"move":{"x":3,"y":20,"z":5},"block_id":615,"extra_data":{"point":{"x":0,"y":0.1,"z":0}},"rotate":{"x":2,"y":0,"z":0}},{"move":{"x":3,"y":20,"z":6},"block_id":615,"extra_data":{"point":{"x":0,"y":0.1,"z":0}},"rotate":{"x":0,"y":0,"z":0}},{"move":{"x":3,"y":20,"z":7},"block_id":90},{"move":{"x":3,"y":20,"z":8},"block_id":103},{"move":{"x":3,"y":21,"z":7},"block_id":90},{"move":{"x":3,"y":21,"z":8},"block_id":632},{"move":{"x":3,"y":22,"z":7},"block_id":90},{"move":{"x":3,"y":22,"z":8},"block_id":103},{"move":{"x":4,"y":-1,"z":0},"block_id":18},{"move":{"x":4,"y":-1,"z":1},"block_id":98},{"move":{"x":4,"y":-1,"z":2},"block_id":103},{"move":{"x":4,"y":-1,"z":3},"block_id":2},{"move":{"x":4,"y":-1,"z":4},"block_id":2},{"move":{"x":4,"y":-1,"z":5},"block_id":98},{"move":{"x":4,"y":-1,"z":6},"block_id":2},{"move":{"x":4,"y":-1,"z":7},"block_id":2},{"move":{"x":4,"y":-1,"z":8},"block_id":103},{"move":{"x":4,"y":-1,"z":9},"block_id":103},{"move":{"x":4,"y":-1,"z":10},"block_id":98},{"move":{"x":4,"y":-1,"z":11},"block_id":2},{"move":{"x":4,"y":0,"z":0},"block_id":8},{"move":{"x":4,"y":0,"z":1},"block_id":103},{"move":{"x":4,"y":0,"z":10},"block_id":103},{"move":{"x":4,"y":1,"z":10},"block_id":103},{"move":{"x":4,"y":2,"z":10},"block_id":103},{"move":{"x":4,"y":2,"z":11},"block_id":106,"rotate":{"x":2,"y":0,"z":0}},{"move":{"x":4,"y":3,"z":1},"block_id":103},{"move":{"x":4,"y":3,"z":10},"block_id":103},{"move":{"x":4,"y":3,"z":11},"block_id":106,"rotate":{"x":2,"y":0,"z":0}},{"move":{"x":4,"y":4,"z":1},"block_id":103},{"move":{"x":4,"y":4,"z":9},"block_id":30},{"move":{"x":4,"y":4,"z":10},"block_id":103},{"move":{"x":4,"y":5,"z":1},"block_id":615,"extra_data":{"point":{"x":0,"y":0.1,"z":0}},"rotate":{"x":0,"y":0,"z":0}},{"move":{"x":4,"y":5,"z":2},"block_id":98},{"move":{"x":4,"y":5,"z":3},"block_id":98},{"move":{"x":4,"y":5,"z":4},"block_id":98},{"move":{"x":4,"y":5,"z":5},"block_id":83},{"move":{"x":4,"y":5,"z":6},"block_id":83},{"move":{"x":4,"y":5,"z":7},"block_id":98},{"move":{"x":4,"y":5,"z":8},"block_id":98},{"move":{"x":4,"y":5,"z":9},"block_id":98},{"move":{"x":4,"y":5,"z":10},"block_id":615,"extra_data":{"point":{"x":0,"y":0.1,"z":0}},"rotate":{"x":2,"y":0,"z":0}},{"move":{"x":4,"y":6,"z":2},"block_id":83},{"move":{"x":4,"y":6,"z":3},"block_id":632},{"move":{"x":4,"y":6,"z":4},"block_id":98},{"move":{"x":4,"y":6,"z":5},"block_id":90},{"move":{"x":4,"y":6,"z":6},"block_id":90},{"move":{"x":4,"y":6,"z":7},"block_id":98},{"move":{"x":4,"y":6,"z":8},"block_id":83},{"move":{"x":4,"y":6,"z":9},"block_id":83},{"move":{"x":4,"y":7,"z":2},"block_id":90},{"move":{"x":4,"y":7,"z":3},"block_id":90},{"move":{"x":4,"y":7,"z":4},"block_id":90},{"move":{"x":4,"y":7,"z":5},"block_id":90},{"move":{"x":4,"y":7,"z":6},"block_id":90},{"move":{"x":4,"y":7,"z":7},"block_id":90},{"move":{"x":4,"y":8,"z":2},"block_id":103},{"move":{"x":4,"y":8,"z":3},"block_id":615,"extra_data":{"point":{"x":0,"y":0.1,"z":0}},"rotate":{"x":1,"y":0,"z":0}},{"move":{"x":4,"y":8,"z":4},"block_id":615,"extra_data":{"point":{"x":0,"y":0.1,"z":0}},"rotate":{"x":1,"y":0,"z":0}},{"move":{"x":4,"y":8,"z":5},"block_id":615,"extra_data":{"point":{"x":0,"y":0.1,"z":0}},"rotate":{"x":1,"y":0,"z":0}},{"move":{"x":4,"y":8,"z":6},"block_id":615,"extra_data":{"point":{"x":0,"y":0.1,"z":0}},"rotate":{"x":1,"y":0,"z":0}},{"move":{"x":4,"y":8,"z":7},"block_id":615,"extra_data":{"point":{"x":0,"y":0.1,"z":0}},"rotate":{"x":1,"y":0,"z":0}},{"move":{"x":4,"y":8,"z":8},"block_id":615,"extra_data":{"point":{"x":0,"y":0.1,"z":0}},"rotate":{"x":1,"y":0,"z":0}},{"move":{"x":4,"y":8,"z":9},"block_id":103},{"move":{"x":4,"y":9,"z":2},"block_id":83},{"move":{"x":4,"y":9,"z":3},"block_id":632},{"move":{"x":4,"y":9,"z":4},"block_id":632},{"move":{"x":4,"y":9,"z":5},"block_id":615,"extra_data":{"point":{"x":0,"y":0.1,"z":0}},"rotate":{"x":2,"y":0,"z":0}},{"move":{"x":4,"y":9,"z":8},"block_id":632},{"move":{"x":4,"y":9,"z":9},"block_id":632},{"move":{"x":4,"y":10,"z":2},"block_id":615,"extra_data":{"point":{"x":0,"y":0.9,"z":0}},"rotate":{"x":1,"y":0,"z":0}},{"move":{"x":4,"y":10,"z":3},"block_id":615,"extra_data":{"point":{"x":0,"y":0.9,"z":0}},"rotate":{"x":1,"y":0,"z":0}},{"move":{"x":4,"y":10,"z":4},"block_id":98},{"move":{"x":4,"y":10,"z":5},"block_id":615,"extra_data":{"point":{"x":0,"y":0.9,"z":0}},"rotate":{"x":2,"y":0,"z":0}},{"move":{"x":4,"y":10,"z":8},"block_id":615,"extra_data":{"point":{"x":0,"y":0.9,"z":0}},"rotate":{"x":1,"y":0,"z":0}},{"move":{"x":4,"y":10,"z":9},"block_id":615,"extra_data":{"point":{"x":0,"y":0.9,"z":0}},"rotate":{"x":2,"y":0,"z":0}},{"move":{"x":4,"y":11,"z":2},"block_id":615,"extra_data":{"point":{"x":0,"y":0.1,"z":0}},"rotate":{"x":0,"y":0,"z":0}},{"move":{"x":4,"y":11,"z":3},"block_id":615,"extra_data":{"point":{"x":0,"y":0.1,"z":0}},"rotate":{"x":1,"y":0,"z":0}},{"move":{"x":4,"y":11,"z":4},"block_id":632},{"move":{"x":4,"y":11,"z":5},"block_id":615,"extra_data":{"point":{"x":0,"y":0.9,"z":0}},"rotate":{"x":1,"y":0,"z":0}},{"move":{"x":4,"y":11,"z":7},"block_id":83},{"move":{"x":4,"y":11,"z":8},"block_id":615,"extra_data":{"point":{"x":0,"y":0.1,"z":0}},"rotate":{"x":1,"y":0,"z":0}},{"move":{"x":4,"y":11,"z":9},"block_id":615,"extra_data":{"point":{"x":0,"y":0.1,"z":0}},"rotate":{"x":1,"y":0,"z":0}},{"move":{"x":4,"y":12,"z":2},"block_id":615,"extra_data":{"point":{"x":0,"y":0.9,"z":0}},"rotate":{"x":1,"y":0,"z":0}},{"move":{"x":4,"y":12,"z":3},"block_id":615,"extra_data":{"point":{"x":0,"y":0.9,"z":0}},"rotate":{"x":1,"y":0,"z":0}},{"move":{"x":4,"y":12,"z":4},"block_id":632},{"move":{"x":4,"y":12,"z":5},"block_id":90},{"move":{"x":4,"y":12,"z":7},"block_id":83},{"move":{"x":4,"y":12,"z":8},"block_id":615,"extra_data":{"point":{"x":0,"y":0.9,"z":0}},"rotate":{"x":1,"y":0,"z":0}},{"move":{"x":4,"y":12,"z":9},"block_id":615,"extra_data":{"point":{"x":0,"y":0.9,"z":0}},"rotate":{"x":2,"y":0,"z":0}},{"move":{"x":4,"y":13,"z":2},"block_id":103},{"move":{"x":4,"y":13,"z":3},"block_id":615,"extra_data":{"point":{"x":0,"y":0.9,"z":0}},"rotate":{"x":1,"y":0,"z":0}},{"move":{"x":4,"y":13,"z":4},"block_id":615,"extra_data":{"point":{"x":0,"y":0.9,"z":0}},"rotate":{"x":1,"y":0,"z":0}},{"move":{"x":4,"y":13,"z":5},"block_id":90},{"move":{"x":4,"y":13,"z":6},"block_id":90},{"move":{"x":4,"y":13,"z":7},"block_id":615,"extra_data":{"point":{"x":0,"y":0.9,"z":0}},"rotate":{"x":1,"y":0,"z":0}},{"move":{"x":4,"y":13,"z":8},"block_id":615,"extra_data":{"point":{"x":0,"y":0.9,"z":0}},"rotate":{"x":1,"y":0,"z":0}},{"move":{"x":4,"y":13,"z":9},"block_id":103},{"move":{"x":4,"y":14,"z":2},"block_id":615,"extra_data":{"point":{"x":0,"y":0.1,"z":0}},"rotate":{"x":1,"y":0,"z":0}},{"move":{"x":4,"y":14,"z":3},"block_id":615,"extra_data":{"point":{"x":0,"y":0.1,"z":0}},"rotate":{"x":1,"y":0,"z":0}},{"move":{"x":4,"y":14,"z":4},"block_id":615,"extra_data":{"point":{"x":0,"y":0.1,"z":0}},"rotate":{"x":1,"y":0,"z":0}},{"move":{"x":4,"y":14,"z":5},"block_id":90},{"move":{"x":4,"y":14,"z":6},"block_id":90},{"move":{"x":4,"y":14,"z":7},"block_id":615,"extra_data":{"point":{"x":0,"y":0.1,"z":0}},"rotate":{"x":1,"y":0,"z":0}},{"move":{"x":4,"y":14,"z":8},"block_id":615,"extra_data":{"point":{"x":0,"y":0.1,"z":0}},"rotate":{"x":1,"y":0,"z":0}},{"move":{"x":4,"y":14,"z":9},"block_id":615,"extra_data":{"point":{"x":0,"y":0.1,"z":0}},"rotate":{"x":2,"y":0,"z":0}},{"move":{"x":4,"y":15,"z":7},"block_id":106,"rotate":{"x":1,"y":0,"z":0}},{"move":{"x":4,"y":16,"z":7},"block_id":106,"rotate":{"x":1,"y":0,"z":0}},{"move":{"x":4,"y":18,"z":7},"block_id":106,"rotate":{"x":1,"y":0,"z":0}},{"move":{"x":4,"y":19,"z":7},"block_id":106,"rotate":{"x":1,"y":0,"z":0}},{"move":{"x":4,"y":20,"z":7},"block_id":106,"rotate":{"x":1,"y":0,"z":0}},{"move":{"x":4,"y":21,"z":7},"block_id":106,"rotate":{"x":1,"y":0,"z":0}},{"move":{"x":4,"y":22,"z":7},"block_id":106,"rotate":{"x":1,"y":0,"z":0}},{"move":{"x":5,"y":-1,"z":0},"block_id":2},{"move":{"x":5,"y":-1,"z":1},"block_id":98},{"move":{"x":5,"y":-1,"z":2},"block_id":98},{"move":{"x":5,"y":-1,"z":3},"block_id":98},{"move":{"x":5,"y":-1,"z":4},"block_id":2},{"move":{"x":5,"y":-1,"z":5},"block_id":103},{"move":{"x":5,"y":-1,"z":6},"block_id":2},{"move":{"x":5,"y":-1,"z":7},"block_id":2},{"move":{"x":5,"y":-1,"z":8},"block_id":98},{"move":{"x":5,"y":-1,"z":9},"block_id":98},{"move":{"x":5,"y":-1,"z":10},"block_id":98},{"move":{"x":5,"y":-1,"z":11},"block_id":632},{"move":{"x":5,"y":0,"z":1},"block_id":632},{"move":{"x":5,"y":0,"z":2},"block_id":103},{"move":{"x":5,"y":0,"z":8},"block_id":632},{"move":{"x":5,"y":0,"z":9},"block_id":103},{"move":{"x":5,"y":0,"z":10},"block_id":632},{"move":{"x":5,"y":0,"z":11},"block_id":83},{"move":{"x":5,"y":1,"z":1},"block_id":103},{"move":{"x":5,"y":1,"z":2},"block_id":103},{"move":{"x":5,"y":1,"z":3},"block_id":103},{"move":{"x":5,"y":1,"z":4},"block_id":98},{"move":{"x":5,"y":1,"z":8},"block_id":103},{"move":{"x":5,"y":1,"z":9},"block_id":103},{"move":{"x":5,"y":1,"z":10},"block_id":103},{"move":{"x":5,"y":2,"z":1},"block_id":98},{"move":{"x":5,"y":2,"z":2},"block_id":103},{"move":{"x":5,"y":2,"z":3},"block_id":83},{"move":{"x":5,"y":2,"z":4},"block_id":83},{"move":{"x":5,"y":2,"z":5},"block_id":615,"extra_data":{"point":{"x":0,"y":0.9,"z":0}},"rotate":{"x":3,"y":0,"z":0}},{"move":{"x":5,"y":2,"z":6},"block_id":615,"extra_data":{"point":{"x":0,"y":0.9,"z":0}},"rotate":{"x":3,"y":0,"z":0}},{"move":{"x":5,"y":2,"z":7},"block_id":83},{"move":{"x":5,"y":2,"z":8},"block_id":83},{"move":{"x":5,"y":2,"z":9},"block_id":103},{"move":{"x":5,"y":2,"z":10},"block_id":83},{"move":{"x":5,"y":3,"z":1},"block_id":103},{"move":{"x":5,"y":3,"z":2},"block_id":103},{"move":{"x":5,"y":3,"z":3},"block_id":103},{"move":{"x":5,"y":3,"z":4},"block_id":98},{"move":{"x":5,"y":3,"z":5},"block_id":615,"extra_data":{"point":{"x":0,"y":0.1,"z":0}},"rotate":{"x":2,"y":0,"z":0}},{"move":{"x":5,"y":3,"z":6},"block_id":615,"extra_data":{"point":{"x":0,"y":0.1,"z":0}},"rotate":{"x":0,"y":0,"z":0}},{"move":{"x":5,"y":3,"z":7},"block_id":83},{"move":{"x":5,"y":3,"z":8},"block_id":103},{"move":{"x":5,"y":3,"z":9},"block_id":103},{"move":{"x":5,"y":3,"z":10},"block_id":103},{"move":{"x":5,"y":4,"z":1},"block_id":98},{"move":{"x":5,"y":4,"z":2},"block_id":103},{"move":{"x":5,"y":4,"z":3},"block_id":98},{"move":{"x":5,"y":4,"z":4},"block_id":98},{"move":{"x":5,"y":4,"z":5},"block_id":615,"extra_data":{"point":{"x":0,"y":0.9,"z":0}},"rotate":{"x":2,"y":0,"z":0}},{"move":{"x":5,"y":4,"z":6},"block_id":615,"extra_data":{"point":{"x":0,"y":0.9,"z":0}},"rotate":{"x":0,"y":0,"z":0}},{"move":{"x":5,"y":4,"z":7},"block_id":98},{"move":{"x":5,"y":4,"z":8},"block_id":30},{"move":{"x":5,"y":4,"z":9},"block_id":103},{"move":{"x":5,"y":4,"z":10},"block_id":83},{"move":{"x":5,"y":5,"z":1},"block_id":615,"extra_data":{"point":{"x":0,"y":0.1,"z":0}},"rotate":{"x":1,"y":0,"z":0}},{"move":{"x":5,"y":5,"z":2},"block_id":615,"extra_data":{"point":{"x":0,"y":0.1,"z":0}},"rotate":{"x":1,"y":0,"z":0}},{"move":{"x":5,"y":5,"z":3},"block_id":615,"extra_data":{"point":{"x":0,"y":0.1,"z":0}},"rotate":{"x":1,"y":0,"z":0}},{"move":{"x":5,"y":5,"z":4},"block_id":101,"extra_data":{"point":{"x":0,"y":0.9,"z":0}}},{"move":{"x":5,"y":5,"z":5},"block_id":98},{"move":{"x":5,"y":5,"z":6},"block_id":98},{"move":{"x":5,"y":5,"z":7},"block_id":101,"extra_data":{"point":{"x":0,"y":0.9,"z":0}}},{"move":{"x":5,"y":5,"z":8},"block_id":615,"extra_data":{"point":{"x":0,"y":0.1,"z":0}},"rotate":{"x":1,"y":0,"z":0}},{"move":{"x":5,"y":5,"z":9},"block_id":615,"extra_data":{"point":{"x":0,"y":0.1,"z":0}},"rotate":{"x":1,"y":0,"z":0}},{"move":{"x":5,"y":5,"z":10},"block_id":615,"extra_data":{"point":{"x":0,"y":0.1,"z":0}},"rotate":{"x":2,"y":0,"z":0}},{"move":{"x":5,"y":6,"z":4},"block_id":101,"extra_data":{"point":{"x":0,"y":0.1,"z":0}}},{"move":{"x":5,"y":6,"z":5},"block_id":615,"extra_data":{"point":{"x":0,"y":0.1,"z":0}},"rotate":{"x":0,"y":0,"z":0}},{"move":{"x":5,"y":6,"z":6},"block_id":615,"extra_data":{"point":{"x":0,"y":0.1,"z":0}},"rotate":{"x":2,"y":0,"z":0}},{"move":{"x":5,"y":6,"z":7},"block_id":101,"extra_data":{"point":{"x":0,"y":0.1,"z":0}}},{"move":{"x":5,"y":12,"z":5},"block_id":106,"rotate":{"x":1,"y":0,"z":0}},{"move":{"x":5,"y":13,"z":5},"block_id":106,"rotate":{"x":1,"y":0,"z":0}},{"move":{"x":5,"y":14,"z":5},"block_id":106,"rotate":{"x":1,"y":0,"z":0}},{"move":{"x":6,"y":-1,"z":0},"block_id":18},{"move":{"x":6,"y":-1,"z":1},"block_id":18},{"move":{"x":6,"y":-1,"z":2},"block_id":2},{"move":{"x":6,"y":-1,"z":3},"block_id":632},{"move":{"x":6,"y":-1,"z":4},"block_id":632},{"move":{"x":6,"y":-1,"z":5},"block_id":2},{"move":{"x":6,"y":-1,"z":6},"block_id":2},{"move":{"x":6,"y":-1,"z":7},"block_id":2},{"move":{"x":6,"y":-1,"z":8},"block_id":632},{"move":{"x":6,"y":-1,"z":9},"block_id":18},{"move":{"x":6,"y":-1,"z":10},"block_id":2},{"move":{"x":6,"y":-1,"z":11},"block_id":632},{"move":{"x":6,"y":0,"z":0},"block_id":8},{"move":{"x":6,"y":0,"z":1},"block_id":8},{"move":{"x":6,"y":0,"z":9},"block_id":8},{"move":{"x":6,"y":0,"z":11},"block_id":83},{"move":{"x":6,"y":1,"z":0},"block_id":8},{"move":{"x":6,"y":1,"z":4},"block_id":632},{"move":{"x":6,"y":2,"z":4},"block_id":98},{"move":{"x":6,"y":2,"z":5},"block_id":90},{"move":{"x":6,"y":2,"z":6},"block_id":90},{"move":{"x":6,"y":2,"z":7},"block_id":83},{"move":{"x":6,"y":2,"z":8},"block_id":106,"rotate":{"x":2,"y":0,"z":0}},{"move":{"x":6,"y":3,"z":4},"block_id":632},{"move":{"x":6,"y":3,"z":5},"block_id":90},{"move":{"x":6,"y":3,"z":6},"block_id":90},{"move":{"x":6,"y":3,"z":7},"block_id":83},{"move":{"x":6,"y":3,"z":8},"block_id":106,"rotate":{"x":2,"y":0,"z":0}},{"move":{"x":6,"y":4,"z":4},"block_id":98},{"move":{"x":6,"y":4,"z":5},"block_id":90},{"move":{"x":6,"y":4,"z":6},"block_id":90},{"move":{"x":6,"y":4,"z":7},"block_id":83},{"move":{"x":6,"y":4,"z":8},"block_id":106,"rotate":{"x":2,"y":0,"z":0}},{"move":{"x":6,"y":5,"z":4},"block_id":615,"extra_data":{"point":{"x":0,"y":0.1,"z":0}},"rotate":{"x":0,"y":0,"z":0}},{"move":{"x":6,"y":5,"z":5},"block_id":615,"extra_data":{"point":{"x":0,"y":0.1,"z":0}},"rotate":{"x":1,"y":0,"z":0}},{"move":{"x":6,"y":5,"z":6},"block_id":615,"extra_data":{"point":{"x":0,"y":0.1,"z":0}},"rotate":{"x":1,"y":0,"z":0}},{"move":{"x":6,"y":5,"z":7},"block_id":615,"extra_data":{"point":{"x":0,"y":0.1,"z":0}},"rotate":{"x":2,"y":0,"z":0}}],"rot":[]}