{"name":"sand_house_2","world":{"pos1":{"x":-224,"y":0,"z":2},"pos2":{"x":-232,"y":8,"z":-6},"entrance":{"x":-228,"y":1,"z":2}},"meta":{},"size":{"x":9,"y":9,"z":9},"door_pos":{"x":4,"y":1,"z":0},"blocks":[{"move":{"x":-4,"y":-1,"z":1},"block_id":2},{"move":{"x":-4,"y":-1,"z":2},"block_id":2},{"move":{"x":-4,"y":-1,"z":3},"block_id":2},{"move":{"x":-4,"y":-1,"z":4},"block_id":2},{"move":{"x":-4,"y":-1,"z":5},"block_id":2},{"move":{"x":-4,"y":-1,"z":6},"block_id":2},{"move":{"x":-4,"y":-1,"z":7},"block_id":2},{"move":{"x":-4,"y":-1,"z":8},"block_id":2},{"move":{"x":-4,"y":2,"z":1},"block_id":774,"extra_data":{"pressed":0},"rotate":{"x":13,"y":0,"z":0}},{"move":{"x":-4,"y":2,"z":4},"block_id":774,"extra_data":{"pressed":0},"rotate":{"x":13,"y":0,"z":0}},{"move":{"x":-4,"y":2,"z":7},"block_id":774,"extra_data":{"pressed":0},"rotate":{"x":13,"y":0,"z":0}},{"move":{"x":-3,"y":-1,"z":0},"block_id":2},{"move":{"x":-3,"y":-1,"z":1},"block_id":24},{"move":{"x":-3,"y":-1,"z":2},"block_id":24},{"move":{"x":-3,"y":-1,"z":3},"block_id":24},{"move":{"x":-3,"y":-1,"z":4},"block_id":24},{"move":{"x":-3,"y":-1,"z":5},"block_id":24},{"move":{"x":-3,"y":-1,"z":6},"block_id":24},{"move":{"x":-3,"y":-1,"z":7},"block_id":24},{"move":{"x":-3,"y":-1,"z":8},"block_id":2},{"move":{"x":-3,"y":0,"z":1},"block_id":577},{"move":{"x":-3,"y":0,"z":2},"block_id":24},{"move":{"x":-3,"y":0,"z":3},"block_id":24},{"move":{"x":-3,"y":0,"z":4},"block_id":24},{"move":{"x":-3,"y":0,"z":5},"block_id":24},{"move":{"x":-3,"y":0,"z":6},"block_id":24},{"move":{"x":-3,"y":0,"z":7},"block_id":577},{"move":{"x":-3,"y":1,"z":1},"block_id":577},{"move":{"x":-3,"y":1,"z":2},"block_id":24},{"move":{"x":-3,"y":1,"z":3},"block_id":24},{"move":{"x":-3,"y":1,"z":4},"block_id":537},{"move":{"x":-3,"y":1,"z":5},"block_id":24},{"move":{"x":-3,"y":1,"z":6},"block_id":24},{"move":{"x":-3,"y":1,"z":7},"block_id":577},{"move":{"x":-3,"y":2,"z":0},"block_id":774,"extra_data":{"pressed":0},"rotate":{"x":18,"y":0,"z":0}},{"move":{"x":-3,"y":2,"z":1},"block_id":123},{"move":{"x":-3,"y":2,"z":2},"block_id":123},{"move":{"x":-3,"y":2,"z":3},"block_id":123},{"move":{"x":-3,"y":2,"z":4},"block_id":123},{"move":{"x":-3,"y":2,"z":5},"block_id":123},{"move":{"x":-3,"y":2,"z":6},"block_id":123},{"move":{"x":-3,"y":2,"z":7},"block_id":123},{"move":{"x":-3,"y":2,"z":8},"block_id":774,"extra_data":{"pressed":0},"rotate":{"x":7,"y":0,"z":0}},{"move":{"x":-3,"y":3,"z":1},"block_id":174},{"move":{"x":-3,"y":3,"z":2},"block_id":175,"extra_data":{"point":{"x":0.6222788956743273,"y":0,"z":0.5322027049668946}}},{"move":{"x":-3,"y":3,"z":3},"block_id":174},{"move":{"x":-3,"y":3,"z":4},"block_id":175,"extra_data":{"point":{"x":0.4014954163143898,"y":0,"z":0.3498110338313176}}},{"move":{"x":-3,"y":3,"z":5},"block_id":174},{"move":{"x":-3,"y":3,"z":6},"block_id":175,"extra_data":{"point":{"x":0.5689473750942682,"y":0,"z":0.40971583219975116}}},{"move":{"x":-3,"y":3,"z":7},"block_id":174},{"move":{"x":-2,"y":-1,"z":0},"block_id":2},{"move":{"x":-2,"y":-1,"z":1},"block_id":24},{"move":{"x":-2,"y":-1,"z":2},"block_id":2},{"move":{"x":-2,"y":-1,"z":3},"block_id":2},{"move":{"x":-2,"y":-1,"z":4},"block_id":2},{"move":{"x":-2,"y":-1,"z":5},"block_id":2},{"move":{"x":-2,"y":-1,"z":6},"block_id":2},{"move":{"x":-2,"y":-1,"z":7},"block_id":24},{"move":{"x":-2,"y":-1,"z":8},"block_id":2},{"move":{"x":-2,"y":0,"z":1},"block_id":24},{"move":{"x":-2,"y":0,"z":2},"block_id":322,"extra_data":{"frame":"spruce_log"},"rotate":{"x":180,"y":1,"z":0}},{"move":{"x":-2,"y":0,"z":6},"block_id":305,"extra_data":{"frame":"dark_oak_log","is_head":false},"rotate":{"x":315,"y":1,"z":0}},{"move":{"x":-2,"y":0,"z":7},"block_id":24},{"move":{"x":-2,"y":1,"z":1},"block_id":24},{"move":{"x":-2,"y":1,"z":6},"block_id":305,"extra_data":{"frame":"dark_oak_log","is_head":true},"rotate":{"x":315,"y":1,"z":0}},{"move":{"x":-2,"y":1,"z":7},"block_id":24},{"move":{"x":-2,"y":2,"z":1},"block_id":123},{"move":{"x":-2,"y":2,"z":2},"block_id":208,"extra_data":{"point":{"x":-0.0020000000000095497,"y":0.6864029411017039,"z":0.26270131907991506}}},{"move":{"x":-2,"y":2,"z":3},"block_id":208,"extra_data":{"point":{"x":-0.0020000000000095497,"y":0.6885138206326231,"z":0.4615552407163044}}},{"move":{"x":-2,"y":2,"z":4},"block_id":208,"extra_data":{"point":{"x":-0.0020000000000095497,"y":0.6682111615912212,"z":0.23548421116592855}}},{"move":{"x":-2,"y":2,"z":5},"block_id":208,"extra_data":{"point":{"x":-0.0020000000000095497,"y":0.6654657625540512,"z":0.40181907709281184}}},{"move":{"x":-2,"y":2,"z":6},"block_id":208,"extra_data":{"point":{"x":0.20899562657643855,"y":0.7626336639049978,"z":1.0019999999999998}}},{"move":{"x":-2,"y":2,"z":7},"block_id":123},{"move":{"x":-2,"y":3,"z":1},"block_id":175,"extra_data":{"point":{"x":0.8662749572859809,"y":0,"z":0.6371242890388176}}},{"move":{"x":-2,"y":3,"z":7},"block_id":175,"extra_data":{"point":{"x":0.748558870541757,"y":0,"z":0.9669635983384133}}},{"move":{"x":-2,"y":5,"z":4},"block_id":774,"extra_data":{"pressed":0},"rotate":{"x":13,"y":0,"z":0}},{"move":{"x":-2,"y":5,"z":7},"block_id":774,"extra_data":{"pressed":0},"rotate":{"x":13,"y":0,"z":0}},{"move":{"x":-1,"y":-1,"z":0},"block_id":2},{"move":{"x":-1,"y":-1,"z":1},"block_id":18,"extra_data":{"max_ticks":342}},{"move":{"x":-1,"y":-1,"z":2},"block_id":2},{"move":{"x":-1,"y":-1,"z":3},"block_id":2},{"move":{"x":-1,"y":-1,"z":4},"block_id":2},{"move":{"x":-1,"y":-1,"z":5},"block_id":2},{"move":{"x":-1,"y":-1,"z":6},"block_id":2},{"move":{"x":-1,"y":-1,"z":7},"block_id":24},{"move":{"x":-1,"y":-1,"z":8},"block_id":2},{"move":{"x":-1,"y":0,"z":0},"block_id":537},{"move":{"x":-1,"y":0,"z":1},"block_id":24},{"move":{"x":-1,"y":0,"z":7},"block_id":24},{"move":{"x":-1,"y":1,"z":0},"block_id":537},{"move":{"x":-1,"y":1,"z":1},"block_id":24},{"move":{"x":-1,"y":1,"z":7},"block_id":24},{"move":{"x":-1,"y":2,"z":0},"block_id":539,"extra_data":{"point":{"x":0.5260702931964261,"y":0.32525915855039367,"z":1.0019999999999998}}},{"move":{"x":-1,"y":2,"z":1},"block_id":123},{"move":{"x":-1,"y":2,"z":2},"block_id":208,"extra_data":{"point":{"x":-0.0020000000000095497,"y":0.8551328536848017,"z":0.527142624968161}}},{"move":{"x":-1,"y":2,"z":3},"block_id":208,"extra_data":{"point":{"x":-0.0020000000000095497,"y":0.7129652842610636,"z":0.39082161635521406}}},{"move":{"x":-1,"y":2,"z":4},"block_id":208,"extra_data":{"point":{"x":-0.0020000000000095497,"y":0.5877078180098678,"z":0.31156160092335883}}},{"move":{"x":-1,"y":2,"z":5},"block_id":208,"extra_data":{"point":{"x":-0.0020000000000095497,"y":0.6973798290589412,"z":0.4898626594802593}}},{"move":{"x":-1,"y":2,"z":6},"block_id":208,"extra_data":{"point":{"x":0.30636059068106647,"y":0.845073565908459,"z":1.0019999999999998}}},{"move":{"x":-1,"y":2,"z":7},"block_id":123},{"move":{"x":-1,"y":3,"z":1},"block_id":174},{"move":{"x":-1,"y":3,"z":4},"block_id":577},{"move":{"x":-1,"y":3,"z":5},"block_id":24},{"move":{"x":-1,"y":3,"z":6},"block_id":24},{"move":{"x":-1,"y":3,"z":7},"block_id":577},{"move":{"x":-1,"y":4,"z":4},"block_id":577},{"move":{"x":-1,"y":4,"z":5},"block_id":24},{"move":{"x":-1,"y":4,"z":6},"block_id":24},{"move":{"x":-1,"y":4,"z":7},"block_id":577},{"move":{"x":-1,"y":5,"z":3},"block_id":774,"extra_data":{"pressed":0},"rotate":{"x":18,"y":0,"z":0}},{"move":{"x":-1,"y":5,"z":4},"block_id":123},{"move":{"x":-1,"y":5,"z":5},"block_id":123},{"move":{"x":-1,"y":5,"z":6},"block_id":123},{"move":{"x":-1,"y":5,"z":7},"block_id":123},{"move":{"x":-1,"y":5,"z":8},"block_id":774,"extra_data":{"pressed":0},"rotate":{"x":7,"y":0,"z":0}},{"move":{"x":-1,"y":6,"z":4},"block_id":174},{"move":{"x":-1,"y":6,"z":5},"block_id":176,"extra_data":{"point":{"x":0.5344392051623288,"y":0,"z":0.36553175466274146}},"rotate":{"x":0,"y":1,"z":0}},{"move":{"x":-1,"y":6,"z":6},"block_id":176,"extra_data":{"point":{"x":0.5849303500607732,"y":0,"z":0.877387855906929}},"rotate":{"x":2,"y":1,"z":0}},{"move":{"x":-1,"y":6,"z":7},"block_id":174},{"move":{"x":0,"y":-1,"z":0},"block_id":2},{"move":{"x":0,"y":-1,"z":1},"block_id":2},{"move":{"x":0,"y":-1,"z":2},"block_id":2},{"move":{"x":0,"y":-1,"z":3},"block_id":2},{"move":{"x":0,"y":-1,"z":4},"block_id":2},{"move":{"x":0,"y":-1,"z":5},"block_id":2},{"move":{"x":0,"y":-1,"z":6},"block_id":2},{"move":{"x":0,"y":-1,"z":7},"block_id":24},{"move":{"x":0,"y":-1,"z":8},"block_id":2},{"move":{"x":0,"y":0,"z":1},"block_id":580,"extra_data":{"point":{"x":0.33041294529360243,"y":0,"z":0.3639590192868196},"opened":false,"left":false,"is_head":false},"rotate":{"x":0,"y":1,"z":0}},{"move":{"x":0,"y":0,"z":7},"block_id":24},{"move":{"x":0,"y":1,"z":1},"block_id":580,"extra_data":{"point":{"x":0.33041294529360243,"y":0,"z":0.3639590192868196},"opened":false,"left":false,"is_head":true},"rotate":{"x":0,"y":1,"z":0}},{"move":{"x":0,"y":1,"z":7},"block_id":537},{"move":{"x":0,"y":2,"z":0},"block_id":539,"extra_data":{"point":{"x":0.3033844554788345,"y":0.8840233582074752,"z":1.0019999999999998}}},{"move":{"x":0,"y":2,"z":1},"block_id":123},{"move":{"x":0,"y":2,"z":2},"block_id":208,"extra_data":{"point":{"x":-0.0020000000000095497,"y":0.8166679832996806,"z":0.5271761662633778}}},{"move":{"x":0,"y":2,"z":3},"block_id":208,"extra_data":{"point":{"x":-0.0020000000000095497,"y":0.7927754268604197,"z":0.45975975766021204}}},{"move":{"x":0,"y":2,"z":4},"block_id":208,"extra_data":{"point":{"x":-0.0020000000000095497,"y":0.7081722704701536,"z":0.6280364646513708}}},{"move":{"x":0,"y":2,"z":5},"block_id":208,"extra_data":{"point":{"x":-0.0020000000000095497,"y":0.6457697952521504,"z":0.5557592365925799}}},{"move":{"x":0,"y":2,"z":6},"block_id":208,"extra_data":{"point":{"x":0.07405833639683124,"y":0.751759266269242,"z":1.0019999999999998}}},{"move":{"x":0,"y":2,"z":7},"block_id":123},{"move":{"x":0,"y":2,"z":8},"block_id":774,"extra_data":{"pressed":0},"rotate":{"x":7,"y":0,"z":0}},{"move":{"x":0,"y":3,"z":1},"block_id":175,"extra_data":{"point":{"x":0.3986583729181632,"y":0,"z":0.8295124137261105}}},{"move":{"x":0,"y":3,"z":4},"block_id":24},{"move":{"x":0,"y":3,"z":7},"block_id":24},{"move":{"x":0,"y":4,"z":4},"block_id":24},{"move":{"x":0,"y":4,"z":6},"block_id":50,"rotate":{"x":0,"y":0,"z":0}},{"move":{"x":0,"y":4,"z":7},"block_id":24},{"move":{"x":0,"y":5,"z":4},"block_id":123},{"move":{"x":0,"y":5,"z":5},"block_id":208,"extra_data":{"point":{"x":1.0020000000000095,"y":0.8592641576319986,"z":0.5532634614521035}}},{"move":{"x":0,"y":5,"z":6},"block_id":208,"extra_data":{"point":{"x":-0.0020000000000095497,"y":0.5719449888099932,"z":0.2871544412312588}}},{"move":{"x":0,"y":5,"z":7},"block_id":123},{"move":{"x":0,"y":6,"z":4},"block_id":175,"extra_data":{"point":{"x":0.30369935913469703,"y":0,"z":0.5293123953457202}}},{"move":{"x":0,"y":6,"z":6},"block_id":52,"extra_data":{"can_destroy":true,"slots":{}},"rotate":{"x":0,"y":1,"z":0}},{"move":{"x":0,"y":6,"z":7},"block_id":175,"extra_data":{"point":{"x":0.4155258712273451,"y":0,"z":0.45299161895484374}}},{"move":{"x":1,"y":-1,"z":0},"block_id":2},{"move":{"x":1,"y":-1,"z":1},"block_id":24},{"move":{"x":1,"y":-1,"z":2},"block_id":2},{"move":{"x":1,"y":-1,"z":3},"block_id":2},{"move":{"x":1,"y":-1,"z":4},"block_id":2},{"move":{"x":1,"y":-1,"z":5},"block_id":2},{"move":{"x":1,"y":-1,"z":6},"block_id":2},{"move":{"x":1,"y":-1,"z":7},"block_id":24},{"move":{"x":1,"y":-1,"z":8},"block_id":2},{"move":{"x":1,"y":0,"z":0},"block_id":537},{"move":{"x":1,"y":0,"z":1},"block_id":24},{"move":{"x":1,"y":0,"z":2},"block_id":461,"extra_data":{"point":{"x":0.5719027580385614,"y":0.8308262156105257,"z":-0.0020000000000000018}}},{"move":{"x":1,"y":0,"z":7},"block_id":24},{"move":{"x":1,"y":1,"z":0},"block_id":537},{"move":{"x":1,"y":1,"z":1},"block_id":24},{"move":{"x":1,"y":1,"z":7},"block_id":24},{"move":{"x":1,"y":2,"z":0},"block_id":539,"extra_data":{"point":{"x":0.6930546872480079,"y":0.322653783514006,"z":1.0019999999999998}}},{"move":{"x":1,"y":2,"z":1},"block_id":123},{"move":{"x":1,"y":2,"z":2},"block_id":208,"extra_data":{"point":{"x":-0.0020000000000095497,"y":0.6218163505990786,"z":0.2369117290388912}}},{"move":{"x":1,"y":2,"z":3},"block_id":208,"extra_data":{"point":{"x":-0.0020000000000095497,"y":0.6561939097944305,"z":0.3552092419428132}}},{"move":{"x":1,"y":2,"z":4},"block_id":208,"extra_data":{"point":{"x":-0.0020000000000095497,"y":0.6780337749810341,"z":0.40138542033580116}}},{"move":{"x":1,"y":2,"z":5},"block_id":208,"extra_data":{"point":{"x":0.6453803395799866,"y":0.8160738863182444,"z":1.0019999999999998}}},{"move":{"x":1,"y":2,"z":6},"block_id":208,"extra_data":{"point":{"x":0.39382849163212086,"y":0.6777609388629333,"z":1.0019999999999998}}},{"move":{"x":1,"y":2,"z":7},"block_id":123},{"move":{"x":1,"y":3,"z":1},"block_id":174},{"move":{"x":1,"y":3,"z":4},"block_id":580,"extra_data":{"point":{"x":0.6213914252838038,"y":0,"z":0.4710514258347831},"opened":false,"left":false,"is_head":false},"rotate":{"x":2,"y":1,"z":0}},{"move":{"x":1,"y":3,"z":7},"block_id":24},{"move":{"x":1,"y":4,"z":4},"block_id":580,"extra_data":{"point":{"x":0.6213914252838038,"y":0,"z":0.4710514258347831},"opened":false,"left":false,"is_head":true},"rotate":{"x":2,"y":1,"z":0}},{"move":{"x":1,"y":4,"z":7},"block_id":537},{"move":{"x":1,"y":5,"z":4},"block_id":123},{"move":{"x":1,"y":5,"z":5},"block_id":208,"extra_data":{"point":{"x":1.0020000000000095,"y":0.8980213292442603,"z":0.5611770925104187}}},{"move":{"x":1,"y":5,"z":6},"block_id":208,"extra_data":{"point":{"x":0.7165169478690245,"y":0.639180103539303,"z":1.0019999999999998}}},{"move":{"x":1,"y":5,"z":7},"block_id":123},{"move":{"x":1,"y":6,"z":4},"block_id":174},{"move":{"x":1,"y":6,"z":7},"block_id":174},{"move":{"x":2,"y":-1,"z":0},"block_id":2},{"move":{"x":2,"y":-1,"z":1},"block_id":24},{"move":{"x":2,"y":-1,"z":2},"block_id":2},{"move":{"x":2,"y":-1,"z":3},"block_id":2},{"move":{"x":2,"y":-1,"z":4},"block_id":2},{"move":{"x":2,"y":-1,"z":5},"block_id":2},{"move":{"x":2,"y":-1,"z":6},"block_id":2},{"move":{"x":2,"y":-1,"z":7},"block_id":24},{"move":{"x":2,"y":-1,"z":8},"block_id":2},{"move":{"x":2,"y":0,"z":1},"block_id":24},{"move":{"x":2,"y":0,"z":2},"block_id":1208,"extra_data":{"is_head":true},"rotate":{"x":2,"y":1,"z":0}},{"move":{"x":2,"y":0,"z":3},"block_id":1208,"extra_data":{"is_head":false},"rotate":{"x":2,"y":1,"z":0}},{"move":{"x":2,"y":0,"z":6},"block_id":65,"rotate":{"x":0,"y":0,"z":0}},{"move":{"x":2,"y":0,"z":7},"block_id":24},{"move":{"x":2,"y":1,"z":1},"block_id":537},{"move":{"x":2,"y":1,"z":5},"block_id":50,"rotate":{"x":3,"y":0,"z":0}},{"move":{"x":2,"y":1,"z":6},"block_id":65,"rotate":{"x":0,"y":0,"z":0}},{"move":{"x":2,"y":1,"z":7},"block_id":24},{"move":{"x":2,"y":2,"z":1},"block_id":123},{"move":{"x":2,"y":2,"z":2},"block_id":208,"extra_data":{"point":{"x":0.4909140921703852,"y":0.5767053903882857,"z":-0.0020000000000000018}}},{"move":{"x":2,"y":2,"z":3},"block_id":208,"extra_data":{"point":{"x":0.49602704637646866,"y":0.8554812035280337,"z":-0.002}}},{"move":{"x":2,"y":2,"z":4},"block_id":208,"extra_data":{"point":{"x":0.538803873004241,"y":0.6205878515389025,"z":-0.0020000000000000018}}},{"move":{"x":2,"y":2,"z":5},"block_id":208,"extra_data":{"point":{"x":1.0020000000000095,"y":0.5423602555126692,"z":0.1279041861230903}}},{"move":{"x":2,"y":2,"z":6},"block_id":65,"rotate":{"x":0,"y":0,"z":0}},{"move":{"x":2,"y":2,"z":7},"block_id":123},{"move":{"x":2,"y":3,"z":1},"block_id":175,"extra_data":{"point":{"x":0.41652562063984533,"y":0,"z":0.6078924671354831}}},{"move":{"x":2,"y":3,"z":3},"block_id":52,"extra_data":{"can_destroy":true,"slots":{}},"rotate":{"x":1,"y":1,"z":0}},{"move":{"x":2,"y":3,"z":4},"block_id":24},{"move":{"x":2,"y":3,"z":6},"block_id":65,"rotate":{"x":0,"y":0,"z":0}},{"move":{"x":2,"y":3,"z":7},"block_id":24},{"move":{"x":2,"y":4,"z":4},"block_id":24},{"move":{"x":2,"y":4,"z":6},"block_id":65,"rotate":{"x":0,"y":0,"z":0}},{"move":{"x":2,"y":4,"z":7},"block_id":24},{"move":{"x":2,"y":5,"z":4},"block_id":123},{"move":{"x":2,"y":5,"z":5},"block_id":208,"extra_data":{"point":{"x":1.0020000000000095,"y":0.541513987307515,"z":0.5607726635734687}}},{"move":{"x":2,"y":5,"z":6},"block_id":65,"rotate":{"x":0,"y":0,"z":0}},{"move":{"x":2,"y":5,"z":7},"block_id":123},{"move":{"x":2,"y":6,"z":4},"block_id":175,"extra_data":{"point":{"x":0.20073704509437107,"y":0,"z":0.4218021376297032}}},{"move":{"x":2,"y":6,"z":7},"block_id":175,"extra_data":{"point":{"x":0.4847449889491031,"y":0,"z":0.4334345075131596}}},{"move":{"x":3,"y":-1,"z":0},"block_id":2},{"move":{"x":3,"y":-1,"z":1},"block_id":24},{"move":{"x":3,"y":-1,"z":2},"block_id":24},{"move":{"x":3,"y":-1,"z":3},"block_id":24},{"move":{"x":3,"y":-1,"z":4},"block_id":24},{"move":{"x":3,"y":-1,"z":5},"block_id":24},{"move":{"x":3,"y":-1,"z":6},"block_id":24},{"move":{"x":3,"y":-1,"z":7},"block_id":24},{"move":{"x":3,"y":-1,"z":8},"block_id":2},{"move":{"x":3,"y":0,"z":1},"block_id":577},{"move":{"x":3,"y":0,"z":2},"block_id":24},{"move":{"x":3,"y":0,"z":3},"block_id":24},{"move":{"x":3,"y":0,"z":4},"block_id":24},{"move":{"x":3,"y":0,"z":5},"block_id":24},{"move":{"x":3,"y":0,"z":6},"block_id":24},{"move":{"x":3,"y":0,"z":7},"block_id":577},{"move":{"x":3,"y":1,"z":1},"block_id":577},{"move":{"x":3,"y":1,"z":2},"block_id":24},{"move":{"x":3,"y":1,"z":3},"block_id":24},{"move":{"x":3,"y":1,"z":4},"block_id":537},{"move":{"x":3,"y":1,"z":5},"block_id":24},{"move":{"x":3,"y":1,"z":6},"block_id":24},{"move":{"x":3,"y":1,"z":7},"block_id":577},{"move":{"x":3,"y":2,"z":0},"block_id":774,"extra_data":{"pressed":0},"rotate":{"x":18,"y":0,"z":0}},{"move":{"x":3,"y":2,"z":1},"block_id":123},{"move":{"x":3,"y":2,"z":2},"block_id":123},{"move":{"x":3,"y":2,"z":3},"block_id":123},{"move":{"x":3,"y":2,"z":4},"block_id":123},{"move":{"x":3,"y":2,"z":5},"block_id":123},{"move":{"x":3,"y":2,"z":6},"block_id":123},{"move":{"x":3,"y":2,"z":7},"block_id":123},{"move":{"x":3,"y":2,"z":8},"block_id":774,"extra_data":{"pressed":0},"rotate":{"x":7,"y":0,"z":0}},{"move":{"x":3,"y":3,"z":1},"block_id":174},{"move":{"x":3,"y":3,"z":2},"block_id":175,"extra_data":{"point":{"x":0.7857853158710668,"y":0,"z":0.7459423500838511}}},{"move":{"x":3,"y":3,"z":3},"block_id":174},{"move":{"x":3,"y":3,"z":4},"block_id":577},{"move":{"x":3,"y":3,"z":5},"block_id":24},{"move":{"x":3,"y":3,"z":6},"block_id":24},{"move":{"x":3,"y":3,"z":7},"block_id":577},{"move":{"x":3,"y":4,"z":4},"block_id":577},{"move":{"x":3,"y":4,"z":5},"block_id":24},{"move":{"x":3,"y":4,"z":6},"block_id":24},{"move":{"x":3,"y":4,"z":7},"block_id":577},{"move":{"x":3,"y":5,"z":3},"block_id":774,"extra_data":{"pressed":0},"rotate":{"x":18,"y":0,"z":0}},{"move":{"x":3,"y":5,"z":4},"block_id":123},{"move":{"x":3,"y":5,"z":5},"block_id":123},{"move":{"x":3,"y":5,"z":6},"block_id":123},{"move":{"x":3,"y":5,"z":7},"block_id":123},{"move":{"x":3,"y":5,"z":8},"block_id":774,"extra_data":{"pressed":0},"rotate":{"x":7,"y":0,"z":0}},{"move":{"x":3,"y":6,"z":4},"block_id":174},{"move":{"x":3,"y":6,"z":5},"block_id":176,"extra_data":{"point":{"x":0.6366840256981163,"y":0,"z":0.2250838119613805}},"rotate":{"x":0,"y":1,"z":0}},{"move":{"x":3,"y":6,"z":6},"block_id":176,"extra_data":{"point":{"x":0.5689881252477562,"y":0,"z":0.9042423485732165}},"rotate":{"x":2,"y":1,"z":0}},{"move":{"x":3,"y":6,"z":7},"block_id":174},{"move":{"x":4,"y":-1,"z":0},"block_id":2},{"move":{"x":4,"y":-1,"z":1},"block_id":2},{"move":{"x":4,"y":-1,"z":2},"block_id":2},{"move":{"x":4,"y":-1,"z":3},"block_id":2},{"move":{"x":4,"y":-1,"z":4},"block_id":2},{"move":{"x":4,"y":-1,"z":5},"block_id":2},{"move":{"x":4,"y":-1,"z":6},"block_id":2},{"move":{"x":4,"y":-1,"z":7},"block_id":2},{"move":{"x":4,"y":-1,"z":8},"block_id":2},{"move":{"x":4,"y":2,"z":1},"block_id":774,"extra_data":{"pressed":0},"rotate":{"x":22,"y":0,"z":0}},{"move":{"x":4,"y":2,"z":4},"block_id":774,"extra_data":{"pressed":0},"rotate":{"x":22,"y":0,"z":0}},{"move":{"x":4,"y":2,"z":7},"block_id":774,"extra_data":{"pressed":0},"rotate":{"x":22,"y":0,"z":0}},{"move":{"x":4,"y":5,"z":4},"block_id":774,"extra_data":{"pressed":0},"rotate":{"x":22,"y":0,"z":0}},{"move":{"x":4,"y":5,"z":7},"block_id":774,"extra_data":{"pressed":0},"rotate":{"x":22,"y":0,"z":0}}],"rot":[],"fluids":[]}