{"name":"stone_house_small","world":{"pos1":{"x":-250,"y":0,"z":1},"pos2":{"x":-260,"y":10,"z":-5},"entrance":{"x":-255,"y":1,"z":1}},"size":{"x":11,"y":11,"z":7},"door_pos":{"x":5,"y":1,"z":0},"blocks":[{"move":{"x":-5,"y":-1,"z":1},"block_id":2},{"move":{"x":-5,"y":-1,"z":2},"block_id":2},{"move":{"x":-5,"y":-1,"z":3},"block_id":2},{"move":{"x":-5,"y":-1,"z":4},"block_id":2},{"move":{"x":-5,"y":-1,"z":5},"block_id":2},{"move":{"x":-5,"y":-1,"z":6},"block_id":2},{"move":{"x":-5,"y":0,"z":1},"block_id":67,"extra_data":{"point":{"x":1.0020000000000095,"y":0.29097682294823346,"z":0.7473402220221598}},"rotate":{"x":3,"y":0,"z":0}},{"move":{"x":-5,"y":0,"z":5},"block_id":67,"extra_data":{"point":{"x":1.0020000000000095,"y":0.024821247109623856,"z":0.4664105339291855}},"rotate":{"x":3,"y":0,"z":0}},{"move":{"x":-5,"y":1,"z":2},"block_id":465,"extra_data":{"point":{"x":1.0020000000000095,"y":0.48056829158787906,"z":0.5117224583223541},"opened":true},"rotate":{"x":3,"y":0,"z":0}},{"move":{"x":-5,"y":2,"z":3},"block_id":50,"rotate":{"x":3,"y":0,"z":0}},{"move":{"x":-5,"y":3,"z":1},"block_id":134,"extra_data":{"point":{"x":1.0020000000000095,"y":0.5352592184717544,"z":0.5123947929702307}},"rotate":{"x":3,"y":0,"z":0}},{"move":{"x":-5,"y":3,"z":2},"block_id":206,"extra_data":{"point":{"x":1.0020000000000095,"y":0.5325980904032344,"z":0.49652472694930094}}},{"move":{"x":-5,"y":3,"z":3},"block_id":465,"extra_data":{"point":{"x":1.0020000000000095,"y":0.9869594536692112,"z":0.42677261286524315},"opened":false},"rotate":{"x":3,"y":0,"z":0}},{"move":{"x":-5,"y":3,"z":4},"block_id":206,"extra_data":{"point":{"x":1.0020000000000095,"y":0.5096310094309038,"z":0.43456635390036524}}},{"move":{"x":-5,"y":3,"z":5},"block_id":134,"extra_data":{"point":{"x":1.0020000000000095,"y":0.6810231343011495,"z":0.23218932888965416}},"rotate":{"x":3,"y":0,"z":0}},{"move":{"x":-5,"y":4,"z":1},"block_id":206,"extra_data":{"point":{"x":1.0020000000000095,"y":0.0351157004704703,"z":0.42891659761264406}}},{"move":{"x":-5,"y":4,"z":2},"block_id":198},{"move":{"x":-5,"y":4,"z":3},"block_id":198},{"move":{"x":-5,"y":4,"z":4},"block_id":198},{"move":{"x":-5,"y":4,"z":5},"block_id":206,"extra_data":{"point":{"x":0.08714516157053254,"y":0,"z":0.4604364683469213}}},{"move":{"x":-5,"y":5,"z":0},"block_id":206,"extra_data":{"point":{"x":0.6057876088425758,"y":1,"z":0.7077066784914481}}},{"move":{"x":-5,"y":5,"z":2},"block_id":465,"extra_data":{"point":{"x":1.0020000000000095,"y":0.5889015958292845,"z":0.40780042303865516},"opened":true},"rotate":{"x":3,"y":0,"z":0}},{"move":{"x":-5,"y":5,"z":6},"block_id":206,"extra_data":{"point":{"x":0.5206907409962298,"y":1,"z":0.9789513037485831}}},{"move":{"x":-5,"y":6,"z":0},"block_id":134,"extra_data":{"point":{"x":1.0010000000000048,"y":0.31052157774704625,"z":0.3357733092974615}},"rotate":{"x":0,"y":0,"z":0}},{"move":{"x":-5,"y":6,"z":1},"block_id":134,"extra_data":{"point":{"x":0.5249081687303772,"y":0.63837578107914,"z":-0.0010000000000000009}},"rotate":{"x":2,"y":0,"z":0}},{"move":{"x":-5,"y":6,"z":2},"block_id":465,"extra_data":{"point":{"x":1.0020000000000095,"y":0.4859253663845715,"z":0.5383805934650674},"opened":true},"rotate":{"x":3,"y":0,"z":0}},{"move":{"x":-5,"y":6,"z":5},"block_id":134,"extra_data":{"point":{"x":0.40034873998340004,"y":1,"z":0.1372390150601963}},"rotate":{"x":0,"y":-1,"z":0}},{"move":{"x":-5,"y":6,"z":6},"block_id":134,"extra_data":{"point":{"x":1.0010000000000048,"y":0.3838100353208045,"z":0.22000135086621775}},"rotate":{"x":2,"y":0,"z":0}},{"move":{"x":-5,"y":7,"z":1},"block_id":134,"extra_data":{"point":{"x":1.0010000000000048,"y":0.2674080505277239,"z":0.3243395398367534}},"rotate":{"x":0,"y":0,"z":0}},{"move":{"x":-5,"y":7,"z":2},"block_id":134,"extra_data":{"point":{"x":0.6056006324790246,"y":0.8613223053852117,"z":-0.001}},"rotate":{"x":2,"y":0,"z":0}},{"move":{"x":-5,"y":7,"z":4},"block_id":134,"extra_data":{"point":{"x":0.43642623309494866,"y":0.6851309362314133,"z":1.001}},"rotate":{"x":0,"y":0,"z":0}},{"move":{"x":-5,"y":7,"z":5},"block_id":134,"extra_data":{"point":{"x":1.0010000000000048,"y":0.18588822234736035,"z":0.5269082447887934}},"rotate":{"x":2,"y":0,"z":0}},{"move":{"x":-5,"y":8,"z":2},"block_id":134,"extra_data":{"point":{"x":1.0010000000000048,"y":0.24558737558141885,"z":0.33619603486420246}},"rotate":{"x":0,"y":0,"z":0}},{"move":{"x":-5,"y":8,"z":3},"block_id":134,"extra_data":{"point":{"x":0.6997458701891333,"y":0.5731139724490273,"z":-0.0009999999999998899}},"rotate":{"x":3,"y":0,"z":0}},{"move":{"x":-5,"y":8,"z":4},"block_id":134,"extra_data":{"point":{"x":1.0010000000000048,"y":0.38859317237510815,"z":0.9896414614651503}},"rotate":{"x":2,"y":0,"z":0}},{"move":{"x":-5,"y":9,"z":3},"block_id":134,"extra_data":{"point":{"x":0.26422176008151155,"y":0,"z":0.39143046753607513}},"rotate":{"x":1,"y":1,"z":0}},{"move":{"x":-4,"y":-1,"z":0},"block_id":2},{"move":{"x":-4,"y":-1,"z":1},"block_id":8},{"move":{"x":-4,"y":-1,"z":2},"block_id":8},{"move":{"x":-4,"y":-1,"z":3},"block_id":8},{"move":{"x":-4,"y":-1,"z":4},"block_id":8},{"move":{"x":-4,"y":-1,"z":5},"block_id":8},{"move":{"x":-4,"y":-1,"z":6},"block_id":2},{"move":{"x":-4,"y":0,"z":0},"block_id":67,"extra_data":{"point":{"x":0.5972783996733426,"y":0.10859274369150174,"z":1.002}},"rotate":{"x":0,"y":0,"z":0}},{"move":{"x":-4,"y":0,"z":1},"block_id":1467},{"move":{"x":-4,"y":0,"z":2},"block_id":8},{"move":{"x":-4,"y":0,"z":3},"block_id":8},{"move":{"x":-4,"y":0,"z":4},"block_id":8},{"move":{"x":-4,"y":0,"z":5},"block_id":1467},{"move":{"x":-4,"y":0,"z":6},"block_id":67,"extra_data":{"point":{"x":0.3513225356059877,"y":0,"z":0.975032589410584}},"rotate":{"x":2,"y":1,"z":0}},{"move":{"x":-4,"y":1,"z":1},"block_id":1467},{"move":{"x":-4,"y":1,"z":2},"block_id":8},{"move":{"x":-4,"y":1,"z":3},"block_id":102,"rotate":{"x":3,"y":1,"z":0}},{"move":{"x":-4,"y":1,"z":4},"block_id":8},{"move":{"x":-4,"y":1,"z":5},"block_id":1467},{"move":{"x":-4,"y":2,"z":0},"block_id":652,"rotate":{"x":0,"y":-1,"z":0}},{"move":{"x":-4,"y":2,"z":1},"block_id":1467},{"move":{"x":-4,"y":2,"z":2},"block_id":8},{"move":{"x":-4,"y":2,"z":3},"block_id":8},{"move":{"x":-4,"y":2,"z":4},"block_id":8},{"move":{"x":-4,"y":2,"z":5},"block_id":1467},{"move":{"x":-4,"y":3,"z":0},"block_id":134,"extra_data":{"point":{"x":0.48322062950447275,"y":0.5977824620500396,"z":1.002}},"rotate":{"x":0,"y":0,"z":0}},{"move":{"x":-4,"y":3,"z":1},"block_id":1467},{"move":{"x":-4,"y":3,"z":2},"block_id":1467},{"move":{"x":-4,"y":3,"z":3},"block_id":1474,"rotate":{"x":7,"y":0,"z":0}},{"move":{"x":-4,"y":3,"z":4},"block_id":1467},{"move":{"x":-4,"y":3,"z":5},"block_id":1467},{"move":{"x":-4,"y":3,"z":6},"block_id":134,"extra_data":{"point":{"x":0.7760737040168522,"y":0.6412676622492048,"z":-0.0019999999999997797}},"rotate":{"x":2,"y":0,"z":0}},{"move":{"x":-4,"y":4,"z":0},"block_id":206,"extra_data":{"point":{"x":0.4699729543769422,"y":0,"z":0.8943364963251579}}},{"move":{"x":-4,"y":4,"z":1},"block_id":1467},{"move":{"x":-4,"y":4,"z":2},"block_id":1471,"rotate":{"x":0,"y":1,"z":0}},{"move":{"x":-4,"y":4,"z":3},"block_id":1471,"rotate":{"x":0,"y":1,"z":0}},{"move":{"x":-4,"y":4,"z":4},"block_id":1471,"rotate":{"x":7,"y":0,"z":0}},{"move":{"x":-4,"y":4,"z":5},"block_id":1467},{"move":{"x":-4,"y":4,"z":6},"block_id":206,"extra_data":{"point":{"x":0.39343254528188254,"y":0.03307456598217051,"z":-0.0019999999999997797}}},{"move":{"x":-4,"y":5,"z":1},"block_id":1467},{"move":{"x":-4,"y":5,"z":2},"block_id":1471,"rotate":{"x":0,"y":1,"z":0}},{"move":{"x":-4,"y":5,"z":3},"block_id":102,"rotate":{"x":3,"y":1,"z":0}},{"move":{"x":-4,"y":5,"z":4},"block_id":1471,"rotate":{"x":0,"y":1,"z":0}},{"move":{"x":-4,"y":5,"z":5},"block_id":1467},{"move":{"x":-4,"y":6,"z":0},"block_id":134,"extra_data":{"point":{"x":0.7591024348052429,"y":0.4854819029494335,"z":1.002}},"rotate":{"x":0,"y":0,"z":0}},{"move":{"x":-4,"y":6,"z":1},"block_id":1467},{"move":{"x":-4,"y":6,"z":2},"block_id":1471,"rotate":{"x":0,"y":1,"z":0}},{"move":{"x":-4,"y":6,"z":3},"block_id":102,"rotate":{"x":3,"y":-1,"z":0}},{"move":{"x":-4,"y":6,"z":4},"block_id":1471,"rotate":{"x":0,"y":1,"z":0}},{"move":{"x":-4,"y":6,"z":5},"block_id":1467},{"move":{"x":-4,"y":6,"z":6},"block_id":134,"extra_data":{"point":{"x":1.0010000000000048,"y":0.11508887720165184,"z":0.5952931593973885}},"rotate":{"x":2,"y":0,"z":0}},{"move":{"x":-4,"y":7,"z":1},"block_id":53,"extra_data":{"point":{"x":1.0010000000000048,"y":0.2696161100007135,"z":0.32158860408389733}},"rotate":{"x":0,"y":0,"z":0}},{"move":{"x":-4,"y":7,"z":2},"block_id":1471,"rotate":{"x":0,"y":1,"z":0}},{"move":{"x":-4,"y":7,"z":3},"block_id":1471,"rotate":{"x":0,"y":1,"z":0}},{"move":{"x":-4,"y":7,"z":4},"block_id":1471,"rotate":{"x":0,"y":1,"z":0}},{"move":{"x":-4,"y":7,"z":5},"block_id":53,"extra_data":{"point":{"x":0.48819778165298544,"y":0.42025883870668324,"z":-0.0019999999999997797}},"rotate":{"x":2,"y":0,"z":0}},{"move":{"x":-4,"y":8,"z":2},"block_id":53,"extra_data":{"point":{"x":0.4033260368577487,"y":0,"z":0.23548145356208594}},"rotate":{"x":0,"y":1,"z":0}},{"move":{"x":-4,"y":8,"z":3},"block_id":1471,"rotate":{"x":0,"y":1,"z":0}},{"move":{"x":-4,"y":8,"z":4},"block_id":53,"extra_data":{"point":{"x":1.0010000000000048,"y":0.026159074761205048,"z":0.9222506859347486}},"rotate":{"x":2,"y":0,"z":0}},{"move":{"x":-4,"y":9,"z":3},"block_id":204,"extra_data":{"point":{"x":0.23998449528360766,"y":0,"z":0.7532723611442362}}},{"move":{"x":-3,"y":-1,"z":0},"block_id":2},{"move":{"x":-3,"y":-1,"z":1},"block_id":8},{"move":{"x":-3,"y":-1,"z":2},"block_id":7},{"move":{"x":-3,"y":-1,"z":3},"block_id":7},{"move":{"x":-3,"y":-1,"z":4},"block_id":7},{"move":{"x":-3,"y":-1,"z":5},"block_id":8},{"move":{"x":-3,"y":-1,"z":6},"block_id":2},{"move":{"x":-3,"y":0,"z":1},"block_id":8},{"move":{"x":-3,"y":0,"z":4},"block_id":139},{"move":{"x":-3,"y":0,"z":5},"block_id":8},{"move":{"x":-3,"y":1,"z":1},"block_id":8},{"move":{"x":-3,"y":1,"z":4},"block_id":139},{"move":{"x":-3,"y":1,"z":5},"block_id":8},{"move":{"x":-3,"y":2,"z":1},"block_id":8},{"move":{"x":-3,"y":2,"z":5},"block_id":8},{"move":{"x":-3,"y":3,"z":0},"block_id":206,"extra_data":{"point":{"x":0.7169200989666251,"y":0.7562638662187942,"z":1.002}}},{"move":{"x":-3,"y":3,"z":1},"block_id":1467},{"move":{"x":-3,"y":3,"z":2},"block_id":204,"extra_data":{"point":{"x":0.45389832232598337,"y":0.8332650204941414,"z":-0.002}}},{"move":{"x":-3,"y":3,"z":3},"block_id":204,"extra_data":{"point":{"x":-0.0020000000000095497,"y":0.5119535414850036,"z":0.4313751541316353}}},{"move":{"x":-3,"y":3,"z":4},"block_id":204,"extra_data":{"point":{"x":-0.0020000000000095497,"y":0.8910083870285881,"z":0.27972876845857675}}},{"move":{"x":-3,"y":3,"z":5},"block_id":1467},{"move":{"x":-3,"y":3,"z":6},"block_id":206,"extra_data":{"point":{"x":0.7127645752218825,"y":0.678241768091632,"z":-0.0019999999999997797}}},{"move":{"x":-3,"y":4,"z":1},"block_id":1471,"rotate":{"x":0,"y":1,"z":0}},{"move":{"x":-3,"y":4,"z":3},"block_id":1201,"extra_data":{"is_head":false},"rotate":{"x":0,"y":1,"z":0}},{"move":{"x":-3,"y":4,"z":4},"block_id":1201,"extra_data":{"is_head":true},"rotate":{"x":0,"y":1,"z":0}},{"move":{"x":-3,"y":4,"z":5},"block_id":1471,"rotate":{"x":0,"y":1,"z":0}},{"move":{"x":-3,"y":5,"z":1},"block_id":1471,"rotate":{"x":0,"y":1,"z":0}},{"move":{"x":-3,"y":5,"z":5},"block_id":1471,"rotate":{"x":0,"y":1,"z":0}},{"move":{"x":-3,"y":6,"z":0},"block_id":134,"extra_data":{"point":{"x":-0.0010000000000047748,"y":0.1590832446701178,"z":0.4012511627735662}},"rotate":{"x":0,"y":0,"z":0}},{"move":{"x":-3,"y":6,"z":1},"block_id":1471,"rotate":{"x":0,"y":1,"z":0}},{"move":{"x":-3,"y":6,"z":5},"block_id":1471,"rotate":{"x":0,"y":1,"z":0}},{"move":{"x":-3,"y":6,"z":6},"block_id":134,"extra_data":{"point":{"x":1.0010000000000048,"y":0.237021706278842,"z":0.35262102308768917}},"rotate":{"x":2,"y":0,"z":0}},{"move":{"x":-3,"y":7,"z":1},"block_id":53,"extra_data":{"point":{"x":1.0010000000000048,"y":0.25229011318009853,"z":0.39575813702178125}},"rotate":{"x":0,"y":0,"z":0}},{"move":{"x":-3,"y":7,"z":5},"block_id":53,"extra_data":{"point":{"x":-0.0010000000000047748,"y":0.46438416786468295,"z":0.3454569752509049}},"rotate":{"x":2,"y":0,"z":0}},{"move":{"x":-3,"y":8,"z":2},"block_id":53,"extra_data":{"point":{"x":-0.0010000000000047748,"y":0.32682948410720236,"z":0.6443057653266171}},"rotate":{"x":0,"y":0,"z":0}},{"move":{"x":-3,"y":8,"z":4},"block_id":53,"extra_data":{"point":{"x":1.0010000000000048,"y":0.07997794229540212,"z":0.6049376529922803}},"rotate":{"x":2,"y":0,"z":0}},{"move":{"x":-3,"y":9,"z":3},"block_id":7},{"move":{"x":-3,"y":9,"z":5},"block_id":465,"extra_data":{"point":{"x":1,"y":0.25550258622849675,"z":0.5613753434529123},"opened":true},"rotate":{"x":3,"y":0,"z":0}},{"move":{"x":-2,"y":-1,"z":0},"block_id":2},{"move":{"x":-2,"y":-1,"z":1},"block_id":7},{"move":{"x":-2,"y":-1,"z":2},"block_id":7},{"move":{"x":-2,"y":-1,"z":3},"block_id":7},{"move":{"x":-2,"y":-1,"z":4},"block_id":7},{"move":{"x":-2,"y":-1,"z":5},"block_id":88},{"move":{"x":-2,"y":-1,"z":6},"block_id":2},{"move":{"x":-2,"y":0,"z":1},"block_id":580,"extra_data":{"point":{"x":0.39262939855393597,"y":0,"z":0.5788055918112174},"opened":false,"left":false,"is_head":false},"rotate":{"x":0,"y":1,"z":0}},{"move":{"x":-2,"y":0,"z":5},"block_id":506,"extra_data":{"age":0,"east":false,"west":false,"north":false,"south":false,"up":true}},{"move":{"x":-2,"y":0,"z":6},"block_id":8},{"move":{"x":-2,"y":1,"z":1},"block_id":580,"extra_data":{"point":{"x":0.39262939855393597,"y":0,"z":0.5788055918112174},"opened":false,"left":false,"is_head":true},"rotate":{"x":0,"y":1,"z":0}},{"move":{"x":-2,"y":1,"z":4},"block_id":139},{"move":{"x":-2,"y":1,"z":5},"block_id":8},{"move":{"x":-2,"y":1,"z":6},"block_id":8},{"move":{"x":-2,"y":2,"z":1},"block_id":8},{"move":{"x":-2,"y":2,"z":5},"block_id":8},{"move":{"x":-2,"y":2,"z":6},"block_id":8},{"move":{"x":-2,"y":3,"z":0},"block_id":465,"extra_data":{"point":{"x":0.4936322467538048,"y":0.9558832835108726,"z":1.002},"opened":false},"rotate":{"x":0,"y":0,"z":0}},{"move":{"x":-2,"y":3,"z":1},"block_id":1467},{"move":{"x":-2,"y":3,"z":2},"block_id":204,"extra_data":{"point":{"x":0.6355917919336491,"y":0.8752948831829466,"z":-0.002}}},{"move":{"x":-2,"y":3,"z":3},"block_id":204,"extra_data":{"point":{"x":-0.0020000000000095497,"y":0.6340615038690771,"z":0.580870031601588}}},{"move":{"x":-2,"y":3,"z":4},"block_id":204,"extra_data":{"point":{"x":0.1609964405237747,"y":0.752449738840486,"z":1.0019999999999998}}},{"move":{"x":-2,"y":3,"z":5},"block_id":1467},{"move":{"x":-2,"y":3,"z":6},"block_id":8},{"move":{"x":-2,"y":4,"z":1},"block_id":1471,"rotate":{"x":0,"y":1,"z":0}},{"move":{"x":-2,"y":4,"z":5},"block_id":1471,"rotate":{"x":0,"y":1,"z":0}},{"move":{"x":-2,"y":4,"z":6},"block_id":8},{"move":{"x":-2,"y":5,"z":0},"block_id":206,"extra_data":{"point":{"x":0.7683995869841453,"y":1,"z":0.5132030095455751}}},{"move":{"x":-2,"y":5,"z":1},"block_id":1471,"rotate":{"x":0,"y":1,"z":0}},{"move":{"x":-2,"y":5,"z":5},"block_id":8},{"move":{"x":-2,"y":5,"z":6},"block_id":67,"extra_data":{"point":{"x":0.5452702761633361,"y":0.2678939238452509,"z":-0.0019999999999997797}},"rotate":{"x":2,"y":0,"z":0}},{"move":{"x":-2,"y":6,"z":0},"block_id":134,"extra_data":{"point":{"x":-0.0010000000000047748,"y":0.3075008830990109,"z":0.5904204431608997}},"rotate":{"x":0,"y":0,"z":0}},{"move":{"x":-2,"y":6,"z":1},"block_id":1471,"rotate":{"x":0,"y":1,"z":0}},{"move":{"x":-2,"y":6,"z":5},"block_id":8},{"move":{"x":-2,"y":6,"z":6},"block_id":134,"extra_data":{"point":{"x":1.0010000000000048,"y":0.22046572820545407,"z":0.4519903390906457}},"rotate":{"x":2,"y":0,"z":0}},{"move":{"x":-2,"y":7,"z":1},"block_id":53,"extra_data":{"point":{"x":1.0010000000000048,"y":0.35105768604919163,"z":0.525862419155233}},"rotate":{"x":0,"y":0,"z":0}},{"move":{"x":-2,"y":7,"z":5},"block_id":8},{"move":{"x":-2,"y":8,"z":2},"block_id":53,"extra_data":{"point":{"x":-0.0010000000000047748,"y":0.22141848193902014,"z":0.5133528606954159}},"rotate":{"x":0,"y":0,"z":0}},{"move":{"x":-2,"y":8,"z":3},"block_id":652,"rotate":{"x":2,"y":-1,"z":0}},{"move":{"x":-2,"y":8,"z":4},"block_id":53,"extra_data":{"point":{"x":1.0010000000000048,"y":0.19750676297560865,"z":0.27831878775747576}},"rotate":{"x":2,"y":0,"z":0}},{"move":{"x":-2,"y":8,"z":5},"block_id":8},{"move":{"x":-2,"y":9,"z":3},"block_id":204,"extra_data":{"point":{"x":-0.0020000000000095497,"y":0.17614294094744665,"z":0.66481484236882}}},{"move":{"x":-2,"y":9,"z":4},"block_id":465,"extra_data":{"point":{"x":0.6076482529650775,"y":0.3506773978771296,"z":1},"opened":true},"rotate":{"x":0,"y":0,"z":0}},{"move":{"x":-2,"y":9,"z":5},"block_id":660,"extra_data":{"active":true},"rotate":{"x":2,"y":1,"z":0}},{"move":{"x":-2,"y":9,"z":6},"block_id":465,"extra_data":{"point":{"x":0.5180062296029178,"y":0.03119693128524048,"z":0},"opened":true},"rotate":{"x":2,"y":0,"z":0}},{"move":{"x":-1,"y":-1,"z":0},"block_id":2},{"move":{"x":-1,"y":-1,"z":1},"block_id":8},{"move":{"x":-1,"y":-1,"z":2},"block_id":7},{"move":{"x":-1,"y":-1,"z":3},"block_id":7},{"move":{"x":-1,"y":-1,"z":4},"block_id":7},{"move":{"x":-1,"y":-1,"z":5},"block_id":8},{"move":{"x":-1,"y":-1,"z":6},"block_id":2},{"move":{"x":-1,"y":0,"z":1},"block_id":8},{"move":{"x":-1,"y":0,"z":2},"block_id":65,"rotate":{"x":2,"y":0,"z":0}},{"move":{"x":-1,"y":0,"z":4},"block_id":139},{"move":{"x":-1,"y":0,"z":5},"block_id":8},{"move":{"x":-1,"y":1,"z":1},"block_id":8},{"move":{"x":-1,"y":1,"z":2},"block_id":65,"rotate":{"x":2,"y":0,"z":0}},{"move":{"x":-1,"y":1,"z":4},"block_id":139},{"move":{"x":-1,"y":1,"z":5},"block_id":8},{"move":{"x":-1,"y":2,"z":1},"block_id":8},{"move":{"x":-1,"y":2,"z":2},"block_id":65,"rotate":{"x":2,"y":0,"z":0}},{"move":{"x":-1,"y":2,"z":5},"block_id":8},{"move":{"x":-1,"y":3,"z":0},"block_id":206,"extra_data":{"point":{"x":0.8001902105187639,"y":0.7821757743410354,"z":1.002}}},{"move":{"x":-1,"y":3,"z":1},"block_id":1467},{"move":{"x":-1,"y":3,"z":2},"block_id":65,"rotate":{"x":2,"y":0,"z":0}},{"move":{"x":-1,"y":3,"z":3},"block_id":204,"extra_data":{"point":{"x":1.0020000000000095,"y":0.7468163643373789,"z":0.4142106983356528}}},{"move":{"x":-1,"y":3,"z":4},"block_id":204,"extra_data":{"point":{"x":1.0020000000000095,"y":0.9438183839820473,"z":0.6098679274262886}}},{"move":{"x":-1,"y":3,"z":5},"block_id":1467},{"move":{"x":-1,"y":3,"z":6},"block_id":206,"extra_data":{"point":{"x":0.07467457421259382,"y":0.6664675687213926,"z":-0.0019999999999997797}}},{"move":{"x":-1,"y":4,"z":1},"block_id":1471,"rotate":{"x":0,"y":1,"z":0}},{"move":{"x":-1,"y":4,"z":5},"block_id":1471,"rotate":{"x":0,"y":1,"z":0}},{"move":{"x":-1,"y":5,"z":1},"block_id":1471,"rotate":{"x":0,"y":1,"z":0}},{"move":{"x":-1,"y":5,"z":5},"block_id":1471,"rotate":{"x":0,"y":1,"z":0}},{"move":{"x":-1,"y":6,"z":0},"block_id":134,"extra_data":{"point":{"x":-0.0010000000000047748,"y":0.21767491192527988,"z":0.4268919085087528}},"rotate":{"x":0,"y":0,"z":0}},{"move":{"x":-1,"y":6,"z":1},"block_id":1471,"rotate":{"x":0,"y":1,"z":0}},{"move":{"x":-1,"y":6,"z":5},"block_id":1471,"rotate":{"x":0,"y":1,"z":0}},{"move":{"x":-1,"y":6,"z":6},"block_id":134,"extra_data":{"point":{"x":1.0010000000000048,"y":0.07478525236013933,"z":0.46967302987394977}},"rotate":{"x":2,"y":0,"z":0}},{"move":{"x":-1,"y":7,"z":1},"block_id":53,"extra_data":{"point":{"x":1.0010000000000048,"y":0.24406694385250383,"z":0.1794599064685791}},"rotate":{"x":0,"y":0,"z":0}},{"move":{"x":-1,"y":7,"z":5},"block_id":53,"extra_data":{"point":{"x":1.0010000000000048,"y":0.3436389856887967,"z":0.841668736317259}},"rotate":{"x":2,"y":0,"z":0}},{"move":{"x":-1,"y":8,"z":2},"block_id":53,"extra_data":{"point":{"x":-0.0010000000000047748,"y":0.17942076949368513,"z":0.3189541017859765}},"rotate":{"x":0,"y":0,"z":0}},{"move":{"x":-1,"y":8,"z":4},"block_id":53,"extra_data":{"point":{"x":1.0010000000000048,"y":0.23043714465707055,"z":0.37547256305200305}},"rotate":{"x":2,"y":0,"z":0}},{"move":{"x":-1,"y":9,"z":3},"block_id":7},{"move":{"x":-1,"y":9,"z":5},"block_id":465,"extra_data":{"point":{"x":0,"y":0.14578638161891178,"z":0.45539929511695476},"opened":true},"rotate":{"x":1,"y":0,"z":0}},{"move":{"x":0,"y":-1,"z":0},"block_id":2},{"move":{"x":0,"y":-1,"z":1},"block_id":8},{"move":{"x":0,"y":-1,"z":2},"block_id":7},{"move":{"x":0,"y":-1,"z":3},"block_id":7},{"move":{"x":0,"y":-1,"z":4},"block_id":7},{"move":{"x":0,"y":-1,"z":5},"block_id":8},{"move":{"x":0,"y":-1,"z":6},"block_id":2},{"move":{"x":0,"y":0,"z":0},"block_id":67,"extra_data":{"point":{"x":0.4462383472442468,"y":0.18260633606983423,"z":1.002}},"rotate":{"x":0,"y":0,"z":0}},{"move":{"x":0,"y":0,"z":1},"block_id":1467},{"move":{"x":0,"y":0,"z":4},"block_id":304,"extra_data":{"frame":"jungle_log","is_head":false},"rotate":{"x":0,"y":1,"z":0}},{"move":{"x":0,"y":0,"z":5},"block_id":1467},{"move":{"x":0,"y":0,"z":6},"block_id":67,"extra_data":{"point":{"x":0.4322450283027024,"y":0.07200585793022518,"z":-0.0019999999999997797}},"rotate":{"x":2,"y":0,"z":0}},{"move":{"x":0,"y":1,"z":1},"block_id":1467},{"move":{"x":0,"y":1,"z":4},"block_id":304,"extra_data":{"frame":"jungle_log","is_head":true},"rotate":{"x":0,"y":1,"z":0}},{"move":{"x":0,"y":1,"z":5},"block_id":1467},{"move":{"x":0,"y":2,"z":0},"block_id":652,"rotate":{"x":0,"y":-1,"z":0}},{"move":{"x":0,"y":2,"z":1},"block_id":1467},{"move":{"x":0,"y":2,"z":5},"block_id":1467},{"move":{"x":0,"y":3,"z":0},"block_id":134,"extra_data":{"point":{"x":0.4680318139406552,"y":0.6513063882903634,"z":1.002}},"rotate":{"x":0,"y":0,"z":0}},{"move":{"x":0,"y":3,"z":1},"block_id":1467},{"move":{"x":0,"y":3,"z":2},"block_id":1467},{"move":{"x":0,"y":3,"z":3},"block_id":1467},{"move":{"x":0,"y":3,"z":4},"block_id":1467},{"move":{"x":0,"y":3,"z":5},"block_id":1467},{"move":{"x":0,"y":3,"z":6},"block_id":134,"extra_data":{"point":{"x":0.3563982047135994,"y":0.5648293745646438,"z":-0.0019999999999997797}},"rotate":{"x":2,"y":0,"z":0}},{"move":{"x":0,"y":4,"z":0},"block_id":206,"extra_data":{"point":{"x":0.6864718097737068,"y":0.14033974648139846,"z":1.002}}},{"move":{"x":0,"y":4,"z":1},"block_id":1467},{"move":{"x":0,"y":4,"z":2},"block_id":1471,"rotate":{"x":0,"y":1,"z":0}},{"move":{"x":0,"y":4,"z":3},"block_id":580,"extra_data":{"point":{"x":0.22973078674485237,"y":0,"z":0.1518179915430624},"opened":false,"left":false,"is_head":false},"rotate":{"x":1,"y":1,"z":0}},{"move":{"x":0,"y":4,"z":4},"block_id":1471,"rotate":{"x":0,"y":1,"z":0}},{"move":{"x":0,"y":4,"z":5},"block_id":1467},{"move":{"x":0,"y":4,"z":6},"block_id":206,"extra_data":{"point":{"x":0.3489626453140602,"y":0.28544540878797875,"z":-0.0019999999999997797}}},{"move":{"x":0,"y":5,"z":1},"block_id":1467},{"move":{"x":0,"y":5,"z":2},"block_id":1471,"rotate":{"x":0,"y":1,"z":0}},{"move":{"x":0,"y":5,"z":3},"block_id":580,"extra_data":{"point":{"x":0.22973078674485237,"y":0,"z":0.1518179915430624},"opened":false,"left":false,"is_head":true},"rotate":{"x":1,"y":1,"z":0}},{"move":{"x":0,"y":5,"z":4},"block_id":1471,"rotate":{"x":0,"y":1,"z":0}},{"move":{"x":0,"y":5,"z":5},"block_id":1467},{"move":{"x":0,"y":5,"z":6},"block_id":50,"rotate":{"x":2,"y":0,"z":0}},{"move":{"x":0,"y":6,"z":0},"block_id":134,"extra_data":{"point":{"x":-0.0010000000000047748,"y":0.1283445639448173,"z":0.2813121397702456}},"rotate":{"x":0,"y":0,"z":0}},{"move":{"x":0,"y":6,"z":1},"block_id":1467},{"move":{"x":0,"y":6,"z":2},"block_id":1471,"rotate":{"x":0,"y":1,"z":0}},{"move":{"x":0,"y":6,"z":3},"block_id":1471,"rotate":{"x":0,"y":1,"z":0}},{"move":{"x":0,"y":6,"z":4},"block_id":1471,"rotate":{"x":0,"y":1,"z":0}},{"move":{"x":0,"y":6,"z":5},"block_id":1467},{"move":{"x":0,"y":6,"z":6},"block_id":134,"extra_data":{"point":{"x":1.0010000000000048,"y":0.4622284106700132,"z":0.6594453336284669}},"rotate":{"x":2,"y":0,"z":0}},{"move":{"x":0,"y":7,"z":1},"block_id":53,"extra_data":{"point":{"x":0.5254006779631482,"y":0.026046363530443983,"z":1.002}},"rotate":{"x":0,"y":0,"z":0}},{"move":{"x":0,"y":7,"z":2},"block_id":1471,"rotate":{"x":0,"y":1,"z":0}},{"move":{"x":0,"y":7,"z":3},"block_id":1471,"rotate":{"x":0,"y":1,"z":0}},{"move":{"x":0,"y":7,"z":4},"block_id":1471,"rotate":{"x":0,"y":1,"z":0}},{"move":{"x":0,"y":7,"z":5},"block_id":53,"extra_data":{"point":{"x":0.9732901832814491,"y":0.22452645174298702,"z":-0.0019999999999997797}},"rotate":{"x":2,"y":0,"z":0}},{"move":{"x":0,"y":8,"z":2},"block_id":53,"extra_data":{"point":{"x":-0.0010000000000047748,"y":0.24167857864897435,"z":0.54945568971549}},"rotate":{"x":0,"y":0,"z":0}},{"move":{"x":0,"y":8,"z":3},"block_id":1471,"rotate":{"x":0,"y":1,"z":0}},{"move":{"x":0,"y":8,"z":4},"block_id":53,"extra_data":{"point":{"x":0.9090852595125227,"y":0.19721525614234103,"z":-0.0019999999999997797}},"rotate":{"x":2,"y":0,"z":0}},{"move":{"x":0,"y":9,"z":3},"block_id":204,"extra_data":{"point":{"x":0.6012558684772102,"y":0,"z":0.8304032694305079}}},{"move":{"x":1,"y":-1,"z":0},"block_id":2},{"move":{"x":1,"y":-1,"z":1},"block_id":8},{"move":{"x":1,"y":-1,"z":2},"block_id":7},{"move":{"x":1,"y":-1,"z":3},"block_id":7},{"move":{"x":1,"y":-1,"z":4},"block_id":7},{"move":{"x":1,"y":-1,"z":5},"block_id":8},{"move":{"x":1,"y":-1,"z":6},"block_id":2},{"move":{"x":1,"y":0,"z":0},"block_id":2},{"move":{"x":1,"y":0,"z":1},"block_id":8},{"move":{"x":1,"y":0,"z":5},"block_id":8},{"move":{"x":1,"y":1,"z":0},"block_id":513},{"move":{"x":1,"y":1,"z":1},"block_id":8},{"move":{"x":1,"y":1,"z":5},"block_id":8},{"move":{"x":1,"y":1,"z":6},"block_id":465,"extra_data":{"point":{"x":0.7752253423973059,"y":0.37109966618776413,"z":-0.0019999999999997797},"opened":true},"rotate":{"x":2,"y":0,"z":0}},{"move":{"x":1,"y":2,"z":1},"block_id":8},{"move":{"x":1,"y":2,"z":5},"block_id":8},{"move":{"x":1,"y":3,"z":0},"block_id":206,"extra_data":{"point":{"x":0.8344935891848024,"y":0.7732429951928719,"z":1.002}}},{"move":{"x":1,"y":3,"z":1},"block_id":1467},{"move":{"x":1,"y":3,"z":2},"block_id":126,"extra_data":{"point":{"x":1.0020000000000095,"y":0.5667539869325706,"z":0.3536246522756048}}},{"move":{"x":1,"y":3,"z":3},"block_id":126,"extra_data":{"point":{"x":1.0020000000000095,"y":0.6043046207108045,"z":0.6271706478037269}}},{"move":{"x":1,"y":3,"z":4},"block_id":126,"extra_data":{"point":{"x":0.5186493703005226,"y":0.5471959892688973,"z":1.0019999999999998}}},{"move":{"x":1,"y":3,"z":5},"block_id":1466},{"move":{"x":1,"y":3,"z":6},"block_id":206,"extra_data":{"point":{"x":0.7342979011895636,"y":0.7199021255511955,"z":-0.0019999999999997797}}},{"move":{"x":1,"y":4,"z":1},"block_id":191},{"move":{"x":1,"y":4,"z":5},"block_id":191},{"move":{"x":1,"y":5,"z":0},"block_id":206,"extra_data":{"point":{"x":0.6503489047168785,"y":1,"z":0.708734359467001}}},{"move":{"x":1,"y":5,"z":2},"block_id":50,"rotate":{"x":1,"y":0,"z":0}},{"move":{"x":1,"y":5,"z":6},"block_id":206,"extra_data":{"point":{"x":0.6019126064790896,"y":1,"z":0.6187820218887881}}},{"move":{"x":1,"y":6,"z":0},"block_id":134,"extra_data":{"point":{"x":-0.0010000000000047748,"y":0.33507688820412973,"z":0.1712467821313184}},"rotate":{"x":0,"y":0,"z":0}},{"move":{"x":1,"y":6,"z":1},"block_id":134,"extra_data":{"point":{"x":0.4304737831645582,"y":0.7409963745254791,"z":-0.0010000000000000009}},"rotate":{"x":2,"y":0,"z":0}},{"move":{"x":1,"y":6,"z":5},"block_id":134,"extra_data":{"point":{"x":0.4812664445005055,"y":1,"z":0.08813569225526363}},"rotate":{"x":0,"y":-1,"z":0}},{"move":{"x":1,"y":6,"z":6},"block_id":134,"extra_data":{"point":{"x":0.4313901351626157,"y":0.17240544119580026,"z":-0.001000000000000334}},"rotate":{"x":2,"y":0,"z":0}},{"move":{"x":1,"y":7,"z":1},"block_id":134,"extra_data":{"point":{"x":-0.0010000000000047748,"y":0.21982756414761262,"z":0.5237620135457923}},"rotate":{"x":0,"y":0,"z":0}},{"move":{"x":1,"y":7,"z":2},"block_id":206,"extra_data":{"point":{"x":-0.0020000000000095497,"y":0.2693443085378213,"z":0.8160546085202234}}},{"move":{"x":1,"y":7,"z":3},"block_id":206,"extra_data":{"point":{"x":1.0020000000000095,"y":0.10802283789080036,"z":0.23379801308038872}}},{"move":{"x":1,"y":7,"z":4},"block_id":206,"extra_data":{"point":{"x":1.0020000000000095,"y":0.21393227546671767,"z":0.67656600103922}}},{"move":{"x":1,"y":7,"z":5},"block_id":134,"extra_data":{"point":{"x":-0.0010000000000047748,"y":0.2973123696494646,"z":0.42605964150084086}},"rotate":{"x":2,"y":0,"z":0}},{"move":{"x":1,"y":8,"z":2},"block_id":134,"extra_data":{"point":{"x":-0.0010000000000047748,"y":0.343882668368126,"z":0.4218402296131434}},"rotate":{"x":0,"y":0,"z":0}},{"move":{"x":1,"y":8,"z":3},"block_id":134,"extra_data":{"point":{"x":-0.0020000000000095497,"y":0.6487764093391419,"z":0.17701644763115043}},"rotate":{"x":1,"y":0,"z":0}},{"move":{"x":1,"y":8,"z":4},"block_id":134,"extra_data":{"point":{"x":-0.0010000000000047748,"y":0.3011187791864689,"z":0.7538568924247682}},"rotate":{"x":2,"y":0,"z":0}},{"move":{"x":1,"y":9,"z":3},"block_id":134,"extra_data":{"point":{"x":0.5123330672800535,"y":0,"z":0.611915062738128}},"rotate":{"x":3,"y":1,"z":0}},{"move":{"x":2,"y":-1,"z":0},"block_id":2},{"move":{"x":2,"y":-1,"z":1},"block_id":8},{"move":{"x":2,"y":-1,"z":2},"block_id":7},{"move":{"x":2,"y":-1,"z":3},"block_id":7},{"move":{"x":2,"y":-1,"z":4},"block_id":7},{"move":{"x":2,"y":-1,"z":5},"block_id":8},{"move":{"x":2,"y":-1,"z":6},"block_id":2},{"move":{"x":2,"y":0,"z":0},"block_id":2},{"move":{"x":2,"y":0,"z":1},"block_id":8},{"move":{"x":2,"y":0,"z":5},"block_id":8},{"move":{"x":2,"y":1,"z":0},"block_id":31},{"move":{"x":2,"y":1,"z":1},"block_id":102,"rotate":{"x":0,"y":1,"z":0}},{"move":{"x":2,"y":1,"z":5},"block_id":102,"rotate":{"x":2,"y":1,"z":0}},{"move":{"x":2,"y":2,"z":1},"block_id":8},{"move":{"x":2,"y":2,"z":5},"block_id":8},{"move":{"x":2,"y":3,"z":0},"block_id":465,"extra_data":{"point":{"x":0.4370010580954613,"y":0.8813418485017497,"z":1.002},"opened":false},"rotate":{"x":0,"y":0,"z":0}},{"move":{"x":2,"y":3,"z":1},"block_id":1467},{"move":{"x":2,"y":3,"z":2},"block_id":126,"extra_data":{"point":{"x":1.0020000000000095,"y":0.7862304998646392,"z":0.47011921511934673}}},{"move":{"x":2,"y":3,"z":3},"block_id":126,"extra_data":{"point":{"x":1.0020000000000095,"y":0.681093595690557,"z":0.6596477198322217}}},{"move":{"x":2,"y":3,"z":4},"block_id":126,"extra_data":{"point":{"x":0.7111550064183234,"y":0.5513877649953383,"z":1.0019999999999998}}},{"move":{"x":2,"y":3,"z":5},"block_id":1467},{"move":{"x":2,"y":4,"z":1},"block_id":191},{"move":{"x":2,"y":4,"z":5},"block_id":191},{"move":{"x":2,"y":7,"z":1},"block_id":206,"extra_data":{"point":{"x":0.5666312481179148,"y":0.20592330566449668,"z":1.002}}},{"move":{"x":2,"y":7,"z":2},"block_id":206,"extra_data":{"point":{"x":0.550219245278754,"y":0.18849373737081443,"z":1.002}}},{"move":{"x":2,"y":7,"z":3},"block_id":206,"extra_data":{"point":{"x":0.6558234228026549,"y":0.24496474312092964,"z":1.002}}},{"move":{"x":2,"y":7,"z":4},"block_id":206,"extra_data":{"point":{"x":0.5629212344518919,"y":0.23618350552509426,"z":1.0019999999999998}}},{"move":{"x":2,"y":7,"z":5},"block_id":206,"extra_data":{"point":{"x":1.0020000000000095,"y":0.04956066377564028,"z":0.3182884226340801}}},{"move":{"x":3,"y":-1,"z":0},"block_id":2},{"move":{"x":3,"y":-1,"z":1},"block_id":8},{"move":{"x":3,"y":-1,"z":2},"block_id":7},{"move":{"x":3,"y":-1,"z":3},"block_id":7},{"move":{"x":3,"y":-1,"z":4},"block_id":7},{"move":{"x":3,"y":-1,"z":5},"block_id":8},{"move":{"x":3,"y":-1,"z":6},"block_id":2},{"move":{"x":3,"y":0,"z":0},"block_id":2},{"move":{"x":3,"y":0,"z":1},"block_id":8},{"move":{"x":3,"y":0,"z":2},"block_id":1201,"extra_data":{"is_head":true},"rotate":{"x":2,"y":1,"z":0}},{"move":{"x":3,"y":0,"z":3},"block_id":1201,"extra_data":{"is_head":false},"rotate":{"x":2,"y":1,"z":0}},{"move":{"x":3,"y":0,"z":4},"block_id":650,"extra_data":{"item":{"id":19},"rot":0}},{"move":{"x":3,"y":0,"z":5},"block_id":8},{"move":{"x":3,"y":1,"z":0},"block_id":465,"extra_data":{"point":{"x":0.5700522974096316,"y":0.793264978469971,"z":1.002},"opened":true},"rotate":{"x":0,"y":0,"z":0}},{"move":{"x":3,"y":1,"z":1},"block_id":8},{"move":{"x":3,"y":1,"z":5},"block_id":8},{"move":{"x":3,"y":2,"z":1},"block_id":8},{"move":{"x":3,"y":2,"z":5},"block_id":8},{"move":{"x":3,"y":3,"z":0},"block_id":206,"extra_data":{"point":{"x":0.6754199858202128,"y":0.6849232997224952,"z":1.002}}},{"move":{"x":3,"y":3,"z":1},"block_id":1467},{"move":{"x":3,"y":3,"z":2},"block_id":126,"extra_data":{"point":{"x":1.0020000000000095,"y":0.5359091417069486,"z":0.5271994679080223}}},{"move":{"x":3,"y":3,"z":3},"block_id":126,"extra_data":{"point":{"x":1.0020000000000095,"y":0.6848910469570395,"z":0.15263216208485453}}},{"move":{"x":3,"y":3,"z":4},"block_id":126,"extra_data":{"point":{"x":0.4156499857201652,"y":0.5818632786254136,"z":1.0019999999999998}}},{"move":{"x":3,"y":3,"z":5},"block_id":1467},{"move":{"x":3,"y":3,"z":6},"block_id":206,"extra_data":{"point":{"x":0.5267487735068812,"y":0.7230716042710545,"z":-0.0019999999999997797}}},{"move":{"x":3,"y":4,"z":1},"block_id":191},{"move":{"x":3,"y":4,"z":2},"block_id":650,"extra_data":{"rot":0,"item":{"id":511}}},{"move":{"x":3,"y":4,"z":4},"block_id":304,"extra_data":{"frame":"jungle_log","is_head":false},"rotate":{"x":0,"y":1,"z":0}},{"move":{"x":3,"y":4,"z":5},"block_id":191},{"move":{"x":3,"y":5,"z":4},"block_id":304,"extra_data":{"frame":"jungle_log","is_head":true},"rotate":{"x":0,"y":1,"z":0}},{"move":{"x":3,"y":7,"z":1},"block_id":206,"extra_data":{"point":{"x":1.0020000000000095,"y":0.09706783190176971,"z":0.24336805812525752}}},{"move":{"x":3,"y":7,"z":2},"block_id":206,"extra_data":{"point":{"x":1.0020000000000095,"y":0.08934989508703062,"z":0.013717630051728769}}},{"move":{"x":3,"y":7,"z":3},"block_id":206,"extra_data":{"point":{"x":0.2731117836421504,"y":0.3188744055878381,"z":1.002}}},{"move":{"x":3,"y":7,"z":4},"block_id":206,"extra_data":{"point":{"x":1.0020000000000095,"y":0.20845704900853157,"z":0.46106476971116006}}},{"move":{"x":3,"y":7,"z":5},"block_id":206,"extra_data":{"point":{"x":1.0020000000000095,"y":0.28332866367837006,"z":0.5257169014788432}}},{"move":{"x":4,"y":-1,"z":0},"block_id":2},{"move":{"x":4,"y":-1,"z":1},"block_id":8},{"move":{"x":4,"y":-1,"z":2},"block_id":8},{"move":{"x":4,"y":-1,"z":3},"block_id":8},{"move":{"x":4,"y":-1,"z":4},"block_id":8},{"move":{"x":4,"y":-1,"z":5},"block_id":8},{"move":{"x":4,"y":-1,"z":6},"block_id":2},{"move":{"x":4,"y":0,"z":0},"block_id":67,"extra_data":{"point":{"x":0.4414257678155309,"y":0.45654111168850897,"z":1.002}},"rotate":{"x":0,"y":0,"z":0}},{"move":{"x":4,"y":0,"z":1},"block_id":1467},{"move":{"x":4,"y":0,"z":2},"block_id":8},{"move":{"x":4,"y":0,"z":3},"block_id":8},{"move":{"x":4,"y":0,"z":4},"block_id":8},{"move":{"x":4,"y":0,"z":5},"block_id":1467},{"move":{"x":4,"y":0,"z":6},"block_id":67,"extra_data":{"point":{"x":0.7299821209805941,"y":0.10258747439127025,"z":-0.0019999999999997797}},"rotate":{"x":2,"y":0,"z":0}},{"move":{"x":4,"y":1,"z":1},"block_id":1467},{"move":{"x":4,"y":1,"z":2},"block_id":8},{"move":{"x":4,"y":1,"z":3},"block_id":102,"rotate":{"x":1,"y":1,"z":0}},{"move":{"x":4,"y":1,"z":4},"block_id":8},{"move":{"x":4,"y":1,"z":5},"block_id":1467},{"move":{"x":4,"y":2,"z":1},"block_id":1467},{"move":{"x":4,"y":2,"z":2},"block_id":8},{"move":{"x":4,"y":2,"z":3},"block_id":8},{"move":{"x":4,"y":2,"z":4},"block_id":8},{"move":{"x":4,"y":2,"z":5},"block_id":1467},{"move":{"x":4,"y":3,"z":0},"block_id":134,"extra_data":{"point":{"x":0.5791567429114366,"y":0.618494254497219,"z":1.002}},"rotate":{"x":0,"y":0,"z":0}},{"move":{"x":4,"y":3,"z":1},"block_id":1467},{"move":{"x":4,"y":3,"z":2},"block_id":1467},{"move":{"x":4,"y":3,"z":3},"block_id":1467},{"move":{"x":4,"y":3,"z":4},"block_id":1467},{"move":{"x":4,"y":3,"z":5},"block_id":1467},{"move":{"x":4,"y":3,"z":6},"block_id":134,"extra_data":{"point":{"x":0.35334712829501314,"y":0.5351199156151054,"z":-0.0019999999999997797}},"rotate":{"x":2,"y":0,"z":0}},{"move":{"x":4,"y":4,"z":0},"block_id":206,"extra_data":{"point":{"x":0.3106511054876364,"y":0,"z":0.630607974547053}}},{"move":{"x":4,"y":4,"z":1},"block_id":1467},{"move":{"x":4,"y":4,"z":2},"block_id":191},{"move":{"x":4,"y":4,"z":3},"block_id":191},{"move":{"x":4,"y":4,"z":4},"block_id":191},{"move":{"x":4,"y":4,"z":5},"block_id":1467},{"move":{"x":4,"y":4,"z":6},"block_id":206,"extra_data":{"point":{"x":0.1858967510900129,"y":0,"z":0.3958552531395201}}},{"move":{"x":4,"y":5,"z":1},"block_id":191},{"move":{"x":4,"y":5,"z":5},"block_id":191},{"move":{"x":4,"y":6,"z":1},"block_id":191},{"move":{"x":4,"y":6,"z":5},"block_id":191},{"move":{"x":4,"y":7,"z":1},"block_id":206,"extra_data":{"point":{"x":0.5976597958783145,"y":0,"z":0.563752357308876}}},{"move":{"x":4,"y":7,"z":2},"block_id":206,"extra_data":{"point":{"x":0.5506626704842006,"y":0.2985290899516144,"z":1.002}}},{"move":{"x":4,"y":7,"z":3},"block_id":206,"extra_data":{"point":{"x":0.5989299313389438,"y":0.3620422726515766,"z":1.002}}},{"move":{"x":4,"y":7,"z":4},"block_id":206,"extra_data":{"point":{"x":0.4779232087979608,"y":0.21311895801063763,"z":1.0019999999999998}}},{"move":{"x":4,"y":7,"z":5},"block_id":206,"extra_data":{"point":{"x":0.5359697512797652,"y":0,"z":0.5552242306470943}}},{"move":{"x":5,"y":-1,"z":0},"block_id":2},{"move":{"x":5,"y":-1,"z":1},"block_id":2},{"move":{"x":5,"y":-1,"z":2},"block_id":2},{"move":{"x":5,"y":-1,"z":3},"block_id":2},{"move":{"x":5,"y":-1,"z":4},"block_id":2},{"move":{"x":5,"y":-1,"z":5},"block_id":2},{"move":{"x":5,"y":-1,"z":6},"block_id":2},{"move":{"x":5,"y":0,"z":1},"block_id":67,"extra_data":{"point":{"x":-0.0020000000000095497,"y":0.3781826641512265,"z":0.5522963776590581}},"rotate":{"x":1,"y":0,"z":0}},{"move":{"x":5,"y":0,"z":5},"block_id":67,"extra_data":{"point":{"x":-0.0020000000000095497,"y":0.3353368778247168,"z":0.31150111945482006}},"rotate":{"x":1,"y":0,"z":0}},{"move":{"x":5,"y":1,"z":4},"block_id":465,"extra_data":{"point":{"x":-0.0020000000000095497,"y":0.2776194616576557,"z":0.7477228712118329},"opened":true},"rotate":{"x":1,"y":0,"z":0}},{"move":{"x":5,"y":3,"z":1},"block_id":134,"extra_data":{"point":{"x":-0.0020000000000095497,"y":0.6876371064368518,"z":0.45092711233853483}},"rotate":{"x":1,"y":0,"z":0}},{"move":{"x":5,"y":3,"z":2},"block_id":206,"extra_data":{"point":{"x":-0.0020000000000095497,"y":0.7107412697265421,"z":0.3981964731239893}}},{"move":{"x":5,"y":3,"z":3},"block_id":465,"extra_data":{"point":{"x":-0.0020000000000095497,"y":0.9118262291016412,"z":0.6190498210481228},"opened":false},"rotate":{"x":1,"y":0,"z":0}},{"move":{"x":5,"y":3,"z":4},"block_id":206,"extra_data":{"point":{"x":-0.0020000000000095497,"y":0.7443342624893354,"z":0.44416309472214266}}},{"move":{"x":5,"y":3,"z":5},"block_id":134,"extra_data":{"point":{"x":-0.0020000000000095497,"y":0.6627634241443721,"z":0.6772721048740209}},"rotate":{"x":1,"y":0,"z":0}},{"move":{"x":5,"y":4,"z":1},"block_id":206,"extra_data":{"point":{"x":0.6796556776876628,"y":0,"z":0.5983697167401005}}},{"move":{"x":5,"y":4,"z":5},"block_id":206,"extra_data":{"point":{"x":0.8460559561528953,"y":0,"z":0.5909831188659127}}}],"rot":[],"fluids":[]}