{"name":"structure3","world":{"pos1":{"x":-302,"y":-1,"z":20},"pos2":{"x":-315,"y":10,"z":8},"entrance":{"x":-308,"y":1,"z":20}},"size":{"x":14,"y":12,"z":13},"door_pos":{"x":6,"y":2,"z":0},"blocks":[{"move":{"x":-6,"y":-2,"z":6},"block_id":2},{"move":{"x":-6,"y":-2,"z":9},"block_id":18},{"move":{"x":-6,"y":-2,"z":10},"block_id":2},{"move":{"x":-5,"y":-2,"z":5},"block_id":2},{"move":{"x":-5,"y":-2,"z":6},"block_id":2},{"move":{"x":-5,"y":-2,"z":7},"block_id":2},{"move":{"x":-5,"y":-2,"z":8},"block_id":18},{"move":{"x":-5,"y":-2,"z":9},"block_id":18},{"move":{"x":-5,"y":-2,"z":10},"block_id":18},{"move":{"x":-5,"y":-2,"z":11},"block_id":2},{"move":{"x":-5,"y":-1,"z":6},"block_id":9},{"move":{"x":-5,"y":-1,"z":9},"block_id":2},{"move":{"x":-5,"y":-1,"z":10},"block_id":2},{"move":{"x":-5,"y":0,"z":9},"block_id":31},{"move":{"x":-5,"y":0,"z":10},"block_id":31},{"move":{"x":-4,"y":-2,"z":4},"block_id":2},{"move":{"x":-4,"y":-2,"z":5},"block_id":2},{"move":{"x":-4,"y":-2,"z":6},"block_id":18},{"move":{"x":-4,"y":-2,"z":7},"block_id":2},{"move":{"x":-4,"y":-2,"z":8},"block_id":2},{"move":{"x":-4,"y":-2,"z":9},"block_id":18},{"move":{"x":-4,"y":-2,"z":10},"block_id":18},{"move":{"x":-4,"y":-2,"z":11},"block_id":2},{"move":{"x":-4,"y":-2,"z":12},"block_id":2},{"move":{"x":-4,"y":-1,"z":5},"block_id":2},{"move":{"x":-4,"y":-1,"z":6},"block_id":2},{"move":{"x":-4,"y":-1,"z":7},"block_id":2},{"move":{"x":-4,"y":-1,"z":8},"block_id":550},{"move":{"x":-4,"y":-1,"z":9},"block_id":2},{"move":{"x":-4,"y":-1,"z":10},"block_id":2},{"move":{"x":-4,"y":-1,"z":11},"block_id":2},{"move":{"x":-4,"y":0,"z":6},"block_id":31},{"move":{"x":-4,"y":0,"z":7},"block_id":31},{"move":{"x":-4,"y":0,"z":8},"block_id":2},{"move":{"x":-4,"y":0,"z":9},"block_id":106,"rotate":{"x":3,"y":0,"z":0}},{"move":{"x":-4,"y":0,"z":10},"block_id":31},{"move":{"x":-4,"y":0,"z":11},"block_id":31},{"move":{"x":-4,"y":1,"z":8},"block_id":31},{"move":{"x":-4,"y":1,"z":9},"block_id":106,"rotate":{"x":3,"y":0,"z":0}},{"move":{"x":-3,"y":-2,"z":3},"block_id":2},{"move":{"x":-3,"y":-2,"z":4},"block_id":2},{"move":{"x":-3,"y":-2,"z":5},"block_id":2},{"move":{"x":-3,"y":-2,"z":6},"block_id":2},{"move":{"x":-3,"y":-2,"z":7},"block_id":2},{"move":{"x":-3,"y":-2,"z":8},"block_id":2},{"move":{"x":-3,"y":-2,"z":9},"block_id":18},{"move":{"x":-3,"y":-2,"z":10},"block_id":2},{"move":{"x":-3,"y":-2,"z":11},"block_id":2},{"move":{"x":-3,"y":-2,"z":12},"block_id":18,"extra_data":{"max_ticks":319}},{"move":{"x":-3,"y":-1,"z":3},"block_id":106,"rotate":{"x":3,"y":0,"z":0}},{"move":{"x":-3,"y":-1,"z":4},"block_id":2},{"move":{"x":-3,"y":-1,"z":5},"block_id":2},{"move":{"x":-3,"y":-1,"z":6},"block_id":18},{"move":{"x":-3,"y":-1,"z":7},"block_id":9},{"move":{"x":-3,"y":-1,"z":8},"block_id":550},{"move":{"x":-3,"y":-1,"z":9},"block_id":549},{"move":{"x":-3,"y":-1,"z":10},"block_id":550},{"move":{"x":-3,"y":-1,"z":11},"block_id":550},{"move":{"x":-3,"y":-1,"z":12},"block_id":2},{"move":{"x":-3,"y":0,"z":3},"block_id":106,"rotate":{"x":3,"y":0,"z":0}},{"move":{"x":-3,"y":0,"z":4},"block_id":31},{"move":{"x":-3,"y":0,"z":5},"block_id":31},{"move":{"x":-3,"y":0,"z":6},"block_id":2},{"move":{"x":-3,"y":0,"z":7},"block_id":106,"rotate":{"x":3,"y":0,"z":0}},{"move":{"x":-3,"y":0,"z":8},"block_id":549},{"move":{"x":-3,"y":0,"z":9},"block_id":9},{"move":{"x":-3,"y":0,"z":10},"block_id":198},{"move":{"x":-3,"y":0,"z":12},"block_id":31},{"move":{"x":-3,"y":1,"z":3},"block_id":106,"rotate":{"x":3,"y":0,"z":0}},{"move":{"x":-3,"y":1,"z":5},"block_id":106,"rotate":{"x":3,"y":0,"z":0}},{"move":{"x":-3,"y":1,"z":6},"block_id":31},{"move":{"x":-3,"y":1,"z":7},"block_id":106,"rotate":{"x":3,"y":0,"z":0}},{"move":{"x":-3,"y":1,"z":8},"block_id":546},{"move":{"x":-3,"y":1,"z":9},"block_id":549},{"move":{"x":-3,"y":2,"z":3},"block_id":106,"rotate":{"x":3,"y":0,"z":0}},{"move":{"x":-3,"y":2,"z":4},"block_id":9},{"move":{"x":-3,"y":2,"z":5},"block_id":106,"rotate":{"x":3,"y":0,"z":0}},{"move":{"x":-3,"y":3,"z":3},"block_id":106,"rotate":{"x":3,"y":0,"z":0}},{"move":{"x":-3,"y":3,"z":4},"block_id":9},{"move":{"x":-3,"y":4,"z":4},"block_id":9},{"move":{"x":-3,"y":5,"z":4},"block_id":9},{"move":{"x":-3,"y":6,"z":4},"block_id":546},{"move":{"x":-3,"y":7,"z":4},"block_id":9},{"move":{"x":-3,"y":8,"z":4},"block_id":546},{"move":{"x":-2,"y":-2,"z":2},"block_id":2},{"move":{"x":-2,"y":-2,"z":3},"block_id":2},{"move":{"x":-2,"y":-2,"z":4},"block_id":2},{"move":{"x":-2,"y":-2,"z":5},"block_id":2},{"move":{"x":-2,"y":-2,"z":6},"block_id":18},{"move":{"x":-2,"y":-2,"z":7},"block_id":18},{"move":{"x":-2,"y":-2,"z":8},"block_id":2},{"move":{"x":-2,"y":-2,"z":9},"block_id":2},{"move":{"x":-2,"y":-2,"z":10},"block_id":18},{"move":{"x":-2,"y":-2,"z":11},"block_id":2},{"move":{"x":-2,"y":-2,"z":12},"block_id":18,"extra_data":{"max_ticks":166}},{"move":{"x":-2,"y":-1,"z":3},"block_id":2},{"move":{"x":-2,"y":-1,"z":4},"block_id":550},{"move":{"x":-2,"y":-1,"z":5},"block_id":9},{"move":{"x":-2,"y":-1,"z":6},"block_id":18},{"move":{"x":-2,"y":-1,"z":7},"block_id":18},{"move":{"x":-2,"y":-1,"z":8},"block_id":545},{"move":{"x":-2,"y":-1,"z":9},"block_id":549},{"move":{"x":-2,"y":-1,"z":10},"block_id":549},{"move":{"x":-2,"y":-1,"z":11},"block_id":2},{"move":{"x":-2,"y":-1,"z":12},"block_id":2},{"move":{"x":-2,"y":0,"z":4},"block_id":550},{"move":{"x":-2,"y":0,"z":5},"block_id":550},{"move":{"x":-2,"y":0,"z":6},"block_id":9},{"move":{"x":-2,"y":0,"z":7},"block_id":550},{"move":{"x":-2,"y":0,"z":8},"block_id":550},{"move":{"x":-2,"y":0,"z":9},"block_id":550},{"move":{"x":-2,"y":0,"z":10},"block_id":549},{"move":{"x":-2,"y":0,"z":12},"block_id":31},{"move":{"x":-2,"y":1,"z":3},"block_id":550},{"move":{"x":-2,"y":1,"z":4},"block_id":550},{"move":{"x":-2,"y":1,"z":5},"block_id":550},{"move":{"x":-2,"y":1,"z":6},"block_id":9},{"move":{"x":-2,"y":1,"z":7},"block_id":546},{"move":{"x":-2,"y":1,"z":8},"block_id":546},{"move":{"x":-2,"y":1,"z":9},"block_id":9},{"move":{"x":-2,"y":2,"z":3},"block_id":9},{"move":{"x":-2,"y":2,"z":5},"block_id":9},{"move":{"x":-2,"y":2,"z":8},"block_id":9},{"move":{"x":-2,"y":3,"z":3},"block_id":9},{"move":{"x":-2,"y":3,"z":4},"block_id":9},{"move":{"x":-2,"y":3,"z":5},"block_id":546},{"move":{"x":-2,"y":4,"z":3},"block_id":546},{"move":{"x":-2,"y":4,"z":4},"block_id":9},{"move":{"x":-2,"y":4,"z":5},"block_id":106,"rotate":{"x":2,"y":0,"z":0}},{"move":{"x":-2,"y":5,"z":4},"block_id":546},{"move":{"x":-2,"y":6,"z":4},"block_id":546},{"move":{"x":-1,"y":-2,"z":1},"block_id":2},{"move":{"x":-1,"y":-2,"z":2},"block_id":2},{"move":{"x":-1,"y":-2,"z":3},"block_id":2},{"move":{"x":-1,"y":-2,"z":4},"block_id":2},{"move":{"x":-1,"y":-2,"z":5},"block_id":18},{"move":{"x":-1,"y":-2,"z":6},"block_id":18},{"move":{"x":-1,"y":-2,"z":8},"block_id":18},{"move":{"x":-1,"y":-2,"z":9},"block_id":2},{"move":{"x":-1,"y":-2,"z":10},"block_id":2},{"move":{"x":-1,"y":-2,"z":11},"block_id":2},{"move":{"x":-1,"y":-2,"z":12},"block_id":18,"extra_data":{"max_ticks":246}},{"move":{"x":-1,"y":-1,"z":2},"block_id":2},{"move":{"x":-1,"y":-1,"z":3},"block_id":550},{"move":{"x":-1,"y":-1,"z":4},"block_id":550},{"move":{"x":-1,"y":-1,"z":5},"block_id":18},{"move":{"x":-1,"y":-1,"z":6},"block_id":18},{"move":{"x":-1,"y":-1,"z":7},"block_id":18},{"move":{"x":-1,"y":-1,"z":8},"block_id":18},{"move":{"x":-1,"y":-1,"z":9},"block_id":549},{"move":{"x":-1,"y":-1,"z":10},"block_id":549},{"move":{"x":-1,"y":-1,"z":11},"block_id":550},{"move":{"x":-1,"y":-1,"z":12},"block_id":2},{"move":{"x":-1,"y":0,"z":2},"block_id":31},{"move":{"x":-1,"y":0,"z":3},"block_id":550},{"move":{"x":-1,"y":0,"z":4},"block_id":550},{"move":{"x":-1,"y":0,"z":5},"block_id":2},{"move":{"x":-1,"y":0,"z":6},"block_id":2},{"move":{"x":-1,"y":0,"z":7},"block_id":549},{"move":{"x":-1,"y":0,"z":8},"block_id":550},{"move":{"x":-1,"y":0,"z":9},"block_id":550},{"move":{"x":-1,"y":0,"z":10},"block_id":549},{"move":{"x":-1,"y":0,"z":11},"block_id":2},{"move":{"x":-1,"y":1,"z":3},"block_id":9},{"move":{"x":-1,"y":1,"z":4},"block_id":550},{"move":{"x":-1,"y":1,"z":5},"block_id":550},{"move":{"x":-1,"y":1,"z":6},"block_id":546},{"move":{"x":-1,"y":1,"z":7},"block_id":546},{"move":{"x":-1,"y":1,"z":8},"block_id":550},{"move":{"x":-1,"y":1,"z":11},"block_id":31},{"move":{"x":-1,"y":2,"z":3},"block_id":106,"rotate":{"x":1,"y":0,"z":0}},{"move":{"x":-1,"y":2,"z":4},"block_id":9},{"move":{"x":-1,"y":2,"z":5},"block_id":106,"rotate":{"x":2,"y":0,"z":0}},{"move":{"x":-1,"y":2,"z":7},"block_id":9},{"move":{"x":-1,"y":2,"z":8},"block_id":545},{"move":{"x":-1,"y":3,"z":3},"block_id":106,"rotate":{"x":1,"y":0,"z":0}},{"move":{"x":-1,"y":3,"z":4},"block_id":9},{"move":{"x":-1,"y":3,"z":5},"block_id":106,"rotate":{"x":2,"y":0,"z":0}},{"move":{"x":-1,"y":4,"z":3},"block_id":106,"rotate":{"x":1,"y":0,"z":0}},{"move":{"x":-1,"y":4,"z":4},"block_id":106,"rotate":{"x":1,"y":0,"z":0}},{"move":{"x":0,"y":-2,"z":1},"block_id":18},{"move":{"x":0,"y":-2,"z":2},"block_id":18,"extra_data":{"max_ticks":287}},{"move":{"x":0,"y":-2,"z":3},"block_id":18,"extra_data":{"max_ticks":314}},{"move":{"x":0,"y":-2,"z":4},"block_id":18},{"move":{"x":0,"y":-2,"z":5},"block_id":18},{"move":{"x":0,"y":-2,"z":8},"block_id":18},{"move":{"x":0,"y":-2,"z":9},"block_id":2},{"move":{"x":0,"y":-2,"z":10},"block_id":2},{"move":{"x":0,"y":-2,"z":11},"block_id":18},{"move":{"x":0,"y":-2,"z":12},"block_id":2},{"move":{"x":0,"y":-1,"z":2},"block_id":2},{"move":{"x":0,"y":-1,"z":3},"block_id":550},{"move":{"x":0,"y":-1,"z":4},"block_id":9},{"move":{"x":0,"y":-1,"z":5},"block_id":18},{"move":{"x":0,"y":-1,"z":7},"block_id":18},{"move":{"x":0,"y":-1,"z":8},"block_id":18},{"move":{"x":0,"y":-1,"z":9},"block_id":549},{"move":{"x":0,"y":-1,"z":10},"block_id":2},{"move":{"x":0,"y":-1,"z":11},"block_id":9},{"move":{"x":0,"y":0,"z":2},"block_id":31},{"move":{"x":0,"y":0,"z":3},"block_id":198},{"move":{"x":0,"y":0,"z":4},"block_id":2},{"move":{"x":0,"y":0,"z":5},"block_id":2},{"move":{"x":0,"y":0,"z":6},"block_id":2},{"move":{"x":0,"y":0,"z":7},"block_id":2},{"move":{"x":0,"y":0,"z":8},"block_id":2},{"move":{"x":0,"y":0,"z":9},"block_id":198},{"move":{"x":0,"y":0,"z":10},"block_id":198},{"move":{"x":0,"y":1,"z":4},"block_id":550},{"move":{"x":0,"y":1,"z":7},"block_id":9},{"move":{"x":0,"y":1,"z":8},"block_id":546},{"move":{"x":0,"y":2,"z":7},"block_id":546},{"move":{"x":1,"y":-2,"z":1},"block_id":2},{"move":{"x":1,"y":-2,"z":2},"block_id":18,"extra_data":{"max_ticks":124}},{"move":{"x":1,"y":-2,"z":3},"block_id":18,"extra_data":{"max_ticks":141}},{"move":{"x":1,"y":-2,"z":4},"block_id":18,"extra_data":{"max_ticks":370}},{"move":{"x":1,"y":-2,"z":5},"block_id":18},{"move":{"x":1,"y":-2,"z":9},"block_id":2},{"move":{"x":1,"y":-2,"z":10},"block_id":2},{"move":{"x":1,"y":-2,"z":11},"block_id":2},{"move":{"x":1,"y":-1,"z":2},"block_id":2},{"move":{"x":1,"y":-1,"z":3},"block_id":18},{"move":{"x":1,"y":-1,"z":4},"block_id":18},{"move":{"x":1,"y":-1,"z":5},"block_id":18},{"move":{"x":1,"y":-1,"z":9},"block_id":198},{"move":{"x":1,"y":0,"z":2},"block_id":31},{"move":{"x":1,"y":0,"z":3},"block_id":2},{"move":{"x":1,"y":0,"z":4},"block_id":2},{"move":{"x":1,"y":0,"z":5},"block_id":2},{"move":{"x":1,"y":0,"z":6},"block_id":2},{"move":{"x":1,"y":0,"z":7},"block_id":2},{"move":{"x":1,"y":0,"z":8},"block_id":2},{"move":{"x":1,"y":0,"z":9},"block_id":2},{"move":{"x":1,"y":1,"z":4},"block_id":31},{"move":{"x":1,"y":1,"z":5},"block_id":106,"rotate":{"x":3,"y":0,"z":0}},{"move":{"x":1,"y":1,"z":7},"block_id":106,"rotate":{"x":1,"y":0,"z":0}},{"move":{"x":2,"y":-2,"z":0},"block_id":2},{"move":{"x":2,"y":-2,"z":1},"block_id":2},{"move":{"x":2,"y":-2,"z":2},"block_id":18,"extra_data":{"max_ticks":433}},{"move":{"x":2,"y":-2,"z":3},"block_id":18,"extra_data":{"max_ticks":266}},{"move":{"x":2,"y":-2,"z":4},"block_id":18,"extra_data":{"max_ticks":471}},{"move":{"x":2,"y":-1,"z":1},"block_id":9},{"move":{"x":2,"y":-1,"z":2},"block_id":2},{"move":{"x":2,"y":-1,"z":3},"block_id":549},{"move":{"x":2,"y":-1,"z":4},"block_id":18,"extra_data":{"max_ticks":485}},{"move":{"x":2,"y":-1,"z":5},"block_id":18},{"move":{"x":2,"y":0,"z":2},"block_id":198},{"move":{"x":2,"y":0,"z":3},"block_id":2},{"move":{"x":2,"y":0,"z":5},"block_id":2},{"move":{"x":2,"y":0,"z":6},"block_id":2},{"move":{"x":2,"y":0,"z":7},"block_id":2},{"move":{"x":2,"y":0,"z":8},"block_id":2},{"move":{"x":2,"y":1,"z":3},"block_id":31},{"move":{"x":2,"y":1,"z":4},"block_id":546},{"move":{"x":2,"y":1,"z":5},"block_id":9},{"move":{"x":2,"y":2,"z":5},"block_id":546},{"move":{"x":3,"y":-2,"z":0},"block_id":18},{"move":{"x":3,"y":-2,"z":1},"block_id":2},{"move":{"x":3,"y":-2,"z":2},"block_id":18},{"move":{"x":3,"y":-2,"z":3},"block_id":2},{"move":{"x":3,"y":-2,"z":4},"block_id":18},{"move":{"x":3,"y":-1,"z":0},"block_id":2},{"move":{"x":3,"y":-1,"z":1},"block_id":550},{"move":{"x":3,"y":-1,"z":2},"block_id":549},{"move":{"x":3,"y":-1,"z":3},"block_id":549},{"move":{"x":3,"y":-1,"z":4},"block_id":2},{"move":{"x":3,"y":-1,"z":5},"block_id":18},{"move":{"x":3,"y":-1,"z":6},"block_id":18},{"move":{"x":3,"y":0,"z":0},"block_id":31},{"move":{"x":3,"y":0,"z":1},"block_id":2},{"move":{"x":3,"y":0,"z":2},"block_id":549},{"move":{"x":3,"y":0,"z":3},"block_id":550},{"move":{"x":3,"y":0,"z":4},"block_id":550},{"move":{"x":3,"y":0,"z":5},"block_id":549},{"move":{"x":3,"y":0,"z":6},"block_id":2},{"move":{"x":3,"y":0,"z":7},"block_id":2},{"move":{"x":3,"y":0,"z":8},"block_id":2},{"move":{"x":3,"y":1,"z":4},"block_id":550},{"move":{"x":3,"y":1,"z":5},"block_id":546},{"move":{"x":3,"y":1,"z":6},"block_id":546},{"move":{"x":3,"y":2,"z":4},"block_id":545},{"move":{"x":3,"y":2,"z":5},"block_id":9},{"move":{"x":4,"y":-2,"z":0},"block_id":18,"extra_data":{"max_ticks":152}},{"move":{"x":4,"y":-2,"z":1},"block_id":2},{"move":{"x":4,"y":-2,"z":2},"block_id":2},{"move":{"x":4,"y":-2,"z":3},"block_id":18},{"move":{"x":4,"y":-2,"z":4},"block_id":18},{"move":{"x":4,"y":-2,"z":5},"block_id":18},{"move":{"x":4,"y":-1,"z":0},"block_id":2},{"move":{"x":4,"y":-1,"z":1},"block_id":2},{"move":{"x":4,"y":-1,"z":2},"block_id":549},{"move":{"x":4,"y":-1,"z":3},"block_id":549},{"move":{"x":4,"y":-1,"z":4},"block_id":545},{"move":{"x":4,"y":-1,"z":5},"block_id":18},{"move":{"x":4,"y":-1,"z":6},"block_id":18},{"move":{"x":4,"y":0,"z":0},"block_id":31},{"move":{"x":4,"y":0,"z":2},"block_id":549},{"move":{"x":4,"y":0,"z":3},"block_id":550},{"move":{"x":4,"y":0,"z":4},"block_id":550},{"move":{"x":4,"y":0,"z":5},"block_id":550},{"move":{"x":4,"y":0,"z":6},"block_id":2},{"move":{"x":4,"y":0,"z":7},"block_id":2},{"move":{"x":4,"y":0,"z":8},"block_id":2},{"move":{"x":4,"y":1,"z":3},"block_id":9},{"move":{"x":4,"y":1,"z":4},"block_id":546},{"move":{"x":4,"y":1,"z":5},"block_id":546},{"move":{"x":4,"y":2,"z":4},"block_id":9},{"move":{"x":5,"y":-2,"z":0},"block_id":18,"extra_data":{"max_ticks":169}},{"move":{"x":5,"y":-2,"z":1},"block_id":2},{"move":{"x":5,"y":-2,"z":2},"block_id":2},{"move":{"x":5,"y":-2,"z":3},"block_id":2},{"move":{"x":5,"y":-2,"z":4},"block_id":2},{"move":{"x":5,"y":-2,"z":5},"block_id":18},{"move":{"x":5,"y":-2,"z":6},"block_id":2},{"move":{"x":5,"y":-1,"z":0},"block_id":2},{"move":{"x":5,"y":-1,"z":1},"block_id":550},{"move":{"x":5,"y":-1,"z":2},"block_id":550},{"move":{"x":5,"y":-1,"z":3},"block_id":549},{"move":{"x":5,"y":-1,"z":4},"block_id":550},{"move":{"x":5,"y":-1,"z":5},"block_id":9},{"move":{"x":5,"y":0,"z":2},"block_id":198},{"move":{"x":5,"y":0,"z":3},"block_id":9},{"move":{"x":5,"y":0,"z":4},"block_id":549},{"move":{"x":5,"y":0,"z":5},"block_id":106,"rotate":{"x":1,"y":0,"z":0}},{"move":{"x":5,"y":0,"z":6},"block_id":2},{"move":{"x":5,"y":0,"z":7},"block_id":2},{"move":{"x":5,"y":1,"z":3},"block_id":549},{"move":{"x":5,"y":1,"z":4},"block_id":546},{"move":{"x":5,"y":1,"z":5},"block_id":106,"rotate":{"x":1,"y":0,"z":0}},{"move":{"x":6,"y":-2,"z":0},"block_id":18},{"move":{"x":6,"y":-2,"z":1},"block_id":2},{"move":{"x":6,"y":-2,"z":2},"block_id":18},{"move":{"x":6,"y":-2,"z":3},"block_id":2},{"move":{"x":6,"y":-2,"z":4},"block_id":2},{"move":{"x":6,"y":-2,"z":5},"block_id":18},{"move":{"x":6,"y":-2,"z":6},"block_id":2},{"move":{"x":6,"y":-1,"z":1},"block_id":2},{"move":{"x":6,"y":-1,"z":2},"block_id":2},{"move":{"x":6,"y":-1,"z":3},"block_id":2},{"move":{"x":6,"y":-1,"z":4},"block_id":550},{"move":{"x":6,"y":0,"z":1},"block_id":31},{"move":{"x":6,"y":0,"z":2},"block_id":31},{"move":{"x":6,"y":0,"z":3},"block_id":106,"rotate":{"x":1,"y":0,"z":0}},{"move":{"x":6,"y":0,"z":4},"block_id":2},{"move":{"x":6,"y":0,"z":6},"block_id":2},{"move":{"x":6,"y":1,"z":3},"block_id":106,"rotate":{"x":1,"y":0,"z":0}},{"move":{"x":6,"y":1,"z":4},"block_id":31},{"move":{"x":7,"y":-2,"z":1},"block_id":2},{"move":{"x":7,"y":-2,"z":2},"block_id":18},{"move":{"x":7,"y":-2,"z":3},"block_id":18},{"move":{"x":7,"y":-2,"z":4},"block_id":2},{"move":{"x":7,"y":-2,"z":5},"block_id":2},{"move":{"x":7,"y":-2,"z":6},"block_id":2},{"move":{"x":7,"y":-2,"z":7},"block_id":2},{"move":{"x":7,"y":-1,"z":2},"block_id":2},{"move":{"x":7,"y":-1,"z":3},"block_id":2},{"move":{"x":7,"y":-1,"z":6},"block_id":9}],"rot":[],"fluids":[]}