{"name":"structure1","world":{"pos1":{"x":-215,"y":1,"z":16},"pos2":{"x":-221,"y":8,"z":10},"entrance":{"x":-218,"y":1,"z":13}},"meta":{},"size":{"x":7,"y":8,"z":7},"door_pos":{"x":3,"y":0,"z":3},"blocks":[{"move":{"x":-3,"y":0,"z":0},"block_id":106,"extra_data":{"east":true,"rotate":false}},{"move":{"x":-3,"y":0,"z":1},"block_id":2},{"move":{"x":-3,"y":1,"z":0},"block_id":106,"extra_data":{"east":true,"rotate":false}},{"move":{"x":-2,"y":0,"z":-2},"block_id":233},{"move":{"x":-2,"y":0,"z":-1},"block_id":8},{"move":{"x":-2,"y":0,"z":0},"block_id":18},{"move":{"x":-2,"y":0,"z":1},"block_id":8},{"move":{"x":-2,"y":0,"z":2},"block_id":2},{"move":{"x":-2,"y":1,"z":-1},"block_id":106,"extra_data":{"east":true,"rotate":false}},{"move":{"x":-2,"y":1,"z":0},"block_id":8},{"move":{"x":-2,"y":1,"z":1},"block_id":2},{"move":{"x":-1,"y":0,"z":-2},"block_id":146},{"move":{"x":-1,"y":0,"z":-1},"block_id":18},{"move":{"x":-1,"y":0,"z":0},"block_id":18},{"move":{"x":-1,"y":0,"z":1},"block_id":18},{"move":{"x":-1,"y":0,"z":2},"block_id":146},{"move":{"x":-1,"y":1,"z":-2},"block_id":106,"extra_data":{"north":true,"rotate":false}},{"move":{"x":-1,"y":1,"z":-1},"block_id":8},{"move":{"x":-1,"y":1,"z":0},"block_id":8},{"move":{"x":-1,"y":1,"z":1},"block_id":545},{"move":{"x":-1,"y":2,"z":-1},"block_id":106,"extra_data":{"up":true,"rotate":false}},{"move":{"x":-1,"y":2,"z":0},"block_id":2},{"move":{"x":0,"y":0,"z":-2},"block_id":545},{"move":{"x":0,"y":0,"z":-1},"block_id":18},{"move":{"x":0,"y":0,"z":0},"block_id":18},{"move":{"x":0,"y":0,"z":1},"block_id":18},{"move":{"x":0,"y":0,"z":2},"block_id":233},{"move":{"x":0,"y":1,"z":-1},"block_id":8},{"move":{"x":0,"y":1,"z":0},"block_id":146},{"move":{"x":0,"y":1,"z":1},"block_id":146},{"move":{"x":0,"y":2,"z":0},"block_id":146},{"move":{"x":0,"y":2,"z":1},"block_id":106,"extra_data":{"south":true,"rotate":false}},{"move":{"x":0,"y":3,"z":0},"block_id":146},{"move":{"x":0,"y":3,"z":1},"block_id":106,"extra_data":{"south":true,"rotate":false}},{"move":{"x":0,"y":4,"z":0},"block_id":146},{"move":{"x":0,"y":5,"z":0},"block_id":8},{"move":{"x":0,"y":6,"z":0},"block_id":106,"extra_data":{"up":true,"rotate":true}},{"move":{"x":1,"y":0,"z":-1},"block_id":546},{"move":{"x":1,"y":0,"z":0},"block_id":2},{"move":{"x":1,"y":0,"z":1},"block_id":18},{"move":{"x":1,"y":0,"z":2},"block_id":18},{"move":{"x":1,"y":0,"z":3},"block_id":545},{"move":{"x":1,"y":1,"z":0},"block_id":106,"extra_data":{"west":true,"rotate":false,"up":true}},{"move":{"x":1,"y":1,"z":1},"block_id":545},{"move":{"x":1,"y":1,"z":2},"block_id":545},{"move":{"x":1,"y":2,"z":0},"block_id":106,"extra_data":{"north":true,"rotate":false}},{"move":{"x":1,"y":2,"z":1},"block_id":545},{"move":{"x":1,"y":2,"z":2},"block_id":106,"extra_data":{"south":true,"rotate":true,"up":true}},{"move":{"x":1,"y":3,"z":0},"block_id":106,"extra_data":{"north":true,"rotate":false}},{"move":{"x":1,"y":3,"z":1},"block_id":545},{"move":{"x":1,"y":3,"z":2},"block_id":106,"extra_data":{"south":true,"rotate":false}},{"move":{"x":1,"y":4,"z":0},"block_id":106,"extra_data":{"west":true,"rotate":false,"north":true}},{"move":{"x":1,"y":4,"z":1},"block_id":545},{"move":{"x":1,"y":4,"z":2},"block_id":106,"extra_data":{"south":true,"rotate":false}},{"move":{"x":1,"y":5,"z":0},"block_id":106,"extra_data":{"west":true,"rotate":false}},{"move":{"x":1,"y":5,"z":1},"block_id":146},{"move":{"x":1,"y":6,"z":1},"block_id":146},{"move":{"x":1,"y":7,"z":1},"block_id":545},{"move":{"x":2,"y":0,"z":0},"block_id":106,"extra_data":{"west":true,"rotate":false}},{"move":{"x":2,"y":0,"z":1},"block_id":546},{"move":{"x":2,"y":0,"z":2},"block_id":546},{"move":{"x":2,"y":0,"z":3},"block_id":545},{"move":{"x":2,"y":1,"z":2},"block_id":106,"extra_data":{"west":true,"rotate":true,"up":true}},{"move":{"x":2,"y":4,"z":1},"block_id":106,"extra_data":{"west":true,"rotate":false}},{"move":{"x":2,"y":5,"z":1},"block_id":106,"extra_data":{"west":true,"rotate":false}},{"move":{"x":2,"y":6,"z":1},"block_id":106,"extra_data":{"west":true,"rotate":false}},{"move":{"x":3,"y":0,"z":2},"block_id":546}],"rot":[]}