{"name":"structure6","world":{"pos1":{"x":-356,"y":1,"z":16},"pos2":{"x":-364,"y":8,"z":7},"entrance":{"x":-360,"y":1,"z":16}},"size":{"x":9,"y":8,"z":10},"door_pos":{"x":4,"y":0,"z":0},"blocks":[{"move":{"x":-3,"y":0,"z":3},"block_id":220},{"move":{"x":-3,"y":0,"z":4},"block_id":8},{"move":{"x":-3,"y":1,"z":4},"block_id":8},{"move":{"x":-3,"y":1,"z":5},"block_id":8},{"move":{"x":-3,"y":2,"z":4},"block_id":9},{"move":{"x":-2,"y":0,"z":1},"block_id":220},{"move":{"x":-2,"y":0,"z":3},"block_id":9},{"move":{"x":-2,"y":0,"z":4},"block_id":9},{"move":{"x":-2,"y":0,"z":5},"block_id":15},{"move":{"x":-2,"y":0,"z":6},"block_id":9},{"move":{"x":-2,"y":0,"z":7},"block_id":8},{"move":{"x":-2,"y":0,"z":8},"block_id":220},{"move":{"x":-2,"y":1,"z":4},"block_id":9},{"move":{"x":-2,"y":1,"z":5},"block_id":9},{"move":{"x":-2,"y":1,"z":6},"block_id":8},{"move":{"x":-2,"y":2,"z":3},"block_id":8},{"move":{"x":-2,"y":2,"z":4},"block_id":9},{"move":{"x":-2,"y":2,"z":5},"block_id":15},{"move":{"x":-2,"y":2,"z":6},"block_id":220},{"move":{"x":-2,"y":3,"z":4},"block_id":8},{"move":{"x":-2,"y":3,"z":5},"block_id":220},{"move":{"x":-1,"y":0,"z":1},"block_id":220},{"move":{"x":-1,"y":0,"z":2},"block_id":146},{"move":{"x":-1,"y":0,"z":3},"block_id":9},{"move":{"x":-1,"y":0,"z":4},"block_id":9},{"move":{"x":-1,"y":0,"z":5},"block_id":9},{"move":{"x":-1,"y":0,"z":6},"block_id":9},{"move":{"x":-1,"y":0,"z":7},"block_id":9},{"move":{"x":-1,"y":1,"z":2},"block_id":220},{"move":{"x":-1,"y":1,"z":3},"block_id":8},{"move":{"x":-1,"y":1,"z":4},"block_id":9},{"move":{"x":-1,"y":1,"z":5},"block_id":9},{"move":{"x":-1,"y":1,"z":6},"block_id":8},{"move":{"x":-1,"y":1,"z":7},"block_id":220},{"move":{"x":-1,"y":2,"z":3},"block_id":9},{"move":{"x":-1,"y":2,"z":4},"block_id":9},{"move":{"x":-1,"y":2,"z":5},"block_id":9},{"move":{"x":-1,"y":2,"z":6},"block_id":8},{"move":{"x":-1,"y":3,"z":3},"block_id":2},{"move":{"x":-1,"y":3,"z":4},"block_id":8},{"move":{"x":-1,"y":3,"z":5},"block_id":146},{"move":{"x":-1,"y":3,"z":6},"block_id":2},{"move":{"x":-1,"y":4,"z":3},"block_id":36},{"move":{"x":-1,"y":4,"z":5},"block_id":9},{"move":{"x":-1,"y":4,"z":6},"block_id":31},{"move":{"x":0,"y":0,"z":1},"block_id":9},{"move":{"x":0,"y":0,"z":2},"block_id":9},{"move":{"x":0,"y":0,"z":3},"block_id":9},{"move":{"x":0,"y":0,"z":4},"block_id":9},{"move":{"x":0,"y":0,"z":5},"block_id":9},{"move":{"x":0,"y":0,"z":6},"block_id":9},{"move":{"x":0,"y":0,"z":7},"block_id":9},{"move":{"x":0,"y":0,"z":8},"block_id":8},{"move":{"x":0,"y":1,"z":1},"block_id":8},{"move":{"x":0,"y":1,"z":2},"block_id":15},{"move":{"x":0,"y":1,"z":3},"block_id":9},{"move":{"x":0,"y":1,"z":4},"block_id":9},{"move":{"x":0,"y":1,"z":5},"block_id":9},{"move":{"x":0,"y":1,"z":6},"block_id":9},{"move":{"x":0,"y":1,"z":7},"block_id":2},{"move":{"x":0,"y":2,"z":1},"block_id":220},{"move":{"x":0,"y":2,"z":2},"block_id":146},{"move":{"x":0,"y":2,"z":3},"block_id":146},{"move":{"x":0,"y":2,"z":4},"block_id":9},{"move":{"x":0,"y":2,"z":5},"block_id":9},{"move":{"x":0,"y":2,"z":6},"block_id":146},{"move":{"x":0,"y":2,"z":7},"block_id":31},{"move":{"x":0,"y":3,"z":2},"block_id":8},{"move":{"x":0,"y":3,"z":3},"block_id":9},{"move":{"x":0,"y":3,"z":4},"block_id":9},{"move":{"x":0,"y":3,"z":5},"block_id":2},{"move":{"x":0,"y":3,"z":6},"block_id":146},{"move":{"x":0,"y":4,"z":3},"block_id":8},{"move":{"x":0,"y":4,"z":4},"block_id":8},{"move":{"x":0,"y":4,"z":5},"block_id":31},{"move":{"x":1,"y":0,"z":1},"block_id":146},{"move":{"x":1,"y":0,"z":2},"block_id":9},{"move":{"x":1,"y":0,"z":3},"block_id":9},{"move":{"x":1,"y":0,"z":4},"block_id":9},{"move":{"x":1,"y":0,"z":5},"block_id":9},{"move":{"x":1,"y":0,"z":6},"block_id":9},{"move":{"x":1,"y":0,"z":7},"block_id":9},{"move":{"x":1,"y":0,"z":8},"block_id":220},{"move":{"x":1,"y":1,"z":2},"block_id":9},{"move":{"x":1,"y":1,"z":3},"block_id":9},{"move":{"x":1,"y":1,"z":4},"block_id":9},{"move":{"x":1,"y":1,"z":5},"block_id":9},{"move":{"x":1,"y":1,"z":6},"block_id":9},{"move":{"x":1,"y":1,"z":7},"block_id":9},{"move":{"x":1,"y":2,"z":2},"block_id":9},{"move":{"x":1,"y":2,"z":3},"block_id":9},{"move":{"x":1,"y":2,"z":4},"block_id":9},{"move":{"x":1,"y":2,"z":5},"block_id":9},{"move":{"x":1,"y":2,"z":6},"block_id":146},{"move":{"x":1,"y":2,"z":7},"block_id":8},{"move":{"x":1,"y":3,"z":3},"block_id":15},{"move":{"x":1,"y":3,"z":4},"block_id":9},{"move":{"x":1,"y":3,"z":5},"block_id":2},{"move":{"x":1,"y":3,"z":6},"block_id":15},{"move":{"x":1,"y":4,"z":4},"block_id":2},{"move":{"x":1,"y":4,"z":5},"block_id":31},{"move":{"x":1,"y":5,"z":4},"block_id":31},{"move":{"x":2,"y":0,"z":2},"block_id":9},{"move":{"x":2,"y":0,"z":3},"block_id":8},{"move":{"x":2,"y":0,"z":4},"block_id":9},{"move":{"x":2,"y":0,"z":5},"block_id":9},{"move":{"x":2,"y":0,"z":6},"block_id":9},{"move":{"x":2,"y":0,"z":7},"block_id":8},{"move":{"x":2,"y":1,"z":2},"block_id":8},{"move":{"x":2,"y":1,"z":3},"block_id":146},{"move":{"x":2,"y":1,"z":4},"block_id":8},{"move":{"x":2,"y":1,"z":5},"block_id":9},{"move":{"x":2,"y":1,"z":6},"block_id":9},{"move":{"x":2,"y":1,"z":7},"block_id":220},{"move":{"x":2,"y":2,"z":3},"block_id":8},{"move":{"x":2,"y":2,"z":4},"block_id":9},{"move":{"x":2,"y":2,"z":5},"block_id":2},{"move":{"x":2,"y":2,"z":6},"block_id":220},{"move":{"x":2,"y":3,"z":4},"block_id":15},{"move":{"x":2,"y":3,"z":5},"block_id":31},{"move":{"x":3,"y":0,"z":4},"block_id":15},{"move":{"x":3,"y":0,"z":5},"block_id":9},{"move":{"x":3,"y":0,"z":6},"block_id":9},{"move":{"x":3,"y":0,"z":7},"block_id":220},{"move":{"x":3,"y":0,"z":8},"block_id":220},{"move":{"x":3,"y":1,"z":5},"block_id":8},{"move":{"x":4,"y":0,"z":5},"block_id":9}],"rot":[],"fluids":[]}