{"name":"structure4","world":{"pos1":{"x":-318,"y":-8,"z":37},"pos2":{"x":-333,"y":6,"z":7},"entrance":{"x":-325,"y":1,"z":37}},"size":{"x":16,"y":15,"z":31},"door_pos":{"x":7,"y":9,"z":0},"blocks":[{"move":{"x":-7,"y":-2,"z":12},"block_id":18,"extra_data":{"max_ticks":368}},{"move":{"x":-7,"y":-2,"z":17},"block_id":18,"extra_data":{"max_ticks":93}},{"move":{"x":-7,"y":-2,"z":18},"block_id":18,"extra_data":{"max_ticks":144}},{"move":{"x":-7,"y":-2,"z":19},"block_id":18,"extra_data":{"max_ticks":105}},{"move":{"x":-7,"y":-2,"z":20},"block_id":18,"extra_data":{"max_ticks":426}},{"move":{"x":-7,"y":-2,"z":21},"block_id":18},{"move":{"x":-7,"y":-2,"z":22},"block_id":18,"extra_data":{"max_ticks":205}},{"move":{"x":-7,"y":-2,"z":23},"block_id":18,"extra_data":{"max_ticks":188}},{"move":{"x":-7,"y":-1,"z":12},"block_id":9},{"move":{"x":-7,"y":-1,"z":16},"block_id":9},{"move":{"x":-7,"y":-1,"z":17},"block_id":9},{"move":{"x":-7,"y":-1,"z":18},"block_id":9},{"move":{"x":-7,"y":-1,"z":19},"block_id":9},{"move":{"x":-7,"y":-1,"z":20},"block_id":9},{"move":{"x":-7,"y":-1,"z":21},"block_id":9},{"move":{"x":-7,"y":-1,"z":22},"block_id":9},{"move":{"x":-7,"y":-1,"z":23},"block_id":9},{"move":{"x":-7,"y":-1,"z":25},"block_id":18},{"move":{"x":-7,"y":0,"z":14},"block_id":9},{"move":{"x":-7,"y":0,"z":17},"block_id":9},{"move":{"x":-7,"y":0,"z":20},"block_id":9},{"move":{"x":-7,"y":0,"z":21},"block_id":9},{"move":{"x":-7,"y":0,"z":22},"block_id":9},{"move":{"x":-7,"y":0,"z":25},"block_id":9},{"move":{"x":-6,"y":-3,"z":18},"block_id":9},{"move":{"x":-6,"y":-3,"z":19},"block_id":9},{"move":{"x":-6,"y":-3,"z":20},"block_id":9},{"move":{"x":-6,"y":-3,"z":21},"block_id":9},{"move":{"x":-6,"y":-2,"z":10},"block_id":18,"extra_data":{"max_ticks":390}},{"move":{"x":-6,"y":-2,"z":14},"block_id":18},{"move":{"x":-6,"y":-2,"z":16},"block_id":18,"extra_data":{"max_ticks":202}},{"move":{"x":-6,"y":-2,"z":17},"block_id":18,"extra_data":{"max_ticks":448}},{"move":{"x":-6,"y":-2,"z":18},"block_id":9},{"move":{"x":-6,"y":-2,"z":19},"block_id":9},{"move":{"x":-6,"y":-2,"z":20},"block_id":90},{"move":{"x":-6,"y":-2,"z":21},"block_id":9},{"move":{"x":-6,"y":-2,"z":22},"block_id":2},{"move":{"x":-6,"y":-2,"z":23},"block_id":18,"extra_data":{"max_ticks":154}},{"move":{"x":-6,"y":-1,"z":10},"block_id":9},{"move":{"x":-6,"y":-1,"z":11},"block_id":18},{"move":{"x":-6,"y":-1,"z":14},"block_id":9},{"move":{"x":-6,"y":-1,"z":15},"block_id":9},{"move":{"x":-6,"y":-1,"z":16},"block_id":9},{"move":{"x":-6,"y":-1,"z":17},"block_id":90},{"move":{"x":-6,"y":-1,"z":18},"block_id":90},{"move":{"x":-6,"y":-1,"z":19},"block_id":9},{"move":{"x":-6,"y":-1,"z":20},"block_id":90},{"move":{"x":-6,"y":-1,"z":21},"block_id":90},{"move":{"x":-6,"y":-1,"z":22},"block_id":90},{"move":{"x":-6,"y":-1,"z":23},"block_id":9},{"move":{"x":-6,"y":-1,"z":24},"block_id":9},{"move":{"x":-6,"y":-1,"z":25},"block_id":9},{"move":{"x":-6,"y":-1,"z":27},"block_id":18},{"move":{"x":-6,"y":0,"z":11},"block_id":9},{"move":{"x":-6,"y":0,"z":15},"block_id":9},{"move":{"x":-6,"y":0,"z":18},"block_id":9},{"move":{"x":-6,"y":0,"z":19},"block_id":9},{"move":{"x":-6,"y":0,"z":20},"block_id":9},{"move":{"x":-6,"y":0,"z":21},"block_id":9},{"move":{"x":-6,"y":0,"z":22},"block_id":9},{"move":{"x":-6,"y":0,"z":23},"block_id":9},{"move":{"x":-6,"y":0,"z":24},"block_id":9},{"move":{"x":-6,"y":0,"z":25},"block_id":9},{"move":{"x":-6,"y":0,"z":27},"block_id":9},{"move":{"x":-6,"y":1,"z":20},"block_id":9},{"move":{"x":-6,"y":1,"z":21},"block_id":9},{"move":{"x":-6,"y":1,"z":22},"block_id":9},{"move":{"x":-6,"y":1,"z":23},"block_id":9},{"move":{"x":-6,"y":2,"z":21},"block_id":9},{"move":{"x":-5,"y":-5,"z":19},"block_id":9},{"move":{"x":-5,"y":-5,"z":20},"block_id":9},{"move":{"x":-5,"y":-5,"z":21},"block_id":9},{"move":{"x":-5,"y":-4,"z":18},"block_id":9},{"move":{"x":-5,"y":-4,"z":19},"block_id":15},{"move":{"x":-5,"y":-4,"z":20},"block_id":88},{"move":{"x":-5,"y":-4,"z":21},"block_id":90},{"move":{"x":-5,"y":-4,"z":22},"block_id":9},{"move":{"x":-5,"y":-4,"z":23},"block_id":9},{"move":{"x":-5,"y":-3,"z":16},"block_id":9},{"move":{"x":-5,"y":-3,"z":17},"block_id":9},{"move":{"x":-5,"y":-3,"z":18},"block_id":90},{"move":{"x":-5,"y":-3,"z":19},"block_id":90},{"move":{"x":-5,"y":-3,"z":20},"block_id":87},{"move":{"x":-5,"y":-3,"z":21},"block_id":88},{"move":{"x":-5,"y":-3,"z":22},"block_id":90},{"move":{"x":-5,"y":-3,"z":23},"block_id":90},{"move":{"x":-5,"y":-2,"z":8},"block_id":18,"extra_data":{"max_ticks":402}},{"move":{"x":-5,"y":-2,"z":16},"block_id":9},{"move":{"x":-5,"y":-2,"z":17},"block_id":9},{"move":{"x":-5,"y":-2,"z":20},"block_id":506},{"move":{"x":-5,"y":-2,"z":22},"block_id":9},{"move":{"x":-5,"y":-2,"z":23},"block_id":90},{"move":{"x":-5,"y":-2,"z":24},"block_id":18,"extra_data":{"max_ticks":483}},{"move":{"x":-5,"y":-2,"z":25},"block_id":18,"extra_data":{"max_ticks":184}},{"move":{"x":-5,"y":-2,"z":26},"block_id":18,"extra_data":{"max_ticks":130}},{"move":{"x":-5,"y":-1,"z":8},"block_id":9},{"move":{"x":-5,"y":-1,"z":9},"block_id":2},{"move":{"x":-5,"y":-1,"z":10},"block_id":2},{"move":{"x":-5,"y":-1,"z":13},"block_id":9},{"move":{"x":-5,"y":-1,"z":14},"block_id":9},{"move":{"x":-5,"y":-1,"z":15},"block_id":90},{"move":{"x":-5,"y":-1,"z":22},"block_id":9},{"move":{"x":-5,"y":-1,"z":23},"block_id":9},{"move":{"x":-5,"y":-1,"z":24},"block_id":90},{"move":{"x":-5,"y":-1,"z":25},"block_id":9},{"move":{"x":-5,"y":-1,"z":26},"block_id":9},{"move":{"x":-5,"y":-1,"z":29},"block_id":18,"extra_data":{"max_ticks":284}},{"move":{"x":-5,"y":0,"z":10},"block_id":9},{"move":{"x":-5,"y":0,"z":13},"block_id":9},{"move":{"x":-5,"y":0,"z":14},"block_id":9},{"move":{"x":-5,"y":0,"z":23},"block_id":90},{"move":{"x":-5,"y":0,"z":24},"block_id":9},{"move":{"x":-5,"y":0,"z":25},"block_id":9},{"move":{"x":-5,"y":0,"z":26},"block_id":9},{"move":{"x":-5,"y":0,"z":29},"block_id":9},{"move":{"x":-5,"y":1,"z":23},"block_id":9},{"move":{"x":-5,"y":1,"z":24},"block_id":9},{"move":{"x":-5,"y":1,"z":25},"block_id":9},{"move":{"x":-5,"y":1,"z":26},"block_id":9},{"move":{"x":-5,"y":2,"z":24},"block_id":9},{"move":{"x":-5,"y":2,"z":25},"block_id":9},{"move":{"x":-4,"y":-7,"z":23},"block_id":9},{"move":{"x":-4,"y":-6,"z":19},"block_id":9},{"move":{"x":-4,"y":-6,"z":20},"block_id":9},{"move":{"x":-4,"y":-6,"z":21},"block_id":9},{"move":{"x":-4,"y":-6,"z":22},"block_id":9},{"move":{"x":-4,"y":-6,"z":23},"block_id":90},{"move":{"x":-4,"y":-5,"z":17},"block_id":9},{"move":{"x":-4,"y":-5,"z":18},"block_id":9},{"move":{"x":-4,"y":-5,"z":19},"block_id":88},{"move":{"x":-4,"y":-5,"z":20},"block_id":90},{"move":{"x":-4,"y":-5,"z":21},"block_id":88},{"move":{"x":-4,"y":-5,"z":22},"block_id":90},{"move":{"x":-4,"y":-5,"z":23},"block_id":90},{"move":{"x":-4,"y":-4,"z":16},"block_id":9},{"move":{"x":-4,"y":-4,"z":17},"block_id":90},{"move":{"x":-4,"y":-4,"z":18},"block_id":88},{"move":{"x":-4,"y":-4,"z":20},"block_id":88},{"move":{"x":-4,"y":-4,"z":22},"block_id":90},{"move":{"x":-4,"y":-4,"z":23},"block_id":88},{"move":{"x":-4,"y":-4,"z":24},"block_id":9},{"move":{"x":-4,"y":-3,"z":16},"block_id":90},{"move":{"x":-4,"y":-3,"z":17},"block_id":90},{"move":{"x":-4,"y":-3,"z":20},"block_id":90},{"move":{"x":-4,"y":-3,"z":22},"block_id":88},{"move":{"x":-4,"y":-3,"z":24},"block_id":90},{"move":{"x":-4,"y":-2,"z":3},"block_id":18,"extra_data":{"max_ticks":189}},{"move":{"x":-4,"y":-2,"z":9},"block_id":18},{"move":{"x":-4,"y":-2,"z":10},"block_id":18},{"move":{"x":-4,"y":-2,"z":15},"block_id":90},{"move":{"x":-4,"y":-2,"z":16},"block_id":90},{"move":{"x":-4,"y":-2,"z":24},"block_id":15},{"move":{"x":-4,"y":-2,"z":25},"block_id":18,"extra_data":{"max_ticks":200}},{"move":{"x":-4,"y":-2,"z":26},"block_id":18},{"move":{"x":-4,"y":-2,"z":27},"block_id":18},{"move":{"x":-4,"y":-1,"z":3},"block_id":9},{"move":{"x":-4,"y":-1,"z":8},"block_id":2},{"move":{"x":-4,"y":-1,"z":10},"block_id":9},{"move":{"x":-4,"y":-1,"z":11},"block_id":87},{"move":{"x":-4,"y":-1,"z":12},"block_id":9},{"move":{"x":-4,"y":-1,"z":13},"block_id":90},{"move":{"x":-4,"y":-1,"z":14},"block_id":90},{"move":{"x":-4,"y":-1,"z":24},"block_id":9},{"move":{"x":-4,"y":-1,"z":25},"block_id":9},{"move":{"x":-4,"y":-1,"z":26},"block_id":9},{"move":{"x":-4,"y":-1,"z":27},"block_id":9},{"move":{"x":-4,"y":-1,"z":28},"block_id":18,"extra_data":{"max_ticks":109}},{"move":{"x":-4,"y":-1,"z":30},"block_id":18,"extra_data":{"max_ticks":151}},{"move":{"x":-4,"y":0,"z":11},"block_id":506},{"move":{"x":-4,"y":0,"z":25},"block_id":9},{"move":{"x":-4,"y":0,"z":26},"block_id":9},{"move":{"x":-4,"y":0,"z":27},"block_id":9},{"move":{"x":-4,"y":0,"z":28},"block_id":9},{"move":{"x":-4,"y":0,"z":30},"block_id":9},{"move":{"x":-4,"y":1,"z":25},"block_id":9},{"move":{"x":-4,"y":1,"z":26},"block_id":9},{"move":{"x":-4,"y":1,"z":27},"block_id":9},{"move":{"x":-4,"y":2,"z":26},"block_id":9},{"move":{"x":-3,"y":-8,"z":20},"block_id":9},{"move":{"x":-3,"y":-8,"z":21},"block_id":9},{"move":{"x":-3,"y":-8,"z":23},"block_id":9},{"move":{"x":-3,"y":-7,"z":19},"block_id":9},{"move":{"x":-3,"y":-7,"z":20},"block_id":9},{"move":{"x":-3,"y":-7,"z":21},"block_id":9},{"move":{"x":-3,"y":-7,"z":22},"block_id":9},{"move":{"x":-3,"y":-7,"z":23},"block_id":90},{"move":{"x":-3,"y":-7,"z":24},"block_id":9},{"move":{"x":-3,"y":-6,"z":17},"block_id":9},{"move":{"x":-3,"y":-6,"z":18},"block_id":9},{"move":{"x":-3,"y":-6,"z":19},"block_id":9},{"move":{"x":-3,"y":-6,"z":20},"block_id":15},{"move":{"x":-3,"y":-6,"z":21},"block_id":88},{"move":{"x":-3,"y":-6,"z":22},"block_id":90},{"move":{"x":-3,"y":-6,"z":24},"block_id":90},{"move":{"x":-3,"y":-5,"z":15},"block_id":9},{"move":{"x":-3,"y":-5,"z":16},"block_id":9},{"move":{"x":-3,"y":-5,"z":17},"block_id":90},{"move":{"x":-3,"y":-5,"z":18},"block_id":87},{"move":{"x":-3,"y":-5,"z":19},"block_id":90},{"move":{"x":-3,"y":-5,"z":20},"block_id":90},{"move":{"x":-3,"y":-5,"z":22},"block_id":88},{"move":{"x":-3,"y":-5,"z":24},"block_id":88},{"move":{"x":-3,"y":-4,"z":14},"block_id":9},{"move":{"x":-3,"y":-4,"z":15},"block_id":15},{"move":{"x":-3,"y":-4,"z":16},"block_id":88},{"move":{"x":-3,"y":-4,"z":18},"block_id":506},{"move":{"x":-3,"y":-4,"z":24},"block_id":88},{"move":{"x":-3,"y":-4,"z":25},"block_id":9},{"move":{"x":-3,"y":-3,"z":12},"block_id":9},{"move":{"x":-3,"y":-3,"z":14},"block_id":9},{"move":{"x":-3,"y":-3,"z":15},"block_id":90},{"move":{"x":-3,"y":-3,"z":25},"block_id":90},{"move":{"x":-3,"y":-3,"z":26},"block_id":9},{"move":{"x":-3,"y":-2,"z":1},"block_id":18},{"move":{"x":-3,"y":-2,"z":6},"block_id":18,"extra_data":{"max_ticks":157}},{"move":{"x":-3,"y":-2,"z":8},"block_id":18},{"move":{"x":-3,"y":-2,"z":10},"block_id":18,"extra_data":{"max_ticks":220}},{"move":{"x":-3,"y":-2,"z":11},"block_id":18,"extra_data":{"max_ticks":237}},{"move":{"x":-3,"y":-2,"z":12},"block_id":9},{"move":{"x":-3,"y":-2,"z":13},"block_id":90},{"move":{"x":-3,"y":-2,"z":14},"block_id":90},{"move":{"x":-3,"y":-2,"z":25},"block_id":90},{"move":{"x":-3,"y":-2,"z":26},"block_id":9},{"move":{"x":-3,"y":-2,"z":27},"block_id":2},{"move":{"x":-3,"y":-2,"z":28},"block_id":18,"extra_data":{"max_ticks":424}},{"move":{"x":-3,"y":-1,"z":1},"block_id":9},{"move":{"x":-3,"y":-1,"z":5},"block_id":18,"extra_data":{"max_ticks":406}},{"move":{"x":-3,"y":-1,"z":6},"block_id":9},{"move":{"x":-3,"y":-1,"z":7},"block_id":2},{"move":{"x":-3,"y":-1,"z":8},"block_id":9},{"move":{"x":-3,"y":-1,"z":9},"block_id":9},{"move":{"x":-3,"y":-1,"z":10},"block_id":90},{"move":{"x":-3,"y":-1,"z":11},"block_id":90},{"move":{"x":-3,"y":-1,"z":26},"block_id":90},{"move":{"x":-3,"y":-1,"z":27},"block_id":9},{"move":{"x":-3,"y":-1,"z":28},"block_id":9},{"move":{"x":-3,"y":-1,"z":29},"block_id":18,"extra_data":{"max_ticks":268}},{"move":{"x":-3,"y":0,"z":5},"block_id":9},{"move":{"x":-3,"y":0,"z":9},"block_id":9},{"move":{"x":-3,"y":0,"z":26},"block_id":9},{"move":{"x":-3,"y":0,"z":27},"block_id":9},{"move":{"x":-3,"y":0,"z":28},"block_id":9},{"move":{"x":-3,"y":0,"z":29},"block_id":9},{"move":{"x":-3,"y":1,"z":27},"block_id":90},{"move":{"x":-3,"y":1,"z":28},"block_id":9},{"move":{"x":-3,"y":2,"z":27},"block_id":9},{"move":{"x":-3,"y":3,"z":26},"block_id":9},{"move":{"x":-2,"y":-8,"z":17},"block_id":9},{"move":{"x":-2,"y":-8,"z":18},"block_id":9},{"move":{"x":-2,"y":-8,"z":19},"block_id":9},{"move":{"x":-2,"y":-8,"z":20},"block_id":9},{"move":{"x":-2,"y":-8,"z":21},"block_id":9},{"move":{"x":-2,"y":-8,"z":22},"block_id":9},{"move":{"x":-2,"y":-8,"z":23},"block_id":9},{"move":{"x":-2,"y":-7,"z":16},"block_id":9},{"move":{"x":-2,"y":-7,"z":17},"block_id":9},{"move":{"x":-2,"y":-7,"z":18},"block_id":9},{"move":{"x":-2,"y":-7,"z":24},"block_id":9},{"move":{"x":-2,"y":-6,"z":15},"block_id":9},{"move":{"x":-2,"y":-6,"z":16},"block_id":9},{"move":{"x":-2,"y":-6,"z":18},"block_id":9},{"move":{"x":-2,"y":-6,"z":19},"block_id":88},{"move":{"x":-2,"y":-6,"z":22},"block_id":88},{"move":{"x":-2,"y":-6,"z":23},"block_id":88},{"move":{"x":-2,"y":-6,"z":24},"block_id":90},{"move":{"x":-2,"y":-6,"z":25},"block_id":9},{"move":{"x":-2,"y":-5,"z":14},"block_id":9},{"move":{"x":-2,"y":-5,"z":15},"block_id":90},{"move":{"x":-2,"y":-5,"z":16},"block_id":87},{"move":{"x":-2,"y":-5,"z":17},"block_id":88},{"move":{"x":-2,"y":-5,"z":18},"block_id":90},{"move":{"x":-2,"y":-5,"z":24},"block_id":90},{"move":{"x":-2,"y":-5,"z":25},"block_id":88},{"move":{"x":-2,"y":-5,"z":26},"block_id":9},{"move":{"x":-2,"y":-4,"z":12},"block_id":9},{"move":{"x":-2,"y":-4,"z":13},"block_id":9},{"move":{"x":-2,"y":-4,"z":14},"block_id":90},{"move":{"x":-2,"y":-4,"z":16},"block_id":506},{"move":{"x":-2,"y":-4,"z":18},"block_id":88},{"move":{"x":-2,"y":-4,"z":25},"block_id":90},{"move":{"x":-2,"y":-4,"z":26},"block_id":88},{"move":{"x":-2,"y":-3,"z":9},"block_id":9},{"move":{"x":-2,"y":-3,"z":10},"block_id":9},{"move":{"x":-2,"y":-3,"z":11},"block_id":9},{"move":{"x":-2,"y":-3,"z":12},"block_id":87},{"move":{"x":-2,"y":-3,"z":13},"block_id":90},{"move":{"x":-2,"y":-3,"z":26},"block_id":90},{"move":{"x":-2,"y":-3,"z":27},"block_id":9},{"move":{"x":-2,"y":-2,"z":2},"block_id":18},{"move":{"x":-2,"y":-2,"z":3},"block_id":18},{"move":{"x":-2,"y":-2,"z":4},"block_id":18,"extra_data":{"max_ticks":439}},{"move":{"x":-2,"y":-2,"z":7},"block_id":18},{"move":{"x":-2,"y":-2,"z":8},"block_id":2},{"move":{"x":-2,"y":-2,"z":9},"block_id":90},{"move":{"x":-2,"y":-2,"z":10},"block_id":90},{"move":{"x":-2,"y":-2,"z":11},"block_id":9},{"move":{"x":-2,"y":-2,"z":12},"block_id":506},{"move":{"x":-2,"y":-2,"z":27},"block_id":90},{"move":{"x":-2,"y":-2,"z":28},"block_id":18,"extra_data":{"max_ticks":174}},{"move":{"x":-2,"y":-1,"z":2},"block_id":9},{"move":{"x":-2,"y":-1,"z":3},"block_id":9},{"move":{"x":-2,"y":-1,"z":4},"block_id":9},{"move":{"x":-2,"y":-1,"z":5},"block_id":18,"extra_data":{"max_ticks":205}},{"move":{"x":-2,"y":-1,"z":7},"block_id":9},{"move":{"x":-2,"y":-1,"z":8},"block_id":90},{"move":{"x":-2,"y":-1,"z":27},"block_id":90},{"move":{"x":-2,"y":-1,"z":28},"block_id":9},{"move":{"x":-2,"y":-1,"z":29},"block_id":18},{"move":{"x":-2,"y":0,"z":7},"block_id":9},{"move":{"x":-2,"y":0,"z":27},"block_id":9},{"move":{"x":-2,"y":0,"z":28},"block_id":9},{"move":{"x":-2,"y":0,"z":29},"block_id":9},{"move":{"x":-2,"y":1,"z":28},"block_id":9},{"move":{"x":-2,"y":1,"z":29},"block_id":9},{"move":{"x":-2,"y":2,"z":27},"block_id":9},{"move":{"x":-2,"y":2,"z":28},"block_id":9},{"move":{"x":-2,"y":3,"z":27},"block_id":9},{"move":{"x":-1,"y":-8,"z":16},"block_id":9},{"move":{"x":-1,"y":-8,"z":17},"block_id":9},{"move":{"x":-1,"y":-8,"z":18},"block_id":9},{"move":{"x":-1,"y":-8,"z":19},"block_id":9},{"move":{"x":-1,"y":-8,"z":20},"block_id":9},{"move":{"x":-1,"y":-8,"z":21},"block_id":9},{"move":{"x":-1,"y":-8,"z":22},"block_id":9},{"move":{"x":-1,"y":-8,"z":23},"block_id":9},{"move":{"x":-1,"y":-7,"z":15},"block_id":9},{"move":{"x":-1,"y":-7,"z":24},"block_id":9},{"move":{"x":-1,"y":-7,"z":25},"block_id":9},{"move":{"x":-1,"y":-6,"z":14},"block_id":9},{"move":{"x":-1,"y":-6,"z":18},"block_id":90},{"move":{"x":-1,"y":-6,"z":21},"block_id":88},{"move":{"x":-1,"y":-6,"z":22},"block_id":90},{"move":{"x":-1,"y":-6,"z":24},"block_id":88},{"move":{"x":-1,"y":-6,"z":26},"block_id":9},{"move":{"x":-1,"y":-5,"z":13},"block_id":9},{"move":{"x":-1,"y":-5,"z":14},"block_id":9},{"move":{"x":-1,"y":-5,"z":15},"block_id":90},{"move":{"x":-1,"y":-5,"z":16},"block_id":9},{"move":{"x":-1,"y":-5,"z":22},"block_id":88},{"move":{"x":-1,"y":-5,"z":26},"block_id":88},{"move":{"x":-1,"y":-5,"z":27},"block_id":9},{"move":{"x":-1,"y":-4,"z":12},"block_id":9},{"move":{"x":-1,"y":-4,"z":13},"block_id":90},{"move":{"x":-1,"y":-4,"z":26},"block_id":88},{"move":{"x":-1,"y":-4,"z":27},"block_id":90},{"move":{"x":-1,"y":-3,"z":7},"block_id":9},{"move":{"x":-1,"y":-3,"z":8},"block_id":9},{"move":{"x":-1,"y":-3,"z":9},"block_id":9},{"move":{"x":-1,"y":-3,"z":10},"block_id":9},{"move":{"x":-1,"y":-3,"z":11},"block_id":9},{"move":{"x":-1,"y":-3,"z":12},"block_id":90},{"move":{"x":-1,"y":-3,"z":27},"block_id":88},{"move":{"x":-1,"y":-2,"z":1},"block_id":18,"extra_data":{"max_ticks":437}},{"move":{"x":-1,"y":-2,"z":2},"block_id":18,"extra_data":{"max_ticks":346}},{"move":{"x":-1,"y":-2,"z":3},"block_id":18},{"move":{"x":-1,"y":-2,"z":4},"block_id":2},{"move":{"x":-1,"y":-2,"z":5},"block_id":18,"extra_data":{"max_ticks":319}},{"move":{"x":-1,"y":-2,"z":7},"block_id":90},{"move":{"x":-1,"y":-2,"z":8},"block_id":9},{"move":{"x":-1,"y":-2,"z":9},"block_id":90},{"move":{"x":-1,"y":-2,"z":10},"block_id":9},{"move":{"x":-1,"y":-2,"z":11},"block_id":90},{"move":{"x":-1,"y":-2,"z":27},"block_id":90},{"move":{"x":-1,"y":-2,"z":28},"block_id":18,"extra_data":{"max_ticks":446}},{"move":{"x":-1,"y":-1,"z":1},"block_id":9},{"move":{"x":-1,"y":-1,"z":2},"block_id":9},{"move":{"x":-1,"y":-1,"z":3},"block_id":87},{"move":{"x":-1,"y":-1,"z":4},"block_id":9},{"move":{"x":-1,"y":-1,"z":5},"block_id":90},{"move":{"x":-1,"y":-1,"z":6},"block_id":9},{"move":{"x":-1,"y":-1,"z":27},"block_id":90},{"move":{"x":-1,"y":-1,"z":28},"block_id":9},{"move":{"x":-1,"y":-1,"z":29},"block_id":2},{"move":{"x":-1,"y":-1,"z":30},"block_id":18,"extra_data":{"max_ticks":115}},{"move":{"x":-1,"y":0,"z":3},"block_id":506},{"move":{"x":-1,"y":0,"z":6},"block_id":9},{"move":{"x":-1,"y":0,"z":27},"block_id":9},{"move":{"x":-1,"y":0,"z":28},"block_id":9},{"move":{"x":-1,"y":0,"z":29},"block_id":9},{"move":{"x":-1,"y":0,"z":30},"block_id":9},{"move":{"x":-1,"y":1,"z":28},"block_id":9},{"move":{"x":-1,"y":1,"z":29},"block_id":9},{"move":{"x":-1,"y":2,"z":28},"block_id":9},{"move":{"x":-1,"y":3,"z":27},"block_id":9},{"move":{"x":0,"y":-8,"z":16},"block_id":9},{"move":{"x":0,"y":-8,"z":17},"block_id":9},{"move":{"x":0,"y":-8,"z":18},"block_id":9},{"move":{"x":0,"y":-8,"z":19},"block_id":9},{"move":{"x":0,"y":-8,"z":20},"block_id":9},{"move":{"x":0,"y":-8,"z":21},"block_id":9},{"move":{"x":0,"y":-8,"z":22},"block_id":9},{"move":{"x":0,"y":-8,"z":23},"block_id":9},{"move":{"x":0,"y":-8,"z":24},"block_id":9},{"move":{"x":0,"y":-7,"z":15},"block_id":9},{"move":{"x":0,"y":-7,"z":16},"block_id":9},{"move":{"x":0,"y":-7,"z":24},"block_id":90},{"move":{"x":0,"y":-7,"z":25},"block_id":9},{"move":{"x":0,"y":-7,"z":26},"block_id":9},{"move":{"x":0,"y":-6,"z":13},"block_id":9},{"move":{"x":0,"y":-6,"z":14},"block_id":9},{"move":{"x":0,"y":-6,"z":15},"block_id":15},{"move":{"x":0,"y":-6,"z":18},"block_id":88},{"move":{"x":0,"y":-6,"z":19},"block_id":90},{"move":{"x":0,"y":-6,"z":20},"block_id":90},{"move":{"x":0,"y":-6,"z":21},"block_id":90},{"move":{"x":0,"y":-6,"z":22},"block_id":88},{"move":{"x":0,"y":-6,"z":26},"block_id":9},{"move":{"x":0,"y":-5,"z":12},"block_id":9},{"move":{"x":0,"y":-5,"z":13},"block_id":90},{"move":{"x":0,"y":-5,"z":14},"block_id":90},{"move":{"x":0,"y":-5,"z":19},"block_id":88},{"move":{"x":0,"y":-5,"z":25},"block_id":88},{"move":{"x":0,"y":-5,"z":26},"block_id":90},{"move":{"x":0,"y":-5,"z":27},"block_id":9},{"move":{"x":0,"y":-4,"z":10},"block_id":9},{"move":{"x":0,"y":-4,"z":11},"block_id":9},{"move":{"x":0,"y":-4,"z":12},"block_id":9},{"move":{"x":0,"y":-4,"z":26},"block_id":88},{"move":{"x":0,"y":-4,"z":27},"block_id":88},{"move":{"x":0,"y":-3,"z":4},"block_id":9},{"move":{"x":0,"y":-3,"z":5},"block_id":9},{"move":{"x":0,"y":-3,"z":6},"block_id":9},{"move":{"x":0,"y":-3,"z":7},"block_id":9},{"move":{"x":0,"y":-3,"z":8},"block_id":9},{"move":{"x":0,"y":-3,"z":10},"block_id":90},{"move":{"x":0,"y":-3,"z":11},"block_id":90},{"move":{"x":0,"y":-3,"z":27},"block_id":90},{"move":{"x":0,"y":-2,"z":0},"block_id":18,"extra_data":{"max_ticks":311}},{"move":{"x":0,"y":-2,"z":1},"block_id":18},{"move":{"x":0,"y":-2,"z":2},"block_id":18},{"move":{"x":0,"y":-2,"z":3},"block_id":18},{"move":{"x":0,"y":-2,"z":4},"block_id":9},{"move":{"x":0,"y":-2,"z":5},"block_id":90},{"move":{"x":0,"y":-2,"z":6},"block_id":90},{"move":{"x":0,"y":-2,"z":7},"block_id":87},{"move":{"x":0,"y":-2,"z":8},"block_id":9},{"move":{"x":0,"y":-2,"z":9},"block_id":90},{"move":{"x":0,"y":-2,"z":27},"block_id":15},{"move":{"x":0,"y":-2,"z":28},"block_id":18},{"move":{"x":0,"y":-1,"z":0},"block_id":9},{"move":{"x":0,"y":-1,"z":1},"block_id":9},{"move":{"x":0,"y":-1,"z":2},"block_id":9},{"move":{"x":0,"y":-1,"z":3},"block_id":90},{"move":{"x":0,"y":-1,"z":7},"block_id":506},{"move":{"x":0,"y":-1,"z":27},"block_id":9},{"move":{"x":0,"y":-1,"z":28},"block_id":9},{"move":{"x":0,"y":-1,"z":29},"block_id":18},{"move":{"x":0,"y":-1,"z":30},"block_id":18},{"move":{"x":0,"y":0,"z":28},"block_id":9},{"move":{"x":0,"y":0,"z":29},"block_id":9},{"move":{"x":0,"y":0,"z":30},"block_id":9},{"move":{"x":0,"y":1,"z":28},"block_id":90},{"move":{"x":0,"y":1,"z":29},"block_id":9},{"move":{"x":0,"y":2,"z":28},"block_id":9},{"move":{"x":0,"y":3,"z":27},"block_id":9},{"move":{"x":1,"y":-8,"z":18},"block_id":9},{"move":{"x":1,"y":-8,"z":19},"block_id":9},{"move":{"x":1,"y":-8,"z":20},"block_id":9},{"move":{"x":1,"y":-8,"z":21},"block_id":9},{"move":{"x":1,"y":-8,"z":22},"block_id":9},{"move":{"x":1,"y":-8,"z":23},"block_id":9},{"move":{"x":1,"y":-8,"z":24},"block_id":9},{"move":{"x":1,"y":-7,"z":17},"block_id":9},{"move":{"x":1,"y":-7,"z":24},"block_id":9},{"move":{"x":1,"y":-7,"z":26},"block_id":9},{"move":{"x":1,"y":-6,"z":14},"block_id":9},{"move":{"x":1,"y":-6,"z":15},"block_id":9},{"move":{"x":1,"y":-6,"z":16},"block_id":9},{"move":{"x":1,"y":-6,"z":17},"block_id":88},{"move":{"x":1,"y":-6,"z":21},"block_id":90},{"move":{"x":1,"y":-6,"z":24},"block_id":90},{"move":{"x":1,"y":-6,"z":25},"block_id":9},{"move":{"x":1,"y":-6,"z":27},"block_id":9},{"move":{"x":1,"y":-5,"z":12},"block_id":9},{"move":{"x":1,"y":-5,"z":13},"block_id":9},{"move":{"x":1,"y":-5,"z":14},"block_id":87},{"move":{"x":1,"y":-5,"z":15},"block_id":90},{"move":{"x":1,"y":-5,"z":16},"block_id":90},{"move":{"x":1,"y":-5,"z":21},"block_id":88},{"move":{"x":1,"y":-5,"z":27},"block_id":9},{"move":{"x":1,"y":-4,"z":10},"block_id":9},{"move":{"x":1,"y":-4,"z":11},"block_id":9},{"move":{"x":1,"y":-4,"z":12},"block_id":90},{"move":{"x":1,"y":-4,"z":13},"block_id":90},{"move":{"x":1,"y":-4,"z":14},"block_id":506},{"move":{"x":1,"y":-4,"z":16},"block_id":88},{"move":{"x":1,"y":-4,"z":27},"block_id":90},{"move":{"x":1,"y":-4,"z":28},"block_id":9},{"move":{"x":1,"y":-3,"z":8},"block_id":9},{"move":{"x":1,"y":-3,"z":9},"block_id":9},{"move":{"x":1,"y":-3,"z":10},"block_id":87},{"move":{"x":1,"y":-3,"z":11},"block_id":90},{"move":{"x":1,"y":-3,"z":27},"block_id":90},{"move":{"x":1,"y":-3,"z":28},"block_id":90},{"move":{"x":1,"y":-2,"z":2},"block_id":18,"extra_data":{"max_ticks":255}},{"move":{"x":1,"y":-2,"z":3},"block_id":18},{"move":{"x":1,"y":-2,"z":7},"block_id":18,"extra_data":{"max_ticks":255}},{"move":{"x":1,"y":-2,"z":8},"block_id":9},{"move":{"x":1,"y":-2,"z":9},"block_id":90},{"move":{"x":1,"y":-2,"z":10},"block_id":506},{"move":{"x":1,"y":-2,"z":27},"block_id":90},{"move":{"x":1,"y":-1,"z":2},"block_id":9},{"move":{"x":1,"y":-1,"z":3},"block_id":9},{"move":{"x":1,"y":-1,"z":4},"block_id":9},{"move":{"x":1,"y":-1,"z":5},"block_id":9},{"move":{"x":1,"y":-1,"z":6},"block_id":90},{"move":{"x":1,"y":-1,"z":7},"block_id":90},{"move":{"x":1,"y":-1,"z":27},"block_id":90},{"move":{"x":1,"y":-1,"z":28},"block_id":9},{"move":{"x":1,"y":-1,"z":29},"block_id":18},{"move":{"x":1,"y":-1,"z":30},"block_id":18},{"move":{"x":1,"y":0,"z":5},"block_id":9},{"move":{"x":1,"y":0,"z":28},"block_id":9},{"move":{"x":1,"y":0,"z":29},"block_id":9},{"move":{"x":1,"y":0,"z":30},"block_id":9},{"move":{"x":1,"y":1,"z":27},"block_id":9},{"move":{"x":1,"y":1,"z":28},"block_id":9},{"move":{"x":1,"y":1,"z":29},"block_id":9},{"move":{"x":1,"y":2,"z":27},"block_id":90},{"move":{"x":1,"y":2,"z":28},"block_id":9},{"move":{"x":1,"y":3,"z":26},"block_id":9},{"move":{"x":2,"y":-8,"z":21},"block_id":9},{"move":{"x":2,"y":-8,"z":22},"block_id":9},{"move":{"x":2,"y":-8,"z":23},"block_id":9},{"move":{"x":2,"y":-7,"z":18},"block_id":9},{"move":{"x":2,"y":-7,"z":19},"block_id":9},{"move":{"x":2,"y":-7,"z":20},"block_id":9},{"move":{"x":2,"y":-7,"z":23},"block_id":9},{"move":{"x":2,"y":-7,"z":24},"block_id":9},{"move":{"x":2,"y":-7,"z":26},"block_id":9},{"move":{"x":2,"y":-6,"z":15},"block_id":9},{"move":{"x":2,"y":-6,"z":16},"block_id":9},{"move":{"x":2,"y":-6,"z":17},"block_id":9},{"move":{"x":2,"y":-6,"z":18},"block_id":88},{"move":{"x":2,"y":-6,"z":19},"block_id":88},{"move":{"x":2,"y":-6,"z":20},"block_id":90},{"move":{"x":2,"y":-6,"z":23},"block_id":90},{"move":{"x":2,"y":-6,"z":24},"block_id":90},{"move":{"x":2,"y":-6,"z":25},"block_id":9},{"move":{"x":2,"y":-6,"z":26},"block_id":9},{"move":{"x":2,"y":-6,"z":27},"block_id":9},{"move":{"x":2,"y":-5,"z":14},"block_id":9},{"move":{"x":2,"y":-5,"z":15},"block_id":90},{"move":{"x":2,"y":-5,"z":16},"block_id":87},{"move":{"x":2,"y":-5,"z":17},"block_id":90},{"move":{"x":2,"y":-5,"z":18},"block_id":90},{"move":{"x":2,"y":-5,"z":19},"block_id":90},{"move":{"x":2,"y":-5,"z":24},"block_id":88},{"move":{"x":2,"y":-5,"z":25},"block_id":87},{"move":{"x":2,"y":-5,"z":27},"block_id":9},{"move":{"x":2,"y":-4,"z":12},"block_id":9},{"move":{"x":2,"y":-4,"z":13},"block_id":9},{"move":{"x":2,"y":-4,"z":14},"block_id":9},{"move":{"x":2,"y":-4,"z":16},"block_id":506},{"move":{"x":2,"y":-4,"z":19},"block_id":88},{"move":{"x":2,"y":-4,"z":25},"block_id":506},{"move":{"x":2,"y":-4,"z":26},"block_id":88},{"move":{"x":2,"y":-4,"z":27},"block_id":9},{"move":{"x":2,"y":-3,"z":9},"block_id":9},{"move":{"x":2,"y":-3,"z":10},"block_id":9},{"move":{"x":2,"y":-3,"z":11},"block_id":9},{"move":{"x":2,"y":-3,"z":12},"block_id":9},{"move":{"x":2,"y":-3,"z":13},"block_id":90},{"move":{"x":2,"y":-3,"z":26},"block_id":88},{"move":{"x":2,"y":-3,"z":27},"block_id":90},{"move":{"x":2,"y":-2,"z":1},"block_id":18},{"move":{"x":2,"y":-2,"z":6},"block_id":18},{"move":{"x":2,"y":-2,"z":9},"block_id":9},{"move":{"x":2,"y":-2,"z":10},"block_id":9},{"move":{"x":2,"y":-2,"z":11},"block_id":90},{"move":{"x":2,"y":-2,"z":12},"block_id":90},{"move":{"x":2,"y":-2,"z":27},"block_id":90},{"move":{"x":2,"y":-2,"z":28},"block_id":18,"extra_data":{"max_ticks":497}},{"move":{"x":2,"y":-1,"z":1},"block_id":9},{"move":{"x":2,"y":-1,"z":2},"block_id":2},{"move":{"x":2,"y":-1,"z":3},"block_id":2},{"move":{"x":2,"y":-1,"z":6},"block_id":9},{"move":{"x":2,"y":-1,"z":7},"block_id":9},{"move":{"x":2,"y":-1,"z":8},"block_id":9},{"move":{"x":2,"y":-1,"z":27},"block_id":90},{"move":{"x":2,"y":-1,"z":28},"block_id":9},{"move":{"x":2,"y":-1,"z":29},"block_id":18,"extra_data":{"max_ticks":340}},{"move":{"x":2,"y":0,"z":3},"block_id":9},{"move":{"x":2,"y":0,"z":6},"block_id":9},{"move":{"x":2,"y":0,"z":8},"block_id":9},{"move":{"x":2,"y":0,"z":27},"block_id":9},{"move":{"x":2,"y":0,"z":28},"block_id":9},{"move":{"x":2,"y":0,"z":29},"block_id":9},{"move":{"x":2,"y":1,"z":27},"block_id":9},{"move":{"x":2,"y":1,"z":28},"block_id":9},{"move":{"x":2,"y":2,"z":27},"block_id":9},{"move":{"x":2,"y":3,"z":26},"block_id":9},{"move":{"x":3,"y":-7,"z":21},"block_id":9},{"move":{"x":3,"y":-7,"z":22},"block_id":9},{"move":{"x":3,"y":-7,"z":23},"block_id":9},{"move":{"x":3,"y":-6,"z":18},"block_id":9},{"move":{"x":3,"y":-6,"z":19},"block_id":9},{"move":{"x":3,"y":-6,"z":20},"block_id":9},{"move":{"x":3,"y":-6,"z":21},"block_id":90},{"move":{"x":3,"y":-6,"z":22},"block_id":15},{"move":{"x":3,"y":-6,"z":24},"block_id":9},{"move":{"x":3,"y":-5,"z":15},"block_id":9},{"move":{"x":3,"y":-5,"z":16},"block_id":9},{"move":{"x":3,"y":-5,"z":17},"block_id":9},{"move":{"x":3,"y":-5,"z":18},"block_id":88},{"move":{"x":3,"y":-5,"z":19},"block_id":90},{"move":{"x":3,"y":-5,"z":20},"block_id":88},{"move":{"x":3,"y":-5,"z":22},"block_id":88},{"move":{"x":3,"y":-5,"z":24},"block_id":90},{"move":{"x":3,"y":-5,"z":25},"block_id":9},{"move":{"x":3,"y":-5,"z":26},"block_id":9},{"move":{"x":3,"y":-4,"z":15},"block_id":90},{"move":{"x":3,"y":-4,"z":16},"block_id":90},{"move":{"x":3,"y":-4,"z":17},"block_id":90},{"move":{"x":3,"y":-4,"z":24},"block_id":88},{"move":{"x":3,"y":-4,"z":25},"block_id":88},{"move":{"x":3,"y":-3,"z":11},"block_id":9},{"move":{"x":3,"y":-3,"z":12},"block_id":9},{"move":{"x":3,"y":-3,"z":14},"block_id":90},{"move":{"x":3,"y":-3,"z":25},"block_id":90},{"move":{"x":3,"y":-3,"z":26},"block_id":9},{"move":{"x":3,"y":-2,"z":3},"block_id":18,"extra_data":{"max_ticks":319}},{"move":{"x":3,"y":-2,"z":5},"block_id":18},{"move":{"x":3,"y":-2,"z":6},"block_id":18},{"move":{"x":3,"y":-2,"z":9},"block_id":18,"extra_data":{"max_ticks":443}},{"move":{"x":3,"y":-2,"z":10},"block_id":18},{"move":{"x":3,"y":-2,"z":11},"block_id":90},{"move":{"x":3,"y":-2,"z":12},"block_id":9},{"move":{"x":3,"y":-2,"z":13},"block_id":9},{"move":{"x":3,"y":-2,"z":26},"block_id":90},{"move":{"x":3,"y":-2,"z":27},"block_id":2},{"move":{"x":3,"y":-2,"z":28},"block_id":18},{"move":{"x":3,"y":-1,"z":3},"block_id":9},{"move":{"x":3,"y":-1,"z":5},"block_id":9},{"move":{"x":3,"y":-1,"z":6},"block_id":9},{"move":{"x":3,"y":-1,"z":7},"block_id":2},{"move":{"x":3,"y":-1,"z":9},"block_id":9},{"move":{"x":3,"y":-1,"z":10},"block_id":90},{"move":{"x":3,"y":-1,"z":26},"block_id":90},{"move":{"x":3,"y":-1,"z":27},"block_id":9},{"move":{"x":3,"y":-1,"z":28},"block_id":9},{"move":{"x":3,"y":0,"z":8},"block_id":9},{"move":{"x":3,"y":0,"z":26},"block_id":15},{"move":{"x":3,"y":0,"z":27},"block_id":9},{"move":{"x":3,"y":0,"z":28},"block_id":9},{"move":{"x":3,"y":1,"z":26},"block_id":9},{"move":{"x":3,"y":1,"z":27},"block_id":9},{"move":{"x":3,"y":2,"z":26},"block_id":9},{"move":{"x":3,"y":3,"z":25},"block_id":9},{"move":{"x":4,"y":-6,"z":19},"block_id":9},{"move":{"x":4,"y":-6,"z":20},"block_id":9},{"move":{"x":4,"y":-6,"z":21},"block_id":9},{"move":{"x":4,"y":-6,"z":22},"block_id":9},{"move":{"x":4,"y":-6,"z":23},"block_id":9},{"move":{"x":4,"y":-5,"z":16},"block_id":9},{"move":{"x":4,"y":-5,"z":17},"block_id":9},{"move":{"x":4,"y":-5,"z":18},"block_id":9},{"move":{"x":4,"y":-5,"z":19},"block_id":90},{"move":{"x":4,"y":-5,"z":20},"block_id":87},{"move":{"x":4,"y":-5,"z":21},"block_id":88},{"move":{"x":4,"y":-5,"z":22},"block_id":90},{"move":{"x":4,"y":-5,"z":23},"block_id":90},{"move":{"x":4,"y":-4,"z":15},"block_id":9},{"move":{"x":4,"y":-4,"z":16},"block_id":90},{"move":{"x":4,"y":-4,"z":17},"block_id":88},{"move":{"x":4,"y":-4,"z":18},"block_id":90},{"move":{"x":4,"y":-4,"z":20},"block_id":506},{"move":{"x":4,"y":-4,"z":21},"block_id":88},{"move":{"x":4,"y":-4,"z":22},"block_id":88},{"move":{"x":4,"y":-4,"z":23},"block_id":88},{"move":{"x":4,"y":-4,"z":24},"block_id":9},{"move":{"x":4,"y":-3,"z":14},"block_id":90},{"move":{"x":4,"y":-3,"z":15},"block_id":9},{"move":{"x":4,"y":-3,"z":16},"block_id":90},{"move":{"x":4,"y":-3,"z":24},"block_id":90},{"move":{"x":4,"y":-3,"z":25},"block_id":9},{"move":{"x":4,"y":-2,"z":8},"block_id":18,"extra_data":{"max_ticks":463}},{"move":{"x":4,"y":-2,"z":11},"block_id":18,"extra_data":{"max_ticks":161}},{"move":{"x":4,"y":-2,"z":13},"block_id":9},{"move":{"x":4,"y":-2,"z":25},"block_id":90},{"move":{"x":4,"y":-2,"z":26},"block_id":18},{"move":{"x":4,"y":-2,"z":27},"block_id":18},{"move":{"x":4,"y":-1,"z":8},"block_id":9},{"move":{"x":4,"y":-1,"z":9},"block_id":2},{"move":{"x":4,"y":-1,"z":10},"block_id":18},{"move":{"x":4,"y":-1,"z":11},"block_id":9},{"move":{"x":4,"y":-1,"z":12},"block_id":90},{"move":{"x":4,"y":-1,"z":13},"block_id":90},{"move":{"x":4,"y":-1,"z":25},"block_id":15},{"move":{"x":4,"y":-1,"z":26},"block_id":9},{"move":{"x":4,"y":-1,"z":27},"block_id":9},{"move":{"x":4,"y":-1,"z":29},"block_id":18,"extra_data":{"max_ticks":56}},{"move":{"x":4,"y":0,"z":10},"block_id":9},{"move":{"x":4,"y":0,"z":11},"block_id":9},{"move":{"x":4,"y":0,"z":25},"block_id":9},{"move":{"x":4,"y":0,"z":26},"block_id":9},{"move":{"x":4,"y":0,"z":27},"block_id":9},{"move":{"x":4,"y":0,"z":29},"block_id":9},{"move":{"x":4,"y":1,"z":26},"block_id":90},{"move":{"x":4,"y":2,"z":26},"block_id":9},{"move":{"x":4,"y":3,"z":25},"block_id":9},{"move":{"x":5,"y":-5,"z":19},"block_id":9},{"move":{"x":5,"y":-5,"z":20},"block_id":9},{"move":{"x":5,"y":-5,"z":21},"block_id":9},{"move":{"x":5,"y":-4,"z":17},"block_id":9},{"move":{"x":5,"y":-4,"z":18},"block_id":9},{"move":{"x":5,"y":-4,"z":19},"block_id":88},{"move":{"x":5,"y":-4,"z":20},"block_id":90},{"move":{"x":5,"y":-4,"z":21},"block_id":88},{"move":{"x":5,"y":-4,"z":22},"block_id":9},{"move":{"x":5,"y":-4,"z":23},"block_id":9},{"move":{"x":5,"y":-3,"z":15},"block_id":9},{"move":{"x":5,"y":-3,"z":16},"block_id":9},{"move":{"x":5,"y":-3,"z":17},"block_id":15},{"move":{"x":5,"y":-3,"z":18},"block_id":90},{"move":{"x":5,"y":-3,"z":19},"block_id":90},{"move":{"x":5,"y":-3,"z":20},"block_id":9},{"move":{"x":5,"y":-3,"z":21},"block_id":90},{"move":{"x":5,"y":-3,"z":22},"block_id":90},{"move":{"x":5,"y":-3,"z":23},"block_id":88},{"move":{"x":5,"y":-2,"z":7},"block_id":18},{"move":{"x":5,"y":-2,"z":14},"block_id":90},{"move":{"x":5,"y":-2,"z":15},"block_id":9},{"move":{"x":5,"y":-2,"z":16},"block_id":90},{"move":{"x":5,"y":-2,"z":17},"block_id":90},{"move":{"x":5,"y":-2,"z":18},"block_id":9},{"move":{"x":5,"y":-2,"z":22},"block_id":90},{"move":{"x":5,"y":-2,"z":23},"block_id":90},{"move":{"x":5,"y":-2,"z":24},"block_id":18},{"move":{"x":5,"y":-2,"z":25},"block_id":18},{"move":{"x":5,"y":-2,"z":26},"block_id":18},{"move":{"x":5,"y":-2,"z":27},"block_id":18},{"move":{"x":5,"y":-1,"z":7},"block_id":9},{"move":{"x":5,"y":-1,"z":9},"block_id":18},{"move":{"x":5,"y":-1,"z":12},"block_id":9},{"move":{"x":5,"y":-1,"z":13},"block_id":9},{"move":{"x":5,"y":-1,"z":14},"block_id":9},{"move":{"x":5,"y":-1,"z":15},"block_id":90},{"move":{"x":5,"y":-1,"z":16},"block_id":90},{"move":{"x":5,"y":-1,"z":23},"block_id":90},{"move":{"x":5,"y":-1,"z":24},"block_id":90},{"move":{"x":5,"y":-1,"z":25},"block_id":9},{"move":{"x":5,"y":-1,"z":26},"block_id":9},{"move":{"x":5,"y":-1,"z":27},"block_id":9},{"move":{"x":5,"y":0,"z":9},"block_id":9},{"move":{"x":5,"y":0,"z":14},"block_id":9},{"move":{"x":5,"y":0,"z":24},"block_id":9},{"move":{"x":5,"y":0,"z":25},"block_id":9},{"move":{"x":5,"y":0,"z":26},"block_id":9},{"move":{"x":5,"y":0,"z":27},"block_id":9},{"move":{"x":5,"y":1,"z":25},"block_id":9},{"move":{"x":5,"y":2,"z":25},"block_id":9},{"move":{"x":6,"y":-3,"z":16},"block_id":9},{"move":{"x":6,"y":-3,"z":18},"block_id":9},{"move":{"x":6,"y":-3,"z":19},"block_id":9},{"move":{"x":6,"y":-3,"z":20},"block_id":9},{"move":{"x":6,"y":-3,"z":21},"block_id":9},{"move":{"x":6,"y":-2,"z":10},"block_id":18},{"move":{"x":6,"y":-2,"z":15},"block_id":18,"extra_data":{"max_ticks":178}},{"move":{"x":6,"y":-2,"z":16},"block_id":90},{"move":{"x":6,"y":-2,"z":17},"block_id":2},{"move":{"x":6,"y":-2,"z":18},"block_id":90},{"move":{"x":6,"y":-2,"z":19},"block_id":90},{"move":{"x":6,"y":-2,"z":20},"block_id":9},{"move":{"x":6,"y":-2,"z":21},"block_id":90},{"move":{"x":6,"y":-2,"z":22},"block_id":18},{"move":{"x":6,"y":-2,"z":23},"block_id":18},{"move":{"x":6,"y":-2,"z":24},"block_id":18},{"move":{"x":6,"y":-2,"z":25},"block_id":18,"extra_data":{"max_ticks":357}},{"move":{"x":6,"y":-2,"z":26},"block_id":18,"extra_data":{"max_ticks":317}},{"move":{"x":6,"y":-1,"z":10},"block_id":9},{"move":{"x":6,"y":-1,"z":14},"block_id":9},{"move":{"x":6,"y":-1,"z":15},"block_id":9},{"move":{"x":6,"y":-1,"z":16},"block_id":87},{"move":{"x":6,"y":-1,"z":17},"block_id":90},{"move":{"x":6,"y":-1,"z":22},"block_id":90},{"move":{"x":6,"y":-1,"z":23},"block_id":9},{"move":{"x":6,"y":-1,"z":24},"block_id":9},{"move":{"x":6,"y":-1,"z":25},"block_id":9},{"move":{"x":6,"y":-1,"z":26},"block_id":9},{"move":{"x":6,"y":-1,"z":27},"block_id":18},{"move":{"x":6,"y":-1,"z":28},"block_id":18},{"move":{"x":6,"y":0,"z":13},"block_id":9},{"move":{"x":6,"y":0,"z":16},"block_id":506},{"move":{"x":6,"y":0,"z":17},"block_id":9},{"move":{"x":6,"y":0,"z":23},"block_id":9},{"move":{"x":6,"y":0,"z":24},"block_id":9},{"move":{"x":6,"y":0,"z":25},"block_id":9},{"move":{"x":6,"y":0,"z":27},"block_id":9},{"move":{"x":6,"y":0,"z":28},"block_id":9},{"move":{"x":6,"y":1,"z":23},"block_id":90},{"move":{"x":6,"y":1,"z":24},"block_id":9},{"move":{"x":6,"y":2,"z":23},"block_id":9},{"move":{"x":7,"y":-2,"z":11},"block_id":18,"extra_data":{"max_ticks":327}},{"move":{"x":7,"y":-2,"z":12},"block_id":18},{"move":{"x":7,"y":-2,"z":16},"block_id":18},{"move":{"x":7,"y":-2,"z":17},"block_id":2},{"move":{"x":7,"y":-2,"z":18},"block_id":18},{"move":{"x":7,"y":-2,"z":19},"block_id":2},{"move":{"x":7,"y":-2,"z":20},"block_id":18},{"move":{"x":7,"y":-2,"z":21},"block_id":18},{"move":{"x":7,"y":-2,"z":22},"block_id":2},{"move":{"x":7,"y":-2,"z":23},"block_id":18},{"move":{"x":7,"y":-2,"z":24},"block_id":18,"extra_data":{"max_ticks":217}},{"move":{"x":7,"y":-1,"z":11},"block_id":9},{"move":{"x":7,"y":-1,"z":12},"block_id":9},{"move":{"x":7,"y":-1,"z":16},"block_id":9},{"move":{"x":7,"y":-1,"z":17},"block_id":9},{"move":{"x":7,"y":-1,"z":18},"block_id":9},{"move":{"x":7,"y":-1,"z":19},"block_id":9},{"move":{"x":7,"y":-1,"z":20},"block_id":90},{"move":{"x":7,"y":-1,"z":21},"block_id":90},{"move":{"x":7,"y":-1,"z":22},"block_id":9},{"move":{"x":7,"y":-1,"z":23},"block_id":9},{"move":{"x":7,"y":-1,"z":24},"block_id":9},{"move":{"x":7,"y":-1,"z":26},"block_id":18,"extra_data":{"max_ticks":221}},{"move":{"x":7,"y":0,"z":16},"block_id":9},{"move":{"x":7,"y":0,"z":19},"block_id":90},{"move":{"x":7,"y":0,"z":21},"block_id":9},{"move":{"x":7,"y":0,"z":22},"block_id":9},{"move":{"x":7,"y":0,"z":23},"block_id":9},{"move":{"x":7,"y":0,"z":24},"block_id":9},{"move":{"x":7,"y":0,"z":26},"block_id":9},{"move":{"x":7,"y":1,"z":21},"block_id":9},{"move":{"x":7,"y":1,"z":22},"block_id":9},{"move":{"x":8,"y":-2,"z":17},"block_id":18,"extra_data":{"max_ticks":69}},{"move":{"x":8,"y":-2,"z":18},"block_id":18,"extra_data":{"max_ticks":163}},{"move":{"x":8,"y":-2,"z":19},"block_id":18},{"move":{"x":8,"y":-2,"z":20},"block_id":18},{"move":{"x":8,"y":-2,"z":21},"block_id":18},{"move":{"x":8,"y":-2,"z":22},"block_id":18,"extra_data":{"max_ticks":444}},{"move":{"x":8,"y":-1,"z":12},"block_id":18},{"move":{"x":8,"y":-1,"z":15},"block_id":18,"extra_data":{"max_ticks":203}},{"move":{"x":8,"y":-1,"z":17},"block_id":9},{"move":{"x":8,"y":-1,"z":18},"block_id":9},{"move":{"x":8,"y":-1,"z":19},"block_id":9},{"move":{"x":8,"y":-1,"z":20},"block_id":9},{"move":{"x":8,"y":-1,"z":21},"block_id":9},{"move":{"x":8,"y":-1,"z":22},"block_id":9},{"move":{"x":8,"y":-1,"z":27},"block_id":18,"extra_data":{"max_ticks":416}},{"move":{"x":8,"y":0,"z":12},"block_id":9},{"move":{"x":8,"y":0,"z":15},"block_id":9},{"move":{"x":8,"y":0,"z":20},"block_id":9},{"move":{"x":8,"y":0,"z":21},"block_id":9},{"move":{"x":8,"y":0,"z":22},"block_id":9},{"move":{"x":8,"y":0,"z":27},"block_id":9}],"rot":[],"fluids":[-4,-3,23,32,-3,-6,23,40,-3,-5,21,40,-3,-5,23,40,-3,-4,21,34,-3,-4,22,40,-3,-4,23,40,-3,-3,22,34,-3,-3,23,32,-3,-3,24,34,-2,-7,19,32,-2,-7,20,32,-2,-7,21,32,-2,-7,22,34,-2,-7,23,34,-2,-6,17,34,-2,-6,21,40,-2,-5,21,34,-2,-5,22,40,-2,-5,23,40,-2,-4,22,34,-2,-4,23,40,-2,-4,24,40,-2,-3,23,34,-2,-3,24,36,-1,-7,16,40,-1,-7,17,40,-1,-7,18,34,-1,-7,19,32,-1,-7,20,32,-1,-7,21,32,-1,-7,22,34,-1,-7,23,40,-1,-6,15,34,-1,-6,16,32,-1,-6,17,32,-1,-6,20,40,-1,-6,23,40,-1,-6,25,40,-1,-5,20,36,-1,-5,21,34,-1,-5,23,34,-1,-5,24,40,-1,-5,25,40,-1,-4,24,40,-1,-4,25,40,-1,-3,24,36,-1,-3,25,34,-1,-3,26,32,0,-7,17,40,0,-7,18,34,0,-7,19,32,0,-7,20,32,0,-7,21,34,0,-7,22,34,0,-7,23,40,0,-6,16,32,0,-6,17,32,0,-6,23,40,0,-6,24,40,0,-6,25,34,0,-5,20,34,0,-5,21,32,0,-5,22,34,0,-5,23,34,0,-5,24,40,0,-4,24,34,0,-4,25,40,0,-3,25,36,0,-3,26,34,1,-7,18,34,1,-7,19,32,1,-7,20,40,1,-7,21,34,1,-7,22,40,1,-7,23,40,1,-6,19,34,1,-6,20,40,1,-6,22,40,1,-6,23,40,1,-6,26,40,1,-5,20,34,1,-5,22,34,1,-5,23,36,1,-5,24,34,1,-5,25,40,1,-5,26,32,1,-4,25,34,1,-4,26,40,1,-3,26,36,2,-7,21,40,2,-7,22,40,2,-6,21,40,2,-6,22,40,2,-5,20,40,2,-5,21,34,2,-5,22,40,2,-5,23,34,2,-5,26,34,2,-4,20,36,2,-4,22,34,3,-6,23,40,3,-5,21,40,3,-5,23,40,3,-4,18,38,3,-4,19,36,3,-4,20,34,3,-4,21,40,3,-4,22,40,3,-4,23,40,3,-3,21,38,3,-3,22,36,3,-3,23,34,4,-4,19,34,4,-4,20,40,4,-3,20,38,4,-3,21,36,4,-3,22,34,4,-3,23,32]}