{"name":"test","world":{"pos1":{"x":-205,"y":1,"z":41},"pos2":{"x":-215,"y":15,"z":32},"entrance":{"x":-210,"y":1,"z":41}},"meta":{"dt":"2023-01-09T23:10:23.584Z","draw_natural_basement":true,"air_column_from_basement":true},"size":{"x":11,"y":15,"z":10},"door_pos":{"x":5,"y":0,"z":0},"blocks":[{"move":{"x":-5,"y":0,"z":0},"block_id":1511},{"move":{"x":-5,"y":0,"z":1},"block_id":1511},{"move":{"x":-5,"y":0,"z":2},"block_id":1511},{"move":{"x":-5,"y":0,"z":3},"block_id":1511},{"move":{"x":-5,"y":0,"z":6},"block_id":1511},{"move":{"x":-5,"y":0,"z":7},"block_id":1511},{"move":{"x":-5,"y":0,"z":8},"block_id":1511},{"move":{"x":-5,"y":0,"z":9},"block_id":1506},{"move":{"x":-5,"y":1,"z":0},"block_id":1511},{"move":{"x":-5,"y":1,"z":1},"block_id":106,"extra_data":{"south":true,"rotate":false}},{"move":{"x":-5,"y":1,"z":8},"block_id":65,"rotate":{"x":0,"y":0,"z":0}},{"move":{"x":-5,"y":1,"z":9},"block_id":1506},{"move":{"x":-5,"y":2,"z":0},"block_id":1511},{"move":{"x":-5,"y":2,"z":1},"block_id":106,"extra_data":{"south":true,"rotate":false}},{"move":{"x":-5,"y":2,"z":8},"block_id":65,"rotate":{"x":0,"y":0,"z":0}},{"move":{"x":-5,"y":2,"z":9},"block_id":1506},{"move":{"x":-5,"y":3,"z":0},"block_id":1511},{"move":{"x":-5,"y":3,"z":1},"block_id":106,"extra_data":{"south":true,"rotate":false}},{"move":{"x":-5,"y":3,"z":8},"block_id":65,"rotate":{"x":0,"y":0,"z":0}},{"move":{"x":-5,"y":3,"z":9},"block_id":1506},{"move":{"x":-5,"y":4,"z":0},"block_id":1511},{"move":{"x":-5,"y":4,"z":1},"block_id":50,"rotate":{"x":2,"y":0,"z":0}},{"move":{"x":-5,"y":4,"z":9},"block_id":1506},{"move":{"x":-5,"y":5,"z":0},"block_id":1511},{"move":{"x":-5,"y":5,"z":8},"block_id":643,"extra_data":{"text":"1","username":"sciner","dt":"2023-01-10T21:00:12.411Z"},"rotate":{"x":0,"y":0,"z":0}},{"move":{"x":-5,"y":5,"z":9},"block_id":1506},{"move":{"x":-5,"y":6,"z":0},"block_id":1511},{"move":{"x":-5,"y":6,"z":1},"block_id":615,"extra_data":{"point":{"x":0.499174181894233,"y":0.720106881501744,"z":-0.0020000000000024443}},"rotate":{"x":2,"y":0,"z":0}},{"move":{"x":-5,"y":6,"z":9},"block_id":1506},{"move":{"x":-5,"y":7,"z":0},"block_id":1511},{"move":{"x":-5,"y":7,"z":9},"block_id":1506},{"move":{"x":-5,"y":8,"z":0},"block_id":1511},{"move":{"x":-5,"y":8,"z":9},"block_id":1506},{"move":{"x":-5,"y":9,"z":0},"block_id":1511},{"move":{"x":-5,"y":9,"z":9},"block_id":1506},{"move":{"x":-5,"y":10,"z":0},"block_id":1511},{"move":{"x":-5,"y":10,"z":9},"block_id":1506},{"move":{"x":-5,"y":11,"z":0},"block_id":1511},{"move":{"x":-5,"y":11,"z":9},"block_id":1506},{"move":{"x":-5,"y":12,"z":0},"block_id":1511},{"move":{"x":-5,"y":12,"z":9},"block_id":1506},{"move":{"x":-5,"y":13,"z":0},"block_id":1511},{"move":{"x":-5,"y":13,"z":9},"block_id":1506},{"move":{"x":-5,"y":14,"z":0},"block_id":69},{"move":{"x":-5,"y":14,"z":1},"block_id":69},{"move":{"x":-5,"y":14,"z":2},"block_id":69},{"move":{"x":-5,"y":14,"z":3},"block_id":69},{"move":{"x":-5,"y":14,"z":6},"block_id":69},{"move":{"x":-5,"y":14,"z":7},"block_id":69},{"move":{"x":-5,"y":14,"z":8},"block_id":69},{"move":{"x":-5,"y":14,"z":9},"block_id":69},{"move":{"x":-4,"y":0,"z":0},"block_id":1504},{"move":{"x":-4,"y":0,"z":1},"block_id":69},{"move":{"x":-4,"y":0,"z":2},"block_id":69},{"move":{"x":-4,"y":0,"z":3},"block_id":69},{"move":{"x":-4,"y":0,"z":6},"block_id":69},{"move":{"x":-4,"y":0,"z":7},"block_id":69},{"move":{"x":-4,"y":0,"z":8},"block_id":69},{"move":{"x":-4,"y":0,"z":9},"block_id":1506},{"move":{"x":-4,"y":1,"z":0},"block_id":65,"rotate":{"x":1,"y":0,"z":0}},{"move":{"x":-4,"y":1,"z":1},"block_id":643,"extra_data":{"text":"4","username":"sciner","dt":"2023-01-10T21:00:07.842Z"},"rotate":{"x":2.5794513168089725,"y":1,"z":0}},{"move":{"x":-4,"y":1,"z":8},"block_id":643,"extra_data":{"text":"1","username":"sciner","dt":"2023-01-10T20:59:57.201Z"},"rotate":{"x":3.4768305479383153,"y":1,"z":0}},{"move":{"x":-4,"y":1,"z":9},"block_id":106,"extra_data":{"west":true,"rotate":false}},{"move":{"x":-4,"y":2,"z":0},"block_id":65,"rotate":{"x":1,"y":0,"z":0}},{"move":{"x":-4,"y":2,"z":9},"block_id":106,"extra_data":{"west":true,"rotate":false}},{"move":{"x":-4,"y":3,"z":0},"block_id":65,"rotate":{"x":1,"y":0,"z":0}},{"move":{"x":-4,"y":3,"z":9},"block_id":106,"extra_data":{"west":true,"rotate":false}},{"move":{"x":-4,"y":4,"z":9},"block_id":50,"rotate":{"x":1,"y":0,"z":0}},{"move":{"x":-4,"y":5,"z":0},"block_id":643,"extra_data":{"text":"4","username":"sciner","dt":"2023-01-10T21:00:21.482Z"},"rotate":{"x":1,"y":0,"z":0}},{"move":{"x":-4,"y":6,"z":9},"block_id":615,"extra_data":{"point":{"x":-0.0020000000000095497,"y":0.6433928794856119,"z":0.38908596301182286}},"rotate":{"x":1,"y":0,"z":0}},{"move":{"x":-4,"y":14,"z":0},"block_id":69},{"move":{"x":-4,"y":14,"z":9},"block_id":69},{"move":{"x":-3,"y":0,"z":0},"block_id":1504},{"move":{"x":-3,"y":0,"z":1},"block_id":69},{"move":{"x":-3,"y":0,"z":2},"block_id":52,"extra_data":{"can_destroy":true,"slots":{}},"rotate":{"x":7,"y":0,"z":0}},{"move":{"x":-3,"y":0,"z":6},"block_id":615,"extra_data":{"point":{"x":-0.0020000000000095497,"y":0.23490106054413928,"z":0.455742679618659}},"rotate":{"x":1,"y":0,"z":0}},{"move":{"x":-3,"y":0,"z":7},"block_id":52,"extra_data":{"can_destroy":true,"slots":{}},"rotate":{"x":22,"y":0,"z":0}},{"move":{"x":-3,"y":0,"z":8},"block_id":69},{"move":{"x":-3,"y":0,"z":9},"block_id":1506},{"move":{"x":-3,"y":14,"z":0},"block_id":69},{"move":{"x":-3,"y":14,"z":9},"block_id":69},{"move":{"x":-2,"y":0,"z":0},"block_id":1504},{"move":{"x":-2,"y":0,"z":1},"block_id":69},{"move":{"x":-2,"y":0,"z":2},"block_id":615,"extra_data":{"point":{"x":0.5798739530728199,"y":0.19781072262566468,"z":-0.0020000000000024443}},"rotate":{"x":2,"y":0,"z":0}},{"move":{"x":-2,"y":0,"z":8},"block_id":69},{"move":{"x":-2,"y":0,"z":9},"block_id":1506},{"move":{"x":-2,"y":14,"z":0},"block_id":69},{"move":{"x":-2,"y":14,"z":9},"block_id":69},{"move":{"x":-1,"y":0,"z":0},"block_id":1504},{"move":{"x":-1,"y":0,"z":1},"block_id":69},{"move":{"x":-1,"y":0,"z":8},"block_id":69},{"move":{"x":-1,"y":0,"z":9},"block_id":1506},{"move":{"x":-1,"y":14,"z":0},"block_id":69},{"move":{"x":-1,"y":14,"z":9},"block_id":69},{"move":{"x":1,"y":0,"z":0},"block_id":1504},{"move":{"x":1,"y":0,"z":1},"block_id":69},{"move":{"x":1,"y":0,"z":8},"block_id":69},{"move":{"x":1,"y":0,"z":9},"block_id":1506},{"move":{"x":1,"y":14,"z":0},"block_id":69},{"move":{"x":1,"y":14,"z":9},"block_id":69},{"move":{"x":2,"y":0,"z":0},"block_id":1504},{"move":{"x":2,"y":0,"z":1},"block_id":69},{"move":{"x":2,"y":0,"z":7},"block_id":615,"extra_data":{"point":{"x":0.27470974286023875,"y":0.4616593054050142,"z":1.0020000000000024}},"rotate":{"x":0,"y":0,"z":0}},{"move":{"x":2,"y":0,"z":8},"block_id":69},{"move":{"x":2,"y":0,"z":9},"block_id":1506},{"move":{"x":2,"y":14,"z":0},"block_id":69},{"move":{"x":2,"y":14,"z":9},"block_id":69},{"move":{"x":3,"y":0,"z":0},"block_id":1504},{"move":{"x":3,"y":0,"z":1},"block_id":69},{"move":{"x":3,"y":0,"z":2},"block_id":52,"extra_data":{"can_destroy":true,"slots":{}},"rotate":{"x":13,"y":0,"z":0}},{"move":{"x":3,"y":0,"z":3},"block_id":615,"extra_data":{"point":{"x":1.0020000000000095,"y":0.2145122113144442,"z":0.29368707105467706}},"rotate":{"x":3,"y":0,"z":0}},{"move":{"x":3,"y":0,"z":7},"block_id":52,"extra_data":{"can_destroy":true,"slots":{}},"rotate":{"x":18,"y":0,"z":0}},{"move":{"x":3,"y":0,"z":8},"block_id":69},{"move":{"x":3,"y":0,"z":9},"block_id":1506},{"move":{"x":3,"y":14,"z":0},"block_id":69},{"move":{"x":3,"y":14,"z":9},"block_id":69},{"move":{"x":4,"y":0,"z":0},"block_id":1504},{"move":{"x":4,"y":0,"z":1},"block_id":69},{"move":{"x":4,"y":0,"z":2},"block_id":69},{"move":{"x":4,"y":0,"z":3},"block_id":69},{"move":{"x":4,"y":0,"z":6},"block_id":69},{"move":{"x":4,"y":0,"z":7},"block_id":69},{"move":{"x":4,"y":0,"z":8},"block_id":69},{"move":{"x":4,"y":0,"z":9},"block_id":1506},{"move":{"x":4,"y":1,"z":0},"block_id":106,"extra_data":{"east":true,"rotate":false}},{"move":{"x":4,"y":1,"z":1},"block_id":643,"extra_data":{"text":"3","username":"sciner","dt":"2023-01-10T21:00:04.524Z"},"rotate":{"x":1.5980476294670962,"y":1,"z":0}},{"move":{"x":4,"y":1,"z":8},"block_id":643,"extra_data":{"text":"2","username":"sciner","dt":"2023-01-10T21:00:01.172Z"},"rotate":{"x":0.5511900757858452,"y":1,"z":0}},{"move":{"x":4,"y":1,"z":9},"block_id":65,"rotate":{"x":3,"y":0,"z":0}},{"move":{"x":4,"y":2,"z":0},"block_id":106,"extra_data":{"east":true,"rotate":false}},{"move":{"x":4,"y":2,"z":9},"block_id":65,"rotate":{"x":3,"y":0,"z":0}},{"move":{"x":4,"y":3,"z":0},"block_id":106,"extra_data":{"east":true,"rotate":false}},{"move":{"x":4,"y":3,"z":9},"block_id":65,"rotate":{"x":3,"y":0,"z":0}},{"move":{"x":4,"y":4,"z":0},"block_id":50,"rotate":{"x":3,"y":0,"z":0}},{"move":{"x":4,"y":5,"z":9},"block_id":643,"extra_data":{"text":"2","username":"sciner","dt":"2023-01-10T21:00:15.464Z"},"rotate":{"x":3,"y":0,"z":0}},{"move":{"x":4,"y":6,"z":0},"block_id":615,"extra_data":{"point":{"x":1.0020000000000095,"y":0.8762874664969491,"z":0.2661063272064723}},"rotate":{"x":3,"y":0,"z":0}},{"move":{"x":4,"y":14,"z":0},"block_id":69},{"move":{"x":4,"y":14,"z":9},"block_id":69},{"move":{"x":5,"y":0,"z":0},"block_id":1504},{"move":{"x":5,"y":0,"z":1},"block_id":1505},{"move":{"x":5,"y":0,"z":2},"block_id":1505},{"move":{"x":5,"y":0,"z":3},"block_id":1505},{"move":{"x":5,"y":0,"z":6},"block_id":1505},{"move":{"x":5,"y":0,"z":7},"block_id":1505},{"move":{"x":5,"y":0,"z":8},"block_id":1505},{"move":{"x":5,"y":0,"z":9},"block_id":1505},{"move":{"x":5,"y":1,"z":0},"block_id":1504},{"move":{"x":5,"y":1,"z":1},"block_id":65,"rotate":{"x":2,"y":0,"z":0}},{"move":{"x":5,"y":1,"z":8},"block_id":106,"extra_data":{"north":true,"rotate":false}},{"move":{"x":5,"y":1,"z":9},"block_id":1505},{"move":{"x":5,"y":2,"z":0},"block_id":1504},{"move":{"x":5,"y":2,"z":1},"block_id":65,"rotate":{"x":2,"y":0,"z":0}},{"move":{"x":5,"y":2,"z":8},"block_id":106,"extra_data":{"north":true,"rotate":false}},{"move":{"x":5,"y":2,"z":9},"block_id":1505},{"move":{"x":5,"y":3,"z":0},"block_id":1504},{"move":{"x":5,"y":3,"z":1},"block_id":65,"rotate":{"x":2,"y":0,"z":0}},{"move":{"x":5,"y":3,"z":8},"block_id":106,"extra_data":{"north":true,"rotate":false}},{"move":{"x":5,"y":3,"z":9},"block_id":1505},{"move":{"x":5,"y":4,"z":0},"block_id":1504},{"move":{"x":5,"y":4,"z":8},"block_id":50,"rotate":{"x":0,"y":0,"z":0}},{"move":{"x":5,"y":4,"z":9},"block_id":1505},{"move":{"x":5,"y":5,"z":0},"block_id":1504},{"move":{"x":5,"y":5,"z":1},"block_id":643,"extra_data":{"text":"3","username":"sciner","dt":"2023-01-10T21:00:17.789Z"},"rotate":{"x":2,"y":0,"z":0}},{"move":{"x":5,"y":5,"z":9},"block_id":1505},{"move":{"x":5,"y":6,"z":0},"block_id":1504},{"move":{"x":5,"y":6,"z":8},"block_id":615,"extra_data":{"point":{"x":0.7037043544094388,"y":0.6496732779040784,"z":1.0020000000000024}},"rotate":{"x":0,"y":0,"z":0}},{"move":{"x":5,"y":6,"z":9},"block_id":1505},{"move":{"x":5,"y":7,"z":0},"block_id":1504},{"move":{"x":5,"y":7,"z":9},"block_id":1505},{"move":{"x":5,"y":8,"z":0},"block_id":1504},{"move":{"x":5,"y":8,"z":9},"block_id":1505},{"move":{"x":5,"y":9,"z":0},"block_id":1504},{"move":{"x":5,"y":9,"z":9},"block_id":1505},{"move":{"x":5,"y":10,"z":0},"block_id":1504},{"move":{"x":5,"y":10,"z":9},"block_id":1505},{"move":{"x":5,"y":11,"z":0},"block_id":1504},{"move":{"x":5,"y":11,"z":9},"block_id":1505},{"move":{"x":5,"y":12,"z":0},"block_id":1504},{"move":{"x":5,"y":12,"z":9},"block_id":1505},{"move":{"x":5,"y":13,"z":0},"block_id":1504},{"move":{"x":5,"y":13,"z":9},"block_id":1505},{"move":{"x":5,"y":14,"z":0},"block_id":69},{"move":{"x":5,"y":14,"z":1},"block_id":69},{"move":{"x":5,"y":14,"z":2},"block_id":69},{"move":{"x":5,"y":14,"z":3},"block_id":69},{"move":{"x":5,"y":14,"z":6},"block_id":69},{"move":{"x":5,"y":14,"z":7},"block_id":69},{"move":{"x":5,"y":14,"z":8},"block_id":69},{"move":{"x":5,"y":14,"z":9},"block_id":69}],"rot":[]}