{"name":"test","world":{"pos1":{"x":-205,"y":9,"z":41},"pos2":{"x":-215,"y":23,"z":32},"door_bottom":{"x":-210,"y":9,"z":37}},"meta":{},"size":{"x":11,"y":15,"z":10},"door_pos":{"x":5,"y":0,"z":4},"blocks":[{"move":{"x":-5,"y":8,"z":0},"block_id":1511},{"move":{"x":-5,"y":8,"z":1},"block_id":1511},{"move":{"x":-5,"y":8,"z":2},"block_id":1511},{"move":{"x":-5,"y":8,"z":3},"block_id":1511},{"move":{"x":-5,"y":8,"z":6},"block_id":1511},{"move":{"x":-5,"y":8,"z":7},"block_id":1511},{"move":{"x":-5,"y":8,"z":8},"block_id":1511},{"move":{"x":-5,"y":8,"z":9},"block_id":1506},{"move":{"x":-5,"y":9,"z":0},"block_id":1511},{"move":{"x":-5,"y":9,"z":9},"block_id":1506},{"move":{"x":-5,"y":10,"z":0},"block_id":1511},{"move":{"x":-5,"y":10,"z":9},"block_id":1506},{"move":{"x":-5,"y":11,"z":0},"block_id":1511},{"move":{"x":-5,"y":11,"z":9},"block_id":1506},{"move":{"x":-5,"y":12,"z":0},"block_id":1511},{"move":{"x":-5,"y":12,"z":9},"block_id":1506},{"move":{"x":-5,"y":13,"z":0},"block_id":1511},{"move":{"x":-5,"y":13,"z":9},"block_id":1506},{"move":{"x":-5,"y":14,"z":0},"block_id":1511},{"move":{"x":-5,"y":14,"z":9},"block_id":1506},{"move":{"x":-5,"y":15,"z":0},"block_id":1511},{"move":{"x":-5,"y":15,"z":9},"block_id":1506},{"move":{"x":-5,"y":16,"z":0},"block_id":1511},{"move":{"x":-5,"y":16,"z":9},"block_id":1506},{"move":{"x":-5,"y":17,"z":0},"block_id":1511},{"move":{"x":-5,"y":17,"z":9},"block_id":1506},{"move":{"x":-5,"y":18,"z":0},"block_id":1511},{"move":{"x":-5,"y":18,"z":9},"block_id":1506},{"move":{"x":-5,"y":19,"z":0},"block_id":1511},{"move":{"x":-5,"y":19,"z":9},"block_id":1506},{"move":{"x":-5,"y":20,"z":0},"block_id":1511},{"move":{"x":-5,"y":20,"z":9},"block_id":1506},{"move":{"x":-5,"y":21,"z":0},"block_id":1511},{"move":{"x":-5,"y":21,"z":9},"block_id":1506},{"move":{"x":-5,"y":22,"z":0},"block_id":69},{"move":{"x":-5,"y":22,"z":1},"block_id":69},{"move":{"x":-5,"y":22,"z":2},"block_id":69},{"move":{"x":-5,"y":22,"z":3},"block_id":69},{"move":{"x":-5,"y":22,"z":6},"block_id":69},{"move":{"x":-5,"y":22,"z":7},"block_id":69},{"move":{"x":-5,"y":22,"z":8},"block_id":69},{"move":{"x":-5,"y":22,"z":9},"block_id":69},{"move":{"x":-4,"y":8,"z":0},"block_id":1504},{"move":{"x":-4,"y":8,"z":1},"block_id":69},{"move":{"x":-4,"y":8,"z":2},"block_id":69},{"move":{"x":-4,"y":8,"z":3},"block_id":69},{"move":{"x":-4,"y":8,"z":6},"block_id":69},{"move":{"x":-4,"y":8,"z":7},"block_id":69},{"move":{"x":-4,"y":8,"z":8},"block_id":69},{"move":{"x":-4,"y":8,"z":9},"block_id":1506},{"move":{"x":-4,"y":22,"z":0},"block_id":69},{"move":{"x":-4,"y":22,"z":9},"block_id":69},{"move":{"x":-3,"y":8,"z":0},"block_id":1504},{"move":{"x":-3,"y":8,"z":1},"block_id":69},{"move":{"x":-3,"y":8,"z":8},"block_id":69},{"move":{"x":-3,"y":8,"z":9},"block_id":1506},{"move":{"x":-3,"y":22,"z":0},"block_id":69},{"move":{"x":-3,"y":22,"z":9},"block_id":69},{"move":{"x":-2,"y":8,"z":0},"block_id":1504},{"move":{"x":-2,"y":8,"z":1},"block_id":69},{"move":{"x":-2,"y":8,"z":8},"block_id":69},{"move":{"x":-2,"y":8,"z":9},"block_id":1506},{"move":{"x":-2,"y":22,"z":0},"block_id":69},{"move":{"x":-2,"y":22,"z":9},"block_id":69},{"move":{"x":-1,"y":8,"z":0},"block_id":1504},{"move":{"x":-1,"y":8,"z":1},"block_id":69},{"move":{"x":-1,"y":8,"z":8},"block_id":69},{"move":{"x":-1,"y":8,"z":9},"block_id":1506},{"move":{"x":-1,"y":22,"z":0},"block_id":69},{"move":{"x":-1,"y":22,"z":9},"block_id":69},{"move":{"x":1,"y":8,"z":0},"block_id":1504},{"move":{"x":1,"y":8,"z":1},"block_id":69},{"move":{"x":1,"y":8,"z":8},"block_id":69},{"move":{"x":1,"y":8,"z":9},"block_id":1506},{"move":{"x":1,"y":22,"z":0},"block_id":69},{"move":{"x":1,"y":22,"z":9},"block_id":69},{"move":{"x":2,"y":8,"z":0},"block_id":1504},{"move":{"x":2,"y":8,"z":1},"block_id":69},{"move":{"x":2,"y":8,"z":8},"block_id":69},{"move":{"x":2,"y":8,"z":9},"block_id":1506},{"move":{"x":2,"y":22,"z":0},"block_id":69},{"move":{"x":2,"y":22,"z":9},"block_id":69},{"move":{"x":3,"y":8,"z":0},"block_id":1504},{"move":{"x":3,"y":8,"z":1},"block_id":69},{"move":{"x":3,"y":8,"z":8},"block_id":69},{"move":{"x":3,"y":8,"z":9},"block_id":1506},{"move":{"x":3,"y":22,"z":0},"block_id":69},{"move":{"x":3,"y":22,"z":9},"block_id":69},{"move":{"x":4,"y":8,"z":0},"block_id":1504},{"move":{"x":4,"y":8,"z":1},"block_id":69},{"move":{"x":4,"y":8,"z":2},"block_id":69},{"move":{"x":4,"y":8,"z":3},"block_id":69},{"move":{"x":4,"y":8,"z":6},"block_id":69},{"move":{"x":4,"y":8,"z":7},"block_id":69},{"move":{"x":4,"y":8,"z":8},"block_id":69},{"move":{"x":4,"y":8,"z":9},"block_id":1506},{"move":{"x":4,"y":22,"z":0},"block_id":69},{"move":{"x":4,"y":22,"z":9},"block_id":69},{"move":{"x":5,"y":8,"z":0},"block_id":1504},{"move":{"x":5,"y":8,"z":1},"block_id":1505},{"move":{"x":5,"y":8,"z":2},"block_id":1505},{"move":{"x":5,"y":8,"z":3},"block_id":1505},{"move":{"x":5,"y":8,"z":6},"block_id":1505},{"move":{"x":5,"y":8,"z":7},"block_id":1505},{"move":{"x":5,"y":8,"z":8},"block_id":1505},{"move":{"x":5,"y":8,"z":9},"block_id":1505},{"move":{"x":5,"y":9,"z":0},"block_id":1504},{"move":{"x":5,"y":9,"z":9},"block_id":1505},{"move":{"x":5,"y":10,"z":0},"block_id":1504},{"move":{"x":5,"y":10,"z":9},"block_id":1505},{"move":{"x":5,"y":11,"z":0},"block_id":1504},{"move":{"x":5,"y":11,"z":9},"block_id":1505},{"move":{"x":5,"y":12,"z":0},"block_id":1504},{"move":{"x":5,"y":12,"z":9},"block_id":1505},{"move":{"x":5,"y":13,"z":0},"block_id":1504},{"move":{"x":5,"y":13,"z":9},"block_id":1505},{"move":{"x":5,"y":14,"z":0},"block_id":1504},{"move":{"x":5,"y":14,"z":9},"block_id":1505},{"move":{"x":5,"y":15,"z":0},"block_id":1504},{"move":{"x":5,"y":15,"z":9},"block_id":1505},{"move":{"x":5,"y":16,"z":0},"block_id":1504},{"move":{"x":5,"y":16,"z":9},"block_id":1505},{"move":{"x":5,"y":17,"z":0},"block_id":1504},{"move":{"x":5,"y":17,"z":9},"block_id":1505},{"move":{"x":5,"y":18,"z":0},"block_id":1504},{"move":{"x":5,"y":18,"z":9},"block_id":1505},{"move":{"x":5,"y":19,"z":0},"block_id":1504},{"move":{"x":5,"y":19,"z":9},"block_id":1505},{"move":{"x":5,"y":20,"z":0},"block_id":1504},{"move":{"x":5,"y":20,"z":9},"block_id":1505},{"move":{"x":5,"y":21,"z":0},"block_id":1504},{"move":{"x":5,"y":21,"z":9},"block_id":1505},{"move":{"x":5,"y":22,"z":0},"block_id":69},{"move":{"x":5,"y":22,"z":1},"block_id":69},{"move":{"x":5,"y":22,"z":2},"block_id":69},{"move":{"x":5,"y":22,"z":3},"block_id":69},{"move":{"x":5,"y":22,"z":6},"block_id":69},{"move":{"x":5,"y":22,"z":7},"block_id":69},{"move":{"x":5,"y":22,"z":8},"block_id":69},{"move":{"x":5,"y":22,"z":9},"block_id":69}],"rot":[]}