{"name":"underearth_tower","world":{"pos1":{"x":-215,"y":-80,"z":1},"pos2":{"x":-221,"y":5,"z":-5},"door_bottom":{"x":-218,"y":1,"z":1}},"meta":null,"size":{"x":7,"y":86,"z":7},"door_pos":{"x":3,"y":81,"z":0},"blocks":[{"move":{"x":-3,"y":-81,"z":0},"block_id":9},{"move":{"x":-3,"y":-81,"z":1},"block_id":70},{"move":{"x":-3,"y":-81,"z":2},"block_id":8},{"move":{"x":-3,"y":-81,"z":3},"block_id":70},{"move":{"x":-3,"y":-81,"z":4},"block_id":70},{"move":{"x":-3,"y":-81,"z":5},"block_id":8},{"move":{"x":-3,"y":-81,"z":6},"block_id":9},{"move":{"x":-3,"y":-80,"z":0},"block_id":9},{"move":{"x":-3,"y":-80,"z":1},"block_id":8},{"move":{"x":-3,"y":-80,"z":2},"block_id":9},{"move":{"x":-3,"y":-80,"z":3},"block_id":146},{"move":{"x":-3,"y":-80,"z":4},"block_id":70},{"move":{"x":-3,"y":-80,"z":5},"block_id":70},{"move":{"x":-3,"y":-80,"z":6},"block_id":70},{"move":{"x":-3,"y":-79,"z":0},"block_id":8},{"move":{"x":-3,"y":-79,"z":1},"block_id":9},{"move":{"x":-3,"y":-79,"z":2},"block_id":8},{"move":{"x":-3,"y":-79,"z":3},"block_id":70},{"move":{"x":-3,"y":-79,"z":4},"block_id":70},{"move":{"x":-3,"y":-79,"z":5},"block_id":9},{"move":{"x":-3,"y":-79,"z":6},"block_id":146},{"move":{"x":-3,"y":-78,"z":0},"block_id":70},{"move":{"x":-3,"y":-78,"z":1},"block_id":9},{"move":{"x":-3,"y":-78,"z":2},"block_id":70},{"move":{"x":-3,"y":-78,"z":3},"block_id":70},{"move":{"x":-3,"y":-78,"z":4},"block_id":70},{"move":{"x":-3,"y":-78,"z":5},"block_id":8},{"move":{"x":-3,"y":-78,"z":6},"block_id":8},{"move":{"x":-3,"y":-77,"z":0},"block_id":146},{"move":{"x":-3,"y":-77,"z":1},"block_id":70},{"move":{"x":-3,"y":-77,"z":2},"block_id":146},{"move":{"x":-3,"y":-77,"z":3},"block_id":146},{"move":{"x":-3,"y":-77,"z":4},"block_id":146},{"move":{"x":-3,"y":-77,"z":5},"block_id":146},{"move":{"x":-3,"y":-77,"z":6},"block_id":8},{"move":{"x":-3,"y":-76,"z":0},"block_id":9},{"move":{"x":-3,"y":-76,"z":1},"block_id":9},{"move":{"x":-3,"y":-76,"z":2},"block_id":8},{"move":{"x":-3,"y":-76,"z":3},"block_id":8},{"move":{"x":-3,"y":-76,"z":4},"block_id":8},{"move":{"x":-3,"y":-76,"z":5},"block_id":146},{"move":{"x":-3,"y":-76,"z":6},"block_id":146},{"move":{"x":-3,"y":-75,"z":0},"block_id":9},{"move":{"x":-3,"y":-75,"z":1},"block_id":146},{"move":{"x":-3,"y":-75,"z":2},"block_id":146},{"move":{"x":-3,"y":-75,"z":3},"block_id":8},{"move":{"x":-3,"y":-75,"z":4},"block_id":8},{"move":{"x":-3,"y":-75,"z":5},"block_id":9},{"move":{"x":-3,"y":-75,"z":6},"block_id":146},{"move":{"x":-3,"y":-74,"z":0},"block_id":8},{"move":{"x":-3,"y":-74,"z":1},"block_id":8},{"move":{"x":-3,"y":-74,"z":2},"block_id":70},{"move":{"x":-3,"y":-74,"z":3},"block_id":8},{"move":{"x":-3,"y":-74,"z":4},"block_id":70},{"move":{"x":-3,"y":-74,"z":5},"block_id":70},{"move":{"x":-3,"y":-74,"z":6},"block_id":146},{"move":{"x":-3,"y":-73,"z":0},"block_id":146},{"move":{"x":-3,"y":-73,"z":1},"block_id":70},{"move":{"x":-3,"y":-73,"z":2},"block_id":70},{"move":{"x":-3,"y":-73,"z":3},"block_id":8},{"move":{"x":-3,"y":-73,"z":4},"block_id":70},{"move":{"x":-3,"y":-73,"z":5},"block_id":8},{"move":{"x":-3,"y":-73,"z":6},"block_id":9},{"move":{"x":-3,"y":-72,"z":0},"block_id":9},{"move":{"x":-3,"y":-72,"z":1},"block_id":70},{"move":{"x":-3,"y":-72,"z":2},"block_id":146},{"move":{"x":-3,"y":-72,"z":3},"block_id":70},{"move":{"x":-3,"y":-72,"z":4},"block_id":9},{"move":{"x":-3,"y":-72,"z":5},"block_id":146},{"move":{"x":-3,"y":-72,"z":6},"block_id":146},{"move":{"x":-3,"y":-71,"z":0},"block_id":70},{"move":{"x":-3,"y":-71,"z":1},"block_id":8},{"move":{"x":-3,"y":-71,"z":2},"block_id":70},{"move":{"x":-3,"y":-71,"z":3},"block_id":70},{"move":{"x":-3,"y":-71,"z":4},"block_id":70},{"move":{"x":-3,"y":-71,"z":5},"block_id":9},{"move":{"x":-3,"y":-71,"z":6},"block_id":8},{"move":{"x":-3,"y":-70,"z":0},"block_id":9},{"move":{"x":-3,"y":-70,"z":1},"block_id":146},{"move":{"x":-3,"y":-70,"z":2},"block_id":70},{"move":{"x":-3,"y":-70,"z":3},"block_id":8},{"move":{"x":-3,"y":-70,"z":4},"block_id":70},{"move":{"x":-3,"y":-70,"z":5},"block_id":70},{"move":{"x":-3,"y":-70,"z":6},"block_id":8},{"move":{"x":-3,"y":-69,"z":0},"block_id":70},{"move":{"x":-3,"y":-69,"z":1},"block_id":8},{"move":{"x":-3,"y":-69,"z":2},"block_id":146},{"move":{"x":-3,"y":-69,"z":3},"block_id":70},{"move":{"x":-3,"y":-69,"z":4},"block_id":9},{"move":{"x":-3,"y":-69,"z":5},"block_id":8},{"move":{"x":-3,"y":-69,"z":6},"block_id":146},{"move":{"x":-3,"y":-68,"z":0},"block_id":70},{"move":{"x":-3,"y":-68,"z":1},"block_id":146},{"move":{"x":-3,"y":-68,"z":2},"block_id":8},{"move":{"x":-3,"y":-68,"z":3},"block_id":70},{"move":{"x":-3,"y":-68,"z":4},"block_id":70},{"move":{"x":-3,"y":-68,"z":5},"block_id":146},{"move":{"x":-3,"y":-68,"z":6},"block_id":146},{"move":{"x":-3,"y":-67,"z":0},"block_id":146},{"move":{"x":-3,"y":-67,"z":1},"block_id":9},{"move":{"x":-3,"y":-67,"z":2},"block_id":70},{"move":{"x":-3,"y":-67,"z":3},"block_id":9},{"move":{"x":-3,"y":-67,"z":4},"block_id":146},{"move":{"x":-3,"y":-67,"z":5},"block_id":146},{"move":{"x":-3,"y":-67,"z":6},"block_id":9},{"move":{"x":-3,"y":-66,"z":0},"block_id":9},{"move":{"x":-3,"y":-66,"z":1},"block_id":9},{"move":{"x":-3,"y":-66,"z":2},"block_id":146},{"move":{"x":-3,"y":-66,"z":3},"block_id":70},{"move":{"x":-3,"y":-66,"z":4},"block_id":8},{"move":{"x":-3,"y":-66,"z":5},"block_id":70},{"move":{"x":-3,"y":-66,"z":6},"block_id":9},{"move":{"x":-3,"y":-65,"z":0},"block_id":9},{"move":{"x":-3,"y":-65,"z":1},"block_id":9},{"move":{"x":-3,"y":-65,"z":2},"block_id":8},{"move":{"x":-3,"y":-65,"z":3},"block_id":70},{"move":{"x":-3,"y":-65,"z":4},"block_id":8},{"move":{"x":-3,"y":-65,"z":5},"block_id":8},{"move":{"x":-3,"y":-65,"z":6},"block_id":9},{"move":{"x":-3,"y":-64,"z":0},"block_id":70},{"move":{"x":-3,"y":-64,"z":1},"block_id":9},{"move":{"x":-3,"y":-64,"z":2},"block_id":146},{"move":{"x":-3,"y":-64,"z":3},"block_id":146},{"move":{"x":-3,"y":-64,"z":4},"block_id":70},{"move":{"x":-3,"y":-64,"z":5},"block_id":8},{"move":{"x":-3,"y":-64,"z":6},"block_id":146},{"move":{"x":-3,"y":-63,"z":0},"block_id":8},{"move":{"x":-3,"y":-63,"z":1},"block_id":70},{"move":{"x":-3,"y":-63,"z":2},"block_id":8},{"move":{"x":-3,"y":-63,"z":3},"block_id":70},{"move":{"x":-3,"y":-63,"z":4},"block_id":8},{"move":{"x":-3,"y":-63,"z":5},"block_id":146},{"move":{"x":-3,"y":-63,"z":6},"block_id":146},{"move":{"x":-3,"y":-62,"z":0},"block_id":146},{"move":{"x":-3,"y":-62,"z":1},"block_id":9},{"move":{"x":-3,"y":-62,"z":2},"block_id":70},{"move":{"x":-3,"y":-62,"z":3},"block_id":146},{"move":{"x":-3,"y":-62,"z":4},"block_id":70},{"move":{"x":-3,"y":-62,"z":5},"block_id":70},{"move":{"x":-3,"y":-62,"z":6},"block_id":8},{"move":{"x":-3,"y":-61,"z":0},"block_id":8},{"move":{"x":-3,"y":-61,"z":1},"block_id":70},{"move":{"x":-3,"y":-61,"z":2},"block_id":146},{"move":{"x":-3,"y":-61,"z":3},"block_id":9},{"move":{"x":-3,"y":-61,"z":4},"block_id":9},{"move":{"x":-3,"y":-61,"z":5},"block_id":9},{"move":{"x":-3,"y":-61,"z":6},"block_id":8},{"move":{"x":-3,"y":-60,"z":0},"block_id":146},{"move":{"x":-3,"y":-60,"z":1},"block_id":9},{"move":{"x":-3,"y":-60,"z":2},"block_id":146},{"move":{"x":-3,"y":-60,"z":3},"block_id":70},{"move":{"x":-3,"y":-60,"z":4},"block_id":8},{"move":{"x":-3,"y":-60,"z":5},"block_id":70},{"move":{"x":-3,"y":-60,"z":6},"block_id":70},{"move":{"x":-3,"y":-59,"z":0},"block_id":70},{"move":{"x":-3,"y":-59,"z":1},"block_id":8},{"move":{"x":-3,"y":-59,"z":2},"block_id":70},{"move":{"x":-3,"y":-59,"z":3},"block_id":146},{"move":{"x":-3,"y":-59,"z":4},"block_id":70},{"move":{"x":-3,"y":-59,"z":5},"block_id":146},{"move":{"x":-3,"y":-59,"z":6},"block_id":9},{"move":{"x":-3,"y":-58,"z":0},"block_id":70},{"move":{"x":-3,"y":-58,"z":1},"block_id":70},{"move":{"x":-3,"y":-58,"z":2},"block_id":70},{"move":{"x":-3,"y":-58,"z":3},"block_id":70},{"move":{"x":-3,"y":-58,"z":4},"block_id":146},{"move":{"x":-3,"y":-58,"z":5},"block_id":9},{"move":{"x":-3,"y":-58,"z":6},"block_id":146},{"move":{"x":-3,"y":-57,"z":0},"block_id":9},{"move":{"x":-3,"y":-57,"z":1},"block_id":146},{"move":{"x":-3,"y":-57,"z":2},"block_id":9},{"move":{"x":-3,"y":-57,"z":3},"block_id":9},{"move":{"x":-3,"y":-57,"z":4},"block_id":146},{"move":{"x":-3,"y":-57,"z":5},"block_id":8},{"move":{"x":-3,"y":-57,"z":6},"block_id":9},{"move":{"x":-3,"y":-56,"z":0},"block_id":70},{"move":{"x":-3,"y":-56,"z":1},"block_id":8},{"move":{"x":-3,"y":-56,"z":2},"block_id":8},{"move":{"x":-3,"y":-56,"z":3},"block_id":70},{"move":{"x":-3,"y":-56,"z":4},"block_id":70},{"move":{"x":-3,"y":-56,"z":5},"block_id":70},{"move":{"x":-3,"y":-56,"z":6},"block_id":70},{"move":{"x":-3,"y":-55,"z":0},"block_id":8},{"move":{"x":-3,"y":-55,"z":1},"block_id":146},{"move":{"x":-3,"y":-55,"z":2},"block_id":70},{"move":{"x":-3,"y":-55,"z":3},"block_id":9},{"move":{"x":-3,"y":-55,"z":4},"block_id":146},{"move":{"x":-3,"y":-55,"z":5},"block_id":9},{"move":{"x":-3,"y":-55,"z":6},"block_id":70},{"move":{"x":-3,"y":-54,"z":0},"block_id":8},{"move":{"x":-3,"y":-54,"z":1},"block_id":8},{"move":{"x":-3,"y":-54,"z":2},"block_id":70},{"move":{"x":-3,"y":-54,"z":3},"block_id":146},{"move":{"x":-3,"y":-54,"z":4},"block_id":8},{"move":{"x":-3,"y":-54,"z":5},"block_id":70},{"move":{"x":-3,"y":-54,"z":6},"block_id":70},{"move":{"x":-3,"y":-53,"z":0},"block_id":70},{"move":{"x":-3,"y":-53,"z":1},"block_id":8},{"move":{"x":-3,"y":-53,"z":2},"block_id":8},{"move":{"x":-3,"y":-53,"z":3},"block_id":70},{"move":{"x":-3,"y":-53,"z":4},"block_id":8},{"move":{"x":-3,"y":-53,"z":5},"block_id":8},{"move":{"x":-3,"y":-53,"z":6},"block_id":8},{"move":{"x":-3,"y":-52,"z":0},"block_id":70},{"move":{"x":-3,"y":-52,"z":1},"block_id":8},{"move":{"x":-3,"y":-52,"z":2},"block_id":9},{"move":{"x":-3,"y":-52,"z":3},"block_id":8},{"move":{"x":-3,"y":-52,"z":4},"block_id":8},{"move":{"x":-3,"y":-52,"z":5},"block_id":70},{"move":{"x":-3,"y":-52,"z":6},"block_id":146},{"move":{"x":-3,"y":-51,"z":0},"block_id":8},{"move":{"x":-3,"y":-51,"z":1},"block_id":9},{"move":{"x":-3,"y":-51,"z":2},"block_id":146},{"move":{"x":-3,"y":-51,"z":3},"block_id":70},{"move":{"x":-3,"y":-51,"z":4},"block_id":70},{"move":{"x":-3,"y":-51,"z":5},"block_id":146},{"move":{"x":-3,"y":-51,"z":6},"block_id":70},{"move":{"x":-3,"y":-50,"z":0},"block_id":146},{"move":{"x":-3,"y":-50,"z":1},"block_id":8},{"move":{"x":-3,"y":-50,"z":2},"block_id":9},{"move":{"x":-3,"y":-50,"z":3},"block_id":146},{"move":{"x":-3,"y":-50,"z":4},"block_id":9},{"move":{"x":-3,"y":-50,"z":5},"block_id":8},{"move":{"x":-3,"y":-50,"z":6},"block_id":9},{"move":{"x":-3,"y":-49,"z":0},"block_id":9},{"move":{"x":-3,"y":-49,"z":1},"block_id":8},{"move":{"x":-3,"y":-49,"z":2},"block_id":8},{"move":{"x":-3,"y":-49,"z":3},"block_id":9},{"move":{"x":-3,"y":-49,"z":4},"block_id":146},{"move":{"x":-3,"y":-49,"z":5},"block_id":70},{"move":{"x":-3,"y":-49,"z":6},"block_id":9},{"move":{"x":-3,"y":-48,"z":0},"block_id":146},{"move":{"x":-3,"y":-48,"z":1},"block_id":146},{"move":{"x":-3,"y":-48,"z":2},"block_id":146},{"move":{"x":-3,"y":-48,"z":3},"block_id":70},{"move":{"x":-3,"y":-48,"z":4},"block_id":9},{"move":{"x":-3,"y":-48,"z":5},"block_id":9},{"move":{"x":-3,"y":-48,"z":6},"block_id":146},{"move":{"x":-3,"y":-47,"z":0},"block_id":8},{"move":{"x":-3,"y":-47,"z":1},"block_id":70},{"move":{"x":-3,"y":-47,"z":2},"block_id":70},{"move":{"x":-3,"y":-47,"z":3},"block_id":9},{"move":{"x":-3,"y":-47,"z":4},"block_id":9},{"move":{"x":-3,"y":-47,"z":5},"block_id":70},{"move":{"x":-3,"y":-47,"z":6},"block_id":146},{"move":{"x":-3,"y":-46,"z":0},"block_id":9},{"move":{"x":-3,"y":-46,"z":1},"block_id":8},{"move":{"x":-3,"y":-46,"z":2},"block_id":8},{"move":{"x":-3,"y":-46,"z":3},"block_id":8},{"move":{"x":-3,"y":-46,"z":4},"block_id":70},{"move":{"x":-3,"y":-46,"z":5},"block_id":8},{"move":{"x":-3,"y":-46,"z":6},"block_id":146},{"move":{"x":-3,"y":-45,"z":0},"block_id":146},{"move":{"x":-3,"y":-45,"z":1},"block_id":146},{"move":{"x":-3,"y":-45,"z":2},"block_id":8},{"move":{"x":-3,"y":-45,"z":3},"block_id":9},{"move":{"x":-3,"y":-45,"z":4},"block_id":146},{"move":{"x":-3,"y":-45,"z":5},"block_id":70},{"move":{"x":-3,"y":-45,"z":6},"block_id":146},{"move":{"x":-3,"y":-44,"z":0},"block_id":70},{"move":{"x":-3,"y":-44,"z":1},"block_id":9},{"move":{"x":-3,"y":-44,"z":2},"block_id":9},{"move":{"x":-3,"y":-44,"z":3},"block_id":70},{"move":{"x":-3,"y":-44,"z":4},"block_id":9},{"move":{"x":-3,"y":-44,"z":5},"block_id":70},{"move":{"x":-3,"y":-44,"z":6},"block_id":146},{"move":{"x":-3,"y":-43,"z":0},"block_id":70},{"move":{"x":-3,"y":-43,"z":1},"block_id":146},{"move":{"x":-3,"y":-43,"z":2},"block_id":70},{"move":{"x":-3,"y":-43,"z":3},"block_id":70},{"move":{"x":-3,"y":-43,"z":4},"block_id":70},{"move":{"x":-3,"y":-43,"z":5},"block_id":146},{"move":{"x":-3,"y":-43,"z":6},"block_id":70},{"move":{"x":-3,"y":-42,"z":0},"block_id":8},{"move":{"x":-3,"y":-42,"z":1},"block_id":9},{"move":{"x":-3,"y":-42,"z":2},"block_id":8},{"move":{"x":-3,"y":-42,"z":3},"block_id":8},{"move":{"x":-3,"y":-42,"z":4},"block_id":146},{"move":{"x":-3,"y":-42,"z":5},"block_id":8},{"move":{"x":-3,"y":-42,"z":6},"block_id":8},{"move":{"x":-3,"y":-41,"z":0},"block_id":8},{"move":{"x":-3,"y":-41,"z":1},"block_id":8},{"move":{"x":-3,"y":-41,"z":2},"block_id":8},{"move":{"x":-3,"y":-41,"z":3},"block_id":146},{"move":{"x":-3,"y":-41,"z":4},"block_id":70},{"move":{"x":-3,"y":-41,"z":5},"block_id":8},{"move":{"x":-3,"y":-41,"z":6},"block_id":8},{"move":{"x":-3,"y":-40,"z":0},"block_id":146},{"move":{"x":-3,"y":-40,"z":1},"block_id":8},{"move":{"x":-3,"y":-40,"z":2},"block_id":9},{"move":{"x":-3,"y":-40,"z":3},"block_id":146},{"move":{"x":-3,"y":-40,"z":4},"block_id":146},{"move":{"x":-3,"y":-40,"z":5},"block_id":8},{"move":{"x":-3,"y":-40,"z":6},"block_id":146},{"move":{"x":-3,"y":-39,"z":0},"block_id":70},{"move":{"x":-3,"y":-39,"z":1},"block_id":9},{"move":{"x":-3,"y":-39,"z":2},"block_id":70},{"move":{"x":-3,"y":-39,"z":3},"block_id":146},{"move":{"x":-3,"y":-39,"z":4},"block_id":9},{"move":{"x":-3,"y":-39,"z":5},"block_id":70},{"move":{"x":-3,"y":-39,"z":6},"block_id":70},{"move":{"x":-3,"y":-38,"z":0},"block_id":8},{"move":{"x":-3,"y":-38,"z":1},"block_id":70},{"move":{"x":-3,"y":-38,"z":2},"block_id":146},{"move":{"x":-3,"y":-38,"z":3},"block_id":146},{"move":{"x":-3,"y":-38,"z":4},"block_id":146},{"move":{"x":-3,"y":-38,"z":5},"block_id":146},{"move":{"x":-3,"y":-38,"z":6},"block_id":9},{"move":{"x":-3,"y":-37,"z":0},"block_id":146},{"move":{"x":-3,"y":-37,"z":1},"block_id":70},{"move":{"x":-3,"y":-37,"z":2},"block_id":8},{"move":{"x":-3,"y":-37,"z":3},"block_id":146},{"move":{"x":-3,"y":-37,"z":4},"block_id":146},{"move":{"x":-3,"y":-37,"z":5},"block_id":9},{"move":{"x":-3,"y":-37,"z":6},"block_id":70},{"move":{"x":-3,"y":-36,"z":0},"block_id":70},{"move":{"x":-3,"y":-36,"z":1},"block_id":146},{"move":{"x":-3,"y":-36,"z":2},"block_id":146},{"move":{"x":-3,"y":-36,"z":3},"block_id":9},{"move":{"x":-3,"y":-36,"z":4},"block_id":9},{"move":{"x":-3,"y":-36,"z":5},"block_id":8},{"move":{"x":-3,"y":-36,"z":6},"block_id":9},{"move":{"x":-3,"y":-35,"z":0},"block_id":9},{"move":{"x":-3,"y":-35,"z":1},"block_id":9},{"move":{"x":-3,"y":-35,"z":2},"block_id":9},{"move":{"x":-3,"y":-35,"z":3},"block_id":9},{"move":{"x":-3,"y":-35,"z":4},"block_id":9},{"move":{"x":-3,"y":-35,"z":5},"block_id":8},{"move":{"x":-3,"y":-35,"z":6},"block_id":70},{"move":{"x":-3,"y":-34,"z":0},"block_id":146},{"move":{"x":-3,"y":-34,"z":1},"block_id":146},{"move":{"x":-3,"y":-34,"z":2},"block_id":70},{"move":{"x":-3,"y":-34,"z":3},"block_id":9},{"move":{"x":-3,"y":-34,"z":4},"block_id":8},{"move":{"x":-3,"y":-34,"z":5},"block_id":146},{"move":{"x":-3,"y":-34,"z":6},"block_id":70},{"move":{"x":-3,"y":-33,"z":0},"block_id":8},{"move":{"x":-3,"y":-33,"z":1},"block_id":9},{"move":{"x":-3,"y":-33,"z":2},"block_id":70},{"move":{"x":-3,"y":-33,"z":3},"block_id":146},{"move":{"x":-3,"y":-33,"z":4},"block_id":9},{"move":{"x":-3,"y":-33,"z":5},"block_id":146},{"move":{"x":-3,"y":-33,"z":6},"block_id":9},{"move":{"x":-3,"y":-32,"z":0},"block_id":8},{"move":{"x":-3,"y":-32,"z":1},"block_id":8},{"move":{"x":-3,"y":-32,"z":2},"block_id":146},{"move":{"x":-3,"y":-32,"z":3},"block_id":146},{"move":{"x":-3,"y":-32,"z":4},"block_id":146},{"move":{"x":-3,"y":-32,"z":5},"block_id":8},{"move":{"x":-3,"y":-32,"z":6},"block_id":8},{"move":{"x":-3,"y":-31,"z":0},"block_id":70},{"move":{"x":-3,"y":-31,"z":1},"block_id":70},{"move":{"x":-3,"y":-31,"z":2},"block_id":8},{"move":{"x":-3,"y":-31,"z":3},"block_id":70},{"move":{"x":-3,"y":-31,"z":4},"block_id":70},{"move":{"x":-3,"y":-31,"z":5},"block_id":70},{"move":{"x":-3,"y":-31,"z":6},"block_id":146},{"move":{"x":-3,"y":-30,"z":0},"block_id":9},{"move":{"x":-3,"y":-30,"z":1},"block_id":8},{"move":{"x":-3,"y":-30,"z":2},"block_id":70},{"move":{"x":-3,"y":-30,"z":3},"block_id":146},{"move":{"x":-3,"y":-30,"z":4},"block_id":8},{"move":{"x":-3,"y":-30,"z":5},"block_id":8},{"move":{"x":-3,"y":-30,"z":6},"block_id":9},{"move":{"x":-3,"y":-29,"z":0},"block_id":70},{"move":{"x":-3,"y":-29,"z":1},"block_id":8},{"move":{"x":-3,"y":-29,"z":2},"block_id":8},{"move":{"x":-3,"y":-29,"z":3},"block_id":8},{"move":{"x":-3,"y":-29,"z":4},"block_id":70},{"move":{"x":-3,"y":-29,"z":5},"block_id":9},{"move":{"x":-3,"y":-29,"z":6},"block_id":146},{"move":{"x":-3,"y":-28,"z":0},"block_id":8},{"move":{"x":-3,"y":-28,"z":1},"block_id":70},{"move":{"x":-3,"y":-28,"z":2},"block_id":70},{"move":{"x":-3,"y":-28,"z":3},"block_id":9},{"move":{"x":-3,"y":-28,"z":4},"block_id":9},{"move":{"x":-3,"y":-28,"z":5},"block_id":8},{"move":{"x":-3,"y":-28,"z":6},"block_id":8},{"move":{"x":-3,"y":-27,"z":0},"block_id":70},{"move":{"x":-3,"y":-27,"z":1},"block_id":8},{"move":{"x":-3,"y":-27,"z":2},"block_id":146},{"move":{"x":-3,"y":-27,"z":3},"block_id":9},{"move":{"x":-3,"y":-27,"z":4},"block_id":146},{"move":{"x":-3,"y":-27,"z":5},"block_id":70},{"move":{"x":-3,"y":-27,"z":6},"block_id":9},{"move":{"x":-3,"y":-26,"z":0},"block_id":8},{"move":{"x":-3,"y":-26,"z":1},"block_id":9},{"move":{"x":-3,"y":-26,"z":2},"block_id":70},{"move":{"x":-3,"y":-26,"z":3},"block_id":9},{"move":{"x":-3,"y":-26,"z":4},"block_id":9},{"move":{"x":-3,"y":-26,"z":5},"block_id":8},{"move":{"x":-3,"y":-26,"z":6},"block_id":8},{"move":{"x":-3,"y":-25,"z":0},"block_id":70},{"move":{"x":-3,"y":-25,"z":1},"block_id":9},{"move":{"x":-3,"y":-25,"z":2},"block_id":8},{"move":{"x":-3,"y":-25,"z":3},"block_id":146},{"move":{"x":-3,"y":-25,"z":4},"block_id":9},{"move":{"x":-3,"y":-25,"z":5},"block_id":9},{"move":{"x":-3,"y":-25,"z":6},"block_id":8},{"move":{"x":-3,"y":-24,"z":0},"block_id":9},{"move":{"x":-3,"y":-24,"z":1},"block_id":146},{"move":{"x":-3,"y":-24,"z":2},"block_id":146},{"move":{"x":-3,"y":-24,"z":3},"block_id":9},{"move":{"x":-3,"y":-24,"z":4},"block_id":9},{"move":{"x":-3,"y":-24,"z":5},"block_id":70},{"move":{"x":-3,"y":-24,"z":6},"block_id":146},{"move":{"x":-3,"y":-23,"z":0},"block_id":146},{"move":{"x":-3,"y":-23,"z":1},"block_id":70},{"move":{"x":-3,"y":-23,"z":2},"block_id":9},{"move":{"x":-3,"y":-23,"z":3},"block_id":9},{"move":{"x":-3,"y":-23,"z":4},"block_id":146},{"move":{"x":-3,"y":-23,"z":5},"block_id":146},{"move":{"x":-3,"y":-23,"z":6},"block_id":8},{"move":{"x":-3,"y":-22,"z":0},"block_id":8},{"move":{"x":-3,"y":-22,"z":1},"block_id":70},{"move":{"x":-3,"y":-22,"z":2},"block_id":70},{"move":{"x":-3,"y":-22,"z":3},"block_id":70},{"move":{"x":-3,"y":-22,"z":4},"block_id":8},{"move":{"x":-3,"y":-22,"z":5},"block_id":146},{"move":{"x":-3,"y":-22,"z":6},"block_id":70},{"move":{"x":-3,"y":-21,"z":0},"block_id":70},{"move":{"x":-3,"y":-21,"z":1},"block_id":146},{"move":{"x":-3,"y":-21,"z":2},"block_id":9},{"move":{"x":-3,"y":-21,"z":3},"block_id":8},{"move":{"x":-3,"y":-21,"z":4},"block_id":146},{"move":{"x":-3,"y":-21,"z":5},"block_id":70},{"move":{"x":-3,"y":-21,"z":6},"block_id":146},{"move":{"x":-3,"y":-20,"z":0},"block_id":9},{"move":{"x":-3,"y":-20,"z":1},"block_id":8},{"move":{"x":-3,"y":-20,"z":2},"block_id":146},{"move":{"x":-3,"y":-20,"z":3},"block_id":146},{"move":{"x":-3,"y":-20,"z":4},"block_id":70},{"move":{"x":-3,"y":-20,"z":5},"block_id":9},{"move":{"x":-3,"y":-20,"z":6},"block_id":9},{"move":{"x":-3,"y":-19,"z":0},"block_id":70},{"move":{"x":-3,"y":-19,"z":1},"block_id":8},{"move":{"x":-3,"y":-19,"z":2},"block_id":146},{"move":{"x":-3,"y":-19,"z":3},"block_id":146},{"move":{"x":-3,"y":-19,"z":4},"block_id":8},{"move":{"x":-3,"y":-19,"z":5},"block_id":146},{"move":{"x":-3,"y":-19,"z":6},"block_id":146},{"move":{"x":-3,"y":-18,"z":0},"block_id":9},{"move":{"x":-3,"y":-18,"z":1},"block_id":70},{"move":{"x":-3,"y":-18,"z":2},"block_id":8},{"move":{"x":-3,"y":-18,"z":3},"block_id":70},{"move":{"x":-3,"y":-18,"z":4},"block_id":9},{"move":{"x":-3,"y":-18,"z":5},"block_id":9},{"move":{"x":-3,"y":-18,"z":6},"block_id":8},{"move":{"x":-3,"y":-17,"z":0},"block_id":9},{"move":{"x":-3,"y":-17,"z":1},"block_id":70},{"move":{"x":-3,"y":-17,"z":2},"block_id":146},{"move":{"x":-3,"y":-17,"z":3},"block_id":146},{"move":{"x":-3,"y":-17,"z":4},"block_id":70},{"move":{"x":-3,"y":-17,"z":5},"block_id":146},{"move":{"x":-3,"y":-17,"z":6},"block_id":9},{"move":{"x":-3,"y":-16,"z":0},"block_id":9},{"move":{"x":-3,"y":-16,"z":1},"block_id":146},{"move":{"x":-3,"y":-16,"z":2},"block_id":9},{"move":{"x":-3,"y":-16,"z":3},"block_id":9},{"move":{"x":-3,"y":-16,"z":4},"block_id":146},{"move":{"x":-3,"y":-16,"z":5},"block_id":146},{"move":{"x":-3,"y":-16,"z":6},"block_id":9},{"move":{"x":-3,"y":-15,"z":0},"block_id":70},{"move":{"x":-3,"y":-15,"z":1},"block_id":70},{"move":{"x":-3,"y":-15,"z":2},"block_id":146},{"move":{"x":-3,"y":-15,"z":3},"block_id":8},{"move":{"x":-3,"y":-15,"z":4},"block_id":9},{"move":{"x":-3,"y":-15,"z":5},"block_id":146},{"move":{"x":-3,"y":-15,"z":6},"block_id":70},{"move":{"x":-3,"y":-14,"z":0},"block_id":9},{"move":{"x":-3,"y":-14,"z":1},"block_id":146},{"move":{"x":-3,"y":-14,"z":2},"block_id":9},{"move":{"x":-3,"y":-14,"z":3},"block_id":70},{"move":{"x":-3,"y":-14,"z":4},"block_id":9},{"move":{"x":-3,"y":-14,"z":5},"block_id":8},{"move":{"x":-3,"y":-14,"z":6},"block_id":9},{"move":{"x":-3,"y":-13,"z":0},"block_id":8},{"move":{"x":-3,"y":-13,"z":1},"block_id":70},{"move":{"x":-3,"y":-13,"z":2},"block_id":8},{"move":{"x":-3,"y":-13,"z":3},"block_id":146},{"move":{"x":-3,"y":-13,"z":4},"block_id":8},{"move":{"x":-3,"y":-13,"z":5},"block_id":70},{"move":{"x":-3,"y":-13,"z":6},"block_id":146},{"move":{"x":-3,"y":-12,"z":0},"block_id":70},{"move":{"x":-3,"y":-12,"z":1},"block_id":146},{"move":{"x":-3,"y":-12,"z":2},"block_id":70},{"move":{"x":-3,"y":-12,"z":3},"block_id":146},{"move":{"x":-3,"y":-12,"z":4},"block_id":8},{"move":{"x":-3,"y":-12,"z":5},"block_id":146},{"move":{"x":-3,"y":-12,"z":6},"block_id":70},{"move":{"x":-3,"y":-11,"z":0},"block_id":146},{"move":{"x":-3,"y":-11,"z":1},"block_id":70},{"move":{"x":-3,"y":-11,"z":2},"block_id":9},{"move":{"x":-3,"y":-11,"z":3},"block_id":146},{"move":{"x":-3,"y":-11,"z":4},"block_id":146},{"move":{"x":-3,"y":-11,"z":5},"block_id":8},{"move":{"x":-3,"y":-11,"z":6},"block_id":9},{"move":{"x":-3,"y":-10,"z":0},"block_id":8},{"move":{"x":-3,"y":-10,"z":1},"block_id":9},{"move":{"x":-3,"y":-10,"z":2},"block_id":70},{"move":{"x":-3,"y":-10,"z":3},"block_id":9},{"move":{"x":-3,"y":-10,"z":4},"block_id":146},{"move":{"x":-3,"y":-10,"z":5},"block_id":146},{"move":{"x":-3,"y":-10,"z":6},"block_id":9},{"move":{"x":-3,"y":-9,"z":0},"block_id":70},{"move":{"x":-3,"y":-9,"z":1},"block_id":9},{"move":{"x":-3,"y":-9,"z":2},"block_id":9},{"move":{"x":-3,"y":-9,"z":3},"block_id":9},{"move":{"x":-3,"y":-9,"z":4},"block_id":9},{"move":{"x":-3,"y":-9,"z":5},"block_id":9},{"move":{"x":-3,"y":-9,"z":6},"block_id":146},{"move":{"x":-3,"y":-8,"z":0},"block_id":9},{"move":{"x":-3,"y":-8,"z":1},"block_id":146},{"move":{"x":-3,"y":-8,"z":2},"block_id":146},{"move":{"x":-3,"y":-8,"z":3},"block_id":8},{"move":{"x":-3,"y":-8,"z":4},"block_id":146},{"move":{"x":-3,"y":-8,"z":5},"block_id":9},{"move":{"x":-3,"y":-8,"z":6},"block_id":146},{"move":{"x":-3,"y":-7,"z":0},"block_id":146},{"move":{"x":-3,"y":-7,"z":1},"block_id":146},{"move":{"x":-3,"y":-7,"z":2},"block_id":70},{"move":{"x":-3,"y":-7,"z":3},"block_id":9},{"move":{"x":-3,"y":-7,"z":4},"block_id":8},{"move":{"x":-3,"y":-7,"z":5},"block_id":9},{"move":{"x":-3,"y":-7,"z":6},"block_id":146},{"move":{"x":-3,"y":-6,"z":0},"block_id":8},{"move":{"x":-3,"y":-6,"z":1},"block_id":146},{"move":{"x":-3,"y":-6,"z":2},"block_id":9},{"move":{"x":-3,"y":-6,"z":3},"block_id":9},{"move":{"x":-3,"y":-6,"z":4},"block_id":8},{"move":{"x":-3,"y":-6,"z":5},"block_id":8},{"move":{"x":-3,"y":-6,"z":6},"block_id":8},{"move":{"x":-3,"y":-5,"z":0},"block_id":70},{"move":{"x":-3,"y":-5,"z":1},"block_id":70},{"move":{"x":-3,"y":-5,"z":2},"block_id":70},{"move":{"x":-3,"y":-5,"z":3},"block_id":9},{"move":{"x":-3,"y":-5,"z":4},"block_id":9},{"move":{"x":-3,"y":-5,"z":5},"block_id":9},{"move":{"x":-3,"y":-5,"z":6},"block_id":9},{"move":{"x":-3,"y":-4,"z":0},"block_id":70},{"move":{"x":-3,"y":-4,"z":1},"block_id":9},{"move":{"x":-3,"y":-4,"z":2},"block_id":70},{"move":{"x":-3,"y":-4,"z":3},"block_id":146},{"move":{"x":-3,"y":-4,"z":4},"block_id":146},{"move":{"x":-3,"y":-4,"z":5},"block_id":146},{"move":{"x":-3,"y":-4,"z":6},"block_id":8},{"move":{"x":-3,"y":-3,"z":0},"block_id":70},{"move":{"x":-3,"y":-3,"z":1},"block_id":8},{"move":{"x":-3,"y":-3,"z":2},"block_id":9},{"move":{"x":-3,"y":-3,"z":3},"block_id":146},{"move":{"x":-3,"y":-3,"z":4},"block_id":146},{"move":{"x":-3,"y":-3,"z":5},"block_id":9},{"move":{"x":-3,"y":-3,"z":6},"block_id":70},{"move":{"x":-3,"y":-2,"z":0},"block_id":70},{"move":{"x":-3,"y":-2,"z":1},"block_id":9},{"move":{"x":-3,"y":-2,"z":2},"block_id":9},{"move":{"x":-3,"y":-2,"z":3},"block_id":9},{"move":{"x":-3,"y":-2,"z":4},"block_id":70},{"move":{"x":-3,"y":-2,"z":5},"block_id":146},{"move":{"x":-3,"y":-2,"z":6},"block_id":70},{"move":{"x":-3,"y":-1,"z":0},"block_id":8},{"move":{"x":-3,"y":-1,"z":1},"block_id":9},{"move":{"x":-3,"y":-1,"z":2},"block_id":9},{"move":{"x":-3,"y":-1,"z":3},"block_id":8},{"move":{"x":-3,"y":-1,"z":4},"block_id":9},{"move":{"x":-3,"y":-1,"z":5},"block_id":146},{"move":{"x":-3,"y":-1,"z":6},"block_id":146},{"move":{"x":-3,"y":0,"z":0},"block_id":70},{"move":{"x":-3,"y":0,"z":1},"block_id":146},{"move":{"x":-3,"y":0,"z":2},"block_id":146},{"move":{"x":-3,"y":0,"z":3},"block_id":70},{"move":{"x":-3,"y":0,"z":4},"block_id":146},{"move":{"x":-3,"y":0,"z":5},"block_id":146},{"move":{"x":-3,"y":0,"z":6},"block_id":70},{"move":{"x":-3,"y":1,"z":0},"block_id":146},{"move":{"x":-3,"y":1,"z":1},"block_id":8},{"move":{"x":-3,"y":1,"z":2},"block_id":146},{"move":{"x":-3,"y":1,"z":3},"block_id":146},{"move":{"x":-3,"y":1,"z":4},"block_id":70},{"move":{"x":-3,"y":1,"z":5},"block_id":70},{"move":{"x":-3,"y":1,"z":6},"block_id":8},{"move":{"x":-3,"y":2,"z":0},"block_id":8},{"move":{"x":-3,"y":2,"z":1},"block_id":8},{"move":{"x":-3,"y":2,"z":2},"block_id":9},{"move":{"x":-3,"y":2,"z":3},"block_id":9},{"move":{"x":-3,"y":2,"z":4},"block_id":8},{"move":{"x":-3,"y":2,"z":5},"block_id":70},{"move":{"x":-3,"y":2,"z":6},"block_id":8},{"move":{"x":-3,"y":3,"z":0},"block_id":8},{"move":{"x":-3,"y":3,"z":1},"block_id":9},{"move":{"x":-3,"y":3,"z":2},"block_id":70},{"move":{"x":-3,"y":3,"z":3},"block_id":8},{"move":{"x":-3,"y":3,"z":4},"block_id":146},{"move":{"x":-3,"y":3,"z":5},"block_id":146},{"move":{"x":-3,"y":3,"z":6},"block_id":146},{"move":{"x":-3,"y":4,"z":0},"block_id":146},{"move":{"x":-3,"y":4,"z":1},"block_id":9},{"move":{"x":-3,"y":4,"z":2},"block_id":8},{"move":{"x":-3,"y":4,"z":3},"block_id":8},{"move":{"x":-3,"y":4,"z":4},"block_id":8},{"move":{"x":-3,"y":4,"z":5},"block_id":146},{"move":{"x":-3,"y":4,"z":6},"block_id":8},{"move":{"x":-2,"y":-81,"z":0},"block_id":146},{"move":{"x":-2,"y":-81,"z":1},"block_id":9},{"move":{"x":-2,"y":-81,"z":2},"block_id":146},{"move":{"x":-2,"y":-81,"z":3},"block_id":8},{"move":{"x":-2,"y":-81,"z":4},"block_id":70},{"move":{"x":-2,"y":-81,"z":5},"block_id":8},{"move":{"x":-2,"y":-81,"z":6},"block_id":146},{"move":{"x":-2,"y":-80,"z":0},"block_id":70},{"move":{"x":-2,"y":-80,"z":6},"block_id":8},{"move":{"x":-2,"y":-79,"z":0},"block_id":9},{"move":{"x":-2,"y":-79,"z":6},"block_id":146},{"move":{"x":-2,"y":-78,"z":0},"block_id":70},{"move":{"x":-2,"y":-78,"z":6},"block_id":70},{"move":{"x":-2,"y":-77,"z":0},"block_id":70},{"move":{"x":-2,"y":-77,"z":6},"block_id":8},{"move":{"x":-2,"y":-76,"z":0},"block_id":9},{"move":{"x":-2,"y":-76,"z":6},"block_id":8},{"move":{"x":-2,"y":-75,"z":0},"block_id":146},{"move":{"x":-2,"y":-75,"z":6},"block_id":70},{"move":{"x":-2,"y":-74,"z":0},"block_id":9},{"move":{"x":-2,"y":-74,"z":6},"block_id":8},{"move":{"x":-2,"y":-73,"z":0},"block_id":146},{"move":{"x":-2,"y":-73,"z":6},"block_id":8},{"move":{"x":-2,"y":-72,"z":0},"block_id":70},{"move":{"x":-2,"y":-72,"z":6},"block_id":9},{"move":{"x":-2,"y":-71,"z":0},"block_id":146},{"move":{"x":-2,"y":-71,"z":6},"block_id":70},{"move":{"x":-2,"y":-70,"z":0},"block_id":9},{"move":{"x":-2,"y":-70,"z":6},"block_id":70},{"move":{"x":-2,"y":-69,"z":0},"block_id":8},{"move":{"x":-2,"y":-69,"z":6},"block_id":70},{"move":{"x":-2,"y":-68,"z":0},"block_id":146},{"move":{"x":-2,"y":-68,"z":6},"block_id":70},{"move":{"x":-2,"y":-67,"z":0},"block_id":9},{"move":{"x":-2,"y":-67,"z":6},"block_id":8},{"move":{"x":-2,"y":-66,"z":0},"block_id":146},{"move":{"x":-2,"y":-66,"z":6},"block_id":146},{"move":{"x":-2,"y":-65,"z":0},"block_id":9},{"move":{"x":-2,"y":-65,"z":6},"block_id":8},{"move":{"x":-2,"y":-64,"z":0},"block_id":70},{"move":{"x":-2,"y":-64,"z":6},"block_id":9},{"move":{"x":-2,"y":-63,"z":0},"block_id":8},{"move":{"x":-2,"y":-63,"z":6},"block_id":70},{"move":{"x":-2,"y":-62,"z":0},"block_id":8},{"move":{"x":-2,"y":-62,"z":6},"block_id":70},{"move":{"x":-2,"y":-61,"z":0},"block_id":146},{"move":{"x":-2,"y":-61,"z":6},"block_id":70},{"move":{"x":-2,"y":-60,"z":0},"block_id":8},{"move":{"x":-2,"y":-60,"z":6},"block_id":70},{"move":{"x":-2,"y":-59,"z":0},"block_id":8},{"move":{"x":-2,"y":-59,"z":6},"block_id":8},{"move":{"x":-2,"y":-58,"z":0},"block_id":8},{"move":{"x":-2,"y":-58,"z":6},"block_id":9},{"move":{"x":-2,"y":-57,"z":0},"block_id":9},{"move":{"x":-2,"y":-57,"z":6},"block_id":9},{"move":{"x":-2,"y":-56,"z":0},"block_id":70},{"move":{"x":-2,"y":-56,"z":6},"block_id":70},{"move":{"x":-2,"y":-55,"z":0},"block_id":146},{"move":{"x":-2,"y":-55,"z":6},"block_id":9},{"move":{"x":-2,"y":-54,"z":0},"block_id":70},{"move":{"x":-2,"y":-54,"z":6},"block_id":146},{"move":{"x":-2,"y":-53,"z":0},"block_id":70},{"move":{"x":-2,"y":-53,"z":6},"block_id":70},{"move":{"x":-2,"y":-52,"z":0},"block_id":8},{"move":{"x":-2,"y":-52,"z":6},"block_id":146},{"move":{"x":-2,"y":-51,"z":0},"block_id":70},{"move":{"x":-2,"y":-51,"z":6},"block_id":9},{"move":{"x":-2,"y":-50,"z":0},"block_id":8},{"move":{"x":-2,"y":-50,"z":6},"block_id":9},{"move":{"x":-2,"y":-49,"z":0},"block_id":70},{"move":{"x":-2,"y":-49,"z":6},"block_id":70},{"move":{"x":-2,"y":-48,"z":0},"block_id":146},{"move":{"x":-2,"y":-48,"z":6},"block_id":146},{"move":{"x":-2,"y":-47,"z":0},"block_id":9},{"move":{"x":-2,"y":-47,"z":6},"block_id":146},{"move":{"x":-2,"y":-46,"z":0},"block_id":8},{"move":{"x":-2,"y":-46,"z":6},"block_id":8},{"move":{"x":-2,"y":-45,"z":0},"block_id":146},{"move":{"x":-2,"y":-45,"z":6},"block_id":8},{"move":{"x":-2,"y":-44,"z":0},"block_id":8},{"move":{"x":-2,"y":-44,"z":6},"block_id":8},{"move":{"x":-2,"y":-43,"z":0},"block_id":8},{"move":{"x":-2,"y":-43,"z":6},"block_id":8},{"move":{"x":-2,"y":-42,"z":0},"block_id":146},{"move":{"x":-2,"y":-42,"z":6},"block_id":9},{"move":{"x":-2,"y":-41,"z":0},"block_id":70},{"move":{"x":-2,"y":-41,"z":6},"block_id":146},{"move":{"x":-2,"y":-40,"z":0},"block_id":146},{"move":{"x":-2,"y":-40,"z":6},"block_id":9},{"move":{"x":-2,"y":-39,"z":0},"block_id":8},{"move":{"x":-2,"y":-39,"z":6},"block_id":9},{"move":{"x":-2,"y":-38,"z":0},"block_id":70},{"move":{"x":-2,"y":-38,"z":6},"block_id":146},{"move":{"x":-2,"y":-37,"z":0},"block_id":70},{"move":{"x":-2,"y":-37,"z":6},"block_id":8},{"move":{"x":-2,"y":-36,"z":0},"block_id":146},{"move":{"x":-2,"y":-36,"z":6},"block_id":70},{"move":{"x":-2,"y":-35,"z":0},"block_id":146},{"move":{"x":-2,"y":-35,"z":6},"block_id":146},{"move":{"x":-2,"y":-34,"z":0},"block_id":146},{"move":{"x":-2,"y":-34,"z":6},"block_id":146},{"move":{"x":-2,"y":-33,"z":0},"block_id":9},{"move":{"x":-2,"y":-33,"z":6},"block_id":70},{"move":{"x":-2,"y":-32,"z":0},"block_id":8},{"move":{"x":-2,"y":-32,"z":6},"block_id":70},{"move":{"x":-2,"y":-31,"z":0},"block_id":9},{"move":{"x":-2,"y":-31,"z":6},"block_id":70},{"move":{"x":-2,"y":-30,"z":0},"block_id":9},{"move":{"x":-2,"y":-30,"z":6},"block_id":70},{"move":{"x":-2,"y":-29,"z":0},"block_id":8},{"move":{"x":-2,"y":-29,"z":6},"block_id":146},{"move":{"x":-2,"y":-28,"z":0},"block_id":70},{"move":{"x":-2,"y":-28,"z":6},"block_id":70},{"move":{"x":-2,"y":-27,"z":0},"block_id":9},{"move":{"x":-2,"y":-27,"z":6},"block_id":146},{"move":{"x":-2,"y":-26,"z":0},"block_id":146},{"move":{"x":-2,"y":-26,"z":6},"block_id":9},{"move":{"x":-2,"y":-25,"z":0},"block_id":8},{"move":{"x":-2,"y":-25,"z":6},"block_id":9},{"move":{"x":-2,"y":-24,"z":0},"block_id":9},{"move":{"x":-2,"y":-24,"z":6},"block_id":9},{"move":{"x":-2,"y":-23,"z":0},"block_id":146},{"move":{"x":-2,"y":-23,"z":6},"block_id":8},{"move":{"x":-2,"y":-22,"z":0},"block_id":70},{"move":{"x":-2,"y":-22,"z":6},"block_id":70},{"move":{"x":-2,"y":-21,"z":0},"block_id":70},{"move":{"x":-2,"y":-21,"z":6},"block_id":9},{"move":{"x":-2,"y":-20,"z":0},"block_id":8},{"move":{"x":-2,"y":-20,"z":6},"block_id":70},{"move":{"x":-2,"y":-19,"z":0},"block_id":9},{"move":{"x":-2,"y":-19,"z":6},"block_id":8},{"move":{"x":-2,"y":-18,"z":0},"block_id":146},{"move":{"x":-2,"y":-18,"z":6},"block_id":70},{"move":{"x":-2,"y":-17,"z":0},"block_id":146},{"move":{"x":-2,"y":-17,"z":6},"block_id":146},{"move":{"x":-2,"y":-16,"z":0},"block_id":70},{"move":{"x":-2,"y":-16,"z":6},"block_id":70},{"move":{"x":-2,"y":-15,"z":0},"block_id":146},{"move":{"x":-2,"y":-15,"z":6},"block_id":146},{"move":{"x":-2,"y":-14,"z":0},"block_id":8},{"move":{"x":-2,"y":-14,"z":6},"block_id":70},{"move":{"x":-2,"y":-13,"z":0},"block_id":9},{"move":{"x":-2,"y":-13,"z":6},"block_id":70},{"move":{"x":-2,"y":-12,"z":0},"block_id":146},{"move":{"x":-2,"y":-12,"z":6},"block_id":8},{"move":{"x":-2,"y":-11,"z":0},"block_id":8},{"move":{"x":-2,"y":-11,"z":6},"block_id":8},{"move":{"x":-2,"y":-10,"z":0},"block_id":8},{"move":{"x":-2,"y":-10,"z":6},"block_id":8},{"move":{"x":-2,"y":-9,"z":0},"block_id":146},{"move":{"x":-2,"y":-9,"z":6},"block_id":8},{"move":{"x":-2,"y":-8,"z":0},"block_id":70},{"move":{"x":-2,"y":-8,"z":6},"block_id":8},{"move":{"x":-2,"y":-7,"z":0},"block_id":146},{"move":{"x":-2,"y":-7,"z":6},"block_id":9},{"move":{"x":-2,"y":-6,"z":0},"block_id":70},{"move":{"x":-2,"y":-6,"z":6},"block_id":8},{"move":{"x":-2,"y":-5,"z":0},"block_id":8},{"move":{"x":-2,"y":-5,"z":6},"block_id":8},{"move":{"x":-2,"y":-4,"z":0},"block_id":9},{"move":{"x":-2,"y":-4,"z":6},"block_id":9},{"move":{"x":-2,"y":-3,"z":0},"block_id":146},{"move":{"x":-2,"y":-3,"z":6},"block_id":9},{"move":{"x":-2,"y":-2,"z":0},"block_id":70},{"move":{"x":-2,"y":-2,"z":6},"block_id":70},{"move":{"x":-2,"y":-1,"z":0},"block_id":8},{"move":{"x":-2,"y":-1,"z":1},"block_id":70},{"move":{"x":-2,"y":-1,"z":2},"block_id":70},{"move":{"x":-2,"y":-1,"z":3},"block_id":70},{"move":{"x":-2,"y":-1,"z":4},"block_id":70},{"move":{"x":-2,"y":-1,"z":5},"block_id":70},{"move":{"x":-2,"y":-1,"z":6},"block_id":8},{"move":{"x":-2,"y":0,"z":0},"block_id":8},{"move":{"x":-2,"y":0,"z":6},"block_id":146},{"move":{"x":-2,"y":1,"z":0},"block_id":70},{"move":{"x":-2,"y":1,"z":6},"block_id":70},{"move":{"x":-2,"y":2,"z":0},"block_id":9},{"move":{"x":-2,"y":2,"z":6},"block_id":146},{"move":{"x":-2,"y":3,"z":0},"block_id":70},{"move":{"x":-2,"y":3,"z":6},"block_id":9},{"move":{"x":-2,"y":4,"z":0},"block_id":9},{"move":{"x":-2,"y":4,"z":1},"block_id":9},{"move":{"x":-2,"y":4,"z":2},"block_id":9},{"move":{"x":-2,"y":4,"z":3},"block_id":8},{"move":{"x":-2,"y":4,"z":4},"block_id":146},{"move":{"x":-2,"y":4,"z":5},"block_id":9},{"move":{"x":-2,"y":4,"z":6},"block_id":146},{"move":{"x":-1,"y":-81,"z":0},"block_id":8},{"move":{"x":-1,"y":-81,"z":1},"block_id":70},{"move":{"x":-1,"y":-81,"z":2},"block_id":70},{"move":{"x":-1,"y":-81,"z":3},"block_id":70},{"move":{"x":-1,"y":-81,"z":4},"block_id":8},{"move":{"x":-1,"y":-81,"z":5},"block_id":8},{"move":{"x":-1,"y":-81,"z":6},"block_id":9},{"move":{"x":-1,"y":-80,"z":0},"block_id":146},{"move":{"x":-1,"y":-80,"z":6},"block_id":146},{"move":{"x":-1,"y":-79,"z":0},"block_id":70},{"move":{"x":-1,"y":-79,"z":6},"block_id":70},{"move":{"x":-1,"y":-78,"z":0},"block_id":9},{"move":{"x":-1,"y":-78,"z":6},"block_id":146},{"move":{"x":-1,"y":-77,"z":0},"block_id":70},{"move":{"x":-1,"y":-77,"z":6},"block_id":146},{"move":{"x":-1,"y":-76,"z":0},"block_id":70},{"move":{"x":-1,"y":-76,"z":6},"block_id":9},{"move":{"x":-1,"y":-75,"z":0},"block_id":146},{"move":{"x":-1,"y":-75,"z":6},"block_id":8},{"move":{"x":-1,"y":-74,"z":0},"block_id":146},{"move":{"x":-1,"y":-74,"z":6},"block_id":9},{"move":{"x":-1,"y":-73,"z":0},"block_id":146},{"move":{"x":-1,"y":-73,"z":6},"block_id":9},{"move":{"x":-1,"y":-72,"z":0},"block_id":8},{"move":{"x":-1,"y":-72,"z":6},"block_id":70},{"move":{"x":-1,"y":-71,"z":0},"block_id":146},{"move":{"x":-1,"y":-71,"z":6},"block_id":9},{"move":{"x":-1,"y":-70,"z":0},"block_id":146},{"move":{"x":-1,"y":-70,"z":6},"block_id":9},{"move":{"x":-1,"y":-69,"z":0},"block_id":9},{"move":{"x":-1,"y":-69,"z":6},"block_id":70},{"move":{"x":-1,"y":-68,"z":0},"block_id":146},{"move":{"x":-1,"y":-68,"z":6},"block_id":9},{"move":{"x":-1,"y":-67,"z":0},"block_id":8},{"move":{"x":-1,"y":-67,"z":6},"block_id":146},{"move":{"x":-1,"y":-66,"z":0},"block_id":146},{"move":{"x":-1,"y":-66,"z":6},"block_id":146},{"move":{"x":-1,"y":-65,"z":0},"block_id":8},{"move":{"x":-1,"y":-65,"z":6},"block_id":146},{"move":{"x":-1,"y":-64,"z":0},"block_id":9},{"move":{"x":-1,"y":-64,"z":6},"block_id":8},{"move":{"x":-1,"y":-63,"z":0},"block_id":70},{"move":{"x":-1,"y":-63,"z":6},"block_id":146},{"move":{"x":-1,"y":-62,"z":0},"block_id":146},{"move":{"x":-1,"y":-62,"z":6},"block_id":8},{"move":{"x":-1,"y":-61,"z":0},"block_id":8},{"move":{"x":-1,"y":-61,"z":6},"block_id":9},{"move":{"x":-1,"y":-60,"z":0},"block_id":9},{"move":{"x":-1,"y":-60,"z":6},"block_id":8},{"move":{"x":-1,"y":-59,"z":0},"block_id":146},{"move":{"x":-1,"y":-59,"z":6},"block_id":9},{"move":{"x":-1,"y":-58,"z":0},"block_id":8},{"move":{"x":-1,"y":-58,"z":6},"block_id":146},{"move":{"x":-1,"y":-57,"z":0},"block_id":146},{"move":{"x":-1,"y":-57,"z":6},"block_id":8},{"move":{"x":-1,"y":-56,"z":0},"block_id":70},{"move":{"x":-1,"y":-56,"z":6},"block_id":146},{"move":{"x":-1,"y":-55,"z":0},"block_id":8},{"move":{"x":-1,"y":-55,"z":6},"block_id":70},{"move":{"x":-1,"y":-54,"z":0},"block_id":8},{"move":{"x":-1,"y":-54,"z":6},"block_id":8},{"move":{"x":-1,"y":-53,"z":0},"block_id":9},{"move":{"x":-1,"y":-53,"z":6},"block_id":9},{"move":{"x":-1,"y":-52,"z":0},"block_id":9},{"move":{"x":-1,"y":-52,"z":6},"block_id":9},{"move":{"x":-1,"y":-51,"z":0},"block_id":70},{"move":{"x":-1,"y":-51,"z":6},"block_id":70},{"move":{"x":-1,"y":-50,"z":0},"block_id":9},{"move":{"x":-1,"y":-50,"z":6},"block_id":9},{"move":{"x":-1,"y":-49,"z":0},"block_id":9},{"move":{"x":-1,"y":-49,"z":6},"block_id":9},{"move":{"x":-1,"y":-48,"z":0},"block_id":70},{"move":{"x":-1,"y":-48,"z":6},"block_id":70},{"move":{"x":-1,"y":-47,"z":0},"block_id":9},{"move":{"x":-1,"y":-47,"z":6},"block_id":146},{"move":{"x":-1,"y":-46,"z":0},"block_id":9},{"move":{"x":-1,"y":-46,"z":6},"block_id":146},{"move":{"x":-1,"y":-45,"z":0},"block_id":70},{"move":{"x":-1,"y":-45,"z":6},"block_id":9},{"move":{"x":-1,"y":-44,"z":0},"block_id":9},{"move":{"x":-1,"y":-44,"z":6},"block_id":9},{"move":{"x":-1,"y":-43,"z":0},"block_id":9},{"move":{"x":-1,"y":-43,"z":6},"block_id":146},{"move":{"x":-1,"y":-42,"z":0},"block_id":8},{"move":{"x":-1,"y":-42,"z":6},"block_id":70},{"move":{"x":-1,"y":-41,"z":0},"block_id":8},{"move":{"x":-1,"y":-41,"z":6},"block_id":8},{"move":{"x":-1,"y":-40,"z":0},"block_id":8},{"move":{"x":-1,"y":-40,"z":6},"block_id":9},{"move":{"x":-1,"y":-39,"z":0},"block_id":8},{"move":{"x":-1,"y":-39,"z":6},"block_id":9},{"move":{"x":-1,"y":-38,"z":0},"block_id":8},{"move":{"x":-1,"y":-38,"z":6},"block_id":9},{"move":{"x":-1,"y":-37,"z":0},"block_id":9},{"move":{"x":-1,"y":-37,"z":6},"block_id":146},{"move":{"x":-1,"y":-36,"z":0},"block_id":8},{"move":{"x":-1,"y":-36,"z":6},"block_id":146},{"move":{"x":-1,"y":-35,"z":0},"block_id":9},{"move":{"x":-1,"y":-35,"z":6},"block_id":8},{"move":{"x":-1,"y":-34,"z":0},"block_id":8},{"move":{"x":-1,"y":-34,"z":6},"block_id":146},{"move":{"x":-1,"y":-33,"z":0},"block_id":8},{"move":{"x":-1,"y":-33,"z":6},"block_id":70},{"move":{"x":-1,"y":-32,"z":0},"block_id":70},{"move":{"x":-1,"y":-32,"z":6},"block_id":70},{"move":{"x":-1,"y":-31,"z":0},"block_id":146},{"move":{"x":-1,"y":-31,"z":6},"block_id":9},{"move":{"x":-1,"y":-30,"z":0},"block_id":146},{"move":{"x":-1,"y":-30,"z":6},"block_id":8},{"move":{"x":-1,"y":-29,"z":0},"block_id":146},{"move":{"x":-1,"y":-29,"z":6},"block_id":8},{"move":{"x":-1,"y":-28,"z":0},"block_id":146},{"move":{"x":-1,"y":-28,"z":6},"block_id":8},{"move":{"x":-1,"y":-27,"z":0},"block_id":146},{"move":{"x":-1,"y":-27,"z":6},"block_id":8},{"move":{"x":-1,"y":-26,"z":0},"block_id":9},{"move":{"x":-1,"y":-26,"z":6},"block_id":8},{"move":{"x":-1,"y":-25,"z":0},"block_id":146},{"move":{"x":-1,"y":-25,"z":6},"block_id":9},{"move":{"x":-1,"y":-24,"z":0},"block_id":9},{"move":{"x":-1,"y":-24,"z":6},"block_id":70},{"move":{"x":-1,"y":-23,"z":0},"block_id":8},{"move":{"x":-1,"y":-23,"z":6},"block_id":70},{"move":{"x":-1,"y":-22,"z":0},"block_id":8},{"move":{"x":-1,"y":-22,"z":6},"block_id":146},{"move":{"x":-1,"y":-21,"z":0},"block_id":8},{"move":{"x":-1,"y":-21,"z":6},"block_id":70},{"move":{"x":-1,"y":-20,"z":0},"block_id":70},{"move":{"x":-1,"y":-20,"z":6},"block_id":70},{"move":{"x":-1,"y":-19,"z":0},"block_id":146},{"move":{"x":-1,"y":-19,"z":6},"block_id":146},{"move":{"x":-1,"y":-18,"z":0},"block_id":70},{"move":{"x":-1,"y":-18,"z":6},"block_id":70},{"move":{"x":-1,"y":-17,"z":0},"block_id":8},{"move":{"x":-1,"y":-17,"z":6},"block_id":146},{"move":{"x":-1,"y":-16,"z":0},"block_id":146},{"move":{"x":-1,"y":-16,"z":6},"block_id":9},{"move":{"x":-1,"y":-15,"z":0},"block_id":146},{"move":{"x":-1,"y":-15,"z":6},"block_id":70},{"move":{"x":-1,"y":-14,"z":0},"block_id":8},{"move":{"x":-1,"y":-14,"z":6},"block_id":8},{"move":{"x":-1,"y":-13,"z":0},"block_id":8},{"move":{"x":-1,"y":-13,"z":6},"block_id":9},{"move":{"x":-1,"y":-12,"z":0},"block_id":70},{"move":{"x":-1,"y":-12,"z":6},"block_id":9},{"move":{"x":-1,"y":-11,"z":0},"block_id":70},{"move":{"x":-1,"y":-11,"z":6},"block_id":9},{"move":{"x":-1,"y":-10,"z":0},"block_id":8},{"move":{"x":-1,"y":-10,"z":6},"block_id":70},{"move":{"x":-1,"y":-9,"z":0},"block_id":70},{"move":{"x":-1,"y":-9,"z":6},"block_id":9},{"move":{"x":-1,"y":-8,"z":0},"block_id":146},{"move":{"x":-1,"y":-8,"z":6},"block_id":146},{"move":{"x":-1,"y":-7,"z":0},"block_id":9},{"move":{"x":-1,"y":-7,"z":6},"block_id":146},{"move":{"x":-1,"y":-6,"z":0},"block_id":146},{"move":{"x":-1,"y":-6,"z":6},"block_id":8},{"move":{"x":-1,"y":-5,"z":0},"block_id":70},{"move":{"x":-1,"y":-5,"z":6},"block_id":8},{"move":{"x":-1,"y":-4,"z":0},"block_id":9},{"move":{"x":-1,"y":-4,"z":6},"block_id":8},{"move":{"x":-1,"y":-3,"z":0},"block_id":9},{"move":{"x":-1,"y":-3,"z":6},"block_id":70},{"move":{"x":-1,"y":-2,"z":0},"block_id":9},{"move":{"x":-1,"y":-2,"z":6},"block_id":8},{"move":{"x":-1,"y":-1,"z":0},"block_id":146},{"move":{"x":-1,"y":-1,"z":1},"block_id":70},{"move":{"x":-1,"y":-1,"z":2},"block_id":70},{"move":{"x":-1,"y":-1,"z":3},"block_id":70},{"move":{"x":-1,"y":-1,"z":4},"block_id":70},{"move":{"x":-1,"y":-1,"z":5},"block_id":70},{"move":{"x":-1,"y":-1,"z":6},"block_id":146},{"move":{"x":-1,"y":0,"z":0},"block_id":8},{"move":{"x":-1,"y":0,"z":6},"block_id":8},{"move":{"x":-1,"y":1,"z":0},"block_id":146},{"move":{"x":-1,"y":1,"z":6},"block_id":70},{"move":{"x":-1,"y":2,"z":0},"block_id":8},{"move":{"x":-1,"y":2,"z":6},"block_id":8},{"move":{"x":-1,"y":3,"z":0},"block_id":8},{"move":{"x":-1,"y":3,"z":6},"block_id":70},{"move":{"x":-1,"y":4,"z":0},"block_id":146},{"move":{"x":-1,"y":4,"z":1},"block_id":70},{"move":{"x":-1,"y":4,"z":2},"block_id":146},{"move":{"x":-1,"y":4,"z":3},"block_id":146},{"move":{"x":-1,"y":4,"z":4},"block_id":9},{"move":{"x":-1,"y":4,"z":5},"block_id":8},{"move":{"x":-1,"y":4,"z":6},"block_id":146},{"move":{"x":0,"y":-81,"z":0},"block_id":70},{"move":{"x":0,"y":-81,"z":1},"block_id":146},{"move":{"x":0,"y":-81,"z":2},"block_id":70},{"move":{"x":0,"y":-81,"z":3},"block_id":8},{"move":{"x":0,"y":-81,"z":4},"block_id":146},{"move":{"x":0,"y":-81,"z":5},"block_id":70},{"move":{"x":0,"y":-81,"z":6},"block_id":146},{"move":{"x":0,"y":-80,"z":0},"block_id":8},{"move":{"x":0,"y":-80,"z":6},"block_id":9},{"move":{"x":0,"y":-79,"z":0},"block_id":70},{"move":{"x":0,"y":-79,"z":6},"block_id":70},{"move":{"x":0,"y":-78,"z":0},"block_id":146},{"move":{"x":0,"y":-78,"z":6},"block_id":8},{"move":{"x":0,"y":-77,"z":0},"block_id":146},{"move":{"x":0,"y":-77,"z":6},"block_id":9},{"move":{"x":0,"y":-76,"z":0},"block_id":9},{"move":{"x":0,"y":-76,"z":6},"block_id":70},{"move":{"x":0,"y":-75,"z":0},"block_id":146},{"move":{"x":0,"y":-75,"z":6},"block_id":146},{"move":{"x":0,"y":-74,"z":0},"block_id":9},{"move":{"x":0,"y":-74,"z":6},"block_id":8},{"move":{"x":0,"y":-73,"z":0},"block_id":8},{"move":{"x":0,"y":-73,"z":6},"block_id":8},{"move":{"x":0,"y":-72,"z":0},"block_id":8},{"move":{"x":0,"y":-72,"z":6},"block_id":146},{"move":{"x":0,"y":-71,"z":0},"block_id":70},{"move":{"x":0,"y":-71,"z":6},"block_id":8},{"move":{"x":0,"y":-70,"z":0},"block_id":146},{"move":{"x":0,"y":-70,"z":6},"block_id":146},{"move":{"x":0,"y":-69,"z":0},"block_id":9},{"move":{"x":0,"y":-69,"z":6},"block_id":9},{"move":{"x":0,"y":-68,"z":0},"block_id":9},{"move":{"x":0,"y":-68,"z":6},"block_id":70},{"move":{"x":0,"y":-67,"z":0},"block_id":9},{"move":{"x":0,"y":-67,"z":6},"block_id":8},{"move":{"x":0,"y":-66,"z":0},"block_id":9},{"move":{"x":0,"y":-66,"z":6},"block_id":70},{"move":{"x":0,"y":-65,"z":0},"block_id":146},{"move":{"x":0,"y":-65,"z":6},"block_id":146},{"move":{"x":0,"y":-64,"z":0},"block_id":9},{"move":{"x":0,"y":-64,"z":6},"block_id":70},{"move":{"x":0,"y":-63,"z":0},"block_id":70},{"move":{"x":0,"y":-63,"z":6},"block_id":9},{"move":{"x":0,"y":-62,"z":0},"block_id":146},{"move":{"x":0,"y":-62,"z":6},"block_id":9},{"move":{"x":0,"y":-61,"z":0},"block_id":9},{"move":{"x":0,"y":-61,"z":6},"block_id":8},{"move":{"x":0,"y":-60,"z":0},"block_id":70},{"move":{"x":0,"y":-60,"z":6},"block_id":8},{"move":{"x":0,"y":-59,"z":0},"block_id":8},{"move":{"x":0,"y":-59,"z":6},"block_id":9},{"move":{"x":0,"y":-58,"z":0},"block_id":9},{"move":{"x":0,"y":-58,"z":6},"block_id":146},{"move":{"x":0,"y":-57,"z":0},"block_id":146},{"move":{"x":0,"y":-57,"z":6},"block_id":146},{"move":{"x":0,"y":-56,"z":0},"block_id":70},{"move":{"x":0,"y":-56,"z":6},"block_id":146},{"move":{"x":0,"y":-55,"z":0},"block_id":9},{"move":{"x":0,"y":-55,"z":6},"block_id":146},{"move":{"x":0,"y":-54,"z":0},"block_id":146},{"move":{"x":0,"y":-54,"z":6},"block_id":70},{"move":{"x":0,"y":-53,"z":0},"block_id":8},{"move":{"x":0,"y":-53,"z":6},"block_id":9},{"move":{"x":0,"y":-52,"z":0},"block_id":70},{"move":{"x":0,"y":-52,"z":6},"block_id":146},{"move":{"x":0,"y":-51,"z":0},"block_id":70},{"move":{"x":0,"y":-51,"z":6},"block_id":8},{"move":{"x":0,"y":-50,"z":0},"block_id":9},{"move":{"x":0,"y":-50,"z":6},"block_id":70},{"move":{"x":0,"y":-49,"z":0},"block_id":146},{"move":{"x":0,"y":-49,"z":6},"block_id":70},{"move":{"x":0,"y":-48,"z":0},"block_id":8},{"move":{"x":0,"y":-48,"z":6},"block_id":146},{"move":{"x":0,"y":-47,"z":0},"block_id":8},{"move":{"x":0,"y":-47,"z":6},"block_id":70},{"move":{"x":0,"y":-46,"z":0},"block_id":8},{"move":{"x":0,"y":-46,"z":6},"block_id":8},{"move":{"x":0,"y":-45,"z":0},"block_id":8},{"move":{"x":0,"y":-45,"z":6},"block_id":9},{"move":{"x":0,"y":-44,"z":0},"block_id":8},{"move":{"x":0,"y":-44,"z":6},"block_id":8},{"move":{"x":0,"y":-43,"z":0},"block_id":8},{"move":{"x":0,"y":-43,"z":6},"block_id":146},{"move":{"x":0,"y":-42,"z":0},"block_id":70},{"move":{"x":0,"y":-42,"z":6},"block_id":70},{"move":{"x":0,"y":-41,"z":0},"block_id":9},{"move":{"x":0,"y":-41,"z":6},"block_id":70},{"move":{"x":0,"y":-40,"z":0},"block_id":70},{"move":{"x":0,"y":-40,"z":6},"block_id":146},{"move":{"x":0,"y":-39,"z":0},"block_id":70},{"move":{"x":0,"y":-39,"z":6},"block_id":9},{"move":{"x":0,"y":-38,"z":0},"block_id":9},{"move":{"x":0,"y":-38,"z":6},"block_id":70},{"move":{"x":0,"y":-37,"z":0},"block_id":146},{"move":{"x":0,"y":-37,"z":6},"block_id":9},{"move":{"x":0,"y":-36,"z":0},"block_id":9},{"move":{"x":0,"y":-36,"z":6},"block_id":9},{"move":{"x":0,"y":-35,"z":0},"block_id":70},{"move":{"x":0,"y":-35,"z":6},"block_id":8},{"move":{"x":0,"y":-34,"z":0},"block_id":70},{"move":{"x":0,"y":-34,"z":6},"block_id":8},{"move":{"x":0,"y":-33,"z":0},"block_id":8},{"move":{"x":0,"y":-33,"z":6},"block_id":8},{"move":{"x":0,"y":-32,"z":0},"block_id":8},{"move":{"x":0,"y":-32,"z":6},"block_id":146},{"move":{"x":0,"y":-31,"z":0},"block_id":8},{"move":{"x":0,"y":-31,"z":6},"block_id":70},{"move":{"x":0,"y":-30,"z":0},"block_id":70},{"move":{"x":0,"y":-30,"z":6},"block_id":70},{"move":{"x":0,"y":-29,"z":0},"block_id":70},{"move":{"x":0,"y":-29,"z":6},"block_id":9},{"move":{"x":0,"y":-28,"z":0},"block_id":8},{"move":{"x":0,"y":-28,"z":6},"block_id":70},{"move":{"x":0,"y":-27,"z":0},"block_id":9},{"move":{"x":0,"y":-27,"z":6},"block_id":70},{"move":{"x":0,"y":-26,"z":0},"block_id":9},{"move":{"x":0,"y":-26,"z":6},"block_id":8},{"move":{"x":0,"y":-25,"z":0},"block_id":8},{"move":{"x":0,"y":-25,"z":6},"block_id":9},{"move":{"x":0,"y":-24,"z":0},"block_id":9},{"move":{"x":0,"y":-24,"z":6},"block_id":9},{"move":{"x":0,"y":-23,"z":0},"block_id":8},{"move":{"x":0,"y":-23,"z":6},"block_id":8},{"move":{"x":0,"y":-22,"z":0},"block_id":70},{"move":{"x":0,"y":-22,"z":6},"block_id":8},{"move":{"x":0,"y":-21,"z":0},"block_id":8},{"move":{"x":0,"y":-21,"z":6},"block_id":9},{"move":{"x":0,"y":-20,"z":0},"block_id":8},{"move":{"x":0,"y":-20,"z":6},"block_id":8},{"move":{"x":0,"y":-19,"z":0},"block_id":8},{"move":{"x":0,"y":-19,"z":6},"block_id":8},{"move":{"x":0,"y":-18,"z":0},"block_id":9},{"move":{"x":0,"y":-18,"z":6},"block_id":9},{"move":{"x":0,"y":-17,"z":0},"block_id":9},{"move":{"x":0,"y":-17,"z":6},"block_id":9},{"move":{"x":0,"y":-16,"z":0},"block_id":9},{"move":{"x":0,"y":-16,"z":6},"block_id":70},{"move":{"x":0,"y":-15,"z":0},"block_id":8},{"move":{"x":0,"y":-15,"z":6},"block_id":8},{"move":{"x":0,"y":-14,"z":0},"block_id":146},{"move":{"x":0,"y":-14,"z":6},"block_id":9},{"move":{"x":0,"y":-13,"z":0},"block_id":146},{"move":{"x":0,"y":-13,"z":6},"block_id":9},{"move":{"x":0,"y":-12,"z":0},"block_id":8},{"move":{"x":0,"y":-12,"z":6},"block_id":8},{"move":{"x":0,"y":-11,"z":0},"block_id":9},{"move":{"x":0,"y":-11,"z":6},"block_id":9},{"move":{"x":0,"y":-10,"z":0},"block_id":8},{"move":{"x":0,"y":-10,"z":6},"block_id":70},{"move":{"x":0,"y":-9,"z":0},"block_id":70},{"move":{"x":0,"y":-9,"z":6},"block_id":8},{"move":{"x":0,"y":-8,"z":0},"block_id":8},{"move":{"x":0,"y":-8,"z":6},"block_id":9},{"move":{"x":0,"y":-7,"z":0},"block_id":8},{"move":{"x":0,"y":-7,"z":6},"block_id":8},{"move":{"x":0,"y":-6,"z":0},"block_id":8},{"move":{"x":0,"y":-6,"z":6},"block_id":9},{"move":{"x":0,"y":-5,"z":0},"block_id":8},{"move":{"x":0,"y":-5,"z":6},"block_id":146},{"move":{"x":0,"y":-4,"z":0},"block_id":146},{"move":{"x":0,"y":-4,"z":6},"block_id":9},{"move":{"x":0,"y":-3,"z":0},"block_id":70},{"move":{"x":0,"y":-3,"z":6},"block_id":8},{"move":{"x":0,"y":-2,"z":0},"block_id":9},{"move":{"x":0,"y":-2,"z":6},"block_id":9},{"move":{"x":0,"y":-1,"z":0},"block_id":70},{"move":{"x":0,"y":-1,"z":1},"block_id":70},{"move":{"x":0,"y":-1,"z":2},"block_id":70},{"move":{"x":0,"y":-1,"z":3},"block_id":70},{"move":{"x":0,"y":-1,"z":4},"block_id":70},{"move":{"x":0,"y":-1,"z":5},"block_id":70},{"move":{"x":0,"y":-1,"z":6},"block_id":9},{"move":{"x":0,"y":0,"z":0},"block_id":584,"extra_data":{"point":{"x":0.780794902043425,"y":0,"z":0.28759820703538796},"opened":false,"left":false,"is_head":false},"rotate":{"x":2,"y":1,"z":0}},{"move":{"x":0,"y":0,"z":6},"block_id":9},{"move":{"x":0,"y":1,"z":0},"block_id":584,"extra_data":{"point":{"x":0.780794902043425,"y":0,"z":0.28759820703538796},"opened":false,"left":false,"is_head":true},"rotate":{"x":2,"y":1,"z":0}},{"move":{"x":0,"y":1,"z":6},"block_id":70},{"move":{"x":0,"y":2,"z":0},"block_id":70},{"move":{"x":0,"y":2,"z":6},"block_id":8},{"move":{"x":0,"y":3,"z":0},"block_id":9},{"move":{"x":0,"y":3,"z":6},"block_id":8},{"move":{"x":0,"y":4,"z":0},"block_id":146},{"move":{"x":0,"y":4,"z":1},"block_id":146},{"move":{"x":0,"y":4,"z":2},"block_id":9},{"move":{"x":0,"y":4,"z":3},"block_id":8},{"move":{"x":0,"y":4,"z":4},"block_id":8},{"move":{"x":0,"y":4,"z":5},"block_id":8},{"move":{"x":0,"y":4,"z":6},"block_id":9},{"move":{"x":1,"y":-81,"z":0},"block_id":8},{"move":{"x":1,"y":-81,"z":1},"block_id":70},{"move":{"x":1,"y":-81,"z":2},"block_id":9},{"move":{"x":1,"y":-81,"z":3},"block_id":146},{"move":{"x":1,"y":-81,"z":4},"block_id":70},{"move":{"x":1,"y":-81,"z":5},"block_id":146},{"move":{"x":1,"y":-81,"z":6},"block_id":70},{"move":{"x":1,"y":-80,"z":0},"block_id":146},{"move":{"x":1,"y":-80,"z":6},"block_id":8},{"move":{"x":1,"y":-79,"z":0},"block_id":9},{"move":{"x":1,"y":-79,"z":6},"block_id":70},{"move":{"x":1,"y":-78,"z":0},"block_id":146},{"move":{"x":1,"y":-78,"z":6},"block_id":8},{"move":{"x":1,"y":-77,"z":0},"block_id":146},{"move":{"x":1,"y":-77,"z":6},"block_id":9},{"move":{"x":1,"y":-76,"z":0},"block_id":9},{"move":{"x":1,"y":-76,"z":6},"block_id":146},{"move":{"x":1,"y":-75,"z":0},"block_id":70},{"move":{"x":1,"y":-75,"z":6},"block_id":70},{"move":{"x":1,"y":-74,"z":0},"block_id":70},{"move":{"x":1,"y":-74,"z":6},"block_id":70},{"move":{"x":1,"y":-73,"z":0},"block_id":70},{"move":{"x":1,"y":-73,"z":6},"block_id":8},{"move":{"x":1,"y":-72,"z":0},"block_id":146},{"move":{"x":1,"y":-72,"z":6},"block_id":70},{"move":{"x":1,"y":-71,"z":0},"block_id":70},{"move":{"x":1,"y":-71,"z":6},"block_id":9},{"move":{"x":1,"y":-70,"z":0},"block_id":9},{"move":{"x":1,"y":-70,"z":6},"block_id":146},{"move":{"x":1,"y":-69,"z":0},"block_id":70},{"move":{"x":1,"y":-69,"z":6},"block_id":9},{"move":{"x":1,"y":-68,"z":0},"block_id":8},{"move":{"x":1,"y":-68,"z":6},"block_id":70},{"move":{"x":1,"y":-67,"z":0},"block_id":8},{"move":{"x":1,"y":-67,"z":6},"block_id":146},{"move":{"x":1,"y":-66,"z":0},"block_id":146},{"move":{"x":1,"y":-66,"z":6},"block_id":8},{"move":{"x":1,"y":-65,"z":0},"block_id":146},{"move":{"x":1,"y":-65,"z":6},"block_id":8},{"move":{"x":1,"y":-64,"z":0},"block_id":146},{"move":{"x":1,"y":-64,"z":6},"block_id":8},{"move":{"x":1,"y":-63,"z":0},"block_id":70},{"move":{"x":1,"y":-63,"z":6},"block_id":70},{"move":{"x":1,"y":-62,"z":0},"block_id":146},{"move":{"x":1,"y":-62,"z":6},"block_id":8},{"move":{"x":1,"y":-61,"z":0},"block_id":8},{"move":{"x":1,"y":-61,"z":6},"block_id":9},{"move":{"x":1,"y":-60,"z":0},"block_id":8},{"move":{"x":1,"y":-60,"z":6},"block_id":9},{"move":{"x":1,"y":-59,"z":0},"block_id":70},{"move":{"x":1,"y":-59,"z":6},"block_id":8},{"move":{"x":1,"y":-58,"z":0},"block_id":70},{"move":{"x":1,"y":-58,"z":6},"block_id":9},{"move":{"x":1,"y":-57,"z":0},"block_id":9},{"move":{"x":1,"y":-57,"z":6},"block_id":70},{"move":{"x":1,"y":-56,"z":0},"block_id":146},{"move":{"x":1,"y":-56,"z":6},"block_id":8},{"move":{"x":1,"y":-55,"z":0},"block_id":9},{"move":{"x":1,"y":-55,"z":6},"block_id":146},{"move":{"x":1,"y":-54,"z":0},"block_id":9},{"move":{"x":1,"y":-54,"z":6},"block_id":70},{"move":{"x":1,"y":-53,"z":0},"block_id":8},{"move":{"x":1,"y":-53,"z":6},"block_id":8},{"move":{"x":1,"y":-52,"z":0},"block_id":8},{"move":{"x":1,"y":-52,"z":6},"block_id":9},{"move":{"x":1,"y":-51,"z":0},"block_id":9},{"move":{"x":1,"y":-51,"z":6},"block_id":8},{"move":{"x":1,"y":-50,"z":0},"block_id":146},{"move":{"x":1,"y":-50,"z":6},"block_id":9},{"move":{"x":1,"y":-49,"z":0},"block_id":70},{"move":{"x":1,"y":-49,"z":6},"block_id":8},{"move":{"x":1,"y":-48,"z":0},"block_id":9},{"move":{"x":1,"y":-48,"z":6},"block_id":8},{"move":{"x":1,"y":-47,"z":0},"block_id":146},{"move":{"x":1,"y":-47,"z":6},"block_id":8},{"move":{"x":1,"y":-46,"z":0},"block_id":8},{"move":{"x":1,"y":-46,"z":6},"block_id":70},{"move":{"x":1,"y":-45,"z":0},"block_id":8},{"move":{"x":1,"y":-45,"z":6},"block_id":8},{"move":{"x":1,"y":-44,"z":0},"block_id":70},{"move":{"x":1,"y":-44,"z":6},"block_id":9},{"move":{"x":1,"y":-43,"z":0},"block_id":8},{"move":{"x":1,"y":-43,"z":6},"block_id":9},{"move":{"x":1,"y":-42,"z":0},"block_id":8},{"move":{"x":1,"y":-42,"z":6},"block_id":9},{"move":{"x":1,"y":-41,"z":0},"block_id":9},{"move":{"x":1,"y":-41,"z":6},"block_id":70},{"move":{"x":1,"y":-40,"z":0},"block_id":70},{"move":{"x":1,"y":-40,"z":6},"block_id":70},{"move":{"x":1,"y":-39,"z":0},"block_id":8},{"move":{"x":1,"y":-39,"z":6},"block_id":146},{"move":{"x":1,"y":-38,"z":0},"block_id":146},{"move":{"x":1,"y":-38,"z":6},"block_id":8},{"move":{"x":1,"y":-37,"z":0},"block_id":9},{"move":{"x":1,"y":-37,"z":6},"block_id":146},{"move":{"x":1,"y":-36,"z":0},"block_id":146},{"move":{"x":1,"y":-36,"z":6},"block_id":146},{"move":{"x":1,"y":-35,"z":0},"block_id":146},{"move":{"x":1,"y":-35,"z":6},"block_id":9},{"move":{"x":1,"y":-34,"z":0},"block_id":9},{"move":{"x":1,"y":-34,"z":6},"block_id":8},{"move":{"x":1,"y":-33,"z":0},"block_id":70},{"move":{"x":1,"y":-33,"z":6},"block_id":9},{"move":{"x":1,"y":-32,"z":0},"block_id":146},{"move":{"x":1,"y":-32,"z":6},"block_id":146},{"move":{"x":1,"y":-31,"z":0},"block_id":70},{"move":{"x":1,"y":-31,"z":6},"block_id":9},{"move":{"x":1,"y":-30,"z":0},"block_id":8},{"move":{"x":1,"y":-30,"z":6},"block_id":70},{"move":{"x":1,"y":-29,"z":0},"block_id":146},{"move":{"x":1,"y":-29,"z":6},"block_id":70},{"move":{"x":1,"y":-28,"z":0},"block_id":146},{"move":{"x":1,"y":-28,"z":6},"block_id":146},{"move":{"x":1,"y":-27,"z":0},"block_id":8},{"move":{"x":1,"y":-27,"z":6},"block_id":8},{"move":{"x":1,"y":-26,"z":0},"block_id":70},{"move":{"x":1,"y":-26,"z":6},"block_id":8},{"move":{"x":1,"y":-25,"z":0},"block_id":146},{"move":{"x":1,"y":-25,"z":6},"block_id":70},{"move":{"x":1,"y":-24,"z":0},"block_id":70},{"move":{"x":1,"y":-24,"z":6},"block_id":70},{"move":{"x":1,"y":-23,"z":0},"block_id":8},{"move":{"x":1,"y":-23,"z":6},"block_id":146},{"move":{"x":1,"y":-22,"z":0},"block_id":146},{"move":{"x":1,"y":-22,"z":6},"block_id":70},{"move":{"x":1,"y":-21,"z":0},"block_id":70},{"move":{"x":1,"y":-21,"z":6},"block_id":9},{"move":{"x":1,"y":-20,"z":0},"block_id":9},{"move":{"x":1,"y":-20,"z":6},"block_id":70},{"move":{"x":1,"y":-19,"z":0},"block_id":146},{"move":{"x":1,"y":-19,"z":6},"block_id":8},{"move":{"x":1,"y":-18,"z":0},"block_id":70},{"move":{"x":1,"y":-18,"z":6},"block_id":9},{"move":{"x":1,"y":-17,"z":0},"block_id":9},{"move":{"x":1,"y":-17,"z":6},"block_id":8},{"move":{"x":1,"y":-16,"z":0},"block_id":8},{"move":{"x":1,"y":-16,"z":6},"block_id":9},{"move":{"x":1,"y":-15,"z":0},"block_id":70},{"move":{"x":1,"y":-15,"z":6},"block_id":70},{"move":{"x":1,"y":-14,"z":0},"block_id":146},{"move":{"x":1,"y":-14,"z":6},"block_id":70},{"move":{"x":1,"y":-13,"z":0},"block_id":146},{"move":{"x":1,"y":-13,"z":6},"block_id":146},{"move":{"x":1,"y":-12,"z":0},"block_id":70},{"move":{"x":1,"y":-12,"z":6},"block_id":8},{"move":{"x":1,"y":-11,"z":0},"block_id":9},{"move":{"x":1,"y":-11,"z":6},"block_id":146},{"move":{"x":1,"y":-10,"z":0},"block_id":9},{"move":{"x":1,"y":-10,"z":6},"block_id":146},{"move":{"x":1,"y":-9,"z":0},"block_id":146},{"move":{"x":1,"y":-9,"z":6},"block_id":9},{"move":{"x":1,"y":-8,"z":0},"block_id":9},{"move":{"x":1,"y":-8,"z":6},"block_id":9},{"move":{"x":1,"y":-7,"z":0},"block_id":146},{"move":{"x":1,"y":-7,"z":6},"block_id":8},{"move":{"x":1,"y":-6,"z":0},"block_id":8},{"move":{"x":1,"y":-6,"z":6},"block_id":9},{"move":{"x":1,"y":-5,"z":0},"block_id":70},{"move":{"x":1,"y":-5,"z":6},"block_id":70},{"move":{"x":1,"y":-4,"z":0},"block_id":146},{"move":{"x":1,"y":-4,"z":6},"block_id":146},{"move":{"x":1,"y":-3,"z":0},"block_id":146},{"move":{"x":1,"y":-3,"z":6},"block_id":70},{"move":{"x":1,"y":-2,"z":0},"block_id":70},{"move":{"x":1,"y":-2,"z":6},"block_id":8},{"move":{"x":1,"y":-1,"z":0},"block_id":70},{"move":{"x":1,"y":-1,"z":1},"block_id":70},{"move":{"x":1,"y":-1,"z":2},"block_id":70},{"move":{"x":1,"y":-1,"z":3},"block_id":70},{"move":{"x":1,"y":-1,"z":4},"block_id":70},{"move":{"x":1,"y":-1,"z":5},"block_id":70},{"move":{"x":1,"y":-1,"z":6},"block_id":70},{"move":{"x":1,"y":0,"z":0},"block_id":70},{"move":{"x":1,"y":0,"z":6},"block_id":8},{"move":{"x":1,"y":1,"z":0},"block_id":70},{"move":{"x":1,"y":1,"z":6},"block_id":146},{"move":{"x":1,"y":2,"z":0},"block_id":146},{"move":{"x":1,"y":2,"z":6},"block_id":146},{"move":{"x":1,"y":3,"z":0},"block_id":8},{"move":{"x":1,"y":3,"z":6},"block_id":146},{"move":{"x":1,"y":4,"z":0},"block_id":146},{"move":{"x":1,"y":4,"z":1},"block_id":146},{"move":{"x":1,"y":4,"z":2},"block_id":70},{"move":{"x":1,"y":4,"z":3},"block_id":9},{"move":{"x":1,"y":4,"z":4},"block_id":146},{"move":{"x":1,"y":4,"z":5},"block_id":70},{"move":{"x":1,"y":4,"z":6},"block_id":9},{"move":{"x":2,"y":-81,"z":0},"block_id":8},{"move":{"x":2,"y":-81,"z":1},"block_id":9},{"move":{"x":2,"y":-81,"z":2},"block_id":70},{"move":{"x":2,"y":-81,"z":3},"block_id":70},{"move":{"x":2,"y":-81,"z":4},"block_id":8},{"move":{"x":2,"y":-81,"z":5},"block_id":146},{"move":{"x":2,"y":-81,"z":6},"block_id":9},{"move":{"x":2,"y":-80,"z":0},"block_id":70},{"move":{"x":2,"y":-80,"z":6},"block_id":8},{"move":{"x":2,"y":-79,"z":0},"block_id":70},{"move":{"x":2,"y":-79,"z":6},"block_id":8},{"move":{"x":2,"y":-78,"z":0},"block_id":8},{"move":{"x":2,"y":-78,"z":6},"block_id":9},{"move":{"x":2,"y":-77,"z":0},"block_id":146},{"move":{"x":2,"y":-77,"z":6},"block_id":146},{"move":{"x":2,"y":-76,"z":0},"block_id":8},{"move":{"x":2,"y":-76,"z":6},"block_id":146},{"move":{"x":2,"y":-75,"z":0},"block_id":146},{"move":{"x":2,"y":-75,"z":6},"block_id":70},{"move":{"x":2,"y":-74,"z":0},"block_id":146},{"move":{"x":2,"y":-74,"z":6},"block_id":9},{"move":{"x":2,"y":-73,"z":0},"block_id":9},{"move":{"x":2,"y":-73,"z":6},"block_id":9},{"move":{"x":2,"y":-72,"z":0},"block_id":8},{"move":{"x":2,"y":-72,"z":6},"block_id":146},{"move":{"x":2,"y":-71,"z":0},"block_id":70},{"move":{"x":2,"y":-71,"z":6},"block_id":8},{"move":{"x":2,"y":-70,"z":0},"block_id":70},{"move":{"x":2,"y":-70,"z":6},"block_id":9},{"move":{"x":2,"y":-69,"z":0},"block_id":146},{"move":{"x":2,"y":-69,"z":6},"block_id":9},{"move":{"x":2,"y":-68,"z":0},"block_id":9},{"move":{"x":2,"y":-68,"z":6},"block_id":9},{"move":{"x":2,"y":-67,"z":0},"block_id":146},{"move":{"x":2,"y":-67,"z":6},"block_id":70},{"move":{"x":2,"y":-66,"z":0},"block_id":70},{"move":{"x":2,"y":-66,"z":6},"block_id":9},{"move":{"x":2,"y":-65,"z":0},"block_id":8},{"move":{"x":2,"y":-65,"z":6},"block_id":9},{"move":{"x":2,"y":-64,"z":0},"block_id":146},{"move":{"x":2,"y":-64,"z":6},"block_id":70},{"move":{"x":2,"y":-63,"z":0},"block_id":9},{"move":{"x":2,"y":-63,"z":6},"block_id":9},{"move":{"x":2,"y":-62,"z":0},"block_id":146},{"move":{"x":2,"y":-62,"z":6},"block_id":146},{"move":{"x":2,"y":-61,"z":0},"block_id":146},{"move":{"x":2,"y":-61,"z":6},"block_id":8},{"move":{"x":2,"y":-60,"z":0},"block_id":70},{"move":{"x":2,"y":-60,"z":6},"block_id":8},{"move":{"x":2,"y":-59,"z":0},"block_id":70},{"move":{"x":2,"y":-59,"z":6},"block_id":146},{"move":{"x":2,"y":-58,"z":0},"block_id":70},{"move":{"x":2,"y":-58,"z":6},"block_id":146},{"move":{"x":2,"y":-57,"z":0},"block_id":8},{"move":{"x":2,"y":-57,"z":6},"block_id":146},{"move":{"x":2,"y":-56,"z":0},"block_id":70},{"move":{"x":2,"y":-56,"z":6},"block_id":9},{"move":{"x":2,"y":-55,"z":0},"block_id":70},{"move":{"x":2,"y":-55,"z":6},"block_id":70},{"move":{"x":2,"y":-54,"z":0},"block_id":8},{"move":{"x":2,"y":-54,"z":6},"block_id":146},{"move":{"x":2,"y":-53,"z":0},"block_id":8},{"move":{"x":2,"y":-53,"z":6},"block_id":146},{"move":{"x":2,"y":-52,"z":0},"block_id":8},{"move":{"x":2,"y":-52,"z":6},"block_id":70},{"move":{"x":2,"y":-51,"z":0},"block_id":8},{"move":{"x":2,"y":-51,"z":6},"block_id":70},{"move":{"x":2,"y":-50,"z":0},"block_id":70},{"move":{"x":2,"y":-50,"z":6},"block_id":9},{"move":{"x":2,"y":-49,"z":0},"block_id":70},{"move":{"x":2,"y":-49,"z":6},"block_id":146},{"move":{"x":2,"y":-48,"z":0},"block_id":146},{"move":{"x":2,"y":-48,"z":6},"block_id":9},{"move":{"x":2,"y":-47,"z":0},"block_id":8},{"move":{"x":2,"y":-47,"z":6},"block_id":146},{"move":{"x":2,"y":-46,"z":0},"block_id":146},{"move":{"x":2,"y":-46,"z":6},"block_id":70},{"move":{"x":2,"y":-45,"z":0},"block_id":146},{"move":{"x":2,"y":-45,"z":6},"block_id":9},{"move":{"x":2,"y":-44,"z":0},"block_id":146},{"move":{"x":2,"y":-44,"z":6},"block_id":146},{"move":{"x":2,"y":-43,"z":0},"block_id":146},{"move":{"x":2,"y":-43,"z":6},"block_id":146},{"move":{"x":2,"y":-42,"z":0},"block_id":9},{"move":{"x":2,"y":-42,"z":6},"block_id":146},{"move":{"x":2,"y":-41,"z":0},"block_id":9},{"move":{"x":2,"y":-41,"z":6},"block_id":70},{"move":{"x":2,"y":-40,"z":0},"block_id":8},{"move":{"x":2,"y":-40,"z":6},"block_id":146},{"move":{"x":2,"y":-39,"z":0},"block_id":146},{"move":{"x":2,"y":-39,"z":6},"block_id":9},{"move":{"x":2,"y":-38,"z":0},"block_id":9},{"move":{"x":2,"y":-38,"z":6},"block_id":70},{"move":{"x":2,"y":-37,"z":0},"block_id":8},{"move":{"x":2,"y":-37,"z":6},"block_id":9},{"move":{"x":2,"y":-36,"z":0},"block_id":8},{"move":{"x":2,"y":-36,"z":6},"block_id":8},{"move":{"x":2,"y":-35,"z":0},"block_id":8},{"move":{"x":2,"y":-35,"z":6},"block_id":9},{"move":{"x":2,"y":-34,"z":0},"block_id":146},{"move":{"x":2,"y":-34,"z":6},"block_id":146},{"move":{"x":2,"y":-33,"z":0},"block_id":70},{"move":{"x":2,"y":-33,"z":6},"block_id":9},{"move":{"x":2,"y":-32,"z":0},"block_id":146},{"move":{"x":2,"y":-32,"z":6},"block_id":70},{"move":{"x":2,"y":-31,"z":0},"block_id":146},{"move":{"x":2,"y":-31,"z":6},"block_id":70},{"move":{"x":2,"y":-30,"z":0},"block_id":8},{"move":{"x":2,"y":-30,"z":6},"block_id":70},{"move":{"x":2,"y":-29,"z":0},"block_id":8},{"move":{"x":2,"y":-29,"z":6},"block_id":9},{"move":{"x":2,"y":-28,"z":0},"block_id":8},{"move":{"x":2,"y":-28,"z":6},"block_id":146},{"move":{"x":2,"y":-27,"z":0},"block_id":8},{"move":{"x":2,"y":-27,"z":6},"block_id":9},{"move":{"x":2,"y":-26,"z":0},"block_id":9},{"move":{"x":2,"y":-26,"z":6},"block_id":70},{"move":{"x":2,"y":-25,"z":0},"block_id":70},{"move":{"x":2,"y":-25,"z":6},"block_id":8},{"move":{"x":2,"y":-24,"z":0},"block_id":146},{"move":{"x":2,"y":-24,"z":6},"block_id":70},{"move":{"x":2,"y":-23,"z":0},"block_id":146},{"move":{"x":2,"y":-23,"z":6},"block_id":146},{"move":{"x":2,"y":-22,"z":0},"block_id":70},{"move":{"x":2,"y":-22,"z":6},"block_id":146},{"move":{"x":2,"y":-21,"z":0},"block_id":146},{"move":{"x":2,"y":-21,"z":6},"block_id":146},{"move":{"x":2,"y":-20,"z":0},"block_id":8},{"move":{"x":2,"y":-20,"z":6},"block_id":9},{"move":{"x":2,"y":-19,"z":0},"block_id":8},{"move":{"x":2,"y":-19,"z":6},"block_id":70},{"move":{"x":2,"y":-18,"z":0},"block_id":9},{"move":{"x":2,"y":-18,"z":6},"block_id":9},{"move":{"x":2,"y":-17,"z":0},"block_id":146},{"move":{"x":2,"y":-17,"z":6},"block_id":9},{"move":{"x":2,"y":-16,"z":0},"block_id":8},{"move":{"x":2,"y":-16,"z":6},"block_id":8},{"move":{"x":2,"y":-15,"z":0},"block_id":146},{"move":{"x":2,"y":-15,"z":6},"block_id":8},{"move":{"x":2,"y":-14,"z":0},"block_id":70},{"move":{"x":2,"y":-14,"z":6},"block_id":8},{"move":{"x":2,"y":-13,"z":0},"block_id":70},{"move":{"x":2,"y":-13,"z":6},"block_id":8},{"move":{"x":2,"y":-12,"z":0},"block_id":70},{"move":{"x":2,"y":-12,"z":6},"block_id":8},{"move":{"x":2,"y":-11,"z":0},"block_id":70},{"move":{"x":2,"y":-11,"z":6},"block_id":70},{"move":{"x":2,"y":-10,"z":0},"block_id":146},{"move":{"x":2,"y":-10,"z":6},"block_id":9},{"move":{"x":2,"y":-9,"z":0},"block_id":146},{"move":{"x":2,"y":-9,"z":6},"block_id":8},{"move":{"x":2,"y":-8,"z":0},"block_id":146},{"move":{"x":2,"y":-8,"z":6},"block_id":9},{"move":{"x":2,"y":-7,"z":0},"block_id":146},{"move":{"x":2,"y":-7,"z":6},"block_id":70},{"move":{"x":2,"y":-6,"z":0},"block_id":9},{"move":{"x":2,"y":-6,"z":6},"block_id":70},{"move":{"x":2,"y":-5,"z":0},"block_id":8},{"move":{"x":2,"y":-5,"z":6},"block_id":9},{"move":{"x":2,"y":-4,"z":0},"block_id":146},{"move":{"x":2,"y":-4,"z":6},"block_id":9},{"move":{"x":2,"y":-3,"z":0},"block_id":8},{"move":{"x":2,"y":-3,"z":6},"block_id":9},{"move":{"x":2,"y":-2,"z":0},"block_id":70},{"move":{"x":2,"y":-2,"z":6},"block_id":70},{"move":{"x":2,"y":-1,"z":0},"block_id":146},{"move":{"x":2,"y":-1,"z":1},"block_id":70},{"move":{"x":2,"y":-1,"z":2},"block_id":70},{"move":{"x":2,"y":-1,"z":3},"block_id":70},{"move":{"x":2,"y":-1,"z":4},"block_id":70},{"move":{"x":2,"y":-1,"z":5},"block_id":70},{"move":{"x":2,"y":-1,"z":6},"block_id":146},{"move":{"x":2,"y":0,"z":0},"block_id":146},{"move":{"x":2,"y":0,"z":6},"block_id":146},{"move":{"x":2,"y":1,"z":0},"block_id":9},{"move":{"x":2,"y":1,"z":6},"block_id":70},{"move":{"x":2,"y":2,"z":0},"block_id":8},{"move":{"x":2,"y":2,"z":6},"block_id":9},{"move":{"x":2,"y":3,"z":0},"block_id":146},{"move":{"x":2,"y":3,"z":6},"block_id":9},{"move":{"x":2,"y":4,"z":0},"block_id":9},{"move":{"x":2,"y":4,"z":1},"block_id":8},{"move":{"x":2,"y":4,"z":2},"block_id":8},{"move":{"x":2,"y":4,"z":3},"block_id":70},{"move":{"x":2,"y":4,"z":4},"block_id":8},{"move":{"x":2,"y":4,"z":5},"block_id":8},{"move":{"x":2,"y":4,"z":6},"block_id":70},{"move":{"x":3,"y":-81,"z":0},"block_id":70},{"move":{"x":3,"y":-81,"z":1},"block_id":146},{"move":{"x":3,"y":-81,"z":2},"block_id":146},{"move":{"x":3,"y":-81,"z":3},"block_id":70},{"move":{"x":3,"y":-81,"z":4},"block_id":8},{"move":{"x":3,"y":-81,"z":5},"block_id":146},{"move":{"x":3,"y":-81,"z":6},"block_id":70},{"move":{"x":3,"y":-80,"z":0},"block_id":70},{"move":{"x":3,"y":-80,"z":1},"block_id":70},{"move":{"x":3,"y":-80,"z":2},"block_id":146},{"move":{"x":3,"y":-80,"z":3},"block_id":8},{"move":{"x":3,"y":-80,"z":4},"block_id":146},{"move":{"x":3,"y":-80,"z":5},"block_id":8},{"move":{"x":3,"y":-80,"z":6},"block_id":70},{"move":{"x":3,"y":-79,"z":0},"block_id":70},{"move":{"x":3,"y":-79,"z":1},"block_id":70},{"move":{"x":3,"y":-79,"z":2},"block_id":70},{"move":{"x":3,"y":-79,"z":3},"block_id":70},{"move":{"x":3,"y":-79,"z":4},"block_id":8},{"move":{"x":3,"y":-79,"z":5},"block_id":146},{"move":{"x":3,"y":-79,"z":6},"block_id":9},{"move":{"x":3,"y":-78,"z":0},"block_id":146},{"move":{"x":3,"y":-78,"z":1},"block_id":8},{"move":{"x":3,"y":-78,"z":2},"block_id":70},{"move":{"x":3,"y":-78,"z":3},"block_id":146},{"move":{"x":3,"y":-78,"z":4},"block_id":8},{"move":{"x":3,"y":-78,"z":5},"block_id":70},{"move":{"x":3,"y":-78,"z":6},"block_id":70},{"move":{"x":3,"y":-77,"z":0},"block_id":9},{"move":{"x":3,"y":-77,"z":1},"block_id":9},{"move":{"x":3,"y":-77,"z":2},"block_id":9},{"move":{"x":3,"y":-77,"z":3},"block_id":146},{"move":{"x":3,"y":-77,"z":4},"block_id":8},{"move":{"x":3,"y":-77,"z":5},"block_id":70},{"move":{"x":3,"y":-77,"z":6},"block_id":70},{"move":{"x":3,"y":-76,"z":0},"block_id":8},{"move":{"x":3,"y":-76,"z":1},"block_id":8},{"move":{"x":3,"y":-76,"z":2},"block_id":146},{"move":{"x":3,"y":-76,"z":3},"block_id":146},{"move":{"x":3,"y":-76,"z":4},"block_id":146},{"move":{"x":3,"y":-76,"z":5},"block_id":70},{"move":{"x":3,"y":-76,"z":6},"block_id":146},{"move":{"x":3,"y":-75,"z":0},"block_id":70},{"move":{"x":3,"y":-75,"z":1},"block_id":70},{"move":{"x":3,"y":-75,"z":2},"block_id":9},{"move":{"x":3,"y":-75,"z":3},"block_id":8},{"move":{"x":3,"y":-75,"z":4},"block_id":146},{"move":{"x":3,"y":-75,"z":5},"block_id":9},{"move":{"x":3,"y":-75,"z":6},"block_id":9},{"move":{"x":3,"y":-74,"z":0},"block_id":146},{"move":{"x":3,"y":-74,"z":1},"block_id":8},{"move":{"x":3,"y":-74,"z":2},"block_id":146},{"move":{"x":3,"y":-74,"z":3},"block_id":70},{"move":{"x":3,"y":-74,"z":4},"block_id":146},{"move":{"x":3,"y":-74,"z":5},"block_id":70},{"move":{"x":3,"y":-74,"z":6},"block_id":9},{"move":{"x":3,"y":-73,"z":0},"block_id":70},{"move":{"x":3,"y":-73,"z":1},"block_id":8},{"move":{"x":3,"y":-73,"z":2},"block_id":8},{"move":{"x":3,"y":-73,"z":3},"block_id":70},{"move":{"x":3,"y":-73,"z":4},"block_id":9},{"move":{"x":3,"y":-73,"z":5},"block_id":9},{"move":{"x":3,"y":-73,"z":6},"block_id":9},{"move":{"x":3,"y":-72,"z":0},"block_id":146},{"move":{"x":3,"y":-72,"z":1},"block_id":8},{"move":{"x":3,"y":-72,"z":2},"block_id":146},{"move":{"x":3,"y":-72,"z":3},"block_id":70},{"move":{"x":3,"y":-72,"z":4},"block_id":8},{"move":{"x":3,"y":-72,"z":5},"block_id":146},{"move":{"x":3,"y":-72,"z":6},"block_id":146},{"move":{"x":3,"y":-71,"z":0},"block_id":70},{"move":{"x":3,"y":-71,"z":1},"block_id":9},{"move":{"x":3,"y":-71,"z":2},"block_id":70},{"move":{"x":3,"y":-71,"z":3},"block_id":8},{"move":{"x":3,"y":-71,"z":4},"block_id":146},{"move":{"x":3,"y":-71,"z":5},"block_id":8},{"move":{"x":3,"y":-71,"z":6},"block_id":70},{"move":{"x":3,"y":-70,"z":0},"block_id":146},{"move":{"x":3,"y":-70,"z":1},"block_id":8},{"move":{"x":3,"y":-70,"z":2},"block_id":70},{"move":{"x":3,"y":-70,"z":3},"block_id":8},{"move":{"x":3,"y":-70,"z":4},"block_id":8},{"move":{"x":3,"y":-70,"z":5},"block_id":146},{"move":{"x":3,"y":-70,"z":6},"block_id":8},{"move":{"x":3,"y":-69,"z":0},"block_id":146},{"move":{"x":3,"y":-69,"z":1},"block_id":8},{"move":{"x":3,"y":-69,"z":2},"block_id":8},{"move":{"x":3,"y":-69,"z":3},"block_id":70},{"move":{"x":3,"y":-69,"z":4},"block_id":70},{"move":{"x":3,"y":-69,"z":5},"block_id":146},{"move":{"x":3,"y":-69,"z":6},"block_id":70},{"move":{"x":3,"y":-68,"z":0},"block_id":70},{"move":{"x":3,"y":-68,"z":1},"block_id":8},{"move":{"x":3,"y":-68,"z":2},"block_id":9},{"move":{"x":3,"y":-68,"z":3},"block_id":70},{"move":{"x":3,"y":-68,"z":4},"block_id":8},{"move":{"x":3,"y":-68,"z":5},"block_id":8},{"move":{"x":3,"y":-68,"z":6},"block_id":9},{"move":{"x":3,"y":-67,"z":0},"block_id":146},{"move":{"x":3,"y":-67,"z":1},"block_id":70},{"move":{"x":3,"y":-67,"z":2},"block_id":9},{"move":{"x":3,"y":-67,"z":3},"block_id":70},{"move":{"x":3,"y":-67,"z":4},"block_id":146},{"move":{"x":3,"y":-67,"z":5},"block_id":8},{"move":{"x":3,"y":-67,"z":6},"block_id":8},{"move":{"x":3,"y":-66,"z":0},"block_id":146},{"move":{"x":3,"y":-66,"z":1},"block_id":146},{"move":{"x":3,"y":-66,"z":2},"block_id":70},{"move":{"x":3,"y":-66,"z":3},"block_id":8},{"move":{"x":3,"y":-66,"z":4},"block_id":9},{"move":{"x":3,"y":-66,"z":5},"block_id":9},{"move":{"x":3,"y":-66,"z":6},"block_id":9},{"move":{"x":3,"y":-65,"z":0},"block_id":70},{"move":{"x":3,"y":-65,"z":1},"block_id":70},{"move":{"x":3,"y":-65,"z":2},"block_id":70},{"move":{"x":3,"y":-65,"z":3},"block_id":70},{"move":{"x":3,"y":-65,"z":4},"block_id":70},{"move":{"x":3,"y":-65,"z":5},"block_id":146},{"move":{"x":3,"y":-65,"z":6},"block_id":70},{"move":{"x":3,"y":-64,"z":0},"block_id":70},{"move":{"x":3,"y":-64,"z":1},"block_id":9},{"move":{"x":3,"y":-64,"z":2},"block_id":70},{"move":{"x":3,"y":-64,"z":3},"block_id":8},{"move":{"x":3,"y":-64,"z":4},"block_id":146},{"move":{"x":3,"y":-64,"z":5},"block_id":146},{"move":{"x":3,"y":-64,"z":6},"block_id":9},{"move":{"x":3,"y":-63,"z":0},"block_id":9},{"move":{"x":3,"y":-63,"z":1},"block_id":146},{"move":{"x":3,"y":-63,"z":2},"block_id":146},{"move":{"x":3,"y":-63,"z":3},"block_id":70},{"move":{"x":3,"y":-63,"z":4},"block_id":9},{"move":{"x":3,"y":-63,"z":5},"block_id":8},{"move":{"x":3,"y":-63,"z":6},"block_id":9},{"move":{"x":3,"y":-62,"z":0},"block_id":8},{"move":{"x":3,"y":-62,"z":1},"block_id":8},{"move":{"x":3,"y":-62,"z":2},"block_id":146},{"move":{"x":3,"y":-62,"z":3},"block_id":9},{"move":{"x":3,"y":-62,"z":4},"block_id":9},{"move":{"x":3,"y":-62,"z":5},"block_id":146},{"move":{"x":3,"y":-62,"z":6},"block_id":9},{"move":{"x":3,"y":-61,"z":0},"block_id":9},{"move":{"x":3,"y":-61,"z":1},"block_id":9},{"move":{"x":3,"y":-61,"z":2},"block_id":146},{"move":{"x":3,"y":-61,"z":3},"block_id":8},{"move":{"x":3,"y":-61,"z":4},"block_id":9},{"move":{"x":3,"y":-61,"z":5},"block_id":146},{"move":{"x":3,"y":-61,"z":6},"block_id":146},{"move":{"x":3,"y":-60,"z":0},"block_id":70},{"move":{"x":3,"y":-60,"z":1},"block_id":8},{"move":{"x":3,"y":-60,"z":2},"block_id":146},{"move":{"x":3,"y":-60,"z":3},"block_id":70},{"move":{"x":3,"y":-60,"z":4},"block_id":8},{"move":{"x":3,"y":-60,"z":5},"block_id":9},{"move":{"x":3,"y":-60,"z":6},"block_id":70},{"move":{"x":3,"y":-59,"z":0},"block_id":8},{"move":{"x":3,"y":-59,"z":1},"block_id":9},{"move":{"x":3,"y":-59,"z":2},"block_id":146},{"move":{"x":3,"y":-59,"z":3},"block_id":9},{"move":{"x":3,"y":-59,"z":4},"block_id":9},{"move":{"x":3,"y":-59,"z":5},"block_id":146},{"move":{"x":3,"y":-59,"z":6},"block_id":8},{"move":{"x":3,"y":-58,"z":0},"block_id":70},{"move":{"x":3,"y":-58,"z":1},"block_id":70},{"move":{"x":3,"y":-58,"z":2},"block_id":9},{"move":{"x":3,"y":-58,"z":3},"block_id":9},{"move":{"x":3,"y":-58,"z":4},"block_id":70},{"move":{"x":3,"y":-58,"z":5},"block_id":9},{"move":{"x":3,"y":-58,"z":6},"block_id":8},{"move":{"x":3,"y":-57,"z":0},"block_id":9},{"move":{"x":3,"y":-57,"z":1},"block_id":146},{"move":{"x":3,"y":-57,"z":2},"block_id":146},{"move":{"x":3,"y":-57,"z":3},"block_id":70},{"move":{"x":3,"y":-57,"z":4},"block_id":70},{"move":{"x":3,"y":-57,"z":5},"block_id":146},{"move":{"x":3,"y":-57,"z":6},"block_id":146},{"move":{"x":3,"y":-56,"z":0},"block_id":9},{"move":{"x":3,"y":-56,"z":1},"block_id":146},{"move":{"x":3,"y":-56,"z":2},"block_id":146},{"move":{"x":3,"y":-56,"z":3},"block_id":9},{"move":{"x":3,"y":-56,"z":4},"block_id":8},{"move":{"x":3,"y":-56,"z":5},"block_id":146},{"move":{"x":3,"y":-56,"z":6},"block_id":8},{"move":{"x":3,"y":-55,"z":0},"block_id":70},{"move":{"x":3,"y":-55,"z":1},"block_id":146},{"move":{"x":3,"y":-55,"z":2},"block_id":8},{"move":{"x":3,"y":-55,"z":3},"block_id":9},{"move":{"x":3,"y":-55,"z":4},"block_id":9},{"move":{"x":3,"y":-55,"z":5},"block_id":8},{"move":{"x":3,"y":-55,"z":6},"block_id":70},{"move":{"x":3,"y":-54,"z":0},"block_id":146},{"move":{"x":3,"y":-54,"z":1},"block_id":70},{"move":{"x":3,"y":-54,"z":2},"block_id":8},{"move":{"x":3,"y":-54,"z":3},"block_id":8},{"move":{"x":3,"y":-54,"z":4},"block_id":9},{"move":{"x":3,"y":-54,"z":5},"block_id":8},{"move":{"x":3,"y":-54,"z":6},"block_id":146},{"move":{"x":3,"y":-53,"z":0},"block_id":9},{"move":{"x":3,"y":-53,"z":1},"block_id":146},{"move":{"x":3,"y":-53,"z":2},"block_id":146},{"move":{"x":3,"y":-53,"z":3},"block_id":70},{"move":{"x":3,"y":-53,"z":4},"block_id":146},{"move":{"x":3,"y":-53,"z":5},"block_id":146},{"move":{"x":3,"y":-53,"z":6},"block_id":146},{"move":{"x":3,"y":-52,"z":0},"block_id":70},{"move":{"x":3,"y":-52,"z":1},"block_id":70},{"move":{"x":3,"y":-52,"z":2},"block_id":9},{"move":{"x":3,"y":-52,"z":3},"block_id":8},{"move":{"x":3,"y":-52,"z":4},"block_id":70},{"move":{"x":3,"y":-52,"z":5},"block_id":70},{"move":{"x":3,"y":-52,"z":6},"block_id":70},{"move":{"x":3,"y":-51,"z":0},"block_id":146},{"move":{"x":3,"y":-51,"z":1},"block_id":146},{"move":{"x":3,"y":-51,"z":2},"block_id":8},{"move":{"x":3,"y":-51,"z":3},"block_id":8},{"move":{"x":3,"y":-51,"z":4},"block_id":8},{"move":{"x":3,"y":-51,"z":5},"block_id":146},{"move":{"x":3,"y":-51,"z":6},"block_id":146},{"move":{"x":3,"y":-50,"z":0},"block_id":9},{"move":{"x":3,"y":-50,"z":1},"block_id":8},{"move":{"x":3,"y":-50,"z":2},"block_id":9},{"move":{"x":3,"y":-50,"z":3},"block_id":146},{"move":{"x":3,"y":-50,"z":4},"block_id":8},{"move":{"x":3,"y":-50,"z":5},"block_id":8},{"move":{"x":3,"y":-50,"z":6},"block_id":70},{"move":{"x":3,"y":-49,"z":0},"block_id":146},{"move":{"x":3,"y":-49,"z":1},"block_id":146},{"move":{"x":3,"y":-49,"z":2},"block_id":70},{"move":{"x":3,"y":-49,"z":3},"block_id":146},{"move":{"x":3,"y":-49,"z":4},"block_id":9},{"move":{"x":3,"y":-49,"z":5},"block_id":146},{"move":{"x":3,"y":-49,"z":6},"block_id":146},{"move":{"x":3,"y":-48,"z":0},"block_id":9},{"move":{"x":3,"y":-48,"z":1},"block_id":146},{"move":{"x":3,"y":-48,"z":2},"block_id":8},{"move":{"x":3,"y":-48,"z":3},"block_id":9},{"move":{"x":3,"y":-48,"z":4},"block_id":146},{"move":{"x":3,"y":-48,"z":5},"block_id":8},{"move":{"x":3,"y":-48,"z":6},"block_id":8},{"move":{"x":3,"y":-47,"z":0},"block_id":8},{"move":{"x":3,"y":-47,"z":1},"block_id":8},{"move":{"x":3,"y":-47,"z":2},"block_id":70},{"move":{"x":3,"y":-47,"z":3},"block_id":146},{"move":{"x":3,"y":-47,"z":4},"block_id":146},{"move":{"x":3,"y":-47,"z":5},"block_id":9},{"move":{"x":3,"y":-47,"z":6},"block_id":8},{"move":{"x":3,"y":-46,"z":0},"block_id":146},{"move":{"x":3,"y":-46,"z":1},"block_id":70},{"move":{"x":3,"y":-46,"z":2},"block_id":146},{"move":{"x":3,"y":-46,"z":3},"block_id":146},{"move":{"x":3,"y":-46,"z":4},"block_id":9},{"move":{"x":3,"y":-46,"z":5},"block_id":146},{"move":{"x":3,"y":-46,"z":6},"block_id":9},{"move":{"x":3,"y":-45,"z":0},"block_id":146},{"move":{"x":3,"y":-45,"z":1},"block_id":70},{"move":{"x":3,"y":-45,"z":2},"block_id":9},{"move":{"x":3,"y":-45,"z":3},"block_id":8},{"move":{"x":3,"y":-45,"z":4},"block_id":8},{"move":{"x":3,"y":-45,"z":5},"block_id":8},{"move":{"x":3,"y":-45,"z":6},"block_id":70},{"move":{"x":3,"y":-44,"z":0},"block_id":70},{"move":{"x":3,"y":-44,"z":1},"block_id":70},{"move":{"x":3,"y":-44,"z":2},"block_id":8},{"move":{"x":3,"y":-44,"z":3},"block_id":8},{"move":{"x":3,"y":-44,"z":4},"block_id":70},{"move":{"x":3,"y":-44,"z":5},"block_id":8},{"move":{"x":3,"y":-44,"z":6},"block_id":8},{"move":{"x":3,"y":-43,"z":0},"block_id":70},{"move":{"x":3,"y":-43,"z":1},"block_id":9},{"move":{"x":3,"y":-43,"z":2},"block_id":8},{"move":{"x":3,"y":-43,"z":3},"block_id":9},{"move":{"x":3,"y":-43,"z":4},"block_id":146},{"move":{"x":3,"y":-43,"z":5},"block_id":70},{"move":{"x":3,"y":-43,"z":6},"block_id":8},{"move":{"x":3,"y":-42,"z":0},"block_id":8},{"move":{"x":3,"y":-42,"z":1},"block_id":146},{"move":{"x":3,"y":-42,"z":2},"block_id":8},{"move":{"x":3,"y":-42,"z":3},"block_id":146},{"move":{"x":3,"y":-42,"z":4},"block_id":70},{"move":{"x":3,"y":-42,"z":5},"block_id":8},{"move":{"x":3,"y":-42,"z":6},"block_id":9},{"move":{"x":3,"y":-41,"z":0},"block_id":146},{"move":{"x":3,"y":-41,"z":1},"block_id":9},{"move":{"x":3,"y":-41,"z":2},"block_id":70},{"move":{"x":3,"y":-41,"z":3},"block_id":70},{"move":{"x":3,"y":-41,"z":4},"block_id":70},{"move":{"x":3,"y":-41,"z":5},"block_id":146},{"move":{"x":3,"y":-41,"z":6},"block_id":146},{"move":{"x":3,"y":-40,"z":0},"block_id":146},{"move":{"x":3,"y":-40,"z":1},"block_id":8},{"move":{"x":3,"y":-40,"z":2},"block_id":70},{"move":{"x":3,"y":-40,"z":3},"block_id":8},{"move":{"x":3,"y":-40,"z":4},"block_id":70},{"move":{"x":3,"y":-40,"z":5},"block_id":146},{"move":{"x":3,"y":-40,"z":6},"block_id":70},{"move":{"x":3,"y":-39,"z":0},"block_id":70},{"move":{"x":3,"y":-39,"z":1},"block_id":146},{"move":{"x":3,"y":-39,"z":2},"block_id":9},{"move":{"x":3,"y":-39,"z":3},"block_id":9},{"move":{"x":3,"y":-39,"z":4},"block_id":146},{"move":{"x":3,"y":-39,"z":5},"block_id":146},{"move":{"x":3,"y":-39,"z":6},"block_id":8},{"move":{"x":3,"y":-38,"z":0},"block_id":146},{"move":{"x":3,"y":-38,"z":1},"block_id":70},{"move":{"x":3,"y":-38,"z":2},"block_id":70},{"move":{"x":3,"y":-38,"z":3},"block_id":8},{"move":{"x":3,"y":-38,"z":4},"block_id":70},{"move":{"x":3,"y":-38,"z":5},"block_id":70},{"move":{"x":3,"y":-38,"z":6},"block_id":8},{"move":{"x":3,"y":-37,"z":0},"block_id":146},{"move":{"x":3,"y":-37,"z":1},"block_id":146},{"move":{"x":3,"y":-37,"z":2},"block_id":146},{"move":{"x":3,"y":-37,"z":3},"block_id":146},{"move":{"x":3,"y":-37,"z":4},"block_id":9},{"move":{"x":3,"y":-37,"z":5},"block_id":146},{"move":{"x":3,"y":-37,"z":6},"block_id":70},{"move":{"x":3,"y":-36,"z":0},"block_id":146},{"move":{"x":3,"y":-36,"z":1},"block_id":146},{"move":{"x":3,"y":-36,"z":2},"block_id":146},{"move":{"x":3,"y":-36,"z":3},"block_id":8},{"move":{"x":3,"y":-36,"z":4},"block_id":70},{"move":{"x":3,"y":-36,"z":5},"block_id":8},{"move":{"x":3,"y":-36,"z":6},"block_id":70},{"move":{"x":3,"y":-35,"z":0},"block_id":70},{"move":{"x":3,"y":-35,"z":1},"block_id":146},{"move":{"x":3,"y":-35,"z":2},"block_id":8},{"move":{"x":3,"y":-35,"z":3},"block_id":70},{"move":{"x":3,"y":-35,"z":4},"block_id":146},{"move":{"x":3,"y":-35,"z":5},"block_id":9},{"move":{"x":3,"y":-35,"z":6},"block_id":70},{"move":{"x":3,"y":-34,"z":0},"block_id":8},{"move":{"x":3,"y":-34,"z":1},"block_id":146},{"move":{"x":3,"y":-34,"z":2},"block_id":8},{"move":{"x":3,"y":-34,"z":3},"block_id":9},{"move":{"x":3,"y":-34,"z":4},"block_id":8},{"move":{"x":3,"y":-34,"z":5},"block_id":70},{"move":{"x":3,"y":-34,"z":6},"block_id":9},{"move":{"x":3,"y":-33,"z":0},"block_id":70},{"move":{"x":3,"y":-33,"z":1},"block_id":70},{"move":{"x":3,"y":-33,"z":2},"block_id":70},{"move":{"x":3,"y":-33,"z":3},"block_id":70},{"move":{"x":3,"y":-33,"z":4},"block_id":8},{"move":{"x":3,"y":-33,"z":5},"block_id":146},{"move":{"x":3,"y":-33,"z":6},"block_id":8},{"move":{"x":3,"y":-32,"z":0},"block_id":8},{"move":{"x":3,"y":-32,"z":1},"block_id":8},{"move":{"x":3,"y":-32,"z":2},"block_id":9},{"move":{"x":3,"y":-32,"z":3},"block_id":9},{"move":{"x":3,"y":-32,"z":4},"block_id":8},{"move":{"x":3,"y":-32,"z":5},"block_id":146},{"move":{"x":3,"y":-32,"z":6},"block_id":8},{"move":{"x":3,"y":-31,"z":0},"block_id":8},{"move":{"x":3,"y":-31,"z":1},"block_id":70},{"move":{"x":3,"y":-31,"z":2},"block_id":146},{"move":{"x":3,"y":-31,"z":3},"block_id":70},{"move":{"x":3,"y":-31,"z":4},"block_id":146},{"move":{"x":3,"y":-31,"z":5},"block_id":70},{"move":{"x":3,"y":-31,"z":6},"block_id":8},{"move":{"x":3,"y":-30,"z":0},"block_id":146},{"move":{"x":3,"y":-30,"z":1},"block_id":70},{"move":{"x":3,"y":-30,"z":2},"block_id":9},{"move":{"x":3,"y":-30,"z":3},"block_id":146},{"move":{"x":3,"y":-30,"z":4},"block_id":8},{"move":{"x":3,"y":-30,"z":5},"block_id":8},{"move":{"x":3,"y":-30,"z":6},"block_id":146},{"move":{"x":3,"y":-29,"z":0},"block_id":146},{"move":{"x":3,"y":-29,"z":1},"block_id":146},{"move":{"x":3,"y":-29,"z":2},"block_id":70},{"move":{"x":3,"y":-29,"z":3},"block_id":70},{"move":{"x":3,"y":-29,"z":4},"block_id":8},{"move":{"x":3,"y":-29,"z":5},"block_id":9},{"move":{"x":3,"y":-29,"z":6},"block_id":70},{"move":{"x":3,"y":-28,"z":0},"block_id":8},{"move":{"x":3,"y":-28,"z":1},"block_id":8},{"move":{"x":3,"y":-28,"z":2},"block_id":9},{"move":{"x":3,"y":-28,"z":3},"block_id":9},{"move":{"x":3,"y":-28,"z":4},"block_id":8},{"move":{"x":3,"y":-28,"z":5},"block_id":8},{"move":{"x":3,"y":-28,"z":6},"block_id":9},{"move":{"x":3,"y":-27,"z":0},"block_id":146},{"move":{"x":3,"y":-27,"z":1},"block_id":8},{"move":{"x":3,"y":-27,"z":2},"block_id":8},{"move":{"x":3,"y":-27,"z":3},"block_id":8},{"move":{"x":3,"y":-27,"z":4},"block_id":8},{"move":{"x":3,"y":-27,"z":5},"block_id":146},{"move":{"x":3,"y":-27,"z":6},"block_id":70},{"move":{"x":3,"y":-26,"z":0},"block_id":8},{"move":{"x":3,"y":-26,"z":1},"block_id":8},{"move":{"x":3,"y":-26,"z":2},"block_id":70},{"move":{"x":3,"y":-26,"z":3},"block_id":146},{"move":{"x":3,"y":-26,"z":4},"block_id":9},{"move":{"x":3,"y":-26,"z":5},"block_id":8},{"move":{"x":3,"y":-26,"z":6},"block_id":146},{"move":{"x":3,"y":-25,"z":0},"block_id":8},{"move":{"x":3,"y":-25,"z":1},"block_id":8},{"move":{"x":3,"y":-25,"z":2},"block_id":9},{"move":{"x":3,"y":-25,"z":3},"block_id":9},{"move":{"x":3,"y":-25,"z":4},"block_id":9},{"move":{"x":3,"y":-25,"z":5},"block_id":70},{"move":{"x":3,"y":-25,"z":6},"block_id":146},{"move":{"x":3,"y":-24,"z":0},"block_id":146},{"move":{"x":3,"y":-24,"z":1},"block_id":70},{"move":{"x":3,"y":-24,"z":2},"block_id":8},{"move":{"x":3,"y":-24,"z":3},"block_id":9},{"move":{"x":3,"y":-24,"z":4},"block_id":146},{"move":{"x":3,"y":-24,"z":5},"block_id":9},{"move":{"x":3,"y":-24,"z":6},"block_id":9},{"move":{"x":3,"y":-23,"z":0},"block_id":8},{"move":{"x":3,"y":-23,"z":1},"block_id":9},{"move":{"x":3,"y":-23,"z":2},"block_id":70},{"move":{"x":3,"y":-23,"z":3},"block_id":8},{"move":{"x":3,"y":-23,"z":4},"block_id":70},{"move":{"x":3,"y":-23,"z":5},"block_id":8},{"move":{"x":3,"y":-23,"z":6},"block_id":8},{"move":{"x":3,"y":-22,"z":0},"block_id":9},{"move":{"x":3,"y":-22,"z":1},"block_id":146},{"move":{"x":3,"y":-22,"z":2},"block_id":8},{"move":{"x":3,"y":-22,"z":3},"block_id":9},{"move":{"x":3,"y":-22,"z":4},"block_id":9},{"move":{"x":3,"y":-22,"z":5},"block_id":146},{"move":{"x":3,"y":-22,"z":6},"block_id":146},{"move":{"x":3,"y":-21,"z":0},"block_id":8},{"move":{"x":3,"y":-21,"z":1},"block_id":70},{"move":{"x":3,"y":-21,"z":2},"block_id":8},{"move":{"x":3,"y":-21,"z":3},"block_id":146},{"move":{"x":3,"y":-21,"z":4},"block_id":9},{"move":{"x":3,"y":-21,"z":5},"block_id":8},{"move":{"x":3,"y":-21,"z":6},"block_id":8},{"move":{"x":3,"y":-20,"z":0},"block_id":70},{"move":{"x":3,"y":-20,"z":1},"block_id":70},{"move":{"x":3,"y":-20,"z":2},"block_id":8},{"move":{"x":3,"y":-20,"z":3},"block_id":9},{"move":{"x":3,"y":-20,"z":4},"block_id":9},{"move":{"x":3,"y":-20,"z":5},"block_id":70},{"move":{"x":3,"y":-20,"z":6},"block_id":146},{"move":{"x":3,"y":-19,"z":0},"block_id":146},{"move":{"x":3,"y":-19,"z":1},"block_id":8},{"move":{"x":3,"y":-19,"z":2},"block_id":70},{"move":{"x":3,"y":-19,"z":3},"block_id":146},{"move":{"x":3,"y":-19,"z":4},"block_id":9},{"move":{"x":3,"y":-19,"z":5},"block_id":146},{"move":{"x":3,"y":-19,"z":6},"block_id":9},{"move":{"x":3,"y":-18,"z":0},"block_id":70},{"move":{"x":3,"y":-18,"z":1},"block_id":70},{"move":{"x":3,"y":-18,"z":2},"block_id":8},{"move":{"x":3,"y":-18,"z":3},"block_id":9},{"move":{"x":3,"y":-18,"z":4},"block_id":8},{"move":{"x":3,"y":-18,"z":5},"block_id":8},{"move":{"x":3,"y":-18,"z":6},"block_id":9},{"move":{"x":3,"y":-17,"z":0},"block_id":70},{"move":{"x":3,"y":-17,"z":1},"block_id":146},{"move":{"x":3,"y":-17,"z":2},"block_id":8},{"move":{"x":3,"y":-17,"z":3},"block_id":70},{"move":{"x":3,"y":-17,"z":4},"block_id":70},{"move":{"x":3,"y":-17,"z":5},"block_id":8},{"move":{"x":3,"y":-17,"z":6},"block_id":9},{"move":{"x":3,"y":-16,"z":0},"block_id":9},{"move":{"x":3,"y":-16,"z":1},"block_id":8},{"move":{"x":3,"y":-16,"z":2},"block_id":9},{"move":{"x":3,"y":-16,"z":3},"block_id":146},{"move":{"x":3,"y":-16,"z":4},"block_id":70},{"move":{"x":3,"y":-16,"z":5},"block_id":8},{"move":{"x":3,"y":-16,"z":6},"block_id":70},{"move":{"x":3,"y":-15,"z":0},"block_id":8},{"move":{"x":3,"y":-15,"z":1},"block_id":8},{"move":{"x":3,"y":-15,"z":2},"block_id":70},{"move":{"x":3,"y":-15,"z":3},"block_id":70},{"move":{"x":3,"y":-15,"z":4},"block_id":70},{"move":{"x":3,"y":-15,"z":5},"block_id":70},{"move":{"x":3,"y":-15,"z":6},"block_id":8},{"move":{"x":3,"y":-14,"z":0},"block_id":146},{"move":{"x":3,"y":-14,"z":1},"block_id":146},{"move":{"x":3,"y":-14,"z":2},"block_id":70},{"move":{"x":3,"y":-14,"z":3},"block_id":146},{"move":{"x":3,"y":-14,"z":4},"block_id":8},{"move":{"x":3,"y":-14,"z":5},"block_id":9},{"move":{"x":3,"y":-14,"z":6},"block_id":146},{"move":{"x":3,"y":-13,"z":0},"block_id":8},{"move":{"x":3,"y":-13,"z":1},"block_id":146},{"move":{"x":3,"y":-13,"z":2},"block_id":146},{"move":{"x":3,"y":-13,"z":3},"block_id":9},{"move":{"x":3,"y":-13,"z":4},"block_id":9},{"move":{"x":3,"y":-13,"z":5},"block_id":9},{"move":{"x":3,"y":-13,"z":6},"block_id":9},{"move":{"x":3,"y":-12,"z":0},"block_id":9},{"move":{"x":3,"y":-12,"z":1},"block_id":146},{"move":{"x":3,"y":-12,"z":2},"block_id":70},{"move":{"x":3,"y":-12,"z":3},"block_id":9},{"move":{"x":3,"y":-12,"z":4},"block_id":146},{"move":{"x":3,"y":-12,"z":5},"block_id":9},{"move":{"x":3,"y":-12,"z":6},"block_id":8},{"move":{"x":3,"y":-11,"z":0},"block_id":9},{"move":{"x":3,"y":-11,"z":1},"block_id":8},{"move":{"x":3,"y":-11,"z":2},"block_id":9},{"move":{"x":3,"y":-11,"z":3},"block_id":8},{"move":{"x":3,"y":-11,"z":4},"block_id":8},{"move":{"x":3,"y":-11,"z":5},"block_id":146},{"move":{"x":3,"y":-11,"z":6},"block_id":8},{"move":{"x":3,"y":-10,"z":0},"block_id":8},{"move":{"x":3,"y":-10,"z":1},"block_id":8},{"move":{"x":3,"y":-10,"z":2},"block_id":9},{"move":{"x":3,"y":-10,"z":3},"block_id":70},{"move":{"x":3,"y":-10,"z":4},"block_id":9},{"move":{"x":3,"y":-10,"z":5},"block_id":70},{"move":{"x":3,"y":-10,"z":6},"block_id":70},{"move":{"x":3,"y":-9,"z":0},"block_id":9},{"move":{"x":3,"y":-9,"z":1},"block_id":9},{"move":{"x":3,"y":-9,"z":2},"block_id":70},{"move":{"x":3,"y":-9,"z":3},"block_id":70},{"move":{"x":3,"y":-9,"z":4},"block_id":146},{"move":{"x":3,"y":-9,"z":5},"block_id":146},{"move":{"x":3,"y":-9,"z":6},"block_id":146},{"move":{"x":3,"y":-8,"z":0},"block_id":70},{"move":{"x":3,"y":-8,"z":1},"block_id":146},{"move":{"x":3,"y":-8,"z":2},"block_id":70},{"move":{"x":3,"y":-8,"z":3},"block_id":9},{"move":{"x":3,"y":-8,"z":4},"block_id":8},{"move":{"x":3,"y":-8,"z":5},"block_id":70},{"move":{"x":3,"y":-8,"z":6},"block_id":70},{"move":{"x":3,"y":-7,"z":0},"block_id":70},{"move":{"x":3,"y":-7,"z":1},"block_id":146},{"move":{"x":3,"y":-7,"z":2},"block_id":146},{"move":{"x":3,"y":-7,"z":3},"block_id":8},{"move":{"x":3,"y":-7,"z":4},"block_id":70},{"move":{"x":3,"y":-7,"z":5},"block_id":146},{"move":{"x":3,"y":-7,"z":6},"block_id":70},{"move":{"x":3,"y":-6,"z":0},"block_id":146},{"move":{"x":3,"y":-6,"z":1},"block_id":9},{"move":{"x":3,"y":-6,"z":2},"block_id":146},{"move":{"x":3,"y":-6,"z":3},"block_id":146},{"move":{"x":3,"y":-6,"z":4},"block_id":8},{"move":{"x":3,"y":-6,"z":5},"block_id":8},{"move":{"x":3,"y":-6,"z":6},"block_id":9},{"move":{"x":3,"y":-5,"z":0},"block_id":9},{"move":{"x":3,"y":-5,"z":1},"block_id":146},{"move":{"x":3,"y":-5,"z":2},"block_id":8},{"move":{"x":3,"y":-5,"z":3},"block_id":146},{"move":{"x":3,"y":-5,"z":4},"block_id":146},{"move":{"x":3,"y":-5,"z":5},"block_id":8},{"move":{"x":3,"y":-5,"z":6},"block_id":9},{"move":{"x":3,"y":-4,"z":0},"block_id":146},{"move":{"x":3,"y":-4,"z":1},"block_id":9},{"move":{"x":3,"y":-4,"z":2},"block_id":146},{"move":{"x":3,"y":-4,"z":3},"block_id":146},{"move":{"x":3,"y":-4,"z":4},"block_id":70},{"move":{"x":3,"y":-4,"z":5},"block_id":9},{"move":{"x":3,"y":-4,"z":6},"block_id":70},{"move":{"x":3,"y":-3,"z":0},"block_id":9},{"move":{"x":3,"y":-3,"z":1},"block_id":9},{"move":{"x":3,"y":-3,"z":2},"block_id":8},{"move":{"x":3,"y":-3,"z":3},"block_id":9},{"move":{"x":3,"y":-3,"z":4},"block_id":146},{"move":{"x":3,"y":-3,"z":5},"block_id":70},{"move":{"x":3,"y":-3,"z":6},"block_id":70},{"move":{"x":3,"y":-2,"z":0},"block_id":9},{"move":{"x":3,"y":-2,"z":1},"block_id":70},{"move":{"x":3,"y":-2,"z":2},"block_id":9},{"move":{"x":3,"y":-2,"z":3},"block_id":146},{"move":{"x":3,"y":-2,"z":4},"block_id":70},{"move":{"x":3,"y":-2,"z":5},"block_id":9},{"move":{"x":3,"y":-2,"z":6},"block_id":70},{"move":{"x":3,"y":-1,"z":0},"block_id":9},{"move":{"x":3,"y":-1,"z":1},"block_id":9},{"move":{"x":3,"y":-1,"z":2},"block_id":9},{"move":{"x":3,"y":-1,"z":3},"block_id":9},{"move":{"x":3,"y":-1,"z":4},"block_id":9},{"move":{"x":3,"y":-1,"z":5},"block_id":70},{"move":{"x":3,"y":-1,"z":6},"block_id":70},{"move":{"x":3,"y":0,"z":0},"block_id":8},{"move":{"x":3,"y":0,"z":1},"block_id":146},{"move":{"x":3,"y":0,"z":2},"block_id":8},{"move":{"x":3,"y":0,"z":3},"block_id":70},{"move":{"x":3,"y":0,"z":4},"block_id":9},{"move":{"x":3,"y":0,"z":5},"block_id":9},{"move":{"x":3,"y":0,"z":6},"block_id":146},{"move":{"x":3,"y":1,"z":0},"block_id":70},{"move":{"x":3,"y":1,"z":1},"block_id":9},{"move":{"x":3,"y":1,"z":2},"block_id":146},{"move":{"x":3,"y":1,"z":3},"block_id":70},{"move":{"x":3,"y":1,"z":4},"block_id":70},{"move":{"x":3,"y":1,"z":5},"block_id":70},{"move":{"x":3,"y":1,"z":6},"block_id":9},{"move":{"x":3,"y":2,"z":0},"block_id":146},{"move":{"x":3,"y":2,"z":1},"block_id":9},{"move":{"x":3,"y":2,"z":2},"block_id":9},{"move":{"x":3,"y":2,"z":3},"block_id":8},{"move":{"x":3,"y":2,"z":4},"block_id":70},{"move":{"x":3,"y":2,"z":5},"block_id":9},{"move":{"x":3,"y":2,"z":6},"block_id":70},{"move":{"x":3,"y":3,"z":0},"block_id":8},{"move":{"x":3,"y":3,"z":1},"block_id":9},{"move":{"x":3,"y":3,"z":2},"block_id":8},{"move":{"x":3,"y":3,"z":3},"block_id":8},{"move":{"x":3,"y":3,"z":4},"block_id":8},{"move":{"x":3,"y":3,"z":5},"block_id":9},{"move":{"x":3,"y":3,"z":6},"block_id":70},{"move":{"x":3,"y":4,"z":0},"block_id":9},{"move":{"x":3,"y":4,"z":1},"block_id":8},{"move":{"x":3,"y":4,"z":2},"block_id":8},{"move":{"x":3,"y":4,"z":3},"block_id":8},{"move":{"x":3,"y":4,"z":4},"block_id":9},{"move":{"x":3,"y":4,"z":5},"block_id":146},{"move":{"x":3,"y":4,"z":6},"block_id":9}],"rot":[]}