{"name":"underearth_rooms","world":{"pos1":{"x":-236,"y":-20,"z":55},"pos2":{"x":-283,"y":7,"z":8},"entrance":{"x":-259,"y":1,"z":55}},"meta":{"draw_natural_basement":false,"air_column_from_basement":false},"size":{"x":48,"y":28,"z":48},"door_pos":{"x":23,"y":21,"z":0},"blocks":[{"move":{"x":-23,"y":-19,"z":21},"block_id":9},{"move":{"x":-23,"y":-19,"z":22},"block_id":146},{"move":{"x":-23,"y":-19,"z":23},"block_id":8},{"move":{"x":-23,"y":-19,"z":24},"block_id":9},{"move":{"x":-23,"y":-19,"z":25},"block_id":9},{"move":{"x":-23,"y":-19,"z":26},"block_id":9},{"move":{"x":-23,"y":-19,"z":27},"block_id":9},{"move":{"x":-23,"y":-19,"z":28},"block_id":9},{"move":{"x":-23,"y":-19,"z":29},"block_id":9},{"move":{"x":-23,"y":-19,"z":30},"block_id":9},{"move":{"x":-23,"y":-19,"z":31},"block_id":9},{"move":{"x":-23,"y":-19,"z":32},"block_id":8},{"move":{"x":-23,"y":-19,"z":33},"block_id":9},{"move":{"x":-23,"y":-19,"z":34},"block_id":9},{"move":{"x":-23,"y":-19,"z":35},"block_id":8},{"move":{"x":-23,"y":-19,"z":42},"block_id":9},{"move":{"x":-23,"y":-19,"z":43},"block_id":9},{"move":{"x":-23,"y":-19,"z":44},"block_id":9},{"move":{"x":-23,"y":-19,"z":45},"block_id":8},{"move":{"x":-23,"y":-19,"z":46},"block_id":9},{"move":{"x":-23,"y":-19,"z":47},"block_id":9},{"move":{"x":-23,"y":-18,"z":21},"block_id":9},{"move":{"x":-23,"y":-18,"z":22},"block_id":9},{"move":{"x":-23,"y":-18,"z":23},"block_id":9},{"move":{"x":-23,"y":-18,"z":24},"block_id":9},{"move":{"x":-23,"y":-18,"z":25},"block_id":9},{"move":{"x":-23,"y":-18,"z":26},"block_id":9},{"move":{"x":-23,"y":-18,"z":27},"block_id":8},{"move":{"x":-23,"y":-18,"z":28},"block_id":9},{"move":{"x":-23,"y":-18,"z":29},"block_id":9},{"move":{"x":-23,"y":-18,"z":30},"block_id":9},{"move":{"x":-23,"y":-18,"z":31},"block_id":9},{"move":{"x":-23,"y":-18,"z":32},"block_id":9},{"move":{"x":-23,"y":-18,"z":33},"block_id":9},{"move":{"x":-23,"y":-18,"z":34},"block_id":9},{"move":{"x":-23,"y":-18,"z":35},"block_id":9},{"move":{"x":-23,"y":-18,"z":42},"block_id":9},{"move":{"x":-23,"y":-18,"z":43},"block_id":9},{"move":{"x":-23,"y":-18,"z":44},"block_id":9},{"move":{"x":-23,"y":-18,"z":45},"block_id":9},{"move":{"x":-23,"y":-18,"z":46},"block_id":9},{"move":{"x":-23,"y":-18,"z":47},"block_id":9},{"move":{"x":-23,"y":-17,"z":21},"block_id":9},{"move":{"x":-23,"y":-17,"z":22},"block_id":9},{"move":{"x":-23,"y":-17,"z":23},"block_id":9},{"move":{"x":-23,"y":-17,"z":24},"block_id":8},{"move":{"x":-23,"y":-17,"z":25},"block_id":9},{"move":{"x":-23,"y":-17,"z":26},"block_id":9},{"move":{"x":-23,"y":-17,"z":27},"block_id":9},{"move":{"x":-23,"y":-17,"z":28},"block_id":146},{"move":{"x":-23,"y":-17,"z":29},"block_id":146},{"move":{"x":-23,"y":-17,"z":30},"block_id":8},{"move":{"x":-23,"y":-17,"z":31},"block_id":9},{"move":{"x":-23,"y":-17,"z":32},"block_id":9},{"move":{"x":-23,"y":-17,"z":33},"block_id":9},{"move":{"x":-23,"y":-17,"z":34},"block_id":9},{"move":{"x":-23,"y":-17,"z":35},"block_id":9},{"move":{"x":-23,"y":-17,"z":42},"block_id":9},{"move":{"x":-23,"y":-17,"z":43},"block_id":9},{"move":{"x":-23,"y":-17,"z":44},"block_id":9},{"move":{"x":-23,"y":-17,"z":45},"block_id":8},{"move":{"x":-23,"y":-17,"z":46},"block_id":9},{"move":{"x":-23,"y":-17,"z":47},"block_id":9},{"move":{"x":-23,"y":-16,"z":21},"block_id":9},{"move":{"x":-23,"y":-16,"z":22},"block_id":9},{"move":{"x":-23,"y":-16,"z":23},"block_id":9},{"move":{"x":-23,"y":-16,"z":24},"block_id":9},{"move":{"x":-23,"y":-16,"z":25},"block_id":9},{"move":{"x":-23,"y":-16,"z":26},"block_id":9},{"move":{"x":-23,"y":-16,"z":27},"block_id":9},{"move":{"x":-23,"y":-16,"z":28},"block_id":9},{"move":{"x":-23,"y":-16,"z":29},"block_id":9},{"move":{"x":-23,"y":-16,"z":30},"block_id":9},{"move":{"x":-23,"y":-16,"z":31},"block_id":9},{"move":{"x":-23,"y":-16,"z":32},"block_id":9},{"move":{"x":-23,"y":-16,"z":33},"block_id":9},{"move":{"x":-23,"y":-16,"z":34},"block_id":9},{"move":{"x":-23,"y":-16,"z":35},"block_id":9},{"move":{"x":-23,"y":-16,"z":42},"block_id":9},{"move":{"x":-23,"y":-16,"z":43},"block_id":9},{"move":{"x":-23,"y":-16,"z":44},"block_id":9},{"move":{"x":-23,"y":-16,"z":45},"block_id":9},{"move":{"x":-23,"y":-16,"z":46},"block_id":9},{"move":{"x":-23,"y":-16,"z":47},"block_id":9},{"move":{"x":-22,"y":-19,"z":21},"block_id":9},{"move":{"x":-22,"y":-19,"z":22},"block_id":9},{"move":{"x":-22,"y":-19,"z":23},"block_id":9},{"move":{"x":-22,"y":-19,"z":24},"block_id":9},{"move":{"x":-22,"y":-19,"z":25},"block_id":9},{"move":{"x":-22,"y":-19,"z":26},"block_id":9},{"move":{"x":-22,"y":-19,"z":27},"block_id":9},{"move":{"x":-22,"y":-19,"z":28},"block_id":9},{"move":{"x":-22,"y":-19,"z":29},"block_id":9},{"move":{"x":-22,"y":-19,"z":30},"block_id":9},{"move":{"x":-22,"y":-19,"z":31},"block_id":8},{"move":{"x":-22,"y":-19,"z":32},"block_id":8},{"move":{"x":-22,"y":-19,"z":33},"block_id":9},{"move":{"x":-22,"y":-19,"z":34},"block_id":9},{"move":{"x":-22,"y":-19,"z":35},"block_id":83},{"move":{"x":-22,"y":-19,"z":42},"block_id":9},{"move":{"x":-22,"y":-19,"z":43},"block_id":9},{"move":{"x":-22,"y":-19,"z":44},"block_id":9},{"move":{"x":-22,"y":-19,"z":45},"block_id":8},{"move":{"x":-22,"y":-19,"z":46},"block_id":9},{"move":{"x":-22,"y":-19,"z":47},"block_id":9},{"move":{"x":-22,"y":-18,"z":21},"block_id":9},{"move":{"x":-22,"y":-18,"z":22},"block_id":106,"rotate":{"x":1,"y":0,"z":0}},{"move":{"x":-22,"y":-18,"z":23},"block_id":30},{"move":{"x":-22,"y":-18,"z":25},"block_id":106,"rotate":{"x":1,"y":0,"z":0}},{"move":{"x":-22,"y":-18,"z":27},"block_id":106,"rotate":{"x":3,"y":0,"z":0}},{"move":{"x":-22,"y":-18,"z":28},"block_id":30},{"move":{"x":-22,"y":-18,"z":35},"block_id":9},{"move":{"x":-22,"y":-18,"z":42},"block_id":9},{"move":{"x":-22,"y":-18,"z":43},"block_id":54,"extra_data":{"can_destroy":true,"slots":{}},"rotate":{"x":1,"y":1,"z":0}},{"move":{"x":-22,"y":-18,"z":44},"block_id":9},{"move":{"x":-22,"y":-18,"z":45},"block_id":9},{"move":{"x":-22,"y":-18,"z":47},"block_id":9},{"move":{"x":-22,"y":-17,"z":21},"block_id":9},{"move":{"x":-22,"y":-17,"z":22},"block_id":106,"rotate":{"x":1,"y":0,"z":0}},{"move":{"x":-22,"y":-17,"z":26},"block_id":106,"rotate":{"x":1,"y":0,"z":0}},{"move":{"x":-22,"y":-17,"z":28},"block_id":106,"rotate":{"x":3,"y":0,"z":0}},{"move":{"x":-22,"y":-17,"z":29},"block_id":106,"rotate":{"x":3,"y":0,"z":0}},{"move":{"x":-22,"y":-17,"z":35},"block_id":67,"extra_data":{"point":{"x":0,"y":0.1,"z":0}},"rotate":{"x":3,"y":0,"z":0}},{"move":{"x":-22,"y":-17,"z":42},"block_id":9},{"move":{"x":-22,"y":-17,"z":44},"block_id":9},{"move":{"x":-22,"y":-17,"z":45},"block_id":9},{"move":{"x":-22,"y":-17,"z":46},"block_id":30},{"move":{"x":-22,"y":-17,"z":47},"block_id":9},{"move":{"x":-22,"y":-16,"z":21},"block_id":9},{"move":{"x":-22,"y":-16,"z":22},"block_id":9},{"move":{"x":-22,"y":-16,"z":23},"block_id":9},{"move":{"x":-22,"y":-16,"z":24},"block_id":9},{"move":{"x":-22,"y":-16,"z":25},"block_id":9},{"move":{"x":-22,"y":-16,"z":26},"block_id":9},{"move":{"x":-22,"y":-16,"z":27},"block_id":9},{"move":{"x":-22,"y":-16,"z":28},"block_id":9},{"move":{"x":-22,"y":-16,"z":29},"block_id":9},{"move":{"x":-22,"y":-16,"z":30},"block_id":9},{"move":{"x":-22,"y":-16,"z":31},"block_id":9},{"move":{"x":-22,"y":-16,"z":32},"block_id":9},{"move":{"x":-22,"y":-16,"z":33},"block_id":9},{"move":{"x":-22,"y":-16,"z":34},"block_id":8},{"move":{"x":-22,"y":-16,"z":35},"block_id":9},{"move":{"x":-22,"y":-16,"z":42},"block_id":9},{"move":{"x":-22,"y":-16,"z":43},"block_id":9},{"move":{"x":-22,"y":-16,"z":44},"block_id":9},{"move":{"x":-22,"y":-16,"z":45},"block_id":8},{"move":{"x":-22,"y":-16,"z":46},"block_id":9},{"move":{"x":-22,"y":-16,"z":47},"block_id":9},{"move":{"x":-21,"y":-19,"z":21},"block_id":9},{"move":{"x":-21,"y":-19,"z":22},"block_id":9},{"move":{"x":-21,"y":-19,"z":23},"block_id":9},{"move":{"x":-21,"y":-19,"z":24},"block_id":9},{"move":{"x":-21,"y":-19,"z":25},"block_id":9},{"move":{"x":-21,"y":-19,"z":26},"block_id":9},{"move":{"x":-21,"y":-19,"z":27},"block_id":9},{"move":{"x":-21,"y":-19,"z":28},"block_id":9},{"move":{"x":-21,"y":-19,"z":29},"block_id":9},{"move":{"x":-21,"y":-19,"z":30},"block_id":9},{"move":{"x":-21,"y":-19,"z":31},"block_id":9},{"move":{"x":-21,"y":-19,"z":32},"block_id":9},{"move":{"x":-21,"y":-19,"z":33},"block_id":9},{"move":{"x":-21,"y":-19,"z":34},"block_id":9},{"move":{"x":-21,"y":-19,"z":35},"block_id":9},{"move":{"x":-21,"y":-19,"z":42},"block_id":9},{"move":{"x":-21,"y":-19,"z":43},"block_id":9},{"move":{"x":-21,"y":-19,"z":44},"block_id":9},{"move":{"x":-21,"y":-19,"z":45},"block_id":9},{"move":{"x":-21,"y":-19,"z":46},"block_id":9},{"move":{"x":-21,"y":-19,"z":47},"block_id":9},{"move":{"x":-21,"y":-18,"z":21},"block_id":67,"extra_data":{"point":{"x":0,"y":0.1,"z":0}},"rotate":{"x":0,"y":0,"z":0}},{"move":{"x":-21,"y":-18,"z":22},"block_id":9},{"move":{"x":-21,"y":-18,"z":23},"block_id":9},{"move":{"x":-21,"y":-18,"z":24},"block_id":9},{"move":{"x":-21,"y":-18,"z":26},"block_id":9},{"move":{"x":-21,"y":-18,"z":27},"block_id":9},{"move":{"x":-21,"y":-18,"z":28},"block_id":9},{"move":{"x":-21,"y":-18,"z":29},"block_id":9},{"move":{"x":-21,"y":-18,"z":30},"block_id":9},{"move":{"x":-21,"y":-18,"z":31},"block_id":9},{"move":{"x":-21,"y":-18,"z":32},"block_id":9},{"move":{"x":-21,"y":-18,"z":33},"block_id":9},{"move":{"x":-21,"y":-18,"z":35},"block_id":9},{"move":{"x":-21,"y":-18,"z":42},"block_id":9},{"move":{"x":-21,"y":-18,"z":44},"block_id":9},{"move":{"x":-21,"y":-18,"z":45},"block_id":9},{"move":{"x":-21,"y":-18,"z":47},"block_id":9},{"move":{"x":-21,"y":-17,"z":21},"block_id":9},{"move":{"x":-21,"y":-17,"z":22},"block_id":9},{"move":{"x":-21,"y":-17,"z":23},"block_id":9},{"move":{"x":-21,"y":-17,"z":24},"block_id":9},{"move":{"x":-21,"y":-17,"z":26},"block_id":9},{"move":{"x":-21,"y":-17,"z":27},"block_id":9},{"move":{"x":-21,"y":-17,"z":28},"block_id":9},{"move":{"x":-21,"y":-17,"z":29},"block_id":9},{"move":{"x":-21,"y":-17,"z":30},"block_id":9},{"move":{"x":-21,"y":-17,"z":31},"block_id":9},{"move":{"x":-21,"y":-17,"z":32},"block_id":8},{"move":{"x":-21,"y":-17,"z":33},"block_id":8},{"move":{"x":-21,"y":-17,"z":34},"block_id":106,"rotate":{"x":2,"y":0,"z":0}},{"move":{"x":-21,"y":-17,"z":35},"block_id":9},{"move":{"x":-21,"y":-17,"z":42},"block_id":9},{"move":{"x":-21,"y":-17,"z":44},"block_id":9},{"move":{"x":-21,"y":-17,"z":45},"block_id":9},{"move":{"x":-21,"y":-17,"z":47},"block_id":9},{"move":{"x":-21,"y":-16,"z":21},"block_id":9},{"move":{"x":-21,"y":-16,"z":22},"block_id":9},{"move":{"x":-21,"y":-16,"z":23},"block_id":9},{"move":{"x":-21,"y":-16,"z":24},"block_id":9},{"move":{"x":-21,"y":-16,"z":25},"block_id":9},{"move":{"x":-21,"y":-16,"z":26},"block_id":9},{"move":{"x":-21,"y":-16,"z":27},"block_id":9},{"move":{"x":-21,"y":-16,"z":28},"block_id":9},{"move":{"x":-21,"y":-16,"z":29},"block_id":9},{"move":{"x":-21,"y":-16,"z":30},"block_id":146},{"move":{"x":-21,"y":-16,"z":31},"block_id":9},{"move":{"x":-21,"y":-16,"z":32},"block_id":146},{"move":{"x":-21,"y":-16,"z":33},"block_id":9},{"move":{"x":-21,"y":-16,"z":34},"block_id":9},{"move":{"x":-21,"y":-16,"z":35},"block_id":9},{"move":{"x":-21,"y":-16,"z":42},"block_id":9},{"move":{"x":-21,"y":-16,"z":43},"block_id":9},{"move":{"x":-21,"y":-16,"z":44},"block_id":9},{"move":{"x":-21,"y":-16,"z":45},"block_id":9},{"move":{"x":-21,"y":-16,"z":46},"block_id":67,"extra_data":{"point":{"x":0,"y":0.9,"z":0}},"rotate":{"x":2,"y":0,"z":0}},{"move":{"x":-21,"y":-16,"z":47},"block_id":9},{"move":{"x":-20,"y":-19,"z":18},"block_id":9},{"move":{"x":-20,"y":-19,"z":19},"block_id":9},{"move":{"x":-20,"y":-19,"z":20},"block_id":9},{"move":{"x":-20,"y":-19,"z":21},"block_id":9},{"move":{"x":-20,"y":-19,"z":22},"block_id":9},{"move":{"x":-20,"y":-19,"z":23},"block_id":9},{"move":{"x":-20,"y":-19,"z":24},"block_id":9},{"move":{"x":-20,"y":-19,"z":25},"block_id":9},{"move":{"x":-20,"y":-19,"z":26},"block_id":8},{"move":{"x":-20,"y":-19,"z":27},"block_id":146},{"move":{"x":-20,"y":-19,"z":28},"block_id":8},{"move":{"x":-20,"y":-19,"z":29},"block_id":9},{"move":{"x":-20,"y":-19,"z":30},"block_id":9},{"move":{"x":-20,"y":-19,"z":31},"block_id":9},{"move":{"x":-20,"y":-19,"z":32},"block_id":9},{"move":{"x":-20,"y":-19,"z":33},"block_id":9},{"move":{"x":-20,"y":-19,"z":34},"block_id":9},{"move":{"x":-20,"y":-19,"z":35},"block_id":9},{"move":{"x":-20,"y":-19,"z":36},"block_id":9},{"move":{"x":-20,"y":-19,"z":37},"block_id":9},{"move":{"x":-20,"y":-19,"z":38},"block_id":9},{"move":{"x":-20,"y":-19,"z":39},"block_id":9},{"move":{"x":-20,"y":-19,"z":40},"block_id":9},{"move":{"x":-20,"y":-19,"z":41},"block_id":9},{"move":{"x":-20,"y":-19,"z":42},"block_id":9},{"move":{"x":-20,"y":-19,"z":43},"block_id":9},{"move":{"x":-20,"y":-19,"z":44},"block_id":9},{"move":{"x":-20,"y":-19,"z":45},"block_id":146},{"move":{"x":-20,"y":-19,"z":46},"block_id":9},{"move":{"x":-20,"y":-19,"z":47},"block_id":9},{"move":{"x":-20,"y":-18,"z":18},"block_id":9},{"move":{"x":-20,"y":-18,"z":19},"block_id":9},{"move":{"x":-20,"y":-18,"z":20},"block_id":9},{"move":{"x":-20,"y":-18,"z":21},"block_id":9},{"move":{"x":-20,"y":-18,"z":22},"block_id":9},{"move":{"x":-20,"y":-18,"z":23},"block_id":9},{"move":{"x":-20,"y":-18,"z":24},"block_id":9},{"move":{"x":-20,"y":-18,"z":25},"block_id":106,"rotate":{"x":2,"y":0,"z":0}},{"move":{"x":-20,"y":-18,"z":26},"block_id":9},{"move":{"x":-20,"y":-18,"z":27},"block_id":9},{"move":{"x":-20,"y":-18,"z":28},"block_id":9},{"move":{"x":-20,"y":-18,"z":29},"block_id":9},{"move":{"x":-20,"y":-18,"z":30},"block_id":9},{"move":{"x":-20,"y":-18,"z":31},"block_id":9},{"move":{"x":-20,"y":-18,"z":32},"block_id":9},{"move":{"x":-20,"y":-18,"z":33},"block_id":9},{"move":{"x":-20,"y":-18,"z":35},"block_id":9},{"move":{"x":-20,"y":-18,"z":36},"block_id":9},{"move":{"x":-20,"y":-18,"z":37},"block_id":9},{"move":{"x":-20,"y":-18,"z":38},"block_id":9},{"move":{"x":-20,"y":-18,"z":39},"block_id":9},{"move":{"x":-20,"y":-18,"z":40},"block_id":9},{"move":{"x":-20,"y":-18,"z":41},"block_id":9},{"move":{"x":-20,"y":-18,"z":42},"block_id":146},{"move":{"x":-20,"y":-18,"z":43},"block_id":106,"rotate":{"x":0,"y":0,"z":0}},{"move":{"x":-20,"y":-18,"z":44},"block_id":9},{"move":{"x":-20,"y":-18,"z":45},"block_id":9},{"move":{"x":-20,"y":-18,"z":47},"block_id":9},{"move":{"x":-20,"y":-17,"z":18},"block_id":9},{"move":{"x":-20,"y":-17,"z":19},"block_id":9},{"move":{"x":-20,"y":-17,"z":20},"block_id":9},{"move":{"x":-20,"y":-17,"z":21},"block_id":9},{"move":{"x":-20,"y":-17,"z":22},"block_id":9},{"move":{"x":-20,"y":-17,"z":23},"block_id":9},{"move":{"x":-20,"y":-17,"z":24},"block_id":9},{"move":{"x":-20,"y":-17,"z":25},"block_id":106,"rotate":{"x":2,"y":0,"z":0}},{"move":{"x":-20,"y":-17,"z":26},"block_id":9},{"move":{"x":-20,"y":-17,"z":27},"block_id":9},{"move":{"x":-20,"y":-17,"z":28},"block_id":9},{"move":{"x":-20,"y":-17,"z":29},"block_id":9},{"move":{"x":-20,"y":-17,"z":30},"block_id":9},{"move":{"x":-20,"y":-17,"z":31},"block_id":9},{"move":{"x":-20,"y":-17,"z":32},"block_id":9},{"move":{"x":-20,"y":-17,"z":33},"block_id":9},{"move":{"x":-20,"y":-17,"z":34},"block_id":30},{"move":{"x":-20,"y":-17,"z":35},"block_id":9},{"move":{"x":-20,"y":-17,"z":36},"block_id":9},{"move":{"x":-20,"y":-17,"z":37},"block_id":9},{"move":{"x":-20,"y":-17,"z":38},"block_id":9},{"move":{"x":-20,"y":-17,"z":39},"block_id":9},{"move":{"x":-20,"y":-17,"z":40},"block_id":9},{"move":{"x":-20,"y":-17,"z":41},"block_id":9},{"move":{"x":-20,"y":-17,"z":42},"block_id":9},{"move":{"x":-20,"y":-17,"z":43},"block_id":106,"rotate":{"x":0,"y":0,"z":0}},{"move":{"x":-20,"y":-17,"z":44},"block_id":9},{"move":{"x":-20,"y":-17,"z":45},"block_id":9},{"move":{"x":-20,"y":-17,"z":46},"block_id":106,"rotate":{"x":0,"y":0,"z":0}},{"move":{"x":-20,"y":-17,"z":47},"block_id":9},{"move":{"x":-20,"y":-16,"z":18},"block_id":9},{"move":{"x":-20,"y":-16,"z":19},"block_id":9},{"move":{"x":-20,"y":-16,"z":20},"block_id":9},{"move":{"x":-20,"y":-16,"z":21},"block_id":9},{"move":{"x":-20,"y":-16,"z":22},"block_id":9},{"move":{"x":-20,"y":-16,"z":23},"block_id":9},{"move":{"x":-20,"y":-16,"z":24},"block_id":8},{"move":{"x":-20,"y":-16,"z":25},"block_id":9},{"move":{"x":-20,"y":-16,"z":26},"block_id":9},{"move":{"x":-20,"y":-16,"z":27},"block_id":8},{"move":{"x":-20,"y":-16,"z":28},"block_id":9},{"move":{"x":-20,"y":-16,"z":29},"block_id":146},{"move":{"x":-20,"y":-16,"z":30},"block_id":9},{"move":{"x":-20,"y":-16,"z":31},"block_id":9},{"move":{"x":-20,"y":-16,"z":32},"block_id":9},{"move":{"x":-20,"y":-16,"z":33},"block_id":9},{"move":{"x":-20,"y":-16,"z":34},"block_id":9},{"move":{"x":-20,"y":-16,"z":35},"block_id":9},{"move":{"x":-20,"y":-16,"z":36},"block_id":9},{"move":{"x":-20,"y":-16,"z":37},"block_id":9},{"move":{"x":-20,"y":-16,"z":38},"block_id":9},{"move":{"x":-20,"y":-16,"z":39},"block_id":9},{"move":{"x":-20,"y":-16,"z":40},"block_id":9},{"move":{"x":-20,"y":-16,"z":41},"block_id":9},{"move":{"x":-20,"y":-16,"z":42},"block_id":9},{"move":{"x":-20,"y":-16,"z":43},"block_id":8},{"move":{"x":-20,"y":-16,"z":44},"block_id":9},{"move":{"x":-20,"y":-16,"z":45},"block_id":9},{"move":{"x":-20,"y":-16,"z":46},"block_id":146},{"move":{"x":-20,"y":-16,"z":47},"block_id":9},{"move":{"x":-19,"y":-20,"z":35},"block_id":9},{"move":{"x":-19,"y":-20,"z":36},"block_id":9},{"move":{"x":-19,"y":-20,"z":37},"block_id":9},{"move":{"x":-19,"y":-20,"z":40},"block_id":9},{"move":{"x":-19,"y":-19,"z":18},"block_id":9},{"move":{"x":-19,"y":-19,"z":19},"block_id":9},{"move":{"x":-19,"y":-19,"z":20},"block_id":9},{"move":{"x":-19,"y":-19,"z":21},"block_id":9},{"move":{"x":-19,"y":-19,"z":22},"block_id":9},{"move":{"x":-19,"y":-19,"z":23},"block_id":9},{"move":{"x":-19,"y":-19,"z":24},"block_id":9},{"move":{"x":-19,"y":-19,"z":25},"block_id":9},{"move":{"x":-19,"y":-19,"z":26},"block_id":9},{"move":{"x":-19,"y":-19,"z":27},"block_id":9},{"move":{"x":-19,"y":-19,"z":28},"block_id":146},{"move":{"x":-19,"y":-19,"z":29},"block_id":9},{"move":{"x":-19,"y":-19,"z":30},"block_id":9},{"move":{"x":-19,"y":-19,"z":31},"block_id":9},{"move":{"x":-19,"y":-19,"z":32},"block_id":9},{"move":{"x":-19,"y":-19,"z":33},"block_id":9},{"move":{"x":-19,"y":-19,"z":34},"block_id":9},{"move":{"x":-19,"y":-19,"z":37},"block_id":83},{"move":{"x":-19,"y":-19,"z":38},"block_id":98},{"move":{"x":-19,"y":-19,"z":39},"block_id":632},{"move":{"x":-19,"y":-19,"z":40},"block_id":199,"extra_data":{"n":"SPAWNER"}},{"move":{"x":-19,"y":-19,"z":41},"block_id":9},{"move":{"x":-19,"y":-19,"z":42},"block_id":9},{"move":{"x":-19,"y":-19,"z":43},"block_id":8},{"move":{"x":-19,"y":-19,"z":44},"block_id":9},{"move":{"x":-19,"y":-19,"z":45},"block_id":9},{"move":{"x":-19,"y":-19,"z":46},"block_id":9},{"move":{"x":-19,"y":-19,"z":47},"block_id":9},{"move":{"x":-19,"y":-18,"z":18},"block_id":9},{"move":{"x":-19,"y":-18,"z":19},"block_id":54,"extra_data":{"can_destroy":true,"slots":{}},"rotate":{"x":1,"y":1,"z":0}},{"move":{"x":-19,"y":-18,"z":20},"block_id":9},{"move":{"x":-19,"y":-18,"z":21},"block_id":9},{"move":{"x":-19,"y":-18,"z":22},"block_id":54,"extra_data":{"can_destroy":true,"slots":{}},"rotate":{"x":1,"y":1,"z":0}},{"move":{"x":-19,"y":-18,"z":23},"block_id":9},{"move":{"x":-19,"y":-18,"z":24},"block_id":9},{"move":{"x":-19,"y":-18,"z":25},"block_id":106,"rotate":{"x":2,"y":0,"z":0}},{"move":{"x":-19,"y":-18,"z":28},"block_id":106,"rotate":{"x":1,"y":0,"z":0}},{"move":{"x":-19,"y":-18,"z":31},"block_id":106,"rotate":{"x":3,"y":0,"z":0}},{"move":{"x":-19,"y":-18,"z":32},"block_id":9},{"move":{"x":-19,"y":-18,"z":33},"block_id":9},{"move":{"x":-19,"y":-18,"z":37},"block_id":83},{"move":{"x":-19,"y":-18,"z":39},"block_id":98},{"move":{"x":-19,"y":-18,"z":40},"block_id":106,"rotate":{"x":1,"y":0,"z":0}},{"move":{"x":-19,"y":-18,"z":41},"block_id":9},{"move":{"x":-19,"y":-18,"z":42},"block_id":9},{"move":{"x":-19,"y":-18,"z":45},"block_id":30},{"move":{"x":-19,"y":-18,"z":46},"block_id":106,"rotate":{"x":0,"y":0,"z":0}},{"move":{"x":-19,"y":-18,"z":47},"block_id":9},{"move":{"x":-19,"y":-17,"z":18},"block_id":9},{"move":{"x":-19,"y":-17,"z":19},"block_id":106,"extra_data":{"west":true,"rotate":false}},{"move":{"x":-19,"y":-17,"z":20},"block_id":9},{"move":{"x":-19,"y":-17,"z":21},"block_id":9},{"move":{"x":-19,"y":-17,"z":22},"block_id":106,"extra_data":{"west":true,"rotate":false}},{"move":{"x":-19,"y":-17,"z":23},"block_id":9},{"move":{"x":-19,"y":-17,"z":24},"block_id":9},{"move":{"x":-19,"y":-17,"z":25},"block_id":106,"rotate":{"x":2,"y":0,"z":0}},{"move":{"x":-19,"y":-17,"z":26},"block_id":106,"rotate":{"x":1,"y":0,"z":0}},{"move":{"x":-19,"y":-17,"z":28},"block_id":106,"rotate":{"x":1,"y":0,"z":0}},{"move":{"x":-19,"y":-17,"z":30},"block_id":30},{"move":{"x":-19,"y":-17,"z":31},"block_id":106,"rotate":{"x":3,"y":0,"z":0}},{"move":{"x":-19,"y":-17,"z":32},"block_id":9},{"move":{"x":-19,"y":-17,"z":33},"block_id":9},{"move":{"x":-19,"y":-17,"z":37},"block_id":615,"extra_data":{"point":{"x":0,"y":0.1,"z":0}},"rotate":{"x":3,"y":0,"z":0}},{"move":{"x":-19,"y":-17,"z":39},"block_id":98},{"move":{"x":-19,"y":-17,"z":40},"block_id":106,"rotate":{"x":1,"y":0,"z":0}},{"move":{"x":-19,"y":-17,"z":41},"block_id":9},{"move":{"x":-19,"y":-17,"z":42},"block_id":9},{"move":{"x":-19,"y":-17,"z":46},"block_id":106,"rotate":{"x":0,"y":0,"z":0}},{"move":{"x":-19,"y":-17,"z":47},"block_id":9},{"move":{"x":-19,"y":-16,"z":18},"block_id":9},{"move":{"x":-19,"y":-16,"z":19},"block_id":9},{"move":{"x":-19,"y":-16,"z":20},"block_id":9},{"move":{"x":-19,"y":-16,"z":21},"block_id":9},{"move":{"x":-19,"y":-16,"z":22},"block_id":9},{"move":{"x":-19,"y":-16,"z":23},"block_id":9},{"move":{"x":-19,"y":-16,"z":24},"block_id":9},{"move":{"x":-19,"y":-16,"z":25},"block_id":9},{"move":{"x":-19,"y":-16,"z":26},"block_id":9},{"move":{"x":-19,"y":-16,"z":27},"block_id":9},{"move":{"x":-19,"y":-16,"z":28},"block_id":9},{"move":{"x":-19,"y":-16,"z":29},"block_id":9},{"move":{"x":-19,"y":-16,"z":30},"block_id":9},{"move":{"x":-19,"y":-16,"z":31},"block_id":9},{"move":{"x":-19,"y":-16,"z":32},"block_id":9},{"move":{"x":-19,"y":-16,"z":33},"block_id":9},{"move":{"x":-19,"y":-16,"z":37},"block_id":83},{"move":{"x":-19,"y":-16,"z":38},"block_id":9},{"move":{"x":-19,"y":-16,"z":39},"block_id":9},{"move":{"x":-19,"y":-16,"z":40},"block_id":9},{"move":{"x":-19,"y":-16,"z":41},"block_id":9},{"move":{"x":-19,"y":-16,"z":42},"block_id":9},{"move":{"x":-19,"y":-16,"z":43},"block_id":9},{"move":{"x":-19,"y":-16,"z":44},"block_id":9},{"move":{"x":-19,"y":-16,"z":45},"block_id":9},{"move":{"x":-19,"y":-16,"z":46},"block_id":146},{"move":{"x":-19,"y":-16,"z":47},"block_id":146},{"move":{"x":-19,"y":-15,"z":34},"block_id":9},{"move":{"x":-19,"y":-15,"z":35},"block_id":9},{"move":{"x":-19,"y":-15,"z":36},"block_id":9},{"move":{"x":-18,"y":-20,"z":35},"block_id":9},{"move":{"x":-18,"y":-20,"z":36},"block_id":9},{"move":{"x":-18,"y":-20,"z":37},"block_id":9},{"move":{"x":-18,"y":-20,"z":40},"block_id":9},{"move":{"x":-18,"y":-19,"z":18},"block_id":9},{"move":{"x":-18,"y":-19,"z":19},"block_id":9},{"move":{"x":-18,"y":-19,"z":20},"block_id":9},{"move":{"x":-18,"y":-19,"z":21},"block_id":9},{"move":{"x":-18,"y":-19,"z":22},"block_id":9},{"move":{"x":-18,"y":-19,"z":23},"block_id":9},{"move":{"x":-18,"y":-19,"z":24},"block_id":146},{"move":{"x":-18,"y":-19,"z":25},"block_id":9},{"move":{"x":-18,"y":-19,"z":26},"block_id":9},{"move":{"x":-18,"y":-19,"z":27},"block_id":9},{"move":{"x":-18,"y":-19,"z":28},"block_id":8},{"move":{"x":-18,"y":-19,"z":29},"block_id":9},{"move":{"x":-18,"y":-19,"z":30},"block_id":9},{"move":{"x":-18,"y":-19,"z":31},"block_id":9},{"move":{"x":-18,"y":-19,"z":32},"block_id":9},{"move":{"x":-18,"y":-19,"z":33},"block_id":9},{"move":{"x":-18,"y":-19,"z":34},"block_id":9},{"move":{"x":-18,"y":-19,"z":37},"block_id":98},{"move":{"x":-18,"y":-19,"z":38},"block_id":615,"extra_data":{"point":{"x":0,"y":0.9,"z":0}},"rotate":{"x":3,"y":0,"z":0}},{"move":{"x":-18,"y":-19,"z":39},"block_id":632},{"move":{"x":-18,"y":-19,"z":40},"block_id":615,"extra_data":{"point":{"x":0,"y":0.1,"z":0}},"rotate":{"x":0,"y":0,"z":0}},{"move":{"x":-18,"y":-19,"z":41},"block_id":9},{"move":{"x":-18,"y":-19,"z":42},"block_id":9},{"move":{"x":-18,"y":-19,"z":43},"block_id":9},{"move":{"x":-18,"y":-19,"z":44},"block_id":9},{"move":{"x":-18,"y":-19,"z":45},"block_id":9},{"move":{"x":-18,"y":-19,"z":46},"block_id":9},{"move":{"x":-18,"y":-19,"z":47},"block_id":9},{"move":{"x":-18,"y":-18,"z":18},"block_id":9},{"move":{"x":-18,"y":-18,"z":20},"block_id":9},{"move":{"x":-18,"y":-18,"z":21},"block_id":9},{"move":{"x":-18,"y":-18,"z":23},"block_id":9},{"move":{"x":-18,"y":-18,"z":24},"block_id":9},{"move":{"x":-18,"y":-18,"z":25},"block_id":9},{"move":{"x":-18,"y":-18,"z":26},"block_id":9},{"move":{"x":-18,"y":-18,"z":27},"block_id":146},{"move":{"x":-18,"y":-18,"z":28},"block_id":106,"rotate":{"x":2,"y":0,"z":0}},{"move":{"x":-18,"y":-18,"z":29},"block_id":9},{"move":{"x":-18,"y":-18,"z":30},"block_id":9},{"move":{"x":-18,"y":-18,"z":31},"block_id":9},{"move":{"x":-18,"y":-18,"z":32},"block_id":9},{"move":{"x":-18,"y":-18,"z":33},"block_id":9},{"move":{"x":-18,"y":-18,"z":37},"block_id":98},{"move":{"x":-18,"y":-18,"z":39},"block_id":83},{"move":{"x":-18,"y":-18,"z":41},"block_id":9},{"move":{"x":-18,"y":-18,"z":42},"block_id":9},{"move":{"x":-18,"y":-18,"z":43},"block_id":9},{"move":{"x":-18,"y":-18,"z":44},"block_id":8},{"move":{"x":-18,"y":-18,"z":45},"block_id":9},{"move":{"x":-18,"y":-18,"z":47},"block_id":9},{"move":{"x":-18,"y":-17,"z":18},"block_id":9},{"move":{"x":-18,"y":-17,"z":20},"block_id":9},{"move":{"x":-18,"y":-17,"z":21},"block_id":9},{"move":{"x":-18,"y":-17,"z":23},"block_id":9},{"move":{"x":-18,"y":-17,"z":24},"block_id":146},{"move":{"x":-18,"y":-17,"z":25},"block_id":9},{"move":{"x":-18,"y":-17,"z":26},"block_id":83},{"move":{"x":-18,"y":-17,"z":27},"block_id":9},{"move":{"x":-18,"y":-17,"z":29},"block_id":9},{"move":{"x":-18,"y":-17,"z":30},"block_id":9},{"move":{"x":-18,"y":-17,"z":31},"block_id":9},{"move":{"x":-18,"y":-17,"z":32},"block_id":9},{"move":{"x":-18,"y":-17,"z":33},"block_id":9},{"move":{"x":-18,"y":-17,"z":39},"block_id":632},{"move":{"x":-18,"y":-17,"z":40},"block_id":30},{"move":{"x":-18,"y":-17,"z":41},"block_id":9},{"move":{"x":-18,"y":-17,"z":42},"block_id":9},{"move":{"x":-18,"y":-17,"z":43},"block_id":9},{"move":{"x":-18,"y":-17,"z":44},"block_id":9},{"move":{"x":-18,"y":-17,"z":45},"block_id":9},{"move":{"x":-18,"y":-17,"z":47},"block_id":8},{"move":{"x":-18,"y":-16,"z":18},"block_id":9},{"move":{"x":-18,"y":-16,"z":19},"block_id":9},{"move":{"x":-18,"y":-16,"z":20},"block_id":9},{"move":{"x":-18,"y":-16,"z":21},"block_id":9},{"move":{"x":-18,"y":-16,"z":22},"block_id":9},{"move":{"x":-18,"y":-16,"z":23},"block_id":9},{"move":{"x":-18,"y":-16,"z":24},"block_id":9},{"move":{"x":-18,"y":-16,"z":25},"block_id":9},{"move":{"x":-18,"y":-16,"z":26},"block_id":146},{"move":{"x":-18,"y":-16,"z":27},"block_id":9},{"move":{"x":-18,"y":-16,"z":28},"block_id":9},{"move":{"x":-18,"y":-16,"z":29},"block_id":9},{"move":{"x":-18,"y":-16,"z":30},"block_id":9},{"move":{"x":-18,"y":-16,"z":31},"block_id":9},{"move":{"x":-18,"y":-16,"z":32},"block_id":9},{"move":{"x":-18,"y":-16,"z":33},"block_id":9},{"move":{"x":-18,"y":-16,"z":37},"block_id":615,"extra_data":{"point":{"x":0,"y":0.1,"z":0}},"rotate":{"x":0,"y":0,"z":0}},{"move":{"x":-18,"y":-16,"z":38},"block_id":9},{"move":{"x":-18,"y":-16,"z":39},"block_id":9},{"move":{"x":-18,"y":-16,"z":40},"block_id":9},{"move":{"x":-18,"y":-16,"z":41},"block_id":9},{"move":{"x":-18,"y":-16,"z":42},"block_id":9},{"move":{"x":-18,"y":-16,"z":43},"block_id":9},{"move":{"x":-18,"y":-16,"z":44},"block_id":9},{"move":{"x":-18,"y":-16,"z":45},"block_id":9},{"move":{"x":-18,"y":-16,"z":46},"block_id":9},{"move":{"x":-18,"y":-16,"z":47},"block_id":9},{"move":{"x":-18,"y":-15,"z":34},"block_id":9},{"move":{"x":-18,"y":-15,"z":35},"block_id":9},{"move":{"x":-18,"y":-15,"z":36},"block_id":9},{"move":{"x":-17,"y":-20,"z":35},"block_id":9},{"move":{"x":-17,"y":-20,"z":36},"block_id":9},{"move":{"x":-17,"y":-20,"z":37},"block_id":9},{"move":{"x":-17,"y":-20,"z":40},"block_id":9},{"move":{"x":-17,"y":-19,"z":5},"block_id":9},{"move":{"x":-17,"y":-19,"z":6},"block_id":9},{"move":{"x":-17,"y":-19,"z":7},"block_id":146},{"move":{"x":-17,"y":-19,"z":8},"block_id":9},{"move":{"x":-17,"y":-19,"z":9},"block_id":146},{"move":{"x":-17,"y":-19,"z":18},"block_id":9},{"move":{"x":-17,"y":-19,"z":19},"block_id":9},{"move":{"x":-17,"y":-19,"z":20},"block_id":9},{"move":{"x":-17,"y":-19,"z":21},"block_id":9},{"move":{"x":-17,"y":-19,"z":22},"block_id":632},{"move":{"x":-17,"y":-19,"z":23},"block_id":9},{"move":{"x":-17,"y":-19,"z":24},"block_id":9},{"move":{"x":-17,"y":-19,"z":25},"block_id":9},{"move":{"x":-17,"y":-19,"z":26},"block_id":9},{"move":{"x":-17,"y":-19,"z":27},"block_id":9},{"move":{"x":-17,"y":-19,"z":28},"block_id":9},{"move":{"x":-17,"y":-19,"z":29},"block_id":9},{"move":{"x":-17,"y":-19,"z":30},"block_id":9},{"move":{"x":-17,"y":-19,"z":31},"block_id":9},{"move":{"x":-17,"y":-19,"z":32},"block_id":9},{"move":{"x":-17,"y":-19,"z":33},"block_id":9},{"move":{"x":-17,"y":-19,"z":34},"block_id":9},{"move":{"x":-17,"y":-19,"z":37},"block_id":98},{"move":{"x":-17,"y":-19,"z":38},"block_id":83},{"move":{"x":-17,"y":-19,"z":39},"block_id":83},{"move":{"x":-17,"y":-19,"z":40},"block_id":98},{"move":{"x":-17,"y":-19,"z":41},"block_id":9},{"move":{"x":-17,"y":-19,"z":45},"block_id":146},{"move":{"x":-17,"y":-19,"z":46},"block_id":9},{"move":{"x":-17,"y":-19,"z":47},"block_id":9},{"move":{"x":-17,"y":-18,"z":5},"block_id":9},{"move":{"x":-17,"y":-18,"z":6},"block_id":9},{"move":{"x":-17,"y":-18,"z":7},"block_id":9},{"move":{"x":-17,"y":-18,"z":8},"block_id":8},{"move":{"x":-17,"y":-18,"z":9},"block_id":9},{"move":{"x":-17,"y":-18,"z":18},"block_id":9},{"move":{"x":-17,"y":-18,"z":20},"block_id":9},{"move":{"x":-17,"y":-18,"z":21},"block_id":9},{"move":{"x":-17,"y":-18,"z":23},"block_id":9},{"move":{"x":-17,"y":-18,"z":24},"block_id":9},{"move":{"x":-17,"y":-18,"z":25},"block_id":9},{"move":{"x":-17,"y":-18,"z":26},"block_id":9},{"move":{"x":-17,"y":-18,"z":27},"block_id":9},{"move":{"x":-17,"y":-18,"z":29},"block_id":9},{"move":{"x":-17,"y":-18,"z":30},"block_id":9},{"move":{"x":-17,"y":-18,"z":31},"block_id":9},{"move":{"x":-17,"y":-18,"z":32},"block_id":9},{"move":{"x":-17,"y":-18,"z":33},"block_id":9},{"move":{"x":-17,"y":-18,"z":37},"block_id":98},{"move":{"x":-17,"y":-18,"z":39},"block_id":615,"extra_data":{"point":{"x":0,"y":0.1,"z":0}},"rotate":{"x":0,"y":0,"z":0}},{"move":{"x":-17,"y":-18,"z":40},"block_id":106,"rotate":{"x":0,"y":0,"z":0}},{"move":{"x":-17,"y":-18,"z":41},"block_id":9},{"move":{"x":-17,"y":-18,"z":45},"block_id":9},{"move":{"x":-17,"y":-18,"z":47},"block_id":9},{"move":{"x":-17,"y":-17,"z":5},"block_id":9},{"move":{"x":-17,"y":-17,"z":6},"block_id":9},{"move":{"x":-17,"y":-17,"z":7},"block_id":9},{"move":{"x":-17,"y":-17,"z":8},"block_id":8},{"move":{"x":-17,"y":-17,"z":9},"block_id":9},{"move":{"x":-17,"y":-17,"z":18},"block_id":9},{"move":{"x":-17,"y":-17,"z":20},"block_id":9},{"move":{"x":-17,"y":-17,"z":21},"block_id":146},{"move":{"x":-17,"y":-17,"z":23},"block_id":9},{"move":{"x":-17,"y":-17,"z":24},"block_id":9},{"move":{"x":-17,"y":-17,"z":25},"block_id":9},{"move":{"x":-17,"y":-17,"z":26},"block_id":9},{"move":{"x":-17,"y":-17,"z":27},"block_id":9},{"move":{"x":-17,"y":-17,"z":29},"block_id":9},{"move":{"x":-17,"y":-17,"z":30},"block_id":9},{"move":{"x":-17,"y":-17,"z":31},"block_id":9},{"move":{"x":-17,"y":-17,"z":32},"block_id":9},{"move":{"x":-17,"y":-17,"z":33},"block_id":9},{"move":{"x":-17,"y":-17,"z":39},"block_id":98},{"move":{"x":-17,"y":-17,"z":40},"block_id":106,"rotate":{"x":0,"y":0,"z":0}},{"move":{"x":-17,"y":-17,"z":41},"block_id":9},{"move":{"x":-17,"y":-17,"z":45},"block_id":9},{"move":{"x":-17,"y":-17,"z":47},"block_id":9},{"move":{"x":-17,"y":-16,"z":5},"block_id":9},{"move":{"x":-17,"y":-16,"z":6},"block_id":9},{"move":{"x":-17,"y":-16,"z":7},"block_id":9},{"move":{"x":-17,"y":-16,"z":8},"block_id":146},{"move":{"x":-17,"y":-16,"z":9},"block_id":9},{"move":{"x":-17,"y":-16,"z":18},"block_id":9},{"move":{"x":-17,"y":-16,"z":19},"block_id":9},{"move":{"x":-17,"y":-16,"z":20},"block_id":9},{"move":{"x":-17,"y":-16,"z":21},"block_id":9},{"move":{"x":-17,"y":-16,"z":22},"block_id":9},{"move":{"x":-17,"y":-16,"z":23},"block_id":9},{"move":{"x":-17,"y":-16,"z":24},"block_id":9},{"move":{"x":-17,"y":-16,"z":25},"block_id":9},{"move":{"x":-17,"y":-16,"z":26},"block_id":9},{"move":{"x":-17,"y":-16,"z":27},"block_id":8},{"move":{"x":-17,"y":-16,"z":28},"block_id":9},{"move":{"x":-17,"y":-16,"z":29},"block_id":9},{"move":{"x":-17,"y":-16,"z":30},"block_id":9},{"move":{"x":-17,"y":-16,"z":31},"block_id":9},{"move":{"x":-17,"y":-16,"z":32},"block_id":9},{"move":{"x":-17,"y":-16,"z":33},"block_id":9},{"move":{"x":-17,"y":-16,"z":37},"block_id":98},{"move":{"x":-17,"y":-16,"z":38},"block_id":9},{"move":{"x":-17,"y":-16,"z":39},"block_id":9},{"move":{"x":-17,"y":-16,"z":40},"block_id":9},{"move":{"x":-17,"y":-16,"z":41},"block_id":9},{"move":{"x":-17,"y":-16,"z":45},"block_id":9},{"move":{"x":-17,"y":-16,"z":46},"block_id":9},{"move":{"x":-17,"y":-16,"z":47},"block_id":9},{"move":{"x":-17,"y":-15,"z":5},"block_id":9},{"move":{"x":-17,"y":-15,"z":6},"block_id":9},{"move":{"x":-17,"y":-15,"z":7},"block_id":9},{"move":{"x":-17,"y":-15,"z":8},"block_id":9},{"move":{"x":-17,"y":-15,"z":9},"block_id":9},{"move":{"x":-17,"y":-15,"z":34},"block_id":9},{"move":{"x":-17,"y":-15,"z":35},"block_id":9},{"move":{"x":-17,"y":-15,"z":36},"block_id":9},{"move":{"x":-16,"y":-20,"z":35},"block_id":9},{"move":{"x":-16,"y":-20,"z":36},"block_id":9},{"move":{"x":-16,"y":-20,"z":37},"block_id":9},{"move":{"x":-16,"y":-20,"z":40},"block_id":9},{"move":{"x":-16,"y":-19,"z":5},"block_id":9},{"move":{"x":-16,"y":-19,"z":6},"block_id":9},{"move":{"x":-16,"y":-19,"z":7},"block_id":9},{"move":{"x":-16,"y":-19,"z":8},"block_id":8},{"move":{"x":-16,"y":-19,"z":9},"block_id":9},{"move":{"x":-16,"y":-19,"z":18},"block_id":9},{"move":{"x":-16,"y":-19,"z":19},"block_id":9},{"move":{"x":-16,"y":-19,"z":20},"block_id":9},{"move":{"x":-16,"y":-19,"z":21},"block_id":9},{"move":{"x":-16,"y":-19,"z":22},"block_id":9},{"move":{"x":-16,"y":-19,"z":23},"block_id":9},{"move":{"x":-16,"y":-19,"z":24},"block_id":9},{"move":{"x":-16,"y":-19,"z":25},"block_id":9},{"move":{"x":-16,"y":-19,"z":26},"block_id":9},{"move":{"x":-16,"y":-19,"z":27},"block_id":9},{"move":{"x":-16,"y":-19,"z":28},"block_id":8},{"move":{"x":-16,"y":-19,"z":29},"block_id":9},{"move":{"x":-16,"y":-19,"z":30},"block_id":9},{"move":{"x":-16,"y":-19,"z":31},"block_id":9},{"move":{"x":-16,"y":-19,"z":32},"block_id":9},{"move":{"x":-16,"y":-19,"z":33},"block_id":9},{"move":{"x":-16,"y":-19,"z":34},"block_id":9},{"move":{"x":-16,"y":-19,"z":37},"block_id":632},{"move":{"x":-16,"y":-19,"z":38},"block_id":98},{"move":{"x":-16,"y":-19,"z":39},"block_id":83},{"move":{"x":-16,"y":-19,"z":40},"block_id":83},{"move":{"x":-16,"y":-19,"z":41},"block_id":9},{"move":{"x":-16,"y":-19,"z":45},"block_id":8},{"move":{"x":-16,"y":-19,"z":46},"block_id":9},{"move":{"x":-16,"y":-19,"z":47},"block_id":9},{"move":{"x":-16,"y":-18,"z":5},"block_id":146},{"move":{"x":-16,"y":-18,"z":6},"block_id":9},{"move":{"x":-16,"y":-18,"z":7},"block_id":9},{"move":{"x":-16,"y":-18,"z":8},"block_id":9},{"move":{"x":-16,"y":-18,"z":9},"block_id":9},{"move":{"x":-16,"y":-18,"z":18},"block_id":9},{"move":{"x":-16,"y":-18,"z":21},"block_id":106,"rotate":{"x":3,"y":0,"z":0}},{"move":{"x":-16,"y":-18,"z":25},"block_id":54,"extra_data":{"can_destroy":true,"slots":{}},"rotate":{"x":0,"y":1,"z":0}},{"move":{"x":-16,"y":-18,"z":26},"block_id":9},{"move":{"x":-16,"y":-18,"z":27},"block_id":9},{"move":{"x":-16,"y":-18,"z":29},"block_id":9},{"move":{"x":-16,"y":-18,"z":30},"block_id":9},{"move":{"x":-16,"y":-18,"z":31},"block_id":54,"extra_data":{"can_destroy":true,"slots":{}},"rotate":{"x":1,"y":1,"z":0}},{"move":{"x":-16,"y":-18,"z":32},"block_id":9},{"move":{"x":-16,"y":-18,"z":33},"block_id":9},{"move":{"x":-16,"y":-18,"z":37},"block_id":103},{"move":{"x":-16,"y":-18,"z":38},"block_id":106,"rotate":{"x":3,"y":0,"z":0}},{"move":{"x":-16,"y":-18,"z":40},"block_id":30},{"move":{"x":-16,"y":-18,"z":41},"block_id":9},{"move":{"x":-16,"y":-18,"z":45},"block_id":9},{"move":{"x":-16,"y":-18,"z":47},"block_id":9},{"move":{"x":-16,"y":-17,"z":5},"block_id":9},{"move":{"x":-16,"y":-17,"z":6},"block_id":9},{"move":{"x":-16,"y":-17,"z":7},"block_id":9},{"move":{"x":-16,"y":-17,"z":8},"block_id":9},{"move":{"x":-16,"y":-17,"z":9},"block_id":9},{"move":{"x":-16,"y":-17,"z":18},"block_id":9},{"move":{"x":-16,"y":-17,"z":21},"block_id":106,"rotate":{"x":3,"y":0,"z":0}},{"move":{"x":-16,"y":-17,"z":25},"block_id":106,"extra_data":{"north":true,"rotate":false}},{"move":{"x":-16,"y":-17,"z":26},"block_id":9},{"move":{"x":-16,"y":-17,"z":27},"block_id":9},{"move":{"x":-16,"y":-17,"z":29},"block_id":9},{"move":{"x":-16,"y":-17,"z":30},"block_id":9},{"move":{"x":-16,"y":-17,"z":31},"block_id":106,"extra_data":{"west":true,"rotate":false,"south":true}},{"move":{"x":-16,"y":-17,"z":32},"block_id":9},{"move":{"x":-16,"y":-17,"z":33},"block_id":9},{"move":{"x":-16,"y":-17,"z":37},"block_id":98},{"move":{"x":-16,"y":-17,"z":38},"block_id":106,"rotate":{"x":3,"y":0,"z":0}},{"move":{"x":-16,"y":-17,"z":41},"block_id":9},{"move":{"x":-16,"y":-17,"z":45},"block_id":9},{"move":{"x":-16,"y":-17,"z":47},"block_id":9},{"move":{"x":-16,"y":-16,"z":5},"block_id":9},{"move":{"x":-16,"y":-16,"z":6},"block_id":9},{"move":{"x":-16,"y":-16,"z":7},"block_id":9},{"move":{"x":-16,"y":-16,"z":8},"block_id":9},{"move":{"x":-16,"y":-16,"z":9},"block_id":9},{"move":{"x":-16,"y":-16,"z":18},"block_id":9},{"move":{"x":-16,"y":-16,"z":19},"block_id":9},{"move":{"x":-16,"y":-16,"z":20},"block_id":9},{"move":{"x":-16,"y":-16,"z":21},"block_id":9},{"move":{"x":-16,"y":-16,"z":22},"block_id":9},{"move":{"x":-16,"y":-16,"z":23},"block_id":9},{"move":{"x":-16,"y":-16,"z":24},"block_id":9},{"move":{"x":-16,"y":-16,"z":25},"block_id":9},{"move":{"x":-16,"y":-16,"z":26},"block_id":9},{"move":{"x":-16,"y":-16,"z":27},"block_id":9},{"move":{"x":-16,"y":-16,"z":28},"block_id":9},{"move":{"x":-16,"y":-16,"z":29},"block_id":9},{"move":{"x":-16,"y":-16,"z":30},"block_id":9},{"move":{"x":-16,"y":-16,"z":31},"block_id":9},{"move":{"x":-16,"y":-16,"z":32},"block_id":9},{"move":{"x":-16,"y":-16,"z":33},"block_id":9},{"move":{"x":-16,"y":-16,"z":37},"block_id":83},{"move":{"x":-16,"y":-16,"z":38},"block_id":9},{"move":{"x":-16,"y":-16,"z":39},"block_id":9},{"move":{"x":-16,"y":-16,"z":40},"block_id":9},{"move":{"x":-16,"y":-16,"z":41},"block_id":9},{"move":{"x":-16,"y":-16,"z":45},"block_id":9},{"move":{"x":-16,"y":-16,"z":46},"block_id":9},{"move":{"x":-16,"y":-16,"z":47},"block_id":9},{"move":{"x":-16,"y":-15,"z":5},"block_id":9},{"move":{"x":-16,"y":-15,"z":6},"block_id":8},{"move":{"x":-16,"y":-15,"z":7},"block_id":9},{"move":{"x":-16,"y":-15,"z":8},"block_id":9},{"move":{"x":-16,"y":-15,"z":9},"block_id":9},{"move":{"x":-16,"y":-15,"z":34},"block_id":9},{"move":{"x":-16,"y":-15,"z":35},"block_id":9},{"move":{"x":-16,"y":-15,"z":36},"block_id":9},{"move":{"x":-15,"y":-19,"z":3},"block_id":9},{"move":{"x":-15,"y":-19,"z":4},"block_id":9},{"move":{"x":-15,"y":-19,"z":5},"block_id":9},{"move":{"x":-15,"y":-19,"z":6},"block_id":9},{"move":{"x":-15,"y":-19,"z":7},"block_id":9},{"move":{"x":-15,"y":-19,"z":8},"block_id":9},{"move":{"x":-15,"y":-19,"z":9},"block_id":9},{"move":{"x":-15,"y":-19,"z":10},"block_id":9},{"move":{"x":-15,"y":-19,"z":11},"block_id":9},{"move":{"x":-15,"y":-19,"z":18},"block_id":9},{"move":{"x":-15,"y":-19,"z":19},"block_id":9},{"move":{"x":-15,"y":-19,"z":20},"block_id":9},{"move":{"x":-15,"y":-19,"z":21},"block_id":9},{"move":{"x":-15,"y":-19,"z":22},"block_id":9},{"move":{"x":-15,"y":-19,"z":23},"block_id":9},{"move":{"x":-15,"y":-19,"z":24},"block_id":9},{"move":{"x":-15,"y":-19,"z":25},"block_id":9},{"move":{"x":-15,"y":-19,"z":26},"block_id":9},{"move":{"x":-15,"y":-19,"z":27},"block_id":9},{"move":{"x":-15,"y":-19,"z":28},"block_id":9},{"move":{"x":-15,"y":-19,"z":29},"block_id":9},{"move":{"x":-15,"y":-19,"z":30},"block_id":9},{"move":{"x":-15,"y":-19,"z":31},"block_id":9},{"move":{"x":-15,"y":-19,"z":32},"block_id":9},{"move":{"x":-15,"y":-19,"z":33},"block_id":9},{"move":{"x":-15,"y":-19,"z":34},"block_id":9},{"move":{"x":-15,"y":-19,"z":35},"block_id":9},{"move":{"x":-15,"y":-19,"z":36},"block_id":9},{"move":{"x":-15,"y":-19,"z":37},"block_id":9},{"move":{"x":-15,"y":-19,"z":38},"block_id":9},{"move":{"x":-15,"y":-19,"z":39},"block_id":9},{"move":{"x":-15,"y":-19,"z":40},"block_id":9},{"move":{"x":-15,"y":-19,"z":41},"block_id":9},{"move":{"x":-15,"y":-19,"z":45},"block_id":9},{"move":{"x":-15,"y":-19,"z":46},"block_id":9},{"move":{"x":-15,"y":-19,"z":47},"block_id":9},{"move":{"x":-15,"y":-18,"z":3},"block_id":9},{"move":{"x":-15,"y":-18,"z":4},"block_id":9},{"move":{"x":-15,"y":-18,"z":5},"block_id":8},{"move":{"x":-15,"y":-18,"z":6},"block_id":8},{"move":{"x":-15,"y":-18,"z":7},"block_id":8},{"move":{"x":-15,"y":-18,"z":8},"block_id":9},{"move":{"x":-15,"y":-18,"z":9},"block_id":9},{"move":{"x":-15,"y":-18,"z":10},"block_id":9},{"move":{"x":-15,"y":-18,"z":11},"block_id":9},{"move":{"x":-15,"y":-18,"z":18},"block_id":9},{"move":{"x":-15,"y":-18,"z":20},"block_id":9},{"move":{"x":-15,"y":-18,"z":21},"block_id":9},{"move":{"x":-15,"y":-18,"z":23},"block_id":9},{"move":{"x":-15,"y":-18,"z":24},"block_id":9},{"move":{"x":-15,"y":-18,"z":25},"block_id":9},{"move":{"x":-15,"y":-18,"z":26},"block_id":9},{"move":{"x":-15,"y":-18,"z":27},"block_id":9},{"move":{"x":-15,"y":-18,"z":28},"block_id":106,"extra_data":{"north":true,"rotate":false}},{"move":{"x":-15,"y":-18,"z":29},"block_id":9},{"move":{"x":-15,"y":-18,"z":30},"block_id":9},{"move":{"x":-15,"y":-18,"z":31},"block_id":106,"extra_data":{"south":true,"rotate":false}},{"move":{"x":-15,"y":-18,"z":32},"block_id":9},{"move":{"x":-15,"y":-18,"z":33},"block_id":9},{"move":{"x":-15,"y":-18,"z":35},"block_id":9},{"move":{"x":-15,"y":-18,"z":36},"block_id":9},{"move":{"x":-15,"y":-18,"z":37},"block_id":9},{"move":{"x":-15,"y":-18,"z":38},"block_id":9},{"move":{"x":-15,"y":-18,"z":39},"block_id":9},{"move":{"x":-15,"y":-18,"z":40},"block_id":9},{"move":{"x":-15,"y":-18,"z":41},"block_id":9},{"move":{"x":-15,"y":-18,"z":45},"block_id":9},{"move":{"x":-15,"y":-18,"z":47},"block_id":9},{"move":{"x":-15,"y":-17,"z":3},"block_id":146},{"move":{"x":-15,"y":-17,"z":4},"block_id":9},{"move":{"x":-15,"y":-17,"z":5},"block_id":9},{"move":{"x":-15,"y":-17,"z":6},"block_id":9},{"move":{"x":-15,"y":-17,"z":7},"block_id":9},{"move":{"x":-15,"y":-17,"z":8},"block_id":9},{"move":{"x":-15,"y":-17,"z":9},"block_id":8},{"move":{"x":-15,"y":-17,"z":10},"block_id":9},{"move":{"x":-15,"y":-17,"z":11},"block_id":146},{"move":{"x":-15,"y":-17,"z":18},"block_id":9},{"move":{"x":-15,"y":-17,"z":20},"block_id":9},{"move":{"x":-15,"y":-17,"z":21},"block_id":9},{"move":{"x":-15,"y":-17,"z":22},"block_id":30},{"move":{"x":-15,"y":-17,"z":23},"block_id":146},{"move":{"x":-15,"y":-17,"z":24},"block_id":9},{"move":{"x":-15,"y":-17,"z":25},"block_id":9},{"move":{"x":-15,"y":-17,"z":26},"block_id":9},{"move":{"x":-15,"y":-17,"z":27},"block_id":9},{"move":{"x":-15,"y":-17,"z":28},"block_id":106,"extra_data":{"north":true,"rotate":false}},{"move":{"x":-15,"y":-17,"z":29},"block_id":9},{"move":{"x":-15,"y":-17,"z":30},"block_id":9},{"move":{"x":-15,"y":-17,"z":31},"block_id":106,"extra_data":{"south":true,"rotate":false}},{"move":{"x":-15,"y":-17,"z":32},"block_id":9},{"move":{"x":-15,"y":-17,"z":33},"block_id":9},{"move":{"x":-15,"y":-17,"z":35},"block_id":9},{"move":{"x":-15,"y":-17,"z":36},"block_id":9},{"move":{"x":-15,"y":-17,"z":37},"block_id":9},{"move":{"x":-15,"y":-17,"z":38},"block_id":9},{"move":{"x":-15,"y":-17,"z":39},"block_id":9},{"move":{"x":-15,"y":-17,"z":40},"block_id":9},{"move":{"x":-15,"y":-17,"z":41},"block_id":9},{"move":{"x":-15,"y":-17,"z":45},"block_id":9},{"move":{"x":-15,"y":-17,"z":46},"block_id":30},{"move":{"x":-15,"y":-17,"z":47},"block_id":9},{"move":{"x":-15,"y":-16,"z":3},"block_id":9},{"move":{"x":-15,"y":-16,"z":4},"block_id":9},{"move":{"x":-15,"y":-16,"z":5},"block_id":9},{"move":{"x":-15,"y":-16,"z":6},"block_id":9},{"move":{"x":-15,"y":-16,"z":7},"block_id":146},{"move":{"x":-15,"y":-16,"z":8},"block_id":9},{"move":{"x":-15,"y":-16,"z":9},"block_id":9},{"move":{"x":-15,"y":-16,"z":10},"block_id":9},{"move":{"x":-15,"y":-16,"z":11},"block_id":9},{"move":{"x":-15,"y":-16,"z":18},"block_id":9},{"move":{"x":-15,"y":-16,"z":19},"block_id":9},{"move":{"x":-15,"y":-16,"z":20},"block_id":9},{"move":{"x":-15,"y":-16,"z":21},"block_id":9},{"move":{"x":-15,"y":-16,"z":22},"block_id":9},{"move":{"x":-15,"y":-16,"z":23},"block_id":8},{"move":{"x":-15,"y":-16,"z":24},"block_id":9},{"move":{"x":-15,"y":-16,"z":25},"block_id":9},{"move":{"x":-15,"y":-16,"z":26},"block_id":9},{"move":{"x":-15,"y":-16,"z":27},"block_id":146},{"move":{"x":-15,"y":-16,"z":28},"block_id":9},{"move":{"x":-15,"y":-16,"z":29},"block_id":9},{"move":{"x":-15,"y":-16,"z":30},"block_id":9},{"move":{"x":-15,"y":-16,"z":31},"block_id":9},{"move":{"x":-15,"y":-16,"z":32},"block_id":9},{"move":{"x":-15,"y":-16,"z":33},"block_id":9},{"move":{"x":-15,"y":-16,"z":34},"block_id":9},{"move":{"x":-15,"y":-16,"z":35},"block_id":9},{"move":{"x":-15,"y":-16,"z":36},"block_id":9},{"move":{"x":-15,"y":-16,"z":37},"block_id":9},{"move":{"x":-15,"y":-16,"z":38},"block_id":9},{"move":{"x":-15,"y":-16,"z":39},"block_id":9},{"move":{"x":-15,"y":-16,"z":40},"block_id":9},{"move":{"x":-15,"y":-16,"z":41},"block_id":9},{"move":{"x":-15,"y":-16,"z":45},"block_id":9},{"move":{"x":-15,"y":-16,"z":46},"block_id":9},{"move":{"x":-15,"y":-16,"z":47},"block_id":146},{"move":{"x":-15,"y":-15,"z":3},"block_id":9},{"move":{"x":-15,"y":-15,"z":4},"block_id":9},{"move":{"x":-15,"y":-15,"z":5},"block_id":9},{"move":{"x":-15,"y":-15,"z":6},"block_id":9},{"move":{"x":-15,"y":-15,"z":7},"block_id":9},{"move":{"x":-15,"y":-15,"z":8},"block_id":9},{"move":{"x":-15,"y":-15,"z":9},"block_id":9},{"move":{"x":-15,"y":-15,"z":10},"block_id":9},{"move":{"x":-15,"y":-15,"z":11},"block_id":83},{"move":{"x":-14,"y":-19,"z":3},"block_id":9},{"move":{"x":-14,"y":-19,"z":4},"block_id":9},{"move":{"x":-14,"y":-19,"z":5},"block_id":9},{"move":{"x":-14,"y":-19,"z":6},"block_id":9},{"move":{"x":-14,"y":-19,"z":7},"block_id":9},{"move":{"x":-14,"y":-19,"z":8},"block_id":9},{"move":{"x":-14,"y":-19,"z":9},"block_id":9},{"move":{"x":-14,"y":-19,"z":10},"block_id":9},{"move":{"x":-14,"y":-19,"z":11},"block_id":9},{"move":{"x":-14,"y":-19,"z":18},"block_id":9},{"move":{"x":-14,"y":-19,"z":19},"block_id":9},{"move":{"x":-14,"y":-19,"z":20},"block_id":9},{"move":{"x":-14,"y":-19,"z":21},"block_id":9},{"move":{"x":-14,"y":-19,"z":22},"block_id":9},{"move":{"x":-14,"y":-19,"z":23},"block_id":9},{"move":{"x":-14,"y":-19,"z":24},"block_id":9},{"move":{"x":-14,"y":-19,"z":25},"block_id":9},{"move":{"x":-14,"y":-19,"z":26},"block_id":9},{"move":{"x":-14,"y":-19,"z":27},"block_id":146},{"move":{"x":-14,"y":-19,"z":28},"block_id":9},{"move":{"x":-14,"y":-19,"z":29},"block_id":9},{"move":{"x":-14,"y":-19,"z":30},"block_id":9},{"move":{"x":-14,"y":-19,"z":31},"block_id":9},{"move":{"x":-14,"y":-19,"z":32},"block_id":8},{"move":{"x":-14,"y":-19,"z":33},"block_id":8},{"move":{"x":-14,"y":-19,"z":34},"block_id":8},{"move":{"x":-14,"y":-19,"z":35},"block_id":9},{"move":{"x":-14,"y":-19,"z":39},"block_id":9},{"move":{"x":-14,"y":-19,"z":40},"block_id":9},{"move":{"x":-14,"y":-19,"z":41},"block_id":9},{"move":{"x":-14,"y":-19,"z":42},"block_id":9},{"move":{"x":-14,"y":-19,"z":43},"block_id":146},{"move":{"x":-14,"y":-19,"z":44},"block_id":9},{"move":{"x":-14,"y":-19,"z":45},"block_id":9},{"move":{"x":-14,"y":-19,"z":46},"block_id":8},{"move":{"x":-14,"y":-19,"z":47},"block_id":9},{"move":{"x":-14,"y":-18,"z":3},"block_id":9},{"move":{"x":-14,"y":-18,"z":4},"block_id":9},{"move":{"x":-14,"y":-18,"z":5},"block_id":9},{"move":{"x":-14,"y":-18,"z":6},"block_id":106,"rotate":{"x":2,"y":0,"z":0}},{"move":{"x":-14,"y":-18,"z":8},"block_id":106,"rotate":{"x":0,"y":0,"z":0}},{"move":{"x":-14,"y":-18,"z":9},"block_id":9},{"move":{"x":-14,"y":-18,"z":10},"block_id":9},{"move":{"x":-14,"y":-18,"z":11},"block_id":9},{"move":{"x":-14,"y":-18,"z":18},"block_id":9},{"move":{"x":-14,"y":-18,"z":20},"block_id":9},{"move":{"x":-14,"y":-18,"z":21},"block_id":9},{"move":{"x":-14,"y":-18,"z":23},"block_id":9},{"move":{"x":-14,"y":-18,"z":24},"block_id":9},{"move":{"x":-14,"y":-18,"z":25},"block_id":9},{"move":{"x":-14,"y":-18,"z":26},"block_id":9},{"move":{"x":-14,"y":-18,"z":27},"block_id":146},{"move":{"x":-14,"y":-18,"z":28},"block_id":106,"extra_data":{"north":true,"rotate":false}},{"move":{"x":-14,"y":-18,"z":29},"block_id":9},{"move":{"x":-14,"y":-18,"z":30},"block_id":9},{"move":{"x":-14,"y":-18,"z":32},"block_id":9},{"move":{"x":-14,"y":-18,"z":33},"block_id":9},{"move":{"x":-14,"y":-18,"z":35},"block_id":9},{"move":{"x":-14,"y":-18,"z":39},"block_id":9},{"move":{"x":-14,"y":-18,"z":40},"block_id":9},{"move":{"x":-14,"y":-18,"z":41},"block_id":9},{"move":{"x":-14,"y":-18,"z":42},"block_id":146},{"move":{"x":-14,"y":-18,"z":43},"block_id":9},{"move":{"x":-14,"y":-18,"z":44},"block_id":9},{"move":{"x":-14,"y":-18,"z":45},"block_id":9},{"move":{"x":-14,"y":-18,"z":47},"block_id":9},{"move":{"x":-14,"y":-17,"z":3},"block_id":9},{"move":{"x":-14,"y":-17,"z":4},"block_id":9},{"move":{"x":-14,"y":-17,"z":5},"block_id":9},{"move":{"x":-14,"y":-17,"z":9},"block_id":9},{"move":{"x":-14,"y":-17,"z":10},"block_id":9},{"move":{"x":-14,"y":-17,"z":11},"block_id":8},{"move":{"x":-14,"y":-17,"z":18},"block_id":9},{"move":{"x":-14,"y":-17,"z":19},"block_id":106,"rotate":{"x":2,"y":0,"z":0}},{"move":{"x":-14,"y":-17,"z":20},"block_id":9},{"move":{"x":-14,"y":-17,"z":21},"block_id":9},{"move":{"x":-14,"y":-17,"z":22},"block_id":106,"rotate":{"x":0,"y":0,"z":0}},{"move":{"x":-14,"y":-17,"z":23},"block_id":9},{"move":{"x":-14,"y":-17,"z":24},"block_id":9},{"move":{"x":-14,"y":-17,"z":25},"block_id":9},{"move":{"x":-14,"y":-17,"z":26},"block_id":9},{"move":{"x":-14,"y":-17,"z":27},"block_id":9},{"move":{"x":-14,"y":-17,"z":28},"block_id":106,"extra_data":{"north":true,"rotate":false}},{"move":{"x":-14,"y":-17,"z":29},"block_id":9},{"move":{"x":-14,"y":-17,"z":30},"block_id":9},{"move":{"x":-14,"y":-17,"z":31},"block_id":106,"rotate":{"x":0,"y":0,"z":0}},{"move":{"x":-14,"y":-17,"z":32},"block_id":9},{"move":{"x":-14,"y":-17,"z":33},"block_id":9},{"move":{"x":-14,"y":-17,"z":35},"block_id":9},{"move":{"x":-14,"y":-17,"z":39},"block_id":9},{"move":{"x":-14,"y":-17,"z":40},"block_id":9},{"move":{"x":-14,"y":-17,"z":41},"block_id":9},{"move":{"x":-14,"y":-17,"z":42},"block_id":9},{"move":{"x":-14,"y":-17,"z":43},"block_id":9},{"move":{"x":-14,"y":-17,"z":44},"block_id":9},{"move":{"x":-14,"y":-17,"z":45},"block_id":9},{"move":{"x":-14,"y":-17,"z":47},"block_id":9},{"move":{"x":-14,"y":-16,"z":3},"block_id":9},{"move":{"x":-14,"y":-16,"z":4},"block_id":9},{"move":{"x":-14,"y":-16,"z":5},"block_id":9},{"move":{"x":-14,"y":-16,"z":6},"block_id":30},{"move":{"x":-14,"y":-16,"z":9},"block_id":9},{"move":{"x":-14,"y":-16,"z":10},"block_id":9},{"move":{"x":-14,"y":-16,"z":11},"block_id":8},{"move":{"x":-14,"y":-16,"z":18},"block_id":146},{"move":{"x":-14,"y":-16,"z":19},"block_id":9},{"move":{"x":-14,"y":-16,"z":20},"block_id":9},{"move":{"x":-14,"y":-16,"z":21},"block_id":9},{"move":{"x":-14,"y":-16,"z":22},"block_id":146},{"move":{"x":-14,"y":-16,"z":23},"block_id":9},{"move":{"x":-14,"y":-16,"z":24},"block_id":9},{"move":{"x":-14,"y":-16,"z":25},"block_id":9},{"move":{"x":-14,"y":-16,"z":26},"block_id":9},{"move":{"x":-14,"y":-16,"z":27},"block_id":9},{"move":{"x":-14,"y":-16,"z":28},"block_id":9},{"move":{"x":-14,"y":-16,"z":29},"block_id":9},{"move":{"x":-14,"y":-16,"z":30},"block_id":9},{"move":{"x":-14,"y":-16,"z":31},"block_id":67,"extra_data":{"point":{"x":0,"y":0.9,"z":0}},"rotate":{"x":1,"y":0,"z":0}},{"move":{"x":-14,"y":-16,"z":32},"block_id":9},{"move":{"x":-14,"y":-16,"z":33},"block_id":9},{"move":{"x":-14,"y":-16,"z":34},"block_id":9},{"move":{"x":-14,"y":-16,"z":35},"block_id":9},{"move":{"x":-14,"y":-16,"z":39},"block_id":9},{"move":{"x":-14,"y":-16,"z":40},"block_id":9},{"move":{"x":-14,"y":-16,"z":41},"block_id":9},{"move":{"x":-14,"y":-16,"z":42},"block_id":9},{"move":{"x":-14,"y":-16,"z":43},"block_id":9},{"move":{"x":-14,"y":-16,"z":44},"block_id":146},{"move":{"x":-14,"y":-16,"z":45},"block_id":9},{"move":{"x":-14,"y":-16,"z":46},"block_id":9},{"move":{"x":-14,"y":-16,"z":47},"block_id":9},{"move":{"x":-14,"y":-15,"z":3},"block_id":9},{"move":{"x":-14,"y":-15,"z":4},"block_id":9},{"move":{"x":-14,"y":-15,"z":5},"block_id":9},{"move":{"x":-14,"y":-15,"z":6},"block_id":9},{"move":{"x":-14,"y":-15,"z":7},"block_id":9},{"move":{"x":-14,"y":-15,"z":8},"block_id":9},{"move":{"x":-14,"y":-15,"z":9},"block_id":9},{"move":{"x":-14,"y":-15,"z":10},"block_id":146},{"move":{"x":-14,"y":-15,"z":11},"block_id":9},{"move":{"x":-13,"y":-19,"z":3},"block_id":9},{"move":{"x":-13,"y":-19,"z":4},"block_id":9},{"move":{"x":-13,"y":-19,"z":5},"block_id":8},{"move":{"x":-13,"y":-19,"z":6},"block_id":9},{"move":{"x":-13,"y":-19,"z":7},"block_id":83},{"move":{"x":-13,"y":-19,"z":8},"block_id":9},{"move":{"x":-13,"y":-19,"z":9},"block_id":9},{"move":{"x":-13,"y":-19,"z":10},"block_id":9},{"move":{"x":-13,"y":-19,"z":11},"block_id":9},{"move":{"x":-13,"y":-19,"z":18},"block_id":9},{"move":{"x":-13,"y":-19,"z":19},"block_id":9},{"move":{"x":-13,"y":-19,"z":20},"block_id":9},{"move":{"x":-13,"y":-19,"z":21},"block_id":9},{"move":{"x":-13,"y":-19,"z":22},"block_id":8},{"move":{"x":-13,"y":-19,"z":23},"block_id":83},{"move":{"x":-13,"y":-19,"z":24},"block_id":9},{"move":{"x":-13,"y":-19,"z":25},"block_id":9},{"move":{"x":-13,"y":-19,"z":26},"block_id":9},{"move":{"x":-13,"y":-19,"z":27},"block_id":9},{"move":{"x":-13,"y":-19,"z":28},"block_id":9},{"move":{"x":-13,"y":-19,"z":29},"block_id":146},{"move":{"x":-13,"y":-19,"z":30},"block_id":9},{"move":{"x":-13,"y":-19,"z":31},"block_id":9},{"move":{"x":-13,"y":-19,"z":32},"block_id":9},{"move":{"x":-13,"y":-19,"z":33},"block_id":146},{"move":{"x":-13,"y":-19,"z":34},"block_id":9},{"move":{"x":-13,"y":-19,"z":35},"block_id":9},{"move":{"x":-13,"y":-19,"z":39},"block_id":9},{"move":{"x":-13,"y":-19,"z":40},"block_id":9},{"move":{"x":-13,"y":-19,"z":41},"block_id":9},{"move":{"x":-13,"y":-19,"z":42},"block_id":9},{"move":{"x":-13,"y":-19,"z":43},"block_id":9},{"move":{"x":-13,"y":-19,"z":44},"block_id":9},{"move":{"x":-13,"y":-19,"z":45},"block_id":9},{"move":{"x":-13,"y":-19,"z":46},"block_id":9},{"move":{"x":-13,"y":-19,"z":47},"block_id":9},{"move":{"x":-13,"y":-18,"z":3},"block_id":9},{"move":{"x":-13,"y":-18,"z":4},"block_id":9},{"move":{"x":-13,"y":-18,"z":5},"block_id":9},{"move":{"x":-13,"y":-18,"z":9},"block_id":9},{"move":{"x":-13,"y":-18,"z":10},"block_id":9},{"move":{"x":-13,"y":-18,"z":11},"block_id":9},{"move":{"x":-13,"y":-18,"z":18},"block_id":9},{"move":{"x":-13,"y":-18,"z":19},"block_id":30},{"move":{"x":-13,"y":-18,"z":22},"block_id":106,"rotate":{"x":3,"y":0,"z":0}},{"move":{"x":-13,"y":-18,"z":23},"block_id":9},{"move":{"x":-13,"y":-18,"z":24},"block_id":9},{"move":{"x":-13,"y":-18,"z":25},"block_id":54,"extra_data":{"can_destroy":true,"slots":{}},"rotate":{"x":2,"y":1,"z":0}},{"move":{"x":-13,"y":-18,"z":32},"block_id":9},{"move":{"x":-13,"y":-18,"z":33},"block_id":9},{"move":{"x":-13,"y":-18,"z":35},"block_id":9},{"move":{"x":-13,"y":-18,"z":39},"block_id":9},{"move":{"x":-13,"y":-18,"z":40},"block_id":54,"extra_data":{"can_destroy":true,"slots":{}},"rotate":{"x":2,"y":1,"z":0}},{"move":{"x":-13,"y":-18,"z":43},"block_id":106,"rotate":{"x":3,"y":0,"z":0}},{"move":{"x":-13,"y":-18,"z":47},"block_id":9},{"move":{"x":-13,"y":-17,"z":3},"block_id":9},{"move":{"x":-13,"y":-17,"z":4},"block_id":9},{"move":{"x":-13,"y":-17,"z":5},"block_id":9},{"move":{"x":-13,"y":-17,"z":9},"block_id":8},{"move":{"x":-13,"y":-17,"z":10},"block_id":9},{"move":{"x":-13,"y":-17,"z":11},"block_id":9},{"move":{"x":-13,"y":-17,"z":18},"block_id":9},{"move":{"x":-13,"y":-17,"z":22},"block_id":106,"rotate":{"x":0,"y":0,"z":0}},{"move":{"x":-13,"y":-17,"z":23},"block_id":9},{"move":{"x":-13,"y":-17,"z":24},"block_id":9},{"move":{"x":-13,"y":-17,"z":27},"block_id":106,"rotate":{"x":1,"y":0,"z":0}},{"move":{"x":-13,"y":-17,"z":32},"block_id":8},{"move":{"x":-13,"y":-17,"z":33},"block_id":146},{"move":{"x":-13,"y":-17,"z":34},"block_id":30},{"move":{"x":-13,"y":-17,"z":35},"block_id":9},{"move":{"x":-13,"y":-17,"z":39},"block_id":9},{"move":{"x":-13,"y":-17,"z":42},"block_id":30},{"move":{"x":-13,"y":-17,"z":43},"block_id":106,"rotate":{"x":3,"y":0,"z":0}},{"move":{"x":-13,"y":-17,"z":47},"block_id":9},{"move":{"x":-13,"y":-16,"z":3},"block_id":9},{"move":{"x":-13,"y":-16,"z":4},"block_id":9},{"move":{"x":-13,"y":-16,"z":5},"block_id":9},{"move":{"x":-13,"y":-16,"z":9},"block_id":9},{"move":{"x":-13,"y":-16,"z":10},"block_id":9},{"move":{"x":-13,"y":-16,"z":11},"block_id":9},{"move":{"x":-13,"y":-16,"z":18},"block_id":146},{"move":{"x":-13,"y":-16,"z":19},"block_id":9},{"move":{"x":-13,"y":-16,"z":20},"block_id":9},{"move":{"x":-13,"y":-16,"z":21},"block_id":9},{"move":{"x":-13,"y":-16,"z":22},"block_id":9},{"move":{"x":-13,"y":-16,"z":23},"block_id":8},{"move":{"x":-13,"y":-16,"z":24},"block_id":9},{"move":{"x":-13,"y":-16,"z":25},"block_id":9},{"move":{"x":-13,"y":-16,"z":26},"block_id":9},{"move":{"x":-13,"y":-16,"z":27},"block_id":9},{"move":{"x":-13,"y":-16,"z":28},"block_id":9},{"move":{"x":-13,"y":-16,"z":29},"block_id":9},{"move":{"x":-13,"y":-16,"z":30},"block_id":9},{"move":{"x":-13,"y":-16,"z":31},"block_id":146},{"move":{"x":-13,"y":-16,"z":32},"block_id":9},{"move":{"x":-13,"y":-16,"z":33},"block_id":9},{"move":{"x":-13,"y":-16,"z":34},"block_id":9},{"move":{"x":-13,"y":-16,"z":35},"block_id":9},{"move":{"x":-13,"y":-16,"z":39},"block_id":9},{"move":{"x":-13,"y":-16,"z":40},"block_id":9},{"move":{"x":-13,"y":-16,"z":41},"block_id":9},{"move":{"x":-13,"y":-16,"z":42},"block_id":9},{"move":{"x":-13,"y":-16,"z":43},"block_id":9},{"move":{"x":-13,"y":-16,"z":44},"block_id":9},{"move":{"x":-13,"y":-16,"z":45},"block_id":8},{"move":{"x":-13,"y":-16,"z":46},"block_id":9},{"move":{"x":-13,"y":-16,"z":47},"block_id":9},{"move":{"x":-13,"y":-15,"z":3},"block_id":9},{"move":{"x":-13,"y":-15,"z":4},"block_id":9},{"move":{"x":-13,"y":-15,"z":5},"block_id":9},{"move":{"x":-13,"y":-15,"z":6},"block_id":9},{"move":{"x":-13,"y":-15,"z":7},"block_id":9},{"move":{"x":-13,"y":-15,"z":8},"block_id":9},{"move":{"x":-13,"y":-15,"z":9},"block_id":9},{"move":{"x":-13,"y":-15,"z":10},"block_id":9},{"move":{"x":-13,"y":-15,"z":11},"block_id":8},{"move":{"x":-12,"y":-19,"z":3},"block_id":9},{"move":{"x":-12,"y":-19,"z":4},"block_id":9},{"move":{"x":-12,"y":-19,"z":5},"block_id":9},{"move":{"x":-12,"y":-19,"z":6},"block_id":9},{"move":{"x":-12,"y":-19,"z":7},"block_id":67,"extra_data":{"point":{"x":0,"y":0.9,"z":0}},"rotate":{"x":1,"y":0,"z":0}},{"move":{"x":-12,"y":-19,"z":8},"block_id":9},{"move":{"x":-12,"y":-19,"z":9},"block_id":9},{"move":{"x":-12,"y":-19,"z":10},"block_id":9},{"move":{"x":-12,"y":-19,"z":11},"block_id":9},{"move":{"x":-12,"y":-19,"z":18},"block_id":9},{"move":{"x":-12,"y":-19,"z":19},"block_id":9},{"move":{"x":-12,"y":-19,"z":20},"block_id":9},{"move":{"x":-12,"y":-19,"z":21},"block_id":9},{"move":{"x":-12,"y":-19,"z":22},"block_id":9},{"move":{"x":-12,"y":-19,"z":23},"block_id":9},{"move":{"x":-12,"y":-19,"z":24},"block_id":9},{"move":{"x":-12,"y":-19,"z":25},"block_id":9},{"move":{"x":-12,"y":-19,"z":26},"block_id":9},{"move":{"x":-12,"y":-19,"z":27},"block_id":9},{"move":{"x":-12,"y":-19,"z":28},"block_id":9},{"move":{"x":-12,"y":-19,"z":29},"block_id":9},{"move":{"x":-12,"y":-19,"z":30},"block_id":9},{"move":{"x":-12,"y":-19,"z":31},"block_id":9},{"move":{"x":-12,"y":-19,"z":32},"block_id":9},{"move":{"x":-12,"y":-19,"z":33},"block_id":9},{"move":{"x":-12,"y":-19,"z":34},"block_id":9},{"move":{"x":-12,"y":-19,"z":35},"block_id":9},{"move":{"x":-12,"y":-19,"z":39},"block_id":9},{"move":{"x":-12,"y":-19,"z":40},"block_id":9},{"move":{"x":-12,"y":-19,"z":41},"block_id":9},{"move":{"x":-12,"y":-19,"z":42},"block_id":9},{"move":{"x":-12,"y":-19,"z":43},"block_id":9},{"move":{"x":-12,"y":-19,"z":44},"block_id":9},{"move":{"x":-12,"y":-19,"z":45},"block_id":9},{"move":{"x":-12,"y":-19,"z":46},"block_id":9},{"move":{"x":-12,"y":-19,"z":47},"block_id":9},{"move":{"x":-12,"y":-18,"z":3},"block_id":9},{"move":{"x":-12,"y":-18,"z":4},"block_id":9},{"move":{"x":-12,"y":-18,"z":5},"block_id":9},{"move":{"x":-12,"y":-18,"z":9},"block_id":9},{"move":{"x":-12,"y":-18,"z":10},"block_id":9},{"move":{"x":-12,"y":-18,"z":11},"block_id":9},{"move":{"x":-12,"y":-18,"z":18},"block_id":9},{"move":{"x":-12,"y":-18,"z":20},"block_id":9},{"move":{"x":-12,"y":-18,"z":21},"block_id":146},{"move":{"x":-12,"y":-18,"z":22},"block_id":9},{"move":{"x":-12,"y":-18,"z":23},"block_id":9},{"move":{"x":-12,"y":-18,"z":24},"block_id":9},{"move":{"x":-12,"y":-18,"z":25},"block_id":9},{"move":{"x":-12,"y":-18,"z":26},"block_id":9},{"move":{"x":-12,"y":-18,"z":27},"block_id":9},{"move":{"x":-12,"y":-18,"z":29},"block_id":8},{"move":{"x":-12,"y":-18,"z":30},"block_id":9},{"move":{"x":-12,"y":-18,"z":31},"block_id":9},{"move":{"x":-12,"y":-18,"z":32},"block_id":8},{"move":{"x":-12,"y":-18,"z":33},"block_id":9},{"move":{"x":-12,"y":-18,"z":35},"block_id":9},{"move":{"x":-12,"y":-18,"z":39},"block_id":9},{"move":{"x":-12,"y":-18,"z":40},"block_id":9},{"move":{"x":-12,"y":-18,"z":41},"block_id":9},{"move":{"x":-12,"y":-18,"z":42},"block_id":9},{"move":{"x":-12,"y":-18,"z":43},"block_id":9},{"move":{"x":-12,"y":-18,"z":44},"block_id":9},{"move":{"x":-12,"y":-18,"z":45},"block_id":9},{"move":{"x":-12,"y":-18,"z":47},"block_id":9},{"move":{"x":-12,"y":-17,"z":3},"block_id":9},{"move":{"x":-12,"y":-17,"z":4},"block_id":9},{"move":{"x":-12,"y":-17,"z":5},"block_id":9},{"move":{"x":-12,"y":-17,"z":9},"block_id":8},{"move":{"x":-12,"y":-17,"z":10},"block_id":8},{"move":{"x":-12,"y":-17,"z":11},"block_id":9},{"move":{"x":-12,"y":-17,"z":18},"block_id":9},{"move":{"x":-12,"y":-17,"z":20},"block_id":9},{"move":{"x":-12,"y":-17,"z":21},"block_id":9},{"move":{"x":-12,"y":-17,"z":22},"block_id":9},{"move":{"x":-12,"y":-17,"z":23},"block_id":9},{"move":{"x":-12,"y":-17,"z":24},"block_id":9},{"move":{"x":-12,"y":-17,"z":25},"block_id":9},{"move":{"x":-12,"y":-17,"z":26},"block_id":9},{"move":{"x":-12,"y":-17,"z":27},"block_id":9},{"move":{"x":-12,"y":-17,"z":28},"block_id":106,"rotate":{"x":2,"y":0,"z":0}},{"move":{"x":-12,"y":-17,"z":29},"block_id":9},{"move":{"x":-12,"y":-17,"z":30},"block_id":9},{"move":{"x":-12,"y":-17,"z":31},"block_id":9},{"move":{"x":-12,"y":-17,"z":32},"block_id":9},{"move":{"x":-12,"y":-17,"z":33},"block_id":9},{"move":{"x":-12,"y":-17,"z":34},"block_id":30},{"move":{"x":-12,"y":-17,"z":35},"block_id":9},{"move":{"x":-12,"y":-17,"z":39},"block_id":9},{"move":{"x":-12,"y":-17,"z":40},"block_id":9},{"move":{"x":-12,"y":-17,"z":41},"block_id":9},{"move":{"x":-12,"y":-17,"z":42},"block_id":9},{"move":{"x":-12,"y":-17,"z":43},"block_id":9},{"move":{"x":-12,"y":-17,"z":44},"block_id":8},{"move":{"x":-12,"y":-17,"z":45},"block_id":9},{"move":{"x":-12,"y":-17,"z":47},"block_id":9},{"move":{"x":-12,"y":-16,"z":3},"block_id":9},{"move":{"x":-12,"y":-16,"z":4},"block_id":146},{"move":{"x":-12,"y":-16,"z":5},"block_id":9},{"move":{"x":-12,"y":-16,"z":9},"block_id":9},{"move":{"x":-12,"y":-16,"z":10},"block_id":9},{"move":{"x":-12,"y":-16,"z":11},"block_id":146},{"move":{"x":-12,"y":-16,"z":18},"block_id":9},{"move":{"x":-12,"y":-16,"z":19},"block_id":9},{"move":{"x":-12,"y":-16,"z":20},"block_id":9},{"move":{"x":-12,"y":-16,"z":21},"block_id":9},{"move":{"x":-12,"y":-16,"z":22},"block_id":9},{"move":{"x":-12,"y":-16,"z":23},"block_id":632},{"move":{"x":-12,"y":-16,"z":24},"block_id":9},{"move":{"x":-12,"y":-16,"z":25},"block_id":9},{"move":{"x":-12,"y":-16,"z":26},"block_id":9},{"move":{"x":-12,"y":-16,"z":27},"block_id":9},{"move":{"x":-12,"y":-16,"z":28},"block_id":9},{"move":{"x":-12,"y":-16,"z":29},"block_id":9},{"move":{"x":-12,"y":-16,"z":30},"block_id":9},{"move":{"x":-12,"y":-16,"z":31},"block_id":9},{"move":{"x":-12,"y":-16,"z":32},"block_id":9},{"move":{"x":-12,"y":-16,"z":33},"block_id":9},{"move":{"x":-12,"y":-16,"z":34},"block_id":9},{"move":{"x":-12,"y":-16,"z":35},"block_id":9},{"move":{"x":-12,"y":-16,"z":39},"block_id":9},{"move":{"x":-12,"y":-16,"z":40},"block_id":9},{"move":{"x":-12,"y":-16,"z":41},"block_id":9},{"move":{"x":-12,"y":-16,"z":42},"block_id":9},{"move":{"x":-12,"y":-16,"z":43},"block_id":9},{"move":{"x":-12,"y":-16,"z":44},"block_id":9},{"move":{"x":-12,"y":-16,"z":45},"block_id":146},{"move":{"x":-12,"y":-16,"z":46},"block_id":9},{"move":{"x":-12,"y":-16,"z":47},"block_id":9},{"move":{"x":-12,"y":-15,"z":3},"block_id":9},{"move":{"x":-12,"y":-15,"z":4},"block_id":9},{"move":{"x":-12,"y":-15,"z":5},"block_id":9},{"move":{"x":-12,"y":-15,"z":6},"block_id":9},{"move":{"x":-12,"y":-15,"z":7},"block_id":9},{"move":{"x":-12,"y":-15,"z":8},"block_id":9},{"move":{"x":-12,"y":-15,"z":9},"block_id":8},{"move":{"x":-12,"y":-15,"z":10},"block_id":9},{"move":{"x":-12,"y":-15,"z":11},"block_id":9},{"move":{"x":-11,"y":-19,"z":3},"block_id":632},{"move":{"x":-11,"y":-19,"z":4},"block_id":9},{"move":{"x":-11,"y":-19,"z":5},"block_id":146},{"move":{"x":-11,"y":-19,"z":6},"block_id":9},{"move":{"x":-11,"y":-19,"z":7},"block_id":9},{"move":{"x":-11,"y":-19,"z":8},"block_id":9},{"move":{"x":-11,"y":-19,"z":9},"block_id":9},{"move":{"x":-11,"y":-19,"z":10},"block_id":9},{"move":{"x":-11,"y":-19,"z":11},"block_id":9},{"move":{"x":-11,"y":-19,"z":17},"block_id":9},{"move":{"x":-11,"y":-19,"z":18},"block_id":9},{"move":{"x":-11,"y":-19,"z":19},"block_id":9},{"move":{"x":-11,"y":-19,"z":20},"block_id":9},{"move":{"x":-11,"y":-19,"z":21},"block_id":9},{"move":{"x":-11,"y":-19,"z":26},"block_id":9},{"move":{"x":-11,"y":-19,"z":27},"block_id":8},{"move":{"x":-11,"y":-19,"z":28},"block_id":9},{"move":{"x":-11,"y":-19,"z":29},"block_id":9},{"move":{"x":-11,"y":-19,"z":30},"block_id":9},{"move":{"x":-11,"y":-19,"z":33},"block_id":9},{"move":{"x":-11,"y":-19,"z":34},"block_id":9},{"move":{"x":-11,"y":-19,"z":35},"block_id":9},{"move":{"x":-11,"y":-19,"z":45},"block_id":9},{"move":{"x":-11,"y":-19,"z":46},"block_id":9},{"move":{"x":-11,"y":-19,"z":47},"block_id":9},{"move":{"x":-11,"y":-18,"z":3},"block_id":9},{"move":{"x":-11,"y":-18,"z":4},"block_id":9},{"move":{"x":-11,"y":-18,"z":5},"block_id":9},{"move":{"x":-11,"y":-18,"z":6},"block_id":106,"rotate":{"x":2,"y":0,"z":0}},{"move":{"x":-11,"y":-18,"z":9},"block_id":8},{"move":{"x":-11,"y":-18,"z":10},"block_id":9},{"move":{"x":-11,"y":-18,"z":11},"block_id":9},{"move":{"x":-11,"y":-18,"z":17},"block_id":9},{"move":{"x":-11,"y":-18,"z":18},"block_id":106,"rotate":{"x":2,"y":0,"z":0}},{"move":{"x":-11,"y":-18,"z":19},"block_id":106,"rotate":{"x":1,"y":0,"z":0}},{"move":{"x":-11,"y":-18,"z":20},"block_id":30},{"move":{"x":-11,"y":-18,"z":21},"block_id":9},{"move":{"x":-11,"y":-18,"z":26},"block_id":146},{"move":{"x":-11,"y":-18,"z":30},"block_id":9},{"move":{"x":-11,"y":-18,"z":33},"block_id":9},{"move":{"x":-11,"y":-18,"z":35},"block_id":9},{"move":{"x":-11,"y":-18,"z":45},"block_id":9},{"move":{"x":-11,"y":-18,"z":47},"block_id":9},{"move":{"x":-11,"y":-17,"z":3},"block_id":9},{"move":{"x":-11,"y":-17,"z":4},"block_id":8},{"move":{"x":-11,"y":-17,"z":5},"block_id":9},{"move":{"x":-11,"y":-17,"z":6},"block_id":106,"rotate":{"x":2,"y":0,"z":0}},{"move":{"x":-11,"y":-17,"z":9},"block_id":9},{"move":{"x":-11,"y":-17,"z":10},"block_id":9},{"move":{"x":-11,"y":-17,"z":11},"block_id":9},{"move":{"x":-11,"y":-17,"z":17},"block_id":9},{"move":{"x":-11,"y":-17,"z":19},"block_id":106,"rotate":{"x":1,"y":0,"z":0}},{"move":{"x":-11,"y":-17,"z":21},"block_id":9},{"move":{"x":-11,"y":-17,"z":26},"block_id":9},{"move":{"x":-11,"y":-17,"z":30},"block_id":9},{"move":{"x":-11,"y":-17,"z":33},"block_id":9},{"move":{"x":-11,"y":-17,"z":35},"block_id":9},{"move":{"x":-11,"y":-17,"z":45},"block_id":9},{"move":{"x":-11,"y":-17,"z":47},"block_id":146},{"move":{"x":-11,"y":-16,"z":3},"block_id":83},{"move":{"x":-11,"y":-16,"z":4},"block_id":83},{"move":{"x":-11,"y":-16,"z":5},"block_id":9},{"move":{"x":-11,"y":-16,"z":6},"block_id":106,"rotate":{"x":2,"y":0,"z":0}},{"move":{"x":-11,"y":-16,"z":9},"block_id":9},{"move":{"x":-11,"y":-16,"z":10},"block_id":8},{"move":{"x":-11,"y":-16,"z":11},"block_id":9},{"move":{"x":-11,"y":-16,"z":17},"block_id":9},{"move":{"x":-11,"y":-16,"z":19},"block_id":106,"rotate":{"x":1,"y":0,"z":0}},{"move":{"x":-11,"y":-16,"z":21},"block_id":9},{"move":{"x":-11,"y":-16,"z":26},"block_id":9},{"move":{"x":-11,"y":-16,"z":27},"block_id":30},{"move":{"x":-11,"y":-16,"z":29},"block_id":30},{"move":{"x":-11,"y":-16,"z":30},"block_id":9},{"move":{"x":-11,"y":-16,"z":33},"block_id":9},{"move":{"x":-11,"y":-16,"z":34},"block_id":9},{"move":{"x":-11,"y":-16,"z":35},"block_id":9},{"move":{"x":-11,"y":-16,"z":45},"block_id":9},{"move":{"x":-11,"y":-16,"z":46},"block_id":9},{"move":{"x":-11,"y":-16,"z":47},"block_id":9},{"move":{"x":-11,"y":-15,"z":3},"block_id":9},{"move":{"x":-11,"y":-15,"z":4},"block_id":8},{"move":{"x":-11,"y":-15,"z":5},"block_id":146},{"move":{"x":-11,"y":-15,"z":6},"block_id":9},{"move":{"x":-11,"y":-15,"z":7},"block_id":9},{"move":{"x":-11,"y":-15,"z":8},"block_id":9},{"move":{"x":-11,"y":-15,"z":9},"block_id":9},{"move":{"x":-11,"y":-15,"z":10},"block_id":9},{"move":{"x":-11,"y":-15,"z":11},"block_id":9},{"move":{"x":-11,"y":-15,"z":17},"block_id":9},{"move":{"x":-11,"y":-15,"z":18},"block_id":9},{"move":{"x":-11,"y":-15,"z":19},"block_id":9},{"move":{"x":-11,"y":-15,"z":20},"block_id":9},{"move":{"x":-11,"y":-15,"z":21},"block_id":9},{"move":{"x":-11,"y":-15,"z":26},"block_id":83},{"move":{"x":-11,"y":-15,"z":27},"block_id":9},{"move":{"x":-11,"y":-15,"z":28},"block_id":9},{"move":{"x":-11,"y":-15,"z":29},"block_id":9},{"move":{"x":-11,"y":-15,"z":30},"block_id":9},{"move":{"x":-10,"y":-19,"z":5},"block_id":8},{"move":{"x":-10,"y":-19,"z":6},"block_id":9},{"move":{"x":-10,"y":-19,"z":7},"block_id":9},{"move":{"x":-10,"y":-19,"z":8},"block_id":9},{"move":{"x":-10,"y":-19,"z":9},"block_id":9},{"move":{"x":-10,"y":-19,"z":17},"block_id":9},{"move":{"x":-10,"y":-19,"z":18},"block_id":9},{"move":{"x":-10,"y":-19,"z":19},"block_id":9},{"move":{"x":-10,"y":-19,"z":20},"block_id":9},{"move":{"x":-10,"y":-19,"z":21},"block_id":9},{"move":{"x":-10,"y":-19,"z":26},"block_id":9},{"move":{"x":-10,"y":-19,"z":27},"block_id":9},{"move":{"x":-10,"y":-19,"z":28},"block_id":9},{"move":{"x":-10,"y":-19,"z":29},"block_id":9},{"move":{"x":-10,"y":-19,"z":30},"block_id":9},{"move":{"x":-10,"y":-19,"z":33},"block_id":9},{"move":{"x":-10,"y":-19,"z":34},"block_id":9},{"move":{"x":-10,"y":-19,"z":35},"block_id":8},{"move":{"x":-10,"y":-19,"z":45},"block_id":9},{"move":{"x":-10,"y":-19,"z":46},"block_id":8},{"move":{"x":-10,"y":-19,"z":47},"block_id":9},{"move":{"x":-10,"y":-18,"z":5},"block_id":9},{"move":{"x":-10,"y":-18,"z":8},"block_id":106,"rotate":{"x":0,"y":0,"z":0}},{"move":{"x":-10,"y":-18,"z":9},"block_id":9},{"move":{"x":-10,"y":-18,"z":17},"block_id":9},{"move":{"x":-10,"y":-18,"z":18},"block_id":106,"rotate":{"x":2,"y":0,"z":0}},{"move":{"x":-10,"y":-18,"z":20},"block_id":30},{"move":{"x":-10,"y":-18,"z":21},"block_id":9},{"move":{"x":-10,"y":-18,"z":26},"block_id":146},{"move":{"x":-10,"y":-18,"z":30},"block_id":9},{"move":{"x":-10,"y":-18,"z":33},"block_id":9},{"move":{"x":-10,"y":-18,"z":35},"block_id":9},{"move":{"x":-10,"y":-18,"z":45},"block_id":9},{"move":{"x":-10,"y":-18,"z":47},"block_id":9},{"move":{"x":-10,"y":-17,"z":5},"block_id":9},{"move":{"x":-10,"y":-17,"z":8},"block_id":106,"rotate":{"x":0,"y":0,"z":0}},{"move":{"x":-10,"y":-17,"z":9},"block_id":9},{"move":{"x":-10,"y":-17,"z":17},"block_id":146},{"move":{"x":-10,"y":-17,"z":18},"block_id":106,"rotate":{"x":2,"y":0,"z":0}},{"move":{"x":-10,"y":-17,"z":21},"block_id":9},{"move":{"x":-10,"y":-17,"z":26},"block_id":9},{"move":{"x":-10,"y":-17,"z":30},"block_id":9},{"move":{"x":-10,"y":-17,"z":33},"block_id":9},{"move":{"x":-10,"y":-17,"z":35},"block_id":9},{"move":{"x":-10,"y":-17,"z":45},"block_id":9},{"move":{"x":-10,"y":-17,"z":46},"block_id":30},{"move":{"x":-10,"y":-17,"z":47},"block_id":9},{"move":{"x":-10,"y":-16,"z":5},"block_id":9},{"move":{"x":-10,"y":-16,"z":9},"block_id":9},{"move":{"x":-10,"y":-16,"z":17},"block_id":9},{"move":{"x":-10,"y":-16,"z":21},"block_id":9},{"move":{"x":-10,"y":-16,"z":26},"block_id":9},{"move":{"x":-10,"y":-16,"z":30},"block_id":9},{"move":{"x":-10,"y":-16,"z":33},"block_id":9},{"move":{"x":-10,"y":-16,"z":34},"block_id":9},{"move":{"x":-10,"y":-16,"z":35},"block_id":9},{"move":{"x":-10,"y":-16,"z":45},"block_id":9},{"move":{"x":-10,"y":-16,"z":46},"block_id":146},{"move":{"x":-10,"y":-16,"z":47},"block_id":9},{"move":{"x":-10,"y":-15,"z":5},"block_id":9},{"move":{"x":-10,"y":-15,"z":6},"block_id":9},{"move":{"x":-10,"y":-15,"z":7},"block_id":9},{"move":{"x":-10,"y":-15,"z":8},"block_id":9},{"move":{"x":-10,"y":-15,"z":9},"block_id":9},{"move":{"x":-10,"y":-15,"z":17},"block_id":9},{"move":{"x":-10,"y":-15,"z":18},"block_id":9},{"move":{"x":-10,"y":-15,"z":19},"block_id":9},{"move":{"x":-10,"y":-15,"z":20},"block_id":9},{"move":{"x":-10,"y":-15,"z":21},"block_id":9},{"move":{"x":-10,"y":-15,"z":26},"block_id":9},{"move":{"x":-10,"y":-15,"z":27},"block_id":9},{"move":{"x":-10,"y":-15,"z":28},"block_id":8},{"move":{"x":-10,"y":-15,"z":29},"block_id":9},{"move":{"x":-10,"y":-15,"z":30},"block_id":8},{"move":{"x":-9,"y":-19,"z":5},"block_id":9},{"move":{"x":-9,"y":-19,"z":6},"block_id":9},{"move":{"x":-9,"y":-19,"z":7},"block_id":146},{"move":{"x":-9,"y":-19,"z":8},"block_id":9},{"move":{"x":-9,"y":-19,"z":9},"block_id":8},{"move":{"x":-9,"y":-19,"z":15},"block_id":9},{"move":{"x":-9,"y":-19,"z":16},"block_id":9},{"move":{"x":-9,"y":-19,"z":17},"block_id":83},{"move":{"x":-9,"y":-19,"z":18},"block_id":9},{"move":{"x":-9,"y":-19,"z":19},"block_id":9},{"move":{"x":-9,"y":-19,"z":20},"block_id":9},{"move":{"x":-9,"y":-19,"z":21},"block_id":9},{"move":{"x":-9,"y":-19,"z":22},"block_id":9},{"move":{"x":-9,"y":-19,"z":23},"block_id":9},{"move":{"x":-9,"y":-19,"z":24},"block_id":9},{"move":{"x":-9,"y":-19,"z":25},"block_id":9},{"move":{"x":-9,"y":-19,"z":26},"block_id":9},{"move":{"x":-9,"y":-19,"z":27},"block_id":9},{"move":{"x":-9,"y":-19,"z":28},"block_id":9},{"move":{"x":-9,"y":-19,"z":29},"block_id":146},{"move":{"x":-9,"y":-19,"z":30},"block_id":9},{"move":{"x":-9,"y":-19,"z":31},"block_id":146},{"move":{"x":-9,"y":-19,"z":32},"block_id":9},{"move":{"x":-9,"y":-19,"z":33},"block_id":146},{"move":{"x":-9,"y":-19,"z":34},"block_id":9},{"move":{"x":-9,"y":-19,"z":35},"block_id":9},{"move":{"x":-9,"y":-19,"z":45},"block_id":9},{"move":{"x":-9,"y":-19,"z":46},"block_id":9},{"move":{"x":-9,"y":-19,"z":47},"block_id":8},{"move":{"x":-9,"y":-18,"z":5},"block_id":9},{"move":{"x":-9,"y":-18,"z":6},"block_id":106,"rotate":{"x":3,"y":0,"z":0}},{"move":{"x":-9,"y":-18,"z":7},"block_id":106,"rotate":{"x":3,"y":0,"z":0}},{"move":{"x":-9,"y":-18,"z":8},"block_id":106,"rotate":{"x":0,"y":0,"z":0}},{"move":{"x":-9,"y":-18,"z":9},"block_id":9},{"move":{"x":-9,"y":-18,"z":15},"block_id":9},{"move":{"x":-9,"y":-18,"z":16},"block_id":9},{"move":{"x":-9,"y":-18,"z":17},"block_id":9},{"move":{"x":-9,"y":-18,"z":18},"block_id":106,"rotate":{"x":2,"y":0,"z":0}},{"move":{"x":-9,"y":-18,"z":20},"block_id":106,"rotate":{"x":0,"y":0,"z":0}},{"move":{"x":-9,"y":-18,"z":21},"block_id":9},{"move":{"x":-9,"y":-18,"z":22},"block_id":9},{"move":{"x":-9,"y":-18,"z":23},"block_id":146},{"move":{"x":-9,"y":-18,"z":24},"block_id":9},{"move":{"x":-9,"y":-18,"z":25},"block_id":9},{"move":{"x":-9,"y":-18,"z":26},"block_id":9},{"move":{"x":-9,"y":-18,"z":30},"block_id":9},{"move":{"x":-9,"y":-18,"z":31},"block_id":9},{"move":{"x":-9,"y":-18,"z":32},"block_id":9},{"move":{"x":-9,"y":-18,"z":33},"block_id":9},{"move":{"x":-9,"y":-18,"z":35},"block_id":67,"extra_data":{"point":{"x":0,"y":0.1,"z":0}},"rotate":{"x":3,"y":0,"z":0}},{"move":{"x":-9,"y":-18,"z":45},"block_id":146},{"move":{"x":-9,"y":-18,"z":47},"block_id":9},{"move":{"x":-9,"y":-17,"z":5},"block_id":9},{"move":{"x":-9,"y":-17,"z":6},"block_id":106,"rotate":{"x":3,"y":0,"z":0}},{"move":{"x":-9,"y":-17,"z":7},"block_id":106,"rotate":{"x":3,"y":0,"z":0}},{"move":{"x":-9,"y":-17,"z":8},"block_id":106,"rotate":{"x":0,"y":0,"z":0}},{"move":{"x":-9,"y":-17,"z":9},"block_id":9},{"move":{"x":-9,"y":-17,"z":15},"block_id":9},{"move":{"x":-9,"y":-17,"z":16},"block_id":9},{"move":{"x":-9,"y":-17,"z":17},"block_id":9},{"move":{"x":-9,"y":-17,"z":18},"block_id":106,"rotate":{"x":2,"y":0,"z":0}},{"move":{"x":-9,"y":-17,"z":20},"block_id":106,"rotate":{"x":0,"y":0,"z":0}},{"move":{"x":-9,"y":-17,"z":21},"block_id":9},{"move":{"x":-9,"y":-17,"z":22},"block_id":9},{"move":{"x":-9,"y":-17,"z":23},"block_id":9},{"move":{"x":-9,"y":-17,"z":24},"block_id":9},{"move":{"x":-9,"y":-17,"z":25},"block_id":9},{"move":{"x":-9,"y":-17,"z":26},"block_id":9},{"move":{"x":-9,"y":-17,"z":27},"block_id":106,"rotate":{"x":2,"y":0,"z":0}},{"move":{"x":-9,"y":-17,"z":30},"block_id":9},{"move":{"x":-9,"y":-17,"z":31},"block_id":146},{"move":{"x":-9,"y":-17,"z":32},"block_id":9},{"move":{"x":-9,"y":-17,"z":33},"block_id":9},{"move":{"x":-9,"y":-17,"z":34},"block_id":106,"rotate":{"x":0,"y":0,"z":0}},{"move":{"x":-9,"y":-17,"z":35},"block_id":9},{"move":{"x":-9,"y":-17,"z":45},"block_id":9},{"move":{"x":-9,"y":-17,"z":47},"block_id":146},{"move":{"x":-9,"y":-16,"z":5},"block_id":9},{"move":{"x":-9,"y":-16,"z":7},"block_id":106,"rotate":{"x":3,"y":0,"z":0}},{"move":{"x":-9,"y":-16,"z":9},"block_id":9},{"move":{"x":-9,"y":-16,"z":15},"block_id":8},{"move":{"x":-9,"y":-16,"z":16},"block_id":9},{"move":{"x":-9,"y":-16,"z":17},"block_id":9},{"move":{"x":-9,"y":-16,"z":21},"block_id":9},{"move":{"x":-9,"y":-16,"z":22},"block_id":9},{"move":{"x":-9,"y":-16,"z":23},"block_id":67,"extra_data":{"point":{"x":0,"y":0.1,"z":0}},"rotate":{"x":1,"y":0,"z":0}},{"move":{"x":-9,"y":-16,"z":24},"block_id":9},{"move":{"x":-9,"y":-16,"z":25},"block_id":9},{"move":{"x":-9,"y":-16,"z":26},"block_id":9},{"move":{"x":-9,"y":-16,"z":30},"block_id":9},{"move":{"x":-9,"y":-16,"z":31},"block_id":9},{"move":{"x":-9,"y":-16,"z":32},"block_id":146},{"move":{"x":-9,"y":-16,"z":33},"block_id":9},{"move":{"x":-9,"y":-16,"z":34},"block_id":9},{"move":{"x":-9,"y":-16,"z":35},"block_id":9},{"move":{"x":-9,"y":-16,"z":45},"block_id":9},{"move":{"x":-9,"y":-16,"z":46},"block_id":9},{"move":{"x":-9,"y":-16,"z":47},"block_id":9},{"move":{"x":-9,"y":-15,"z":5},"block_id":9},{"move":{"x":-9,"y":-15,"z":6},"block_id":9},{"move":{"x":-9,"y":-15,"z":7},"block_id":9},{"move":{"x":-9,"y":-15,"z":8},"block_id":9},{"move":{"x":-9,"y":-15,"z":9},"block_id":9},{"move":{"x":-9,"y":-15,"z":15},"block_id":632},{"move":{"x":-9,"y":-15,"z":16},"block_id":8},{"move":{"x":-9,"y":-15,"z":17},"block_id":9},{"move":{"x":-9,"y":-15,"z":18},"block_id":9},{"move":{"x":-9,"y":-15,"z":19},"block_id":9},{"move":{"x":-9,"y":-15,"z":20},"block_id":9},{"move":{"x":-9,"y":-15,"z":21},"block_id":9},{"move":{"x":-9,"y":-15,"z":22},"block_id":9},{"move":{"x":-9,"y":-15,"z":23},"block_id":9},{"move":{"x":-9,"y":-15,"z":24},"block_id":9},{"move":{"x":-9,"y":-15,"z":25},"block_id":9},{"move":{"x":-9,"y":-15,"z":26},"block_id":9},{"move":{"x":-9,"y":-15,"z":27},"block_id":9},{"move":{"x":-9,"y":-15,"z":28},"block_id":9},{"move":{"x":-9,"y":-15,"z":29},"block_id":9},{"move":{"x":-9,"y":-15,"z":30},"block_id":9},{"move":{"x":-9,"y":-15,"z":31},"block_id":9},{"move":{"x":-9,"y":-15,"z":32},"block_id":9},{"move":{"x":-8,"y":-19,"z":0},"block_id":9},{"move":{"x":-8,"y":-19,"z":1},"block_id":9},{"move":{"x":-8,"y":-19,"z":2},"block_id":9},{"move":{"x":-8,"y":-19,"z":3},"block_id":9},{"move":{"x":-8,"y":-19,"z":4},"block_id":9},{"move":{"x":-8,"y":-19,"z":5},"block_id":9},{"move":{"x":-8,"y":-19,"z":6},"block_id":9},{"move":{"x":-8,"y":-19,"z":7},"block_id":9},{"move":{"x":-8,"y":-19,"z":8},"block_id":9},{"move":{"x":-8,"y":-19,"z":9},"block_id":9},{"move":{"x":-8,"y":-19,"z":10},"block_id":9},{"move":{"x":-8,"y":-19,"z":11},"block_id":9},{"move":{"x":-8,"y":-19,"z":12},"block_id":9},{"move":{"x":-8,"y":-19,"z":13},"block_id":9},{"move":{"x":-8,"y":-19,"z":14},"block_id":9},{"move":{"x":-8,"y":-19,"z":15},"block_id":9},{"move":{"x":-8,"y":-19,"z":16},"block_id":9},{"move":{"x":-8,"y":-19,"z":17},"block_id":9},{"move":{"x":-8,"y":-19,"z":18},"block_id":8},{"move":{"x":-8,"y":-19,"z":19},"block_id":146},{"move":{"x":-8,"y":-19,"z":20},"block_id":9},{"move":{"x":-8,"y":-19,"z":21},"block_id":9},{"move":{"x":-8,"y":-19,"z":22},"block_id":632},{"move":{"x":-8,"y":-19,"z":23},"block_id":8},{"move":{"x":-8,"y":-19,"z":24},"block_id":9},{"move":{"x":-8,"y":-19,"z":25},"block_id":9},{"move":{"x":-8,"y":-19,"z":26},"block_id":9},{"move":{"x":-8,"y":-19,"z":27},"block_id":146},{"move":{"x":-8,"y":-19,"z":28},"block_id":9},{"move":{"x":-8,"y":-19,"z":29},"block_id":9},{"move":{"x":-8,"y":-19,"z":30},"block_id":9},{"move":{"x":-8,"y":-19,"z":31},"block_id":9},{"move":{"x":-8,"y":-19,"z":32},"block_id":9},{"move":{"x":-8,"y":-19,"z":33},"block_id":9},{"move":{"x":-8,"y":-19,"z":34},"block_id":9},{"move":{"x":-8,"y":-19,"z":35},"block_id":9},{"move":{"x":-8,"y":-19,"z":36},"block_id":9},{"move":{"x":-8,"y":-19,"z":37},"block_id":9},{"move":{"x":-8,"y":-19,"z":38},"block_id":9},{"move":{"x":-8,"y":-19,"z":39},"block_id":9},{"move":{"x":-8,"y":-19,"z":40},"block_id":9},{"move":{"x":-8,"y":-19,"z":41},"block_id":9},{"move":{"x":-8,"y":-19,"z":42},"block_id":9},{"move":{"x":-8,"y":-19,"z":43},"block_id":146},{"move":{"x":-8,"y":-19,"z":44},"block_id":9},{"move":{"x":-8,"y":-19,"z":45},"block_id":8},{"move":{"x":-8,"y":-19,"z":46},"block_id":146},{"move":{"x":-8,"y":-19,"z":47},"block_id":8},{"move":{"x":-8,"y":-18,"z":0},"block_id":9},{"move":{"x":-8,"y":-18,"z":1},"block_id":9},{"move":{"x":-8,"y":-18,"z":2},"block_id":9},{"move":{"x":-8,"y":-18,"z":3},"block_id":8},{"move":{"x":-8,"y":-18,"z":4},"block_id":9},{"move":{"x":-8,"y":-18,"z":5},"block_id":9},{"move":{"x":-8,"y":-18,"z":6},"block_id":9},{"move":{"x":-8,"y":-18,"z":7},"block_id":30},{"move":{"x":-8,"y":-18,"z":8},"block_id":9},{"move":{"x":-8,"y":-18,"z":9},"block_id":9},{"move":{"x":-8,"y":-18,"z":10},"block_id":9},{"move":{"x":-8,"y":-18,"z":11},"block_id":9},{"move":{"x":-8,"y":-18,"z":12},"block_id":9},{"move":{"x":-8,"y":-18,"z":13},"block_id":9},{"move":{"x":-8,"y":-18,"z":14},"block_id":9},{"move":{"x":-8,"y":-18,"z":15},"block_id":146},{"move":{"x":-8,"y":-18,"z":16},"block_id":9},{"move":{"x":-8,"y":-18,"z":17},"block_id":9},{"move":{"x":-8,"y":-18,"z":21},"block_id":106,"rotate":{"x":1,"y":0,"z":0}},{"move":{"x":-8,"y":-18,"z":23},"block_id":106,"rotate":{"x":1,"y":0,"z":0}},{"move":{"x":-8,"y":-18,"z":24},"block_id":106,"rotate":{"x":1,"y":0,"z":0}},{"move":{"x":-8,"y":-18,"z":25},"block_id":106,"rotate":{"x":1,"y":0,"z":0}},{"move":{"x":-8,"y":-18,"z":30},"block_id":9},{"move":{"x":-8,"y":-18,"z":31},"block_id":9},{"move":{"x":-8,"y":-18,"z":32},"block_id":9},{"move":{"x":-8,"y":-18,"z":33},"block_id":9},{"move":{"x":-8,"y":-18,"z":35},"block_id":9},{"move":{"x":-8,"y":-18,"z":36},"block_id":9},{"move":{"x":-8,"y":-18,"z":37},"block_id":9},{"move":{"x":-8,"y":-18,"z":38},"block_id":9},{"move":{"x":-8,"y":-18,"z":39},"block_id":9},{"move":{"x":-8,"y":-18,"z":40},"block_id":9},{"move":{"x":-8,"y":-18,"z":41},"block_id":9},{"move":{"x":-8,"y":-18,"z":42},"block_id":9},{"move":{"x":-8,"y":-18,"z":43},"block_id":9},{"move":{"x":-8,"y":-18,"z":44},"block_id":9},{"move":{"x":-8,"y":-18,"z":45},"block_id":9},{"move":{"x":-8,"y":-18,"z":47},"block_id":9},{"move":{"x":-8,"y":-17,"z":0},"block_id":9},{"move":{"x":-8,"y":-17,"z":1},"block_id":9},{"move":{"x":-8,"y":-17,"z":2},"block_id":9},{"move":{"x":-8,"y":-17,"z":3},"block_id":8},{"move":{"x":-8,"y":-17,"z":4},"block_id":9},{"move":{"x":-8,"y":-17,"z":5},"block_id":9},{"move":{"x":-8,"y":-17,"z":6},"block_id":9},{"move":{"x":-8,"y":-17,"z":8},"block_id":8},{"move":{"x":-8,"y":-17,"z":9},"block_id":9},{"move":{"x":-8,"y":-17,"z":10},"block_id":9},{"move":{"x":-8,"y":-17,"z":11},"block_id":9},{"move":{"x":-8,"y":-17,"z":12},"block_id":8},{"move":{"x":-8,"y":-17,"z":13},"block_id":9},{"move":{"x":-8,"y":-17,"z":14},"block_id":9},{"move":{"x":-8,"y":-17,"z":15},"block_id":9},{"move":{"x":-8,"y":-17,"z":16},"block_id":9},{"move":{"x":-8,"y":-17,"z":17},"block_id":9},{"move":{"x":-8,"y":-17,"z":21},"block_id":106,"rotate":{"x":1,"y":0,"z":0}},{"move":{"x":-8,"y":-17,"z":22},"block_id":106,"rotate":{"x":1,"y":0,"z":0}},{"move":{"x":-8,"y":-17,"z":24},"block_id":106,"rotate":{"x":1,"y":0,"z":0}},{"move":{"x":-8,"y":-17,"z":25},"block_id":106,"rotate":{"x":1,"y":0,"z":0}},{"move":{"x":-8,"y":-17,"z":26},"block_id":106,"rotate":{"x":1,"y":0,"z":0}},{"move":{"x":-8,"y":-17,"z":30},"block_id":9},{"move":{"x":-8,"y":-17,"z":31},"block_id":8},{"move":{"x":-8,"y":-17,"z":32},"block_id":9},{"move":{"x":-8,"y":-17,"z":33},"block_id":9},{"move":{"x":-8,"y":-17,"z":35},"block_id":9},{"move":{"x":-8,"y":-17,"z":36},"block_id":9},{"move":{"x":-8,"y":-17,"z":37},"block_id":9},{"move":{"x":-8,"y":-17,"z":38},"block_id":9},{"move":{"x":-8,"y":-17,"z":39},"block_id":9},{"move":{"x":-8,"y":-17,"z":40},"block_id":9},{"move":{"x":-8,"y":-17,"z":41},"block_id":9},{"move":{"x":-8,"y":-17,"z":42},"block_id":9},{"move":{"x":-8,"y":-17,"z":43},"block_id":9},{"move":{"x":-8,"y":-17,"z":44},"block_id":146},{"move":{"x":-8,"y":-17,"z":45},"block_id":9},{"move":{"x":-8,"y":-17,"z":46},"block_id":30},{"move":{"x":-8,"y":-17,"z":47},"block_id":9},{"move":{"x":-8,"y":-16,"z":0},"block_id":9},{"move":{"x":-8,"y":-16,"z":1},"block_id":9},{"move":{"x":-8,"y":-16,"z":2},"block_id":9},{"move":{"x":-8,"y":-16,"z":3},"block_id":9},{"move":{"x":-8,"y":-16,"z":4},"block_id":83},{"move":{"x":-8,"y":-16,"z":5},"block_id":8},{"move":{"x":-8,"y":-16,"z":6},"block_id":9},{"move":{"x":-8,"y":-16,"z":7},"block_id":9},{"move":{"x":-8,"y":-16,"z":8},"block_id":9},{"move":{"x":-8,"y":-16,"z":9},"block_id":9},{"move":{"x":-8,"y":-16,"z":10},"block_id":9},{"move":{"x":-8,"y":-16,"z":11},"block_id":9},{"move":{"x":-8,"y":-16,"z":12},"block_id":9},{"move":{"x":-8,"y":-16,"z":13},"block_id":9},{"move":{"x":-8,"y":-16,"z":14},"block_id":9},{"move":{"x":-8,"y":-16,"z":15},"block_id":9},{"move":{"x":-8,"y":-16,"z":16},"block_id":146},{"move":{"x":-8,"y":-16,"z":17},"block_id":9},{"move":{"x":-8,"y":-16,"z":21},"block_id":106,"rotate":{"x":1,"y":0,"z":0}},{"move":{"x":-8,"y":-16,"z":22},"block_id":106,"rotate":{"x":1,"y":0,"z":0}},{"move":{"x":-8,"y":-16,"z":24},"block_id":106,"rotate":{"x":1,"y":0,"z":0}},{"move":{"x":-8,"y":-16,"z":30},"block_id":8},{"move":{"x":-8,"y":-16,"z":31},"block_id":9},{"move":{"x":-8,"y":-16,"z":32},"block_id":9},{"move":{"x":-8,"y":-16,"z":33},"block_id":9},{"move":{"x":-8,"y":-16,"z":34},"block_id":9},{"move":{"x":-8,"y":-16,"z":35},"block_id":9},{"move":{"x":-8,"y":-16,"z":36},"block_id":9},{"move":{"x":-8,"y":-16,"z":37},"block_id":9},{"move":{"x":-8,"y":-16,"z":38},"block_id":9},{"move":{"x":-8,"y":-16,"z":39},"block_id":9},{"move":{"x":-8,"y":-16,"z":40},"block_id":9},{"move":{"x":-8,"y":-16,"z":41},"block_id":9},{"move":{"x":-8,"y":-16,"z":42},"block_id":9},{"move":{"x":-8,"y":-16,"z":43},"block_id":9},{"move":{"x":-8,"y":-16,"z":44},"block_id":9},{"move":{"x":-8,"y":-16,"z":45},"block_id":146},{"move":{"x":-8,"y":-16,"z":46},"block_id":9},{"move":{"x":-8,"y":-16,"z":47},"block_id":9},{"move":{"x":-8,"y":-15,"z":15},"block_id":9},{"move":{"x":-8,"y":-15,"z":16},"block_id":9},{"move":{"x":-8,"y":-15,"z":17},"block_id":9},{"move":{"x":-8,"y":-15,"z":18},"block_id":9},{"move":{"x":-8,"y":-15,"z":19},"block_id":9},{"move":{"x":-8,"y":-15,"z":20},"block_id":9},{"move":{"x":-8,"y":-15,"z":21},"block_id":9},{"move":{"x":-8,"y":-15,"z":22},"block_id":9},{"move":{"x":-8,"y":-15,"z":23},"block_id":146},{"move":{"x":-8,"y":-15,"z":24},"block_id":9},{"move":{"x":-8,"y":-15,"z":25},"block_id":9},{"move":{"x":-8,"y":-15,"z":26},"block_id":9},{"move":{"x":-8,"y":-15,"z":27},"block_id":9},{"move":{"x":-8,"y":-15,"z":28},"block_id":9},{"move":{"x":-8,"y":-15,"z":29},"block_id":146},{"move":{"x":-8,"y":-15,"z":30},"block_id":146},{"move":{"x":-8,"y":-15,"z":31},"block_id":9},{"move":{"x":-8,"y":-15,"z":32},"block_id":9},{"move":{"x":-8,"y":3,"z":16},"block_id":67,"extra_data":{"point":{"x":0,"y":0.1,"z":0}},"rotate":{"x":3,"y":0,"z":0}},{"move":{"x":-8,"y":3,"z":17},"block_id":67,"extra_data":{"point":{"x":0,"y":0.1,"z":0}},"rotate":{"x":3,"y":0,"z":0}},{"move":{"x":-8,"y":3,"z":18},"block_id":67,"extra_data":{"point":{"x":0,"y":0.1,"z":0}},"rotate":{"x":3,"y":0,"z":0}},{"move":{"x":-8,"y":3,"z":19},"block_id":67,"extra_data":{"point":{"x":0,"y":0.1,"z":0}},"rotate":{"x":3,"y":0,"z":0}},{"move":{"x":-8,"y":3,"z":20},"block_id":146},{"move":{"x":-8,"y":3,"z":21},"block_id":67,"extra_data":{"point":{"x":0,"y":0.1,"z":0}},"rotate":{"x":3,"y":0,"z":0}},{"move":{"x":-8,"y":3,"z":22},"block_id":67,"extra_data":{"point":{"x":0,"y":0.1,"z":0}},"rotate":{"x":3,"y":0,"z":0}},{"move":{"x":-8,"y":3,"z":23},"block_id":67,"extra_data":{"point":{"x":0,"y":0.1,"z":0}},"rotate":{"x":3,"y":0,"z":0}},{"move":{"x":-8,"y":3,"z":24},"block_id":67,"extra_data":{"point":{"x":0,"y":0.1,"z":0}},"rotate":{"x":3,"y":0,"z":0}},{"move":{"x":-8,"y":3,"z":25},"block_id":67,"extra_data":{"point":{"x":0,"y":0.1,"z":0}},"rotate":{"x":3,"y":0,"z":0}},{"move":{"x":-8,"y":3,"z":26},"block_id":67,"extra_data":{"point":{"x":0,"y":0.1,"z":0}},"rotate":{"x":3,"y":0,"z":0}},{"move":{"x":-8,"y":3,"z":27},"block_id":146},{"move":{"x":-8,"y":3,"z":28},"block_id":67,"extra_data":{"point":{"x":0,"y":0.1,"z":0}},"rotate":{"x":3,"y":0,"z":0}},{"move":{"x":-8,"y":3,"z":29},"block_id":67,"extra_data":{"point":{"x":0,"y":0.1,"z":0}},"rotate":{"x":3,"y":0,"z":0}},{"move":{"x":-8,"y":3,"z":30},"block_id":67,"extra_data":{"point":{"x":0,"y":0.1,"z":0}},"rotate":{"x":3,"y":0,"z":0}},{"move":{"x":-8,"y":3,"z":31},"block_id":67,"extra_data":{"point":{"x":0,"y":0.1,"z":0}},"rotate":{"x":2,"y":0,"z":0}},{"move":{"x":-8,"y":4,"z":20},"block_id":67,"extra_data":{"point":{"x":0,"y":0.1,"z":0}},"rotate":{"x":3,"y":0,"z":0}},{"move":{"x":-7,"y":-20,"z":35},"block_id":9},{"move":{"x":-7,"y":-20,"z":36},"block_id":9},{"move":{"x":-7,"y":-20,"z":37},"block_id":9},{"move":{"x":-7,"y":-20,"z":40},"block_id":9},{"move":{"x":-7,"y":-19,"z":0},"block_id":8},{"move":{"x":-7,"y":-19,"z":1},"block_id":9},{"move":{"x":-7,"y":-19,"z":2},"block_id":67,"extra_data":{"point":{"x":0,"y":0.9,"z":0}},"rotate":{"x":0,"y":0,"z":0}},{"move":{"x":-7,"y":-19,"z":3},"block_id":9},{"move":{"x":-7,"y":-19,"z":4},"block_id":9},{"move":{"x":-7,"y":-19,"z":5},"block_id":9},{"move":{"x":-7,"y":-19,"z":6},"block_id":9},{"move":{"x":-7,"y":-19,"z":7},"block_id":9},{"move":{"x":-7,"y":-19,"z":8},"block_id":9},{"move":{"x":-7,"y":-19,"z":9},"block_id":9},{"move":{"x":-7,"y":-19,"z":10},"block_id":9},{"move":{"x":-7,"y":-19,"z":11},"block_id":9},{"move":{"x":-7,"y":-19,"z":12},"block_id":9},{"move":{"x":-7,"y":-19,"z":13},"block_id":9},{"move":{"x":-7,"y":-19,"z":14},"block_id":9},{"move":{"x":-7,"y":-19,"z":15},"block_id":9},{"move":{"x":-7,"y":-19,"z":16},"block_id":9},{"move":{"x":-7,"y":-19,"z":17},"block_id":9},{"move":{"x":-7,"y":-19,"z":18},"block_id":8},{"move":{"x":-7,"y":-19,"z":19},"block_id":8},{"move":{"x":-7,"y":-19,"z":20},"block_id":83},{"move":{"x":-7,"y":-19,"z":21},"block_id":9},{"move":{"x":-7,"y":-19,"z":22},"block_id":9},{"move":{"x":-7,"y":-19,"z":23},"block_id":146},{"move":{"x":-7,"y":-19,"z":24},"block_id":9},{"move":{"x":-7,"y":-19,"z":25},"block_id":146},{"move":{"x":-7,"y":-19,"z":26},"block_id":9},{"move":{"x":-7,"y":-19,"z":27},"block_id":9},{"move":{"x":-7,"y":-19,"z":28},"block_id":9},{"move":{"x":-7,"y":-19,"z":29},"block_id":9},{"move":{"x":-7,"y":-19,"z":30},"block_id":9},{"move":{"x":-7,"y":-19,"z":31},"block_id":9},{"move":{"x":-7,"y":-19,"z":32},"block_id":9},{"move":{"x":-7,"y":-19,"z":33},"block_id":9},{"move":{"x":-7,"y":-19,"z":34},"block_id":9},{"move":{"x":-7,"y":-19,"z":37},"block_id":83},{"move":{"x":-7,"y":-19,"z":38},"block_id":83},{"move":{"x":-7,"y":-19,"z":39},"block_id":98},{"move":{"x":-7,"y":-19,"z":40},"block_id":199,"extra_data":{"n":"SPAWNER"}},{"move":{"x":-7,"y":-19,"z":41},"block_id":9},{"move":{"x":-7,"y":-19,"z":42},"block_id":9},{"move":{"x":-7,"y":-19,"z":43},"block_id":9},{"move":{"x":-7,"y":-19,"z":44},"block_id":8},{"move":{"x":-7,"y":-19,"z":45},"block_id":9},{"move":{"x":-7,"y":-19,"z":46},"block_id":9},{"move":{"x":-7,"y":-19,"z":47},"block_id":9},{"move":{"x":-7,"y":-18,"z":0},"block_id":9},{"move":{"x":-7,"y":-18,"z":2},"block_id":106,"rotate":{"x":1,"y":0,"z":0}},{"move":{"x":-7,"y":-18,"z":4},"block_id":106,"rotate":{"x":1,"y":0,"z":0}},{"move":{"x":-7,"y":-18,"z":9},"block_id":106,"rotate":{"x":3,"y":0,"z":0}},{"move":{"x":-7,"y":-18,"z":10},"block_id":106,"rotate":{"x":1,"y":0,"z":0}},{"move":{"x":-7,"y":-18,"z":14},"block_id":9},{"move":{"x":-7,"y":-18,"z":15},"block_id":9},{"move":{"x":-7,"y":-18,"z":16},"block_id":9},{"move":{"x":-7,"y":-18,"z":17},"block_id":9},{"move":{"x":-7,"y":-18,"z":30},"block_id":9},{"move":{"x":-7,"y":-18,"z":31},"block_id":9},{"move":{"x":-7,"y":-18,"z":32},"block_id":9},{"move":{"x":-7,"y":-18,"z":33},"block_id":9},{"move":{"x":-7,"y":-18,"z":37},"block_id":632},{"move":{"x":-7,"y":-18,"z":39},"block_id":83},{"move":{"x":-7,"y":-18,"z":41},"block_id":9},{"move":{"x":-7,"y":-18,"z":42},"block_id":9},{"move":{"x":-7,"y":-18,"z":43},"block_id":106,"rotate":{"x":1,"y":0,"z":0}},{"move":{"x":-7,"y":-18,"z":44},"block_id":106,"rotate":{"x":3,"y":0,"z":0}},{"move":{"x":-7,"y":-18,"z":45},"block_id":106,"rotate":{"x":3,"y":0,"z":0}},{"move":{"x":-7,"y":-18,"z":46},"block_id":106,"rotate":{"x":1,"y":0,"z":0}},{"move":{"x":-7,"y":-18,"z":47},"block_id":9},{"move":{"x":-7,"y":-17,"z":0},"block_id":9},{"move":{"x":-7,"y":-17,"z":3},"block_id":106,"rotate":{"x":3,"y":0,"z":0}},{"move":{"x":-7,"y":-17,"z":4},"block_id":106,"rotate":{"x":1,"y":0,"z":0}},{"move":{"x":-7,"y":-17,"z":5},"block_id":30},{"move":{"x":-7,"y":-17,"z":8},"block_id":30},{"move":{"x":-7,"y":-17,"z":11},"block_id":30},{"move":{"x":-7,"y":-17,"z":12},"block_id":106,"rotate":{"x":1,"y":0,"z":0}},{"move":{"x":-7,"y":-17,"z":13},"block_id":106,"rotate":{"x":1,"y":0,"z":0}},{"move":{"x":-7,"y":-17,"z":14},"block_id":9},{"move":{"x":-7,"y":-17,"z":15},"block_id":9},{"move":{"x":-7,"y":-17,"z":16},"block_id":9},{"move":{"x":-7,"y":-17,"z":17},"block_id":9},{"move":{"x":-7,"y":-17,"z":30},"block_id":9},{"move":{"x":-7,"y":-17,"z":31},"block_id":9},{"move":{"x":-7,"y":-17,"z":32},"block_id":9},{"move":{"x":-7,"y":-17,"z":33},"block_id":9},{"move":{"x":-7,"y":-17,"z":34},"block_id":106,"rotate":{"x":1,"y":0,"z":0}},{"move":{"x":-7,"y":-17,"z":37},"block_id":632},{"move":{"x":-7,"y":-17,"z":39},"block_id":98},{"move":{"x":-7,"y":-17,"z":41},"block_id":9},{"move":{"x":-7,"y":-17,"z":42},"block_id":632},{"move":{"x":-7,"y":-17,"z":46},"block_id":106,"rotate":{"x":0,"y":0,"z":0}},{"move":{"x":-7,"y":-17,"z":47},"block_id":9},{"move":{"x":-7,"y":-16,"z":0},"block_id":9},{"move":{"x":-7,"y":-16,"z":1},"block_id":9},{"move":{"x":-7,"y":-16,"z":2},"block_id":9},{"move":{"x":-7,"y":-16,"z":3},"block_id":9},{"move":{"x":-7,"y":-16,"z":4},"block_id":9},{"move":{"x":-7,"y":-16,"z":5},"block_id":9},{"move":{"x":-7,"y":-16,"z":6},"block_id":9},{"move":{"x":-7,"y":-16,"z":7},"block_id":9},{"move":{"x":-7,"y":-16,"z":8},"block_id":8},{"move":{"x":-7,"y":-16,"z":9},"block_id":9},{"move":{"x":-7,"y":-16,"z":10},"block_id":9},{"move":{"x":-7,"y":-16,"z":11},"block_id":9},{"move":{"x":-7,"y":-16,"z":12},"block_id":9},{"move":{"x":-7,"y":-16,"z":13},"block_id":9},{"move":{"x":-7,"y":-16,"z":14},"block_id":146},{"move":{"x":-7,"y":-16,"z":15},"block_id":9},{"move":{"x":-7,"y":-16,"z":16},"block_id":9},{"move":{"x":-7,"y":-16,"z":17},"block_id":9},{"move":{"x":-7,"y":-16,"z":30},"block_id":9},{"move":{"x":-7,"y":-16,"z":31},"block_id":9},{"move":{"x":-7,"y":-16,"z":32},"block_id":9},{"move":{"x":-7,"y":-16,"z":33},"block_id":9},{"move":{"x":-7,"y":-16,"z":34},"block_id":106,"rotate":{"x":1,"y":0,"z":0}},{"move":{"x":-7,"y":-16,"z":37},"block_id":103},{"move":{"x":-7,"y":-16,"z":38},"block_id":9},{"move":{"x":-7,"y":-16,"z":39},"block_id":9},{"move":{"x":-7,"y":-16,"z":40},"block_id":9},{"move":{"x":-7,"y":-16,"z":41},"block_id":9},{"move":{"x":-7,"y":-16,"z":42},"block_id":8},{"move":{"x":-7,"y":-16,"z":43},"block_id":9},{"move":{"x":-7,"y":-16,"z":44},"block_id":9},{"move":{"x":-7,"y":-16,"z":45},"block_id":9},{"move":{"x":-7,"y":-16,"z":46},"block_id":9},{"move":{"x":-7,"y":-16,"z":47},"block_id":9},{"move":{"x":-7,"y":-15,"z":15},"block_id":9},{"move":{"x":-7,"y":-15,"z":16},"block_id":9},{"move":{"x":-7,"y":-15,"z":17},"block_id":9},{"move":{"x":-7,"y":-15,"z":18},"block_id":8},{"move":{"x":-7,"y":-15,"z":19},"block_id":9},{"move":{"x":-7,"y":-15,"z":20},"block_id":9},{"move":{"x":-7,"y":-15,"z":21},"block_id":9},{"move":{"x":-7,"y":-15,"z":22},"block_id":8},{"move":{"x":-7,"y":-15,"z":23},"block_id":9},{"move":{"x":-7,"y":-15,"z":24},"block_id":9},{"move":{"x":-7,"y":-15,"z":25},"block_id":8},{"move":{"x":-7,"y":-15,"z":26},"block_id":9},{"move":{"x":-7,"y":-15,"z":27},"block_id":9},{"move":{"x":-7,"y":-15,"z":28},"block_id":9},{"move":{"x":-7,"y":-15,"z":29},"block_id":9},{"move":{"x":-7,"y":-15,"z":30},"block_id":9},{"move":{"x":-7,"y":-15,"z":31},"block_id":9},{"move":{"x":-7,"y":-15,"z":32},"block_id":9},{"move":{"x":-7,"y":-15,"z":34},"block_id":9},{"move":{"x":-7,"y":-15,"z":35},"block_id":9},{"move":{"x":-7,"y":-15,"z":36},"block_id":9},{"move":{"x":-7,"y":-14,"z":17},"block_id":8},{"move":{"x":-7,"y":-14,"z":30},"block_id":8},{"move":{"x":-7,"y":-13,"z":17},"block_id":8},{"move":{"x":-7,"y":-13,"z":30},"block_id":8},{"move":{"x":-7,"y":-12,"z":17},"block_id":8},{"move":{"x":-7,"y":-12,"z":30},"block_id":8},{"move":{"x":-7,"y":-11,"z":17},"block_id":8},{"move":{"x":-7,"y":-11,"z":30},"block_id":8},{"move":{"x":-7,"y":-10,"z":17},"block_id":8},{"move":{"x":-7,"y":-10,"z":30},"block_id":8},{"move":{"x":-7,"y":-9,"z":17},"block_id":8},{"move":{"x":-7,"y":-9,"z":30},"block_id":8},{"move":{"x":-7,"y":-8,"z":17},"block_id":8},{"move":{"x":-7,"y":-8,"z":30},"block_id":8},{"move":{"x":-7,"y":-7,"z":17},"block_id":8},{"move":{"x":-7,"y":-7,"z":30},"block_id":8},{"move":{"x":-7,"y":-6,"z":17},"block_id":8},{"move":{"x":-7,"y":-6,"z":30},"block_id":8},{"move":{"x":-7,"y":-5,"z":17},"block_id":8},{"move":{"x":-7,"y":-5,"z":30},"block_id":8},{"move":{"x":-7,"y":-4,"z":17},"block_id":8},{"move":{"x":-7,"y":-4,"z":30},"block_id":8},{"move":{"x":-7,"y":-3,"z":17},"block_id":8},{"move":{"x":-7,"y":-3,"z":30},"block_id":8},{"move":{"x":-7,"y":-2,"z":17},"block_id":8},{"move":{"x":-7,"y":-2,"z":30},"block_id":8},{"move":{"x":-7,"y":-1,"z":17},"block_id":8},{"move":{"x":-7,"y":-1,"z":30},"block_id":8},{"move":{"x":-7,"y":0,"z":17},"block_id":139},{"move":{"x":-7,"y":0,"z":30},"block_id":139},{"move":{"x":-7,"y":1,"z":17},"block_id":139},{"move":{"x":-7,"y":1,"z":30},"block_id":139},{"move":{"x":-7,"y":2,"z":17},"block_id":139},{"move":{"x":-7,"y":2,"z":30},"block_id":139},{"move":{"x":-7,"y":3,"z":16},"block_id":67,"extra_data":{"point":{"x":0,"y":0.1,"z":0}},"rotate":{"x":0,"y":0,"z":0}},{"move":{"x":-7,"y":3,"z":17},"block_id":139},{"move":{"x":-7,"y":3,"z":18},"block_id":139},{"move":{"x":-7,"y":3,"z":29},"block_id":139},{"move":{"x":-7,"y":3,"z":30},"block_id":139},{"move":{"x":-7,"y":3,"z":31},