{"name":"waterwell2","world":{"pos1":{"x":-48,"y":-28,"z":1},"pos2":{"x":-50,"y":6,"z":-1},"entrance":{"x":-49,"y":1,"z":0}},"meta":{},"size":{"x":3,"y":35,"z":3},"door_pos":{"x":1,"y":29,"z":1},"blocks":[{"move":{"x":-1,"y":-29,"z":-1},"block_id":8},{"move":{"x":-1,"y":-29,"z":0},"block_id":8},{"move":{"x":-1,"y":-29,"z":1},"block_id":8},{"move":{"x":-1,"y":-28,"z":-1},"block_id":8},{"move":{"x":-1,"y":-28,"z":0},"block_id":8},{"move":{"x":-1,"y":-28,"z":1},"block_id":8},{"move":{"x":-1,"y":-27,"z":-1},"block_id":8},{"move":{"x":-1,"y":-27,"z":0},"block_id":8},{"move":{"x":-1,"y":-27,"z":1},"block_id":8},{"move":{"x":-1,"y":-26,"z":-1},"block_id":8},{"move":{"x":-1,"y":-26,"z":0},"block_id":8},{"move":{"x":-1,"y":-26,"z":1},"block_id":8},{"move":{"x":-1,"y":-25,"z":-1},"block_id":8},{"move":{"x":-1,"y":-25,"z":0},"block_id":8},{"move":{"x":-1,"y":-25,"z":1},"block_id":8},{"move":{"x":-1,"y":-24,"z":-1},"block_id":8},{"move":{"x":-1,"y":-24,"z":0},"block_id":8},{"move":{"x":-1,"y":-24,"z":1},"block_id":8},{"move":{"x":-1,"y":-23,"z":-1},"block_id":8},{"move":{"x":-1,"y":-23,"z":0},"block_id":8},{"move":{"x":-1,"y":-23,"z":1},"block_id":8},{"move":{"x":-1,"y":-22,"z":-1},"block_id":8},{"move":{"x":-1,"y":-22,"z":0},"block_id":8},{"move":{"x":-1,"y":-22,"z":1},"block_id":8},{"move":{"x":-1,"y":-21,"z":-1},"block_id":8},{"move":{"x":-1,"y":-21,"z":0},"block_id":8},{"move":{"x":-1,"y":-21,"z":1},"block_id":8},{"move":{"x":-1,"y":-20,"z":-1},"block_id":8},{"move":{"x":-1,"y":-20,"z":0},"block_id":8},{"move":{"x":-1,"y":-20,"z":1},"block_id":8},{"move":{"x":-1,"y":-19,"z":-1},"block_id":8},{"move":{"x":-1,"y":-19,"z":0},"block_id":8},{"move":{"x":-1,"y":-19,"z":1},"block_id":8},{"move":{"x":-1,"y":-18,"z":-1},"block_id":8},{"move":{"x":-1,"y":-18,"z":0},"block_id":8},{"move":{"x":-1,"y":-18,"z":1},"block_id":8},{"move":{"x":-1,"y":-17,"z":-1},"block_id":8},{"move":{"x":-1,"y":-17,"z":0},"block_id":8},{"move":{"x":-1,"y":-17,"z":1},"block_id":8},{"move":{"x":-1,"y":-16,"z":-1},"block_id":8},{"move":{"x":-1,"y":-16,"z":0},"block_id":8},{"move":{"x":-1,"y":-16,"z":1},"block_id":8},{"move":{"x":-1,"y":-15,"z":-1},"block_id":8},{"move":{"x":-1,"y":-15,"z":0},"block_id":8},{"move":{"x":-1,"y":-15,"z":1},"block_id":8},{"move":{"x":-1,"y":-14,"z":-1},"block_id":8},{"move":{"x":-1,"y":-14,"z":0},"block_id":8},{"move":{"x":-1,"y":-14,"z":1},"block_id":8},{"move":{"x":-1,"y":-13,"z":-1},"block_id":8},{"move":{"x":-1,"y":-13,"z":0},"block_id":8},{"move":{"x":-1,"y":-13,"z":1},"block_id":8},{"move":{"x":-1,"y":-12,"z":-1},"block_id":8},{"move":{"x":-1,"y":-12,"z":0},"block_id":8},{"move":{"x":-1,"y":-12,"z":1},"block_id":8},{"move":{"x":-1,"y":-11,"z":-1},"block_id":8},{"move":{"x":-1,"y":-11,"z":0},"block_id":8},{"move":{"x":-1,"y":-11,"z":1},"block_id":8},{"move":{"x":-1,"y":-10,"z":-1},"block_id":8},{"move":{"x":-1,"y":-10,"z":0},"block_id":8},{"move":{"x":-1,"y":-10,"z":1},"block_id":8},{"move":{"x":-1,"y":-9,"z":-1},"block_id":8},{"move":{"x":-1,"y":-9,"z":0},"block_id":8},{"move":{"x":-1,"y":-9,"z":1},"block_id":8},{"move":{"x":-1,"y":-8,"z":-1},"block_id":8},{"move":{"x":-1,"y":-8,"z":0},"block_id":8},{"move":{"x":-1,"y":-8,"z":1},"block_id":8},{"move":{"x":-1,"y":-7,"z":-1},"block_id":8},{"move":{"x":-1,"y":-7,"z":0},"block_id":8},{"move":{"x":-1,"y":-7,"z":1},"block_id":8},{"move":{"x":-1,"y":-6,"z":-1},"block_id":8},{"move":{"x":-1,"y":-6,"z":0},"block_id":8},{"move":{"x":-1,"y":-6,"z":1},"block_id":8},{"move":{"x":-1,"y":-5,"z":-1},"block_id":8},{"move":{"x":-1,"y":-5,"z":0},"block_id":8},{"move":{"x":-1,"y":-5,"z":1},"block_id":8},{"move":{"x":-1,"y":-4,"z":-1},"block_id":8},{"move":{"x":-1,"y":-4,"z":0},"block_id":8},{"move":{"x":-1,"y":-4,"z":1},"block_id":8},{"move":{"x":-1,"y":-3,"z":-1},"block_id":8},{"move":{"x":-1,"y":-3,"z":0},"block_id":8},{"move":{"x":-1,"y":-3,"z":1},"block_id":8},{"move":{"x":-1,"y":-2,"z":-1},"block_id":8},{"move":{"x":-1,"y":-2,"z":0},"block_id":8},{"move":{"x":-1,"y":-2,"z":1},"block_id":8},{"move":{"x":-1,"y":-1,"z":-1},"block_id":8},{"move":{"x":-1,"y":-1,"z":0},"block_id":8},{"move":{"x":-1,"y":-1,"z":1},"block_id":8},{"move":{"x":-1,"y":0,"z":-1},"block_id":144},{"move":{"x":-1,"y":0,"z":0},"block_id":8},{"move":{"x":-1,"y":0,"z":1},"block_id":139},{"move":{"x":-1,"y":1,"z":0},"block_id":139},{"move":{"x":-1,"y":2,"z":0},"block_id":139},{"move":{"x":-1,"y":3,"z":0},"block_id":45,"extra_data":{"point":{"x":1.0020000000000024,"y":0.32249196724029616,"z":0.5725609996338761}}},{"move":{"x":0,"y":-29,"z":-1},"block_id":8},{"move":{"x":0,"y":-29,"z":0},"block_id":8},{"move":{"x":0,"y":-29,"z":1},"block_id":8},{"move":{"x":0,"y":-28,"z":-1},"block_id":8},{"move":{"x":0,"y":-28,"z":1},"block_id":8},{"move":{"x":0,"y":-27,"z":-1},"block_id":8},{"move":{"x":0,"y":-27,"z":1},"block_id":8},{"move":{"x":0,"y":-26,"z":-1},"block_id":8},{"move":{"x":0,"y":-26,"z":1},"block_id":8},{"move":{"x":0,"y":-25,"z":-1},"block_id":8},{"move":{"x":0,"y":-25,"z":1},"block_id":8},{"move":{"x":0,"y":-24,"z":-1},"block_id":8},{"move":{"x":0,"y":-24,"z":1},"block_id":8},{"move":{"x":0,"y":-23,"z":-1},"block_id":8},{"move":{"x":0,"y":-23,"z":1},"block_id":8},{"move":{"x":0,"y":-22,"z":-1},"block_id":8},{"move":{"x":0,"y":-22,"z":1},"block_id":8},{"move":{"x":0,"y":-21,"z":-1},"block_id":8},{"move":{"x":0,"y":-21,"z":1},"block_id":8},{"move":{"x":0,"y":-20,"z":-1},"block_id":8},{"move":{"x":0,"y":-20,"z":1},"block_id":8},{"move":{"x":0,"y":-19,"z":-1},"block_id":8},{"move":{"x":0,"y":-19,"z":1},"block_id":8},{"move":{"x":0,"y":-18,"z":-1},"block_id":8},{"move":{"x":0,"y":-18,"z":1},"block_id":8},{"move":{"x":0,"y":-17,"z":-1},"block_id":8},{"move":{"x":0,"y":-17,"z":1},"block_id":8},{"move":{"x":0,"y":-16,"z":-1},"block_id":8},{"move":{"x":0,"y":-16,"z":1},"block_id":8},{"move":{"x":0,"y":-15,"z":-1},"block_id":8},{"move":{"x":0,"y":-15,"z":1},"block_id":8},{"move":{"x":0,"y":-14,"z":-1},"block_id":8},{"move":{"x":0,"y":-14,"z":1},"block_id":8},{"move":{"x":0,"y":-13,"z":-1},"block_id":8},{"move":{"x":0,"y":-13,"z":1},"block_id":8},{"move":{"x":0,"y":-12,"z":-1},"block_id":8},{"move":{"x":0,"y":-12,"z":1},"block_id":8},{"move":{"x":0,"y":-11,"z":-1},"block_id":8},{"move":{"x":0,"y":-11,"z":1},"block_id":8},{"move":{"x":0,"y":-10,"z":-1},"block_id":8},{"move":{"x":0,"y":-10,"z":1},"block_id":8},{"move":{"x":0,"y":-9,"z":-1},"block_id":8},{"move":{"x":0,"y":-9,"z":1},"block_id":8},{"move":{"x":0,"y":-8,"z":-1},"block_id":8},{"move":{"x":0,"y":-8,"z":1},"block_id":8},{"move":{"x":0,"y":-7,"z":-1},"block_id":8},{"move":{"x":0,"y":-7,"z":1},"block_id":8},{"move":{"x":0,"y":-6,"z":-1},"block_id":8},{"move":{"x":0,"y":-6,"z":1},"block_id":8},{"move":{"x":0,"y":-5,"z":-1},"block_id":8},{"move":{"x":0,"y":-5,"z":1},"block_id":8},{"move":{"x":0,"y":-4,"z":-1},"block_id":8},{"move":{"x":0,"y":-4,"z":1},"block_id":8},{"move":{"x":0,"y":-3,"z":-1},"block_id":8},{"move":{"x":0,"y":-3,"z":1},"block_id":8},{"move":{"x":0,"y":-2,"z":-1},"block_id":8},{"move":{"x":0,"y":-2,"z":1},"block_id":8},{"move":{"x":0,"y":-1,"z":-1},"block_id":8},{"move":{"x":0,"y":-1,"z":1},"block_id":8},{"move":{"x":0,"y":0,"z":-1},"block_id":8},{"move":{"x":0,"y":0,"z":1},"block_id":8},{"move":{"x":0,"y":3,"z":0},"block_id":8},{"move":{"x":1,"y":-29,"z":-1},"block_id":8},{"move":{"x":1,"y":-29,"z":0},"block_id":8},{"move":{"x":1,"y":-29,"z":1},"block_id":8},{"move":{"x":1,"y":-28,"z":-1},"block_id":8},{"move":{"x":1,"y":-28,"z":0},"block_id":8},{"move":{"x":1,"y":-28,"z":1},"block_id":8},{"move":{"x":1,"y":-27,"z":-1},"block_id":8},{"move":{"x":1,"y":-27,"z":0},"block_id":8},{"move":{"x":1,"y":-27,"z":1},"block_id":8},{"move":{"x":1,"y":-26,"z":-1},"block_id":8},{"move":{"x":1,"y":-26,"z":0},"block_id":8},{"move":{"x":1,"y":-26,"z":1},"block_id":8},{"move":{"x":1,"y":-25,"z":-1},"block_id":8},{"move":{"x":1,"y":-25,"z":0},"block_id":8},{"move":{"x":1,"y":-25,"z":1},"block_id":8},{"move":{"x":1,"y":-24,"z":-1},"block_id":8},{"move":{"x":1,"y":-24,"z":0},"block_id":8},{"move":{"x":1,"y":-24,"z":1},"block_id":8},{"move":{"x":1,"y":-23,"z":-1},"block_id":8},{"move":{"x":1,"y":-23,"z":0},"block_id":8},{"move":{"x":1,"y":-23,"z":1},"block_id":8},{"move":{"x":1,"y":-22,"z":-1},"block_id":8},{"move":{"x":1,"y":-22,"z":0},"block_id":8},{"move":{"x":1,"y":-22,"z":1},"block_id":8},{"move":{"x":1,"y":-21,"z":-1},"block_id":8},{"move":{"x":1,"y":-21,"z":0},"block_id":8},{"move":{"x":1,"y":-21,"z":1},"block_id":8},{"move":{"x":1,"y":-20,"z":-1},"block_id":8},{"move":{"x":1,"y":-20,"z":0},"block_id":8},{"move":{"x":1,"y":-20,"z":1},"block_id":8},{"move":{"x":1,"y":-19,"z":-1},"block_id":8},{"move":{"x":1,"y":-19,"z":0},"block_id":8},{"move":{"x":1,"y":-19,"z":1},"block_id":8},{"move":{"x":1,"y":-18,"z":-1},"block_id":8},{"move":{"x":1,"y":-18,"z":0},"block_id":8},{"move":{"x":1,"y":-18,"z":1},"block_id":8},{"move":{"x":1,"y":-17,"z":-1},"block_id":8},{"move":{"x":1,"y":-17,"z":0},"block_id":8},{"move":{"x":1,"y":-17,"z":1},"block_id":8},{"move":{"x":1,"y":-16,"z":-1},"block_id":8},{"move":{"x":1,"y":-16,"z":0},"block_id":8},{"move":{"x":1,"y":-16,"z":1},"block_id":8},{"move":{"x":1,"y":-15,"z":-1},"block_id":8},{"move":{"x":1,"y":-15,"z":0},"block_id":8},{"move":{"x":1,"y":-15,"z":1},"block_id":8},{"move":{"x":1,"y":-14,"z":-1},"block_id":8},{"move":{"x":1,"y":-14,"z":0},"block_id":8},{"move":{"x":1,"y":-14,"z":1},"block_id":8},{"move":{"x":1,"y":-13,"z":-1},"block_id":8},{"move":{"x":1,"y":-13,"z":0},"block_id":8},{"move":{"x":1,"y":-13,"z":1},"block_id":8},{"move":{"x":1,"y":-12,"z":-1},"block_id":8},{"move":{"x":1,"y":-12,"z":0},"block_id":8},{"move":{"x":1,"y":-12,"z":1},"block_id":8},{"move":{"x":1,"y":-11,"z":-1},"block_id":8},{"move":{"x":1,"y":-11,"z":0},"block_id":8},{"move":{"x":1,"y":-11,"z":1},"block_id":8},{"move":{"x":1,"y":-10,"z":-1},"block_id":8},{"move":{"x":1,"y":-10,"z":0},"block_id":8},{"move":{"x":1,"y":-10,"z":1},"block_id":8},{"move":{"x":1,"y":-9,"z":-1},"block_id":8},{"move":{"x":1,"y":-9,"z":0},"block_id":8},{"move":{"x":1,"y":-9,"z":1},"block_id":8},{"move":{"x":1,"y":-8,"z":-1},"block_id":8},{"move":{"x":1,"y":-8,"z":0},"block_id":8},{"move":{"x":1,"y":-8,"z":1},"block_id":8},{"move":{"x":1,"y":-7,"z":-1},"block_id":8},{"move":{"x":1,"y":-7,"z":0},"block_id":8},{"move":{"x":1,"y":-7,"z":1},"block_id":8},{"move":{"x":1,"y":-6,"z":-1},"block_id":8},{"move":{"x":1,"y":-6,"z":0},"block_id":8},{"move":{"x":1,"y":-6,"z":1},"block_id":8},{"move":{"x":1,"y":-5,"z":-1},"block_id":8},{"move":{"x":1,"y":-5,"z":0},"block_id":8},{"move":{"x":1,"y":-5,"z":1},"block_id":8},{"move":{"x":1,"y":-4,"z":-1},"block_id":8},{"move":{"x":1,"y":-4,"z":0},"block_id":8},{"move":{"x":1,"y":-4,"z":1},"block_id":8},{"move":{"x":1,"y":-3,"z":-1},"block_id":8},{"move":{"x":1,"y":-3,"z":0},"block_id":8},{"move":{"x":1,"y":-3,"z":1},"block_id":8},{"move":{"x":1,"y":-2,"z":-1},"block_id":8},{"move":{"x":1,"y":-2,"z":0},"block_id":8},{"move":{"x":1,"y":-2,"z":1},"block_id":8},{"move":{"x":1,"y":-1,"z":-1},"block_id":8},{"move":{"x":1,"y":-1,"z":0},"block_id":8},{"move":{"x":1,"y":-1,"z":1},"block_id":8},{"move":{"x":1,"y":0,"z":-1},"block_id":139},{"move":{"x":1,"y":0,"z":0},"block_id":8},{"move":{"x":1,"y":0,"z":1},"block_id":144},{"move":{"x":1,"y":1,"z":0},"block_id":139},{"move":{"x":1,"y":2,"z":0},"block_id":139},{"move":{"x":1,"y":3,"z":0},"block_id":45,"extra_data":{"point":{"x":0.5267468351629887,"y":0,"z":0.5931522728642661}}}],"rot":[],"fluids":[0,-28,0,16,0,-27,0,16,0,-26,0,16,0,-25,0,16,0,-24,0,16,0,-23,0,16,0,-22,0,16,0,-21,0,16,0,-20,0,16,0,-19,0,16,0,-18,0,16,0,-17,0,16,0,-16,0,16,0,-15,0,16,0,-14,0,16,0,-13,0,16,0,-12,0,16,0,-11,0,16,0,-10,0,16,0,-9,0,16,0,-8,0,16,0,-7,0,16,0,-6,0,16,0,-5,0,16,0,-4,0,16,0,-3,0,16,0,-2,0,16,0,-1,0,16,0,0,0,16]}