{"name":"waterwell","world":{"pos1":{"x":-52,"y":-29,"z":1},"pos2":{"x":-54,"y":6,"z":-1},"entrance":{"x":-53,"y":1,"z":0}},"meta":{},"size":{"x":3,"y":36,"z":3},"door_pos":{"x":1,"y":30,"z":1},"blocks":[{"move":{"x":-1,"y":-29,"z":-1},"block_id":7},{"move":{"x":-1,"y":-29,"z":0},"block_id":7},{"move":{"x":-1,"y":-29,"z":1},"block_id":7},{"move":{"x":-1,"y":-28,"z":-1},"block_id":7},{"move":{"x":-1,"y":-28,"z":0},"block_id":7},{"move":{"x":-1,"y":-28,"z":1},"block_id":7},{"move":{"x":-1,"y":-27,"z":-1},"block_id":7},{"move":{"x":-1,"y":-27,"z":0},"block_id":7},{"move":{"x":-1,"y":-27,"z":1},"block_id":7},{"move":{"x":-1,"y":-26,"z":-1},"block_id":7},{"move":{"x":-1,"y":-26,"z":0},"block_id":7},{"move":{"x":-1,"y":-26,"z":1},"block_id":7},{"move":{"x":-1,"y":-25,"z":-1},"block_id":7},{"move":{"x":-1,"y":-25,"z":0},"block_id":7},{"move":{"x":-1,"y":-25,"z":1},"block_id":7},{"move":{"x":-1,"y":-24,"z":-1},"block_id":7},{"move":{"x":-1,"y":-24,"z":0},"block_id":7},{"move":{"x":-1,"y":-24,"z":1},"block_id":7},{"move":{"x":-1,"y":-23,"z":-1},"block_id":7},{"move":{"x":-1,"y":-23,"z":0},"block_id":7},{"move":{"x":-1,"y":-23,"z":1},"block_id":7},{"move":{"x":-1,"y":-22,"z":-1},"block_id":7},{"move":{"x":-1,"y":-22,"z":0},"block_id":7},{"move":{"x":-1,"y":-22,"z":1},"block_id":7},{"move":{"x":-1,"y":-21,"z":-1},"block_id":7},{"move":{"x":-1,"y":-21,"z":0},"block_id":7},{"move":{"x":-1,"y":-21,"z":1},"block_id":7},{"move":{"x":-1,"y":-20,"z":-1},"block_id":7},{"move":{"x":-1,"y":-20,"z":0},"block_id":7},{"move":{"x":-1,"y":-20,"z":1},"block_id":7},{"move":{"x":-1,"y":-19,"z":-1},"block_id":7},{"move":{"x":-1,"y":-19,"z":0},"block_id":7},{"move":{"x":-1,"y":-19,"z":1},"block_id":7},{"move":{"x":-1,"y":-18,"z":-1},"block_id":7},{"move":{"x":-1,"y":-18,"z":0},"block_id":7},{"move":{"x":-1,"y":-18,"z":1},"block_id":7},{"move":{"x":-1,"y":-17,"z":-1},"block_id":7},{"move":{"x":-1,"y":-17,"z":0},"block_id":7},{"move":{"x":-1,"y":-17,"z":1},"block_id":7},{"move":{"x":-1,"y":-16,"z":-1},"block_id":7},{"move":{"x":-1,"y":-16,"z":0},"block_id":7},{"move":{"x":-1,"y":-16,"z":1},"block_id":7},{"move":{"x":-1,"y":-15,"z":-1},"block_id":7},{"move":{"x":-1,"y":-15,"z":0},"block_id":7},{"move":{"x":-1,"y":-15,"z":1},"block_id":7},{"move":{"x":-1,"y":-14,"z":-1},"block_id":7},{"move":{"x":-1,"y":-14,"z":0},"block_id":7},{"move":{"x":-1,"y":-14,"z":1},"block_id":7},{"move":{"x":-1,"y":-13,"z":-1},"block_id":7},{"move":{"x":-1,"y":-13,"z":0},"block_id":7},{"move":{"x":-1,"y":-13,"z":1},"block_id":7},{"move":{"x":-1,"y":-12,"z":-1},"block_id":7},{"move":{"x":-1,"y":-12,"z":0},"block_id":7},{"move":{"x":-1,"y":-12,"z":1},"block_id":7},{"move":{"x":-1,"y":-11,"z":-1},"block_id":7},{"move":{"x":-1,"y":-11,"z":0},"block_id":7},{"move":{"x":-1,"y":-11,"z":1},"block_id":7},{"move":{"x":-1,"y":-10,"z":-1},"block_id":7},{"move":{"x":-1,"y":-10,"z":0},"block_id":7},{"move":{"x":-1,"y":-10,"z":1},"block_id":7},{"move":{"x":-1,"y":-9,"z":-1},"block_id":7},{"move":{"x":-1,"y":-9,"z":0},"block_id":7},{"move":{"x":-1,"y":-9,"z":1},"block_id":7},{"move":{"x":-1,"y":-8,"z":-1},"block_id":7},{"move":{"x":-1,"y":-8,"z":0},"block_id":7},{"move":{"x":-1,"y":-8,"z":1},"block_id":7},{"move":{"x":-1,"y":-7,"z":-1},"block_id":7},{"move":{"x":-1,"y":-7,"z":0},"block_id":7},{"move":{"x":-1,"y":-7,"z":1},"block_id":7},{"move":{"x":-1,"y":-6,"z":-1},"block_id":7},{"move":{"x":-1,"y":-6,"z":0},"block_id":7},{"move":{"x":-1,"y":-6,"z":1},"block_id":7},{"move":{"x":-1,"y":-5,"z":-1},"block_id":7},{"move":{"x":-1,"y":-5,"z":0},"block_id":7},{"move":{"x":-1,"y":-5,"z":1},"block_id":7},{"move":{"x":-1,"y":-4,"z":-1},"block_id":7},{"move":{"x":-1,"y":-4,"z":0},"block_id":7},{"move":{"x":-1,"y":-4,"z":1},"block_id":7},{"move":{"x":-1,"y":-3,"z":-1},"block_id":7},{"move":{"x":-1,"y":-3,"z":0},"block_id":7},{"move":{"x":-1,"y":-3,"z":1},"block_id":7},{"move":{"x":-1,"y":-2,"z":-1},"block_id":7},{"move":{"x":-1,"y":-2,"z":0},"block_id":7},{"move":{"x":-1,"y":-2,"z":1},"block_id":7},{"move":{"x":-1,"y":-1,"z":-1},"block_id":7},{"move":{"x":-1,"y":-1,"z":0},"block_id":7},{"move":{"x":-1,"y":-1,"z":1},"block_id":7},{"move":{"x":-1,"y":0,"z":-1},"block_id":7},{"move":{"x":-1,"y":0,"z":0},"block_id":53,"extra_data":{"point":{"x":0.6162348029254332,"y":0,"z":0.6166290213172085}},"rotate":{"x":3,"y":1,"z":0}},{"move":{"x":-1,"y":0,"z":1},"block_id":7},{"move":{"x":-1,"y":1,"z":-1},"block_id":85},{"move":{"x":-1,"y":1,"z":1},"block_id":85},{"move":{"x":-1,"y":2,"z":-1},"block_id":85},{"move":{"x":-1,"y":2,"z":1},"block_id":85},{"move":{"x":-1,"y":3,"z":-1},"block_id":126,"extra_data":{"point":{"x":0.2027381209899346,"y":0.25479449508660945,"z":1.002}}},{"move":{"x":-1,"y":3,"z":0},"block_id":126,"extra_data":{"point":{"x":1.0020000000000024,"y":0.17360380981074375,"z":0.5097414166182969}}},{"move":{"x":-1,"y":3,"z":1},"block_id":126,"extra_data":{"point":{"x":0.2130923817573347,"y":0.25278808127150576,"z":-0.002}}},{"move":{"x":0,"y":-29,"z":-1},"block_id":7},{"move":{"x":0,"y":-29,"z":0},"block_id":7},{"move":{"x":0,"y":-29,"z":1},"block_id":7},{"move":{"x":0,"y":-28,"z":-1},"block_id":7},{"move":{"x":0,"y":-28,"z":1},"block_id":7},{"move":{"x":0,"y":-27,"z":-1},"block_id":7},{"move":{"x":0,"y":-27,"z":1},"block_id":7},{"move":{"x":0,"y":-26,"z":-1},"block_id":7},{"move":{"x":0,"y":-26,"z":1},"block_id":7},{"move":{"x":0,"y":-25,"z":-1},"block_id":7},{"move":{"x":0,"y":-25,"z":1},"block_id":7},{"move":{"x":0,"y":-24,"z":-1},"block_id":7},{"move":{"x":0,"y":-24,"z":1},"block_id":7},{"move":{"x":0,"y":-23,"z":-1},"block_id":7},{"move":{"x":0,"y":-23,"z":1},"block_id":7},{"move":{"x":0,"y":-22,"z":-1},"block_id":7},{"move":{"x":0,"y":-22,"z":1},"block_id":7},{"move":{"x":0,"y":-21,"z":-1},"block_id":7},{"move":{"x":0,"y":-21,"z":1},"block_id":7},{"move":{"x":0,"y":-20,"z":-1},"block_id":7},{"move":{"x":0,"y":-20,"z":1},"block_id":7},{"move":{"x":0,"y":-19,"z":-1},"block_id":7},{"move":{"x":0,"y":-19,"z":1},"block_id":7},{"move":{"x":0,"y":-18,"z":-1},"block_id":7},{"move":{"x":0,"y":-18,"z":1},"block_id":7},{"move":{"x":0,"y":-17,"z":-1},"block_id":7},{"move":{"x":0,"y":-17,"z":1},"block_id":7},{"move":{"x":0,"y":-16,"z":-1},"block_id":7},{"move":{"x":0,"y":-16,"z":1},"block_id":7},{"move":{"x":0,"y":-15,"z":-1},"block_id":7},{"move":{"x":0,"y":-15,"z":1},"block_id":7},{"move":{"x":0,"y":-14,"z":-1},"block_id":7},{"move":{"x":0,"y":-14,"z":1},"block_id":7},{"move":{"x":0,"y":-13,"z":-1},"block_id":7},{"move":{"x":0,"y":-13,"z":1},"block_id":7},{"move":{"x":0,"y":-12,"z":-1},"block_id":7},{"move":{"x":0,"y":-12,"z":1},"block_id":7},{"move":{"x":0,"y":-11,"z":-1},"block_id":7},{"move":{"x":0,"y":-11,"z":1},"block_id":7},{"move":{"x":0,"y":-10,"z":-1},"block_id":7},{"move":{"x":0,"y":-10,"z":1},"block_id":7},{"move":{"x":0,"y":-9,"z":-1},"block_id":7},{"move":{"x":0,"y":-9,"z":1},"block_id":7},{"move":{"x":0,"y":-8,"z":-1},"block_id":7},{"move":{"x":0,"y":-8,"z":1},"block_id":7},{"move":{"x":0,"y":-7,"z":-1},"block_id":7},{"move":{"x":0,"y":-7,"z":1},"block_id":7},{"move":{"x":0,"y":-6,"z":-1},"block_id":7},{"move":{"x":0,"y":-6,"z":1},"block_id":7},{"move":{"x":0,"y":-5,"z":-1},"block_id":7},{"move":{"x":0,"y":-5,"z":1},"block_id":7},{"move":{"x":0,"y":-4,"z":-1},"block_id":7},{"move":{"x":0,"y":-4,"z":1},"block_id":7},{"move":{"x":0,"y":-3,"z":-1},"block_id":7},{"move":{"x":0,"y":-3,"z":1},"block_id":7},{"move":{"x":0,"y":-2,"z":-1},"block_id":7},{"move":{"x":0,"y":-2,"z":1},"block_id":7},{"move":{"x":0,"y":-1,"z":-1},"block_id":7},{"move":{"x":0,"y":-1,"z":1},"block_id":7},{"move":{"x":0,"y":0,"z":-1},"block_id":53,"extra_data":{"point":{"x":0.6876729490947682,"y":0,"z":0.18892819569184316}},"rotate":{"x":0,"y":1,"z":0}},{"move":{"x":0,"y":0,"z":1},"block_id":53,"extra_data":{"point":{"x":0.5351718142775042,"y":0,"z":0.737396318256258}},"rotate":{"x":2,"y":1,"z":0}},{"move":{"x":0,"y":3,"z":-1},"block_id":126,"extra_data":{"point":{"x":0.48671166853318937,"y":0.37495125274501717,"z":1.002}}},{"move":{"x":0,"y":3,"z":0},"block_id":7},{"move":{"x":0,"y":3,"z":1},"block_id":126,"extra_data":{"point":{"x":0.324067878841511,"y":0.2199396799259956,"z":-0.002}}},{"move":{"x":1,"y":-29,"z":-1},"block_id":7},{"move":{"x":1,"y":-29,"z":0},"block_id":7},{"move":{"x":1,"y":-29,"z":1},"block_id":7},{"move":{"x":1,"y":-28,"z":-1},"block_id":7},{"move":{"x":1,"y":-28,"z":0},"block_id":7},{"move":{"x":1,"y":-28,"z":1},"block_id":7},{"move":{"x":1,"y":-27,"z":-1},"block_id":7},{"move":{"x":1,"y":-27,"z":0},"block_id":7},{"move":{"x":1,"y":-27,"z":1},"block_id":7},{"move":{"x":1,"y":-26,"z":-1},"block_id":7},{"move":{"x":1,"y":-26,"z":0},"block_id":7},{"move":{"x":1,"y":-26,"z":1},"block_id":7},{"move":{"x":1,"y":-25,"z":-1},"block_id":7},{"move":{"x":1,"y":-25,"z":0},"block_id":7},{"move":{"x":1,"y":-25,"z":1},"block_id":7},{"move":{"x":1,"y":-24,"z":-1},"block_id":7},{"move":{"x":1,"y":-24,"z":0},"block_id":7},{"move":{"x":1,"y":-24,"z":1},"block_id":7},{"move":{"x":1,"y":-23,"z":-1},"block_id":7},{"move":{"x":1,"y":-23,"z":0},"block_id":7},{"move":{"x":1,"y":-23,"z":1},"block_id":7},{"move":{"x":1,"y":-22,"z":-1},"block_id":7},{"move":{"x":1,"y":-22,"z":0},"block_id":7},{"move":{"x":1,"y":-22,"z":1},"block_id":7},{"move":{"x":1,"y":-21,"z":-1},"block_id":7},{"move":{"x":1,"y":-21,"z":0},"block_id":7},{"move":{"x":1,"y":-21,"z":1},"block_id":7},{"move":{"x":1,"y":-20,"z":-1},"block_id":7},{"move":{"x":1,"y":-20,"z":0},"block_id":7},{"move":{"x":1,"y":-20,"z":1},"block_id":7},{"move":{"x":1,"y":-19,"z":-1},"block_id":7},{"move":{"x":1,"y":-19,"z":0},"block_id":7},{"move":{"x":1,"y":-19,"z":1},"block_id":7},{"move":{"x":1,"y":-18,"z":-1},"block_id":7},{"move":{"x":1,"y":-18,"z":0},"block_id":7},{"move":{"x":1,"y":-18,"z":1},"block_id":7},{"move":{"x":1,"y":-17,"z":-1},"block_id":7},{"move":{"x":1,"y":-17,"z":0},"block_id":7},{"move":{"x":1,"y":-17,"z":1},"block_id":7},{"move":{"x":1,"y":-16,"z":-1},"block_id":7},{"move":{"x":1,"y":-16,"z":0},"block_id":7},{"move":{"x":1,"y":-16,"z":1},"block_id":7},{"move":{"x":1,"y":-15,"z":-1},"block_id":7},{"move":{"x":1,"y":-15,"z":0},"block_id":7},{"move":{"x":1,"y":-15,"z":1},"block_id":7},{"move":{"x":1,"y":-14,"z":-1},"block_id":7},{"move":{"x":1,"y":-14,"z":0},"block_id":7},{"move":{"x":1,"y":-14,"z":1},"block_id":7},{"move":{"x":1,"y":-13,"z":-1},"block_id":7},{"move":{"x":1,"y":-13,"z":0},"block_id":7},{"move":{"x":1,"y":-13,"z":1},"block_id":7},{"move":{"x":1,"y":-12,"z":-1},"block_id":7},{"move":{"x":1,"y":-12,"z":0},"block_id":7},{"move":{"x":1,"y":-12,"z":1},"block_id":7},{"move":{"x":1,"y":-11,"z":-1},"block_id":7},{"move":{"x":1,"y":-11,"z":0},"block_id":7},{"move":{"x":1,"y":-11,"z":1},"block_id":7},{"move":{"x":1,"y":-10,"z":-1},"block_id":7},{"move":{"x":1,"y":-10,"z":0},"block_id":7},{"move":{"x":1,"y":-10,"z":1},"block_id":7},{"move":{"x":1,"y":-9,"z":-1},"block_id":7},{"move":{"x":1,"y":-9,"z":0},"block_id":7},{"move":{"x":1,"y":-9,"z":1},"block_id":7},{"move":{"x":1,"y":-8,"z":-1},"block_id":7},{"move":{"x":1,"y":-8,"z":0},"block_id":7},{"move":{"x":1,"y":-8,"z":1},"block_id":7},{"move":{"x":1,"y":-7,"z":-1},"block_id":7},{"move":{"x":1,"y":-7,"z":0},"block_id":7},{"move":{"x":1,"y":-7,"z":1},"block_id":7},{"move":{"x":1,"y":-6,"z":-1},"block_id":7},{"move":{"x":1,"y":-6,"z":0},"block_id":7},{"move":{"x":1,"y":-6,"z":1},"block_id":7},{"move":{"x":1,"y":-5,"z":-1},"block_id":7},{"move":{"x":1,"y":-5,"z":0},"block_id":7},{"move":{"x":1,"y":-5,"z":1},"block_id":7},{"move":{"x":1,"y":-4,"z":-1},"block_id":7},{"move":{"x":1,"y":-4,"z":0},"block_id":7},{"move":{"x":1,"y":-4,"z":1},"block_id":7},{"move":{"x":1,"y":-3,"z":-1},"block_id":7},{"move":{"x":1,"y":-3,"z":0},"block_id":7},{"move":{"x":1,"y":-3,"z":1},"block_id":7},{"move":{"x":1,"y":-2,"z":-1},"block_id":7},{"move":{"x":1,"y":-2,"z":0},"block_id":7},{"move":{"x":1,"y":-2,"z":1},"block_id":7},{"move":{"x":1,"y":-1,"z":-1},"block_id":7},{"move":{"x":1,"y":-1,"z":0},"block_id":7},{"move":{"x":1,"y":-1,"z":1},"block_id":7},{"move":{"x":1,"y":0,"z":-1},"block_id":7},{"move":{"x":1,"y":0,"z":0},"block_id":53,"extra_data":{"point":{"x":0.7712486527959186,"y":0,"z":0.556559081006259}},"rotate":{"x":1,"y":1,"z":0}},{"move":{"x":1,"y":0,"z":1},"block_id":7},{"move":{"x":1,"y":1,"z":-1},"block_id":85},{"move":{"x":1,"y":1,"z":1},"block_id":85},{"move":{"x":1,"y":2,"z":-1},"block_id":85},{"move":{"x":1,"y":2,"z":1},"block_id":85},{"move":{"x":1,"y":3,"z":-1},"block_id":126,"extra_data":{"point":{"x":0.8379613358387203,"y":0.2862169624576625,"z":1.002}}},{"move":{"x":1,"y":3,"z":0},"block_id":126,"extra_data":{"point":{"x":-0.0020000000000024443,"y":0.21149891144213662,"z":0.3809424671187005}}},{"move":{"x":1,"y":3,"z":1},"block_id":126,"extra_data":{"point":{"x":0.5326522797253972,"y":0.2754087123979785,"z":-0.002}}}],"rot":[],"fluids":[0,-28,0,16,0,-27,0,16,0,-26,0,16,0,-25,0,16,0,-24,0,16,0,-23,0,16,0,-22,0,16,0,-21,0,16,0,-20,0,16,0,-19,0,16,0,-18,0,16,0,-17,0,16,0,-16,0,16,0,-15,0,16,0,-14,0,16,0,-13,0,16,0,-12,0,16,0,-11,0,16,0,-10,0,16,0,-9,0,16,0,-8,0,16,0,-7,0,16,0,-6,0,16,0,-5,0,16,0,-4,0,16,0,-3,0,16,0,-2,0,16,0,-1,0,16,0,0,0,16]}